Workbook

Sheet Elec
B2: ~TFM_INS
B3: Attribute | C3: Curr | D3: Attrib_Cond | E3: LimType | F3: Other_Indexes | G3: Year | H3: AllRegions | I3: PSET_SET | J3: PSET_PN | K3: PSET_CI | L3: CSET_CN | M3: Top_Check
B4: NCAP_BND | D4: PASTI | E4: FX | G4: 0 | H4: 2 | I4: ELE,CHP,STS,STG
B5: PRC_CAPACT | H5: 31.536 | I5: =I4 -> ELE,CHP,STS,STG
B6: PASTI | D6: PASTI | G6: 0 | H6: 1 | I6: =I5 -> ELE,CHP,STS,STG
B7: RCAP_BND | D7: PASTI | E7: UP | G7: 2025 | H7: 0 | I7: ELE,CHP | K7: -ELCHYD,-ELCBIO,-ELCWAS,-ELCGEO
B8: RCAP_BND | D8: PASTI | E8: UP | G8: 2030 | H8: 0 | I8: ELE,CHP | K8: ELCNGA
B9: RCAP_BND | D9: PASTI | E9: UP | G9: 0 | H9: 4 | I9: ELE,CHP | K9: =K7 -> -ELCHYD,-ELCBIO,-ELCWAS,-ELCGEO
B10: PEAK | H10: 1 | I10: =I6 -> ELE,CHP,STS,STG
B14: ~TFM_UPD
B15: Attribute | C15: Curr | D15: Attrib_Cond | E15: LimType | F15: Other_Indexes | G15: Year | H15: AllRegions | I15: PSET_SET | J15: PSET_CI
B16: EFF | H16: 0.32 | J16: ELCNUC
B17: EFF | H17: 1 | J17: *HYD,*SPV,*WIN
B18: FIXOM | H18: 0 | J18: *HYD,*SPV,*STH,*WIN | L18: will come from WEO pg techs
B25: ~TFM_INS
B26: Attribute | C26: Curr | D26: Attrib_Cond | E26: LimType | F26: Other_Indexes | G26: Year | H26: AllRegions | I26: PSET_SET | J26: PSET_PD | K26: PSET_PN
B27: INVCOST | C27: USD11 | H27: 2882.6578 | I27: ELE | K27: EP*Coa*
B28: INVCOST | C28: USD11 | H28: 893.70914 | I28: ELE | K28: EP*NGA*,EP*Oil*
B29: INVCOST | C29: USD11 | H29: 3000 | I29: ELE,STS | K29: EP*Hyd*
B30: ELIFE | H30: 30 | K30: EP*
B31: LIFE | D31: -LIFE | H31: 200 | I31: ELE,CHP,STS
B32: PRC_AOFF | G32: BOH-2030 | H32: 1 | I32: ELE,CHP | J32: *-- mothballed | M32: ~md-v_r: placeholder assumption on standby power generation capacity; date: 01-02-2025; author: Amit Kanudia

Sheet Transport
J1: =AVERAGE(J5:J24) -> 0.80600458
B3: ~TFM_MIG | G3: ~TFM_INS | L3: ~TFM_INS: Limtype=FX | S3: Sum of val_field | T3: 2020 | V3: 2030 | X3: 2040 | Z3: 2050
B4: attribute | C4: pset_pn | D4: year2 | E4: allregions | G4: attribute | H4: other_indexes | I4: year | J4: value | L4: attribute | M4: pset_pn | N4: year | O4: value | S4: process | T4: NCAP_COST | U4: NCAP_FOM | V4: NCAP_COST | W4: NCAP_FOM | X4: NCAP_COST | Y4: NCAP_FOM | Z4: NCAP_COST | AA4: NCAP_FOM
B5: PASTI | C5: Trd[_]* | D5: 2019 | E5: ="*"&1/20/$J$1 -> *0.0620343872322709 | G5: SHAPE | H5: 15 | I5: =SHAPES!A8 -> 1 | J5: =SHAPES!B8 -> 0.98 | L5: NCAP_BND | M5: Trd[_]* | N5: 0 | O5: 2 | S5: Trd_2w_gsl150_02 | T5: 2548.4 | U5: 76.451999 | V5: 2548.4 | W5: 76.451999 | X5: 2548.4 | Y5: 76.451999 | Z5: 2548.4 | AA5: 76.451999
B6: PASTI | C6: Trd[_]* | D6: =D5-1 -> 2018 | E6: ="*"&1/20/$J$1 -> *0.0620343872322709 | G6: SHAPE | H6: 15 | I6: =SHAPES!A9 -> 2 | J6: =SHAPES!B9 -> 0.97062258 | S6: Trd_3w_gsl_02 | T6: 11100.695 | U6: 333.02086 | V6: 11100.695 | W6: 333.02086 | X6: 11100.695 | Y6: 333.02086 | Z6: 11100.695 | AA6: 333.02086
B7: PASTI | C7: Trd[_]* | D7: =D6-1 -> 2017 | E7: ="*"&1/20/$J$1 -> *0.0620343872322709 | G7: SHAPE | H7: 15 | I7: =SHAPES!A10 -> 3 | J7: =SHAPES!B10 -> 0.96239644 | S7: Trd_bus_dsl_04 | T7: 277035.55 | U7: 8311.0664 | V7: 277035.55 | W7: 8311.0664 | X7: 277035.55 | Y7: 8311.0664 | Z7: 277035.55 | AA7: 8311.0664
B8: PASTI | C8: Trd[_]* | D8: =D7-1 -> 2016 | E8: ="*"&1/20/$J$1 -> *0.0620343872322709 | G8: SHAPE | H8: 15 | I8: =SHAPES!A11 -> 4 | J8: =SHAPES!B11 -> 0.96239644 | S8: Trd_car_gsl_00 | T8: 19114.108 | U8: 573.42324
B9: PASTI | C9: Trd[_]* | D9: =D8-1 -> 2015 | E9: ="*"&1/20/$J$1 -> *0.0620343872322709 | G9: SHAPE | H9: 15 | I9: =SHAPES!A12 -> 5 | J9: =SHAPES!B12 -> 0.95334895 | S9: Trd_hdt_dsl_04 | T9: 79927.754 | U9: 2397.8326 | V9: 79927.754 | W9: 2397.8326 | X9: 79927.754 | Y9: 2397.8326 | Z9: 79927.754 | AA9: 2397.8326
B10: PASTI | C10: Trd[_]* | D10: =D9-1 -> 2014 | E10: ="*"&1/20/$J$1 -> *0.0620343872322709 | G10: SHAPE | H10: 15 | I10: =SHAPES!A13 -> 6 | J10: =SHAPES!B13 -> 0.94694722 | S10: Trd_lcv_gsl_00 | T10: 17407.979 | U10: 522.23936
B11: PASTI | C11: Trd[_]* | D11: =D10-1 -> 2013 | E11: ="*"&1/20/$J$1 -> *0.0620343872322709 | G11: SHAPE | H11: 15 | I11: =SHAPES!A14 -> 7 | J11: =SHAPES!B14 -> 0.94694722
B12: PASTI | C12: Trd[_]* | D12: =D11-1 -> 2012 | E12: ="*"&1/20/$J$1 -> *0.0620343872322709 | G12: SHAPE | H12: 15 | I12: =SHAPES!A15 -> 8 | J12: =SHAPES!B15 -> 0.92626111
B13: PASTI | C13: Trd[_]* | D13: =D12-1 -> 2011 | E13: ="*"&1/20/$J$1 -> *0.0620343872322709 | G13: SHAPE | H13: 15 | I13: =SHAPES!A16 -> 9 | J13: =SHAPES!B16 -> 0.89816276 | S13: ~TFM_INS-AT: curr=USD20
B14: PASTI | C14: Trd[_]* | D14: =D13-1 -> 2010 | E14: ="*"&1/20/$J$1 -> *0.0620343872322709 | G14: SHAPE | H14: 15 | I14: =SHAPES!A17 -> 10 | J14: =SHAPES!B17 -> 0.89816276 | S14: pset_set | T14: pset_co | U14: INVCOST | V14: FIXOM
B15: PASTI | C15: Trd[_]* | D15: =D14-1 -> 2009 | E15: ="*"&1/20/$J$1 -> *0.0620343872322709 | G15: SHAPE | H15: 15 | I15: =SHAPES!A18 -> 11 | J15: =SHAPES!B18 -> 0.84618938 | S15: DMD | T15: =LEFT(S5,6) -> Trd_2w | U15: =T5 -> 2548.4 | V15: =U5 -> 76.451999
B16: PASTI | C16: Trd[_]* | D16: =D15-1 -> 2008 | E16: ="*"&1/20/$J$1 -> *0.0620343872322709 | G16: SHAPE | H16: 15 | I16: =SHAPES!A19 -> 12 | J16: =SHAPES!B19 -> 0.83608997 | S16: DMD | T16: =LEFT(S6,6) -> Trd_3w | U16: =T6 -> 11100.695 | V16: =U6 -> 333.02086
B17: PASTI | C17: Trd[_]* | D17: =D16-1 -> 2007 | E17: ="*"&1/20/$J$1 -> *0.0620343872322709 | G17: SHAPE | H17: 15 | I17: =SHAPES!A20 -> 13 | J17: =SHAPES!B20 -> 0.78534775 | S17: DMD | T17: =LEFT(S7,7) -> Trd_bus | U17: =T7 -> 277035.55 | V17: =U7 -> 8311.0664
B18: PASTI | C18: Trd[_]* | D18: =D17-1 -> 2006 | E18: ="*"&1/20/$J$1 -> *0.0620343872322709 | G18: SHAPE | H18: 15 | I18: =SHAPES!A21 -> 14 | J18: =SHAPES!B21 -> 0.76515842 | S18: DMD | T18: =LEFT(S8,7) -> Trd_car | U18: =T8 -> 19114.108 | V18: =U8 -> 573.42324
B19: PASTI | C19: Trd[_]* | D19: =D18-1 -> 2005 | E19: ="*"&1/20/$J$1 -> *0.0620343872322709 | G19: SHAPE | H19: 15 | I19: =SHAPES!A22 -> 15 | J19: =SHAPES!B22 -> 0.7228882 | S19: DMD | T19: =LEFT(S9,7) -> Trd_hdt | U19: =T9 -> 79927.754 | V19: =U9 -> 2397.8326
B20: PASTI | C20: Trd[_]* | D20: =D19-1 -> 2004 | E20: ="*"&1/20/$J$1 -> *0.0620343872322709 | G20: SHAPE | H20: 15 | I20: =SHAPES!A23 -> 16 | J20: =SHAPES!B23 -> 0.66220665 | S20: DMD | T20: =LEFT(S10,7) -> Trd_lcv | U20: =T10 -> 17407.979 | V20: =U10 -> 522.23936
B21: PASTI | C21: Trd[_]* | D21: =D20-1 -> 2003 | E21: ="*"&1/20/$J$1 -> *0.0620343872322709 | G21: SHAPE | H21: 15 | I21: =SHAPES!A24 -> 17 | J21: =SHAPES!B24 -> 0.62309315 | T21: =LEFT(S11,6)
B22: PASTI | C22: Trd[_]* | D22: =D21-1 -> 2002 | E22: ="*"&1/20/$J$1 -> *0.0620343872322709 | G22: SHAPE | H22: 15 | I22: =SHAPES!A25 -> 18 | J22: =SHAPES!B25 -> 0.53759209
B23: PASTI | C23: Trd[_]* | D23: =D22-1 -> 2001 | E23: ="*"&1/20/$J$1 -> *0.0620343872322709 | G23: SHAPE | H23: 15 | I23: =SHAPES!A26 -> 19 | J23: =SHAPES!B26 -> 0.47418922
B24: PASTI | C24: Trd[_]* | D24: =D23-1 -> 2000 | E24: ="*"&1/20/$J$1 -> *0.0620343872322709 | G24: SHAPE | H24: 15 | I24: =SHAPES!A27 -> 20 | J24: =SHAPES!B27 -> 0.42209122
G25: SHAPE | H25: 15 | I25: =SHAPES!A28 -> 21 | J25: =SHAPES!B28 -> 0.34697102
G26: SHAPE | H26: 15 | I26: =SHAPES!A29 -> 22 | J26: =SHAPES!B29 -> 0.29306436
G27: SHAPE | H27: 15 | I27: =SHAPES!A30 -> 23 | J27: =SHAPES!B30 -> 0.23285804
G28: SHAPE | H28: 15 | I28: =SHAPES!A31 -> 24 | J28: =SHAPES!B31 -> 0.19094253
G29: SHAPE | H29: 15 | I29: =SHAPES!A32 -> 25 | J29: =SHAPES!B32 -> 0.1646531
G30: SHAPE | H30: 15 | I30: =SHAPES!A33 -> 26 | J30: =SHAPES!B33 -> 0.14886833
G31: SHAPE | H31: 15 | I31: =SHAPES!A34 -> 27 | J31: =SHAPES!B34 -> 0.11454491
G32: SHAPE | H32: 15 | I32: =SHAPES!A35 -> 28 | J32: =SHAPES!B35 -> 0.10305458
G33: SHAPE | H33: 15 | I33: =SHAPES!A36 -> 29 | J33: =SHAPES!B36 -> 0.0950979
G34: SHAPE | H34: 15 | I34: =SHAPES!A37 -> 30 | J34: =SHAPES!B37 -> 0.0950979
G35: SHAPE | H35: 15 | I35: =SHAPES!A38 -> 31 | J35: =SHAPES!B38 -> 0.079496509
G36: SHAPE | H36: 15 | I36: =SHAPES!A39 -> 32 | J36: =SHAPES!B39 -> 0.056842043
... G54: SHAPE | H54: 29 | I54: =SHAPES!A57 -> 50 | J54: =SHAPES!B57 -> 0

Sheet IND2
B3: ~TFM_INS
B4: attribute | C4: pset_set | D4: attrib_cond | E4: value | F4: pset_co | G4: limtype | H4: pset_pn
B5: *START | C5: DMD_IIS | D5: PASTI | E5: 2020 | H5: -IMstlbof_Conventional BOF,-IMstl_Electric Arc Furnace (EAF)
B6: *START | C6: DMD_IIS | E6: 2020 | F6: im_fesponge,im_stlmolten | H6: -IMstlbof_Conventional BOF,-IMstl_Electric Arc Furnace (EAF)
B7: LIFE | C7: DMD_IIS | E7: 25
B11: ~TFM_TOPINS
B12: pset_ci | C12: pset_co | D12: pset_pn | E12: commodity | F12: io
B13: INDNGA | C13: INDELC | D13: EA* | E13: INDBFG | F13: IN
A17: CALIBRATION | F17: Africa_north | G17: Africa_other | H17: Arg-Chi | I17: Asia_central | J17: Asia_east | K17: Asia_other | L17: Australia_NZ | M17: Brazil | N17: Canada | O17: China | P17: EU_north | Q17: EU_northeast | R17: EU_northwest | S17: EU_south | T17: EU_southeast | U17: EU_southwest | V17: Europe_other | W17: France | X17: Germany | Y17: India | Z17: LatAm_other | AA17: Mexico | AB17: MidEast_other | AC17: Nor-Ice | AD17: Russia | AE17: SaudiArabia | AF17: SouthAfrica | AG17: UK | AH17: USA
C18: cok coal/coke | F18: 1.0967323 | G18: 1.4767169 | H18: 1.0236472 | I18: 1.1332997 | J18: 1.4120485 | K18: 1.2509555 | L18: 1.6376253 | M18: 1.1311407 | N18: 1.3258611 | O18: 1.3396947 | P18: 1.4046526 | Q18: 1.3355551 | R18: 1.317089 | S18: 1.3803047 | T18: 1.3915961 | U18: 1.2773772 | V18: 1.5310173 | W18: 1.4036627 | X18: 1.3358333 | Y18: 1.3639818 | Z18: 1.3333636 | AA18: 1.3303397 | AB18: 1.2692213 | AD18: 1.5622758 | AF18: 1.9495183 | AG18: 1.3463368 | AH18: 1.5632099
C20: BF cok input | F20: 0.44133643 | G20: 0 | H20: 0.53868622 | I20: 0.71643091 | J20: 1.1482411 | K20: 0.36026727 | L20: 0.80470668 | M20: 0.68320858 | N20: 0.47499946 | O20: 0.84056472 | P20: 0.83111119 | Q20: 1.0061244 | R20: 1.0264271 | S20: 0.49952906 | T20: 0.75767814 | U20: 0.71347724 | V20: 1.0352143 | W20: 1.1056145 | X20: 1.1313942 | Y20: 1.6767105 | Z20: 0.2162925 | AA20: 0.72665174 | AB20: 1.1467008 | AC20: 6.199426 | AD20: 0.90332843 | AF20: 0 | AG20: 0.62120979 | AH20: 0.2415161
C22: Electricity | F22: 0.045098091 | G22: 0.11014977 | H22: 1.500539 | I22: 8.9244125 | J22: 1.4689585 | K22: 0.96540688 | L22: 1.5985905 | M22: 1.6680031 | N22: 1.0434674 | O22: 1.6785732 | P22: 2.2360232 | Q22: 1.2427716 | R22: 1.1007992 | S22: 0.97142057 | T22: 1.3123714 | U22: 1.2620447 | V22: 1.3677899 | W22: 1.6988729 | X22: 1.2590045 | Y22: 1.1423043 | Z22: 2.1026556 | AA22: 0.35112794 | AB22: 0.0097495255 | AC22: 9.9836658 | AD22: 1.6698328 | AE22: 0.53133439 | AF22: 4.3099811 | AG22: 0.78359341 | AH22: 0.8712262
A25: ~TFM_UPD: attribute=INPUT
A26: process | B26: commodity | C26: *MIN | D26: *MAX | E26: top_check | F26: =F17 -> Africa_north | G26: =G17 -> Africa_other | H26: =H17 -> Arg-Chi | I26: =I17 -> Asia_central | J26: =J17 -> Asia_east | K26: =K17 -> Asia_other | L26: =L17 -> Australia_NZ | M26: =M17 -> Brazil | ... AH26: =AH17 -> USA
A27: IMstlbof_Coke Ovens | B27: im_cokcoal | E27: IN | F27: =IF(F18="","",F18) -> 1.0967323 | G27: =IF(G18="","",G18) -> 1.4767169 | H27: =IF(H18="","",H18) -> 1.0236472 | I27: =IF(I18="","",I18) -> 1.1332997 | J27: =IF(J18="","",J18) -> 1.4120485 | K27: =IF(K18="","",K18) -> 1.2509555 | L27: =IF(L18="","",L18) -> 1.6376253 | M27: =IF(M18="","",M18) -> 1.1311407 | ... AH27: =IF(AH18="","",AH18) -> 1.5632099
A28: IMstlbof_Modern BF* | B28: im_coke,GASBFG | C28: 0.8 | D28: 1.5 | E28: IN | F28: ="*"&MAX(MIN($D$28,F20),$C$28) -> *0.8 | G28: ="*"&MAX(MIN($D$28,G20),$C$28) -> *0.8 | H28: ="*"&MAX(MIN($D$28,H20),$C$28) -> *0.8 | I28: ="*"&MAX(MIN($D$28,I20),$C$28) -> *0.8 | J28: ="*"&MAX(MIN($D$28,J20),$C$28) -> *1.14824107835245 | K28: ="*"&MAX(MIN($D$28,K20),$C$28) -> *0.8 | L28: ="*"&MAX(MIN($D$28,L20),$C$28) -> *0.8047066816 | M28: ="*"&MAX(MIN($D$28,M20),$C$28) -> *0.8 | ... AH28: ="*"&MAX(MIN($D$28,AH20),$C$28) -> *0.8
A29: Imstl*,Imfe* | B29: INDELC | C29: 0.8 | D29: 1.5 | E29: IN | F29: ="*"&MAX(MIN($D$29,F22),$C$29) -> *0.8 | G29: ="*"&MAX(MIN($D$29,G22),$C$29) -> *0.8 | H29: ="*"&MAX(MIN($D$29,H22),$C$29) -> *1.5 | I29: ="*"&MAX(MIN($D$29,I22),$C$29) -> *1.5 | J29: ="*"&MAX(MIN($D$29,J22),$C$29) -> *1.46895850233908 | K29: ="*"&MAX(MIN($D$29,K22),$C$29) -> *0.965406877764689 | L29: ="*"&MAX(MIN($D$29,L22),$C$29) -> *1.5 | M29: ="*"&MAX(MIN($D$29,M22),$C$29) -> *1.5 | ... AH29: ="*"&MAX(MIN($D$29,AH22),$C$29) -> *0.871226195357065
B32: ~TFM_INS
B33: attribute | C33: pset_pn | D33: other_indexes | E33: commodity | F33: value
B34: FLO_EMIS | C34: * with CCS | D34: INDCO2Nc,INDCO2Ng | E34: CO2Captured_ind | F34: 0.9
B38: ~TFM_INS
B39: attribute | C39: value | D39: pset_ci | E39: pset_co | F39: cset_cn | G39: curr
B40: START | C40: 2110 | D40: ind_coal | E40: im_fesponge
B41: FLO_COST | C41: 100 | D41: im_feore | F41: =D41 -> im_feore | G41: USD20

Sheet SHAPES
B4: k | C4: 0.192 | D4: 0.195 | E4: 0.131 | F4: 0.13
B5: a | C5: 1200 | D5: 900 | E5: 21 | F5: 52
B7: Data (18.5) | C7: =SUM(C8:C32) -> 10.023425 | D7: =SUM(D8:D32) -> 11.950326 | E7: =SUM(E8:E32) -> 19.958953 | F7: =SUM(F8:F32) -> 15.036068 | G7: Mean AGE (TLIFE = 25)
A8: 1 | B8: 0.98 | C8: =(1/(1+EXP(-(50-$A8)*C$4)))^C$5 -> 0.90621939 | D8: =(1/(1+EXP(-(50-$A8)*D$4)))^D$5 -> 0.93823083 | E8: =(1/(1+EXP(-(50-$A8)*E$4)))^E$5 -> 0.96637036 | F8: =(1/(1+EXP(-(50-$A8)*F$4)))^F$5 -> 0.91488569
A9: 2 | B9: 0.97062258 | C9: =(1/(1+EXP(-(50-$A9)*C$4)))^C$5 -> 0.88752656 | D9: =(1/(1+EXP(-(50-$A9)*D$4)))^D$5 -> 0.92543928 | E9: =(1/(1+EXP(-(50-$A9)*E$4)))^E$5 -> 0.96175868 | F9: =(1/(1+EXP(-(50-$A9)*F$4)))^F$5 -> 0.90366753
A10: 3 | B10: 0.96239644 | C10: =(1/(1+EXP(-(50-$A10)*C$4)))^C$5 -> 0.86539332 | D10: =(1/(1+EXP(-(50-$A10)*D$4)))^D$5 -> 0.91012836 | E10: =(1/(1+EXP(-(50-$A10)*E$4)))^E$5 -> 0.95652962 | F10: =(1/(1+EXP(-(50-$A10)*F$4)))^F$5 -> 0.89106257
A11: 4 | B11: 0.96239644 | C11: =(1/(1+EXP(-(50-$A11)*C$4)))^C$5 -> 0.839314 | D11: =(1/(1+EXP(-(50-$A11)*D$4)))^D$5 -> 0.8918618 | E11: =(1/(1+EXP(-(50-$A11)*E$4)))^E$5 -> 0.95060496 | F11: =(1/(1+EXP(-(50-$A11)*F$4)))^F$5 -> 0.87692573
A12: 5 | B12: 0.95334895 | C12: =(1/(1+EXP(-(50-$A12)*C$4)))^C$5 -> 0.80876611 | D12: =(1/(1+EXP(-(50-$A12)*D$4)))^D$5 -> 0.87015557 | E12: =(1/(1+EXP(-(50-$A12)*E$4)))^E$5 -> 0.94389792 | F12: =(1/(1+EXP(-(50-$A12)*F$4)))^F$5 -> 0.8611044
A13: 6 | B13: 0.94694722 | C13: =(1/(1+EXP(-(50-$A13)*C$4)))^C$5 -> 0.77323922 | D13: =(1/(1+EXP(-(50-$A13)*D$4)))^D$5 -> 0.84448643 | E13: =(1/(1+EXP(-(50-$A13)*E$4)))^E$5 -> 0.93631252 | F13: =(1/(1+EXP(-(50-$A13)*F$4)))^F$5 -> 0.84344051
A14: 7 | B14: 0.94694722 | C14: =(1/(1+EXP(-(50-$A14)*C$4)))^C$5 -> 0.73227849 | D14: =(1/(1+EXP(-(50-$A14)*D$4)))^D$5 -> 0.81430871 | E14: =(1/(1+EXP(-(50-$A14)*E$4)))^E$5 -> 0.92774325 | F14: =(1/(1+EXP(-(50-$A14)*F$4)))^F$5 -> 0.82377352
A15: 8 | B15: 0.92626111 | C15: =(1/(1+EXP(-(50-$A15)*C$4)))^C$5 -> 0.68554622 | D15: =(1/(1+EXP(-(50-$A15)*D$4)))^D$5 -> 0.77908286 | E15: =(1/(1+EXP(-(50-$A15)*E$4)))^E$5 -> 0.91807469 | F15: =(1/(1+EXP(-(50-$A15)*F$4)))^F$5 -> 0.80194455
A16: 9 | B16: 0.89816276 | C16: =(1/(1+EXP(-(50-$A16)*C$4)))^C$5 -> 0.63290302 | D16: =(1/(1+EXP(-(50-$A16)*D$4)))^D$5 -> 0.73831952 | E16: =(1/(1+EXP(-(50-$A16)*E$4)))^E$5 -> 0.90718146 | F16: =(1/(1+EXP(-(50-$A16)*F$4)))^F$5 -> 0.77780182
A17: 10 | B17: 0.89816276 | C17: =(1/(1+EXP(-(50-$A17)*C$4)))^C$5 -> 0.57450765 | D17: =(1/(1+EXP(-(50-$A17)*D$4)))^D$5 -> 0.69164258 | E17: =(1/(1+EXP(-(50-$A17)*E$4)))^E$5 -> 0.89492849 | F17: =(1/(1+EXP(-(50-$A17)*F$4)))^F$5 -> 0.75120777
A18: 11 | B18: 0.84618938 | C18: =(1/(1+EXP(-(50-$A18)*C$4)))^C$5 -> 0.51092846 | D18: =(1/(1+EXP(-(50-$A18)*D$4)))^D$5 -> 0.6388738 | E18: =(1/(1+EXP(-(50-$A18)*E$4)))^E$5 -> 0.88117171 | F18: =(1/(1+EXP(-(50-$A18)*F$4)))^F$5 -> 0.7220478
A19: 12 | B19: 0.83608997 | C19: =(1/(1+EXP(-(50-$A19)*C$4)))^C$5 -> 0.44325071 | D19: =(1/(1+EXP(-(50-$A19)*D$4)))^D$5 -> 0.58013822 | E19: =(1/(1+EXP(-(50-$A19)*E$4)))^E$5 -> 0.86575922 | F19: =(1/(1+EXP(-(50-$A19)*F$4)))^F$5 -> 0.69024095
... A36: 29 | B36: 0.0950979 | C36: =(1/(1+EXP(-(50-$A36)*C$4)))^C$5 -> 6.8610925e-10 | D36: =(1/(1+EXP(-(50-$A36)*D$4)))^D$5 -> 3.495202e-07 | E36: =(1/(1+EXP(-(50-$A36)*E$4)))^E$5 -> 0.27251595 | F36: =(1/(1+EXP(-(50-$A36)*F$4)))^F$5 -> 0.037425778
A37: 30 | B37: 0.0950979 | C37: =(1/(1+EXP(-(50-$A37)*C$4)))^C$5 -> 8.2645525e-12 | D37: =(1/(1+EXP(-(50-$A37)*D$4)))^D$5 -> 1.469453e-08 | E37: =(1/(1+EXP(-(50-$A37)*E$4)))^E$5 -> 0.22860283 | F37: =(1/(1+EXP(-(50-$A37)*F$4)))^F$5 -> 0.024100469 | I37: 20 | J37: trucks and buses
A38: 31 | B38: 0.079496509 | C38: =(1/(1+EXP(-(50-$A38)*C$4)))^C$5 -> 3.9924823e-14 | D38: =(1/(1+EXP(-(50-$A38)*D$4)))^D$5 -> 3.1695725e-10 | E38: =(1/(1+EXP(-(50-$A38)*E$4)))^E$5 -> 0.1874399 | F38: =(1/(1+EXP(-(50-$A38)*F$4)))^F$5 -> 0.014665472 | I38: 15 | J38: lcv, pas and mot
A39: 32 | B39: 0.056842043 | C39: =(1/(1+EXP(-(50-$A39)*C$4)))^C$5 -> 6.4381875e-17 | D39: =(1/(1+EXP(-(50-$A39)*D$4)))^D$5 -> 3.0592763e-12 | E39: =(1/(1+EXP(-(50-$A39)*E$4)))^E$5 -> 0.14981613 | F39: =(1/(1+EXP(-(50-$A39)*F$4)))^F$5 -> 0.0083772435
A40: 33 | B40: 0.054254089 | C40: =(1/(1+EXP(-(50-$A40)*C$4)))^C$5 -> 2.7869281e-20 | D40: =(1/(1+EXP(-(50-$A40)*D$4)))^D$5 -> 1.1225602e-14 | E40: =(1/(1+EXP(-(50-$A40)*E$4)))^E$5 -> 0.11638244 | F40: =(1/(1+EXP(-(50-$A40)*F$4)))^F$5 -> 0.0044596043
A41: 34 | B41: 0.054254089 | C41: =(1/(1+EXP(-(50-$A41)*C$4)))^C$5 -> 2.5025419e-24 | D41: =(1/(1+EXP(-(50-$A41)*D$4)))^D$5 -> 1.2903664e-17 | E41: =(1/(1+EXP(-(50-$A41)*E$4)))^E$5 -> 0.087589823 | F41: =(1/(1+EXP(-(50-$A41)*F$4)))^F$5 -> 0.0021951783
A42: 35 | B42: 0.054254089 | C42: =(1/(1+EXP(-(50-$A42)*C$4)))^C$5 -> 3.4418721e-29 | D42: =(1/(1+EXP(-(50-$A42)*D$4)))^D$5 -> 3.6967114e-21 | E42: =(1/(1+EXP(-(50-$A42)*E$4)))^E$5 -> 0.063643065 | F42: =(1/(1+EXP(-(50-$A42)*F$4)))^F$5 -> 0.00099070286
A43: 36 | B43: 0.045375223 | C43: =(1/(1+EXP(-(50-$A43)*C$4)))^C$5 -> 5.0848812e-35 | D43: =(1/(1+EXP(-(50-$A43)*D$4)))^D$5 -> 2.0178083e-25 | E43: =(1/(1+EXP(-(50-$A43)*E$4)))^E$5 -> 0.044480083 | F43: =(1/(1+EXP(-(50-$A43)*F$4)))^F$5 -> 0.00040623831
A44: 37 | B44: 0.033017316 | C44: =(1/(1+EXP(-(50-$A44)*C$4)))^C$5 -> 5.3446696e-42 | D44: =(1/(1+EXP(-(50-$A44)*D$4)))^D$5 -> 1.5342783e-30 | E44: =(1/(1+EXP(-(50-$A44)*E$4)))^E$5 -> 0.02978389 | F44: =(1/(1+EXP(-(50-$A44)*F$4)))^F$5 -> 0.00014990095
A45: 38 | B45: 0.033017316 | C45: =(1/(1+EXP(-(50-$A45)*C$4)))^C$5 -> 2.4875372e-50 | D45: =(1/(1+EXP(-(50-$A45)*D$4)))^D$5 -> 1.1315495e-36 | E45: =(1/(1+EXP(-(50-$A45)*E$4)))^E$5 -> 0.019027948 | F45: =(1/(1+EXP(-(50-$A45)*F$4)))^F$5 -> 4.9274391e-05
A46: 39 | B46: 0.031841484 | C46: =(1/(1+EXP(-(50-$A46)*C$4)))^C$5 -> 2.9870927e-60 | D46: =(1/(1+EXP(-(50-$A46)*D$4)))^D$5 -> 5.3497949e-44 | E46: =(1/(1+EXP(-(50-$A46)*E$4)))^E$5 -> 0.011548223 | F46: =(1/(1+EXP(-(50-$A46)*F$4)))^F$5 -> 1.4277824e-05
A47: 40 | B47: 0.028946804 | C47: =(1/(1+EXP(-(50-$A47)*C$4)))^C$5 -> 5.0409298e-72 | D47: =(1/(1+EXP(-(50-$A47)*D$4)))^D$5 -> 1.0155774e-52 | E47: =(1/(1+EXP(-(50-$A47)*E$4)))^E$5 -> 0.0066284834 | F47: =(1/(1+EXP(-(50-$A47)*F$4)))^F$5 -> 3.6077018e-06
A48: 41 | B48: 0.026052123 | C48: =(1/(1+EXP(-(50-$A48)*C$4)))^C$5 -> 6.0986906e-86 | D48: =(1/(1+EXP(-(50-$A48)*D$4)))^D$5 -> 4.5993756e-63 | E48: =(1/(1+EXP(-(50-$A48)*E$4)))^E$5 -> 0.0035819812 | F48: =(1/(1+EXP(-(50-$A48)*F$4)))^F$5 -> 7.8626284e-07
A49: 42 | B49: 0.023157443 | C49: =(1/(1+EXP(-(50-$A49)*C$4)))^C$5 -> 2.5432298e-102 | D49: =(1/(1+EXP(-(50-$A49)*D$4)))^D$5 -> 2.8132884e-75 | E49: =(1/(1+EXP(-(50-$A49)*E$4)))^E$5 -> 0.0018141766 | F49: =(1/(1+EXP(-(50-$A49)*F$4)))^F$5 -> 1.4619302e-07
A50: 43 | B50: 0.020262763 | C50: =(1/(1+EXP(-(50-$A50)*C$4)))^C$5 -> 1.6765003e-121 | D50: =(1/(1+EXP(-(50-$A50)*D$4)))^D$5 -> 1.2650411e-89 | E50: =(1/(1+EXP(-(50-$A50)*E$4)))^E$5 -> 0.00085735161 | F50: =(1/(1+EXP(-(50-$A50)*F$4)))^F$5 -> 2.2943555e-08
... A57: 50 | B57: 0 | C57: =(1/(1+EXP(-(50-$A57)*C$4)))^C$5 -> 0 | D57: =(1/(1+EXP(-(50-$A57)*D$4)))^D$5 -> 1.1830522e-271 | E57: =(1/(1+EXP(-(50-$A57)*E$4)))^E$5 -> 4.7683716e-07 | F57: =(1/(1+EXP(-(50-$A57)*F$4)))^F$5 -> 2.220446e-16

Sheet Elec-CHP EFF calibration
J1: tech | K1: region | L1: CHP | M1: Elec | R1: 7 | S1: 8 | X1: DeACT TFM_UPD: attribute=EFF
B2: Model | C2: ActiveReg | D2: Fuel | E2: AutoCHP | F2: AutoElec | G2: MainCHP | H2: MainELEC | J2: Bio | K2: Africa_other | L2: 0.27 | M2: 0.2698327 | R2: =G2 -> MainCHP | S2: =H2 -> MainELEC | X2: process | Y2: pset_ci | Z2: Africa_north | AA2: Africa_other | AB2: Arg-Chi | AC2: Asia_central | AD2: Asia_east | AE2: Asia_other | AF2: Australia_NZ | AG2: Brazil | AH2: Canada | AI2: China | AJ2: EU_north | AK2: EU_northeast | AL2: EU_northwest | AM2: EU_south | AN2: EU_southeast | AO2: EU_southwest | AP2: Europe_other | AQ2: France | AR2: Germany | AS2: India | AT2: LatAm_other | AU2: Mexico | AV2: MidEast_other | AW2: Nor-Ice | AX2: Russia | AY2: SaudiArabia | AZ2: SouthAfrica | BA2: UK | BB2: USA
A3: =C3&D3 -> Africa_otherBIO | B3: IEA | C3: Africa_other | D3: BIO | E3: 0.13377499 | F3: 0.17378009 | G3: 0 | H3: 0.20510296 | J3: Bio | K3: Arg-Chi | L3: 0.315 | M3: 0.32286196 | Q3: =K3&LEFT(J3,3) -> Arg-ChiBio | R3: =IFERROR(IF(L3>0,VLOOKUP($Q3,$A$3:$H$102,R$1,FALSE)/L3,""),"") -> 0.05230291 | S3: =IFERROR(IF(M3>0,VLOOKUP($Q3,$A$3:$H$102,S$1,FALSE)/M3,""),"") -> 0.011150276 | U3: 3 | V3: COA | X3: EP*,EA*,-*CHP | Y3: ="*"&V3&"*" -> *COA* | Z3: =IFERROR(IF(VLOOKUP(Z$2&$V3,$Q$3:$S$999,$U3,FALSE)>1,"*"&ROUND(VLOOKUP(Z$2&$V3,$Q$3:$S$999,$U3,FALSE),4),""),"") -> *1.0676 | AA3: =IFERROR(IF(VLOOKUP(AA$2&$V3,$Q$3:$S$999,$U3,FALSE)>1,"*"&ROUND(VLOOKUP(AA$2&$V3,$Q$3:$S$999,$U3,FALSE),4),""),"") | AB3: =IFERROR(IF(VLOOKUP(AB$2&$V3,$Q$3:$S$999,$U3,FALSE)>1,"*"&ROUND(VLOOKUP(AB$2&$V3,$Q$3:$S$999,$U3,FALSE),4),""),"") -> *1.1733 | AC3: =IFERROR(IF(VLOOKUP(AC$2&$V3,$Q$3:$S$999,$U3,FALSE)>1,"*"&ROUND(VLOOKUP(AC$2&$V3,$Q$3:$S$999,$U3,FALSE),4),""),"") | AD3: =IFERROR(IF(VLOOKUP(AD$2&$V3,$Q$3:$S$999,$U3,FALSE)>1,"*"&ROUND(VLOOKUP(AD$2&$V3,$Q$3:$S$999,$U3,FALSE),4),""),"") -> *1.1732 | AE3: =IFERROR(IF(VLOOKUP(AE$2&$V3,$Q$3:$S$999,$U3,FALSE)>1,"*"&ROUND(VLOOKUP(AE$2&$V3,$Q$3:$S$999,$U3,FALSE),4),""),"") -> *1.1294 | AF3: =IFERROR(IF(VLOOKUP(AF$2&$V3,$Q$3:$S$999,$U3,FALSE)>1,"*"&ROUND(VLOOKUP(AF$2&$V3,$Q$3:$S$999,$U3,FALSE),4),""),"") -> *1.0352 | AG3: =IFERROR(IF(VLOOKUP(AG$2&$V3,$Q$3:$S$999,$U3,FALSE)>1,"*"&ROUND(VLOOKUP(AG$2&$V3,$Q$3:$S$999,$U3,FALSE),4),""),"") -> *1.1646 | ... BB3: =IFERROR(IF(VLOOKUP(BB$2&$V3,$Q$3:$S$999,$U3,FALSE)>1,"*"&ROUND(VLOOKUP(BB$2&$V3,$Q$3:$S$999,$U3,FALSE),4),""),"") -> *1.0743
A4: =C4&D4 -> Arg-ChiBIO | B4: IEA | C4: Arg-Chi | D4: BIO | E4: 0.13989046 | F4: 0.16810224 | G4: 0.016475417 | H4: 0.0036 | J4: Bio | K4: Asia_central | L4: 0.27 | M4: 0.328 | Q4: =K4&LEFT(J4,3) -> Asia_centralBio | R4: =IFERROR(IF(L4>0,VLOOKUP($Q4,$A$3:$H$102,R$1,FALSE)/L4,""),"") -> 0 | S4: =IFERROR(IF(M4>0,VLOOKUP($Q4,$A$3:$H$102,S$1,FALSE)/M4,""),"") -> 0 | U4: 2 | V4: COA | X4: EP*CHP, EA*CHP | Y4: ="*"&V4&"*" -> *COA* | Z4: =IFERROR(IF(VLOOKUP(Z$2&$V4,$Q$3:$S$999,$U4,FALSE)>1,"*"&ROUND(VLOOKUP(Z$2&$V4,$Q$3:$S$999,$U4,FALSE),4),""),"") | AA4: =IFERROR(IF(VLOOKUP(AA$2&$V4,$Q$3:$S$999,$U4,FALSE)>1,"*"&ROUND(VLOOKUP(AA$2&$V4,$Q$3:$S$999,$U4,FALSE),4),""),"") | AB4: =IFERROR(IF(VLOOKUP(AB$2&$V4,$Q$3:$S$999,$U4,FALSE)>1,"*"&ROUND(VLOOKUP(AB$2&$V4,$Q$3:$S$999,$U4,FALSE),4),""),"") | AC4: =IFERROR(IF(VLOOKUP(AC$2&$V4,$Q$3:$S$999,$U4,FALSE)>1,"*"&ROUND(VLOOKUP(AC$2&$V4,$Q$3:$S$999,$U4,FALSE),4),""),"") | AD4: =IFERROR(IF(VLOOKUP(AD$2&$V4,$Q$3:$S$999,$U4,FALSE)>1,"*"&ROUND(VLOOKUP(AD$2&$V4,$Q$3:$S$999,$U4,FALSE),4),""),"") | AE4: =IFERROR(IF(VLOOKUP(AE$2&$V4,$Q$3:$S$999,$U4,FALSE)>1,"*"&ROUND(VLOOKUP(AE$2&$V4,$Q$3:$S$999,$U4,FALSE),4),""),"") | AF4: =IFERROR(IF(VLOOKUP(AF$2&$V4,$Q$3:$S$999,$U4,FALSE)>1,"*"&ROUND(VLOOKUP(AF$2&$V4,$Q$3:$S$999,$U4,FALSE),4),""),"") -> *1.0976 | AG4: =IFERROR(IF(VLOOKUP(AG$2&$V4,$Q$3:$S$999,$U4,FALSE)>1,"*"&ROUND(VLOOKUP(AG$2&$V4,$Q$3:$S$999,$U4,FALSE),4),""),"") | ... BB4: =IFERROR(IF(VLOOKUP(BB$2&$V4,$Q$3:$S$999,$U4,FALSE)>1,"*"&ROUND(VLOOKUP(BB$2&$V4,$Q$3:$S$999,$U4,FALSE),4),""),"")
A5: =C5&D5 -> Asia_centralBIO | B5: IEA | C5: Asia_central | D5: BIO | E5: 0 | F5: 0.2180027 | G5: 0 | H5: 0 | J5: Bio | K5: Asia_east | L5: 0.33477045 | M5: 0.32924771 | Q5: =K5&LEFT(J5,3) -> Asia_eastBio | R5: =IFERROR(IF(L5>0,VLOOKUP($Q5,$A$3:$H$102,R$1,FALSE)/L5,""),"") -> 0.9244341 | S5: =IFERROR(IF(M5>0,VLOOKUP($Q5,$A$3:$H$102,S$1,FALSE)/M5,""),"") -> 1.1122927 | X5: \I:
A6: =C6&D6 -> Asia_eastBIO | B6: IEA | C6: Asia_east | D6: BIO | E6: 0.13460134 | F6: 0.41807299 | G6: 0.30947323 | H6: 0.36621984 | J6: Bio | K6: Asia_other | L6: 0.33594976 | M6: 0.32652925 | Q6: =K6&LEFT(J6,3) -> Asia_otherBio | R6: =IFERROR(IF(L6>0,VLOOKUP($Q6,$A$3:$H$102,R$1,FALSE)/L6,""),"") -> 0.76573452 | S6: =IFERROR(IF(M6>0,VLOOKUP($Q6,$A$3:$H$102,S$1,FALSE)/M6,""),"") -> 0.65968059 | U6: =U3 -> 3 | V6: GAS | X6: EP*,EA*,-*CHP | Y6: *NGA* | Z6: =IFERROR(IF(VLOOKUP(Z$2&$V6,$Q$3:$S$999,$U6,FALSE)>1,"*"&ROUND(VLOOKUP(Z$2&$V6,$Q$3:$S$999,$U6,FALSE),4),""),"") -> *1.141 | AA6: =IFERROR(IF(VLOOKUP(AA$2&$V6,$Q$3:$S$999,$U6,FALSE)>1,"*"&ROUND(VLOOKUP(AA$2&$V6,$Q$3:$S$999,$U6,FALSE),4),""),"") -> *1.129 | AB6: =IFERROR(IF(VLOOKUP(AB$2&$V6,$Q$3:$S$999,$U6,FALSE)>1,"*"&ROUND(VLOOKUP(AB$2&$V6,$Q$3:$S$999,$U6,FALSE),4),""),"") -> *1.1492 | AC6: =IFERROR(IF(VLOOKUP(AC$2&$V6,$Q$3:$S$999,$U6,FALSE)>1,"*"&ROUND(VLOOKUP(AC$2&$V6,$Q$3:$S$999,$U6,FALSE),4),""),"") -> *1.1616 | AD6: =IFERROR(IF(VLOOKUP(AD$2&$V6,$Q$3:$S$999,$U6,FALSE)>1,"*"&ROUND(VLOOKUP(AD$2&$V6,$Q$3:$S$999,$U6,FALSE),4),""),"") -> *1.0797 | AE6: =IFERROR(IF(VLOOKUP(AE$2&$V6,$Q$3:$S$999,$U6,FALSE)>1,"*"&ROUND(VLOOKUP(AE$2&$V6,$Q$3:$S$999,$U6,FALSE),4),""),"") | AF6: =IFERROR(IF(VLOOKUP(AF$2&$V6,$Q$3:$S$999,$U6,FALSE)>1,"*"&ROUND(VLOOKUP(AF$2&$V6,$Q$3:$S$999,$U6,FALSE),4),""),"") -> *1.0683 | AG6: =IFERROR(IF(VLOOKUP(AG$2&$V6,$Q$3:$S$999,$U6,FALSE)>1,"*"&ROUND(VLOOKUP(AG$2&$V6,$Q$3:$S$999,$U6,FALSE),4),""),"") -> *1.0389 | ... BB6: =IFERROR(IF(VLOOKUP(BB$2&$V6,$Q$3:$S$999,$U6,FALSE)>1,"*"&ROUND(VLOOKUP(BB$2&$V6,$Q$3:$S$999,$U6,FALSE),4),""),"") -> *1.1939
A7: =C7&D7 -> Asia_otherBIO | B7: IEA | C7: Asia_other | D7: BIO | E7: 0.28475525 | F7: 0.16983262 | G7: 0.25724833 | H7: 0.21540501 | J7: Bio | K7: Australia_NZ | L7: 0.32506351 | M7: 0.2681163 | Q7: =K7&LEFT(J7,3) -> Australia_NZBio | R7: =IFERROR(IF(L7>0,VLOOKUP($Q7,$A$3:$H$102,R$1,FALSE)/L7,""),"") -> 0 | S7: =IFERROR(IF(M7>0,VLOOKUP($Q7,$A$3:$H$102,S$1,FALSE)/M7,""),"") -> 1.1591607 | U7: =U4 -> 2 | V7: GAS | X7: EP*CHP, EA*CHP | Y7: *NGA* | Z7: =IFERROR(IF(VLOOKUP(Z$2&$V7,$Q$3:$S$999,$U7,FALSE)>1,"*"&ROUND(VLOOKUP(Z$2&$V7,$Q$3:$S$999,$U7,FALSE),4),""),"") | AA7: =IFERROR(IF(VLOOKUP(AA$2&$V7,$Q$3:$S$999,$U7,FALSE)>1,"*"&ROUND(VLOOKUP(AA$2&$V7,$Q$3:$S$999,$U7,FALSE),4),""),"") | AB7: =IFERROR(IF(VLOOKUP(AB$2&$V7,$Q$3:$S$999,$U7,FALSE)>1,"*"&ROUND(VLOOKUP(AB$2&$V7,$Q$3:$S$999,$U7,FALSE),4),""),"") | AC7: =IFERROR(IF(VLOOKUP(AC$2&$V7,$Q$3:$S$999,$U7,FALSE)>1,"*"&ROUND(VLOOKUP(AC$2&$V7,$Q$3:$S$999,$U7,FALSE),4),""),"") | AD7: =IFERROR(IF(VLOOKUP(AD$2&$V7,$Q$3:$S$999,$U7,FALSE)>1,"*"&ROUND(VLOOKUP(AD$2&$V7,$Q$3:$S$999,$U7,FALSE),4),""),"") | AE7: =IFERROR(IF(VLOOKUP(AE$2&$V7,$Q$3:$S$999,$U7,FALSE)>1,"*"&ROUND(VLOOKUP(AE$2&$V7,$Q$3:$S$999,$U7,FALSE),4),""),"") -> *17.3399 | AF7: =IFERROR(IF(VLOOKUP(AF$2&$V7,$Q$3:$S$999,$U7,FALSE)>1,"*"&ROUND(VLOOKUP(AF$2&$V7,$Q$3:$S$999,$U7,FALSE),4),""),"") -> *1.1579 | AG7: =IFERROR(IF(VLOOKUP(AG$2&$V7,$Q$3:$S$999,$U7,FALSE)>1,"*"&ROUND(VLOOKUP(AG$2&$V7,$Q$3:$S$999,$U7,FALSE),4),""),"") | ... BB7: =IFERROR(IF(VLOOKUP(BB$2&$V7,$Q$3:$S$999,$U7,FALSE)>1,"*"&ROUND(VLOOKUP(BB$2&$V7,$Q$3:$S$999,$U7,FALSE),4),""),"") -> *1.0491
A8: =C8&D8 -> Australia_NZBIO | B8: IEA | C8: Australia_NZ | D8: BIO | E8: 0.21853879 | F8: 0.3319328 | G8: 0 | H8: 0.31078988 | J8: Bio | K8: Brazil | L8: 0.333 | M8: 0.32901715 | Q8: =K8&LEFT(J8,3) -> BrazilBio | R8: =IFERROR(IF(L8>0,VLOOKUP($Q8,$A$3:$H$102,R$1,FALSE)/L8,""),"") -> 0 | S8: =IFERROR(IF(M8>0,VLOOKUP($Q8,$A$3:$H$102,S$1,FALSE)/M8,""),"") -> 1.1837653 | X8: \I:
A9: =C9&D9 -> BrazilBIO | B9: IEA | C9: Brazil | D9: BIO | E9: 0.48770425 | F9: 0.3743067 | G9: 0 | H9: 0.38947909 | J9: Bio | K9: Canada | L9: 0.32341071 | M9: 0.33385184 | Q9: =K9&LEFT(J9,3) -> CanadaBio | R9: =IFERROR(IF(L9>0,VLOOKUP($Q9,$A$3:$H$102,R$1,FALSE)/L9,""),"") -> 0.98833242 | S9: =IFERROR(IF(M9>0,VLOOKUP($Q9,$A$3:$H$102,S$1,FALSE)/M9,""),"") -> 1.067711 | U9: 3 | V9: BIO | X9: EP*,EA*,-*CHP | Y9: ="*"&V9&"*" -> *BIO* | Z9: =IFERROR(IF(VLOOKUP(Z$2&$V9,$Q$3:$S$999,$U9,FALSE)>1,"*"&ROUND(VLOOKUP(Z$2&$V9,$Q$3:$S$999,$U9,FALSE),4),""),"") | AA9: =IFERROR(IF(VLOOKUP(AA$2&$V9,$Q$3:$S$999,$U9,FALSE)>1,"*"&ROUND(VLOOKUP(AA$2&$V9,$Q$3:$S$999,$U9,FALSE),4),""),"") | AB9: =IFERROR(IF(VLOOKUP(AB$2&$V9,$Q$3:$S$999,$U9,FALSE)>1,"*"&ROUND(VLOOKUP(AB$2&$V9,$Q$3:$S$999,$U9,FALSE),4),""),"") | AC9: =IFERROR(IF(VLOOKUP(AC$2&$V9,$Q$3:$S$999,$U9,FALSE)>1,"*"&ROUND(VLOOKUP(AC$2&$V9,$Q$3:$S$999,$U9,FALSE),4),""),"") | AD9: =IFERROR(IF(VLOOKUP(AD$2&$V9,$Q$3:$S$999,$U9,FALSE)>1,"*"&ROUND(VLOOKUP(AD$2&$V9,$Q$3:$S$999,$U9,FALSE),4),""),"") -> *1.1123 | AE9: =IFERROR(IF(VLOOKUP(AE$2&$V9,$Q$3:$S$999,$U9,FALSE)>1,"*"&ROUND(VLOOKUP(AE$2&$V9,$Q$3:$S$999,$U9,FALSE),4),""),"") | AF9: =IFERROR(IF(VLOOKUP(AF$2&$V9,$Q$3:$S$999,$U9,FALSE)>1,"*"&ROUND(VLOOKUP(AF$2&$V9,$Q$3:$S$999,$U9,FALSE),4),""),"") -> *1.1592 | AG9: =IFERROR(IF(VLOOKUP(AG$2&$V9,$Q$3:$S$999,$U9,FALSE)>1,"*"&ROUND(VLOOKUP(AG$2&$V9,$Q$3:$S$999,$U9,FALSE),4),""),"") -> *1.1838 | ... BB9: =IFERROR(IF(VLOOKUP(BB$2&$V9,$Q$3:$S$999,$U9,FALSE)>1,"*"&ROUND(VLOOKUP(BB$2&$V9,$Q$3:$S$999,$U9,FALSE),4),""),"")
A10: =C10&D10 -> CanadaBIO | B10: IEA | C10: Canada | D10: BIO | E10: 0.31363628 | F10: 0.37455951 | G10: 0.31963729 | H10: 0.3564573 | J10: Bio | K10: EU_north | L10: 0.34209439 | M10: 0.32732752 | Q10: =K10&LEFT(J10,3) -> EU_northBio | R10: =IFERROR(IF(L10>0,VLOOKUP($Q10,$A$3:$H$102,R$1,FALSE)/L10,""),"") -> 0.61692158 | S10: =IFERROR(IF(M10>0,VLOOKUP($Q10,$A$3:$H$102,S$1,FALSE)/M10,""),"") -> 1.1815961 | U10: 2 | V10: BIO | X10: EP*CHP, EA*CHP | Y10: ="*"&V10&"*" -> *BIO* | Z10: =IFERROR(IF(VLOOKUP(Z$2&$V10,$Q$3:$S$999,$U10,FALSE)>1,"*"&ROUND(VLOOKUP(Z$2&$V10,$Q$3:$S$999,$U10,FALSE),4),""),"") | AA10: =IFERROR(IF(VLOOKUP(AA$2&$V10,$Q$3:$S$999,$U10,FALSE)>1,"*"&ROUND(VLOOKUP(AA$2&$V10,$Q$3:$S$999,$U10,FALSE),4),""),"") | AB10: =IFERROR(IF(VLOOKUP(AB$2&$V10,$Q$3:$S$999,$U10,FALSE)>1,"*"&ROUND(VLOOKUP(AB$2&$V10,$Q$3:$S$999,$U10,FALSE),4),""),"") | AC10: =IFERROR(IF(VLOOKUP(AC$2&$V10,$Q$3:$S$999,$U10,FALSE)>1,"*"&ROUND(VLOOKUP(AC$2&$V10,$Q$3:$S$999,$U10,FALSE),4),""),"") | AD10: =IFERROR(IF(VLOOKUP(AD$2&$V10,$Q$3:$S$999,$U10,FALSE)>1,"*"&ROUND(VLOOKUP(AD$2&$V10,$Q$3:$S$999,$U10,FALSE),4),""),"") | AE10: =IFERROR(IF(VLOOKUP(AE$2&$V10,$Q$3:$S$999,$U10,FALSE)>1,"*"&ROUND(VLOOKUP(AE$2&$V10,$Q$3:$S$999,$U10,FALSE),4),""),"") | AF10: =IFERROR(IF(VLOOKUP(AF$2&$V10,$Q$3:$S$999,$U10,FALSE)>1,"*"&ROUND(VLOOKUP(AF$2&$V10,$Q$3:$S$999,$U10,FALSE),4),""),"") | AG10: =IFERROR(IF(VLOOKUP(AG$2&$V10,$Q$3:$S$999,$U10,FALSE)>1,"*"&ROUND(VLOOKUP(AG$2&$V10,$Q$3:$S$999,$U10,FALSE),4),""),"") | ... BB10: =IFERROR(IF(VLOOKUP(BB$2&$V10,$Q$3:$S$999,$U10,FALSE)>1,"*"&ROUND(VLOOKUP(BB$2&$V10,$Q$3:$S$999,$U10,FALSE),4),""),"")
A11: =C11&D11 -> ChinaBIO | B11: IEA | C11: China | D11: BIO | E11: 0.080519264 | F11: 0.25002637 | G11: 0 | H11: 0 | J11: Bio | K11: EU_northeast | L11: 0.33376717 | M11: 0.31039723 | Q11: =K11&LEFT(J11,3) -> EU_northeastBio | R11: =IFERROR(IF(L11>0,VLOOKUP($Q11,$A$3:$H$102,R$1,FALSE)/L11,""),"") -> 0.6945798 | S11: =IFERROR(IF(M11>0,VLOOKUP($Q11,$A$3:$H$102,S$1,FALSE)/M11,""),"") -> 1.0380454 | X11: \I:
A12: =C12&D12 -> EU_northBIO | B12: IEA | C12: EU_north | D12: BIO | E12: 0.40245659 | F12: 0.33304306 | G12: 0.21104541 | H12: 0.38676891 | J12: Bio | K12: EU_northwest | L12: 0.33337511 | M12: 0.29239288 | Q12: =K12&LEFT(J12,3) -> EU_northwestBio | R12: =IFERROR(IF(L12>0,VLOOKUP($Q12,$A$3:$H$102,R$1,FALSE)/L12,""),"") -> 0.70185405 | S12: =IFERROR(IF(M12>0,VLOOKUP($Q12,$A$3:$H$102,S$1,FALSE)/M12,""),"") -> 1.0935612 | U12: =U9 -> 3 | V12: OIL | X12: EP*,EA*,-*CHP | Y12: ="*"&V12&"*" -> *OIL* | Z12: =IFERROR(IF(VLOOKUP(Z$2&$V12,$Q$3:$S$999,$U12,FALSE)>1,"*"&ROUND(VLOOKUP(Z$2&$V12,$Q$3:$S$999,$U12,FALSE),4),""),"") | AA12: =IFERROR(IF(VLOOKUP(AA$2&$V12,$Q$3:$S$999,$U12,FALSE)>1,"*"&ROUND(VLOOKUP(AA$2&$V12,$Q$3:$S$999,$U12,FALSE),4),""),"") -> *1.0762 | AB12: =IFERROR(IF(VLOOKUP(AB$2&$V12,$Q$3:$S$999,$U12,FALSE)>1,"*"&ROUND(VLOOKUP(AB$2&$V12,$Q$3:$S$999,$U12,FALSE),4),""),"") -> *1.3163 | AC12: =IFERROR(IF(VLOOKUP(AC$2&$V12,$Q$3:$S$999,$U12,FALSE)>1,"*"&ROUND(VLOOKUP(AC$2&$V12,$Q$3:$S$999,$U12,FALSE),4),""),"") -> *1.2093 | AD12: =IFERROR(IF(VLOOKUP(AD$2&$V12,$Q$3:$S$999,$U12,FALSE)>1,"*"&ROUND(VLOOKUP(AD$2&$V12,$Q$3:$S$999,$U12,FALSE),4),""),"") -> *1.1184 | AE12: =IFERROR(IF(VLOOKUP(AE$2&$V12,$Q$3:$S$999,$U12,FALSE)>1,"*"&ROUND(VLOOKUP(AE$2&$V12,$Q$3:$S$999,$U12,FALSE),4),""),"") -> *1.2009 | AF12: =IFERROR(IF(VLOOKUP(AF$2&$V12,$Q$3:$S$999,$U12,FALSE)>1,"*"&ROUND(VLOOKUP(AF$2&$V12,$Q$3:$S$999,$U12,FALSE),4),""),"") -> *1.2955 | AG12: =IFERROR(IF(VLOOKUP(AG$2&$V12,$Q$3:$S$999,$U12,FALSE)>1,"*"&ROUND(VLOOKUP(AG$2&$V12,$Q$3:$S$999,$U12,FALSE),4),""),"") | ... BB12: =IFERROR(IF(VLOOKUP(BB$2&$V12,$Q$3:$S$999,$U12,FALSE)>1,"*"&ROUND(VLOOKUP(BB$2&$V12,$Q$3:$S$999,$U12,FALSE),4),""),"")
A13: =C13&D13 -> EU_northeastBIO | B13: IEA | C13: EU_northeast | D13: BIO | E13: 0.42296845 | F13: 0.29476827 | G13: 0.23182793 | H13: 0.32220643 | J13: Bio | K13: EU_south | L13: 0.30660731 | M13: 0.30977876 | Q13: =K13&LEFT(J13,3) -> EU_southBio | R13: =IFERROR(IF(L13>0,VLOOKUP($Q13,$A$3:$H$102,R$1,FALSE)/L13,""),"") -> 0.91003602 | S13: =IFERROR(IF(M13>0,VLOOKUP($Q13,$A$3:$H$102,S$1,FALSE)/M13,""),"") -> 1.0667069 | U13: =U10 -> 2 | V13: OIL | X13: EP*CHP, EA*CHP | Y13: \I: | Z13: =IFERROR(IF(VLOOKUP(Z$2&$V13,$Q$3:$S$999,$U13,FALSE)>1,"*"&ROUND(VLOOKUP(Z$2&$V13,$Q$3:$S$999,$U13,FALSE),4),""),"") | AA13: =IFERROR(IF(VLOOKUP(AA$2&$V13,$Q$3:$S$999,$U13,FALSE)>1,"*"&ROUND(VLOOKUP(AA$2&$V13,$Q$3:$S$999,$U13,FALSE),4),""),"") | AB13: =IFERROR(IF(VLOOKUP(AB$2&$V13,$Q$3:$S$999,$U13,FALSE)>1,"*"&ROUND(VLOOKUP(AB$2&$V13,$Q$3:$S$999,$U13,FALSE),4),""),"") | AC13: =IFERROR(IF(VLOOKUP(AC$2&$V13,$Q$3:$S$999,$U13,FALSE)>1,"*"&ROUND(VLOOKUP(AC$2&$V13,$Q$3:$S$999,$U13,FALSE),4),""),"") -> *1.1164 | AD13: =IFERROR(IF(VLOOKUP(AD$2&$V13,$Q$3:$S$999,$U13,FALSE)>1,"*"&ROUND(VLOOKUP(AD$2&$V13,$Q$3:$S$999,$U13,FALSE),4),""),"") | AE13: =IFERROR(IF(VLOOKUP(AE$2&$V13,$Q$3:$S$999,$U13,FALSE)>1,"*"&ROUND(VLOOKUP(AE$2&$V13,$Q$3:$S$999,$U13,FALSE),4),""),"") | AF13: =IFERROR(IF(VLOOKUP(AF$2&$V13,$Q$3:$S$999,$U13,FALSE)>1,"*"&ROUND(VLOOKUP(AF$2&$V13,$Q$3:$S$999,$U13,FALSE),4),""),"") | AG13: =IFERROR(IF(VLOOKUP(AG$2&$V13,$Q$3:$S$999,$U13,FALSE)>1,"*"&ROUND(VLOOKUP(AG$2&$V13,$Q$3:$S$999,$U13,FALSE),4),""),"") | ... BB13: =IFERROR(IF(VLOOKUP(BB$2&$V13,$Q$3:$S$999,$U13,FALSE)>1,"*"&ROUND(VLOOKUP(BB$2&$V13,$Q$3:$S$999,$U13,FALSE),4),""),"")
A14: =C14&D14 -> EU_northwestBIO | B14: IEA | C14: EU_northwest | D14: BIO | E14: 0.27204958 | F14: 0.2902395 | G14: 0.23398067 | H14: 0.31974949 | J14: Bio | K14: EU_southeast | L14: 0.32720548 | M14: 0.32598828 | Q14: =K14&LEFT(J14,3) -> EU_southeastBio | R14: =IFERROR(IF(L14>0,VLOOKUP($Q14,$A$3:$H$102,R$1,FALSE)/L14,""),"") -> 0.77514429 | S14: =IFERROR(IF(M14>0,VLOOKUP($Q14,$A$3:$H$102,S$1,FALSE)/M14,""),"") -> 0.94338871
A15: =C15&D15 -> EU_southBIO | B15: IEA | C15: EU_south | D15: BIO | E15: 0.37717153 | F15: 0.33664684 | G15: 0.2790237 | H15: 0.33044314 | J15: Bio | K15: EU_southwest | L15: 0.28564326 | M15: 0.31966137 | Q15: =K15&LEFT(J15,3) -> EU_southwestBio | R15: =IFERROR(IF(L15>0,VLOOKUP($Q15,$A$3:$H$102,R$1,FALSE)/L15,""),"") -> 0 | S15: =IFERROR(IF(M15>0,VLOOKUP($Q15,$A$3:$H$102,S$1,FALSE)/M15,""),"") -> 0.84151036
A16: =C16&D16 -> EU_southeastBIO | B16: IEA | C16: EU_southeast | D16: BIO | E16: 0.48024204 | F16: 0.33635085 | G16: 0.25363146 | H16: 0.30753366 | J16: Bio | K16: Europe_other | L16: 0.33433851 | M16: 0.27902571 | Q16: =K16&LEFT(J16,3) -> Europe_otherBio | R16: =IFERROR(IF(L16>0,VLOOKUP($Q16,$A$3:$H$102,R$1,FALSE)/L16,""),"") -> 0.63813963 | S16: =IFERROR(IF(M16>0,VLOOKUP($Q16,$A$3:$H$102,S$1,FALSE)/M16,""),"") -> 1.2639004
A17: =C17&D17 -> EU_southwestBIO | B17: IEA | C17: EU_southwest | D17: BIO | E17: 0.41829906 | F17: 0.27879047 | G17: 0 | H17: 0.26899836 | J17: Bio | K17: France | L17: 0.32905718 | M17: 0.31205708 | Q17: =K17&LEFT(J17,3) -> FranceBio | R17: =IFERROR(IF(L17>0,VLOOKUP($Q17,$A$3:$H$102,R$1,FALSE)/L17,""),"") -> 0.51784872 | S17: =IFERROR(IF(M17>0,VLOOKUP($Q17,$A$3:$H$102,S$1,FALSE)/M17,""),"") -> 0.94300135
A18: =C18&D18 -> Europe_otherBIO | B18: IEA | C18: Europe_other | D18: BIO | E18: 0.17901314 | F18: 0.28952254 | G18: 0.21335465 | H18: 0.3526607 | J18: Bio | K18: Germany | L18: 0.32634396 | M18: 0.30531707 | Q18: =K18&LEFT(J18,3) -> GermanyBio | R18: =IFERROR(IF(L18>0,VLOOKUP($Q18,$A$3:$H$102,R$1,FALSE)/L18,""),"") -> 1.1269673 | S18: =IFERROR(IF(M18>0,VLOOKUP($Q18,$A$3:$H$102,S$1,FALSE)/M18,""),"") -> 1.117922
A19: =C19&D19 -> FranceBIO | B19: IEA | C19: France | D19: BIO | E19: 0.21133616 | F19: 0.2276061 | G19: 0.17040184 | H19: 0.29427025 | J19: Bio | K19: India | L19: 0.328 | M19: 0.33073883 | Q19: =K19&LEFT(J19,3) -> IndiaBio | R19: =IFERROR(IF(L19>0,VLOOKUP($Q19,$A$3:$H$102,R$1,FALSE)/L19,""),"") -> 0 | S19: =IFERROR(IF(M19>0,VLOOKUP($Q19,$A$3:$H$102,S$1,FALSE)/M19,""),"") -> 0.66517722
A20: =C20&D20 -> GermanyBIO | B20: IEA | C20: Germany | D20: BIO | E20: 0.51594504 | F20: 0.28942636 | G20: 0.36777899 | H20: 0.34132068 | J20: Bio | K20: LatAm_other | L20: 0.332 | M20: 0.29952361 | Q20: =K20&LEFT(J20,3) -> LatAm_otherBio | R20: =IFERROR(IF(L20>0,VLOOKUP($Q20,$A$3:$H$102,R$1,FALSE)/L20,""),"") -> 0 | S20: =IFERROR(IF(M20>0,VLOOKUP($Q20,$A$3:$H$102,S$1,FALSE)/M20,""),"") -> 0.74032786
A21: =C21&D21 -> IndiaBIO | B21: IEA | C21: India | D21: BIO | E21: 0.16254073 | F21: 0.2 | G21: 0 | H21: 0.21999993 | J21: Bio | K21: Nor-Ice | L21: 0.329 | Q21: =K21&LEFT(J21,3) -> Nor-IceBio | R21: =IFERROR(IF(L21>0,VLOOKUP($Q21,$A$3:$H$102,R$1,FALSE)/L21,""),"") -> 0.45637903 | S21: =IFERROR(IF(M21>0,VLOOKUP($Q21,$A$3:$H$102,S$1,FALSE)/M21,""),"")
A22: =C22&D22 -> LatAm_otherBIO | B22: IEA | C22: LatAm_other | D22: BIO | E22: 0.62636687 | F22: 0.18783341 | G22: 0 | H22: 0.22174567 | J22: Bio | K22: Russia | L22: 0.2851551 | Q22: =K22&LEFT(J22,3) -> RussiaBio | R22: =IFERROR(IF(L22>0,VLOOKUP($Q22,$A$3:$H$102,R$1,FALSE)/L22,""),"") -> 0 | S22: =IFERROR(IF(M22>0,VLOOKUP($Q22,$A$3:$H$102,S$1,FALSE)/M22,""),"")
A23: =C23&D23 -> MexicoBIO | B23: IEA | C23: Mexico | D23: BIO | E23: 0.10149143 | F23: 0.082916495 | G23: 0 | H23: 0 | J23: Bio | K23: UK | L23: 0.33049989 | M23: 0.37939766 | Q23: =K23&LEFT(J23,3) -> UKBio | R23: =IFERROR(IF(L23>0,VLOOKUP($Q23,$A$3:$H$102,R$1,FALSE)/L23,""),"") -> 0 | S23: =IFERROR(IF(M23>0,VLOOKUP($Q23,$A$3:$H$102,S$1,FALSE)/M23,""),"") -> 1.2008358
A24: =C24&D24 -> MidEast_otherBIO | B24: IEA | C24: MidEast_other | D24: BIO | E24: 0 | F24: 0.18057881 | G24: 0 | H24: 0.30396197 | J24: Bio | K24: USA | L24: 0.3101724 | M24: 0.31323224 | Q24: =K24&LEFT(J24,3) -> USABio | R24: =IFERROR(IF(L24>0,VLOOKUP($Q24,$A$3:$H$102,R$1,FALSE)/L24,""),"") -> 0.59608747 | S24: =IFERROR(IF(M24>0,VLOOKUP($Q24,$A$3:$H$102,S$1,FALSE)/M24,""),"") -> 0.79978774
A25: =C25&D25 -> Nor-IceBIO | B25: IEA | C25: Nor-Ice | D25: BIO | E25: 0 | F25: 0 | G25: 0.1501487 | H25: 0.53273919 | J25: Coal | K25: Africa_north | M25: 0.32281708 | Q25: =K25&LEFT(J25,3) -> Africa_northCoa | R25: =IFERROR(IF(L25>0,VLOOKUP($Q25,$A$3:$H$102,R$1,FALSE)/L25,""),"") | S25: =IFERROR(IF(M25>0,VLOOKUP($Q25,$A$3:$H$102,S$1,FALSE)/M25,""),"") -> 1.0676183
A26: =C26&D26 -> RussiaBIO | B26: IEA | C26: Russia | D26: BIO | E26: 0.10305266 | F26: 0 | G26: 0 | H26: 0 | J26: Coal | K26: Africa_other | L26: 0.273 | M26: 0.30965531 | Q26: =K26&LEFT(J26,3) -> Africa_otherCoa | R26: =IFERROR(IF(L26>0,VLOOKUP($Q26,$A$3:$H$102,R$1,FALSE)/L26,""),"") -> 0 | S26: =IFERROR(IF(M26>0,VLOOKUP($Q26,$A$3:$H$102,S$1,FALSE)/M26,""),"") -> 0.82993532
A27: =C27&D27 -> SouthAfricaBIO | B27: IEA | C27: SouthAfrica | D27: BIO | E27: 0.50000097 | F27: 0.25411262 | G27: 0 | H27: 0 | J27: Coal | K27: Arg-Chi | M27: 0.30762931 | Q27: =K27&LEFT(J27,3) -> Arg-ChiCoa | R27: =IFERROR(IF(L27>0,VLOOKUP($Q27,$A$3:$H$102,R$1,FALSE)/L27,""),"") | S27: =IFERROR(IF(M27>0,VLOOKUP($Q27,$A$3:$H$102,S$1,FALSE)/M27,""),"") -> 1.1732766
A28: =C28&D28 -> UKBIO | B28: IEA | C28: UK | D28: BIO | E28: 0.36237241 | F28: 0.33179883 | G28: 0 | H28: 0.4555943 | J28: Coal | K28: Asia_central | L28: 0.32982987 | M28: 0.34767641 | Q28: =K28&LEFT(J28,3) -> Asia_centralCoa | R28: =IFERROR(IF(L28>0,VLOOKUP($Q28,$A$3:$H$102,R$1,FALSE)/L28,""),"") -> 0.85719758 | S28: =IFERROR(IF(M28>0,VLOOKUP($Q28,$A$3:$H$102,S$1,FALSE)/M28,""),"") -> 0.57479266
A29: =C29&D29 -> USABIO | B29: IEA | C29: USA | D29: BIO | E29: 0.59548027 | F29: 0.21384718 | G29: 0.18488988 | H29: 0.2505193 | J29: Coal | K29: Asia_east | L29: 0.29843541 | M29: 0.3439991 | Q29: =K29&LEFT(J29,3) -> Asia_eastCoa | R29: =IFERROR(IF(L29>0,VLOOKUP($Q29,$A$3:$H$102,R$1,FALSE)/L29,""),"") -> 0 | S29: =IFERROR(IF(M29>0,VLOOKUP($Q29,$A$3:$H$102,S$1,FALSE)/M29,""),"") -> 1.1732118
A30: =C30&D30 -> Africa_northCOA | B30: IEA | C30: Africa_north | D30: COA | E30: 0 | F30: 0 | G30: 0 | H30: 0.34464544 | J30: Coal | K30: Asia_other | L30: 0.32134595 | M30: 0.30755439 | Q30: =K30&LEFT(J30,3) -> Asia_otherCoa | R30: =IFERROR(IF(L30>0,VLOOKUP($Q30,$A$3:$H$102,R$1,FALSE)/L30,""),"") -> 0.57158842 | S30: =IFERROR(IF(M30>0,VLOOKUP($Q30,$A$3:$H$102,S$1,FALSE)/M30,""),"") -> 1.1294404
A31: =C31&D31 -> Africa_otherCOA | B31: IEA | C31: Africa_other | D31: COA | E31: 0 | F31: 0.25245255 | G31: 0 | H31: 0.25699388 | J31: Coal | K31: Australia_NZ | L31: 0.313 | M31: 0.3280209 | Q31: =K31&LEFT(J31,3) -> Australia_NZCoa | R31: =IFERROR(IF(L31>0,VLOOKUP($Q31,$A$3:$H$102,R$1,FALSE)/L31,""),"") -> 1.0975789 | S31: =IFERROR(IF(M31>0,VLOOKUP($Q31,$A$3:$H$102,S$1,FALSE)/M31,""),"") -> 1.035192
A32: =C32&D32 -> Arg-ChiCOA | B32: IEA | C32: Arg-Chi | D32: COA | E32: 0 | F32: 0.34667331 | G32: 0 | H32: 0.36093425 | J32: Coal | K32: Brazil | M32: 0.30434031 | Q32: =K32&LEFT(J32,3) -> BrazilCoa | R32: =IFERROR(IF(L32>0,VLOOKUP($Q32,$A$3:$H$102,R$1,FALSE)/L32,""),"") | S32: =IFERROR(IF(M32>0,VLOOKUP($Q32,$A$3:$H$102,S$1,FALSE)/M32,""),"") -> 1.1646373
A33: =C33&D33 -> Asia_centralCOA | B33: IEA | C33: Asia_central | D33: COA | E33: 0 | F33: 0.24847149 | G33: 0.28272937 | H33: 0.19984185 | J33: Coal | K33: Canada | M33: 0.31867136 | Q33: =K33&LEFT(J33,3) -> CanadaCoa | R33: =IFERROR(IF(L33>0,VLOOKUP($Q33,$A$3:$H$102,R$1,FALSE)/L33,""),"") | S33: =IFERROR(IF(M33>0,VLOOKUP($Q33,$A$3:$H$102,S$1,FALSE)/M33,""),"") -> 1.2154099
A34: =C34&D34 -> Asia_eastCOA | B34: IEA | C34: Asia_east | D34: COA | E34: 0.1405905 | F34: 0.71573503 | G34: 0 | H34: 0.40358379 | J34: Coal | K34: China | L34: 0.30761476 | M34: 0.32764685 | Q34: =K34&LEFT(J34,3) -> ChinaCoa | R34: =IFERROR(IF(L34>0,VLOOKUP($Q34,$A$3:$H$102,R$1,FALSE)/L34,""),"") -> 1.0170902 | S34: =IFERROR(IF(M34>0,VLOOKUP($Q34,$A$3:$H$102,S$1,FALSE)/M34,""),"") -> 1.1727523
A35: =C35&D35 -> Asia_otherCOA | B35: IEA | C35: Asia_other | D35: COA | E35: 0.31239856 | F35: 0.32001898 | G35: 0.18367762 | H35: 0.34736437 | J35: Coal | K35: EU_north | L35: 0.32295861 | M35: 0.31520691 | Q35: =K35&LEFT(J35,3) -> EU_northCoa | R35: =IFERROR(IF(L35>0,VLOOKUP($Q35,$A$3:$H$102,R$1,FALSE)/L35,""),"") -> 0.86645212 | S35: =IFERROR(IF(M35>0,VLOOKUP($Q35,$A$3:$H$102,S$1,FALSE)/M35,""),"") -> 1.2757768
A36: =C36&D36 -> Australia_NZCOA | B36: IEA | C36: Australia_NZ | D36: COA | E36: 0.15938244 | F36: 0 | G36: 0.34354218 | H36: 0.33956461 | J36: Coal | K36: EU_northeast | L36: 0.31797627 | M36: 0.33064774 | Q36: =K36&LEFT(J36,3) -> EU_northeastCoa | R36: =IFERROR(IF(L36>0,VLOOKUP($Q36,$A$3:$H$102,R$1,FALSE)/L36,""),"") -> 1.0594711 | S36: =IFERROR(IF(M36>0,VLOOKUP($Q36,$A$3:$H$102,S$1,FALSE)/M36,""),"") -> 1.1053042
A37: =C37&D37 -> BrazilCOA | B37: IEA | C37: Brazil | D37: COA | E37: 0.46826464 | F37: 0 | G37: 0 | H37: 0.35444608 | J37: Coal | K37: EU_northwest | L37: 0.34320126 | M37: 0.35071385 | Q37: =K37&LEFT(J37,3) -> EU_northwestCoa | R37: =IFERROR(IF(L37>0,VLOOKUP($Q37,$A$3:$H$102,R$1,FALSE)/L37,""),"") -> 1.2786507 | S37: =IFERROR(IF(M37>0,VLOOKUP($Q37,$A$3:$H$102,S$1,FALSE)/M37,""),"") -> 1.2116574
A38: =C38&D38 -> CanadaCOA | B38: IEA | C38: Canada | D38: COA | E38: 0 | F38: 0 | G38: 0 | H38: 0.38731632 | J38: Coal | K38: EU_south | L38: 0.32609896 | M38: 0.34049553 | Q38: =K38&LEFT(J38,3) -> EU_southCoa | R38: =IFERROR(IF(L38>0,VLOOKUP($Q38,$A$3:$H$102,R$1,FALSE)/L38,""),"") -> 1.0210356 | S38: =IFERROR(IF(M38>0,VLOOKUP($Q38,$A$3:$H$102,S$1,FALSE)/M38,""),"") -> 1.1128129
A39: =C39&D39 -> ChinaCOA | B39: IEA | C39: China | D39: COA | E39: 0 | F39: 0 | G39: 0.31287195 | H39: 0.3842486 | J39: Coal | K39: EU_southeast | L39: 0.29081245 | M39: 0.32032442 | Q39: =K39&LEFT(J39,3) -> EU_southeastCoa | R39: =IFERROR(IF(L39>0,VLOOKUP($Q39,$A$3:$H$102,R$1,FALSE)/L39,""),"") -> 0.892066 | S39: =IFERROR(IF(M39>0,VLOOKUP($Q39,$A$3:$H$102,S$1,FALSE)/M39,""),"") -> 1.0624531
A40: =C40&D40 -> EU_northCOA | B40: IEA | C40: EU_north | D40: COA | E40: 0.61092812 | F40: 0.35757566 | G40: 0.27982817 | H40: 0.40213367 | J40: Coal | K40: EU_southwest | L40: 0.27334337 | M40: 0.31716379 | Q40: =K40&LEFT(J40,3) -> EU_southwestCoa | R40: =IFERROR(IF(L40>0,VLOOKUP($Q40,$A$3:$H$102,R$1,FALSE)/L40,""),"") -> 0 | S40: =IFERROR(IF(M40>0,VLOOKUP($Q40,$A$3:$H$102,S$1,FALSE)/M40,""),"") -> 1.1932261
...

Sheet Misc
B3: ~TFM_UPD
B4: attribute | C4: year | D4: process | E4: value
B5: ACT_BND | C5: 2018 | D5: MinBIOBSL-07 | E5: 99999
B8: ~TFM_MIG: attribute=stock
B9: year2 | C9: Val_Cond | D9: value | E9: pset_ci | J9: ~TFM_UPD
B10: 2100 | C10: >1 | D10: *1 | E10: ???GEO,???STH,???HET | J10: TimeSlice | K10: Attribute | L10: Val_Cond | M10: AllRegions | N10: Pset_Set | O10: Pset_PN | P10: Pset_CI | Q10: avc_limtype | R10: limtype
K11: RESID | L11: <.001 | M11: 0 | N11: PRE | P11: IND* | T11: scaling
K12: FLO_SHAR | L12: <.001 | M12: 0 | N12: DMD | O12: T*generic*
K13: FLO_MARK | L13: <.001 | M13: 0 | O13: I* | Q13: LO | R13: LO
B16: ~TFM_TOPINS
B17: process | C17: io | D17: commodity
B18: SUP_GasSupply | C18: IN | D18: GAS[_]*
B19: SUP_OilSupply | C19: IN | D19: OIL[_]*
B22: ~TFM_INS
B23: attribute | C23: process | D23: pset_ci | E23: value
B24: START | C24: SUP_GasSupply | D24: -Gas[_]* | E24: 2150
B25: START | C25: =B19 -> SUP_OilSupply | D25: -Oil[_]* | E25: 2150
B28: ~TFM_TOPINS
B29: process | C29: io | D29: commodity
B30: FT_INDNGA | C30: IN | D30: GASRFG

Sheet pumped hydro
C3: ~TFM_INS
C4: attribute | D4: other_indexes | E4: timeslice | F4: allregions | G4: process | H4: commodity | I4: pset_co | L4: assuming 6h storage capacity for day-night operation of pumped hydro
C5: NCAP_AFAC | D5: ELC | F5: =6/24 -> 0.25 | G5: EP_HPS* | I5: ELC
C6: NCAP_AFAC | D6: INDELC | F6: =6/24 -> 0.25 | G6: EA_HPS* | I6: INDELC
C7: NCAP_AFC | D7: ACT | E7: DAYNITE | F7: =6/24/F11 -> 0.3125 | G7: E?_HPS*
C8: NCAP_AFC | D8: ELC | E8: DAYNITE | F8: 1 | G8: =G5 -> EP_HPS* | I8: ELC
C9: NCAP_AFC | D9: INDELC | E9: DAYNITE | F9: 1 | G9: =G6 -> EA_HPS* | I9: INDELC
C10: NCAP_AFC | D10: NRG | E10: DAYNITE | F10: =6/9 -> 0.66666667 | G10: =$G$7 -> E?_HPS* | L10: takes 9h to full charge (pump has a smaller capacity than the hydro turbine)
C11: STG_EFF | F11: 0.8 | G11: =$G$7 -> E?_HPS*
C12: FLO_FUNC | D12: AuxStoOUT | F12: =1/F11 -> 1.25 | G12: =G5 -> EP_HPS* | H12: ELC
C13: FLO_FUNC | D13: AuxStoOUT | F13: =1/F12 -> 0.8 | G13: =G6 -> EA_HPS* | H13: INDELC
C16: ~TFM_TOPINS-A
C17: process | D17: commodity | E17: value
C18: =G12 -> EP_HPS* | D18: =D12 -> AuxStoOUT | E18: OUT
