Workbook

Sheet TRA balance
A1: 0.041868 | B1: ktoe to PJ
B4: Sector | C4: Sub-Sector | D4: sectfuel | E4: Africa_north | F4: Africa_other | G4: Arg-Chi | H4: Asia_central | I4: Asia_east | J4: Asia_other | K4: Australia_NZ | L4: Brazil | M4: Canada | N4: China | O4: EU_north | P4: EU_northeast | Q4: EU_northwest | R4: EU_south | S4: EU_southeast | T4: EU_southwest | U4: Europe_other | V4: France | W4: Germany | X4: India | Y4: LatAm_other | Z4: Mexico | AA4: MidEast_other | AB4: Nor-Ice | AC4: Russia | AD4: SaudiArabia | AE4: SouthAfrica | AF4: UK | AG4: USA | AH4: \I:
A5: =IF(OR(C5="TT",C5="TR"),"RR","") | B5: TRA | C5: NEU | D5: COATAR | L5: 6.1607004 | P5: 0.023990364 | Z5: 2.5819619 | AK5: Bio Diesel | AL5: TRABDS | AM5: bdl
A6: =IF(OR(C6="TT",C6="TR"),"RR","") | B6: TRA | C6: NEU | D6: OILASP | F6: 2.3701893 | H6: 0.50052775 | M6: 22.480001 | N6: 1314.758 | P6: 0.011036405 | R6: 0.011388096 | S6: 0.04711406 | U6: 15.369902 | Y6: 0.37424549 | AA6: 1.7316019 | AB6: 0.079440343 | AE6: 3.601925 | AK6: Bio Gasoline | AL6: TRABGS | AM6: eth
A7: =IF(OR(C7="TT",C7="TR"),"RR","") | B7: TRA | C7: NEU | D7: OILKER | E7: 0.27722059 | H7: 0.69119881 | Q7: 0.075379147 | S7: 0.0033159456 | Y7: 0.23994969 | AK7: Biogas | AL7: TRANGA | AM7: nga
A8: =IF(OR(C8="TT",C8="TR"),"RR","") | B8: TRA | C8: NEU | D8: OILLUB | E8: 2.5678105 | F8: 2.1184789 | H8: 7.7056965 | I8: 86.862606 | J8: 3.9347923 | M8: 21.702998 | N8: 99.093555 | O8: 1.7354412 | P8: 28.133207 | Q8: 7.0347074 | R8: 10.076853 | S8: 6.7545854 | T8: 10.991359 | U8: 12.182985 | V8: 12.396298 | W8: 13.188001 | Y8: 2.2883667 | AA8: 8.2227203 | AB8: 2.043016 | AE8: 6.0861251 | AF8: 5.7178709 | AG8: 105.003 | AK8: Coal | AL8: TRACOA | AM8: coa
A9: =IF(OR(C9="TT",C9="TR"),"RR","") | B9: TRA | C9: NEU | D9: OILNSP | F9: 0.14324718 | H9: 0.12708194 | I9: 0.003998394 | J9: 2.8799992 | M9: 85.400002 | U9: 0.035998106 | AG9: 176.04 | AK9: Diesel | AL9: TRADST | AM9: dsl
A10: =IF(OR(C10="TT",C10="TR"),"RR","") | B10: TRA | C10: TAD | D10: TRADST | F10: 0.046243206 | G10: 0.30864252 | H10: 0.012794861 | I10: 0.056019384 | AE10: 0.74616312 | AK10: Electricity | AL10: TRAELC | AM10: elc
A11: =IF(OR(C11="TT",C11="TR"),"RR","") | B11: TRA | C11: TAD | D11: TRAGSL | G11: 0.18076928 | J11: 0.008959752 | O11: 4.60548e-05 | Q11: 0.030932078 | Y11: 0.51011553 | AK11: Gasoline | AL11: TRAGSL | AM11: gsl
A12: =IF(OR(C12="TT",C12="TR"),"RR","") | B12: TRA | C12: TAD | D12: TRAHFO | E12: 0.011999369 | I12: 0.0005945256 | U12: 7.6400015 | AK12: Heavy Fuel Oil | AL12: TRAHFO | AM12: hfo
A13: =IF(OR(C13="TT",C13="TR"),"RR","") | B13: TRA | C13: TAD | D13: TRAJTK | E13: 28.892667 | F13: 22.625924 | G13: 52.095645 | H13: 25.442263 | I13: 193.77429 | J13: 278.03335 | K13: 137.98737 | L13: 140.16919 | M13: 290.2216 | N13: 1141.9091 | O13: 10.771347 | P13: 4.7938525 | Q13: 0.7666282 | R13: 47.447853 | S13: 3.6679717 | T13: 104.06785 | U13: 53.855018 | V13: 67.799231 | W13: 30.753001 | X13: 179.28629 | Y13: 36.970817 | Z13: 0.54145372 | AA13: 60.200674 | AB13: 15.07984 | AC13: 245.144 | AD13: 40.847534 | AE13: 51.997134 | AF13: 37.125494 | AG13: 2524.0834 | AK13: Liquified Petroleum Gases | AL13: TRALPG | AM13: lpg
A14: =IF(OR(C14="TT",C14="TR"),"RR","") | B14: TRA | C14: TAI | D14: TRAHFO | U14: -5.0799994 | AK14: Natural Gas | AL14: TRANGA | AM14: nga
A15: =IF(OR(C15="TT",C15="TR"),"RR","") | B15: TRA | C15: TAI | D15: TRAJTK | E15: -99.12303 | F15: -192.0928 | G15: -79.985695 | H15: =-61.7382848448-6.9025133916 -> -68.640798 | I15: -541.37213 | J15: -1095.7451 | K15: -265.72401 | L15: -101.44622 | M15: -35.947601 | N15: -739.07707 | O15: -115.46579 | P15: -118.57451 | Q15: -306.15463 | R15: -233.4101 | S15: -37.673999 | T15: -260.69911 | U15: -282.17336 | V15: -260.04602 | W15: -409.876 | X15: -177.46911 | Y15: -242.43197 | Z15: -176.72739 | AA15: -762.82424 | AB15: -35.984771 | AC15: -245.1 | AD15: -153.09619 | AE15: -46.072598 | AF15: -493.59478 | AG15: -1072.184
A16: =IF(OR(C16="TT",C16="TR"),"RR","") -> RR | B16: TRA | C16: TR | D16: TRABDS | G16: 42.357391 | H16: 0.0096045192 | I16: 27.370456 | J16: 257.75518 | K16: 0.21377801 | L16: 651.02992 | M16: 21.418522 | N16: 38.175623 | O16: 71.665049 | P16: 74.214078 | Q16: 43.711729 | R16: 59.775015 | S16: 32.294936 | T16: 73.584672 | U16: 16.16001 | V16: 105.70326 | W16: 79.09389 | X16: 1.6369383 | Y16: 31.906137 | AB16: 18.191458 | AF16: 52.885602 | AG16: 182.82091
A17: =IF(OR(C17="TT",C17="TR"),"RR","") -> RR | B17: TRA | C17: TR | D17: TRABGS | F17: 1.9221473 | G17: 22.553672 | I17: 16.636849 | J17: 53.312425 | K17: 5.4593946 | L17: 235.95355 | M17: 66.814998 | N17: 85.76 | O17: 9.3798262 | P17: 15.139456 | Q17: 15.655638 | R17: 2.3274547 | S17: 7.5601131 | T17: 5.7976587 | U17: 7.2547866 | V17: 27.351933 | W17: 30.097494 | X17: 36.820817 | Y17: 30.535861 | AB17: 1.9523928 | AF17: 16.015121 | AG17: 1368.3873
A18: =IF(OR(C18="TT",C18="TR"),"RR","") -> RR | B18: TRA | C18: TR | D18: TRADST | E18: 1112.0205 | F18: 988.22762 | G18: 474.01883 | H18: 196.82152 | I18: 1715.4087 | J18: 2836.3807 | K18: 674.97822 | L18: 1435.9916 | M18: 644.83407 | N18: 3962.0627 | O18: 322.46291 | P18: 1230.9174 | Q18: 671.57682 | R18: 1012.3927 | S18: 523.33751 | T18: 1074.1823 | U18: 1390.5106 | V18: 1286.4001 | W18: 1389.2712 | X18: 2433.6589 | Y18: 1000.3491 | Z18: 517.18572 | AA18: 1497.7659 | AB18: 96.304757 | AC18: 616.49953 | AD18: 851.79872 | AE18: 347.12819 | AF18: 1019.9282 | AG18: 5138.1263 | AK18: =31536000/10^9 -> 0.031536 | AL18: GJ/lt Gasoline | AN18: =1/AK18 -> 31.709792 | AO18: km/l | AP18: equivalent to Bvkm/PJ = 1 | AT18: =100/AN18 -> 3.1536 | AU18: l/100km
A19: =IF(OR(C19="TT",C19="TR"),"RR","") -> RR | B19: TRA | C19: TR | D19: TRAELC | G19: 2.9016701 | H19: 0.13203492 | I19: 0.89122318 | J19: 0.6155224 | K19: 0.21488332 | M19: 4.6296002 | N19: 245.36301 | O19: 1.3584366 | P19: 0.79621213 | Q19: 2.4166168 | R19: 0.57130561 | S19: 0.43623525 | T19: 0.60042061 | U19: 0.56393684 | V19: 1.1790573 | W19: 1.2096 | Y19: 0.039439656 | AB19: 3.1735986 | AE19: 0.19335061 | AF19: 1.3193653 | AG19: 23.414913 | AK19: 0.038 | AL19: GJ/lt Diesel | AN19: =1/AK19 -> 26.315789 | AO19: km/l | AP19: equivalent to Bvkm/PJ = 1 | AT19: =100/AN19 -> 3.8 | AU19: l/100km
A20: =IF(OR(C20="TT",C20="TR"),"RR","") -> RR | B20: TRA | C20: TR | D20: TRAGSL | E20: 715.67029 | F20: 1242.7522 | G20: 410.20751 | H20: 410.23312 | I20: 2017.2047 | J20: 3553.7055 | K20: 674.81303 | L20: 898.18184 | M20: 1359.4517 | N20: 6022.405 | O20: 190.16307 | P20: 381.57698 | Q20: 300.14472 | R20: 439.49505 | S20: 176.45298 | T20: 271.13869 | U20: 369.35101 | V20: 329.10323 | W20: 722.612 | X20: 1342.88 | Y20: 1297.5831 | Z20: 1497.1269 | AA20: 2359.6239 | AB20: 33.120607 | AC20: 1493.067 | AD20: 1019.3707 | AE20: 316.57445 | AF20: 517.44924 | AG20: 15490.671
A21: =IF(OR(C21="TT",C21="TR"),"RR","") -> RR | B21: TRA | C21: TR | D21: TRAHFO | G21: 0.090451627 | H21: 0.20284627 | I21: 0.15391514 | R21: 0.0020808396 | X21: 0.064200391 | AE21: 0.7493116
A22: =IF(OR(C22="TT",C22="TR"),"RR","") -> RR | B22: TRA | C22: TR | D22: TRAJTK | G22: 0.32455655 | I22: 0.028315328 | AE22: 2.5273995 | AT22: =AT18/7.96 -> 0.3961809
A23: =IF(OR(C23="TT",C23="TR"),"RR","") -> RR | B23: TRA | C23: TR | D23: TRALPG | E23: 42.939992 | F23: 0.024643505 | G23: 0.52063277 | H23: 18.922825 | I23: 175.40778 | J23: 55.315411 | K23: 15.340222 | M23: 10.9263 | N23: 90.603704 | P23: 100.19563 | Q23: 8.255482 | R23: 86.156368 | S23: 27.006715 | T23: 5.6658625 | U23: 252.03443 | V23: 2.4205649 | W23: 15.594 | X23: 8.1308703 | Y23: 34.076508 | Z23: 59.731104 | AA23: 2.8085347 | AB23: 0.21472841 | AC23: 55.659081 | AE23: 0.65408283 | AF23: 2.8979983 | AG23: 3.169102
A24: =IF(OR(C24="TT",C24="TR"),"RR","") -> RR | B24: TRA | C24: TR | D24: TRANGA | E24: 20.348053 | F24: 0.074688325 | G24: 86.137837 | H24: 147.97629 | I24: 51.227713 | J24: 167.09004 | K24: 3.1234533 | L24: 84.173068 | M24: 2.0538012 | N24: 1028.3403 | O24: 5.276063 | P24: 5.4630581 | Q24: 3.8368882 | R24: 40.93794 | S24: 4.3994894 | T24: 8.8681657 | U24: 6.0262957 | V24: 6.8120701 | W24: 8.336551 | X24: 123.38074 | Y24: 75.744123 | Z24: 1.8773988 | AA24: 279.44311 | AB24: 2.4442664 | AC24: 8.7022177 | AE24: 0.0073310868 | AF24: 0.56970206 | AG24: 50.417245 | AK24: mtoe | AL24: 41.868 | AM24: PJ | AT24: =AT18/14.35 -> 0.21976307
A25: =IF(OR(C25="TT",C25="TR"),"RR","") -> RR | B25: TRA | C25: TT | D25: TRABDS | J25: 0.0012602268 | L25: 4.392284 | P25: 0.39039817 | Q25: 0.069345968 | U25: 0.012983267 | V25: 0.34193177 | W25: 0.59372592 | AG25: 17.209033
A26: =IF(OR(C26="TT",C26="TR"),"RR","") -> RR | B26: TRA | C26: TT | D26: TRACOA | F26: 0.146157 | H26: 0.7101399 | I26: 0.035989733 | J26: 0.75160596 | P26: 0.017463143 | Q26: 0.0026293104 | S26: 0.0042998436 | U26: 0.44037181 | AF26: 0.41068321
A27: =IF(OR(C27="TT",C27="TR"),"RR","") -> RR | B27: TRA | C27: TT | D27: TRADST | E27: 2.6678206 | F27: 15.084555 | G27: 1.8757576 | H27: 4.2143198 | I27: 10.483391 | J27: 68.181624 | K27: 49.288199 | L27: 40.785771 | M27: 94.018199 | N27: 114.11818 | O27: 4.553258 | P27: 12.799981 | Q27: 3.5362676 | R27: 2.2759487 | S27: 8.3750654 | T27: 3.8659069 | U27: 14.919272 | V27: 4.9130172 | W27: 10.735198 | X27: 109.95602 | Y27: 0.0774558 | Z27: 27.067059 | AA27: 3.4297931 | AB27: 0.56947598 | AC27: 164.53398 | AE27: 5.0480499 | AF27: 27.030977 | AG27: 562.80223 | AK27: 1489
A28: =IF(OR(C28="TT",C28="TR"),"RR","") -> RR | B28: TRA | C28: TT | D28: TRAELC | E28: 7.7860747 | F28: 0.18188715 | G28: 3.6344857 | H28: 21.966142 | I28: 72.601574 | J28: 18.411118 | K28: 11.929839 | L28: 8.1020442 | N28: 351.09232 | O28: 13.254643 | P28: 26.296788 | Q28: 12.346513 | R28: 20.635628 | S28: 10.521495 | T28: 14.232742 | U28: 38.995236 | V28: 30.492908 | W28: 40.568401 | X28: 68.932798 | Y28: 1.5699244 | Z28: 3.9816007 | AB28: 2.1131994 | AC28: 190.37124 | AE28: 9.3600017 | AF28: 20.356774 | AG28: 26.401521
A29: =IF(OR(C29="TT",C29="TR"),"RR","") -> RR | B29: TRA | C29: TT | D29: TRAGSL | H29: 0.08267674 | K29: 0.044555926 | O29: 8.79228e-05 | R29: 0.010111122 | Y29: 0.022219348 | AC29: 1.196801 | AE29: 1.3372053 | AK29: 6344
A30: =IF(OR(C30="TT",C30="TR"),"RR","") -> RR | B30: TRA | C30: TT | D30: TRAHFO | E30: 4.2400017 | H30: 0.014046714 | J30: 0.0082563696 | K30: 0.0017040276 | AC30: 0.087198484 | AE30: 3.0902729 | AK30: 39.45
A31: =IF(OR(C31="TT",C31="TR"),"RR","") | B31: TRA | C31: TWD | D31: TRABDS | J31: 0.25656292 | O31: 0.16820469 | Q31: 0.11824779 | R31: 0.016964914 | T31: 0.10596372 | U31: 0.028968469 | V31: 0.1783828 | AB31: 4.1868e-05 | AG31: 4.5131527 | AK31: 14164
A32: =IF(OR(C32="TT",C32="TR"),"RR","") | B32: TRA | C32: TWD | D32: TRADST | E32: 2.2515982 | F32: 20.462294 | G32: 17.652453 | H32: 1.3265792 | I32: 52.541351 | J32: 232.61042 | K32: 14.617295 | L32: 13.32218 | M32: 31.609201 | N32: 622.70791 | O32: 10.993741 | P32: 1.8474757 | Q32: 21.490681 | R32: 23.319681 | S32: 4.135026 | T32: 20.691115 | U32: 23.018729 | V32: 7.330823 | W32: 11.246398 | X32: 35.081662 | Y32: 17.33295 | Z32: 26.123811 | AB32: 36.583388 | AC32: 17.106457 | AE32: 11.016965 | AF32: 36.848575 | AG32: 146.75257
A33: =IF(OR(C33="TT",C33="TR"),"RR","") | B33: TRA | C33: TWD | D33: TRAGSL | F33: 2.8287654 | G33: 0.020967494 | J33: 9.0982597 | K33: 11.24232 | O33: 1.3640008 | P33: 0.10238819 | Q33: 0.0018463788 | R33: 0.020238991 | U33: 0.82389944 | V33: 13.110286 | Y33: 0.31506089 | AB33: 2.6370978 | AC33: 0.5852016 | AE33: 0.038229671 | AG33: 198.209
A34: =IF(OR(C34="TT",C34="TR"),"RR","") | B34: TRA | C34: TWD | D34: TRAHFO | E34: 9.7814743 | F34: 0.26331623 | G34: 9.4408404 | I34: 94.339021 | J34: 17.339829 | K34: 7.7457433 | L34: 40.989354 | M34: 21.4668 | N34: 395.31816 | O34: 3.9209173 | Q34: 0.028001318 | R34: 29.446522 | T34: 25.903359 | U34: 1.3999989 | V34: 0.47387877 | X34: 29.293742 | Y34: 7.1833723 | Z34: 2.6532003 | AB34: 0.32504222 | AC34: 7.8600011 | AF34: 0.33040132 | AG34: 14.352564
A35: =IF(OR(C35="TT",C35="TR"),"RR","") | B35: TRA | C35: TWD | D35: TRANGA | AB35: 3.1542221 | AK35: 89.6
A36: =IF(OR(C36="TT",C36="TR"),"RR","") | B36: TRA | C36: TWI | D36: TRABDS | Q36: -1.9816836 | R36: -0.0015449292 | AG36: -8.5687467
A37: =IF(OR(C37="TT",C37="TR"),"RR","") | B37: TRA | C37: TWI | D37: TRADST | E37: -9.1431003 | F37: -35.018965 | G37: -3.3965415 | H37: -1.4358128 | I37: -67.518656 | J37: -196.70222 | K37: -5.1881695 | L37: -19.71809 | M37: -4.6860005 | N37: -177.87758 | O37: -38.84979 | P37: -25.386235 | Q37: -138.48621 | R37: -59.697609 | S37: -5.9606341 | T37: -74.435618 | U37: -8.3002975 | V37: -5.9298779 | W37: -30.075601 | X37: -2.3815021 | Y37: -65.907061 | Z37: -30.033001 | AA37: -35.604874 | AB37: -12.07582 | AC37: -364.01444 | AE37: -68.67503 | AF37: -87.642088 | AG37: -427.02095
A38: =IF(OR(C38="TT",C38="TR"),"RR","") | B38: TRA | C38: TWI | D38: TRAHFO | E38: -26.703469 | F38: -53.407918 | G38: -19.622569 | I38: -468.93261 | J38: -1904.0823 | K38: -40.581057 | L38: -119.43586 | M38: -18.813599 | N38: -701.8157 | O38: -88.967679 | P38: -13.961441 | Q38: -673.53079 | R38: -263.21381 | S38: -7.4917678 | T38: -261.79841 | U38: -30.72 | V38: -65.158239 | W38: -26.719999 | X38: -65.767439 | Y38: -272.17003 | Z38: -3.0168029 | AA38: -833.70405 | AB38: -2.1987608 | AC38: -88.48 | AD38: -135.01029 | AE38: -57.689934 | AF38: -179.67128 | AG38: -522.96715
A39: =IF(OR(C39="TT",C39="TR"),"RR","") | B39: TRA | C39: TWI | D39: TRAJTK
A40: =IF(OR(C40="TT",C40="TR"),"RR","") | B40: TRA | C40: TWI | D40: TRANGA | O40: -0.74190096 | P40: -0.8522985 | Q40: -2.8695364 | T40: -1.4913005 | AB40: -2.2015199
E42: =SUMIF($A$5:$A$40,"RR",E$5:E$40) -> 1905.6728 | F42: =SUMIF($A$5:$A$40,"RR",F$5:F$40) -> 2248.4139 | G42: =SUMIF($A$5:$A$40,"RR",G$5:G$40) -> 1044.6228 | H42: =SUMIF($A$5:$A$40,"RR",H$5:H$40) -> 801.28556 | I42: =SUMIF($A$5:$A$40,"RR",I$5:I$40) -> 4087.4506 | J42: =SUMIF($A$5:$A$40,"RR",J$5:J$40) -> 7011.5286 | K42: =SUMIF($A$5:$A$40,"RR",K$5:K$40) -> 1435.4073 | L42: =SUMIF($A$5:$A$40,"RR",L$5:L$40) -> 3358.6101 | ... AI42: =SUMIF($A$5:$A$40,"RR",AI$5:AI$40) -> 0
E43: =SUM(Assumptions!AN3:AN103) -> 1905.6728 | F43: =SUM(Assumptions!AO3:AO103) -> 2248.4139 | G43: =SUM(Assumptions!AP3:AP103) -> 1044.2078 | H43: =SUM(Assumptions!AQ3:AQ103) -> 801.08272 | I43: =SUM(Assumptions!AR3:AR103) -> 4087.2684 | J43: =SUM(Assumptions!AS3:AS103) -> 7011.5286 | K43: =SUM(Assumptions!AT3:AT103) -> 1435.4073 | L43: =SUM(Assumptions!AU3:AU103) -> 3358.6101 | ... AI43: =SUM(Assumptions!BR3:BR103) -> 0
...

Sheet 2-w
AI2: ~FI_T | AN2: ~FI_Process
C3: comm-in | D3: ='TRA balance'!E4 -> Africa_north | E3: ='TRA balance'!F4 -> Africa_other | F3: ='TRA balance'!G4 -> Arg-Chi | G3: ='TRA balance'!H4 -> Asia_central | H3: ='TRA balance'!I4 -> Asia_east | I3: ='TRA balance'!J4 -> Asia_other | J3: ='TRA balance'!K4 -> Australia_NZ | K3: ='TRA balance'!L4 -> Brazil | ... AG3: ='TRA balance'!AH4 -> \I: | AH3: * | AI3: attribute | AJ3: process | AK3: comm-out | AL3: LIFE | AN3: Sets | AO3: TechName | AP3: TechDesc | AQ3: Tact | AR3: Tcap | AS3: Vintage
A4: TR | C4: TRABDS | D4: {=SUM(SUMIFS(Assumptions!AN$3:AN$102,Assumptions!$B$3:$B$102,'2-w'!$C4,Assumptions!$G$3:$G$102,{"TRW"}))} -> 0 | E4: {=SUM(SUMIFS(Assumptions!AO$3:AO$102,Assumptions!$B$3:$B$102,'2-w'!$C4,Assumptions!$G$3:$G$102,{"TRW"}))} -> 0 | F4: {=SUM(SUMIFS(Assumptions!AP$3:AP$102,Assumptions!$B$3:$B$102,'2-w'!$C4,Assumptions!$G$3:$G$102,{"TRW"}))} -> 0 | G4: {=SUM(SUMIFS(Assumptions!AQ$3:AQ$102,Assumptions!$B$3:$B$102,'2-w'!$C4,Assumptions!$G$3:$G$102,{"TRW"}))} -> 0 | H4: {=SUM(SUMIFS(Assumptions!AR$3:AR$102,Assumptions!$B$3:$B$102,'2-w'!$C4,Assumptions!$G$3:$G$102,{"TRW"}))} -> 0 | I4: {=SUM(SUMIFS(Assumptions!AS$3:AS$102,Assumptions!$B$3:$B$102,'2-w'!$C4,Assumptions!$G$3:$G$102,{"TRW"}))} -> 0 | J4: {=SUM(SUMIFS(Assumptions!AT$3:AT$102,Assumptions!$B$3:$B$102,'2-w'!$C4,Assumptions!$G$3:$G$102,{"TRW"}))} -> 0 | K4: {=SUM(SUMIFS(Assumptions!AU$3:AU$102,Assumptions!$B$3:$B$102,'2-w'!$C4,Assumptions!$G$3:$G$102,{"TRW"}))} -> 0 | ... AG4: {=SUM(SUMIFS(Assumptions!BQ$3:BQ$102,Assumptions!$B$3:$B$102,'2-w'!$C4,Assumptions!$G$3:$G$102,{"TRW"}))} -> 0 | AH4: =IF(SUM(D4:AG4)=0,"zero","") -> zero | AI4: * | AK4: =IF($AJ4="","",$AK$45) | AL4: =IF($AJ4="","",25) | AN4: =IF($AJ4="","*","DMD") -> * | AO4: =AJ4 -> 0 | AQ4: Bvkm | AR4: million Vehicles | AS4: yes
A5: TR | C5: TRABGS | D5: {=SUM(SUMIFS(Assumptions!AN$3:AN$102,Assumptions!$B$3:$B$102,'2-w'!$C5,Assumptions!$G$3:$G$102,{"TRW"}))} -> 0 | E5: {=SUM(SUMIFS(Assumptions!AO$3:AO$102,Assumptions!$B$3:$B$102,'2-w'!$C5,Assumptions!$G$3:$G$102,{"TRW"}))} -> 0.67275156 | F5: {=SUM(SUMIFS(Assumptions!AP$3:AP$102,Assumptions!$B$3:$B$102,'2-w'!$C5,Assumptions!$G$3:$G$102,{"TRW"}))} -> 0.30447457 | G5: {=SUM(SUMIFS(Assumptions!AQ$3:AQ$102,Assumptions!$B$3:$B$102,'2-w'!$C5,Assumptions!$G$3:$G$102,{"TRW"}))} -> 0 | H5: {=SUM(SUMIFS(Assumptions!AR$3:AR$102,Assumptions!$B$3:$B$102,'2-w'!$C5,Assumptions!$G$3:$G$102,{"TRW"}))} -> 0.14973164 | I5: {=SUM(SUMIFS(Assumptions!AS$3:AS$102,Assumptions!$B$3:$B$102,'2-w'!$C5,Assumptions!$G$3:$G$102,{"TRW"}))} -> 18.659349 | J5: {=SUM(SUMIFS(Assumptions!AT$3:AT$102,Assumptions!$B$3:$B$102,'2-w'!$C5,Assumptions!$G$3:$G$102,{"TRW"}))} -> 0.098269103 | K5: {=SUM(SUMIFS(Assumptions!AU$3:AU$102,Assumptions!$B$3:$B$102,'2-w'!$C5,Assumptions!$G$3:$G$102,{"TRW"}))} -> 3.1853729 | ... AG5: {=SUM(SUMIFS(Assumptions!BQ$3:BQ$102,Assumptions!$B$3:$B$102,'2-w'!$C5,Assumptions!$G$3:$G$102,{"TRW"}))} -> 0 | AH5: =IF(SUM(D5:AG5)=0,"zero","") | AI5: * | AK5: =IF($AJ5="","",$AK$45) | AL5: =IF($AJ5="","",25) | AN5: =IF(AJ5="","*","DMD") -> * | AO5: =AJ5 -> 0 | AQ5: Bvkm | AR5: million Vehicles | AS5: yes
A6: TR | C6: TRADST | D6: {=SUM(SUMIFS(Assumptions!AN$3:AN$102,Assumptions!$B$3:$B$102,'2-w'!$C6,Assumptions!$G$3:$G$102,{"TRW"}))} -> 0 | E6: {=SUM(SUMIFS(Assumptions!AO$3:AO$102,Assumptions!$B$3:$B$102,'2-w'!$C6,Assumptions!$G$3:$G$102,{"TRW"}))} -> 0 | F6: {=SUM(SUMIFS(Assumptions!AP$3:AP$102,Assumptions!$B$3:$B$102,'2-w'!$C6,Assumptions!$G$3:$G$102,{"TRW"}))} -> 0 | G6: {=SUM(SUMIFS(Assumptions!AQ$3:AQ$102,Assumptions!$B$3:$B$102,'2-w'!$C6,Assumptions!$G$3:$G$102,{"TRW"}))} -> 0 | H6: {=SUM(SUMIFS(Assumptions!AR$3:AR$102,Assumptions!$B$3:$B$102,'2-w'!$C6,Assumptions!$G$3:$G$102,{"TRW"}))} -> 0 | I6: {=SUM(SUMIFS(Assumptions!AS$3:AS$102,Assumptions!$B$3:$B$102,'2-w'!$C6,Assumptions!$G$3:$G$102,{"TRW"}))} -> 0 | J6: {=SUM(SUMIFS(Assumptions!AT$3:AT$102,Assumptions!$B$3:$B$102,'2-w'!$C6,Assumptions!$G$3:$G$102,{"TRW"}))} -> 0 | K6: {=SUM(SUMIFS(Assumptions!AU$3:AU$102,Assumptions!$B$3:$B$102,'2-w'!$C6,Assumptions!$G$3:$G$102,{"TRW"}))} -> 0 | ... AG6: {=SUM(SUMIFS(Assumptions!BQ$3:BQ$102,Assumptions!$B$3:$B$102,'2-w'!$C6,Assumptions!$G$3:$G$102,{"TRW"}))} -> 0 | AH6: =IF(SUM(D6:AG6)=0,"zero","") -> zero | AI6: * | AK6: =IF($AJ6="","",$AK$45) | AL6: =IF($AJ6="","",25) | AN6: =IF(AJ6="","*","DMD") -> * | AO6: =AJ6 -> 0 | AQ6: Bvkm | AR6: million Vehicles | AS6: yes
A7: TR | C7: TRAELC | D7: {=SUM(SUMIFS(Assumptions!AN$3:AN$102,Assumptions!$B$3:$B$102,'2-w'!$C7,Assumptions!$G$3:$G$102,{"TRW"}))} -> 0 | E7: {=SUM(SUMIFS(Assumptions!AO$3:AO$102,Assumptions!$B$3:$B$102,'2-w'!$C7,Assumptions!$G$3:$G$102,{"TRW"}))} -> 0 | F7: {=SUM(SUMIFS(Assumptions!AP$3:AP$102,Assumptions!$B$3:$B$102,'2-w'!$C7,Assumptions!$G$3:$G$102,{"TRW"}))} -> 0 | G7: {=SUM(SUMIFS(Assumptions!AQ$3:AQ$102,Assumptions!$B$3:$B$102,'2-w'!$C7,Assumptions!$G$3:$G$102,{"TRW"}))} -> 0 | H7: {=SUM(SUMIFS(Assumptions!AR$3:AR$102,Assumptions!$B$3:$B$102,'2-w'!$C7,Assumptions!$G$3:$G$102,{"TRW"}))} -> 0 | I7: {=SUM(SUMIFS(Assumptions!AS$3:AS$102,Assumptions!$B$3:$B$102,'2-w'!$C7,Assumptions!$G$3:$G$102,{"TRW"}))} -> 0 | J7: {=SUM(SUMIFS(Assumptions!AT$3:AT$102,Assumptions!$B$3:$B$102,'2-w'!$C7,Assumptions!$G$3:$G$102,{"TRW"}))} -> 0 | K7: {=SUM(SUMIFS(Assumptions!AU$3:AU$102,Assumptions!$B$3:$B$102,'2-w'!$C7,Assumptions!$G$3:$G$102,{"TRW"}))} -> 0 | ... AG7: {=SUM(SUMIFS(Assumptions!BQ$3:BQ$102,Assumptions!$B$3:$B$102,'2-w'!$C7,Assumptions!$G$3:$G$102,{"TRW"}))} -> 0 | AH7: =IF(SUM(D7:AG7)=0,"zero","") -> zero | AI7: * | AK7: =IF($AJ7="","",$AK$45) | AL7: =IF($AJ7="","",25) | AN7: =IF(AJ7="","*","DMD") -> * | AO7: =AJ7 -> 0 | AQ7: Bvkm | AR7: million Vehicles | AS7: yes
A8: TR | C8: TRAGSL | D8: {=SUM(SUMIFS(Assumptions!AN$3:AN$102,Assumptions!$B$3:$B$102,'2-w'!$C8,Assumptions!$G$3:$G$102,{"TRW"}))} -> 250.4846 | E8: {=SUM(SUMIFS(Assumptions!AO$3:AO$102,Assumptions!$B$3:$B$102,'2-w'!$C8,Assumptions!$G$3:$G$102,{"TRW"}))} -> 434.96326 | F8: {=SUM(SUMIFS(Assumptions!AP$3:AP$102,Assumptions!$B$3:$B$102,'2-w'!$C8,Assumptions!$G$3:$G$102,{"TRW"}))} -> 5.5378014 | G8: {=SUM(SUMIFS(Assumptions!AQ$3:AQ$102,Assumptions!$B$3:$B$102,'2-w'!$C8,Assumptions!$G$3:$G$102,{"TRW"}))} -> 4.3074478 | H8: {=SUM(SUMIFS(Assumptions!AR$3:AR$102,Assumptions!$B$3:$B$102,'2-w'!$C8,Assumptions!$G$3:$G$102,{"TRW"}))} -> 18.154842 | I8: {=SUM(SUMIFS(Assumptions!AS$3:AS$102,Assumptions!$B$3:$B$102,'2-w'!$C8,Assumptions!$G$3:$G$102,{"TRW"}))} -> 1243.7969 | J8: {=SUM(SUMIFS(Assumptions!AT$3:AT$102,Assumptions!$B$3:$B$102,'2-w'!$C8,Assumptions!$G$3:$G$102,{"TRW"}))} -> 12.146635 | K8: {=SUM(SUMIFS(Assumptions!AU$3:AU$102,Assumptions!$B$3:$B$102,'2-w'!$C8,Assumptions!$G$3:$G$102,{"TRW"}))} -> 12.125455 | ... AG8: {=SUM(SUMIFS(Assumptions!BQ$3:BQ$102,Assumptions!$B$3:$B$102,'2-w'!$C8,Assumptions!$G$3:$G$102,{"TRW"}))} -> 0 | AH8: =IF(SUM(D8:AG8)=0,"zero","") | AI8: * | AK8: =IF($AJ8="","",$AK$45) | AL8: =IF($AJ8="","",25) | AN8: =IF(AJ8="","*","DMD") -> * | AO8: =AJ8 -> 0 | AQ8: Bvkm | AR8: million Vehicles | AS8: yes
A9: TR | C9: TRALPG | D9: {=SUM(SUMIFS(Assumptions!AN$3:AN$102,Assumptions!$B$3:$B$102,'2-w'!$C9,Assumptions!$G$3:$G$102,{"TRW"}))} -> 0 | E9: {=SUM(SUMIFS(Assumptions!AO$3:AO$102,Assumptions!$B$3:$B$102,'2-w'!$C9,Assumptions!$G$3:$G$102,{"TRW"}))} -> 0 | F9: {=SUM(SUMIFS(Assumptions!AP$3:AP$102,Assumptions!$B$3:$B$102,'2-w'!$C9,Assumptions!$G$3:$G$102,{"TRW"}))} -> 0 | G9: {=SUM(SUMIFS(Assumptions!AQ$3:AQ$102,Assumptions!$B$3:$B$102,'2-w'!$C9,Assumptions!$G$3:$G$102,{"TRW"}))} -> 0 | H9: {=SUM(SUMIFS(Assumptions!AR$3:AR$102,Assumptions!$B$3:$B$102,'2-w'!$C9,Assumptions!$G$3:$G$102,{"TRW"}))} -> 0 | I9: {=SUM(SUMIFS(Assumptions!AS$3:AS$102,Assumptions!$B$3:$B$102,'2-w'!$C9,Assumptions!$G$3:$G$102,{"TRW"}))} -> 0 | J9: {=SUM(SUMIFS(Assumptions!AT$3:AT$102,Assumptions!$B$3:$B$102,'2-w'!$C9,Assumptions!$G$3:$G$102,{"TRW"}))} -> 0 | K9: {=SUM(SUMIFS(Assumptions!AU$3:AU$102,Assumptions!$B$3:$B$102,'2-w'!$C9,Assumptions!$G$3:$G$102,{"TRW"}))} -> 0 | ... AG9: {=SUM(SUMIFS(Assumptions!BQ$3:BQ$102,Assumptions!$B$3:$B$102,'2-w'!$C9,Assumptions!$G$3:$G$102,{"TRW"}))} -> 0 | AH9: =IF(SUM(D9:AG9)=0,"zero","") -> zero | AI9: * | AK9: =IF($AJ9="","",$AK$45) | AL9: =IF($AJ9="","",25) | AN9: =IF(AJ9="","*","DMD") -> * | AO9: =AJ9 -> 0 | AQ9: Bvkm | AR9: million Vehicles | AS9: yes
A10: TR | C10: TRANGA | D10: {=SUM(SUMIFS(Assumptions!AN$3:AN$102,Assumptions!$B$3:$B$102,'2-w'!$C10,Assumptions!$G$3:$G$102,{"TRW"}))} -> 0 | E10: {=SUM(SUMIFS(Assumptions!AO$3:AO$102,Assumptions!$B$3:$B$102,'2-w'!$C10,Assumptions!$G$3:$G$102,{"TRW"}))} -> 0 | F10: {=SUM(SUMIFS(Assumptions!AP$3:AP$102,Assumptions!$B$3:$B$102,'2-w'!$C10,Assumptions!$G$3:$G$102,{"TRW"}))} -> 0 | G10: {=SUM(SUMIFS(Assumptions!AQ$3:AQ$102,Assumptions!$B$3:$B$102,'2-w'!$C10,Assumptions!$G$3:$G$102,{"TRW"}))} -> 0 | H10: {=SUM(SUMIFS(Assumptions!AR$3:AR$102,Assumptions!$B$3:$B$102,'2-w'!$C10,Assumptions!$G$3:$G$102,{"TRW"}))} -> 0 | I10: {=SUM(SUMIFS(Assumptions!AS$3:AS$102,Assumptions!$B$3:$B$102,'2-w'!$C10,Assumptions!$G$3:$G$102,{"TRW"}))} -> 0 | J10: {=SUM(SUMIFS(Assumptions!AT$3:AT$102,Assumptions!$B$3:$B$102,'2-w'!$C10,Assumptions!$G$3:$G$102,{"TRW"}))} -> 0 | K10: {=SUM(SUMIFS(Assumptions!AU$3:AU$102,Assumptions!$B$3:$B$102,'2-w'!$C10,Assumptions!$G$3:$G$102,{"TRW"}))} -> 0 | ... AG10: {=SUM(SUMIFS(Assumptions!BQ$3:BQ$102,Assumptions!$B$3:$B$102,'2-w'!$C10,Assumptions!$G$3:$G$102,{"TRW"}))} -> 0 | AH10: =IF(SUM(D10:AG10)=0,"zero","") -> zero | AI10: * | AK10: =IF($AJ10="","",$AK$45) | AL10: =IF($AJ10="","",25) | AN10: =IF(AJ10="","*","DMD") -> * | AO10: =AJ10 -> 0 | AQ10: Bvkm | AR10: million Vehicles | AS10: yes
A11: Share of PJ | D11: =SUM(D$4:D$10)/SUM($D$4:$T$10) -> 0.06801815 | E11: =SUM(E$4:E$10)/SUM($D$4:$T$10) -> 0.11829532 | F11: =SUM(F$4:F$10)/SUM($D$4:$T$10) -> 0.001586448 | G11: =SUM(G$4:G$10)/SUM($D$4:$T$10) -> 0.0011696712 | H11: =SUM(H$4:H$10)/SUM($D$4:$T$10) -> 0.0049705381 | I11: =SUM(I$4:I$10)/SUM($D$4:$T$10) -> 0.34281524 | J11: =SUM(J$4:J$10)/SUM($D$4:$T$10) -> 0.0033250575 | K11: =SUM(K$4:K$10)/SUM($D$4:$T$10) -> 0.0041575976 | ... AG11: =SUM(AG$4:AG$10)/SUM($D$4:$T$10) -> 0 | AI11: * | AK11: =IF($AJ11="","",$AK$45) | AL11: =IF($AJ11="","",25) | AN11: =IF(AJ11="","*","DMD") -> * | AO11: =AJ11 -> 0 | AQ11: Bvkm | AR11: million Vehicles | AS11: yes
AI12: * | AK12: =IF($AJ12="","",$AK$45) | AL12: =IF($AJ12="","",25) | AN12: =IF(AJ12="","*","DMD") -> * | AO12: =AJ12 -> 0 | AQ12: Bvkm | AR12: million Vehicles | AS12: yes
A13: m Vehicles | C13: =SUM(D13:T13) -> 520.81 | D13: =SUM(D19:D25) -> 35.43 | E13: =SUM(E19:E25) -> 61.62 | F13: =SUM(F19:F25) -> 0.82 | G13: =SUM(G19:G25) -> 0.61 | H13: =SUM(H19:H25) -> 2.59 | I13: =SUM(I19:I25) -> 178.55 | J13: =SUM(J19:J25) -> 1.73 | K13: =SUM(K19:K25) -> 2.16 | ... AG13: =SUM(AG19:AG25) -> 0 | AI13: * | AK13: =IF($AJ13="","",$AK$45) | AL13: =IF($AJ13="","",25) | AN13: =IF(AJ13="","*","DMD") -> * | AO13: =AJ13 -> 0 | AQ13: Bvkm | AR13: million Vehicles | AS13: yes
A14: Share of Veh | D14: =D13/SUM($D$13:$T$13) -> 0.068028648 | E14: =E13/SUM($D$13:$T$13) -> 0.1183157 | F14: =F13/SUM($D$13:$T$13) -> 0.0015744705 | G14: =G13/SUM($D$13:$T$13) -> 0.0011712525 | H14: =H13/SUM($D$13:$T$13) -> 0.0049730228 | I14: =I13/SUM($D$13:$T$13) -> 0.34283136 | J14: =J13/SUM($D$13:$T$13) -> 0.0033217488 | K14: =K13/SUM($D$13:$T$13) -> 0.0041473858 | ... AG14: =AG13/SUM($D$13:$T$13) -> 0 | AI14: * | AK14: =IF($AJ14="","",$AK$45) | AL14: =IF($AJ14="","",25) | AN14: =IF(AJ14="","*","DMD") -> * | AO14: =AJ14 -> 0 | AQ14: Bvkm | AR14: million Vehicles | AS14: yes
AI15: * | AK15: =IF($AJ15="","",$AK$45) | AL15: =IF($AJ15="","",25) | AN15: =IF(AJ15="","*","DMD") -> * | AO15: =AJ15 -> 0 | AQ15: Bvkm | AR15: million Vehicles | AS15: yes
AI16: * | AK16: =IF($AJ16="","",$AK$45) | AL16: =IF($AJ16="","",25) | AN16: =IF(AJ16="","*","DMD") -> * | AO16: =AJ16 -> 0 | AQ16: Bvkm | AR16: million Vehicles | AS16: yes
A17: PJ share/Veh share | D17: =IFERROR(D11/D14,"") -> 0.99984569 | E17: =IFERROR(E11/E14,"") -> 0.99982773 | F17: =IFERROR(F11/F14,"") -> 1.0076073 | G17: =IFERROR(G11/G14,"") -> 0.99864995 | H17: =IFERROR(H11/H14,"") -> 0.99950037 | I17: =IFERROR(I11/I14,"") -> 0.99995299 | J17: =IFERROR(J11/J14,"") -> 1.0009961 | K17: =IFERROR(K11/K14,"") -> 1.0024622 | ... AG17: =IFERROR(AG11/AG14,"") | AI17: * | AK17: =IF($AJ17="","",$AK$45) | AL17: =IF($AJ17="","",25) | AN17: =IF(AJ17="","*","DMD") -> * | AO17: =AJ17 -> 0 | AQ17: Bvkm | AR17: million Vehicles | AS17: yes
AI18: * | AK18: =IF($AJ18="","",$AK$45) | AL18: =IF($AJ18="","",25) | AN18: =IF(AJ18="","*","DMD") -> * | AO18: =AJ18 -> 0 | AQ18: Bvkm | AR18: million Vehicles | AS18: yes
A19: mVeh | C19: =C4 -> TRABDS | D19: =ROUND(D4*D28/D36,2) -> 0 | E19: =ROUND(E4*E28/E36,2) -> 0 | F19: =ROUND(F4*F28/F36,2) -> 0 | G19: =ROUND(G4*G28/G36,2) -> 0 | H19: =ROUND(H4*H28/H36,2) -> 0 | I19: =ROUND(I4*I28/I36,2) -> 0 | J19: =ROUND(J4*J28/J36,2) -> 0 | K19: =ROUND(K4*K28/K36,2) -> 0 | ... AG19: =ROUND(AG4*AG28/AG36,2) -> 0 | AI19: PASTI | AJ19: =IF(AH4="zero","\I:",$AK$45&"_"&VLOOKUP(C19,'TRA balance'!$AL$5:$AM$15,2,FALSE)) -> \I: | AK19: =IF($AJ19="","",$AK$45) -> Trd_2w | AL19: =IF($AJ19="","",25) -> 25 | AN19: =IF(AJ19="","*","DMD") -> DMD | AO19: =AJ19 -> \I: | AQ19: Bvkm | AR19: million Vehicles | AS19: yes
C20: =C5 -> TRABGS | D20: =ROUND(D5*D29/D37,2) -> 0 | E20: =ROUND(E5*E29/E37,2) -> 0.1 | F20: =ROUND(F5*F29/F37,2) -> 0.04 | G20: =ROUND(G5*G29/G37,2) -> 0 | H20: =ROUND(H5*H29/H37,2) -> 0.02 | I20: =ROUND(I5*I29/I37,2) -> 2.64 | J20: =ROUND(J5*J29/J37,2) -> 0.01 | K20: =ROUND(K5*K29/K37,2) -> 0.45 | ... AG20: =ROUND(AG5*AG29/AG37,2) -> 0 | AI20: PASTI | AJ20: =IF(AH5="zero","\I:",$AK$45&"_"&VLOOKUP(C20,'TRA balance'!$AL$5:$AM$15,2,FALSE)) -> Trd_2w_eth | AK20: =IF($AJ20="","",$AK$45) -> Trd_2w | AL20: =IF($AJ20="","",25) -> 25 | AN20: =IF(AJ20="","*","DMD") -> DMD | AO20: =AJ20 -> Trd_2w_eth | AQ20: Bvkm | AR20: million Vehicles | AS20: yes
C21: =C6 -> TRADST | D21: =ROUND(D6*D30/D38,2) -> 0 | E21: =ROUND(E6*E30/E38,2) -> 0 | F21: =ROUND(F6*F30/F38,2) -> 0 | G21: =ROUND(G6*G30/G38,2) -> 0 | H21: =ROUND(H6*H30/H38,2) -> 0 | I21: =ROUND(I6*I30/I38,2) -> 0 | J21: =ROUND(J6*J30/J38,2) -> 0 | K21: =ROUND(K6*K30/K38,2) -> 0 | ... AG21: =ROUND(AG6*AG30/AG38,2) -> 0 | AI21: PASTI | AJ21: =IF(AH6="zero","\I:",$AK$45&"_"&VLOOKUP(C21,'TRA balance'!$AL$5:$AM$15,2,FALSE)) -> \I: | AK21: =IF($AJ21="","",$AK$45) -> Trd_2w | AL21: =IF($AJ21="","",25) -> 25 | AN21: =IF(AJ21="","*","DMD") -> DMD | AO21: =AJ21 -> \I: | AQ21: Bvkm | AR21: million Vehicles | AS21: yes
C22: =C7 -> TRAELC | D22: =ROUND(D7*D31/D39,2) -> 0 | E22: =ROUND(E7*E31/E39,2) -> 0 | F22: =ROUND(F7*F31/F39,2) -> 0 | G22: =ROUND(G7*G31/G39,2) -> 0 | H22: =ROUND(H7*H31/H39,2) -> 0 | I22: =ROUND(I7*I31/I39,2) -> 0 | J22: =ROUND(J7*J31/J39,2) -> 0 | K22: =ROUND(K7*K31/K39,2) -> 0 | ... AG22: =ROUND(AG7*AG31/AG39,2) -> 0 | AI22: PASTI | AJ22: =IF(AH7="zero","\I:",$AK$45&"_"&VLOOKUP(C22,'TRA balance'!$AL$5:$AM$15,2,FALSE)) -> \I: | AK22: =IF($AJ22="","",$AK$45) -> Trd_2w | AL22: =IF($AJ22="","",25) -> 25 | AN22: =IF(AJ22="","*","DMD") -> DMD | AO22: =AJ22 -> \I: | AQ22: Bvkm | AR22: million Vehicles | AS22: yes
C23: =C8 -> TRAGSL | D23: =ROUND(D8*D32/D40,2) -> 35.43 | E23: =ROUND(E8*E32/E40,2) -> 61.52 | F23: =ROUND(F8*F32/F40,2) -> 0.78 | G23: =ROUND(G8*G32/G40,2) -> 0.61 | H23: =ROUND(H8*H32/H40,2) -> 2.57 | I23: =ROUND(I8*I32/I40,2) -> 175.91 | J23: =ROUND(J8*J32/J40,2) -> 1.72 | K23: =ROUND(K8*K32/K40,2) -> 1.71 | ... AG23: =ROUND(AG8*AG32/AG40,2) -> 0 | AI23: PASTI | AJ23: =IF(AH8="zero","\I:",$AK$45&"_"&VLOOKUP(C23,'TRA balance'!$AL$5:$AM$15,2,FALSE)) -> Trd_2w_gsl | AK23: =IF($AJ23="","",$AK$45) -> Trd_2w | AL23: =IF($AJ23="","",25) -> 25 | AN23: =IF(AJ23="","*","DMD") -> DMD | AO23: =AJ23 -> Trd_2w_gsl | AQ23: Bvkm | AR23: million Vehicles | AS23: yes
C24: =C9 -> TRALPG | D24: =ROUND(D9*D33/D41,2) -> 0 | E24: =ROUND(E9*E33/E41,2) -> 0 | F24: =ROUND(F9*F33/F41,2) -> 0 | G24: =ROUND(G9*G33/G41,2) -> 0 | H24: =ROUND(H9*H33/H41,2) -> 0 | I24: =ROUND(I9*I33/I41,2) -> 0 | J24: =ROUND(J9*J33/J41,2) -> 0 | K24: =ROUND(K9*K33/K41,2) -> 0 | ... AG24: =ROUND(AG9*AG33/AG41,2) -> 0 | AI24: PASTI | AJ24: =IF(AH9="zero","\I:",$AK$45&"_"&VLOOKUP(C24,'TRA balance'!$AL$5:$AM$15,2,FALSE)) -> \I: | AK24: =IF($AJ24="","",$AK$45) -> Trd_2w | AL24: =IF($AJ24="","",25) -> 25 | AN24: =IF(AJ24="","*","DMD") -> DMD | AO24: =AJ24 -> \I: | AQ24: Bvkm | AR24: million Vehicles | AS24: yes
C25: =C10 -> TRANGA | D25: =ROUND(D10*D34/D42,2) -> 0 | E25: =ROUND(E10*E34/E42,2) -> 0 | F25: =ROUND(F10*F34/F42,2) -> 0 | G25: =ROUND(G10*G34/G42,2) -> 0 | H25: =ROUND(H10*H34/H42,2) -> 0 | I25: =ROUND(I10*I34/I42,2) -> 0 | J25: =ROUND(J10*J34/J42,2) -> 0 | K25: =ROUND(K10*K34/K42,2) -> 0 | ... AG25: =ROUND(AG10*AG34/AG42,2) -> 0 | AI25: PASTI | AJ25: =IF(AH10="zero","\I:",$AK$45&"_"&VLOOKUP(C25,'TRA balance'!$AL$5:$AM$15,2,FALSE)) -> \I: | AK25: =IF($AJ25="","",$AK$45) -> Trd_2w | AL25: =IF($AJ25="","",25) -> 25 | AN25: =IF(AJ25="","*","DMD") -> DMD | AO25: =AJ25 -> \I: | AQ25: Bvkm | AR25: million Vehicles | AS25: yes
AI26: * | AK26: =IF($AJ26="","",$AK$45) | AL26: =IF($AJ26="","",25) | AN26: =IF(AJ26="","*","DMD") -> * | AO26: =AJ26 -> 0 | AQ26: Bvkm | AR26: million Vehicles | AS26: yes
D27: 1 | E27: 1 | F27: 1 | G27: 1 | H27: 1 | I27: 1 | J27: 1 | K27: 1 | L27: 1 | M27: 1 | N27: 1 | O27: 1 | P27: 1 | Q27: 1 | R27: 1 | S27: 1 | T27: 1 | U27: 1 | V27: 1 | W27: 1 | X27: 1 | Y27: 1 | Z27: 1 | AA27: 1 | AB27: 1 | AC27: 1 | AD27: 1 | AE27: 1 | AF27: 1 | AG27: 1 | AI27: * | AK27: =IF($AJ27="","",$AK$45) | AL27: =IF($AJ27="","",25) | AN27: =IF(AJ27="","*","DMD") -> * | AO27: =AJ27 -> 0 | AQ27: Bvkm | AR27: million Vehicles | AS27: yes
A28: Efficiency | C28: =C19 -> TRABDS | D28: =$AH28*D$27 -> 0.99 | E28: =$AH28*E$27 -> 0.99 | F28: =$AH28*F$27 -> 0.99 | G28: =$AH28*G$27 -> 0.99 | H28: =$AH28*H$27 -> 0.99 | I28: =$AH28*I$27 -> 0.99 | J28: =$AH28*J$27 -> 0.99 | K28: =$AH28*K$27 -> 0.99 | ... AG28: =$AH28*AG$27 -> 0.99 | AH28: 0.99 | AI28: EFF | AJ28: =AJ19 -> \I: | AK28: =IF($AJ28="","",$AK$45) -> Trd_2w | AL28: =IF($AJ28="","",25) -> 25 | AN28: =IF(AJ28="","*","DMD") -> DMD | AO28: =AJ28 -> \I: | AQ28: Bvkm | AR28: million Vehicles | AS28: yes
C29: =C20 -> TRABGS | D29: =$AH29*D$27 -> 0.99 | E29: =$AH29*E$27 -> 0.99 | F29: =$AH29*F$27 -> 0.99 | G29: =$AH29*G$27 -> 0.99 | H29: =$AH29*H$27 -> 0.99 | I29: =$AH29*I$27 -> 0.99 | J29: =$AH29*J$27 -> 0.99 | K29: =$AH29*K$27 -> 0.99 | ... AG29: =$AH29*AG$27 -> 0.99 | AH29: 0.99 | AI29: EFF | AJ29: =AJ20 -> Trd_2w_eth | AK29: =IF($AJ29="","",$AK$45) -> Trd_2w | AL29: =IF($AJ29="","",25) -> 25 | AN29: =IF(AJ29="","*","DMD") -> DMD | AO29: =AJ29 -> Trd_2w_eth | AQ29: Bvkm | AR29: million Vehicles | AS29: yes
C30: =C21 -> TRADST | D30: =$AH30*D$27 -> 0.99 | E30: =$AH30*E$27 -> 0.99 | F30: =$AH30*F$27 -> 0.99 | G30: =$AH30*G$27 -> 0.99 | H30: =$AH30*H$27 -> 0.99 | I30: =$AH30*I$27 -> 0.99 | J30: =$AH30*J$27 -> 0.99 | K30: =$AH30*K$27 -> 0.99 | ... AG30: =$AH30*AG$27 -> 0.99 | AH30: 0.99 | AI30: EFF | AJ30: =AJ21 -> \I: | AK30: =IF($AJ30="","",$AK$45) -> Trd_2w | AL30: =IF($AJ30="","",25) -> 25 | AN30: =IF(AJ30="","*","DMD") -> DMD | AO30: =AJ30 -> \I: | AQ30: Bvkm | AR30: million Vehicles | AS30: yes
C31: =C22 -> TRAELC | D31: =$AH31*D$27 -> 0.99 | E31: =$AH31*E$27 -> 0.99 | F31: =$AH31*F$27 -> 0.99 | G31: =$AH31*G$27 -> 0.99 | H31: =$AH31*H$27 -> 0.99 | I31: =$AH31*I$27 -> 0.99 | J31: =$AH31*J$27 -> 0.99 | K31: =$AH31*K$27 -> 0.99 | ... AG31: =$AH31*AG$27 -> 0.99 | AH31: 0.99 | AI31: EFF | AJ31: =AJ22 -> \I: | AK31: =IF($AJ31="","",$AK$45) -> Trd_2w | AL31: =IF($AJ31="","",25) -> 25 | AN31: =IF(AJ31="","*","DMD") -> DMD | AO31: =AJ31 -> \I: | AQ31: Bvkm | AR31: million Vehicles | AS31: yes
C32: =C23 -> TRAGSL | D32: =$AH32*D$27 -> 0.99 | E32: =$AH32*E$27 -> 0.99 | F32: =$AH32*F$27 -> 0.99 | G32: =$AH32*G$27 -> 0.99 | H32: =$AH32*H$27 -> 0.99 | I32: =$AH32*I$27 -> 0.99 | J32: =$AH32*J$27 -> 0.99 | K32: =$AH32*K$27 -> 0.99 | ... AG32: =$AH32*AG$27 -> 0.99 | AH32: 0.99 | AI32: EFF | AJ32: =AJ23 -> Trd_2w_gsl | AK32: =IF($AJ32="","",$AK$45) -> Trd_2w | AL32: =IF($AJ32="","",25) -> 25 | AN32: =IF(AJ32="","*","DMD") -> DMD | AO32: =AJ32 -> Trd_2w_gsl | AQ32: Bvkm | AR32: million Vehicles | AS32: yes
C33: =C24 -> TRALPG | D33: =$AH33*D$27 -> 0.99 | E33: =$AH33*E$27 -> 0.99 | F33: =$AH33*F$27 -> 0.99 | G33: =$AH33*G$27 -> 0.99 | H33: =$AH33*H$27 -> 0.99 | I33: =$AH33*I$27 -> 0.99 | J33: =$AH33*J$27 -> 0.99 | K33: =$AH33*K$27 -> 0.99 | ... AG33: =$AH33*AG$27 -> 0.99 | AH33: 0.99 | AI33: EFF | AJ33: =AJ24 -> \I: | AK33: =IF($AJ33="","",$AK$45) -> Trd_2w | AL33: =IF($AJ33="","",25) -> 25 | AN33: =IF(AJ33="","*","DMD") -> DMD | AO33: =AJ33 -> \I: | AQ33: Bvkm | AR33: million Vehicles | AS33: yes
C34: =C25 -> TRANGA | D34: =$AH34*D$27 -> 0.99 | E34: =$AH34*E$27 -> 0.99 | F34: =$AH34*F$27 -> 0.99 | G34: =$AH34*G$27 -> 0.99 | H34: =$AH34*H$27 -> 0.99 | I34: =$AH34*I$27 -> 0.99 | J34: =$AH34*J$27 -> 0.99 | K34: =$AH34*K$27 -> 0.99 | ... AG34: =$AH34*AG$27 -> 0.99 | AH34: 0.99 | AI34: EFF | AJ34: =AJ25 -> \I: | AK34: =IF($AJ34="","",$AK$45) -> Trd_2w | AL34: =IF($AJ34="","",25) -> 25 | AN34: =IF(AJ34="","*","DMD") -> DMD | AO34: =AJ34 -> \I: | AQ34: Bvkm | AR34: million Vehicles | AS34: yes
AI35: * | AK35: =IF($AJ35="","",$AK$45) | AL35: =IF($AJ35="","",25) | AN35: =IF(AJ35="","*","DMD") -> * | AO35: =AJ35 -> 0 | AQ35: Bvkm | AR35: million Vehicles | AS35: yes
A36: 000km/veh | C36: =C28 -> TRABDS | D36: 7 | E36: 7 | F36: 7 | G36: 7 | H36: 7 | I36: 7 | J36: 7 | K36: 7 | L36: 7 | M36: 7 | N36: 7 | O36: 7 | P36: 7 | Q36: 7 | R36: 7 | S36: 7 | T36: 7 | U36: 7 | V36: 7 | W36: 7 | X36: 7 | Y36: 7 | Z36: 7 | AA36: 7 | AB36: 7 | AC36: 7 | AD36: 7 | AE36: 7 | AF36: 7 | AG36: 7 | AI36: AF | AJ36: =AJ28 -> \I: | AK36: =IF($AJ36="","",$AK$45) -> Trd_2w | AL36: =IF($AJ36="","",25) -> 25 | AN36: =IF(AJ36="","*","DMD") -> DMD | AO36: =AJ36 -> \I: | AQ36: Bvkm | AR36: million Vehicles | AS36: yes
C37: =C29 -> TRABGS | D37: =D$36 -> 7 | E37: =E$36 -> 7 | F37: =F$36 -> 7 | G37: =G$36 -> 7 | H37: =H$36 -> 7 | I37: =I$36 -> 7 | J37: =J$36 -> 7 | K37: =K$36 -> 7 | ... AG37: =AG$36 -> 7 | AI37: AF | AJ37: =AJ29 -> Trd_2w_eth | AK37: =IF($AJ37="","",$AK$45) -> Trd_2w | AL37: =IF($AJ37="","",25) -> 25 | AN37: =IF(AJ37="","*","DMD") -> DMD | AO37: =AJ37 -> Trd_2w_eth | AQ37: Bvkm | AR37: million Vehicles | AS37: yes
C38: =C30 -> TRADST | D38: =D$36 -> 7 | E38: =E$36 -> 7 | F38: =F$36 -> 7 | G38: =G$36 -> 7 | H38: =H$36 -> 7 | I38: =I$36 -> 7 | J38: =J$36 -> 7 | K38: =K$36 -> 7 | ... AG38: =AG$36 -> 7 | AI38: AF | AJ38: =AJ30 -> \I: | AK38: =IF($AJ38="","",$AK$45) -> Trd_2w | AL38: =IF($AJ38="","",25) -> 25 | AN38: =IF(AJ38="","*","DMD") -> DMD | AO38: =AJ38 -> \I: | AQ38: Bvkm | AR38: million Vehicles | AS38: yes
C39: =C31 -> TRAELC | D39: =D$36 -> 7 | E39: =E$36 -> 7 | F39: =F$36 -> 7 | G39: =G$36 -> 7 | H39: =H$36 -> 7 | I39: =I$36 -> 7 | J39: =J$36 -> 7 | K39: =K$36 -> 7 | ... AG39: =AG$36 -> 7 | AI39: AF | AJ39: =AJ31 -> \I: | AK39: =IF($AJ39="","",$AK$45) -> Trd_2w | AL39: =IF($AJ39="","",25) -> 25 | AN39: =IF(AJ39="","*","DMD") -> DMD | AO39: =AJ39 -> \I: | AQ39: Bvkm | AR39: million Vehicles | AS39: yes
C40: =C32 -> TRAGSL | D40: =D$36 -> 7 | E40: =E$36 -> 7 | F40: =F$36 -> 7 | G40: =G$36 -> 7 | H40: =H$36 -> 7 | I40: =I$36 -> 7 | J40: =J$36 -> 7 | K40: =K$36 -> 7 | ... AG40: =AG$36 -> 7 | AI40: AF | AJ40: =AJ32 -> Trd_2w_gsl | AK40: =IF($AJ40="","",$AK$45) -> Trd_2w | AL40: =IF($AJ40="","",25) -> 25 | AN40: =IF(AJ40="","*","DMD") -> DMD | AO40: =AJ40 -> Trd_2w_gsl | AQ40: Bvkm | AR40: million Vehicles | AS40: yes
C41: =C33 -> TRALPG | D41: =D$36 -> 7 | E41: =E$36 -> 7 | F41: =F$36 -> 7 | G41: =G$36 -> 7 | H41: =H$36 -> 7 | I41: =I$36 -> 7 | J41: =J$36 -> 7 | K41: =K$36 -> 7 | ... AG41: =AG$36 -> 7 | AI41: AF | AJ41: =AJ33 -> \I: | AK41: =IF($AJ41="","",$AK$45) -> Trd_2w | AL41: =IF($AJ41="","",25) -> 25 | AN41: =IF(AJ41="","*","DMD") -> DMD | AO41: =AJ41 -> \I: | AQ41: Bvkm | AR41: million Vehicles | AS41: yes
...

Sheet 3-w
AI2: ~FI_T | AN2: ~FI_Process
C3: comm-in | D3: ='TRA balance'!E4 -> Africa_north | E3: ='TRA balance'!F4 -> Africa_other | F3: ='TRA balance'!G4 -> Arg-Chi | G3: ='TRA balance'!H4 -> Asia_central | H3: ='TRA balance'!I4 -> Asia_east | I3: ='TRA balance'!J4 -> Asia_other | J3: ='TRA balance'!K4 -> Australia_NZ | K3: ='TRA balance'!L4 -> Brazil | ... AG3: ='TRA balance'!AH4 -> \I: | AH3: * | AI3: attribute | AJ3: process | AK3: comm-out | AL3: LIFE | AN3: Sets | AO3: TechName | AP3: TechDesc | AQ3: Tact | AR3: Tcap | AS3: Vintage
A4: TR | C4: TRABDS | D4: {=SUM(SUMIFS(Assumptions!AN$3:AN$102,Assumptions!$B$3:$B$102,'3-w'!$C4,Assumptions!$G$3:$G$102,{"TRE"}))} -> 0 | E4: {=SUM(SUMIFS(Assumptions!AO$3:AO$102,Assumptions!$B$3:$B$102,'3-w'!$C4,Assumptions!$G$3:$G$102,{"TRE"}))} -> 0 | F4: {=SUM(SUMIFS(Assumptions!AP$3:AP$102,Assumptions!$B$3:$B$102,'3-w'!$C4,Assumptions!$G$3:$G$102,{"TRE"}))} -> 0.029650174 | G4: {=SUM(SUMIFS(Assumptions!AQ$3:AQ$102,Assumptions!$B$3:$B$102,'3-w'!$C4,Assumptions!$G$3:$G$102,{"TRE"}))} -> 0 | H4: {=SUM(SUMIFS(Assumptions!AR$3:AR$102,Assumptions!$B$3:$B$102,'3-w'!$C4,Assumptions!$G$3:$G$102,{"TRE"}))} -> 0.013685228 | I4: {=SUM(SUMIFS(Assumptions!AS$3:AS$102,Assumptions!$B$3:$B$102,'3-w'!$C4,Assumptions!$G$3:$G$102,{"TRE"}))} -> 0 | J4: {=SUM(SUMIFS(Assumptions!AT$3:AT$102,Assumptions!$B$3:$B$102,'3-w'!$C4,Assumptions!$G$3:$G$102,{"TRE"}))} -> 0 | K4: {=SUM(SUMIFS(Assumptions!AU$3:AU$102,Assumptions!$B$3:$B$102,'3-w'!$C4,Assumptions!$G$3:$G$102,{"TRE"}))} -> 0.45572095 | ... AG4: {=SUM(SUMIFS(Assumptions!BQ$3:BQ$102,Assumptions!$B$3:$B$102,'3-w'!$C4,Assumptions!$G$3:$G$102,{"TRE"}))} -> 0 | AH4: =IF(SUM(D4:AG4)=0,"zero","") | AI4: * | AK4: =IF($AJ4="","",$AK$45) | AL4: =IF($AJ4="","",25) | AN4: =IF($AJ4="","*","DMD") -> * | AO4: =AJ4 -> 0 | AQ4: Bvkm | AR4: million Vehicles | AS4: yes
A5: TR | C5: TRABGS | D5: {=SUM(SUMIFS(Assumptions!AN$3:AN$102,Assumptions!$B$3:$B$102,'3-w'!$C5,Assumptions!$G$3:$G$102,{"TRE"}))} -> 0 | E5: {=SUM(SUMIFS(Assumptions!AO$3:AO$102,Assumptions!$B$3:$B$102,'3-w'!$C5,Assumptions!$G$3:$G$102,{"TRE"}))} -> 0.19221473 | F5: {=SUM(SUMIFS(Assumptions!AP$3:AP$102,Assumptions!$B$3:$B$102,'3-w'!$C5,Assumptions!$G$3:$G$102,{"TRE"}))} -> 0.10149152 | G5: {=SUM(SUMIFS(Assumptions!AQ$3:AQ$102,Assumptions!$B$3:$B$102,'3-w'!$C5,Assumptions!$G$3:$G$102,{"TRE"}))} -> 0 | H5: {=SUM(SUMIFS(Assumptions!AR$3:AR$102,Assumptions!$B$3:$B$102,'3-w'!$C5,Assumptions!$G$3:$G$102,{"TRE"}))} -> 0.074865818 | I5: {=SUM(SUMIFS(Assumptions!AS$3:AS$102,Assumptions!$B$3:$B$102,'3-w'!$C5,Assumptions!$G$3:$G$102,{"TRE"}))} -> 5.3312425 | J5: {=SUM(SUMIFS(Assumptions!AT$3:AT$102,Assumptions!$B$3:$B$102,'3-w'!$C5,Assumptions!$G$3:$G$102,{"TRE"}))} -> 0 | K5: {=SUM(SUMIFS(Assumptions!AU$3:AU$102,Assumptions!$B$3:$B$102,'3-w'!$C5,Assumptions!$G$3:$G$102,{"TRE"}))} -> 1.061791 | ... AG5: {=SUM(SUMIFS(Assumptions!BQ$3:BQ$102,Assumptions!$B$3:$B$102,'3-w'!$C5,Assumptions!$G$3:$G$102,{"TRE"}))} -> 0 | AH5: =IF(SUM(D5:AG5)=0,"zero","") | AI5: * | AK5: =IF($AJ5="","",$AK$45) | AL5: =IF($AJ5="","",25) | AN5: =IF(AJ5="","*","DMD") -> * | AO5: =AJ5 -> 0 | AQ5: Bvkm | AR5: million Vehicles | AS5: yes
A6: TR | C6: TRADST | D6: {=SUM(SUMIFS(Assumptions!AN$3:AN$102,Assumptions!$B$3:$B$102,'3-w'!$C6,Assumptions!$G$3:$G$102,{"TRE"}))} -> 0 | E6: {=SUM(SUMIFS(Assumptions!AO$3:AO$102,Assumptions!$B$3:$B$102,'3-w'!$C6,Assumptions!$G$3:$G$102,{"TRE"}))} -> 0 | F6: {=SUM(SUMIFS(Assumptions!AP$3:AP$102,Assumptions!$B$3:$B$102,'3-w'!$C6,Assumptions!$G$3:$G$102,{"TRE"}))} -> 0.33181318 | G6: {=SUM(SUMIFS(Assumptions!AQ$3:AQ$102,Assumptions!$B$3:$B$102,'3-w'!$C6,Assumptions!$G$3:$G$102,{"TRE"}))} -> 0 | H6: {=SUM(SUMIFS(Assumptions!AR$3:AR$102,Assumptions!$B$3:$B$102,'3-w'!$C6,Assumptions!$G$3:$G$102,{"TRE"}))} -> 0.85770435 | I6: {=SUM(SUMIFS(Assumptions!AS$3:AS$102,Assumptions!$B$3:$B$102,'3-w'!$C6,Assumptions!$G$3:$G$102,{"TRE"}))} -> 0 | J6: {=SUM(SUMIFS(Assumptions!AT$3:AT$102,Assumptions!$B$3:$B$102,'3-w'!$C6,Assumptions!$G$3:$G$102,{"TRE"}))} -> 0 | K6: {=SUM(SUMIFS(Assumptions!AU$3:AU$102,Assumptions!$B$3:$B$102,'3-w'!$C6,Assumptions!$G$3:$G$102,{"TRE"}))} -> 1.0051941 | ... AG6: {=SUM(SUMIFS(Assumptions!BQ$3:BQ$102,Assumptions!$B$3:$B$102,'3-w'!$C6,Assumptions!$G$3:$G$102,{"TRE"}))} -> 0 | AH6: =IF(SUM(D6:AG6)=0,"zero","") | AI6: * | AK6: =IF($AJ6="","",$AK$45) | AL6: =IF($AJ6="","",25) | AN6: =IF(AJ6="","*","DMD") -> * | AO6: =AJ6 -> 0 | AQ6: Bvkm | AR6: million Vehicles | AS6: yes
A7: TR | C7: TRAELC | D7: {=SUM(SUMIFS(Assumptions!AN$3:AN$102,Assumptions!$B$3:$B$102,'3-w'!$C7,Assumptions!$G$3:$G$102,{"TRE"}))} -> 0 | E7: {=SUM(SUMIFS(Assumptions!AO$3:AO$102,Assumptions!$B$3:$B$102,'3-w'!$C7,Assumptions!$G$3:$G$102,{"TRE"}))} -> 0 | F7: {=SUM(SUMIFS(Assumptions!AP$3:AP$102,Assumptions!$B$3:$B$102,'3-w'!$C7,Assumptions!$G$3:$G$102,{"TRE"}))} -> 0 | G7: {=SUM(SUMIFS(Assumptions!AQ$3:AQ$102,Assumptions!$B$3:$B$102,'3-w'!$C7,Assumptions!$G$3:$G$102,{"TRE"}))} -> 0 | H7: {=SUM(SUMIFS(Assumptions!AR$3:AR$102,Assumptions!$B$3:$B$102,'3-w'!$C7,Assumptions!$G$3:$G$102,{"TRE"}))} -> 0 | I7: {=SUM(SUMIFS(Assumptions!AS$3:AS$102,Assumptions!$B$3:$B$102,'3-w'!$C7,Assumptions!$G$3:$G$102,{"TRE"}))} -> 0 | J7: {=SUM(SUMIFS(Assumptions!AT$3:AT$102,Assumptions!$B$3:$B$102,'3-w'!$C7,Assumptions!$G$3:$G$102,{"TRE"}))} -> 0 | K7: {=SUM(SUMIFS(Assumptions!AU$3:AU$102,Assumptions!$B$3:$B$102,'3-w'!$C7,Assumptions!$G$3:$G$102,{"TRE"}))} -> 0 | ... AG7: {=SUM(SUMIFS(Assumptions!BQ$3:BQ$102,Assumptions!$B$3:$B$102,'3-w'!$C7,Assumptions!$G$3:$G$102,{"TRE"}))} -> 0 | AH7: =IF(SUM(D7:AG7)=0,"zero","") -> zero | AI7: * | AK7: =IF($AJ7="","",$AK$45) | AL7: =IF($AJ7="","",25) | AN7: =IF(AJ7="","*","DMD") -> * | AO7: =AJ7 -> 0 | AQ7: Bvkm | AR7: million Vehicles | AS7: yes
A8: TR | C8: TRAGSL | D8: {=SUM(SUMIFS(Assumptions!AN$3:AN$102,Assumptions!$B$3:$B$102,'3-w'!$C8,Assumptions!$G$3:$G$102,{"TRE"}))} -> 71.567029 | E8: {=SUM(SUMIFS(Assumptions!AO$3:AO$102,Assumptions!$B$3:$B$102,'3-w'!$C8,Assumptions!$G$3:$G$102,{"TRE"}))} -> 124.27522 | F8: {=SUM(SUMIFS(Assumptions!AP$3:AP$102,Assumptions!$B$3:$B$102,'3-w'!$C8,Assumptions!$G$3:$G$102,{"TRE"}))} -> 1.8459338 | G8: {=SUM(SUMIFS(Assumptions!AQ$3:AQ$102,Assumptions!$B$3:$B$102,'3-w'!$C8,Assumptions!$G$3:$G$102,{"TRE"}))} -> 1.4358159 | H8: {=SUM(SUMIFS(Assumptions!AR$3:AR$102,Assumptions!$B$3:$B$102,'3-w'!$C8,Assumptions!$G$3:$G$102,{"TRE"}))} -> 9.0774212 | I8: {=SUM(SUMIFS(Assumptions!AS$3:AS$102,Assumptions!$B$3:$B$102,'3-w'!$C8,Assumptions!$G$3:$G$102,{"TRE"}))} -> 355.37055 | J8: {=SUM(SUMIFS(Assumptions!AT$3:AT$102,Assumptions!$B$3:$B$102,'3-w'!$C8,Assumptions!$G$3:$G$102,{"TRE"}))} -> 0 | K8: {=SUM(SUMIFS(Assumptions!AU$3:AU$102,Assumptions!$B$3:$B$102,'3-w'!$C8,Assumptions!$G$3:$G$102,{"TRE"}))} -> 4.0418183 | ... AG8: {=SUM(SUMIFS(Assumptions!BQ$3:BQ$102,Assumptions!$B$3:$B$102,'3-w'!$C8,Assumptions!$G$3:$G$102,{"TRE"}))} -> 0 | AH8: =IF(SUM(D8:AG8)=0,"zero","") | AI8: * | AK8: =IF($AJ8="","",$AK$45) | AL8: =IF($AJ8="","",25) | AN8: =IF(AJ8="","*","DMD") -> * | AO8: =AJ8 -> 0 | AQ8: Bvkm | AR8: million Vehicles | AS8: yes
A9: TR | C9: TRALPG | D9: {=SUM(SUMIFS(Assumptions!AN$3:AN$102,Assumptions!$B$3:$B$102,'3-w'!$C9,Assumptions!$G$3:$G$102,{"TRE"}))} -> 0 | E9: {=SUM(SUMIFS(Assumptions!AO$3:AO$102,Assumptions!$B$3:$B$102,'3-w'!$C9,Assumptions!$G$3:$G$102,{"TRE"}))} -> 0 | F9: {=SUM(SUMIFS(Assumptions!AP$3:AP$102,Assumptions!$B$3:$B$102,'3-w'!$C9,Assumptions!$G$3:$G$102,{"TRE"}))} -> 0 | G9: {=SUM(SUMIFS(Assumptions!AQ$3:AQ$102,Assumptions!$B$3:$B$102,'3-w'!$C9,Assumptions!$G$3:$G$102,{"TRE"}))} -> 0 | H9: {=SUM(SUMIFS(Assumptions!AR$3:AR$102,Assumptions!$B$3:$B$102,'3-w'!$C9,Assumptions!$G$3:$G$102,{"TRE"}))} -> 0 | I9: {=SUM(SUMIFS(Assumptions!AS$3:AS$102,Assumptions!$B$3:$B$102,'3-w'!$C9,Assumptions!$G$3:$G$102,{"TRE"}))} -> 0 | J9: {=SUM(SUMIFS(Assumptions!AT$3:AT$102,Assumptions!$B$3:$B$102,'3-w'!$C9,Assumptions!$G$3:$G$102,{"TRE"}))} -> 0 | K9: {=SUM(SUMIFS(Assumptions!AU$3:AU$102,Assumptions!$B$3:$B$102,'3-w'!$C9,Assumptions!$G$3:$G$102,{"TRE"}))} -> 0 | ... AG9: {=SUM(SUMIFS(Assumptions!BQ$3:BQ$102,Assumptions!$B$3:$B$102,'3-w'!$C9,Assumptions!$G$3:$G$102,{"TRE"}))} -> 0 | AH9: =IF(SUM(D9:AG9)=0,"zero","") -> zero | AI9: * | AK9: =IF($AJ9="","",$AK$45) | AL9: =IF($AJ9="","",25) | AN9: =IF(AJ9="","*","DMD") -> * | AO9: =AJ9 -> 0 | AQ9: Bvkm | AR9: million Vehicles | AS9: yes
A10: TR | C10: TRANGA | D10: {=SUM(SUMIFS(Assumptions!AN$3:AN$102,Assumptions!$B$3:$B$102,'3-w'!$C10,Assumptions!$G$3:$G$102,{"TRE"}))} -> 0 | E10: {=SUM(SUMIFS(Assumptions!AO$3:AO$102,Assumptions!$B$3:$B$102,'3-w'!$C10,Assumptions!$G$3:$G$102,{"TRE"}))} -> 0 | F10: {=SUM(SUMIFS(Assumptions!AP$3:AP$102,Assumptions!$B$3:$B$102,'3-w'!$C10,Assumptions!$G$3:$G$102,{"TRE"}))} -> 0 | G10: {=SUM(SUMIFS(Assumptions!AQ$3:AQ$102,Assumptions!$B$3:$B$102,'3-w'!$C10,Assumptions!$G$3:$G$102,{"TRE"}))} -> 0 | H10: {=SUM(SUMIFS(Assumptions!AR$3:AR$102,Assumptions!$B$3:$B$102,'3-w'!$C10,Assumptions!$G$3:$G$102,{"TRE"}))} -> 0 | I10: {=SUM(SUMIFS(Assumptions!AS$3:AS$102,Assumptions!$B$3:$B$102,'3-w'!$C10,Assumptions!$G$3:$G$102,{"TRE"}))} -> 0 | J10: {=SUM(SUMIFS(Assumptions!AT$3:AT$102,Assumptions!$B$3:$B$102,'3-w'!$C10,Assumptions!$G$3:$G$102,{"TRE"}))} -> 0 | K10: {=SUM(SUMIFS(Assumptions!AU$3:AU$102,Assumptions!$B$3:$B$102,'3-w'!$C10,Assumptions!$G$3:$G$102,{"TRE"}))} -> 0 | ... AG10: {=SUM(SUMIFS(Assumptions!BQ$3:BQ$102,Assumptions!$B$3:$B$102,'3-w'!$C10,Assumptions!$G$3:$G$102,{"TRE"}))} -> 0 | AH10: =IF(SUM(D10:AG10)=0,"zero","") -> zero | AI10: * | AK10: =IF($AJ10="","",$AK$45) | AL10: =IF($AJ10="","",25) | AN10: =IF(AJ10="","*","DMD") -> * | AO10: =AJ10 -> 0 | AQ10: Bvkm | AR10: million Vehicles | AS10: yes
A11: Share of PJ | D11: =SUM(D$4:D$10)/SUM($D$4:$T$10) -> 0.086526264 | E11: =SUM(E$4:E$10)/SUM($D$4:$T$10) -> 0.15048413 | F11: =SUM(F$4:F$10)/SUM($D$4:$T$10) -> 0.0027915021 | G11: =SUM(G$4:G$10)/SUM($D$4:$T$10) -> 0.0017359361 | H11: =SUM(H$4:H$10)/SUM($D$4:$T$10) -> 0.012118867 | I11: =SUM(I$4:I$10)/SUM($D$4:$T$10) -> 0.43609716 | J11: =SUM(J$4:J$10)/SUM($D$4:$T$10) -> 0 | K11: =SUM(K$4:K$10)/SUM($D$4:$T$10) -> 0.0079366682 | ... AG11: =SUM(AG$4:AG$10)/SUM($D$4:$T$10) -> 0 | AI11: * | AK11: =IF($AJ11="","",$AK$45) | AL11: =IF($AJ11="","",25) | AN11: =IF(AJ11="","*","DMD") -> * | AO11: =AJ11 -> 0 | AQ11: Bvkm | AR11: million Vehicles | AS11: yes
AI12: * | AK12: =IF($AJ12="","",$AK$45) | AL12: =IF($AJ12="","",25) | AN12: =IF(AJ12="","*","DMD") -> * | AO12: =AJ12 -> 0 | AQ12: Bvkm | AR12: million Vehicles | AS12: yes
A13: m Vehicles | C13: =SUM(D13:T13) -> 32.36 | D13: =SUM(D19:D25) -> 2.8 | E13: =SUM(E19:E25) -> 4.87 | F13: =SUM(F19:F25) -> 0.08 | G13: =SUM(G19:G25) -> 0.06 | H13: =SUM(H19:H25) -> 0.39 | I13: =SUM(I19:I25) -> 14.12 | J13: =SUM(J19:J25) -> 0 | K13: =SUM(K19:K25) -> 0.26 | ... AG13: =SUM(AG19:AG25) -> 0 | AI13: * | AK13: =IF($AJ13="","",$AK$45) | AL13: =IF($AJ13="","",25) | AN13: =IF(AJ13="","*","DMD") -> * | AO13: =AJ13 -> 0 | AQ13: Bvkm | AR13: million Vehicles | AS13: yes
A14: Share of Veh | D14: =D13/SUM($D$13:$T$13) -> 0.086526576 | E14: =E13/SUM($D$13:$T$13) -> 0.15049444 | F14: =F13/SUM($D$13:$T$13) -> 0.0024721879 | G14: =G13/SUM($D$13:$T$13) -> 0.0018541409 | H14: =H13/SUM($D$13:$T$13) -> 0.012051916 | I14: =I13/SUM($D$13:$T$13) -> 0.43634116 | J14: =J13/SUM($D$13:$T$13) -> 0 | K14: =K13/SUM($D$13:$T$13) -> 0.0080346106 | ... AG14: =AG13/SUM($D$13:$T$13) -> 0 | AI14: * | AK14: =IF($AJ14="","",$AK$45) | AL14: =IF($AJ14="","",25) | AN14: =IF(AJ14="","*","DMD") -> * | AO14: =AJ14 -> 0 | AQ14: Bvkm | AR14: million Vehicles | AS14: yes
AI15: * | AK15: =IF($AJ15="","",$AK$45) | AL15: =IF($AJ15="","",25) | AN15: =IF(AJ15="","*","DMD") -> * | AO15: =AJ15 -> 0 | AQ15: Bvkm | AR15: million Vehicles | AS15: yes
AI16: * | AK16: =IF($AJ16="","",$AK$45) | AL16: =IF($AJ16="","",25) | AN16: =IF(AJ16="","*","DMD") -> * | AO16: =AJ16 -> 0 | AQ16: Bvkm | AR16: million Vehicles | AS16: yes
A17: PJ share/Veh share | D17: =IFERROR(D11/D14,"") -> 0.9999964 | E17: =IFERROR(E11/E14,"") -> 0.99993149 | F17: =IFERROR(F11/F14,"") -> 1.1291626 | G17: =IFERROR(G11/G14,"") -> 0.93624819 | H17: =IFERROR(H11/H14,"") -> 1.0055552 | I17: =IFERROR(I11/I14,"") -> 0.9994408 | J17: =IFERROR(J11/J14,"") | K17: =IFERROR(K11/K14,"") -> 0.98780994 | ... AG17: =IFERROR(AG11/AG14,"") | AI17: * | AK17: =IF($AJ17="","",$AK$45) | AL17: =IF($AJ17="","",25) | AN17: =IF(AJ17="","*","DMD") -> * | AO17: =AJ17 -> 0 | AQ17: Bvkm | AR17: million Vehicles | AS17: yes
AI18: * | AK18: =IF($AJ18="","",$AK$45) | AL18: =IF($AJ18="","",25) | AN18: =IF(AJ18="","*","DMD") -> * | AO18: =AJ18 -> 0 | AQ18: Bvkm | AR18: million Vehicles | AS18: yes
A19: mVeh | C19: =C4 -> TRABDS | D19: =ROUND(D4*D28/D36,2) -> 0 | E19: =ROUND(E4*E28/E36,2) -> 0 | F19: =ROUND(F4*F28/F36,2) -> 0 | G19: =ROUND(G4*G28/G36,2) -> 0 | H19: =ROUND(H4*H28/H36,2) -> 0 | I19: =ROUND(I4*I28/I36,2) -> 0 | J19: =ROUND(J4*J28/J36,2) -> 0 | K19: =ROUND(K4*K28/K36,2) -> 0.02 | ... AG19: =ROUND(AG4*AG28/AG36,2) -> 0 | AI19: PASTI | AJ19: =IF(AH4="zero","\I:",$AK$45&"_"&VLOOKUP(C19,'TRA balance'!$AL$5:$AM$15,2,FALSE)) -> Trd_3w_bdl | AK19: =IF($AJ19="","",$AK$45) -> Trd_3w | AL19: =IF($AJ19="","",25) -> 25 | AN19: =IF(AJ19="","*","DMD") -> DMD | AO19: =AJ19 -> Trd_3w_bdl | AQ19: Bvkm | AR19: million Vehicles | AS19: yes
C20: =C5 -> TRABGS | D20: =ROUND(D5*D29/D37,2) -> 0 | E20: =ROUND(E5*E29/E37,2) -> 0.01 | F20: =ROUND(F5*F29/F37,2) -> 0 | G20: =ROUND(G5*G29/G37,2) -> 0 | H20: =ROUND(H5*H29/H37,2) -> 0 | I20: =ROUND(I5*I29/I37,2) -> 0.21 | J20: =ROUND(J5*J29/J37,2) -> 0 | K20: =ROUND(K5*K29/K37,2) -> 0.04 | ... AG20: =ROUND(AG5*AG29/AG37,2) -> 0 | AI20: PASTI | AJ20: =IF(AH5="zero","\I:",$AK$45&"_"&VLOOKUP(C20,'TRA balance'!$AL$5:$AM$15,2,FALSE)) -> Trd_3w_eth | AK20: =IF($AJ20="","",$AK$45) -> Trd_3w | AL20: =IF($AJ20="","",25) -> 25 | AN20: =IF(AJ20="","*","DMD") -> DMD | AO20: =AJ20 -> Trd_3w_eth | AQ20: Bvkm | AR20: million Vehicles | AS20: yes
C21: =C6 -> TRADST | D21: =ROUND(D6*D30/D38,2) -> 0 | E21: =ROUND(E6*E30/E38,2) -> 0 | F21: =ROUND(F6*F30/F38,2) -> 0.01 | G21: =ROUND(G6*G30/G38,2) -> 0 | H21: =ROUND(H6*H30/H38,2) -> 0.03 | I21: =ROUND(I6*I30/I38,2) -> 0 | J21: =ROUND(J6*J30/J38,2) -> 0 | K21: =ROUND(K6*K30/K38,2) -> 0.04 | ... AG21: =ROUND(AG6*AG30/AG38,2) -> 0 | AI21: PASTI | AJ21: =IF(AH6="zero","\I:",$AK$45&"_"&VLOOKUP(C21,'TRA balance'!$AL$5:$AM$15,2,FALSE)) -> Trd_3w_dsl | AK21: =IF($AJ21="","",$AK$45) -> Trd_3w | AL21: =IF($AJ21="","",25) -> 25 | AN21: =IF(AJ21="","*","DMD") -> DMD | AO21: =AJ21 -> Trd_3w_dsl | AQ21: Bvkm | AR21: million Vehicles | AS21: yes
C22: =C7 -> TRAELC | D22: =ROUND(D7*D31/D39,2) -> 0 | E22: =ROUND(E7*E31/E39,2) -> 0 | F22: =ROUND(F7*F31/F39,2) -> 0 | G22: =ROUND(G7*G31/G39,2) -> 0 | H22: =ROUND(H7*H31/H39,2) -> 0 | I22: =ROUND(I7*I31/I39,2) -> 0 | J22: =ROUND(J7*J31/J39,2) -> 0 | K22: =ROUND(K7*K31/K39,2) -> 0 | ... AG22: =ROUND(AG7*AG31/AG39,2) -> 0 | AI22: PASTI | AJ22: =IF(AH7="zero","\I:",$AK$45&"_"&VLOOKUP(C22,'TRA balance'!$AL$5:$AM$15,2,FALSE)) -> \I: | AK22: =IF($AJ22="","",$AK$45) -> Trd_3w | AL22: =IF($AJ22="","",25) -> 25 | AN22: =IF(AJ22="","*","DMD") -> DMD | AO22: =AJ22 -> \I: | AQ22: Bvkm | AR22: million Vehicles | AS22: yes
C23: =C8 -> TRAGSL | D23: =ROUND(D8*D32/D40,2) -> 2.8 | E23: =ROUND(E8*E32/E40,2) -> 4.86 | F23: =ROUND(F8*F32/F40,2) -> 0.07 | G23: =ROUND(G8*G32/G40,2) -> 0.06 | H23: =ROUND(H8*H32/H40,2) -> 0.36 | I23: =ROUND(I8*I32/I40,2) -> 13.91 | J23: =ROUND(J8*J32/J40,2) -> 0 | K23: =ROUND(K8*K32/K40,2) -> 0.16 | ... AG23: =ROUND(AG8*AG32/AG40,2) -> 0 | AI23: PASTI | AJ23: =IF(AH8="zero","\I:",$AK$45&"_"&VLOOKUP(C23,'TRA balance'!$AL$5:$AM$15,2,FALSE)) -> Trd_3w_gsl | AK23: =IF($AJ23="","",$AK$45) -> Trd_3w | AL23: =IF($AJ23="","",25) -> 25 | AN23: =IF(AJ23="","*","DMD") -> DMD | AO23: =AJ23 -> Trd_3w_gsl | AQ23: Bvkm | AR23: million Vehicles | AS23: yes
C24: =C9 -> TRALPG | D24: =ROUND(D9*D33/D41,2) -> 0 | E24: =ROUND(E9*E33/E41,2) -> 0 | F24: =ROUND(F9*F33/F41,2) -> 0 | G24: =ROUND(G9*G33/G41,2) -> 0 | H24: =ROUND(H9*H33/H41,2) -> 0 | I24: =ROUND(I9*I33/I41,2) -> 0 | J24: =ROUND(J9*J33/J41,2) -> 0 | K24: =ROUND(K9*K33/K41,2) -> 0 | ... AG24: =ROUND(AG9*AG33/AG41,2) -> 0 | AI24: PASTI | AJ24: =IF(AH9="zero","\I:",$AK$45&"_"&VLOOKUP(C24,'TRA balance'!$AL$5:$AM$15,2,FALSE)) -> \I: | AK24: =IF($AJ24="","",$AK$45) -> Trd_3w | AL24: =IF($AJ24="","",25) -> 25 | AN24: =IF(AJ24="","*","DMD") -> DMD | AO24: =AJ24 -> \I: | AQ24: Bvkm | AR24: million Vehicles | AS24: yes
C25: =C10 -> TRANGA | D25: =ROUND(D10*D34/D42,2) -> 0 | E25: =ROUND(E10*E34/E42,2) -> 0 | F25: =ROUND(F10*F34/F42,2) -> 0 | G25: =ROUND(G10*G34/G42,2) -> 0 | H25: =ROUND(H10*H34/H42,2) -> 0 | I25: =ROUND(I10*I34/I42,2) -> 0 | J25: =ROUND(J10*J34/J42,2) -> 0 | K25: =ROUND(K10*K34/K42,2) -> 0 | ... AG25: =ROUND(AG10*AG34/AG42,2) -> 0 | AI25: PASTI | AJ25: =IF(AH10="zero","\I:",$AK$45&"_"&VLOOKUP(C25,'TRA balance'!$AL$5:$AM$15,2,FALSE)) -> \I: | AK25: =IF($AJ25="","",$AK$45) -> Trd_3w | AL25: =IF($AJ25="","",25) -> 25 | AN25: =IF(AJ25="","*","DMD") -> DMD | AO25: =AJ25 -> \I: | AQ25: Bvkm | AR25: million Vehicles | AS25: yes
AI26: * | AK26: =IF($AJ26="","",$AK$45) | AL26: =IF($AJ26="","",25) | AN26: =IF(AJ26="","*","DMD") -> * | AO26: =AJ26 -> 0 | AQ26: Bvkm | AR26: million Vehicles | AS26: yes
D27: 1 | E27: 1 | F27: 1 | G27: 1 | H27: 1 | I27: 1 | J27: 1 | K27: 1 | L27: 1 | M27: 1 | N27: 1 | O27: 1 | P27: 1 | Q27: 1 | R27: 1 | S27: 1 | T27: 1 | U27: 1 | V27: 1 | W27: 1 | X27: 1 | Y27: 1 | Z27: 1 | AA27: 1 | AB27: 1 | AC27: 1 | AD27: 1 | AE27: 1 | AF27: 1 | AG27: 1 | AI27: * | AK27: =IF($AJ27="","",$AK$45) | AL27: =IF($AJ27="","",25) | AN27: =IF(AJ27="","*","DMD") -> * | AO27: =AJ27 -> 0 | AQ27: Bvkm | AR27: million Vehicles | AS27: yes
A28: Efficiency | C28: =C19 -> TRABDS | D28: =$AH28*D$27 -> 0.58697 | E28: =$AH28*E$27 -> 0.58697 | F28: =$AH28*F$27 -> 0.58697 | G28: =$AH28*G$27 -> 0.58697 | H28: =$AH28*H$27 -> 0.58697 | I28: =$AH28*I$27 -> 0.58697 | J28: =$AH28*J$27 -> 0.58697 | K28: =$AH28*K$27 -> 0.58697 | ... AG28: =$AH28*AG$27 -> 0.58697 | AH28: 0.58697 | AI28: EFF | AJ28: =AJ19 -> Trd_3w_bdl | AK28: =IF($AJ28="","",$AK$45) -> Trd_3w | AL28: =IF($AJ28="","",25) -> 25 | AN28: =IF(AJ28="","*","DMD") -> DMD | AO28: =AJ28 -> Trd_3w_bdl | AQ28: Bvkm | AR28: million Vehicles | AS28: yes
C29: =C20 -> TRABGS | D29: =$AH29*D$27 -> 0.58697 | E29: =$AH29*E$27 -> 0.58697 | F29: =$AH29*F$27 -> 0.58697 | G29: =$AH29*G$27 -> 0.58697 | H29: =$AH29*H$27 -> 0.58697 | I29: =$AH29*I$27 -> 0.58697 | J29: =$AH29*J$27 -> 0.58697 | K29: =$AH29*K$27 -> 0.58697 | ... AG29: =$AH29*AG$27 -> 0.58697 | AH29: 0.58697 | AI29: EFF | AJ29: =AJ20 -> Trd_3w_eth | AK29: =IF($AJ29="","",$AK$45) -> Trd_3w | AL29: =IF($AJ29="","",25) -> 25 | AN29: =IF(AJ29="","*","DMD") -> DMD | AO29: =AJ29 -> Trd_3w_eth | AQ29: Bvkm | AR29: million Vehicles | AS29: yes
C30: =C21 -> TRADST | D30: =$AH30*D$27 -> 0.58697 | E30: =$AH30*E$27 -> 0.58697 | F30: =$AH30*F$27 -> 0.58697 | G30: =$AH30*G$27 -> 0.58697 | H30: =$AH30*H$27 -> 0.58697 | I30: =$AH30*I$27 -> 0.58697 | J30: =$AH30*J$27 -> 0.58697 | K30: =$AH30*K$27 -> 0.58697 | ... AG30: =$AH30*AG$27 -> 0.58697 | AH30: 0.58697 | AI30: EFF | AJ30: =AJ21 -> Trd_3w_dsl | AK30: =IF($AJ30="","",$AK$45) -> Trd_3w | AL30: =IF($AJ30="","",25) -> 25 | AN30: =IF(AJ30="","*","DMD") -> DMD | AO30: =AJ30 -> Trd_3w_dsl | AQ30: Bvkm | AR30: million Vehicles | AS30: yes
C31: =C22 -> TRAELC | D31: =$AH31*D$27 -> 0.58697 | E31: =$AH31*E$27 -> 0.58697 | F31: =$AH31*F$27 -> 0.58697 | G31: =$AH31*G$27 -> 0.58697 | H31: =$AH31*H$27 -> 0.58697 | I31: =$AH31*I$27 -> 0.58697 | J31: =$AH31*J$27 -> 0.58697 | K31: =$AH31*K$27 -> 0.58697 | ... AG31: =$AH31*AG$27 -> 0.58697 | AH31: 0.58697 | AI31: EFF | AJ31: =AJ22 -> \I: | AK31: =IF($AJ31="","",$AK$45) -> Trd_3w | AL31: =IF($AJ31="","",25) -> 25 | AN31: =IF(AJ31="","*","DMD") -> DMD | AO31: =AJ31 -> \I: | AQ31: Bvkm | AR31: million Vehicles | AS31: yes
C32: =C23 -> TRAGSL | D32: =$AH32*D$27 -> 0.58697 | E32: =$AH32*E$27 -> 0.58697 | F32: =$AH32*F$27 -> 0.58697 | G32: =$AH32*G$27 -> 0.58697 | H32: =$AH32*H$27 -> 0.58697 | I32: =$AH32*I$27 -> 0.58697 | J32: =$AH32*J$27 -> 0.58697 | K32: =$AH32*K$27 -> 0.58697 | ... AG32: =$AH32*AG$27 -> 0.58697 | AH32: 0.58697 | AI32: EFF | AJ32: =AJ23 -> Trd_3w_gsl | AK32: =IF($AJ32="","",$AK$45) -> Trd_3w | AL32: =IF($AJ32="","",25) -> 25 | AN32: =IF(AJ32="","*","DMD") -> DMD | AO32: =AJ32 -> Trd_3w_gsl | AQ32: Bvkm | AR32: million Vehicles | AS32: yes
C33: =C24 -> TRALPG | D33: =$AH33*D$27 -> 0.58697 | E33: =$AH33*E$27 -> 0.58697 | F33: =$AH33*F$27 -> 0.58697 | G33: =$AH33*G$27 -> 0.58697 | H33: =$AH33*H$27 -> 0.58697 | I33: =$AH33*I$27 -> 0.58697 | J33: =$AH33*J$27 -> 0.58697 | K33: =$AH33*K$27 -> 0.58697 | ... AG33: =$AH33*AG$27 -> 0.58697 | AH33: 0.58697 | AI33: EFF | AJ33: =AJ24 -> \I: | AK33: =IF($AJ33="","",$AK$45) -> Trd_3w | AL33: =IF($AJ33="","",25) -> 25 | AN33: =IF(AJ33="","*","DMD") -> DMD | AO33: =AJ33 -> \I: | AQ33: Bvkm | AR33: million Vehicles | AS33: yes
