Workbook

Sheet Globiom data
A1: ActiveReg | B1: Region | C1: Variable | D1: BIOscen | E1: SDGscen | F1: *2010 | G1: 2018 | H1: 2020 | I1: 2030 | J1: 2040 | K1: 2050 | L1: 2060 | M1: 2070 | N1: 2080 | O1: 2090 | P1: 2100 | Q1: TF - step 3 - Bio potential from Globium.sql
A2: Africa_north | B2: MAF | C2: Energy Crops | D2: BIO00 | E2: scenBASE | F2: 6.4071508e-05 | G2: 0 | H2: 0 | I2: 0 | J2: 0 | K2: 0 | L2: 0 | M2: 0 | N2: 0 | O2: 0 | P2: 0
A3: Africa_north | B3: MAF | C3: Energy Crops | D3: BIO03 | E3: scenBASE | F3: 0 | G3: 0 | H3: 0 | I3: 0 | J3: 0 | K3: 0 | L3: 0 | M3: 0 | N3: 0 | O3: 0 | P3: 0
A4: Africa_north | B4: MAF | C4: Energy Crops | D4: BIO05 | E4: scenBASE | F4: 0 | G4: 0 | H4: 0 | I4: 0 | J4: 0 | K4: 0 | L4: 0 | M4: 6.4023559e-05 | N4: 0.0034740869 | O4: 0.01388827 | P4: 0.016291749 | R4: Region | S4: Variable | T4: Unit | U4: SSPscen | V4: GHGscen | W4: BIOscen | X4: SDGscen | Y4: 2000 | Z4: 2010 | AA4: 2020 | AB4: 2030 | AC4: 2040 | AD4: 2050 | AE4: 2060 | AF4: 2070 | AG4: 2080 | AH4: 2090 | AI4: 2100
A5: Africa_north | B5: MAF | C5: Energy Crops | D5: BIO08 | E5: scenBASE | F5: 0 | G5: 0 | H5: 0 | I5: 0 | J5: 0 | K5: 0 | L5: 0.0090464528 | M5: 0.015881334 | N5: 0.016081829 | O5: 0.015261061 | P5: 0.037680707 | R5: World | S5: Price|Primary Energy|Biomass | T5: US$2000/GJ | U5: SSP2 | V5: GHG000 | W5: BIO03 | X5: scenBASE | Y5: 0 | Z5: 0 | AA5: 0.17647059 | AB5: 0.52941176 | AC5: 0.88235294 | AD5: 1.2352941 | AE5: 1.5882353 | AF5: 1.9411765 | AG5: 2.2941176 | AH5: 2.6470588 | AI5: 3
A6: Africa_north | B6: MAF | C6: Energy Crops | D6: BIO13 | E6: scenBASE | F6: 0 | G6: 0 | H6: 0 | I6: 0 | J6: 0.0036353819 | K6: 0.016048477 | L6: 0.020484071 | M6: 0.046575266 | N6: 0.068856656 | O6: 0.081296583 | P6: 0.072241499 | R6: World | S6: Price|Primary Energy|Biomass | T6: US$2000/GJ | U6: SSP2 | V6: GHG000 | W6: BIO05 | X6: scenBASE | Y6: 0 | Z6: 0 | AA6: 0.29411765 | AB6: 0.88235294 | AC6: 1.4705882 | AD6: 2.0588235 | AE6: 2.6470588 | AF6: 3.2352941 | AG6: 3.8235294 | AH6: 4.4117647 | AI6: 5
A7: Africa_north | B7: MAF | C7: Energy Crops | D7: BIO30 | E7: scenBASE | F7: 0 | G7: 0 | H7: 0 | I7: 0.017695883 | J7: 0.055775114 | K7: 0.07050319 | L7: 0.079824901 | M7: 0.065671746 | N7: 0.053771487 | O7: 0.038182844 | P7: 0.022599707 | R7: World | S7: Price|Primary Energy|Biomass | T7: US$2000/GJ | U7: SSP2 | V7: GHG000 | W7: BIO08 | X7: scenBASE | Y7: 0 | Z7: 0 | AA7: 0.47058824 | AB7: 1.4117647 | AC7: 2.3529412 | AD7: 3.2941176 | AE7: 4.2352941 | AF7: 5.1764706 | AG7: 6.1176471 | AH7: 7.0588235 | AI7: 8
A8: Africa_north | B8: MAF | C8: Energy Crops | D8: BIO60 | E8: scenBASE | F8: 0 | G8: 0.00025886496 | H8: 0.00025886496 | I8: 0.044229961 | J8: 0.030516485 | K8: 0.02775175 | L8: 0.024963624 | M8: 0.021425755 | N8: 0.01919537 | O8: 0.013072809 | P8: 0.013278536 | R8: World | S8: Price|Primary Energy|Biomass | T8: US$2000/GJ | U8: SSP2 | V8: GHG000 | W8: BIO13 | X8: scenBASE | Y8: 0 | Z8: 0 | AA8: 0.76470588 | AB8: 2.2941176 | AC8: 3.8235294 | AD8: 5.3529412 | AE8: 6.8823529 | AF8: 8.4117647 | AG8: 9.9411765 | AH8: 11.470588 | AI8: 13
A9: Africa_north | B9: MAF | C9: Forest industry residues | D9: BIO00 | E9: scenBASE | F9: 0.02361781 | G9: 0.034055774 | H9: 0.034055774 | I9: 0.043091373 | J9: 0.04989648 | K9: 0.054067604 | L9: 0.055259588 | M9: 0.056533039 | N9: 0.057383392 | O9: 0.058151683 | P9: 0.058717807 | R9: World | S9: Price|Primary Energy|Biomass | T9: US$2000/GJ | U9: SSP2 | V9: GHG000 | W9: BIO30 | X9: scenBASE | Y9: 0 | Z9: 0 | AA9: 1.7647059 | AB9: 5.2941176 | AC9: 8.8235294 | AD9: 12.352941 | AE9: 15.882353 | AF9: 19.411765 | AG9: 22.941176 | AH9: 26.470588 | AI9: 30
A10: Africa_north | B10: MAF | C10: Forest industry residues | D10: BIO03 | E10: scenBASE | F10: 0 | G10: -6.8632826e-05 | H10: -6.8632826e-05 | I10: -0.00013729261 | J10: -0.00036402577 | K10: -4.3118213e-05 | L10: 0.015276613 | M10: 0.019065261 | N10: 0.022729611 | O10: 0.025645681 | P10: 0.028016925 | R10: World | S10: Price|Primary Energy|Biomass | T10: US$2000/GJ | U10: SSP2 | V10: GHG000 | W10: BIO60 | X10: scenBASE | Y10: 0 | Z10: 0 | AA10: 3.5294118 | AB10: 10.588235 | AC10: 17.647059 | AD10: 24.705882 | AE10: 31.764706 | AF10: 38.823529 | AG10: 45.882353 | AH10: 52.941176 | AI10: 60
A11: Africa_north | B11: MAF | C11: Forest industry residues | D11: BIO05 | E11: scenBASE | F11: 0 | G11: 0 | H11: 0 | I11: 2.09857e-05 | J11: -0.00015515527 | K11: 0.010457348 | L11: -2.4028373e-05 | M11: 0.00010080711 | N11: 6.3389294e-05 | O11: 0.000432399 | P11: 0.00079730719 | R11: World | S11: Price|Primary Energy|Biomass | T11: US$2000/GJ | U11: SSP2 | V11: GHG000 | W11: BIO03 | X11: scenSDGs | Y11: 0 | Z11: 0 | AA11: 0.17647059 | AB11: 0.52941176 | AC11: 0.88235294 | AD11: 1.2352941 | AE11: 1.5882353 | AF11: 1.9411765 | AG11: 2.2941176 | AH11: 2.6470588 | AI11: 3
A12: Africa_north | B12: MAF | C12: Forest industry residues | D12: BIO08 | E12: scenBASE | F12: 0 | G12: 0 | H12: 0 | I12: 7.5248304e-05 | J12: 0.0078549062 | K12: 0.00035295423 | L12: 0.00053011819 | M12: 0.00065939919 | N12: 0.00051401555 | O12: -0.00038830813 | P12: -0.0010513741 | R12: World | S12: Price|Primary Energy|Biomass | T12: US$2000/GJ | U12: SSP2 | V12: GHG000 | W12: BIO05 | X12: scenSDGs | Y12: 0 | Z12: 0 | AA12: 0.29411765 | AB12: 0.88235294 | AC12: 1.4705882 | AD12: 2.0588235 | AE12: 2.6470588 | AF12: 3.2352941 | AG12: 3.8235294 | AH12: 4.4117647 | AI12: 5
A13: Africa_north | B13: MAF | C13: Forest industry residues | D13: BIO13 | E13: scenBASE | F13: 0 | G13: -3.2851228e-05 | H13: -3.2851228e-05 | I13: 0.0069046615 | J13: 0.00077851049 | K13: 0.0013562479 | L13: 0.0010467327 | M13: -0.00033000246 | N13: -0.0011242942 | O13: -0.0014014949 | P13: -0.0019448033 | R13: World | S13: Price|Primary Energy|Biomass | T13: US$2000/GJ | U13: SSP2 | V13: GHG000 | W13: BIO08 | X13: scenSDGs | Y13: 0 | Z13: 0 | AA13: 0.47058824 | AB13: 1.4117647 | AC13: 2.3529412 | AD13: 3.2941176 | AE13: 4.2352941 | AF13: 5.1764706 | AG13: 6.1176471 | AH13: 7.0588235 | AI13: 8
A14: Africa_north | B14: MAF | C14: Forest industry residues | D14: BIO30 | E14: scenBASE | F14: 0 | G14: 0.0022129543 | H14: 0.0022129543 | I14: -0.0017497201 | J14: -0.00089239169 | K14: -0.0029002806 | L14: -0.0044813402 | M14: -0.0048467243 | N14: -0.0057086528 | O14: -0.0063128986 | P14: -0.006761553 | R14: World | S14: Price|Primary Energy|Biomass | T14: US$2000/GJ | U14: SSP2 | V14: GHG000 | W14: BIO13 | X14: scenSDGs | Y14: 0 | Z14: 0 | AA14: 0.76470588 | AB14: 2.2941176 | AC14: 3.8235294 | AD14: 5.3529412 | AE14: 6.8823529 | AF14: 8.4117647 | AG14: 9.9411765 | AH14: 11.470588 | AI14: 13
A15: Africa_north | B15: MAF | C15: Forest industry residues | D15: BIO60 | E15: scenBASE | F15: 0 | G15: -0.00064832182 | H15: -0.00064832182 | I15: -0.0017904682 | J15: -0.0033129377 | K15: -0.0026993612 | L15: -0.0036826181 | M15: -0.0043918584 | N15: -0.004963233 | O15: -0.0055011216 | P15: -0.0060962118 | R15: World | S15: Price|Primary Energy|Biomass | T15: US$2000/GJ | U15: SSP2 | V15: GHG000 | W15: BIO30 | X15: scenSDGs | Y15: 0 | Z15: 0 | AA15: 1.7647059 | AB15: 5.2941176 | AC15: 8.8235294 | AD15: 12.352941 | AE15: 15.882353 | AF15: 19.411765 | AG15: 22.941176 | AH15: 26.470588 | AI15: 30
A16: Africa_north | B16: MAF | C16: Fuelwood | D16: BIO00 | E16: scenBASE | F16: 0.037121777 | G16: 0.044967496 | H16: 0.044967496 | I16: 0.024587559 | J16: 0.016704442 | K16: 0.017522482 | L16: 0.017730428 | M16: 0.018194878 | N16: 0.018332161 | O16: 0.018332161 | P16: 0.018332161 | R16: World | S16: Price|Primary Energy|Biomass | T16: US$2000/GJ | U16: SSP2 | V16: GHG000 | W16: BIO60 | X16: scenSDGs | Y16: 0 | Z16: 0 | AA16: 3.5294118 | AB16: 10.588235 | AC16: 17.647059 | AD16: 24.705882 | AE16: 31.764706 | AF16: 38.823529 | AG16: 45.882353 | AH16: 52.941176 | AI16: 60
A17: Africa_north | B17: MAF | C17: Fuelwood | D17: BIO03 | E17: scenBASE | F17: 0 | G17: 1.9983978e-05 | H17: 1.9983978e-05 | I17: 0 | J17: -0.000144037 | K17: 0 | L17: -0.00016838422 | M17: -0.00028880602 | N17: -0.00022064241 | O17: -0.00022064241 | P17: -0.00022064241
A18: Africa_north | B18: MAF | C18: Fuelwood | D18: BIO05 | E18: scenBASE | F18: 0 | G18: 0 | H18: 0 | I18: 0 | J18: -0.00014110586 | K18: -8.9410641e-05 | L18: 0 | M18: -2.4977703e-05 | N18: -0.00023042431 | O18: -0.00023042431 | P18: -0.00023042431
A19: Africa_north | B19: MAF | C19: Fuelwood | D19: BIO08 | E19: scenBASE | F19: 0 | G19: 1.179612e-16 | H19: 1.179612e-16 | I19: 0 | J19: -7.8770432e-05 | K19: 0 | L19: -1.2034381e-06 | M19: 0.00032996328 | N19: 0.00051226974 | O19: 0.00051226974 | P19: 0.00051226974
A20: Africa_north | B20: MAF | C20: Fuelwood | D20: BIO13 | E20: scenBASE | F20: 0 | G20: 3.8286014e-05 | H20: 3.8286014e-05 | I20: 0 | J20: -0.00034155326 | K20: 0.0001276637 | L20: 0.00080529097 | M20: 0.00019179393 | N20: 1.0955342e-05 | O20: 1.3953947e-05 | P20: 1.5470799e-05
A21: Africa_north | B21: MAF | C21: Fuelwood | D21: BIO30 | E21: scenBASE | F21: 0 | G21: -5.8269992e-05 | H21: -5.8269992e-05 | I21: 0.0012308759 | J21: 0.0023331853 | K21: 0.00084772357 | L21: 4.271437e-05 | M21: 5.9986137e-06 | N21: 4.530779e-06 | O21: 1.5321738e-06 | P21: 1.5321738e-08 | S21: 1 | T21: Africa_north | V21: 1 | W21: BIO00 | X21: MinBIOBSL-01
A22: Africa_north | B22: MAF | C22: Fuelwood | D22: BIO60 | E22: scenBASE | F22: 0 | G22: -6.9175403e-05 | H22: -6.9175403e-05 | I22: 0.0026296149 | J22: 7.6512864e-05 | K22: 3.8895012e-07 | L22: 3.8895013e-09 | M22: 3.8895085e-11 | N22: 3.8905684e-13 | O22: 3.9135362e-15 | P22: 0 | S22: 2 | T22: Africa_other | V22: 2 | W22: BIO03 | X22: MinBIOBSL-02
A23: Africa_north | B23: MAF | C23: Logging residues | D23: BIO00 | E23: scenBASE | F23: 0.0061997424 | G23: 0.0072236027 | H23: 0.0072236027 | I23: 0.0088610979 | J23: 0.010219681 | K23: 0.010723633 | L23: 0.010855273 | M23: 0.011147476 | N23: 0.011232826 | O23: 0.011232826 | P23: 0.011232826 | S23: 3 | T23: Arg-Chi | V23: 3 | W23: BIO05 | X23: MinBIOBSL-03
A24: Africa_north | B24: MAF | C24: Logging residues | D24: BIO03 | E24: scenBASE | F24: 0 | G24: 1.2550391e-05 | H24: 1.2550391e-05 | I24: 1.0408341e-17 | J24: -8.8978293e-05 | K24: 0 | L24: 0.00013754181 | M24: 2.5058631e-05 | N24: 1.2255996e-05 | O24: -4.0196066e-05 | P24: 0.00058308565 | S24: 4 | T24: Asia_central | V24: 4 | W24: BIO08 | X24: MinBIOBSL-04
A25: Africa_north | B25: MAF | C25: Logging residues | D25: BIO05 | E25: scenBASE | F25: 0 | G25: 0 | H25: 0 | I25: -1.0408341e-17 | J25: -8.7167589e-05 | K25: 0.00032171727 | L25: 7.1973886e-05 | M25: 0.0041461938 | N25: 0.0072180525 | O25: 0.0074233483 | P25: 0.0068000665 | S25: 5 | T25: Asia_east | V25: 5 | W25: BIO13 | X25: MinBIOBSL-05
A26: Africa_north | B26: MAF | C26: Logging residues | D26: BIO08 | E26: scenBASE | F26: 0 | G26: 0 | H26: 0 | I26: 0 | J26: -4.864545e-05 | K26: 0.0046079141 | L26: 0.0073023756 | M26: 0.0035024559 | N26: 0.00047198976 | O26: 0.00033298058 | P26: 0.0003715906 | S26: 6 | T26: Asia_other | V26: 6 | W26: BIO30 | X26: MinBIOBSL-06
A27: Africa_north | B27: MAF | C27: Logging residues | D27: BIO13 | E27: scenBASE | F27: 0 | G27: 2.4044485e-05 | H27: 2.4044485e-05 | I27: 0 | J27: 0.0071595735 | K27: 0.0027806307 | L27: 0.00060293445 | M27: 0.00022347185 | N27: 0.00016163507 | O27: 0.00017197468 | P27: 0.00022932953 | S27: 7 | T27: Australia_NZ | V27: 7 | W27: BIO60 | X27: MinBIOBSL-07
A28: Africa_north | B28: MAF | C28: Logging residues | D28: BIO30 | E28: scenBASE | F28: 0 | G28: -3.6594876e-05 | H28: -3.6594876e-05 | I28: 0.0084844768 | J28: 0.0018886257 | K28: 0.00079494949 | L28: 0.00029133913 | M28: 0.00028337886 | N28: 0.00023251343 | O28: 0.00020847312 | P28: 0.00011618452 | S28: 8 | T28: Brazil
A29: Africa_north | B29: MAF | C29: Logging residues | D29: BIO60 | E29: scenBASE | F29: 0 | G29: -4.1933728e-05 | H29: -4.1933728e-05 | I29: 0.0017562755 | J29: 0.00022217377 | K29: 0.00010056085 | L29: 7.1897134e-05 | M29: 7.1627491e-06 | N29: 5.9890801e-06 | O29: 6.1417734e-06 | P29: 2.6921496e-06 | S29: 9 | T29: Canada
A30: Africa_north | B30: MAF | C30: Other Solid | D30: BIO00 | E30: scenBASE | F30: 0.038901598 | G30: 0.029220312 | H30: 0.029220312 | I30: 0.010713309 | J30: 0.0043775885 | K30: 3.2932252e-18 | L30: 1.3172901e-17 | M30: 0 | N30: 0 | O30: 0 | P30: 0 | S30: 10 | T30: China
A31: Africa_north | B31: MAF | C31: Other Solid | D31: BIO03 | E31: scenBASE | F31: 0 | G31: 1.179612e-16 | H31: 1.179612e-16 | I31: 1.2143064e-17 | J31: 1.2143064e-17 | K31: -3.2932252e-18 | L31: -1.3172901e-17 | M31: 0 | N31: 3.2932252e-18 | O31: 3.2932252e-18 | P31: 0 | S31: 11 | T31: EU_north
A32: Africa_north | B32: MAF | C32: Other Solid | D32: BIO05 | E32: scenBASE | F32: 0 | G32: 0 | H32: 0 | I32: -1.2143064e-17 | J32: 1.2143064e-17 | K32: 0 | L32: 3.2932252e-18 | M32: 0 | N32: 6.5864504e-18 | O32: 3.2932252e-18 | P32: 0 | S32: 12 | T32: EU_northeast
A33: Africa_north | B33: MAF | C33: Other Solid | D33: BIO08 | E33: scenBASE | F33: 0 | G33: 0 | H33: 0 | I33: 0 | J33: -2.4286129e-17 | K33: 6.5864504e-18 | L33: 3.2932252e-18 | M33: 9.8796755e-18 | N33: -9.8796755e-18 | O33: -6.5864504e-18 | P33: 1.3172901e-17 | S33: 13 | T33: EU_northwest
A34: Africa_north | B34: MAF | C34: Other Solid | D34: BIO13 | E34: scenBASE | F34: 0 | G34: 0 | H34: 0 | I34: 0 | J34: 2.4286129e-17 | K34: -6.5864504e-18 | L34: -6.5864504e-18 | M34: -6.5864504e-18 | N34: 6.5864504e-18 | O34: 1.3172901e-17 | P34: -1.3172901e-17 | S34: 14 | T34: EU_south
A35: Africa_north | B35: MAF | C35: Other Solid | D35: BIO30 | E35: scenBASE | F35: 0 | G35: 0 | H35: 0 | I35: 0 | J35: -1.2143064e-17 | K35: 0 | L35: 6.5864504e-18 | M35: 1.6466126e-17 | N35: -6.5864504e-18 | O35: 3.6225477e-17 | P35: 2.3052576e-17 | S35: 15 | T35: EU_southeast
A36: Africa_north | B36: MAF | C36: Other Solid | D36: BIO60 | E36: scenBASE | F36: 0 | G36: -1.179612e-16 | H36: -1.179612e-16 | I36: -1.2143064e-17 | J36: -2.3418767e-17 | K36: 0 | L36: -6.5864504e-18 | M36: -1.9759351e-17 | N36: 9.8796755e-18 | O36: -3.2932252e-17 | P36: -2.3052576e-17 | S36: 16 | T36: EU_southwest
A37: Africa_north | B37: MAF | C37: Roundwood harvest | D37: BIO00 | E37: scenBASE | F37: 0.00061957207 | G37: 0 | H37: 0 | I37: 0 | J37: 0 | K37: 0 | L37: 0 | M37: 0 | N37: 0 | O37: 0 | P37: 0 | S37: 17 | T37: Europe_other
A38: Africa_north | B38: MAF | C38: Roundwood harvest | D38: BIO03 | E38: scenBASE | F38: 0 | G38: 0 | H38: 0 | I38: 0 | J38: 0 | K38: 0 | L38: 0 | M38: 0 | N38: 0 | O38: 0 | P38: 0 | S38: 18 | T38: France
A39: Africa_north | B39: MAF | C39: Roundwood harvest | D39: BIO05 | E39: scenBASE | F39: 0 | G39: 0 | H39: 0 | I39: 0 | J39: 0 | K39: 0 | L39: 0 | M39: 0 | N39: 0 | O39: 0 | P39: 0 | S39: 19 | T39: Germany
... A50: Africa_other | B50: MAF | C50: Energy Crops | D50: BIO60 | E50: scenBASE | F50: 0 | G50: 0.0018854971 | H50: 0.0018854971 | I50: 0.32215817 | J50: 0.2222732 | K50: 0.20213567 | L50: 0.18182778 | M50: 0.15605897 | N50: 0.13981349 | O50: 0.095218541 | P50: 0.096716994 | S50: 30 | T50: \I:
...

Sheet Veda
C1: =D2 -> scenSDGs | D1: scenBASE | G1: =SUM(G6:G999)/1000 -> 46.881221 | H1: =SUM(H6:H999)/1000 -> 59.624766 | I1: =SUM(I6:I999)/1000 -> 59.624766 | J1: =SUM(J6:J999)/1000 -> 119.0718 | K1: =SUM(K6:K999)/1000 -> 155.90442 | L1: =SUM(L6:L999)/1000 -> 172.76533 | M1: =SUM(M6:M999)/1000 -> 185.49487 | N1: =SUM(N6:N999)/1000 -> 195.76937 | ... Q1: =SUM(Q6:Q999)/1000 -> 213.40925 | R1: EJ | T1: GLOBAL potential
D2: scenSDGs
F4: ~FI_T: ACT_BND~UP | T4: ~FI_T: COST~USD00 | AE4: ~FI_Process
D5: region | E5: process | F5: comm-out | G5: ='Globiom data'!F1 -> *2010 | H5: ='Globiom data'!G1 -> 2018 | I5: ='Globiom data'!H1 -> 2020 | J5: ='Globiom data'!I1 -> 2030 | K5: ='Globiom data'!J1 -> 2040 | L5: ='Globiom data'!K1 -> 2050 | M5: ='Globiom data'!L1 -> 2060 | N5: ='Globiom data'!M1 -> 2070 | ... Q5: ='Globiom data'!P1 -> 2100 | R5: 0 | T5: process | U5: =I5 -> 2020 | V5: =J5 -> 2030 | W5: =K5 -> 2040 | X5: =L5 -> 2050 | Y5: =M5 -> 2060 | Z5: =N5 -> 2070 | AA5: =O5 -> 2080 | AB5: =P5 -> 2090 | AC5: =Q5 -> 2100 | AE5: Sets | AF5: TechName | AG5: TechDesc | AH5: Tact | AI5: Tcap
A6: 1 | B6: 1 | D6: =VLOOKUP(A6,'Globiom data'!$S$21:$T$51,2,FALSE) -> Africa_north | E6: =VLOOKUP(B6,'Globiom data'!$V$21:$X$30,3,FALSE) -> MinBIOBSL-01 | F6: BIOBSL | G6: =MAX(SUMIFS('Globiom data'!F$2:F$9999,'Globiom data'!$A$2:$A$9999,Veda!$D6,'Globiom data'!$D$2:$D$9999,VLOOKUP(Veda!$B6,'Globiom data'!$V$21:$X$29,2,FALSE),'Globiom data'!$E$2:$E$9999,Veda!$C$1),0)*1000 -> 106.52457 | H6: =MAX(SUMIFS('Globiom data'!G$2:G$9999,'Globiom data'!$A$2:$A$9999,Veda!$D6,'Globiom data'!$D$2:$D$9999,VLOOKUP(Veda!$B6,'Globiom data'!$V$21:$X$29,2,FALSE),'Globiom data'!$E$2:$E$9999,Veda!$C$1),0)*1000 -> 115.46718 | I6: =MAX(SUMIFS('Globiom data'!H$2:H$9999,'Globiom data'!$A$2:$A$9999,Veda!$D6,'Globiom data'!$D$2:$D$9999,VLOOKUP(Veda!$B6,'Globiom data'!$V$21:$X$29,2,FALSE),'Globiom data'!$E$2:$E$9999,Veda!$C$1),0)*1000 -> 115.46718 | J6: =MAX(SUMIFS('Globiom data'!I$2:I$9999,'Globiom data'!$A$2:$A$9999,Veda!$D6,'Globiom data'!$D$2:$D$9999,VLOOKUP(Veda!$B6,'Globiom data'!$V$21:$X$29,2,FALSE),'Globiom data'!$E$2:$E$9999,Veda!$C$1),0)*1000 -> 83.454537 | K6: =MAX(SUMIFS('Globiom data'!J$2:J$9999,'Globiom data'!$A$2:$A$9999,Veda!$D6,'Globiom data'!$D$2:$D$9999,VLOOKUP(Veda!$B6,'Globiom data'!$V$21:$X$29,2,FALSE),'Globiom data'!$E$2:$E$9999,Veda!$C$1),0)*1000 -> 73.236072 | L6: =MAX(SUMIFS('Globiom data'!K$2:K$9999,'Globiom data'!$A$2:$A$9999,Veda!$D6,'Globiom data'!$D$2:$D$9999,VLOOKUP(Veda!$B6,'Globiom data'!$V$21:$X$29,2,FALSE),'Globiom data'!$E$2:$E$9999,Veda!$C$1),0)*1000 -> 74.613676 | M6: =MAX(SUMIFS('Globiom data'!L$2:L$9999,'Globiom data'!$A$2:$A$9999,Veda!$D6,'Globiom data'!$D$2:$D$9999,VLOOKUP(Veda!$B6,'Globiom data'!$V$21:$X$29,2,FALSE),'Globiom data'!$E$2:$E$9999,Veda!$C$1),0)*1000 -> 76.108202 | N6: =MAX(SUMIFS('Globiom data'!M$2:M$9999,'Globiom data'!$A$2:$A$9999,Veda!$D6,'Globiom data'!$D$2:$D$9999,VLOOKUP(Veda!$B6,'Globiom data'!$V$21:$X$29,2,FALSE),'Globiom data'!$E$2:$E$9999,Veda!$C$1),0)*1000 -> 77.422211 | ... Q6: =MAX(SUMIFS('Globiom data'!P$2:P$9999,'Globiom data'!$A$2:$A$9999,Veda!$D6,'Globiom data'!$D$2:$D$9999,VLOOKUP(Veda!$B6,'Globiom data'!$V$21:$X$29,2,FALSE),'Globiom data'!$E$2:$E$9999,Veda!$C$1),0)*1000 -> 80.508736 | R6: 3 | T6: =E6 -> MinBIOBSL-01 | U6: =U7 -> 0.17647059 | V6: =V7 -> 0.52941176 | W6: =W7 -> 0.88235294 | X6: =X7 -> 1.2352941 | Y6: =Y7 -> 1.5882353 | Z6: =Z7 -> 1.9411765 | AA6: =AA7 -> 2.2941176 | AB6: =AB7 -> 2.6470588 | AC6: =AC7 -> 3 | AE6: MIN | AF6: =T6 -> MinBIOBSL-01 | AG6: ="Globium step - "&'Globiom data'!W21 -> Globium step - BIO00 | AH6: PJ | AI6: PJ-a
A7: 1 | B7: 2 | D7: =VLOOKUP(A7,'Globiom data'!$S$21:$T$51,2,FALSE) -> Africa_north | E7: =VLOOKUP(B7,'Globiom data'!$V$21:$X$30,3,FALSE) -> MinBIOBSL-02 | F7: BIOBSL | G7: =MAX(SUMIFS('Globiom data'!F$2:F$9999,'Globiom data'!$A$2:$A$9999,Veda!$D7,'Globiom data'!$D$2:$D$9999,VLOOKUP(Veda!$B7,'Globiom data'!$V$21:$X$29,2,FALSE),'Globiom data'!$E$2:$E$9999,Veda!$C$1),0)*1000 -> 0 | H7: =MAX(SUMIFS('Globiom data'!G$2:G$9999,'Globiom data'!$A$2:$A$9999,Veda!$D7,'Globiom data'!$D$2:$D$9999,VLOOKUP(Veda!$B7,'Globiom data'!$V$21:$X$29,2,FALSE),'Globiom data'!$E$2:$E$9999,Veda!$C$1),0)*1000 -> 0 | I7: =MAX(SUMIFS('Globiom data'!H$2:H$9999,'Globiom data'!$A$2:$A$9999,Veda!$D7,'Globiom data'!$D$2:$D$9999,VLOOKUP(Veda!$B7,'Globiom data'!$V$21:$X$29,2,FALSE),'Globiom data'!$E$2:$E$9999,Veda!$C$1),0)*1000 -> 0 | J7: =MAX(SUMIFS('Globiom data'!I$2:I$9999,'Globiom data'!$A$2:$A$9999,Veda!$D7,'Globiom data'!$D$2:$D$9999,VLOOKUP(Veda!$B7,'Globiom data'!$V$21:$X$29,2,FALSE),'Globiom data'!$E$2:$E$9999,Veda!$C$1),0)*1000 -> 0 | K7: =MAX(SUMIFS('Globiom data'!J$2:J$9999,'Globiom data'!$A$2:$A$9999,Veda!$D7,'Globiom data'!$D$2:$D$9999,VLOOKUP(Veda!$B7,'Globiom data'!$V$21:$X$29,2,FALSE),'Globiom data'!$E$2:$E$9999,Veda!$C$1),0)*1000 -> 0.096823027 | L7: =MAX(SUMIFS('Globiom data'!K$2:K$9999,'Globiom data'!$A$2:$A$9999,Veda!$D7,'Globiom data'!$D$2:$D$9999,VLOOKUP(Veda!$B7,'Globiom data'!$V$21:$X$29,2,FALSE),'Globiom data'!$E$2:$E$9999,Veda!$C$1),0)*1000 -> 0.41241291 | M7: =MAX(SUMIFS('Globiom data'!L$2:L$9999,'Globiom data'!$A$2:$A$9999,Veda!$D7,'Globiom data'!$D$2:$D$9999,VLOOKUP(Veda!$B7,'Globiom data'!$V$21:$X$29,2,FALSE),'Globiom data'!$E$2:$E$9999,Veda!$C$1),0)*1000 -> 13.659908 | N7: =MAX(SUMIFS('Globiom data'!M$2:M$9999,'Globiom data'!$A$2:$A$9999,Veda!$D7,'Globiom data'!$D$2:$D$9999,VLOOKUP(Veda!$B7,'Globiom data'!$V$21:$X$29,2,FALSE),'Globiom data'!$E$2:$E$9999,Veda!$C$1),0)*1000 -> 16.83651 | ... Q7: =MAX(SUMIFS('Globiom data'!P$2:P$9999,'Globiom data'!$A$2:$A$9999,Veda!$D7,'Globiom data'!$D$2:$D$9999,VLOOKUP(Veda!$B7,'Globiom data'!$V$21:$X$29,2,FALSE),'Globiom data'!$E$2:$E$9999,Veda!$C$1),0)*1000 -> 25.217719 | R7: 3 | T7: =E7 -> MinBIOBSL-02 | U7: ='Globiom data'!AA5 -> 0.17647059 | V7: ='Globiom data'!AB5 -> 0.52941176 | W7: ='Globiom data'!AC5 -> 0.88235294 | X7: ='Globiom data'!AD5 -> 1.2352941 | Y7: ='Globiom data'!AE5 -> 1.5882353 | Z7: ='Globiom data'!AF5 -> 1.9411765 | AA7: ='Globiom data'!AG5 -> 2.2941176 | AB7: ='Globiom data'!AH5 -> 2.6470588 | AC7: ='Globiom data'!AI5 -> 3 | AF7: =T7 -> MinBIOBSL-02 | AG7: ="Globium step - "&'Globiom data'!W22 -> Globium step - BIO03 | AH7: PJ | AI7: PJ-a
A8: 1 | B8: 3 | D8: =VLOOKUP(A8,'Globiom data'!$S$21:$T$51,2,FALSE) -> Africa_north | E8: =VLOOKUP(B8,'Globiom data'!$V$21:$X$30,3,FALSE) -> MinBIOBSL-03 | F8: BIOBSL | G8: =MAX(SUMIFS('Globiom data'!F$2:F$9999,'Globiom data'!$A$2:$A$9999,Veda!$D8,'Globiom data'!$D$2:$D$9999,VLOOKUP(Veda!$B8,'Globiom data'!$V$21:$X$29,2,FALSE),'Globiom data'!$E$2:$E$9999,Veda!$C$1),0)*1000 -> 0 | H8: =MAX(SUMIFS('Globiom data'!G$2:G$9999,'Globiom data'!$A$2:$A$9999,Veda!$D8,'Globiom data'!$D$2:$D$9999,VLOOKUP(Veda!$B8,'Globiom data'!$V$21:$X$29,2,FALSE),'Globiom data'!$E$2:$E$9999,Veda!$C$1),0)*1000 -> 0 | I8: =MAX(SUMIFS('Globiom data'!H$2:H$9999,'Globiom data'!$A$2:$A$9999,Veda!$D8,'Globiom data'!$D$2:$D$9999,VLOOKUP(Veda!$B8,'Globiom data'!$V$21:$X$29,2,FALSE),'Globiom data'!$E$2:$E$9999,Veda!$C$1),0)*1000 -> 0 | J8: =MAX(SUMIFS('Globiom data'!I$2:I$9999,'Globiom data'!$A$2:$A$9999,Veda!$D8,'Globiom data'!$D$2:$D$9999,VLOOKUP(Veda!$B8,'Globiom data'!$V$21:$X$29,2,FALSE),'Globiom data'!$E$2:$E$9999,Veda!$C$1),0)*1000 -> 0 | K8: =MAX(SUMIFS('Globiom data'!J$2:J$9999,'Globiom data'!$A$2:$A$9999,Veda!$D8,'Globiom data'!$D$2:$D$9999,VLOOKUP(Veda!$B8,'Globiom data'!$V$21:$X$29,2,FALSE),'Globiom data'!$E$2:$E$9999,Veda!$C$1),0)*1000 -> 0 | L8: =MAX(SUMIFS('Globiom data'!K$2:K$9999,'Globiom data'!$A$2:$A$9999,Veda!$D8,'Globiom data'!$D$2:$D$9999,VLOOKUP(Veda!$B8,'Globiom data'!$V$21:$X$29,2,FALSE),'Globiom data'!$E$2:$E$9999,Veda!$C$1),0)*1000 -> 8.6377858 | M8: =MAX(SUMIFS('Globiom data'!L$2:L$9999,'Globiom data'!$A$2:$A$9999,Veda!$D8,'Globiom data'!$D$2:$D$9999,VLOOKUP(Veda!$B8,'Globiom data'!$V$21:$X$29,2,FALSE),'Globiom data'!$E$2:$E$9999,Veda!$C$1),0)*1000 -> 0 | N8: =MAX(SUMIFS('Globiom data'!M$2:M$9999,'Globiom data'!$A$2:$A$9999,Veda!$D8,'Globiom data'!$D$2:$D$9999,VLOOKUP(Veda!$B8,'Globiom data'!$V$21:$X$29,2,FALSE),'Globiom data'!$E$2:$E$9999,Veda!$C$1),0)*1000 -> 3.9140652 | ... Q8: =MAX(SUMIFS('Globiom data'!P$2:P$9999,'Globiom data'!$A$2:$A$9999,Veda!$D8,'Globiom data'!$D$2:$D$9999,VLOOKUP(Veda!$B8,'Globiom data'!$V$21:$X$29,2,FALSE),'Globiom data'!$E$2:$E$9999,Veda!$C$1),0)*1000 -> 23.224136 | R8: 3 | T8: =E8 -> MinBIOBSL-03 | U8: ='Globiom data'!AA6 -> 0.29411765 | V8: ='Globiom data'!AB6 -> 0.88235294 | W8: ='Globiom data'!AC6 -> 1.4705882 | X8: ='Globiom data'!AD6 -> 2.0588235 | Y8: ='Globiom data'!AE6 -> 2.6470588 | Z8: ='Globiom data'!AF6 -> 3.2352941 | AA8: ='Globiom data'!AG6 -> 3.8235294 | AB8: ='Globiom data'!AH6 -> 4.4117647 | AC8: ='Globiom data'!AI6 -> 5 | AF8: =T8 -> MinBIOBSL-03 | AG8: ="Globium step - "&'Globiom data'!W23 -> Globium step - BIO05 | AH8: PJ | AI8: PJ-a
A9: 1 | B9: 4 | D9: =VLOOKUP(A9,'Globiom data'!$S$21:$T$51,2,FALSE) -> Africa_north | E9: =VLOOKUP(B9,'Globiom data'!$V$21:$X$30,3,FALSE) -> MinBIOBSL-04 | F9: BIOBSL | G9: =MAX(SUMIFS('Globiom data'!F$2:F$9999,'Globiom data'!$A$2:$A$9999,Veda!$D9,'Globiom data'!$D$2:$D$9999,VLOOKUP(Veda!$B9,'Globiom data'!$V$21:$X$29,2,FALSE),'Globiom data'!$E$2:$E$9999,Veda!$C$1),0)*1000 -> 0 | H9: =MAX(SUMIFS('Globiom data'!G$2:G$9999,'Globiom data'!$A$2:$A$9999,Veda!$D9,'Globiom data'!$D$2:$D$9999,VLOOKUP(Veda!$B9,'Globiom data'!$V$21:$X$29,2,FALSE),'Globiom data'!$E$2:$E$9999,Veda!$C$1),0)*1000 -> 1.179612e-13 | I9: =MAX(SUMIFS('Globiom data'!H$2:H$9999,'Globiom data'!$A$2:$A$9999,Veda!$D9,'Globiom data'!$D$2:$D$9999,VLOOKUP(Veda!$B9,'Globiom data'!$V$21:$X$29,2,FALSE),'Globiom data'!$E$2:$E$9999,Veda!$C$1),0)*1000 -> 1.179612e-13 | J9: =MAX(SUMIFS('Globiom data'!I$2:I$9999,'Globiom data'!$A$2:$A$9999,Veda!$D9,'Globiom data'!$D$2:$D$9999,VLOOKUP(Veda!$B9,'Globiom data'!$V$21:$X$29,2,FALSE),'Globiom data'!$E$2:$E$9999,Veda!$C$1),0)*1000 -> 0.049746232 | K9: =MAX(SUMIFS('Globiom data'!J$2:J$9999,'Globiom data'!$A$2:$A$9999,Veda!$D9,'Globiom data'!$D$2:$D$9999,VLOOKUP(Veda!$B9,'Globiom data'!$V$21:$X$29,2,FALSE),'Globiom data'!$E$2:$E$9999,Veda!$C$1),0)*1000 -> 6.0441659 | L9: =MAX(SUMIFS('Globiom data'!K$2:K$9999,'Globiom data'!$A$2:$A$9999,Veda!$D9,'Globiom data'!$D$2:$D$9999,VLOOKUP(Veda!$B9,'Globiom data'!$V$21:$X$29,2,FALSE),'Globiom data'!$E$2:$E$9999,Veda!$C$1),0)*1000 -> 6.1564835 | M9: =MAX(SUMIFS('Globiom data'!L$2:L$9999,'Globiom data'!$A$2:$A$9999,Veda!$D9,'Globiom data'!$D$2:$D$9999,VLOOKUP(Veda!$B9,'Globiom data'!$V$21:$X$29,2,FALSE),'Globiom data'!$E$2:$E$9999,Veda!$C$1),0)*1000 -> 17.030691 | N9: =MAX(SUMIFS('Globiom data'!M$2:M$9999,'Globiom data'!$A$2:$A$9999,Veda!$D9,'Globiom data'!$D$2:$D$9999,VLOOKUP(Veda!$B9,'Globiom data'!$V$21:$X$29,2,FALSE),'Globiom data'!$E$2:$E$9999,Veda!$C$1),0)*1000 -> 18.571699 | ... Q9: =MAX(SUMIFS('Globiom data'!P$2:P$9999,'Globiom data'!$A$2:$A$9999,Veda!$D9,'Globiom data'!$D$2:$D$9999,VLOOKUP(Veda!$B9,'Globiom data'!$V$21:$X$29,2,FALSE),'Globiom data'!$E$2:$E$9999,Veda!$C$1),0)*1000 -> 22.843433 | R9: 3 | T9: =E9 -> MinBIOBSL-04 | U9: ='Globiom data'!AA7 -> 0.47058824 | V9: ='Globiom data'!AB7 -> 1.4117647 | W9: ='Globiom data'!AC7 -> 2.3529412 | X9: ='Globiom data'!AD7 -> 3.2941176 | Y9: ='Globiom data'!AE7 -> 4.2352941 | Z9: ='Globiom data'!AF7 -> 5.1764706 | AA9: ='Globiom data'!AG7 -> 6.1176471 | AB9: ='Globiom data'!AH7 -> 7.0588235 | AC9: ='Globiom data'!AI7 -> 8 | AF9: =T9 -> MinBIOBSL-04 | AG9: ="Globium step - "&'Globiom data'!W24 -> Globium step - BIO08 | AH9: PJ | AI9: PJ-a
A10: 1 | B10: 5 | D10: =VLOOKUP(A10,'Globiom data'!$S$21:$T$51,2,FALSE) -> Africa_north | E10: =VLOOKUP(B10,'Globiom data'!$V$21:$X$30,3,FALSE) -> MinBIOBSL-05 | F10: BIOBSL | G10: =MAX(SUMIFS('Globiom data'!F$2:F$9999,'Globiom data'!$A$2:$A$9999,Veda!$D10,'Globiom data'!$D$2:$D$9999,VLOOKUP(Veda!$B10,'Globiom data'!$V$21:$X$29,2,FALSE),'Globiom data'!$E$2:$E$9999,Veda!$C$1),0)*1000 -> 0 | H10: =MAX(SUMIFS('Globiom data'!G$2:G$9999,'Globiom data'!$A$2:$A$9999,Veda!$D10,'Globiom data'!$D$2:$D$9999,VLOOKUP(Veda!$B10,'Globiom data'!$V$21:$X$29,2,FALSE),'Globiom data'!$E$2:$E$9999,Veda!$C$1),0)*1000 -> 0.029479272 | I10: =MAX(SUMIFS('Globiom data'!H$2:H$9999,'Globiom data'!$A$2:$A$9999,Veda!$D10,'Globiom data'!$D$2:$D$9999,VLOOKUP(Veda!$B10,'Globiom data'!$V$21:$X$29,2,FALSE),'Globiom data'!$E$2:$E$9999,Veda!$C$1),0)*1000 -> 0.029479272 | J10: =MAX(SUMIFS('Globiom data'!I$2:I$9999,'Globiom data'!$A$2:$A$9999,Veda!$D10,'Globiom data'!$D$2:$D$9999,VLOOKUP(Veda!$B10,'Globiom data'!$V$21:$X$29,2,FALSE),'Globiom data'!$E$2:$E$9999,Veda!$C$1),0)*1000 -> 6.2982169 | K10: =MAX(SUMIFS('Globiom data'!J$2:J$9999,'Globiom data'!$A$2:$A$9999,Veda!$D10,'Globiom data'!$D$2:$D$9999,VLOOKUP(Veda!$B10,'Globiom data'!$V$21:$X$29,2,FALSE),'Globiom data'!$E$2:$E$9999,Veda!$C$1),0)*1000 -> 15.966649 | L10: =MAX(SUMIFS('Globiom data'!K$2:K$9999,'Globiom data'!$A$2:$A$9999,Veda!$D10,'Globiom data'!$D$2:$D$9999,VLOOKUP(Veda!$B10,'Globiom data'!$V$21:$X$29,2,FALSE),'Globiom data'!$E$2:$E$9999,Veda!$C$1),0)*1000 -> 20.892844 | M10: =MAX(SUMIFS('Globiom data'!L$2:L$9999,'Globiom data'!$A$2:$A$9999,Veda!$D10,'Globiom data'!$D$2:$D$9999,VLOOKUP(Veda!$B10,'Globiom data'!$V$21:$X$29,2,FALSE),'Globiom data'!$E$2:$E$9999,Veda!$C$1),0)*1000 -> 15.929482 | N10: =MAX(SUMIFS('Globiom data'!M$2:M$9999,'Globiom data'!$A$2:$A$9999,Veda!$D10,'Globiom data'!$D$2:$D$9999,VLOOKUP(Veda!$B10,'Globiom data'!$V$21:$X$29,2,FALSE),'Globiom data'!$E$2:$E$9999,Veda!$C$1),0)*1000 -> 27.616925 | ... Q10: =MAX(SUMIFS('Globiom data'!P$2:P$9999,'Globiom data'!$A$2:$A$9999,Veda!$D10,'Globiom data'!$D$2:$D$9999,VLOOKUP(Veda!$B10,'Globiom data'!$V$21:$X$29,2,FALSE),'Globiom data'!$E$2:$E$9999,Veda!$C$1),0)*1000 -> 45.146799 | R10: 3 | T10: =E10 -> MinBIOBSL-05 | U10: ='Globiom data'!AA8 -> 0.76470588 | V10: ='Globiom data'!AB8 -> 2.2941176 | W10: ='Globiom data'!AC8 -> 3.8235294 | X10: ='Globiom data'!AD8 -> 5.3529412 | Y10: ='Globiom data'!AE8 -> 6.8823529 | Z10: ='Globiom data'!AF8 -> 8.4117647 | AA10: ='Globiom data'!AG8 -> 9.9411765 | AB10: ='Globiom data'!AH8 -> 11.470588 | AC10: ='Globiom data'!AI8 -> 13 | AF10: =T10 -> MinBIOBSL-05 | AG10: ="Globium step - "&'Globiom data'!W25 -> Globium step - BIO13 | AH10: PJ | AI10: PJ-a
A11: 1 | B11: 6 | D11: =VLOOKUP(A11,'Globiom data'!$S$21:$T$51,2,FALSE) -> Africa_north | E11: =VLOOKUP(B11,'Globiom data'!$V$21:$X$30,3,FALSE) -> MinBIOBSL-06 | F11: BIOBSL | G11: =MAX(SUMIFS('Globiom data'!F$2:F$9999,'Globiom data'!$A$2:$A$9999,Veda!$D11,'Globiom data'!$D$2:$D$9999,VLOOKUP(Veda!$B11,'Globiom data'!$V$21:$X$29,2,FALSE),'Globiom data'!$E$2:$E$9999,Veda!$C$1),0)*1000 -> 0 | H11: =MAX(SUMIFS('Globiom data'!G$2:G$9999,'Globiom data'!$A$2:$A$9999,Veda!$D11,'Globiom data'!$D$2:$D$9999,VLOOKUP(Veda!$B11,'Globiom data'!$V$21:$X$29,2,FALSE),'Globiom data'!$E$2:$E$9999,Veda!$C$1),0)*1000 -> 2.1180894 | I11: =MAX(SUMIFS('Globiom data'!H$2:H$9999,'Globiom data'!$A$2:$A$9999,Veda!$D11,'Globiom data'!$D$2:$D$9999,VLOOKUP(Veda!$B11,'Globiom data'!$V$21:$X$29,2,FALSE),'Globiom data'!$E$2:$E$9999,Veda!$C$1),0)*1000 -> 2.1180894 | J11: =MAX(SUMIFS('Globiom data'!I$2:I$9999,'Globiom data'!$A$2:$A$9999,Veda!$D11,'Globiom data'!$D$2:$D$9999,VLOOKUP(Veda!$B11,'Globiom data'!$V$21:$X$29,2,FALSE),'Globiom data'!$E$2:$E$9999,Veda!$C$1),0)*1000 -> 26.548701 | K11: =MAX(SUMIFS('Globiom data'!J$2:J$9999,'Globiom data'!$A$2:$A$9999,Veda!$D11,'Globiom data'!$D$2:$D$9999,VLOOKUP(Veda!$B11,'Globiom data'!$V$21:$X$29,2,FALSE),'Globiom data'!$E$2:$E$9999,Veda!$C$1),0)*1000 -> 30.622981 | L11: =MAX(SUMIFS('Globiom data'!K$2:K$9999,'Globiom data'!$A$2:$A$9999,Veda!$D11,'Globiom data'!$D$2:$D$9999,VLOOKUP(Veda!$B11,'Globiom data'!$V$21:$X$29,2,FALSE),'Globiom data'!$E$2:$E$9999,Veda!$C$1),0)*1000 -> 33.582618 | M11: =MAX(SUMIFS('Globiom data'!L$2:L$9999,'Globiom data'!$A$2:$A$9999,Veda!$D11,'Globiom data'!$D$2:$D$9999,VLOOKUP(Veda!$B11,'Globiom data'!$V$21:$X$29,2,FALSE),'Globiom data'!$E$2:$E$9999,Veda!$C$1),0)*1000 -> 41.268061 | N11: =MAX(SUMIFS('Globiom data'!M$2:M$9999,'Globiom data'!$A$2:$A$9999,Veda!$D11,'Globiom data'!$D$2:$D$9999,VLOOKUP(Veda!$B11,'Globiom data'!$V$21:$X$29,2,FALSE),'Globiom data'!$E$2:$E$9999,Veda!$C$1),0)*1000 -> 35.766441 | ... Q11: =MAX(SUMIFS('Globiom data'!P$2:P$9999,'Globiom data'!$A$2:$A$9999,Veda!$D11,'Globiom data'!$D$2:$D$9999,VLOOKUP(Veda!$B11,'Globiom data'!$V$21:$X$29,2,FALSE),'Globiom data'!$E$2:$E$9999,Veda!$C$1),0)*1000 -> 24.703563 | R11: 3 | T11: =E11 -> MinBIOBSL-06 | U11: ='Globiom data'!AA9 -> 1.7647059 | V11: ='Globiom data'!AB9 -> 5.2941176 | W11: ='Globiom data'!AC9 -> 8.8235294 | X11: ='Globiom data'!AD9 -> 12.352941 | Y11: ='Globiom data'!AE9 -> 15.882353 | Z11: ='Globiom data'!AF9 -> 19.411765 | AA11: ='Globiom data'!AG9 -> 22.941176 | AB11: ='Globiom data'!AH9 -> 26.470588 | AC11: ='Globiom data'!AI9 -> 30 | AF11: =T11 -> MinBIOBSL-06 | AG11: ="Globium step - "&'Globiom data'!W26 -> Globium step - BIO30 | AH11: PJ | AI11: PJ-a
A12: 1 | B12: 7 | D12: =VLOOKUP(A12,'Globiom data'!$S$21:$T$51,2,FALSE) -> Africa_north | E12: =VLOOKUP(B12,'Globiom data'!$V$21:$X$30,3,FALSE) -> MinBIOBSL-07 | F12: BIOBSL | G12: =MAX(SUMIFS('Globiom data'!F$2:F$9999,'Globiom data'!$A$2:$A$9999,Veda!$D12,'Globiom data'!$D$2:$D$9999,VLOOKUP(Veda!$B12,'Globiom data'!$V$21:$X$29,2,FALSE),'Globiom data'!$E$2:$E$9999,Veda!$C$1),0)*1000 -> 0 | H12: =MAX(SUMIFS('Globiom data'!G$2:G$9999,'Globiom data'!$A$2:$A$9999,Veda!$D12,'Globiom data'!$D$2:$D$9999,VLOOKUP(Veda!$B12,'Globiom data'!$V$21:$X$29,2,FALSE),'Globiom data'!$E$2:$E$9999,Veda!$C$1),0)*1000 -> 0 | I12: =MAX(SUMIFS('Globiom data'!H$2:H$9999,'Globiom data'!$A$2:$A$9999,Veda!$D12,'Globiom data'!$D$2:$D$9999,VLOOKUP(Veda!$B12,'Globiom data'!$V$21:$X$29,2,FALSE),'Globiom data'!$E$2:$E$9999,Veda!$C$1),0)*1000 -> 0 | J12: =MAX(SUMIFS('Globiom data'!I$2:I$9999,'Globiom data'!$A$2:$A$9999,Veda!$D12,'Globiom data'!$D$2:$D$9999,VLOOKUP(Veda!$B12,'Globiom data'!$V$21:$X$29,2,FALSE),'Globiom data'!$E$2:$E$9999,Veda!$C$1),0)*1000 -> 30.917213 | K12: =MAX(SUMIFS('Globiom data'!J$2:J$9999,'Globiom data'!$A$2:$A$9999,Veda!$D12,'Globiom data'!$D$2:$D$9999,VLOOKUP(Veda!$B12,'Globiom data'!$V$21:$X$29,2,FALSE),'Globiom data'!$E$2:$E$9999,Veda!$C$1),0)*1000 -> 26.837255 | L12: =MAX(SUMIFS('Globiom data'!K$2:K$9999,'Globiom data'!$A$2:$A$9999,Veda!$D12,'Globiom data'!$D$2:$D$9999,VLOOKUP(Veda!$B12,'Globiom data'!$V$21:$X$29,2,FALSE),'Globiom data'!$E$2:$E$9999,Veda!$C$1),0)*1000 -> 28.975294 | M12: =MAX(SUMIFS('Globiom data'!L$2:L$9999,'Globiom data'!$A$2:$A$9999,Veda!$D12,'Globiom data'!$D$2:$D$9999,VLOOKUP(Veda!$B12,'Globiom data'!$V$21:$X$29,2,FALSE),'Globiom data'!$E$2:$E$9999,Veda!$C$1),0)*1000 -> 35.163779 | N12: =MAX(SUMIFS('Globiom data'!M$2:M$9999,'Globiom data'!$A$2:$A$9999,Veda!$D12,'Globiom data'!$D$2:$D$9999,VLOOKUP(Veda!$B12,'Globiom data'!$V$21:$X$29,2,FALSE),'Globiom data'!$E$2:$E$9999,Veda!$C$1),0)*1000 -> 38.235409 | ... Q12: =MAX(SUMIFS('Globiom data'!P$2:P$9999,'Globiom data'!$A$2:$A$9999,Veda!$D12,'Globiom data'!$D$2:$D$9999,VLOOKUP(Veda!$B12,'Globiom data'!$V$21:$X$29,2,FALSE),'Globiom data'!$E$2:$E$9999,Veda!$C$1),0)*1000 -> 44.607746 | R12: 3 | T12: =E12 -> MinBIOBSL-07 | U12: ='Globiom data'!AA10 -> 3.5294118 | V12: ='Globiom data'!AB10 -> 10.588235 | W12: ='Globiom data'!AC10 -> 17.647059 | X12: ='Globiom data'!AD10 -> 24.705882 | Y12: ='Globiom data'!AE10 -> 31.764706 | Z12: ='Globiom data'!AF10 -> 38.823529 | AA12: ='Globiom data'!AG10 -> 45.882353 | AB12: ='Globiom data'!AH10 -> 52.941176 | AC12: ='Globiom data'!AI10 -> 60 | AF12: =T12 -> MinBIOBSL-07 | AG12: ="Globium step - "&'Globiom data'!W27 -> Globium step - BIO60 | AH12: PJ | AI12: PJ-a
A13: =A6+1 -> 2 | B13: =B6 -> 1 | D13: =VLOOKUP(A13,'Globiom data'!$S$21:$T$51,2,FALSE) -> Africa_other | E13: =VLOOKUP(B13,'Globiom data'!$V$21:$X$30,3,FALSE) -> MinBIOBSL-01 | F13: BIOBSL | G13: =MAX(SUMIFS('Globiom data'!F$2:F$9999,'Globiom data'!$A$2:$A$9999,Veda!$D13,'Globiom data'!$D$2:$D$9999,VLOOKUP(Veda!$B13,'Globiom data'!$V$21:$X$29,2,FALSE),'Globiom data'!$E$2:$E$9999,Veda!$C$1),0)*1000 -> 9140.4346 | H13: =MAX(SUMIFS('Globiom data'!G$2:G$9999,'Globiom data'!$A$2:$A$9999,Veda!$D13,'Globiom data'!$D$2:$D$9999,VLOOKUP(Veda!$B13,'Globiom data'!$V$21:$X$29,2,FALSE),'Globiom data'!$E$2:$E$9999,Veda!$C$1),0)*1000 -> 10341.675 | I13: =MAX(SUMIFS('Globiom data'!H$2:H$9999,'Globiom data'!$A$2:$A$9999,Veda!$D13,'Globiom data'!$D$2:$D$9999,VLOOKUP(Veda!$B13,'Globiom data'!$V$21:$X$29,2,FALSE),'Globiom data'!$E$2:$E$9999,Veda!$C$1),0)*1000 -> 10341.675 | J13: =MAX(SUMIFS('Globiom data'!I$2:I$9999,'Globiom data'!$A$2:$A$9999,Veda!$D13,'Globiom data'!$D$2:$D$9999,VLOOKUP(Veda!$B13,'Globiom data'!$V$21:$X$29,2,FALSE),'Globiom data'!$E$2:$E$9999,Veda!$C$1),0)*1000 -> 11109.749 | K13: =MAX(SUMIFS('Globiom data'!J$2:J$9999,'Globiom data'!$A$2:$A$9999,Veda!$D13,'Globiom data'!$D$2:$D$9999,VLOOKUP(Veda!$B13,'Globiom data'!$V$21:$X$29,2,FALSE),'Globiom data'!$E$2:$E$9999,Veda!$C$1),0)*1000 -> 11632.493 | L13: =MAX(SUMIFS('Globiom data'!K$2:K$9999,'Globiom data'!$A$2:$A$9999,Veda!$D13,'Globiom data'!$D$2:$D$9999,VLOOKUP(Veda!$B13,'Globiom data'!$V$21:$X$29,2,FALSE),'Globiom data'!$E$2:$E$9999,Veda!$C$1),0)*1000 -> 11281.69 | M13: =MAX(SUMIFS('Globiom data'!L$2:L$9999,'Globiom data'!$A$2:$A$9999,Veda!$D13,'Globiom data'!$D$2:$D$9999,VLOOKUP(Veda!$B13,'Globiom data'!$V$21:$X$29,2,FALSE),'Globiom data'!$E$2:$E$9999,Veda!$C$1),0)*1000 -> 9886.1695 | N13: =MAX(SUMIFS('Globiom data'!M$2:M$9999,'Globiom data'!$A$2:$A$9999,Veda!$D13,'Globiom data'!$D$2:$D$9999,VLOOKUP(Veda!$B13,'Globiom data'!$V$21:$X$29,2,FALSE),'Globiom data'!$E$2:$E$9999,Veda!$C$1),0)*1000 -> 7267.7569 | ... Q13: =MAX(SUMIFS('Globiom data'!P$2:P$9999,'Globiom data'!$A$2:$A$9999,Veda!$D13,'Globiom data'!$D$2:$D$9999,VLOOKUP(Veda!$B13,'Globiom data'!$V$21:$X$29,2,FALSE),'Globiom data'!$E$2:$E$9999,Veda!$C$1),0)*1000 -> 1847.9076 | R13: 3
A14: =A7+1 -> 2 | B14: =B7 -> 2 | D14: =VLOOKUP(A14,'Globiom data'!$S$21:$T$51,2,FALSE) -> Africa_other | E14: =VLOOKUP(B14,'Globiom data'!$V$21:$X$30,3,FALSE) -> MinBIOBSL-02 | F14: BIOBSL | G14: =MAX(SUMIFS('Globiom data'!F$2:F$9999,'Globiom data'!$A$2:$A$9999,Veda!$D14,'Globiom data'!$D$2:$D$9999,VLOOKUP(Veda!$B14,'Globiom data'!$V$21:$X$29,2,FALSE),'Globiom data'!$E$2:$E$9999,Veda!$C$1),0)*1000 -> 0 | H14: =MAX(SUMIFS('Globiom data'!G$2:G$9999,'Globiom data'!$A$2:$A$9999,Veda!$D14,'Globiom data'!$D$2:$D$9999,VLOOKUP(Veda!$B14,'Globiom data'!$V$21:$X$29,2,FALSE),'Globiom data'!$E$2:$E$9999,Veda!$C$1),0)*1000 -> 0 | I14: =MAX(SUMIFS('Globiom data'!H$2:H$9999,'Globiom data'!$A$2:$A$9999,Veda!$D14,'Globiom data'!$D$2:$D$9999,VLOOKUP(Veda!$B14,'Globiom data'!$V$21:$X$29,2,FALSE),'Globiom data'!$E$2:$E$9999,Veda!$C$1),0)*1000 -> 0 | J14: =MAX(SUMIFS('Globiom data'!I$2:I$9999,'Globiom data'!$A$2:$A$9999,Veda!$D14,'Globiom data'!$D$2:$D$9999,VLOOKUP(Veda!$B14,'Globiom data'!$V$21:$X$29,2,FALSE),'Globiom data'!$E$2:$E$9999,Veda!$C$1),0)*1000 -> 79.086537 | K14: =MAX(SUMIFS('Globiom data'!J$2:J$9999,'Globiom data'!$A$2:$A$9999,Veda!$D14,'Globiom data'!$D$2:$D$9999,VLOOKUP(Veda!$B14,'Globiom data'!$V$21:$X$29,2,FALSE),'Globiom data'!$E$2:$E$9999,Veda!$C$1),0)*1000 -> 91.02481 | L14: =MAX(SUMIFS('Globiom data'!K$2:K$9999,'Globiom data'!$A$2:$A$9999,Veda!$D14,'Globiom data'!$D$2:$D$9999,VLOOKUP(Veda!$B14,'Globiom data'!$V$21:$X$29,2,FALSE),'Globiom data'!$E$2:$E$9999,Veda!$C$1),0)*1000 -> 126.16897 | M14: =MAX(SUMIFS('Globiom data'!L$2:L$9999,'Globiom data'!$A$2:$A$9999,Veda!$D14,'Globiom data'!$D$2:$D$9999,VLOOKUP(Veda!$B14,'Globiom data'!$V$21:$X$29,2,FALSE),'Globiom data'!$E$2:$E$9999,Veda!$C$1),0)*1000 -> 684.78658 | N14: =MAX(SUMIFS('Globiom data'!M$2:M$9999,'Globiom data'!$A$2:$A$9999,Veda!$D14,'Globiom data'!$D$2:$D$9999,VLOOKUP(Veda!$B14,'Globiom data'!$V$21:$X$29,2,FALSE),'Globiom data'!$E$2:$E$9999,Veda!$C$1),0)*1000 -> 1044.6916 | ... Q14: =MAX(SUMIFS('Globiom data'!P$2:P$9999,'Globiom data'!$A$2:$A$9999,Veda!$D14,'Globiom data'!$D$2:$D$9999,VLOOKUP(Veda!$B14,'Globiom data'!$V$21:$X$29,2,FALSE),'Globiom data'!$E$2:$E$9999,Veda!$C$1),0)*1000 -> 3601.4799 | R14: 3
A15: =A8+1 -> 2 | B15: =B8 -> 3 | D15: =VLOOKUP(A15,'Globiom data'!$S$21:$T$51,2,FALSE) -> Africa_other | E15: =VLOOKUP(B15,'Globiom data'!$V$21:$X$30,3,FALSE) -> MinBIOBSL-03 | F15: BIOBSL | G15: =MAX(SUMIFS('Globiom data'!F$2:F$9999,'Globiom data'!$A$2:$A$9999,Veda!$D15,'Globiom data'!$D$2:$D$9999,VLOOKUP(Veda!$B15,'Globiom data'!$V$21:$X$29,2,FALSE),'Globiom data'!$E$2:$E$9999,Veda!$C$1),0)*1000 -> 0 | H15: =MAX(SUMIFS('Globiom data'!G$2:G$9999,'Globiom data'!$A$2:$A$9999,Veda!$D15,'Globiom data'!$D$2:$D$9999,VLOOKUP(Veda!$B15,'Globiom data'!$V$21:$X$29,2,FALSE),'Globiom data'!$E$2:$E$9999,Veda!$C$1),0)*1000 -> 0.081481739 | I15: =MAX(SUMIFS('Globiom data'!H$2:H$9999,'Globiom data'!$A$2:$A$9999,Veda!$D15,'Globiom data'!$D$2:$D$9999,VLOOKUP(Veda!$B15,'Globiom data'!$V$21:$X$29,2,FALSE),'Globiom data'!$E$2:$E$9999,Veda!$C$1),0)*1000 -> 0.081481739 | J15: =MAX(SUMIFS('Globiom data'!I$2:I$9999,'Globiom data'!$A$2:$A$9999,Veda!$D15,'Globiom data'!$D$2:$D$9999,VLOOKUP(Veda!$B15,'Globiom data'!$V$21:$X$29,2,FALSE),'Globiom data'!$E$2:$E$9999,Veda!$C$1),0)*1000 -> 10.459267 | K15: =MAX(SUMIFS('Globiom data'!J$2:J$9999,'Globiom data'!$A$2:$A$9999,Veda!$D15,'Globiom data'!$D$2:$D$9999,VLOOKUP(Veda!$B15,'Globiom data'!$V$21:$X$29,2,FALSE),'Globiom data'!$E$2:$E$9999,Veda!$C$1),0)*1000 -> 152.38378 | L15: =MAX(SUMIFS('Globiom data'!K$2:K$9999,'Globiom data'!$A$2:$A$9999,Veda!$D15,'Globiom data'!$D$2:$D$9999,VLOOKUP(Veda!$B15,'Globiom data'!$V$21:$X$29,2,FALSE),'Globiom data'!$E$2:$E$9999,Veda!$C$1),0)*1000 -> 281.67465 | M15: =MAX(SUMIFS('Globiom data'!L$2:L$9999,'Globiom data'!$A$2:$A$9999,Veda!$D15,'Globiom data'!$D$2:$D$9999,VLOOKUP(Veda!$B15,'Globiom data'!$V$21:$X$29,2,FALSE),'Globiom data'!$E$2:$E$9999,Veda!$C$1),0)*1000 -> 599.11814 | N15: =MAX(SUMIFS('Globiom data'!M$2:M$9999,'Globiom data'!$A$2:$A$9999,Veda!$D15,'Globiom data'!$D$2:$D$9999,VLOOKUP(Veda!$B15,'Globiom data'!$V$21:$X$29,2,FALSE),'Globiom data'!$E$2:$E$9999,Veda!$C$1),0)*1000 -> 3916.3766 | ... Q15: =MAX(SUMIFS('Globiom data'!P$2:P$9999,'Globiom data'!$A$2:$A$9999,Veda!$D15,'Globiom data'!$D$2:$D$9999,VLOOKUP(Veda!$B15,'Globiom data'!$V$21:$X$29,2,FALSE),'Globiom data'!$E$2:$E$9999,Veda!$C$1),0)*1000 -> 9132.6585 | R15: 3
A16: =A9+1 -> 2 | B16: =B9 -> 4 | D16: =VLOOKUP(A16,'Globiom data'!$S$21:$T$51,2,FALSE) -> Africa_other | E16: =VLOOKUP(B16,'Globiom data'!$V$21:$X$30,3,FALSE) -> MinBIOBSL-04 | F16: BIOBSL | G16: =MAX(SUMIFS('Globiom data'!F$2:F$9999,'Globiom data'!$A$2:$A$9999,Veda!$D16,'Globiom data'!$D$2:$D$9999,VLOOKUP(Veda!$B16,'Globiom data'!$V$21:$X$29,2,FALSE),'Globiom data'!$E$2:$E$9999,Veda!$C$1),0)*1000 -> 0 | H16: =MAX(SUMIFS('Globiom data'!G$2:G$9999,'Globiom data'!$A$2:$A$9999,Veda!$D16,'Globiom data'!$D$2:$D$9999,VLOOKUP(Veda!$B16,'Globiom data'!$V$21:$X$29,2,FALSE),'Globiom data'!$E$2:$E$9999,Veda!$C$1),0)*1000 -> 0 | I16: =MAX(SUMIFS('Globiom data'!H$2:H$9999,'Globiom data'!$A$2:$A$9999,Veda!$D16,'Globiom data'!$D$2:$D$9999,VLOOKUP(Veda!$B16,'Globiom data'!$V$21:$X$29,2,FALSE),'Globiom data'!$E$2:$E$9999,Veda!$C$1),0)*1000 -> 0 | J16: =MAX(SUMIFS('Globiom data'!I$2:I$9999,'Globiom data'!$A$2:$A$9999,Veda!$D16,'Globiom data'!$D$2:$D$9999,VLOOKUP(Veda!$B16,'Globiom data'!$V$21:$X$29,2,FALSE),'Globiom data'!$E$2:$E$9999,Veda!$C$1),0)*1000 -> 101.70668 | K16: =MAX(SUMIFS('Globiom data'!J$2:J$9999,'Globiom data'!$A$2:$A$9999,Veda!$D16,'Globiom data'!$D$2:$D$9999,VLOOKUP(Veda!$B16,'Globiom data'!$V$21:$X$29,2,FALSE),'Globiom data'!$E$2:$E$9999,Veda!$C$1),0)*1000 -> 109.99614 | L16: =MAX(SUMIFS('Globiom data'!K$2:K$9999,'Globiom data'!$A$2:$A$9999,Veda!$D16,'Globiom data'!$D$2:$D$9999,VLOOKUP(Veda!$B16,'Globiom data'!$V$21:$X$29,2,FALSE),'Globiom data'!$E$2:$E$9999,Veda!$C$1),0)*1000 -> 2541.6609 | M16: =MAX(SUMIFS('Globiom data'!L$2:L$9999,'Globiom data'!$A$2:$A$9999,Veda!$D16,'Globiom data'!$D$2:$D$9999,VLOOKUP(Veda!$B16,'Globiom data'!$V$21:$X$29,2,FALSE),'Globiom data'!$E$2:$E$9999,Veda!$C$1),0)*1000 -> 6537.8461 | N16: =MAX(SUMIFS('Globiom data'!M$2:M$9999,'Globiom data'!$A$2:$A$9999,Veda!$D16,'Globiom data'!$D$2:$D$9999,VLOOKUP(Veda!$B16,'Globiom data'!$V$21:$X$29,2,FALSE),'Globiom data'!$E$2:$E$9999,Veda!$C$1),0)*1000 -> 9717.6304 | ... Q16: =MAX(SUMIFS('Globiom data'!P$2:P$9999,'Globiom data'!$A$2:$A$9999,Veda!$D16,'Globiom data'!$D$2:$D$9999,VLOOKUP(Veda!$B16,'Globiom data'!$V$21:$X$29,2,FALSE),'Globiom data'!$E$2:$E$9999,Veda!$C$1),0)*1000 -> 12113.001 | R16: 3
A17: =A10+1 -> 2 | B17: =B10 -> 5 | D17: =VLOOKUP(A17,'Globiom data'!$S$21:$T$51,2,FALSE) -> Africa_other | E17: =VLOOKUP(B17,'Globiom data'!$V$21:$X$30,3,FALSE) -> MinBIOBSL-05 | F17: BIOBSL | G17: =MAX(SUMIFS('Globiom data'!F$2:F$9999,'Globiom data'!$A$2:$A$9999,Veda!$D17,'Globiom data'!$D$2:$D$9999,VLOOKUP(Veda!$B17,'Globiom data'!$V$21:$X$29,2,FALSE),'Globiom data'!$E$2:$E$9999,Veda!$C$1),0)*1000 -> 0 | H17: =MAX(SUMIFS('Globiom data'!G$2:G$9999,'Globiom data'!$A$2:$A$9999,Veda!$D17,'Globiom data'!$D$2:$D$9999,VLOOKUP(Veda!$B17,'Globiom data'!$V$21:$X$29,2,FALSE),'Globiom data'!$E$2:$E$9999,Veda!$C$1),0)*1000 -> 1.3388164 | I17: =MAX(SUMIFS('Globiom data'!H$2:H$9999,'Globiom data'!$A$2:$A$9999,Veda!$D17,'Globiom data'!$D$2:$D$9999,VLOOKUP(Veda!$B17,'Globiom data'!$V$21:$X$29,2,FALSE),'Globiom data'!$E$2:$E$9999,Veda!$C$1),0)*1000 -> 1.3388164 | J17: =MAX(SUMIFS('Globiom data'!I$2:I$9999,'Globiom data'!$A$2:$A$9999,Veda!$D17,'Globiom data'!$D$2:$D$9999,VLOOKUP(Veda!$B17,'Globiom data'!$V$21:$X$29,2,FALSE),'Globiom data'!$E$2:$E$9999,Veda!$C$1),0)*1000 -> 80.165842 | K17: =MAX(SUMIFS('Globiom data'!J$2:J$9999,'Globiom data'!$A$2:$A$9999,Veda!$D17,'Globiom data'!$D$2:$D$9999,VLOOKUP(Veda!$B17,'Globiom data'!$V$21:$X$29,2,FALSE),'Globiom data'!$E$2:$E$9999,Veda!$C$1),0)*1000 -> 3870.9523 | L17: =MAX(SUMIFS('Globiom data'!K$2:K$9999,'Globiom data'!$A$2:$A$9999,Veda!$D17,'Globiom data'!$D$2:$D$9999,VLOOKUP(Veda!$B17,'Globiom data'!$V$21:$X$29,2,FALSE),'Globiom data'!$E$2:$E$9999,Veda!$C$1),0)*1000 -> 9895.1425 | M17: =MAX(SUMIFS('Globiom data'!L$2:L$9999,'Globiom data'!$A$2:$A$9999,Veda!$D17,'Globiom data'!$D$2:$D$9999,VLOOKUP(Veda!$B17,'Globiom data'!$V$21:$X$29,2,FALSE),'Globiom data'!$E$2:$E$9999,Veda!$C$1),0)*1000 -> 12272.137 | N17: =MAX(SUMIFS('Globiom data'!M$2:M$9999,'Globiom data'!$A$2:$A$9999,Veda!$D17,'Globiom data'!$D$2:$D$9999,VLOOKUP(Veda!$B17,'Globiom data'!$V$21:$X$29,2,FALSE),'Globiom data'!$E$2:$E$9999,Veda!$C$1),0)*1000 -> 11651.066 | ... Q17: =MAX(SUMIFS('Globiom data'!P$2:P$9999,'Globiom data'!$A$2:$A$9999,Veda!$D17,'Globiom data'!$D$2:$D$9999,VLOOKUP(Veda!$B17,'Globiom data'!$V$21:$X$29,2,FALSE),'Globiom data'!$E$2:$E$9999,Veda!$C$1),0)*1000 -> 6350.9141 | R17: 3
A18: =A11+1 -> 2 | B18: =B11 -> 6 | D18: =VLOOKUP(A18,'Globiom data'!$S$21:$T$51,2,FALSE) -> Africa_other | E18: =VLOOKUP(B18,'Globiom data'!$V$21:$X$30,3,FALSE) -> MinBIOBSL-06 | F18: BIOBSL | G18: =MAX(SUMIFS('Globiom data'!F$2:F$9999,'Globiom data'!$A$2:$A$9999,Veda!$D18,'Globiom data'!$D$2:$D$9999,VLOOKUP(Veda!$B18,'Globiom data'!$V$21:$X$29,2,FALSE),'Globiom data'!$E$2:$E$9999,Veda!$C$1),0)*1000 -> 0 | H18: =MAX(SUMIFS('Globiom data'!G$2:G$9999,'Globiom data'!$A$2:$A$9999,Veda!$D18,'Globiom data'!$D$2:$D$9999,VLOOKUP(Veda!$B18,'Globiom data'!$V$21:$X$29,2,FALSE),'Globiom data'!$E$2:$E$9999,Veda!$C$1),0)*1000 -> 120.43081 | I18: =MAX(SUMIFS('Globiom data'!H$2:H$9999,'Globiom data'!$A$2:$A$9999,Veda!$D18,'Globiom data'!$D$2:$D$9999,VLOOKUP(Veda!$B18,'Globiom data'!$V$21:$X$29,2,FALSE),'Globiom data'!$E$2:$E$9999,Veda!$C$1),0)*1000 -> 120.43081 | J18: =MAX(SUMIFS('Globiom data'!I$2:I$9999,'Globiom data'!$A$2:$A$9999,Veda!$D18,'Globiom data'!$D$2:$D$9999,VLOOKUP(Veda!$B18,'Globiom data'!$V$21:$X$29,2,FALSE),'Globiom data'!$E$2:$E$9999,Veda!$C$1),0)*1000 -> 9016.525 | K18: =MAX(SUMIFS('Globiom data'!J$2:J$9999,'Globiom data'!$A$2:$A$9999,Veda!$D18,'Globiom data'!$D$2:$D$9999,VLOOKUP(Veda!$B18,'Globiom data'!$V$21:$X$29,2,FALSE),'Globiom data'!$E$2:$E$9999,Veda!$C$1),0)*1000 -> 16964.524 | L18: =MAX(SUMIFS('Globiom data'!K$2:K$9999,'Globiom data'!$A$2:$A$9999,Veda!$D18,'Globiom data'!$D$2:$D$9999,VLOOKUP(Veda!$B18,'Globiom data'!$V$21:$X$29,2,FALSE),'Globiom data'!$E$2:$E$9999,Veda!$C$1),0)*1000 -> 17018.201 | M18: =MAX(SUMIFS('Globiom data'!L$2:L$9999,'Globiom data'!$A$2:$A$9999,Veda!$D18,'Globiom data'!$D$2:$D$9999,VLOOKUP(Veda!$B18,'Globiom data'!$V$21:$X$29,2,FALSE),'Globiom data'!$E$2:$E$9999,Veda!$C$1),0)*1000 -> 14926.878 | N18: =MAX(SUMIFS('Globiom data'!M$2:M$9999,'Globiom data'!$A$2:$A$9999,Veda!$D18,'Globiom data'!$D$2:$D$9999,VLOOKUP(Veda!$B18,'Globiom data'!$V$21:$X$29,2,FALSE),'Globiom data'!$E$2:$E$9999,Veda!$C$1),0)*1000 -> 10380.59 | ... Q18: =MAX(SUMIFS('Globiom data'!P$2:P$9999,'Globiom data'!$A$2:$A$9999,Veda!$D18,'Globiom data'!$D$2:$D$9999,VLOOKUP(Veda!$B18,'Globiom data'!$V$21:$X$29,2,FALSE),'Globiom data'!$E$2:$E$9999,Veda!$C$1),0)*1000 -> 4906.469 | R18: 3
A19: =A12+1 -> 2 | B19: =B12 -> 7 | D19: =VLOOKUP(A19,'Globiom data'!$S$21:$T$51,2,FALSE) -> Africa_other | E19: =VLOOKUP(B19,'Globiom data'!$V$21:$X$30,3,FALSE) -> MinBIOBSL-07 | F19: BIOBSL | G19: =MAX(SUMIFS('Globiom data'!F$2:F$9999,'Globiom data'!$A$2:$A$9999,Veda!$D19,'Globiom data'!$D$2:$D$9999,VLOOKUP(Veda!$B19,'Globiom data'!$V$21:$X$29,2,FALSE),'Globiom data'!$E$2:$E$9999,Veda!$C$1),0)*1000 -> 0 | H19: =MAX(SUMIFS('Globiom data'!G$2:G$9999,'Globiom data'!$A$2:$A$9999,Veda!$D19,'Globiom data'!$D$2:$D$9999,VLOOKUP(Veda!$B19,'Globiom data'!$V$21:$X$29,2,FALSE),'Globiom data'!$E$2:$E$9999,Veda!$C$1),0)*1000 -> 2963.5683 | I19: =MAX(SUMIFS('Globiom data'!H$2:H$9999,'Globiom data'!$A$2:$A$9999,Veda!$D19,'Globiom data'!$D$2:$D$9999,VLOOKUP(Veda!$B19,'Globiom data'!$V$21:$X$29,2,FALSE),'Globiom data'!$E$2:$E$9999,Veda!$C$1),0)*1000 -> 2963.5683 | J19: =MAX(SUMIFS('Globiom data'!I$2:I$9999,'Globiom data'!$A$2:$A$9999,Veda!$D19,'Globiom data'!$D$2:$D$9999,VLOOKUP(Veda!$B19,'Globiom data'!$V$21:$X$29,2,FALSE),'Globiom data'!$E$2:$E$9999,Veda!$C$1),0)*1000 -> 12952.092 | K19: =MAX(SUMIFS('Globiom data'!J$2:J$9999,'Globiom data'!$A$2:$A$9999,Veda!$D19,'Globiom data'!$D$2:$D$9999,VLOOKUP(Veda!$B19,'Globiom data'!$V$21:$X$29,2,FALSE),'Globiom data'!$E$2:$E$9999,Veda!$C$1),0)*1000 -> 12958.067 | L19: =MAX(SUMIFS('Globiom data'!K$2:K$9999,'Globiom data'!$A$2:$A$9999,Veda!$D19,'Globiom data'!$D$2:$D$9999,VLOOKUP(Veda!$B19,'Globiom data'!$V$21:$X$29,2,FALSE),'Globiom data'!$E$2:$E$9999,Veda!$C$1),0)*1000 -> 7856.3966 | M19: =MAX(SUMIFS('Globiom data'!L$2:L$9999,'Globiom data'!$A$2:$A$9999,Veda!$D19,'Globiom data'!$D$2:$D$9999,VLOOKUP(Veda!$B19,'Globiom data'!$V$21:$X$29,2,FALSE),'Globiom data'!$E$2:$E$9999,Veda!$C$1),0)*1000 -> 4718.1938 | N19: =MAX(SUMIFS('Globiom data'!M$2:M$9999,'Globiom data'!$A$2:$A$9999,Veda!$D19,'Globiom data'!$D$2:$D$9999,VLOOKUP(Veda!$B19,'Globiom data'!$V$21:$X$29,2,FALSE),'Globiom data'!$E$2:$E$9999,Veda!$C$1),0)*1000 -> 4418.3807 | ... Q19: =MAX(SUMIFS('Globiom data'!P$2:P$9999,'Globiom data'!$A$2:$A$9999,Veda!$D19,'Globiom data'!$D$2:$D$9999,VLOOKUP(Veda!$B19,'Globiom data'!$V$21:$X$29,2,FALSE),'Globiom data'!$E$2:$E$9999,Veda!$C$1),0)*1000 -> 4396.7354 | R19: 3
A20: =A13+1 -> 3 | B20: =B13 -> 1 | D20: =VLOOKUP(A20,'Globiom data'!$S$21:$T$51,2,FALSE) -> Arg-Chi | E20: =VLOOKUP(B20,'Globiom data'!$V$21:$X$30,3,FALSE) -> MinBIOBSL-01 | F20: BIOBSL | G20: =MAX(SUMIFS('Globiom data'!F$2:F$9999,'Globiom data'!$A$2:$A$9999,Veda!$D20,'Globiom data'!$D$2:$D$9999,VLOOKUP(Veda!$B20,'Globiom data'!$V$21:$X$29,2,FALSE),'Globiom data'!$E$2:$E$9999,Veda!$C$1),0)*1000 -> 446.30737 | H20: =MAX(SUMIFS('Globiom data'!G$2:G$9999,'Globiom data'!$A$2:$A$9999,Veda!$D20,'Globiom data'!$D$2:$D$9999,VLOOKUP(Veda!$B20,'Globiom data'!$V$21:$X$29,2,FALSE),'Globiom data'!$E$2:$E$9999,Veda!$C$1),0)*1000 -> 404.37696 | I20: =MAX(SUMIFS('Globiom data'!H$2:H$9999,'Globiom data'!$A$2:$A$9999,Veda!$D20,'Globiom data'!$D$2:$D$9999,VLOOKUP(Veda!$B20,'Globiom data'!$V$21:$X$29,2,FALSE),'Globiom data'!$E$2:$E$9999,Veda!$C$1),0)*1000 -> 404.37696 | J20: =MAX(SUMIFS('Globiom data'!I$2:I$9999,'Globiom data'!$A$2:$A$9999,Veda!$D20,'Globiom data'!$D$2:$D$9999,VLOOKUP(Veda!$B20,'Globiom data'!$V$21:$X$29,2,FALSE),'Globiom data'!$E$2:$E$9999,Veda!$C$1),0)*1000 -> 382.33758 | K20: =MAX(SUMIFS('Globiom data'!J$2:J$9999,'Globiom data'!$A$2:$A$9999,Veda!$D20,'Globiom data'!$D$2:$D$9999,VLOOKUP(Veda!$B20,'Globiom data'!$V$21:$X$29,2,FALSE),'Globiom data'!$E$2:$E$9999,Veda!$C$1),0)*1000 -> 371.71974 | L20: =MAX(SUMIFS('Globiom data'!K$2:K$9999,'Globiom data'!$A$2:$A$9999,Veda!$D20,'Globiom data'!$D$2:$D$9999,VLOOKUP(Veda!$B20,'Globiom data'!$V$21:$X$29,2,FALSE),'Globiom data'!$E$2:$E$9999,Veda!$C$1),0)*1000 -> 357.31198 | M20: =MAX(SUMIFS('Globiom data'!L$2:L$9999,'Globiom data'!$A$2:$A$9999,Veda!$D20,'Globiom data'!$D$2:$D$9999,VLOOKUP(Veda!$B20,'Globiom data'!$V$21:$X$29,2,FALSE),'Globiom data'!$E$2:$E$9999,Veda!$C$1),0)*1000 -> 356.81461 | N20: =MAX(SUMIFS('Globiom data'!M$2:M$9999,'Globiom data'!$A$2:$A$9999,Veda!$D20,'Globiom data'!$D$2:$D$9999,VLOOKUP(Veda!$B20,'Globiom data'!$V$21:$X$29,2,FALSE),'Globiom data'!$E$2:$E$9999,Veda!$C$1),0)*1000 -> 361.19003 | ... Q20: =MAX(SUMIFS('Globiom data'!P$2:P$9999,'Globiom data'!$A$2:$A$9999,Veda!$D20,'Globiom data'!$D$2:$D$9999,VLOOKUP(Veda!$B20,'Globiom data'!$V$21:$X$29,2,FALSE),'Globiom data'!$E$2:$E$9999,Veda!$C$1),0)*1000 -> 361.16947 | R20: 3
A21: =A14+1 -> 3 | B21: =B14 -> 2 | D21: =VLOOKUP(A21,'Globiom data'!$S$21:$T$51,2,FALSE) -> Arg-Chi | E21: =VLOOKUP(B21,'Globiom data'!$V$21:$X$30,3,FALSE) -> MinBIOBSL-02 | F21: BIOBSL | G21: =MAX(SUMIFS('Globiom data'!F$2:F$9999,'Globiom data'!$A$2:$A$9999,Veda!$D21,'Globiom data'!$D$2:$D$9999,VLOOKUP(Veda!$B21,'Globiom data'!$V$21:$X$29,2,FALSE),'Globiom data'!$E$2:$E$9999,Veda!$C$1),0)*1000 -> 0 | H21: =MAX(SUMIFS('Globiom data'!G$2:G$9999,'Globiom data'!$A$2:$A$9999,Veda!$D21,'Globiom data'!$D$2:$D$9999,VLOOKUP(Veda!$B21,'Globiom data'!$V$21:$X$29,2,FALSE),'Globiom data'!$E$2:$E$9999,Veda!$C$1),0)*1000 -> 0.51257137 | I21: =MAX(SUMIFS('Globiom data'!H$2:H$9999,'Globiom data'!$A$2:$A$9999,Veda!$D21,'Globiom data'!$D$2:$D$9999,VLOOKUP(Veda!$B21,'Globiom data'!$V$21:$X$29,2,FALSE),'Globiom data'!$E$2:$E$9999,Veda!$C$1),0)*1000 -> 0.51257137 | J21: =MAX(SUMIFS('Globiom data'!I$2:I$9999,'Globiom data'!$A$2:$A$9999,Veda!$D21,'Globiom data'!$D$2:$D$9999,VLOOKUP(Veda!$B21,'Globiom data'!$V$21:$X$29,2,FALSE),'Globiom data'!$E$2:$E$9999,Veda!$C$1),0)*1000 -> 0.43818556 | K21: =MAX(SUMIFS('Globiom data'!J$2:J$9999,'Globiom data'!$A$2:$A$9999,Veda!$D21,'Globiom data'!$D$2:$D$9999,VLOOKUP(Veda!$B21,'Globiom data'!$V$21:$X$29,2,FALSE),'Globiom data'!$E$2:$E$9999,Veda!$C$1),0)*1000 -> 0.11416008 | L21: =MAX(SUMIFS('Globiom data'!K$2:K$9999,'Globiom data'!$A$2:$A$9999,Veda!$D21,'Globiom data'!$D$2:$D$9999,VLOOKUP(Veda!$B21,'Globiom data'!$V$21:$X$29,2,FALSE),'Globiom data'!$E$2:$E$9999,Veda!$C$1),0)*1000 -> 1.4744283 | M21: =MAX(SUMIFS('Globiom data'!L$2:L$9999,'Globiom data'!$A$2:$A$9999,Veda!$D21,'Globiom data'!$D$2:$D$9999,VLOOKUP(Veda!$B21,'Globiom data'!$V$21:$X$29,2,FALSE),'Globiom data'!$E$2:$E$9999,Veda!$C$1),0)*1000 -> 23.641577 | N21: =MAX(SUMIFS('Globiom data'!M$2:M$9999,'Globiom data'!$A$2:$A$9999,Veda!$D21,'Globiom data'!$D$2:$D$9999,VLOOKUP(Veda!$B21,'Globiom data'!$V$21:$X$29,2,FALSE),'Globiom data'!$E$2:$E$9999,Veda!$C$1),0)*1000 -> 40.707015 | ... Q21: =MAX(SUMIFS('Globiom data'!P$2:P$9999,'Globiom data'!$A$2:$A$9999,Veda!$D21,'Globiom data'!$D$2:$D$9999,VLOOKUP(Veda!$B21,'Globiom data'!$V$21:$X$29,2,FALSE),'Globiom data'!$E$2:$E$9999,Veda!$C$1),0)*1000 -> 104.66391 | R21: 3
A22: =A15+1 -> 3 | B22: =B15 -> 3 | D22: =VLOOKUP(A22,'Globiom data'!$S$21:$T$51,2,FALSE) -> Arg-Chi | E22: =VLOOKUP(B22,'Globiom data'!$V$21:$X$30,3,FALSE) -> MinBIOBSL-03 | F22: BIOBSL | G22: =MAX(SUMIFS('Globiom data'!F$2:F$9999,'Globiom data'!$A$2:$A$9999,Veda!$D22,'Globiom data'!$D$2:$D$9999,VLOOKUP(Veda!$B22,'Globiom data'!$V$21:$X$29,2,FALSE),'Globiom data'!$E$2:$E$9999,Veda!$C$1),0)*1000 -> 0 | H22: =MAX(SUMIFS('Globiom data'!G$2:G$9999,'Globiom data'!$A$2:$A$9999,Veda!$D22,'Globiom data'!$D$2:$D$9999,VLOOKUP(Veda!$B22,'Globiom data'!$V$21:$X$29,2,FALSE),'Globiom data'!$E$2:$E$9999,Veda!$C$1),0)*1000 -> 0 | I22: =MAX(SUMIFS('Globiom data'!H$2:H$9999,'Globiom data'!$A$2:$A$9999,Veda!$D22,'Globiom data'!$D$2:$D$9999,VLOOKUP(Veda!$B22,'Globiom data'!$V$21:$X$29,2,FALSE),'Globiom data'!$E$2:$E$9999,Veda!$C$1),0)*1000 -> 0 | J22: =MAX(SUMIFS('Globiom data'!I$2:I$9999,'Globiom data'!$A$2:$A$9999,Veda!$D22,'Globiom data'!$D$2:$D$9999,VLOOKUP(Veda!$B22,'Globiom data'!$V$21:$X$29,2,FALSE),'Globiom data'!$E$2:$E$9999,Veda!$C$1),0)*1000 -> 0.10801132 | K22: =MAX(SUMIFS('Globiom data'!J$2:J$9999,'Globiom data'!$A$2:$A$9999,Veda!$D22,'Globiom data'!$D$2:$D$9999,VLOOKUP(Veda!$B22,'Globiom data'!$V$21:$X$29,2,FALSE),'Globiom data'!$E$2:$E$9999,Veda!$C$1),0)*1000 -> 14.096232 | L22: =MAX(SUMIFS('Globiom data'!K$2:K$9999,'Globiom data'!$A$2:$A$9999,Veda!$D22,'Globiom data'!$D$2:$D$9999,VLOOKUP(Veda!$B22,'Globiom data'!$V$21:$X$29,2,FALSE),'Globiom data'!$E$2:$E$9999,Veda!$C$1),0)*1000 -> 15.873756 | M22: =MAX(SUMIFS('Globiom data'!L$2:L$9999,'Globiom data'!$A$2:$A$9999,Veda!$D22,'Globiom data'!$D$2:$D$9999,VLOOKUP(Veda!$B22,'Globiom data'!$V$21:$X$29,2,FALSE),'Globiom data'!$E$2:$E$9999,Veda!$C$1),0)*1000 -> 30.441538 | N22: =MAX(SUMIFS('Globiom data'!M$2:M$9999,'Globiom data'!$A$2:$A$9999,Veda!$D22,'Globiom data'!$D$2:$D$9999,VLOOKUP(Veda!$B22,'Globiom data'!$V$21:$X$29,2,FALSE),'Globiom data'!$E$2:$E$9999,Veda!$C$1),0)*1000 -> 184.26287 | ... Q22: =MAX(SUMIFS('Globiom data'!P$2:P$9999,'Globiom data'!$A$2:$A$9999,Veda!$D22,'Globiom data'!$D$2:$D$9999,VLOOKUP(Veda!$B22,'Globiom data'!$V$21:$X$29,2,FALSE),'Globiom data'!$E$2:$E$9999,Veda!$C$1),0)*1000 -> 570.05868 | R22: 3
A23: =A16+1 -> 3 | B23: =B16 -> 4 | D23: =VLOOKUP(A23,'Globiom data'!$S$21:$T$51,2,FALSE) -> Arg-Chi | E23: =VLOOKUP(B23,'Globiom data'!$V$21:$X$30,3,FALSE) -> MinBIOBSL-04 | F23: BIOBSL | G23: =MAX(SUMIFS('Globiom data'!F$2:F$9999,'Globiom data'!$A$2:$A$9999,Veda!$D23,'Globiom data'!$D$2:$D$9999,VLOOKUP(Veda!$B23,'Globiom data'!$V$21:$X$29,2,FALSE),'Globiom data'!$E$2:$E$9999,Veda!$C$1),0)*1000 -> 0 | H23: =MAX(SUMIFS('Globiom data'!G$2:G$9999,'Globiom data'!$A$2:$A$9999,Veda!$D23,'Globiom data'!$D$2:$D$9999,VLOOKUP(Veda!$B23,'Globiom data'!$V$21:$X$29,2,FALSE),'Globiom data'!$E$2:$E$9999,Veda!$C$1),0)*1000 -> 0 | I23: =MAX(SUMIFS('Globiom data'!H$2:H$9999,'Globiom data'!$A$2:$A$9999,Veda!$D23,'Globiom data'!$D$2:$D$9999,VLOOKUP(Veda!$B23,'Globiom data'!$V$21:$X$29,2,FALSE),'Globiom data'!$E$2:$E$9999,Veda!$C$1),0)*1000 -> 0 | J23: =MAX(SUMIFS('Globiom data'!I$2:I$9999,'Globiom data'!$A$2:$A$9999,Veda!$D23,'Globiom data'!$D$2:$D$9999,VLOOKUP(Veda!$B23,'Globiom data'!$V$21:$X$29,2,FALSE),'Globiom data'!$E$2:$E$9999,Veda!$C$1),0)*1000 -> 1.2146645 | K23: =MAX(SUMIFS('Globiom data'!J$2:J$9999,'Globiom data'!$A$2:$A$9999,Veda!$D23,'Globiom data'!$D$2:$D$9999,VLOOKUP(Veda!$B23,'Globiom data'!$V$21:$X$29,2,FALSE),'Globiom data'!$E$2:$E$9999,Veda!$C$1),0)*1000 -> 2.7812948 | L23: =MAX(SUMIFS('Globiom data'!K$2:K$9999,'Globiom data'!$A$2:$A$9999,Veda!$D23,'Globiom data'!$D$2:$D$9999,VLOOKUP(Veda!$B23,'Globiom data'!$V$21:$X$29,2,FALSE),'Globiom data'!$E$2:$E$9999,Veda!$C$1),0)*1000 -> 151.01457 | M23: =MAX(SUMIFS('Globiom data'!L$2:L$9999,'Globiom data'!$A$2:$A$9999,Veda!$D23,'Globiom data'!$D$2:$D$9999,VLOOKUP(Veda!$B23,'Globiom data'!$V$21:$X$29,2,FALSE),'Globiom data'!$E$2:$E$9999,Veda!$C$1),0)*1000 -> 279.84816 | N23: =MAX(SUMIFS('Globiom data'!M$2:M$9999,'Globiom data'!$A$2:$A$9999,Veda!$D23,'Globiom data'!$D$2:$D$9999,VLOOKUP(Veda!$B23,'Globiom data'!$V$21:$X$29,2,FALSE),'Globiom data'!$E$2:$E$9999,Veda!$C$1),0)*1000 -> 426.84042 | ... Q23: =MAX(SUMIFS('Globiom data'!P$2:P$9999,'Globiom data'!$A$2:$A$9999,Veda!$D23,'Globiom data'!$D$2:$D$9999,VLOOKUP(Veda!$B23,'Globiom data'!$V$21:$X$29,2,FALSE),'Globiom data'!$E$2:$E$9999,Veda!$C$1),0)*1000 -> 906.437 | R23: 3
