Workbook

Sheet IND Balance
A1: 0.041868 | B1: ktoe to PJ
A2: 0.0036
B4: Sector | C4: Sub-Sector | D4: sectfuel | E4: Africa_north | F4: Africa_other | G4: Arg-Chi | H4: Asia_central | I4: Asia_east | J4: Asia_other | K4: Australia_NZ | L4: Brazil | M4: Canada | N4: China | O4: EU_north | P4: EU_northeast | Q4: EU_northwest | R4: EU_south | S4: EU_southeast | T4: EU_southwest | U4: Europe_other | V4: France | W4: Germany | X4: India | Y4: LatAm_other | Z4: Mexico | AA4: MidEast_other | AB4: Nor-Ice | AC4: Russia | AD4: SaudiArabia | AE4: SouthAfrica | AF4: UK | AG4: USA | AH4: \I: | AI4: WORLD | AM4: TIAM Ind | AN4: Description | AO4: IEA FLOW
A5: =IF(C5="NECHEM","ICH_Feedstock",IF(AND(LEN(C5)=3,LEFT(C5,1)="I"),"IND","")) -> IND | B5: IND | C5: ICH | D5: INDBFG | I5: 4.3372066 | AB5: 0.28945023 | AI5: =SUM(E5:AH5) -> 4.6266568 | AK5: =IF(AM5<>AM6,1,0) -> 1 | AL5: CHEMICAL | AM5: ICH | AN5: Chemicals | AO5: =IF(AM5<>AM4,AL5,AO4&","&AL5) -> CHEMICAL
A6: =IF(C6="NECHEM","ICH_Feedstock",IF(AND(LEN(C6)=3,LEFT(C6,1)="I"),"IND","")) -> IND | B6: IND | C6: ICH | D6: INDBIO | E6: 0.36601843 | I6: 24.380486 | J6: 0.045904075 | K6: 3.8970023 | L6: 5.7708339 | M6: 0.06700136 | O6: 1.2592722 | P6: 7.2209153 | Q6: 0.56043249 | R6: 3.7089563 | S6: 2.2611651 | T6: 0.54703473 | U6: 5.8729751 | V6: 4.5246706 | W6: 10.569924 | Y6: 4.7691127 | AB6: 4.9583226 | AC6: 6.8716567 | AF6: 3.7389966 | AG6: 12.305206 | AI6: =SUM(E6:AH6) -> 103.69589 | AK6: =IF(AM6<>AM7,1,0) -> 1 | AL6: FOODPRO | AM6: IFP | AN6: Food processing | AO6: =IF(AM6<>AM5,AL6,AO5&","&AL6) -> FOODPRO
A7: =IF(C7="NECHEM","ICH_Feedstock",IF(AND(LEN(C7)=3,LEFT(C7,1)="I"),"IND","")) -> IND | B7: IND | C7: ICH | D7: INDCOA | F7: 0.04983548 | H7: 0.52572392 | I7: 111.47157 | J7: 99.790088 | K7: 6.4642852 | L7: 5.6323764 | N7: 1602.789 | O7: 0.10799851 | P7: 58.425689 | Q7: 0.058368179 | S7: 6.8989044 | T7: 4.8200284 | U7: 32.717585 | V7: 13.059525 | W7: 14.640821 | X7: 45.441057 | Y7: 3.6732597 | AB7: 8.1112635 | AC7: 6.7422092 | AE7: 43.889153 | AF7: 1.3960633 | AG7: 66.68215 | AI7: =SUM(E7:AH7) -> 2133.3869 | AK7: =IF(AM7<>AM8,1,0) -> 1 | AL7: IRONSTL | AM7: IIS | AN7: Iron and Steel | AO7: =IF(AM7<>AM6,AL7,AO6&","&AL7) -> IRONSTL
A8: =IF(C8="NECHEM","ICH_Feedstock",IF(AND(LEN(C8)=3,LEFT(C8,1)="I"),"IND","")) -> IND | B8: IND | C8: ICH | D8: INDCOG | I8: 24.640365 | J8: 0.18629167 | N8: 132.62583 | P8: 0.57997647 | W8: 1.6919989 | AI8: =SUM(E8:AH8) -> 159.72446 | AK8: =IF(AM8<>AM9,1,0) -> 1 | AL8: PAPERPRO | AM8: ILP | AN8: Pulp and Paper | AO8: =IF(AM8<>AM7,AL8,AO7&","&AL8) -> PAPERPRO
A9: =IF(C9="NECHEM","ICH_Feedstock",IF(AND(LEN(C9)=3,LEFT(C9,1)="I"),"IND","")) -> IND | B9: IND | C9: ICH | D9: INDELC | E9: 12.999495 | F9: 2.0887443 | G9: 43.624296 | H9: 35.447873 | I9: 393.0046 | J9: 236.64104 | K9: 15.540074 | L9: 75.579942 | M9: 75.2436 | N9: 2264.4864 | O9: 37.681786 | P9: 69.394745 | Q9: 103.67778 | R9: 51.156847 | S9: 32.164974 | T9: 42.165564 | U9: 67.710068 | V9: 70.728127 | W9: 189.7488 | X9: 65.317358 | Y9: 26.697838 | Z9: 20.6784 | AA9: 0.5400009 | AB9: 26.719458 | AC9: 171.5814 | AD9: 35.276708 | AE9: 28.702126 | AF9: 53.910129 | AG9: 448.02386 | AI9: =SUM(E9:AH9) -> 4696.532 | AK9: =IF(AM9<>AM10,1,0) -> 0 | AL9: CONSTRUC | AM9: IMC | AN9: Mining and Construction | AO9: =IF(AM9<>AM8,AL9,AO8&","&AL9) -> CONSTRUC
A10: =IF(C10="NECHEM","ICH_Feedstock",IF(AND(LEN(C10)=3,LEFT(C10,1)="I"),"IND","")) -> IND | B10: IND | C10: ICH | D10: INDHET | H10: 13.945 | I10: 86.325285 | J10: 66.825565 | M10: 10.533001 | N10: 1668.86 | O10: 11.514412 | P10: 33.236443 | Q10: 72.099321 | R10: 40.764895 | S10: 19.50211 | T10: 2.6495703 | U10: 54.634374 | V10: 40.393861 | W10: 105.172 | AB10: 0.33599907 | AC10: 518.99522 | AF10: 9.663461 | AG10: 122.3174 | AI10: =SUM(E10:AH10) -> 2877.7679 | AK10: =IF(AM10<>AM11,1,0) -> 1 | AL10: MINING | AM10: IMC | AN10: Mining and Construction | AO10: =IF(AM10<>AM9,AL10,AO9&","&AL10) -> CONSTRUC,MINING
A11: =IF(C11="NECHEM","ICH_Feedstock",IF(AND(LEN(C11)=3,LEFT(C11,1)="I"),"IND","")) -> IND | B11: IND | C11: ICH | D11: INDNGA | E11: 6.8981214 | F11: 57.930382 | G11: 25.270415 | H11: 111.43138 | I11: 135.46439 | J11: 401.60497 | K11: 84.405813 | L11: 92.513777 | M11: 146.1186 | N11: 1086.7643 | O11: 8.8904814 | P11: 78.602858 | Q11: 258.88002 | R11: 40.493913 | S11: 67.55141 | T11: 115.96293 | U11: 83.643807 | V11: 141.27286 | W11: 223.64461 | Y11: 72.830433 | Z11: 108.5607 | AA11: 728.49506 | AB11: 15.533932 | AC11: 352.44226 | AE11: 51.323858 | AF11: 65.628002 | AG11: 2285.6441 | AI11: =SUM(E11:AH11) -> 6847.8033 | AK11: =IF(AM11<>AM12,1,0) -> 1 | AL11: NONFERR | AM11: INF | AN11: Non-ferrous metals | AO11: =IF(AM11<>AM10,AL11,AO10&","&AL11) -> NONFERR
A12: =IF(C12="NECHEM","ICH_Feedstock",IF(AND(LEN(C12)=3,LEFT(C12,1)="I"),"IND","")) -> IND | B12: IND | C12: ICH | D12: INDOIL | E12: 2.9034704 | F12: 0.9253456 | G12: 4.1868e-05 | H12: 4.2379669 | I12: 372.73287 | J12: 91.418786 | K12: 4.4374553 | L12: 99.797787 | M12: 0.92447893 | N12: 1181.7628 | O12: 12.692108 | P12: 12.231451 | Q12: 46.427689 | R12: 14.404865 | S12: 26.880813 | T12: 3.6219211 | U12: 4.5531869 | V12: 2.9902126 | W12: 23.0162 | X12: 224.53652 | Y12: 9.9887753 | Z12: 9.0985779 | AA12: 13.121406 | AB12: 3.7340646 | AC12: 17.137012 | AE12: 0.095722808 | AF12: 4.7428908 | AG12: 68.227682 | AI12: =SUM(E12:AH12) -> 2256.6421 | AK12: =IF(AM12<>AM13,1,0) -> 1 | AL12: NONMET | AM12: INM | AN12: Non-metals | AO12: =IF(AM12<>AM11,AL12,AO11&","&AL12) -> NONMET
A13: =IF(C13="NECHEM","ICH_Feedstock",IF(AND(LEN(C13)=3,LEFT(C13,1)="I"),"IND","")) -> IND | B13: IND | C13: ICH | D13: INDOVC | H13: 9.1102842 | I13: 1.2387862 | K13: 0.18900053 | N13: 670.21619 | P13: 2.2581464 | Q13: 0.47919182 | R13: 0.028399064 | S13: 0.10929223 | T13: 0.27341897 | V13: 0.24808046 | W13: 0.012120786 | Y13: 0.013929484 | AB13: 1.392312 | AC13: 0.78920761 | AI13: =SUM(E13:AH13) -> 686.35836 | AK13: =IF(AM13<>AM14,1,0) -> 0 | AL13: INONSPEC | AM13: IOI | AN13: Other | AO13: =IF(AM13<>AM12,AL13,AO12&","&AL13) -> INONSPEC
A14: =IF(C14="NECHEM","ICH_Feedstock",IF(AND(LEN(C14)=3,LEFT(C14,1)="I"),"IND","")) -> IND | B14: IND | C14: IFP | D14: INDBIO | E14: 0.18975834 | F14: 11.088484 | G14: 0.012459917 | H14: 0.29984606 | I14: 6.8032569 | J14: 328.68886 | K14: 80.638999 | L14: 646.99056 | M14: 0.53699897 | O14: 2.7268293 | P14: 3.1780324 | Q14: 6.5811974 | R14: 6.5383078 | S14: 6.0703911 | T14: 20.805302 | U14: 7.8445936 | V14: 7.8830033 | W14: 3.0088522 | X14: 372.9628 | Y14: 100.24969 | Z14: 54.1174 | AB14: 0.32273948 | AC14: 11.189068 | AE14: 3.2221655 | AF14: 2.5239998 | AG14: 61.87583 | AI14: =SUM(E14:AH14) -> 1746.3494 | AK14: =IF(AM14<>AM15,1,0) -> 0 | AL14: TEXTILES | AM14: IOI | AN14: Other | AO14: =IF(AM14<>AM13,AL14,AO13&","&AL14) -> INONSPEC,TEXTILES
A15: =IF(C15="NECHEM","ICH_Feedstock",IF(AND(LEN(C15)=3,LEFT(C15,1)="I"),"IND","")) -> IND | B15: IND | C15: IFP | D15: INDCOA | E15: 0.74141948 | F15: 2.7292409 | G15: 2.1833576 | H15: 1.7897146 | I15: 0.028440932 | J15: 53.028661 | K15: 25.265965 | L15: 1.1937111 | N15: 520.48363 | O15: 1.615594 | P15: 24.993052 | Q15: 2.0641426 | S15: 0.33908056 | T15: 0.40766034 | U15: 37.468284 | V15: 7.1917878 | W15: 7.1274743 | Y15: 27.701791 | AC15: 4.1848448 | AF15: 1.4994731 | AG15: 119.21221 | AI15: =SUM(E15:AH15) -> 841.24954 | AK15: =IF(AM15<>AM16,1,0) -> 1 | AL15: WOODPRO | AM15: IOI | AN15: Other | AO15: =IF(AM15<>AM14,AL15,AO14&","&AL15) -> INONSPEC,TEXTILES,WOODPRO
A16: =IF(C16="NECHEM","ICH_Feedstock",IF(AND(LEN(C16)=3,LEFT(C16,1)="I"),"IND","")) -> IND | B16: IND | C16: IFP | D16: INDELC | E16: 17.577158 | F16: 7.8139504 | G16: 44.467446 | H16: 13.429395 | I16: 133.11444 | J16: 163.29724 | K16: 31.786152 | L16: 94.340407 | M16: 21.2148 | N16: 477.3024 | O16: 24.14152 | P16: 48.115036 | Q16: 52.334213 | R16: 55.550802 | S16: 25.032031 | T16: 45.83367 | U16: 70.406564 | V16: 82.963774 | W16: 67.237199 | X16: 262.31011 | Y16: 26.166771 | Z16: 9.1367992 | AA16: 5.7755776 | AB16: 12.718908 | AC16: 59.793118 | AE16: 2.5691545 | AF16: 41.29932 | AG16: 279.33483 | AI16: =SUM(E16:AH16) -> 2175.0628 | AK16: =IF(AM16<>AM17,1,0) -> 0 | AL16: MACHINE | AM16: ITM | AN16: Transport and machinery | AO16: =IF(AM16<>AM15,AL16,AO15&","&AL16) -> MACHINE
A17: =IF(C17="NECHEM","ICH_Feedstock",IF(AND(LEN(C17)=3,LEFT(C17,1)="I"),"IND","")) -> IND | B17: IND | C17: IFP | D17: INDHET | H17: 8.4380097 | I17: 5.4256364 | J17: 1.0304175 | M17: 0.094002034 | N17: 206.322 | O17: 7.9773571 | P17: 8.2375123 | Q17: 2.3438753 | R17: 15.00586 | S17: 2.5613754 | T17: 1.1600744 | U17: 54.588813 | V17: 9.9075263 | W17: 11.956002 | AB17: 0.60699808 | AC17: 173.82492 | AF17: 0.71560367 | AG17: 22.0526 | AI17: =SUM(E17:AH17) -> 532.24859 | AK17: =IF(AM17<>AM18,1,0) -> 1 | AL17: TRANSEQ | AM17: ITM | AN17: Transport and machinery | AO17: =IF(AM17<>AM16,AL17,AO16&","&AL17) -> MACHINE,TRANSEQ
A18: =IF(C18="NECHEM","ICH_Feedstock",IF(AND(LEN(C18)=3,LEFT(C18,1)="I"),"IND","")) -> IND | B18: IND | C18: IFP | D18: INDNGA | E18: 24.488514 | F18: 6.4661358 | G18: 62.197221 | H18: 37.632595 | I18: 105.76674 | J18: 15.842696 | K18: 49.013339 | L18: 36.5435 | M18: 71.6895 | N18: 241.18253 | O18: 15.279011 | P18: 67.82992 | Q18: 106.10298 | R18: 49.069401 | S18: 34.803177 | T18: 46.643799 | U18: 72.882081 | V18: 94.97917 | W18: 116.59355 | Y18: 13.154051 | Z18: 20.687402 | AA18: 0.04648604 | AB18: 2.3269858 | AC18: 55.72936 | AE18: 3.5729984 | AF18: 66.001498 | AG18: 646.28202 | AI18: =SUM(E18:AH18) -> 2062.8067 | AK18: =IF(AM18<>AM19,1,0) -> 1 | AL18: NECHEM | AM18: ICH_Feedstock | AN18: Chemical Feedstock | AO18: =IF(AM18<>AM17,AL18,AO17&","&AL18) -> NECHEM
A19: =IF(C19="NECHEM","ICH_Feedstock",IF(AND(LEN(C19)=3,LEFT(C19,1)="I"),"IND","")) -> IND | B19: IND | C19: IFP | D19: INDOIL | E19: 7.4229075 | F19: 11.896064 | G19: 0.22680733 | H19: 3.1530372 | I19: 49.613894 | J19: 80.89938 | K19: 5.0604135 | L19: 25.696418 | N19: 18.381873 | O19: 4.7711224 | P19: 4.9368317 | Q19: 3.3264796 | R19: 11.645806 | S19: 3.9085997 | T19: 14.348134 | U19: 9.1338433 | V19: 10.62923 | W19: 6.8009961 | X19: 0.19263885 | Y19: 10.520143 | Z19: 4.9261135 | AA19: 0.39740687 | AB19: 2.937551 | AC19: 23.630228 | AE19: 3.0790606 | AF19: 4.6855567 | AG19: 11.094936 | AI19: =SUM(E19:AH19) -> 333.31547 | AK19: =IF(AM19<>AM20,1,0) -> 1 | AL19: ONONSPEC | AM19: ONO | AN19: Other non-specified | AO19: =IF(AM19<>AM18,AL19,AO18&","&AL19) -> ONONSPEC
A20: =IF(C20="NECHEM","ICH_Feedstock",IF(AND(LEN(C20)=3,LEFT(C20,1)="I"),"IND","")) -> IND | B20: IND | C20: IFP | D20: INDOVC | G20: 0.11449642 | N20: 33.787078 | O20: 0.19191454 | P20: 1.2018963 | Q20: 0.11687452 | S20: 0.19128233 | T20: 0.65620972 | U20: 1.4349001 | V20: 0.61468504 | W20: 0.71859723 | Y20: 0.40184069 | AC20: 0.0002888892 | AI20: =SUM(E20:AH20) -> 39.430064
A21: =IF(C21="NECHEM","ICH_Feedstock",IF(AND(LEN(C21)=3,LEFT(C21,1)="I"),"IND","")) | B21: IND | C21: *IIS | D21: INDBFG | E21: 5.2041631 | G21: 4.4760995 | H21: 9.4339029 | I21: 161.62115 | J21: 14.653432 | K21: 1.0297309 | L21: 15.682777 | M21: 20.040001 | N21: 3143.1129 | O21: 4.5219994 | P21: 21.004054 | Q21: 3.8611423 | S21: 6.2049213 | T21: 1.4379983 | U21: 53.831509 | W21: 61.208998 | X21: 432.34051 | Y21: 0.56588789 | Z21: 2.2299985 | AA21: 1.9922385 | AB21: 1.7901961 | AC21: 138.8518 | AE21: 18.124632 | AF21: 0.91199808 | AG21: 63.144999 | AI21: =SUM(E21:AH21) -> 4187.277
A22: =IF(C22="NECHEM","ICH_Feedstock",IF(AND(LEN(C22)=3,LEFT(C22,1)="I"),"IND","")) | B22: IND | C22: *IIS | D22: INDBIO | I22: 2.1027073 | J22: 0.016165235 | L22: 140.12579 | M22: 0.068002006 | O22: 0.086578837 | P22: 0.26987275 | Q22: 0.066398461 | R22: 0.0045468648 | S22: 0.049065109 | T22: 0.0041072508 | U22: 0.65962615 | V22: 0.021733679 | W22: 0.003998394 | Y22: 0.3945096 | AB22: 0.58622736 | AC22: 53.944444 | AG22: 0.084359833 | AI22: =SUM(E22:AH22) -> 198.48814 | AM22: INDBFG | AN22: BF Gas
A23: =IF(C23="NECHEM","ICH_Feedstock",IF(AND(LEN(C23)=3,LEFT(C23,1)="I"),"IND","")) | B23: IND | C23: *IIS | D23: INDCOA | E23: 0.22661474 | F23: 0.03965737 | G23: 0.18143079 | H23: 22.837378 | I23: 150.22424 | J23: 355.47567 | K23: 0.67352633 | L23: 95.704173 | M23: 9.3672197 | N23: 2122.4898 | O23: 3.052487 | P23: 13.443028 | Q23: 11.021956 | R23: 0.86862702 | S23: 12.220763 | T23: 4.5049173 | U23: 70.003618 | V23: 1.8844075 | W23: 28.433279 | X23: 1542.0742 | Y23: 0.04867155 | AB23: 6.01003 | AC23: 98.881067 | AE23: 83.145979 | AF23: 4.6196314 | AG23: 8.8313387 | AI23: =SUM(E23:AH23) -> 4646.2637 | AM23: INDBIO | AN23: Biomass
A24: =IF(C24="NECHEM","ICH_Feedstock",IF(AND(LEN(C24)=3,LEFT(C24,1)="I"),"IND","")) | B24: IND | C24: *IIS | D24: INDCOG | F24: 0.8340608 | G24: 7.5567302 | I24: 195.95806 | J24: 30.737422 | K24: 0.7877841 | L24: 44.585279 | M24: 19.907099 | N24: 569.78817 | O24: 5.8553989 | P24: 18.512882 | Q24: 9.6562513 | R24: 3.0562845 | S24: 1.3166984 | T24: 1.6164021 | U24: 37.404243 | W24: 24.650099 | X24: 75.001314 | Y24: 0.50075803 | Z24: 6.9965992 | AA24: 2.5255154 | AC24: 132.2967 | AE24: 18.214024 | AF24: 2.5893013 | AG24: 0.18449972 | AI24: =SUM(E24:AH24) -> 1210.5316 | AM24: INDCOA | AN24: Coal
A25: =IF(C25="NECHEM","ICH_Feedstock",IF(AND(LEN(C25)=3,LEFT(C25,1)="I"),"IND","")) | B25: IND | C25: *IIS | D25: INDELC | E25: 3.0732787 | F25: 1.1637504 | G25: 23.895533 | H25: 87.381233 | I25: 433.31776 | J25: 173.67332 | K25: 17.187404 | L25: 85.630837 | M25: 29.498401 | N25: 2325.4848 | O25: 33.443032 | P25: 47.75346 | Q25: 30.067596 | R25: 72.544474 | S25: 17.081692 | T25: 53.527953 | U25: 174.27332 | V25: 45.951662 | W25: 87.7392 | X25: 350.63679 | Y25: 68.281588 | Z25: 19.429201 | AA25: 1.6120604 | AB25: 21.689102 | AC25: 223.47735 | AD25: 16.618644 | AE25: 67.765535 | AF25: 8.7959518 | AG25: 204.41374 | AI25: =SUM(E25:AH25) -> 4725.4087 | AM25: INDELC | AN25: Electricity
A26: =IF(C26="NECHEM","ICH_Feedstock",IF(AND(LEN(C26)=3,LEFT(C26,1)="I"),"IND","")) | B26: IND | C26: *IIS | D26: INDHET | H26: 35.69973 | I26: 0.23466595 | J26: 0.19284401 | M26: 0.056999095 | N26: 194.7274 | O26: 3.792035 | P26: 6.755226 | Q26: 0.013067003 | R26: 7.0243828 | S26: 1.3235103 | U26: 53.475681 | V26: 0.4182362 | W26: 1.4100012 | AB26: 0.0070003296 | AC26: 253.88066 | AG26: 7.327281 | AI26: =SUM(E26:AH26) -> 566.33871 | AM26: INDHET | AN26: Heat
A27: =IF(C27="NECHEM","ICH_Feedstock",IF(AND(LEN(C27)=3,LEFT(C27,1)="I"),"IND","")) | B27: IND | C27: *IIS | D27: INDNGA | E27: 88.866861 | F27: 10.66239 | G27: 34.209593 | H27: 27.625005 | I27: 199.60413 | J27: 51.623194 | K27: 8.4235695 | L27: 54.722142 | M27: 74.809801 | N27: 929.78709 | O27: 12.972197 | P27: 55.94671 | Q27: 38.021583 | R27: 55.646265 | S27: 20.724082 | T27: 26.522637 | U27: 134.18267 | V27: 23.384639 | W27: 94.027113 | X27: 21.470991 | Y27: 47.968498 | Z27: 154.0584 | AA27: 72.99914 | AB27: 0.043404556 | AC27: 488.51988 | AE27: 14.295598 | AF27: 13.5855 | AG27: 393.06899 | AI27: =SUM(E27:AH27) -> 3147.7721 | AM27: INDNGA | AN27: Natural Gas
A28: =IF(C28="NECHEM","ICH_Feedstock",IF(AND(LEN(C28)=3,LEFT(C28,1)="I"),"IND","")) | B28: IND | C28: *IIS | D28: INDOIL | E28: 2.3829968 | F28: 0.39150348 | G28: 0.35065287 | H28: 22.864446 | I28: 54.777554 | J28: 50.859886 | K28: 0.87116422 | L28: 11.928758 | M28: 0.18143916 | N28: 28.547419 | O28: 9.2687546 | P28: 0.35197172 | Q28: 0.7412855 | R28: 3.3251147 | S28: 0.13797599 | T28: 3.3590864 | U28: 7.3766392 | V28: 0.93863869 | W28: 0.59999775 | X28: 24.166323 | Y28: 0.50863758 | Z28: 3.2494802 | AB28: 0.61515815 | AC28: 13.775501 | AE28: 0.64145125 | AF28: 0.2313207 | AG28: 3.6858033 | AI28: =SUM(E28:AH28) -> 246.12896 | AM28: INDOIL | AN28: Oil
A29: =IF(C29="NECHEM","ICH_Feedstock",IF(AND(LEN(C29)=3,LEFT(C29,1)="I"),"IND","")) | B29: IND | C29: *IIS | D29: INDOVC | E29: 7.6538388 | F29: 1.3480701 | G29: 3.2370788 | H29: 27.373294 | I29: 114.24441 | J29: 169.83155 | K29: 12.285001 | L29: 71.299814 | M29: 20.373094 | N29: 1233.2233 | O29: 12.853183 | P29: 19.575697 | Q29: 17.730081 | R29: 19.215214 | S29: 2.4194429 | T29: 5.7615141 | U29: 86.008248 | V29: 2.2752244 | X29: 215.51669 | Y29: 0.060331788 | Z29: 22.0605 | AB29: 2.2235718 | AC29: 768.67759 | AE29: 4.6360101 | AF29: 15.227802 | AG29: 77.531388 | AI29: =SUM(E29:AH29) -> 2932.642 | AM29: INDOVC | AN29: Oven Coke
A30: =IF(C30="NECHEM","ICH_Feedstock",IF(AND(LEN(C30)=3,LEFT(C30,1)="I"),"IND","")) -> IND | B30: IND | C30: ILP | D30: INDBIO | G30: 63.6468 | I30: 135.202 | J30: 4.6462259 | K30: 7.3629986 | L30: 389.47277 | M30: 182.289 | O30: 326.07196 | P30: 100.73913 | Q30: 12.411028 | R30: 0.12249321 | S30: 8.292531 | T30: 62.762209 | U30: 2.008207 | V30: 25.758169 | W30: 34.984629 | Y30: 45.762457 | AB30: 4.3265931 | AC30: 19.313126 | AF30: 17.024998 | AG30: 1165.5846 | AI30: =SUM(E30:AH30) -> 2607.7819
A31: =IF(C31="NECHEM","ICH_Feedstock",IF(AND(LEN(C31)=3,LEFT(C31,1)="I"),"IND","")) -> IND | B31: IND | C31: ILP | D31: INDCOA | F31: 0.5064437 | H31: 0.042801656 | I31: 65.79408 | J31: 111.58915 | K31: 1.765942 | L31: 4.2823386 | N31: 156.24381 | O31: 7.9602121 | P31: 11.930261 | Q31: 0.86937227 | S31: 2.8957332 | U31: 12.278846 | V31: 0.40373731 | W31: 10.776848 | X31: 29.338767 | Y31: 12.523502 | AC31: 0.00083736 | AF31: 2.5077425 | AG31: 40.971326 | AI31: =SUM(E31:AH31) -> 472.68175
A32: =IF(C32="NECHEM","ICH_Feedstock",IF(AND(LEN(C32)=3,LEFT(C32,1)="I"),"IND","")) -> IND | B32: IND | C32: ILP | D32: INDELC | E32: 1.9958476 | F32: 0.030676684 | G32: 31.846526 | H32: 1.0418601 | I32: 159.98148 | J32: 43.818906 | K32: 18.100076 | L32: 84.360851 | M32: 146.8008 | N32: 315.2376 | O32: 135.30076 | P32: 47.264383 | Q32: 15.445658 | R32: 33.142252 | S32: 10.993009 | T32: 32.412414 | U32: 26.284601 | V32: 27.056471 | W32: 71.236798 | X32: 47.201276 | Y32: 11.857704 | Z32: 12.2796 | AA32: 0.26966341 | AB32: 13.392217 | AC32: 65.393282 | AE32: 4.2856587 | AF32: 36.62938 | AG32: 263.5879 | AI32: =SUM(E32:AH32) -> 1657.2477
A33: =IF(C33="NECHEM","ICH_Feedstock",IF(AND(LEN(C33)=3,LEFT(C33,1)="I"),"IND","")) -> IND | B33: IND | C33: ILP | D33: INDHET | H33: 0.72604974 | I33: 11.31571 | J33: 0.23196965 | M33: 4.6140001 | N33: 219.0485 | O33: 13.0681 | P33: 5.9627694 | Q33: 2.9553868 | R33: 27.561549 | S33: 1.0894054 | T33: 3.4624585 | U33: 15.281351 | V33: 11.042785 | W33: 26.801001 | AB33: 0.0099980784 | AC33: 176.70115 | AF33: 0.006510474 | AG33: 18.550358 | AI33: =SUM(E33:AH33) -> 538.42905
A34: =IF(C34="NECHEM","ICH_Feedstock",IF(AND(LEN(C34)=3,LEFT(C34,1)="I"),"IND","")) -> IND | B34: IND | C34: ILP | D34: INDNGA | E34: 2.4348754 | F34: 0.0080219088 | G34: 15.129743 | H34: 2.3323825 | I34: 40.252481 | J34: 12.522493 | K34: 13.156713 | L34: 38.310229 | M34: 86.448598 | N34: 87.287332 | O34: 18.381136 | P34: 42.708412 | Q34: 17.896958 | R34: 26.625745 | S34: 12.366765 | T34: 31.755551 | U34: 13.204033 | V34: 31.961252 | W34: 78.489358 | Y34: 5.2736389 | Z34: 32.783402 | AA34: 0.33023804 | AB34: 1.1019239 | AC34: 23.0637 | AE34: 4.2983992 | AF34: 14.668198 | AG34: 332.41077 | AI34: =SUM(E34:AH34) -> 985.20235
A35: =IF(C35="NECHEM","ICH_Feedstock",IF(AND(LEN(C35)=3,LEFT(C35,1)="I"),"IND","")) -> IND | B35: IND | C35: ILP | D35: INDOIL | E35: 0.82752939 | F35: 0.14312994 | G35: 9.8350737 | H35: 0.19715641 | I35: 29.612269 | J35: 9.8259758 | K35: 2.1882394 | L35: 18.44107 | M35: 5.0802003 | N35: 13.228823 | O35: 11.855695 | P35: 2.0767533 | Q35: 0.48898056 | R35: 2.1094857 | S35: 0.34812823 | T35: 4.8512326 | U35: 1.2178815 | V35: 1.7989759 | W35: 1.6396011 | Y35: 1.3285805 | Z35: 3.2754383 | AB35: 0.46851967 | AC35: 8.2867867 | AE35: 0.21486239 | AF35: 1.2626635 | AG35: 4.9315354 | AI35: =SUM(E35:AH35) -> 135.53459
A36: =IF(C36="NECHEM","ICH_Feedstock",IF(AND(LEN(C36)=3,LEFT(C36,1)="I"),"IND","")) -> IND | B36: IND | C36: IMC | D36: INDBIO | E36: 0.029106634 | F36: 0.24813908 | G36: 0.1172304 | H36: 0.010580044 | I36: 1.2923647 | J36: 0.3346593 | K36: 0.015001304 | L36: 1.5117991 | M36: 13.312998 | O36: 3.363089 | P36: 1.0318745 | Q36: 1.6168961 | R36: 0.19739925 | S36: 0.50036028 | T36: 1.5448999 | U36: 3.31721 | V36: 3.2754467 | W36: 2.3293555 | X36: 257.175 | Y36: 0.73030352 | AC36: 0.87583669 | AG36: 17.335567 | AI36: =SUM(E36:AH36) -> 310.16512
A37: =IF(C37="NECHEM","ICH_Feedstock",IF(AND(LEN(C37)=3,LEFT(C37,1)="I"),"IND","")) -> IND | B37: IND | C37: IMC | D37: INDCOA | F37: 1.8256374 | G37: 1.2458284 | H37: 18.20918 | J37: 17.693526 | K37: 4.0611332 | L37: 8.5354491 | N37: 306.35572 | O37: 3.8837259 | P37: 1.6478742 | Q37: 0.18862371 | S37: 0.18699505 | U37: 0.86169787 | W37: 2.4482857 | X37: 4.4388914 | AC37: 1.358311 | AE37: 10.92898 | AF37: 0.12926326 | AI37: =SUM(E37:AH37) -> 383.99912
A38: =IF(C38="NECHEM","ICH_Feedstock",IF(AND(LEN(C38)=3,LEFT(C38,1)="I"),"IND","")) -> IND | B38: IND | C38: IMC | D38: INDCOG | N38: 7.0868749 | O38: 0.13409902 | AI38: =SUM(E38:AH38) -> 7.220974
A39: =IF(C39="NECHEM","ICH_Feedstock",IF(AND(LEN(C39)=3,LEFT(C39,1)="I"),"IND","")) -> IND | B39: IND | C39: IMC | D39: INDELC | E39: 14.361616 | F39: 28.040323 | G39: 97.583071 | H39: 39.035667 | I39: 29.872537 | J39: 46.734833 | K39: 85.095739 | L39: 43.220324 | M39: 72.399598 | N39: 830.4912 | O39: 27.32675 | P39: 26.703837 | Q39: 11.258418 | R39: 11.901021 | S39: 11.393376 | T39: 23.698398 | U39: 66.79148 | V39: 20.50994 | W39: 23.785198 | X39: 92.770968 | Y39: 25.476423 | Z39: 43.527597 | AA39: 9.5146244 | AB39: 6.8244589 | AC39: 149.3352 | AD39: 1.0689905 | AE39: 104.20146 | AF39: 5.4377321 | AG39: 286.3652 | AI39: =SUM(E39:AH39) -> 2234.726
A40: =IF(C40="NECHEM","ICH_Feedstock",IF(AND(LEN(C40)=3,LEFT(C40,1)="I"),"IND","")) -> IND | B40: IND | C40: IMC | D40: INDHET | H40: 29.170449 | M40: 0.033000358 | N40: 49.8811 | O40: 0.22692037 | P40: 4.017737 | Q40: 1.4745449 | R40: 0.22775355 | S40: 1.0709583 | T40: 0.016102433 | U40: 3.9820613 | V40: 0.35349571 | W40: 0.19399956 | AB40: 0.49899957 | AC40: 54.53814 | AI40: =SUM(E40:AH40) -> 145.68526
A41: =IF(C41="NECHEM","ICH_Feedstock",IF(AND(LEN(C41)=3,LEFT(C41,1)="I"),"IND","")) -> IND | B41: IND | C41: IMC | D41: INDNGA | E41: 1.5443849 | F41: 0.0065816496 | G41: 9.9614062 | H41: 21.214612 | I41: 2.5060887 | J41: 1.2214152 | K41: 8.2145728 | L41: 12.985817 | M41: 59.013 | N41: 83.721413 | O41: 1.2679766 | P41: 18.372637 | Q41: 10.134514 | R41: 10.950353 | S41: 7.8628188 | T41: 26.580679 | U41: 30.982961 | V41: 10.376963 | W41: 30.366835 | Y41: 8.8358437 | Z41: 11.645099 | AA41: 0.6005211 | AB41: 0.15080016 | AC41: 240.56721 | AE41: 0.27089852 | AF41: 17.105402 | AG41: 200.33734 | AI41: =SUM(E41:AH41) -> 826.79814
...

Sheet Service shares
A1: from MECS
A2: Fuel | B2: Industry | C2: Service | D2: Share | F2: ='IND Balance'!E4 -> Africa_north | G2: ='IND Balance'!F4 -> Africa_other | H2: ='IND Balance'!G4 -> Arg-Chi | I2: ='IND Balance'!H4 -> Asia_central | J2: ='IND Balance'!I4 -> Asia_east | K2: ='IND Balance'!J4 -> Asia_other | L2: ='IND Balance'!K4 -> Australia_NZ | M2: ='IND Balance'!L4 -> Brazil | ... AI2: ='IND Balance'!AH4 -> \I: | AK2: =F2 -> Africa_north | AL2: =G2 -> Africa_other | AM2: =H2 -> Arg-Chi | AN2: =I2 -> Asia_central | AO2: =J2 -> Asia_east | AP2: =K2 -> Asia_other | AQ2: =L2 -> Australia_NZ | AR2: =M2 -> Brazil | ... BN2: =AI2 -> \I:
A3: ELC | B3: IFP | C3: STM | D3: 0.028301887 | F3: =$D3 -> 0.028301887 | G3: =$D3 -> 0.028301887 | H3: =$D3 -> 0.028301887 | I3: =$D3 -> 0.028301887 | J3: =$D3 -> 0.028301887 | K3: =$D3 -> 0.028301887 | L3: =$D3 -> 0.028301887 | M3: =$D3 -> 0.028301887 | ... AI3: =$D3 -> 0.028301887 | AK3: =SUMIFS('IND Balance'!E$5:E$141,'IND Balance'!$C$5:$C$141,'Service shares'!$B3,'IND Balance'!$D$5:$D$141,"*"&'Service shares'!$A3)*F3 -> 0.49746673 | AL3: =SUMIFS('IND Balance'!F$5:F$141,'IND Balance'!$C$5:$C$141,'Service shares'!$B3,'IND Balance'!$D$5:$D$141,"*"&'Service shares'!$A3)*G3 -> 0.22114954 | AM3: =SUMIFS('IND Balance'!G$5:G$141,'IND Balance'!$C$5:$C$141,'Service shares'!$B3,'IND Balance'!$D$5:$D$141,"*"&'Service shares'!$A3)*H3 -> 1.2585126 | AN3: =SUMIFS('IND Balance'!H$5:H$141,'IND Balance'!$C$5:$C$141,'Service shares'!$B3,'IND Balance'!$D$5:$D$141,"*"&'Service shares'!$A3)*I3 -> 0.38007723 | AO3: =SUMIFS('IND Balance'!I$5:I$141,'IND Balance'!$C$5:$C$141,'Service shares'!$B3,'IND Balance'!$D$5:$D$141,"*"&'Service shares'!$A3)*J3 -> 3.7673897 | AP3: =SUMIFS('IND Balance'!J$5:J$141,'IND Balance'!$C$5:$C$141,'Service shares'!$B3,'IND Balance'!$D$5:$D$141,"*"&'Service shares'!$A3)*K3 -> 4.6216199 | AQ3: =SUMIFS('IND Balance'!K$5:K$141,'IND Balance'!$C$5:$C$141,'Service shares'!$B3,'IND Balance'!$D$5:$D$141,"*"&'Service shares'!$A3)*L3 -> 0.89960808 | AR3: =SUMIFS('IND Balance'!L$5:L$141,'IND Balance'!$C$5:$C$141,'Service shares'!$B3,'IND Balance'!$D$5:$D$141,"*"&'Service shares'!$A3)*M3 -> 2.6700115 | ... BN3: =SUMIFS('IND Balance'!AH$5:AH$141,'IND Balance'!$C$5:$C$141,'Service shares'!$B3,'IND Balance'!$D$5:$D$141,"*"&'Service shares'!$A3)*AI3 -> 0
A4: ELC | B4: IFP | C4: PRH | D4: 0.034591195 | F4: =$D4 -> 0.034591195 | G4: =$D4 -> 0.034591195 | H4: =$D4 -> 0.034591195 | I4: =$D4 -> 0.034591195 | J4: =$D4 -> 0.034591195 | K4: =$D4 -> 0.034591195 | L4: =$D4 -> 0.034591195 | M4: =$D4 -> 0.034591195 | ... AI4: =$D4 -> 0.034591195 | AK4: =SUMIFS('IND Balance'!E$5:E$141,'IND Balance'!$C$5:$C$141,'Service shares'!$B4,'IND Balance'!$D$5:$D$141,"*"&'Service shares'!$A4)*F4 -> 0.60801489 | AL4: =SUMIFS('IND Balance'!F$5:F$141,'IND Balance'!$C$5:$C$141,'Service shares'!$B4,'IND Balance'!$D$5:$D$141,"*"&'Service shares'!$A4)*G4 -> 0.27029388 | AM4: =SUMIFS('IND Balance'!G$5:G$141,'IND Balance'!$C$5:$C$141,'Service shares'!$B4,'IND Balance'!$D$5:$D$141,"*"&'Service shares'!$A4)*H4 -> 1.5381821 | AN4: =SUMIFS('IND Balance'!H$5:H$141,'IND Balance'!$C$5:$C$141,'Service shares'!$B4,'IND Balance'!$D$5:$D$141,"*"&'Service shares'!$A4)*I4 -> 0.46453884 | AO4: =SUMIFS('IND Balance'!I$5:I$141,'IND Balance'!$C$5:$C$141,'Service shares'!$B4,'IND Balance'!$D$5:$D$141,"*"&'Service shares'!$A4)*J4 -> 4.6045874 | AP4: =SUMIFS('IND Balance'!J$5:J$141,'IND Balance'!$C$5:$C$141,'Service shares'!$B4,'IND Balance'!$D$5:$D$141,"*"&'Service shares'!$A4)*K4 -> 5.6486466 | AQ4: =SUMIFS('IND Balance'!K$5:K$141,'IND Balance'!$C$5:$C$141,'Service shares'!$B4,'IND Balance'!$D$5:$D$141,"*"&'Service shares'!$A4)*L4 -> 1.099521 | AR4: =SUMIFS('IND Balance'!L$5:L$141,'IND Balance'!$C$5:$C$141,'Service shares'!$B4,'IND Balance'!$D$5:$D$141,"*"&'Service shares'!$A4)*M4 -> 3.2633474 | ... BN4: =SUMIFS('IND Balance'!AH$5:AH$141,'IND Balance'!$C$5:$C$141,'Service shares'!$B4,'IND Balance'!$D$5:$D$141,"*"&'Service shares'!$A4)*AI4 -> 0
A5: ELC | B5: IFP | C5: PRC | D5: 0.2672956 | F5: =$D5 -> 0.2672956 | G5: =$D5 -> 0.2672956 | H5: =$D5 -> 0.2672956 | I5: =$D5 -> 0.2672956 | J5: =$D5 -> 0.2672956 | K5: =$D5 -> 0.2672956 | L5: =$D5 -> 0.2672956 | M5: =$D5 -> 0.2672956 | ... AI5: =$D5 -> 0.2672956 | AK5: =SUMIFS('IND Balance'!E$5:E$141,'IND Balance'!$C$5:$C$141,'Service shares'!$B5,'IND Balance'!$D$5:$D$141,"*"&'Service shares'!$A5)*F5 -> 4.6982969 | AL5: =SUMIFS('IND Balance'!F$5:F$141,'IND Balance'!$C$5:$C$141,'Service shares'!$B5,'IND Balance'!$D$5:$D$141,"*"&'Service shares'!$A5)*G5 -> 2.0886346 | AM5: =SUMIFS('IND Balance'!G$5:G$141,'IND Balance'!$C$5:$C$141,'Service shares'!$B5,'IND Balance'!$D$5:$D$141,"*"&'Service shares'!$A5)*H5 -> 11.885953 | AN5: =SUMIFS('IND Balance'!H$5:H$141,'IND Balance'!$C$5:$C$141,'Service shares'!$B5,'IND Balance'!$D$5:$D$141,"*"&'Service shares'!$A5)*I5 -> 3.5896183 | AO5: =SUMIFS('IND Balance'!I$5:I$141,'IND Balance'!$C$5:$C$141,'Service shares'!$B5,'IND Balance'!$D$5:$D$141,"*"&'Service shares'!$A5)*J5 -> 35.580903 | AP5: =SUMIFS('IND Balance'!J$5:J$141,'IND Balance'!$C$5:$C$141,'Service shares'!$B5,'IND Balance'!$D$5:$D$141,"*"&'Service shares'!$A5)*K5 -> 43.648633 | AQ5: =SUMIFS('IND Balance'!K$5:K$141,'IND Balance'!$C$5:$C$141,'Service shares'!$B5,'IND Balance'!$D$5:$D$141,"*"&'Service shares'!$A5)*L5 -> 8.4962985 | AR5: =SUMIFS('IND Balance'!L$5:L$141,'IND Balance'!$C$5:$C$141,'Service shares'!$B5,'IND Balance'!$D$5:$D$141,"*"&'Service shares'!$A5)*M5 -> 25.216775 | ... BN5: =SUMIFS('IND Balance'!AH$5:AH$141,'IND Balance'!$C$5:$C$141,'Service shares'!$B5,'IND Balance'!$D$5:$D$141,"*"&'Service shares'!$A5)*AI5 -> 0
A6: ELC | B6: IFP | C6: MDR | D6: 0.4245283 | F6: =$D6 -> 0.4245283 | G6: =$D6 -> 0.4245283 | H6: =$D6 -> 0.4245283 | I6: =$D6 -> 0.4245283 | J6: =$D6 -> 0.4245283 | K6: =$D6 -> 0.4245283 | L6: =$D6 -> 0.4245283 | M6: =$D6 -> 0.4245283 | ... AI6: =$D6 -> 0.4245283 | AK6: =SUMIFS('IND Balance'!E$5:E$141,'IND Balance'!$C$5:$C$141,'Service shares'!$B6,'IND Balance'!$D$5:$D$141,"*"&'Service shares'!$A6)*F6 -> 7.4620009 | AL6: =SUMIFS('IND Balance'!F$5:F$141,'IND Balance'!$C$5:$C$141,'Service shares'!$B6,'IND Balance'!$D$5:$D$141,"*"&'Service shares'!$A6)*G6 -> 3.3172431 | AM6: =SUMIFS('IND Balance'!G$5:G$141,'IND Balance'!$C$5:$C$141,'Service shares'!$B6,'IND Balance'!$D$5:$D$141,"*"&'Service shares'!$A6)*H6 -> 18.877689 | AN6: =SUMIFS('IND Balance'!H$5:H$141,'IND Balance'!$C$5:$C$141,'Service shares'!$B6,'IND Balance'!$D$5:$D$141,"*"&'Service shares'!$A6)*I6 -> 5.7011585 | AO6: =SUMIFS('IND Balance'!I$5:I$141,'IND Balance'!$C$5:$C$141,'Service shares'!$B6,'IND Balance'!$D$5:$D$141,"*"&'Service shares'!$A6)*J6 -> 56.510846 | AP6: =SUMIFS('IND Balance'!J$5:J$141,'IND Balance'!$C$5:$C$141,'Service shares'!$B6,'IND Balance'!$D$5:$D$141,"*"&'Service shares'!$A6)*K6 -> 69.324299 | AQ6: =SUMIFS('IND Balance'!K$5:K$141,'IND Balance'!$C$5:$C$141,'Service shares'!$B6,'IND Balance'!$D$5:$D$141,"*"&'Service shares'!$A6)*L6 -> 13.494121 | AR6: =SUMIFS('IND Balance'!L$5:L$141,'IND Balance'!$C$5:$C$141,'Service shares'!$B6,'IND Balance'!$D$5:$D$141,"*"&'Service shares'!$A6)*M6 -> 40.050173 | ... BN6: =SUMIFS('IND Balance'!AH$5:AH$141,'IND Balance'!$C$5:$C$141,'Service shares'!$B6,'IND Balance'!$D$5:$D$141,"*"&'Service shares'!$A6)*AI6 -> 0
A7: ELC | B7: IFP | C7: ECP | D7: 0.0062893082 | F7: =$D7 -> 0.0062893082 | G7: =$D7 -> 0.0062893082 | H7: =$D7 -> 0.0062893082 | I7: =$D7 -> 0.0062893082 | J7: =$D7 -> 0.0062893082 | K7: =$D7 -> 0.0062893082 | L7: =$D7 -> 0.0062893082 | M7: =$D7 -> 0.0062893082 | ... AI7: =$D7 -> 0.0062893082 | AK7: =SUMIFS('IND Balance'!E$5:E$141,'IND Balance'!$C$5:$C$141,'Service shares'!$B7,'IND Balance'!$D$5:$D$141,"*"&'Service shares'!$A7)*F7 -> 0.11054816 | AL7: =SUMIFS('IND Balance'!F$5:F$141,'IND Balance'!$C$5:$C$141,'Service shares'!$B7,'IND Balance'!$D$5:$D$141,"*"&'Service shares'!$A7)*G7 -> 0.049144342 | AM7: =SUMIFS('IND Balance'!G$5:G$141,'IND Balance'!$C$5:$C$141,'Service shares'!$B7,'IND Balance'!$D$5:$D$141,"*"&'Service shares'!$A7)*H7 -> 0.27966947 | AN7: =SUMIFS('IND Balance'!H$5:H$141,'IND Balance'!$C$5:$C$141,'Service shares'!$B7,'IND Balance'!$D$5:$D$141,"*"&'Service shares'!$A7)*I7 -> 0.084461607 | AO7: =SUMIFS('IND Balance'!I$5:I$141,'IND Balance'!$C$5:$C$141,'Service shares'!$B7,'IND Balance'!$D$5:$D$141,"*"&'Service shares'!$A7)*J7 -> 0.83719772 | AP7: =SUMIFS('IND Balance'!J$5:J$141,'IND Balance'!$C$5:$C$141,'Service shares'!$B7,'IND Balance'!$D$5:$D$141,"*"&'Service shares'!$A7)*K7 -> 1.0270266 | AQ7: =SUMIFS('IND Balance'!K$5:K$141,'IND Balance'!$C$5:$C$141,'Service shares'!$B7,'IND Balance'!$D$5:$D$141,"*"&'Service shares'!$A7)*L7 -> 0.19991291 | AR7: =SUMIFS('IND Balance'!L$5:L$141,'IND Balance'!$C$5:$C$141,'Service shares'!$B7,'IND Balance'!$D$5:$D$141,"*"&'Service shares'!$A7)*M7 -> 0.59333589 | ... BN7: =SUMIFS('IND Balance'!AH$5:AH$141,'IND Balance'!$C$5:$C$141,'Service shares'!$B7,'IND Balance'!$D$5:$D$141,"*"&'Service shares'!$A7)*AI7 -> 0
A8: ELC | B8: IFP | C8: OTP | D8: 0.012578616 | F8: =$D8 -> 0.012578616 | G8: =$D8 -> 0.012578616 | H8: =$D8 -> 0.012578616 | I8: =$D8 -> 0.012578616 | J8: =$D8 -> 0.012578616 | K8: =$D8 -> 0.012578616 | L8: =$D8 -> 0.012578616 | M8: =$D8 -> 0.012578616 | ... AI8: =$D8 -> 0.012578616 | AK8: =SUMIFS('IND Balance'!E$5:E$141,'IND Balance'!$C$5:$C$141,'Service shares'!$B8,'IND Balance'!$D$5:$D$141,"*"&'Service shares'!$A8)*F8 -> 0.22109632 | AL8: =SUMIFS('IND Balance'!F$5:F$141,'IND Balance'!$C$5:$C$141,'Service shares'!$B8,'IND Balance'!$D$5:$D$141,"*"&'Service shares'!$A8)*G8 -> 0.098288685 | AM8: =SUMIFS('IND Balance'!G$5:G$141,'IND Balance'!$C$5:$C$141,'Service shares'!$B8,'IND Balance'!$D$5:$D$141,"*"&'Service shares'!$A8)*H8 -> 0.55933894 | AN8: =SUMIFS('IND Balance'!H$5:H$141,'IND Balance'!$C$5:$C$141,'Service shares'!$B8,'IND Balance'!$D$5:$D$141,"*"&'Service shares'!$A8)*I8 -> 0.16892321 | AO8: =SUMIFS('IND Balance'!I$5:I$141,'IND Balance'!$C$5:$C$141,'Service shares'!$B8,'IND Balance'!$D$5:$D$141,"*"&'Service shares'!$A8)*J8 -> 1.6743954 | AP8: =SUMIFS('IND Balance'!J$5:J$141,'IND Balance'!$C$5:$C$141,'Service shares'!$B8,'IND Balance'!$D$5:$D$141,"*"&'Service shares'!$A8)*K8 -> 2.0540533 | AQ8: =SUMIFS('IND Balance'!K$5:K$141,'IND Balance'!$C$5:$C$141,'Service shares'!$B8,'IND Balance'!$D$5:$D$141,"*"&'Service shares'!$A8)*L8 -> 0.39982581 | AR8: =SUMIFS('IND Balance'!L$5:L$141,'IND Balance'!$C$5:$C$141,'Service shares'!$B8,'IND Balance'!$D$5:$D$141,"*"&'Service shares'!$A8)*M8 -> 1.1866718 | ... BN8: =SUMIFS('IND Balance'!AH$5:AH$141,'IND Balance'!$C$5:$C$141,'Service shares'!$B8,'IND Balance'!$D$5:$D$141,"*"&'Service shares'!$A8)*AI8 -> 0
A9: ELC | B9: IFP | C9: SPC | D9: 0.10691824 | F9: =$D9 -> 0.10691824 | G9: =$D9 -> 0.10691824 | H9: =$D9 -> 0.10691824 | I9: =$D9 -> 0.10691824 | J9: =$D9 -> 0.10691824 | K9: =$D9 -> 0.10691824 | L9: =$D9 -> 0.10691824 | M9: =$D9 -> 0.10691824 | ... AI9: =$D9 -> 0.10691824 | AK9: =SUMIFS('IND Balance'!E$5:E$141,'IND Balance'!$C$5:$C$141,'Service shares'!$B9,'IND Balance'!$D$5:$D$141,"*"&'Service shares'!$A9)*F9 -> 1.8793188 | AL9: =SUMIFS('IND Balance'!F$5:F$141,'IND Balance'!$C$5:$C$141,'Service shares'!$B9,'IND Balance'!$D$5:$D$141,"*"&'Service shares'!$A9)*G9 -> 0.83545382 | AM9: =SUMIFS('IND Balance'!G$5:G$141,'IND Balance'!$C$5:$C$141,'Service shares'!$B9,'IND Balance'!$D$5:$D$141,"*"&'Service shares'!$A9)*H9 -> 4.754381 | AN9: =SUMIFS('IND Balance'!H$5:H$141,'IND Balance'!$C$5:$C$141,'Service shares'!$B9,'IND Balance'!$D$5:$D$141,"*"&'Service shares'!$A9)*I9 -> 1.4358473 | AO9: =SUMIFS('IND Balance'!I$5:I$141,'IND Balance'!$C$5:$C$141,'Service shares'!$B9,'IND Balance'!$D$5:$D$141,"*"&'Service shares'!$A9)*J9 -> 14.232361 | AP9: =SUMIFS('IND Balance'!J$5:J$141,'IND Balance'!$C$5:$C$141,'Service shares'!$B9,'IND Balance'!$D$5:$D$141,"*"&'Service shares'!$A9)*K9 -> 17.459453 | AQ9: =SUMIFS('IND Balance'!K$5:K$141,'IND Balance'!$C$5:$C$141,'Service shares'!$B9,'IND Balance'!$D$5:$D$141,"*"&'Service shares'!$A9)*L9 -> 3.3985194 | AR9: =SUMIFS('IND Balance'!L$5:L$141,'IND Balance'!$C$5:$C$141,'Service shares'!$B9,'IND Balance'!$D$5:$D$141,"*"&'Service shares'!$A9)*M9 -> 10.08671 | ... BN9: =SUMIFS('IND Balance'!AH$5:AH$141,'IND Balance'!$C$5:$C$141,'Service shares'!$B9,'IND Balance'!$D$5:$D$141,"*"&'Service shares'!$A9)*AI9 -> 0
A10: ELC | B10: IFP | C10: LIG | D10: 0.088050314 | F10: =$D10 -> 0.088050314 | G10: =$D10 -> 0.088050314 | H10: =$D10 -> 0.088050314 | I10: =$D10 -> 0.088050314 | J10: =$D10 -> 0.088050314 | K10: =$D10 -> 0.088050314 | L10: =$D10 -> 0.088050314 | M10: =$D10 -> 0.088050314 | ... AI10: =$D10 -> 0.088050314 | AK10: =SUMIFS('IND Balance'!E$5:E$141,'IND Balance'!$C$5:$C$141,'Service shares'!$B10,'IND Balance'!$D$5:$D$141,"*"&'Service shares'!$A10)*F10 -> 1.5476743 | AL10: =SUMIFS('IND Balance'!F$5:F$141,'IND Balance'!$C$5:$C$141,'Service shares'!$B10,'IND Balance'!$D$5:$D$141,"*"&'Service shares'!$A10)*G10 -> 0.68802079 | AM10: =SUMIFS('IND Balance'!G$5:G$141,'IND Balance'!$C$5:$C$141,'Service shares'!$B10,'IND Balance'!$D$5:$D$141,"*"&'Service shares'!$A10)*H10 -> 3.9153726 | AN10: =SUMIFS('IND Balance'!H$5:H$141,'IND Balance'!$C$5:$C$141,'Service shares'!$B10,'IND Balance'!$D$5:$D$141,"*"&'Service shares'!$A10)*I10 -> 1.1824625 | AO10: =SUMIFS('IND Balance'!I$5:I$141,'IND Balance'!$C$5:$C$141,'Service shares'!$B10,'IND Balance'!$D$5:$D$141,"*"&'Service shares'!$A10)*J10 -> 11.720768 | AP10: =SUMIFS('IND Balance'!J$5:J$141,'IND Balance'!$C$5:$C$141,'Service shares'!$B10,'IND Balance'!$D$5:$D$141,"*"&'Service shares'!$A10)*K10 -> 14.378373 | AQ10: =SUMIFS('IND Balance'!K$5:K$141,'IND Balance'!$C$5:$C$141,'Service shares'!$B10,'IND Balance'!$D$5:$D$141,"*"&'Service shares'!$A10)*L10 -> 2.7987807 | AR10: =SUMIFS('IND Balance'!L$5:L$141,'IND Balance'!$C$5:$C$141,'Service shares'!$B10,'IND Balance'!$D$5:$D$141,"*"&'Service shares'!$A10)*M10 -> 8.3067025 | ... BN10: =SUMIFS('IND Balance'!AH$5:AH$141,'IND Balance'!$C$5:$C$141,'Service shares'!$B10,'IND Balance'!$D$5:$D$141,"*"&'Service shares'!$A10)*AI10 -> 0
A11: ELC | B11: IFP | C11: OTH | D11: 0.031446541 | F11: =$D11 -> 0.031446541 | G11: =$D11 -> 0.031446541 | H11: =$D11 -> 0.031446541 | I11: =$D11 -> 0.031446541 | J11: =$D11 -> 0.031446541 | K11: =$D11 -> 0.031446541 | L11: =$D11 -> 0.031446541 | M11: =$D11 -> 0.031446541 | ... AI11: =$D11 -> 0.031446541 | AK11: =SUMIFS('IND Balance'!E$5:E$141,'IND Balance'!$C$5:$C$141,'Service shares'!$B11,'IND Balance'!$D$5:$D$141,"*"&'Service shares'!$A11)*F11 -> 0.55274081 | AL11: =SUMIFS('IND Balance'!F$5:F$141,'IND Balance'!$C$5:$C$141,'Service shares'!$B11,'IND Balance'!$D$5:$D$141,"*"&'Service shares'!$A11)*G11 -> 0.24572171 | AM11: =SUMIFS('IND Balance'!G$5:G$141,'IND Balance'!$C$5:$C$141,'Service shares'!$B11,'IND Balance'!$D$5:$D$141,"*"&'Service shares'!$A11)*H11 -> 1.3983474 | AN11: =SUMIFS('IND Balance'!H$5:H$141,'IND Balance'!$C$5:$C$141,'Service shares'!$B11,'IND Balance'!$D$5:$D$141,"*"&'Service shares'!$A11)*I11 -> 0.42230803 | AO11: =SUMIFS('IND Balance'!I$5:I$141,'IND Balance'!$C$5:$C$141,'Service shares'!$B11,'IND Balance'!$D$5:$D$141,"*"&'Service shares'!$A11)*J11 -> 4.1859886 | AP11: =SUMIFS('IND Balance'!J$5:J$141,'IND Balance'!$C$5:$C$141,'Service shares'!$B11,'IND Balance'!$D$5:$D$141,"*"&'Service shares'!$A11)*K11 -> 5.1351332 | AQ11: =SUMIFS('IND Balance'!K$5:K$141,'IND Balance'!$C$5:$C$141,'Service shares'!$B11,'IND Balance'!$D$5:$D$141,"*"&'Service shares'!$A11)*L11 -> 0.99956453 | AR11: =SUMIFS('IND Balance'!L$5:L$141,'IND Balance'!$C$5:$C$141,'Service shares'!$B11,'IND Balance'!$D$5:$D$141,"*"&'Service shares'!$A11)*M11 -> 2.9666795 | ... BN11: =SUMIFS('IND Balance'!AH$5:AH$141,'IND Balance'!$C$5:$C$141,'Service shares'!$B11,'IND Balance'!$D$5:$D$141,"*"&'Service shares'!$A11)*AI11 -> 0
A12: ELC | B12: IOI | C12: STM | D12: 0.015936255 | F12: =$D12 -> 0.015936255 | G12: =$D12 -> 0.015936255 | H12: =$D12 -> 0.015936255 | I12: =$D12 -> 0.015936255 | J12: =$D12 -> 0.015936255 | K12: =$D12 -> 0.015936255 | L12: =$D12 -> 0.015936255 | M12: =$D12 -> 0.015936255 | ... AI12: =$D12 -> 0.015936255 | AK12: =SUMIFS('IND Balance'!E$5:E$141,'IND Balance'!$C$5:$C$141,'Service shares'!$B12,'IND Balance'!$D$5:$D$141,"*"&'Service shares'!$A12)*F12 -> 3.2728974 | AL12: =SUMIFS('IND Balance'!F$5:F$141,'IND Balance'!$C$5:$C$141,'Service shares'!$B12,'IND Balance'!$D$5:$D$141,"*"&'Service shares'!$A12)*G12 -> 2.2763719 | AM12: =SUMIFS('IND Balance'!G$5:G$141,'IND Balance'!$C$5:$C$141,'Service shares'!$B12,'IND Balance'!$D$5:$D$141,"*"&'Service shares'!$A12)*H12 -> 0.84083468 | AN12: =SUMIFS('IND Balance'!H$5:H$141,'IND Balance'!$C$5:$C$141,'Service shares'!$B12,'IND Balance'!$D$5:$D$141,"*"&'Service shares'!$A12)*I12 -> 0.48632614 | AO12: =SUMIFS('IND Balance'!I$5:I$141,'IND Balance'!$C$5:$C$141,'Service shares'!$B12,'IND Balance'!$D$5:$D$141,"*"&'Service shares'!$A12)*J12 -> 2.6212116 | AP12: =SUMIFS('IND Balance'!J$5:J$141,'IND Balance'!$C$5:$C$141,'Service shares'!$B12,'IND Balance'!$D$5:$D$141,"*"&'Service shares'!$A12)*K12 -> 20.215465 | AQ12: =SUMIFS('IND Balance'!K$5:K$141,'IND Balance'!$C$5:$C$141,'Service shares'!$B12,'IND Balance'!$D$5:$D$141,"*"&'Service shares'!$A12)*L12 -> 0.17848398 | AR12: =SUMIFS('IND Balance'!L$5:L$141,'IND Balance'!$C$5:$C$141,'Service shares'!$B12,'IND Balance'!$D$5:$D$141,"*"&'Service shares'!$A12)*M12 -> 3.146991 | ... BN12: =SUMIFS('IND Balance'!AH$5:AH$141,'IND Balance'!$C$5:$C$141,'Service shares'!$B12,'IND Balance'!$D$5:$D$141,"*"&'Service shares'!$A12)*AI12 -> 0
A13: ELC | B13: IOI | C13: PRH | D13: 0.051792829 | F13: =$D13 -> 0.051792829 | G13: =$D13 -> 0.051792829 | H13: =$D13 -> 0.051792829 | I13: =$D13 -> 0.051792829 | J13: =$D13 -> 0.051792829 | K13: =$D13 -> 0.051792829 | L13: =$D13 -> 0.051792829 | M13: =$D13 -> 0.051792829 | ... AI13: =$D13 -> 0.051792829 | AK13: =SUMIFS('IND Balance'!E$5:E$141,'IND Balance'!$C$5:$C$141,'Service shares'!$B13,'IND Balance'!$D$5:$D$141,"*"&'Service shares'!$A13)*F13 -> 10.636916 | AL13: =SUMIFS('IND Balance'!F$5:F$141,'IND Balance'!$C$5:$C$141,'Service shares'!$B13,'IND Balance'!$D$5:$D$141,"*"&'Service shares'!$A13)*G13 -> 7.3982087 | AM13: =SUMIFS('IND Balance'!G$5:G$141,'IND Balance'!$C$5:$C$141,'Service shares'!$B13,'IND Balance'!$D$5:$D$141,"*"&'Service shares'!$A13)*H13 -> 2.7327127 | AN13: =SUMIFS('IND Balance'!H$5:H$141,'IND Balance'!$C$5:$C$141,'Service shares'!$B13,'IND Balance'!$D$5:$D$141,"*"&'Service shares'!$A13)*I13 -> 1.58056 | AO13: =SUMIFS('IND Balance'!I$5:I$141,'IND Balance'!$C$5:$C$141,'Service shares'!$B13,'IND Balance'!$D$5:$D$141,"*"&'Service shares'!$A13)*J13 -> 8.5189378 | AP13: =SUMIFS('IND Balance'!J$5:J$141,'IND Balance'!$C$5:$C$141,'Service shares'!$B13,'IND Balance'!$D$5:$D$141,"*"&'Service shares'!$A13)*K13 -> 65.700263 | AQ13: =SUMIFS('IND Balance'!K$5:K$141,'IND Balance'!$C$5:$C$141,'Service shares'!$B13,'IND Balance'!$D$5:$D$141,"*"&'Service shares'!$A13)*L13 -> 0.58007295 | AR13: =SUMIFS('IND Balance'!L$5:L$141,'IND Balance'!$C$5:$C$141,'Service shares'!$B13,'IND Balance'!$D$5:$D$141,"*"&'Service shares'!$A13)*M13 -> 10.227721 | ... BN13: =SUMIFS('IND Balance'!AH$5:AH$141,'IND Balance'!$C$5:$C$141,'Service shares'!$B13,'IND Balance'!$D$5:$D$141,"*"&'Service shares'!$A13)*AI13 -> 0
A14: ELC | B14: IOI | C14: PRC | D14: 0.067729084 | F14: =$D14 -> 0.067729084 | G14: =$D14 -> 0.067729084 | H14: =$D14 -> 0.067729084 | I14: =$D14 -> 0.067729084 | J14: =$D14 -> 0.067729084 | K14: =$D14 -> 0.067729084 | L14: =$D14 -> 0.067729084 | M14: =$D14 -> 0.067729084 | ... AI14: =$D14 -> 0.067729084 | AK14: =SUMIFS('IND Balance'!E$5:E$141,'IND Balance'!$C$5:$C$141,'Service shares'!$B14,'IND Balance'!$D$5:$D$141,"*"&'Service shares'!$A14)*F14 -> 13.909814 | AL14: =SUMIFS('IND Balance'!F$5:F$141,'IND Balance'!$C$5:$C$141,'Service shares'!$B14,'IND Balance'!$D$5:$D$141,"*"&'Service shares'!$A14)*G14 -> 9.6745806 | AM14: =SUMIFS('IND Balance'!G$5:G$141,'IND Balance'!$C$5:$C$141,'Service shares'!$B14,'IND Balance'!$D$5:$D$141,"*"&'Service shares'!$A14)*H14 -> 3.5735474 | AN14: =SUMIFS('IND Balance'!H$5:H$141,'IND Balance'!$C$5:$C$141,'Service shares'!$B14,'IND Balance'!$D$5:$D$141,"*"&'Service shares'!$A14)*I14 -> 2.0668861 | AO14: =SUMIFS('IND Balance'!I$5:I$141,'IND Balance'!$C$5:$C$141,'Service shares'!$B14,'IND Balance'!$D$5:$D$141,"*"&'Service shares'!$A14)*J14 -> 11.140149 | AP14: =SUMIFS('IND Balance'!J$5:J$141,'IND Balance'!$C$5:$C$141,'Service shares'!$B14,'IND Balance'!$D$5:$D$141,"*"&'Service shares'!$A14)*K14 -> 85.915728 | AQ14: =SUMIFS('IND Balance'!K$5:K$141,'IND Balance'!$C$5:$C$141,'Service shares'!$B14,'IND Balance'!$D$5:$D$141,"*"&'Service shares'!$A14)*L14 -> 0.75855693 | AR14: =SUMIFS('IND Balance'!L$5:L$141,'IND Balance'!$C$5:$C$141,'Service shares'!$B14,'IND Balance'!$D$5:$D$141,"*"&'Service shares'!$A14)*M14 -> 13.374712 | ... BN14: =SUMIFS('IND Balance'!AH$5:AH$141,'IND Balance'!$C$5:$C$141,'Service shares'!$B14,'IND Balance'!$D$5:$D$141,"*"&'Service shares'!$A14)*AI14 -> 0
... A153: COA | B153: IIS | C153: OTP | D153: 0.74074074 | F153: =$D153 -> 0.74074074 | G153: =$D153 -> 0.74074074 | H153: =$D153 -> 0.74074074 | I153: =$D153 -> 0.74074074 | J153: =$D153 -> 0.74074074 | K153: =$D153 -> 0.74074074 | L153: =$D153 -> 0.74074074 | M153: =$D153 -> 0.74074074 | ... AI153: =$D153 -> 0.74074074 | AK153: =SUMIFS('IND Balance'!E$5:E$141,'IND Balance'!$C$5:$C$141,'Service shares'!$B153,'IND Balance'!$D$5:$D$141,"*"&'Service shares'!$A153)*F153 -> 0 | AL153: =SUMIFS('IND Balance'!F$5:F$141,'IND Balance'!$C$5:$C$141,'Service shares'!$B153,'IND Balance'!$D$5:$D$141,"*"&'Service shares'!$A153)*G153 -> 0 | AM153: =SUMIFS('IND Balance'!G$5:G$141,'IND Balance'!$C$5:$C$141,'Service shares'!$B153,'IND Balance'!$D$5:$D$141,"*"&'Service shares'!$A153)*H153 -> 0 | AN153: =SUMIFS('IND Balance'!H$5:H$141,'IND Balance'!$C$5:$C$141,'Service shares'!$B153,'IND Balance'!$D$5:$D$141,"*"&'Service shares'!$A153)*I153 -> 0 | AO153: =SUMIFS('IND Balance'!I$5:I$141,'IND Balance'!$C$5:$C$141,'Service shares'!$B153,'IND Balance'!$D$5:$D$141,"*"&'Service shares'!$A153)*J153 -> 0 | AP153: =SUMIFS('IND Balance'!J$5:J$141,'IND Balance'!$C$5:$C$141,'Service shares'!$B153,'IND Balance'!$D$5:$D$141,"*"&'Service shares'!$A153)*K153 -> 0 | AQ153: =SUMIFS('IND Balance'!K$5:K$141,'IND Balance'!$C$5:$C$141,'Service shares'!$B153,'IND Balance'!$D$5:$D$141,"*"&'Service shares'!$A153)*L153 -> 0 | AR153: =SUMIFS('IND Balance'!L$5:L$141,'IND Balance'!$C$5:$C$141,'Service shares'!$B153,'IND Balance'!$D$5:$D$141,"*"&'Service shares'!$A153)*M153 -> 0 | ... BN153: =SUMIFS('IND Balance'!AH$5:AH$141,'IND Balance'!$C$5:$C$141,'Service shares'!$B153,'IND Balance'!$D$5:$D$141,"*"&'Service shares'!$A153)*AI153 -> 0
A154: =A153 -> COA | B154: INF | C154: PRH | D154: 1 | F154: =$D154 -> 1 | G154: =$D154 -> 1 | H154: =$D154 -> 1 | I154: =$D154 -> 1 | J154: =$D154 -> 1 | K154: =$D154 -> 1 | L154: =$D154 -> 1 | M154: =$D154 -> 1 | ... AI154: =$D154 -> 1 | AK154: =SUMIFS('IND Balance'!E$5:E$141,'IND Balance'!$C$5:$C$141,'Service shares'!$B154,'IND Balance'!$D$5:$D$141,"*"&'Service shares'!$A154)*F154 -> 0.087566922 | AL154: =SUMIFS('IND Balance'!F$5:F$141,'IND Balance'!$C$5:$C$141,'Service shares'!$B154,'IND Balance'!$D$5:$D$141,"*"&'Service shares'!$A154)*G154 -> 0.01276974 | AM154: =SUMIFS('IND Balance'!G$5:G$141,'IND Balance'!$C$5:$C$141,'Service shares'!$B154,'IND Balance'!$D$5:$D$141,"*"&'Service shares'!$A154)*H154 -> 0 | AN154: =SUMIFS('IND Balance'!H$5:H$141,'IND Balance'!$C$5:$C$141,'Service shares'!$B154,'IND Balance'!$D$5:$D$141,"*"&'Service shares'!$A154)*I154 -> 64.917711 | AO154: =SUMIFS('IND Balance'!I$5:I$141,'IND Balance'!$C$5:$C$141,'Service shares'!$B154,'IND Balance'!$D$5:$D$141,"*"&'Service shares'!$A154)*J154 -> 1.3052391 | AP154: =SUMIFS('IND Balance'!J$5:J$141,'IND Balance'!$C$5:$C$141,'Service shares'!$B154,'IND Balance'!$D$5:$D$141,"*"&'Service shares'!$A154)*K154 -> 163.01094 | AQ154: =SUMIFS('IND Balance'!K$5:K$141,'IND Balance'!$C$5:$C$141,'Service shares'!$B154,'IND Balance'!$D$5:$D$141,"*"&'Service shares'!$A154)*L154 -> 61.821142 | AR154: =SUMIFS('IND Balance'!L$5:L$141,'IND Balance'!$C$5:$C$141,'Service shares'!$B154,'IND Balance'!$D$5:$D$141,"*"&'Service shares'!$A154)*M154 -> 26.965064 | ... BN154: =SUMIFS('IND Balance'!AH$5:AH$141,'IND Balance'!$C$5:$C$141,'Service shares'!$B154,'IND Balance'!$D$5:$D$141,"*"&'Service shares'!$A154)*AI154 -> 0
A155: =A154 -> COA | B155: IMC | C155: PRH | D155: 1 | F155: =$D155 -> 1 | G155: =$D155 -> 1 | H155: =$D155 -> 1 | I155: =$D155 -> 1 | J155: =$D155 -> 1 | K155: =$D155 -> 1 | L155: =$D155 -> 1 | M155: =$D155 -> 1 | ... AI155: =$D155 -> 1 | AK155: =SUMIFS('IND Balance'!E$5:E$141,'IND Balance'!$C$5:$C$141,'Service shares'!$B155,'IND Balance'!$D$5:$D$141,"*"&'Service shares'!$A155)*F155 -> 0 | AL155: =SUMIFS('IND Balance'!F$5:F$141,'IND Balance'!$C$5:$C$141,'Service shares'!$B155,'IND Balance'!$D$5:$D$141,"*"&'Service shares'!$A155)*G155 -> 1.8256374 | AM155: =SUMIFS('IND Balance'!G$5:G$141,'IND Balance'!$C$5:$C$141,'Service shares'!$B155,'IND Balance'!$D$5:$D$141,"*"&'Service shares'!$A155)*H155 -> 1.2458284 | AN155: =SUMIFS('IND Balance'!H$5:H$141,'IND Balance'!$C$5:$C$141,'Service shares'!$B155,'IND Balance'!$D$5:$D$141,"*"&'Service shares'!$A155)*I155 -> 18.20918 | AO155: =SUMIFS('IND Balance'!I$5:I$141,'IND Balance'!$C$5:$C$141,'Service shares'!$B155,'IND Balance'!$D$5:$D$141,"*"&'Service shares'!$A155)*J155 -> 0 | AP155: =SUMIFS('IND Balance'!J$5:J$141,'IND Balance'!$C$5:$C$141,'Service shares'!$B155,'IND Balance'!$D$5:$D$141,"*"&'Service shares'!$A155)*K155 -> 17.693526 | AQ155: =SUMIFS('IND Balance'!K$5:K$141,'IND Balance'!$C$5:$C$141,'Service shares'!$B155,'IND Balance'!$D$5:$D$141,"*"&'Service shares'!$A155)*L155 -> 4.0611332 | AR155: =SUMIFS('IND Balance'!L$5:L$141,'IND Balance'!$C$5:$C$141,'Service shares'!$B155,'IND Balance'!$D$5:$D$141,"*"&'Service shares'!$A155)*M155 -> 8.5354491 | ... BN155: =SUMIFS('IND Balance'!AH$5:AH$141,'IND Balance'!$C$5:$C$141,'Service shares'!$B155,'IND Balance'!$D$5:$D$141,"*"&'Service shares'!$A155)*AI155 -> 0
A156: =A155 -> COA | B156: ITM | C156: PRH | D156: 1 | F156: =$D156 -> 1 | G156: =$D156 -> 1 | H156: =$D156 -> 1 | I156: =$D156 -> 1 | J156: =$D156 -> 1 | K156: =$D156 -> 1 | L156: =$D156 -> 1 | M156: =$D156 -> 1 | ... AI156: =$D156 -> 1 | AK156: =SUMIFS('IND Balance'!E$5:E$141,'IND Balance'!$C$5:$C$141,'Service shares'!$B156,'IND Balance'!$D$5:$D$141,"*"&'Service shares'!$A156)*F156 -> 0 | AL156: =SUMIFS('IND Balance'!F$5:F$141,'IND Balance'!$C$5:$C$141,'Service shares'!$B156,'IND Balance'!$D$5:$D$141,"*"&'Service shares'!$A156)*G156 -> 0.076991065 | AM156: =SUMIFS('IND Balance'!G$5:G$141,'IND Balance'!$C$5:$C$141,'Service shares'!$B156,'IND Balance'!$D$5:$D$141,"*"&'Service shares'!$A156)*H156 -> 0 | AN156: =SUMIFS('IND Balance'!H$5:H$141,'IND Balance'!$C$5:$C$141,'Service shares'!$B156,'IND Balance'!$D$5:$D$141,"*"&'Service shares'!$A156)*I156 -> 1.2897982 | AO156: =SUMIFS('IND Balance'!I$5:I$141,'IND Balance'!$C$5:$C$141,'Service shares'!$B156,'IND Balance'!$D$5:$D$141,"*"&'Service shares'!$A156)*J156 -> 0.20447075 | AP156: =SUMIFS('IND Balance'!J$5:J$141,'IND Balance'!$C$5:$C$141,'Service shares'!$B156,'IND Balance'!$D$5:$D$141,"*"&'Service shares'!$A156)*K156 -> 0.72337018 | AQ156: =SUMIFS('IND Balance'!K$5:K$141,'IND Balance'!$C$5:$C$141,'Service shares'!$B156,'IND Balance'!$D$5:$D$141,"*"&'Service shares'!$A156)*L156 -> 0 | AR156: =SUMIFS('IND Balance'!L$5:L$141,'IND Balance'!$C$5:$C$141,'Service shares'!$B156,'IND Balance'!$D$5:$D$141,"*"&'Service shares'!$A156)*M156 -> 0 | ... BN156: =SUMIFS('IND Balance'!AH$5:AH$141,'IND Balance'!$C$5:$C$141,'Service shares'!$B156,'IND Balance'!$D$5:$D$141,"*"&'Service shares'!$A156)*AI156 -> 0
A157: OIL | B157: IFP | C157: STM | D157: 0.3 | F157: =$D157 -> 0.3 | G157: =$D157 -> 0.3 | H157: =$D157 -> 0.3 | I157: =$D157 -> 0.3 | J157: =$D157 -> 0.3 | K157: =$D157 -> 0.3 | L157: =$D157 -> 0.3 | M157: =$D157 -> 0.3 | ... AI157: =$D157 -> 0.3 | AK157: =SUMIFS('IND Balance'!E$5:E$141,'IND Balance'!$C$5:$C$141,'Service shares'!$B157,'IND Balance'!$D$5:$D$141,"*"&'Service shares'!$A157)*F157 -> 2.2268723 | AL157: =SUMIFS('IND Balance'!F$5:F$141,'IND Balance'!$C$5:$C$141,'Service shares'!$B157,'IND Balance'!$D$5:$D$141,"*"&'Service shares'!$A157)*G157 -> 3.5688191 | AM157: =SUMIFS('IND Balance'!G$5:G$141,'IND Balance'!$C$5:$C$141,'Service shares'!$B157,'IND Balance'!$D$5:$D$141,"*"&'Service shares'!$A157)*H157 -> 0.068042199 | AN157: =SUMIFS('IND Balance'!H$5:H$141,'IND Balance'!$C$5:$C$141,'Service shares'!$B157,'IND Balance'!$D$5:$D$141,"*"&'Service shares'!$A157)*I157 -> 0.94591116 | AO157: =SUMIFS('IND Balance'!I$5:I$141,'IND Balance'!$C$5:$C$141,'Service shares'!$B157,'IND Balance'!$D$5:$D$141,"*"&'Service shares'!$A157)*J157 -> 14.884168 | AP157: =SUMIFS('IND Balance'!J$5:J$141,'IND Balance'!$C$5:$C$141,'Service shares'!$B157,'IND Balance'!$D$5:$D$141,"*"&'Service shares'!$A157)*K157 -> 24.269814 | AQ157: =SUMIFS('IND Balance'!K$5:K$141,'IND Balance'!$C$5:$C$141,'Service shares'!$B157,'IND Balance'!$D$5:$D$141,"*"&'Service shares'!$A157)*L157 -> 1.5181241 | AR157: =SUMIFS('IND Balance'!L$5:L$141,'IND Balance'!$C$5:$C$141,'Service shares'!$B157,'IND Balance'!$D$5:$D$141,"*"&'Service shares'!$A157)*M157 -> 7.7089254 | ... BN157: =SUMIFS('IND Balance'!AH$5:AH$141,'IND Balance'!$C$5:$C$141,'Service shares'!$B157,'IND Balance'!$D$5:$D$141,"*"&'Service shares'!$A157)*AI157 -> 0
A158: OIL | B158: IFP | C158: SPC | D158: 0.1 | F158: =$D158 -> 0.1 | G158: =$D158 -> 0.1 | H158: =$D158 -> 0.1 | I158: =$D158 -> 0.1 | J158: =$D158 -> 0.1 | K158: =$D158 -> 0.1 | L158: =$D158 -> 0.1 | M158: =$D158 -> 0.1 | ... AI158: =$D158 -> 0.1 | AK158: =SUMIFS('IND Balance'!E$5:E$141,'IND Balance'!$C$5:$C$141,'Service shares'!$B158,'IND Balance'!$D$5:$D$141,"*"&'Service shares'!$A158)*F158 -> 0.74229075 | AL158: =SUMIFS('IND Balance'!F$5:F$141,'IND Balance'!$C$5:$C$141,'Service shares'!$B158,'IND Balance'!$D$5:$D$141,"*"&'Service shares'!$A158)*G158 -> 1.1896064 | AM158: =SUMIFS('IND Balance'!G$5:G$141,'IND Balance'!$C$5:$C$141,'Service shares'!$B158,'IND Balance'!$D$5:$D$141,"*"&'Service shares'!$A158)*H158 -> 0.022680733 | AN158: =SUMIFS('IND Balance'!H$5:H$141,'IND Balance'!$C$5:$C$141,'Service shares'!$B158,'IND Balance'!$D$5:$D$141,"*"&'Service shares'!$A158)*I158 -> 0.31530372 | AO158: =SUMIFS('IND Balance'!I$5:I$141,'IND Balance'!$C$5:$C$141,'Service shares'!$B158,'IND Balance'!$D$5:$D$141,"*"&'Service shares'!$A158)*J158 -> 4.9613894 | AP158: =SUMIFS('IND Balance'!J$5:J$141,'IND Balance'!$C$5:$C$141,'Service shares'!$B158,'IND Balance'!$D$5:$D$141,"*"&'Service shares'!$A158)*K158 -> 8.089938 | AQ158: =SUMIFS('IND Balance'!K$5:K$141,'IND Balance'!$C$5:$C$141,'Service shares'!$B158,'IND Balance'!$D$5:$D$141,"*"&'Service shares'!$A158)*L158 -> 0.50604135 | AR158: =SUMIFS('IND Balance'!L$5:L$141,'IND Balance'!$C$5:$C$141,'Service shares'!$B158,'IND Balance'!$D$5:$D$141,"*"&'Service shares'!$A158)*M158 -> 2.5696418 | ... BN158: =SUMIFS('IND Balance'!AH$5:AH$141,'IND Balance'!$C$5:$C$141,'Service shares'!$B158,'IND Balance'!$D$5:$D$141,"*"&'Service shares'!$A158)*AI158 -> 0
A159: OIL | B159: IFP | C159: OTH | D159: 0.6 | F159: =$D159 -> 0.6 | G159: =$D159 -> 0.6 | H159: =$D159 -> 0.6 | I159: =$D159 -> 0.6 | J159: =$D159 -> 0.6 | K159: =$D159 -> 0.6 | L159: =$D159 -> 0.6 | M159: =$D159 -> 0.6 | ... AI159: =$D159 -> 0.6 | AK159: =SUMIFS('IND Balance'!E$5:E$141,'IND Balance'!$C$5:$C$141,'Service shares'!$B159,'IND Balance'!$D$5:$D$141,"*"&'Service shares'!$A159)*F159 -> 4.4537445 | AL159: =SUMIFS('IND Balance'!F$5:F$141,'IND Balance'!$C$5:$C$141,'Service shares'!$B159,'IND Balance'!$D$5:$D$141,"*"&'Service shares'!$A159)*G159 -> 7.1376382 | AM159: =SUMIFS('IND Balance'!G$5:G$141,'IND Balance'!$C$5:$C$141,'Service shares'!$B159,'IND Balance'!$D$5:$D$141,"*"&'Service shares'!$A159)*H159 -> 0.1360844 | AN159: =SUMIFS('IND Balance'!H$5:H$141,'IND Balance'!$C$5:$C$141,'Service shares'!$B159,'IND Balance'!$D$5:$D$141,"*"&'Service shares'!$A159)*I159 -> 1.8918223 | AO159: =SUMIFS('IND Balance'!I$5:I$141,'IND Balance'!$C$5:$C$141,'Service shares'!$B159,'IND Balance'!$D$5:$D$141,"*"&'Service shares'!$A159)*J159 -> 29.768336 | AP159: =SUMIFS('IND Balance'!J$5:J$141,'IND Balance'!$C$5:$C$141,'Service shares'!$B159,'IND Balance'!$D$5:$D$141,"*"&'Service shares'!$A159)*K159 -> 48.539628 | AQ159: =SUMIFS('IND Balance'!K$5:K$141,'IND Balance'!$C$5:$C$141,'Service shares'!$B159,'IND Balance'!$D$5:$D$141,"*"&'Service shares'!$A159)*L159 -> 3.0362481 | AR159: =SUMIFS('IND Balance'!L$5:L$141,'IND Balance'!$C$5:$C$141,'Service shares'!$B159,'IND Balance'!$D$5:$D$141,"*"&'Service shares'!$A159)*M159 -> 15.417851 | ... BN159: =SUMIFS('IND Balance'!AH$5:AH$141,'IND Balance'!$C$5:$C$141,'Service shares'!$B159,'IND Balance'!$D$5:$D$141,"*"&'Service shares'!$A159)*AI159 -> 0
A160: OIL | B160: IOI | C160: MDR | D160: 0.1 | F160: =$D160 -> 0.1 | G160: =$D160 -> 0.1 | H160: =$D160 -> 0.1 | I160: =$D160 -> 0.1 | J160: =$D160 -> 0.1 | K160: =$D160 -> 0.1 | L160: =$D160 -> 0.1 | M160: =$D160 -> 0.1 | ... AI160: =$D160 -> 0.1 | AK160: =SUMIFS('IND Balance'!E$5:E$141,'IND Balance'!$C$5:$C$141,'Service shares'!$B160,'IND Balance'!$D$5:$D$141,"*"&'Service shares'!$A160)*F160 -> 18.40131 | AL160: =SUMIFS('IND Balance'!F$5:F$141,'IND Balance'!$C$5:$C$141,'Service shares'!$B160,'IND Balance'!$D$5:$D$141,"*"&'Service shares'!$A160)*G160 -> 20.303901 | AM160: =SUMIFS('IND Balance'!G$5:G$141,'IND Balance'!$C$5:$C$141,'Service shares'!$B160,'IND Balance'!$D$5:$D$141,"*"&'Service shares'!$A160)*H160 -> 5.8097439 | AN160: =SUMIFS('IND Balance'!H$5:H$141,'IND Balance'!$C$5:$C$141,'Service shares'!$B160,'IND Balance'!$D$5:$D$141,"*"&'Service shares'!$A160)*I160 -> 0.45228158 | AO160: =SUMIFS('IND Balance'!I$5:I$141,'IND Balance'!$C$5:$C$141,'Service shares'!$B160,'IND Balance'!$D$5:$D$141,"*"&'Service shares'!$A160)*J160 -> 7.0728542 | AP160: =SUMIFS('IND Balance'!J$5:J$141,'IND Balance'!$C$5:$C$141,'Service shares'!$B160,'IND Balance'!$D$5:$D$141,"*"&'Service shares'!$A160)*K160 -> 51.612223 | AQ160: =SUMIFS('IND Balance'!K$5:K$141,'IND Balance'!$C$5:$C$141,'Service shares'!$B160,'IND Balance'!$D$5:$D$141,"*"&'Service shares'!$A160)*L160 -> 1.2703086 | AR160: =SUMIFS('IND Balance'!L$5:L$141,'IND Balance'!$C$5:$C$141,'Service shares'!$B160,'IND Balance'!$D$5:$D$141,"*"&'Service shares'!$A160)*M160 -> 2.8976181 | ... BN160: =SUMIFS('IND Balance'!AH$5:AH$141,'IND Balance'!$C$5:$C$141,'Service shares'!$B160,'IND Balance'!$D$5:$D$141,"*"&'Service shares'!$A160)*AI160 -> 0
A161: OIL | B161: IOI | C161: OTH | D161: 0.9 | F161: =$D161 -> 0.9 | G161: =$D161 -> 0.9 | H161: =$D161 -> 0.9 | I161: =$D161 -> 0.9 | J161: =$D161 -> 0.9 | K161: =$D161 -> 0.9 | L161: =$D161 -> 0.9 | M161: =$D161 -> 0.9 | ... AI161: =$D161 -> 0.9 | AK161: =SUMIFS('IND Balance'!E$5:E$141,'IND Balance'!$C$5:$C$141,'Service shares'!$B161,'IND Balance'!$D$5:$D$141,"*"&'Service shares'!$A161)*F161 -> 165.61179 | AL161: =SUMIFS('IND Balance'!F$5:F$141,'IND Balance'!$C$5:$C$141,'Service shares'!$B161,'IND Balance'!$D$5:$D$141,"*"&'Service shares'!$A161)*G161 -> 182.73511 | AM161: =SUMIFS('IND Balance'!G$5:G$141,'IND Balance'!$C$5:$C$141,'Service shares'!$B161,'IND Balance'!$D$5:$D$141,"*"&'Service shares'!$A161)*H161 -> 52.287695 | AN161: =SUMIFS('IND Balance'!H$5:H$141,'IND Balance'!$C$5:$C$141,'Service shares'!$B161,'IND Balance'!$D$5:$D$141,"*"&'Service shares'!$A161)*I161 -> 4.0705342 | AO161: =SUMIFS('IND Balance'!I$5:I$141,'IND Balance'!$C$5:$C$141,'Service shares'!$B161,'IND Balance'!$D$5:$D$141,"*"&'Service shares'!$A161)*J161 -> 63.655688 | AP161: =SUMIFS('IND Balance'!J$5:J$141,'IND Balance'!$C$5:$C$141,'Service shares'!$B161,'IND Balance'!$D$5:$D$141,"*"&'Service shares'!$A161)*K161 -> 464.51 | AQ161: =SUMIFS('IND Balance'!K$5:K$141,'IND Balance'!$C$5:$C$141,'Service shares'!$B161,'IND Balance'!$D$5:$D$141,"*"&'Service shares'!$A161)*L161 -> 11.432778 | AR161: =SUMIFS('IND Balance'!L$5:L$141,'IND Balance'!$C$5:$C$141,'Service shares'!$B161,'IND Balance'!$D$5:$D$141,"*"&'Service shares'!$A161)*M161 -> 26.078563 | ... BN161: =SUMIFS('IND Balance'!AH$5:AH$141,'IND Balance'!$C$5:$C$141,'Service shares'!$B161,'IND Balance'!$D$5:$D$141,"*"&'Service shares'!$A161)*AI161 -> 0
