Workbook

Sheet Agri
A1: 0.041868 | B1: ktoe to PJ
B4: Sector | C4: Sub-Sector | D4: sectfuel | E4: Africa_north | F4: Africa_other | G4: Arg-Chi | H4: Asia_central | I4: Asia_east | J4: Asia_other | K4: Australia_NZ | L4: Brazil | M4: Canada | N4: China | O4: EU_north | P4: EU_northeast | Q4: EU_northwest | R4: EU_south | S4: EU_southeast | T4: EU_southwest | U4: Europe_other | V4: France | W4: Germany | X4: India | Y4: LatAm_other | Z4: Mexico | AA4: MidEast_other | AB4: Nor-Ice | AC4: Russia | AD4: SaudiArabia | AE4: SouthAfrica | AF4: UK | AG4: USA | AH4: ='RES balance'!AH4 -> \I: | AI4: WORLD
B5: AGR | C5: AGR | D5: AGRBIO | F5: 79.26822 | G5: 0.29791175 | H5: 0.013196794 | I5: 0.66043839 | J5: 16.314427 | L5: 160.81702 | O5: 18.656343 | P5: 29.1682 | Q5: 7.0199531 | R5: 2.7106474 | S5: 1.0680652 | T5: 3.3636877 | U5: 4.5694191 | V5: 12.894142 | W5: 8.6651394 | Y5: 16.35308 | AB5: 0.012773927 | AC5: 3.2356846 | AF5: 4.4099983 | AG5: 68.48785 | AI5: =SUM(E5:AH5) -> 437.9862
B6: AGR | C6: AGR | D6: AGRCOA | F6: 0.23369043 | H6: 4.1332215 | I6: 0.0009713376 | J6: 8.7414732 | K6: 2.095171 | M6: 0.86979514 | N6: 483.84096 | O6: 2.3309465 | P6: 31.152287 | Q6: 0.53943987 | R6: 0.025593908 | S6: 1.0946975 | U6: 0.44840628 | V6: 0.060419711 | Y6: 0.0036927576 | AC6: 2.1092722 | AE6: 10.527658 | AI6: =SUM(E6:AH6) -> 548.2077
B7: AGR | C7: AGR | D7: AGRELC | E7: 52.169044 | F7: 10.594886 | G7: 11.820391 | H7: 85.560214 | I7: 73.314954 | J7: 101.86568 | K7: 16.989071 | L7: 112.11527 | M7: 37.972798 | N7: 481.032 | O7: 15.57176 | P7: 17.602475 | Q7: 50.13165 | R7: 31.037121 | S7: 8.1794539 | T7: 23.423651 | U7: 59.877951 | V7: 30.525904 | W7: 18.468 | X7: 760.662 | Y7: 19.629104 | Z7: 47.271601 | AA7: 171.92891 | AB7: 8.6628576 | AC7: 70.950597 | AD7: 16.92014 | AE7: 21.547282 | AF7: 15.139197 | AG7: 270.74102 | AI7: =SUM(E7:AH7) -> 2641.705
B8: AGR | C8: AGR | D8: AGRGEO | H8: 0.04260069 | I8: 1.6982498 | K8: 0.44499822 | N8: 46.343086 | P8: 0.029998422 | Q8: 5.5639181 | R8: 2.1864181 | S8: 1.995768 | U8: 26.528105 | V8: 0.98114309 | AB8: 0.6925679 | AI8: =SUM(E8:AH8) -> 86.506854
B9: AGR | C9: AGR | D9: AGRHET | H9: 8.5703754 | J9: 0.22273776 | N9: 0.69880204 | O9: 2.4396274 | P9: 2.2580417 | Q9: 3.0276091 | R9: 0.62585961 | S9: 1.0561664 | U9: 14.786999 | V9: 0.77969102 | AB9: 1.7615417 | AC9: 106.42336 | AF9: 0.17113545 | AI9: =SUM(E9:AH9) -> 142.82194
B10: AGR | C10: AGR | D10: AGRKER | E10: 0.013640594 | F10: 0.1486942 | H10: 0.03800777 | I10: 24.973508 | J10: 0.10430994 | M10: 0.56940061 | N10: 8.8543912 | Q10: 0.26659868 | R10: 0.014448647 | S10: 0.04564868 | T10: 0.01006088 | U10: 0.044346586 | Y10: 0.11705037 | AA10: 0.45407521 | AE10: 5.2289657 | AF10: 13.018679 | AI10: =SUM(E10:AH10) -> 53.901826
B11: AGR | C11: AGR | D11: AGRLPG | E11: 5.8027122 | F11: 0.23913746 | G11: 6.940517 | H11: 0.71708161 | I11: 0.33886703 | J11: 0.086909594 | K11: 2.1275643 | L11: 0.86151784 | M11: 9.838398 | N11: 3.9289224 | O11: 0.39661138 | P11: 3.7831757 | Q11: 1.4889768 | R11: 2.5035389 | S11: 1.5317701 | T11: 2.6304157 | U11: 1.0847706 | V11: 13.038562 | W11: 9.4300008 | X11: 1.2156081 | Y11: 1.7547297 | Z11: 3.4647235 | AB11: 0.65333758 | AC11: 2.3607188 | AE11: 0.000795492 | AF11: 3.367661 | AG11: 36.231801 | AI11: =SUM(E11:AH11) -> 115.81882
B12: AGR | C12: AGR | D12: AGRNGA | E12: 2.581539 | G12: 1.0606755 | H12: 9.7361648 | I12: 0.28134877 | J12: 1.1640393 | K12: 2.4265479 | M12: 39.8023 | N12: 4.344701 | O12: 2.0392689 | P12: 13.862859 | Q12: 105.02481 | R12: 6.1507693 | S12: 11.19243 | T12: 8.5300356 | U12: 16.575721 | V12: 9.4594424 | W12: 34.262301 | X12: 7.2183614 | Y12: 0.37049831 | AA12: 80.354389 | AB12: 0.56379449 | AC12: 51.654884 | AF12: 3.6518986 | AG12: 62.218766 | AI12: =SUM(E12:AH12) -> 474.52755
B13: AGR | C13: AGR | D13: AGROIL | E13: 85.922255 | F13: 50.344306 | G13: 155.67478 | H13: 35.06831 | I13: 202.6196 | J13: 446.46422 | K13: 96.929411 | L13: 257.23271 | M13: 204.8184 | N13: 739.59968 | O13: 44.615458 | P13: 132.89376 | Q13: 46.42364 | R13: 91.753772 | S13: 46.51467 | T13: 102.44187 | U13: 221.81479 | V13: 114.75069 | W13: 79.782999 | X13: 451.90598 | Y13: 47.082245 | Z13: 125.4927 | AA13: 120.84687 | AB13: 22.562117 | AC13: 139.26309 | AE13: 43.620854 | AF13: 17.769646 | AG13: 459.66965 | AI13: =SUM(E13:AH13) -> 4583.8785
D16: ~FI_T: Share-I~UP | AL16: ~FI_T: Share-I~UP~2050
A17: process | B17: attribute | C17: Comm-IN | D17: Comm-OUT | E17: =E4 -> Africa_north | F17: =F4 -> Africa_other | G17: =G4 -> Arg-Chi | H17: =H4 -> Asia_central | I17: =I4 -> Asia_east | J17: =J4 -> Asia_other | K17: =K4 -> Australia_NZ | L17: =L4 -> Brazil | ... AH17: =AH4 -> \I: | AI17: EFF | AK17: process | AL17: commodity | AM17: =E17 -> Africa_north | AN17: =F17 -> Africa_other | AO17: =G17 -> Arg-Chi | AP17: =H17 -> Asia_central | AQ17: =I17 -> Asia_east | AR17: =J17 -> Asia_other | AS17: =K17 -> Australia_NZ | AT17: =L17 -> Brazil | ... BP17: =AH17 -> \I: | BQ17: 0 | BR17: LimType
A18: AGR000 | C18: =D5 -> AGRBIO | E18: =IFERROR(E5/SUM(E$5:E$13),0) -> 0 | F18: =IFERROR(F5/SUM(F$5:F$13),0) -> 0.56286885 | G18: =IFERROR(G5/SUM(G$5:G$13),0) -> 0.0016946613 | H18: =IFERROR(H5/SUM(H$5:H$13),0) -> 9.1721361e-05 | I18: =IFERROR(I5/SUM(I$5:I$13),0) -> 0.0021732959 | J18: =IFERROR(J5/SUM(J$5:J$13),0) -> 0.028374704 | K18: =IFERROR(K5/SUM(K$5:K$13),0) -> 0 | L18: =IFERROR(L5/SUM(L$5:L$13),0) -> 0.30284179 | ... AH18: =IFERROR(AH5/SUM(AH$5:AH$13),0) -> 0 | AK18: AGR000 | AL18: =C18 -> AGRBIO | AM18: =MAX(AVERAGE($E18:$AC18),E18) -> 0.066949954 | AN18: =MAX(AVERAGE($E18:$AC18),F18) -> 0.56286885 | AO18: =MAX(AVERAGE($E18:$AC18),G18) -> 0.066949954 | AP18: =MAX(AVERAGE($E18:$AC18),H18) -> 0.066949954 | AQ18: =MAX(AVERAGE($E18:$AC18),I18) -> 0.066949954 | AR18: =MAX(AVERAGE($E18:$AC18),J18) -> 0.066949954 | AS18: =MAX(AVERAGE($E18:$AC18),K18) -> 0.066949954 | AT18: =MAX(AVERAGE($E18:$AC18),L18) -> 0.30284179 | ... BP18: =MAX(AVERAGE($E18:$AC18),AH18) -> 0.066949954 | BQ18: 3
C19: =D6 -> AGRCOA | E19: =IFERROR(E6/SUM(E$5:E$13),0) -> 0 | F19: =IFERROR(F6/SUM(F$5:F$13),0) -> 0.0016593922 | G19: =IFERROR(G6/SUM(G$5:G$13),0) -> 0 | H19: =IFERROR(H6/SUM(H$5:H$13),0) -> 0.028727031 | I19: =IFERROR(I6/SUM(I$5:I$13),0) -> 3.1963678e-06 | J19: =IFERROR(J6/SUM(J$5:J$13),0) -> 0.015203519 | K19: =IFERROR(K6/SUM(K$5:K$13),0) -> 0.017313637 | L19: =IFERROR(L6/SUM(L$5:L$13),0) -> 0 | ... AH19: =IFERROR(AH6/SUM(AH$5:AH$13),0) -> 0 | AL19: =C19 -> AGRCOA | AM19: =E19*$BT19 -> 0 | AN19: =F19*$BT19 -> 0.00082969608 | AO19: =G19*$BT19 -> 0 | AP19: =H19*$BT19 -> 0.014363516 | AQ19: =I19*$BT19 -> 1.5981839e-06 | AR19: =J19*$BT19 -> 0.0076017597 | AS19: =K19*$BT19 -> 0.0086568183 | AT19: =L19*$BT19 -> 0 | ... BP19: =AH19*$BT19 -> 0 | BQ19: 3 | BT19: 0.5
C20: =D7 -> AGRELC | E20: =IFERROR(E7/SUM(E$5:E$13),0) -> 0.35612896 | F20: =IFERROR(F7/SUM(F$5:F$13),0) -> 0.075232309 | G20: =IFERROR(G7/SUM(G$5:G$13),0) -> 0.06723991 | H20: =IFERROR(H7/SUM(H$5:H$13),0) -> 0.59466712 | I20: =IFERROR(I7/SUM(I$5:I$13),0) -> 0.24125655 | J20: =IFERROR(J7/SUM(J$5:J$13),0) -> 0.17716886 | K20: =IFERROR(K7/SUM(K$5:K$13),0) -> 0.14039074 | L20: =IFERROR(L7/SUM(L$5:L$13),0) -> 0.21112932 | ... AH20: =IFERROR(AH7/SUM(AH$5:AH$13),0) -> 0 | AL20: =C20 -> AGRELC | AM20: =MAX(E20:S20)*$BT20 -> 0.65413384 | AN20: =AM20 -> 0.65413384 | AO20: =AN20 -> 0.65413384 | AP20: =AO20 -> 0.65413384 | AQ20: =AP20 -> 0.65413384 | AR20: =AQ20 -> 0.65413384 | AS20: =AR20 -> 0.65413384 | AT20: =AS20 -> 0.65413384 | AU20: =AT20 -> 0.65413384 | ... BP20: =BO20 -> 0.65413384 | BQ20: 3 | BT20: 1.1
C21: =D8 -> AGRGEO | E21: =IFERROR(E8/SUM(E$5:E$13),0) -> 0 | F21: =IFERROR(F8/SUM(F$5:F$13),0) -> 0 | G21: =IFERROR(G8/SUM(G$5:G$13),0) -> 0 | H21: =IFERROR(H8/SUM(H$5:H$13),0) -> 0.00029608656 | I21: =IFERROR(I8/SUM(I$5:I$13),0) -> 0.0055884082 | J21: =IFERROR(J8/SUM(J$5:J$13),0) -> 0 | K21: =IFERROR(K8/SUM(K$5:K$13),0) -> 0.0036772834 | L21: =IFERROR(L8/SUM(L$5:L$13),0) -> 0 | ... AH21: =IFERROR(AH8/SUM(AH$5:AH$13),0) -> 0 | AL21: =C21 -> AGRGEO | AM21: =E21*$BT21 -> 0 | AN21: =F21*$BT21 -> 0 | AO21: =G21*$BT21 -> 0 | AP21: =H21*$BT21 -> 0.00029608656 | AQ21: =I21*$BT21 -> 0.0055884082 | AR21: =J21*$BT21 -> 0 | AS21: =K21*$BT21 -> 0.0036772834 | AT21: =L21*$BT21 -> 0 | ... BP21: =AH21*$BT21 -> 0 | BQ21: 3 | BT21: 1
C22: =D9 -> AGRHET | E22: =IFERROR(E9/SUM(E$5:E$13),0) -> 0 | F22: =IFERROR(F9/SUM(F$5:F$13),0) -> 0 | G22: =IFERROR(G9/SUM(G$5:G$13),0) -> 0 | H22: =IFERROR(H9/SUM(H$5:H$13),0) -> 0.059566477 | I22: =IFERROR(I9/SUM(I$5:I$13),0) -> 0 | J22: =IFERROR(J9/SUM(J$5:J$13),0) -> 0.00038739441 | K22: =IFERROR(K9/SUM(K$5:K$13),0) -> 0 | L22: =IFERROR(L9/SUM(L$5:L$13),0) -> 0 | ... AH22: =IFERROR(AH9/SUM(AH$5:AH$13),0) -> 0 | AL22: =C22 -> AGRHET | AM22: =MAX(E22:Z22) -> 0.059566477 | AN22: =AM22 -> 0.059566477 | AO22: =AN22 -> 0.059566477 | AP22: =AO22 -> 0.059566477 | AQ22: =AP22 -> 0.059566477 | AR22: =AQ22 -> 0.059566477 | AS22: =AR22 -> 0.059566477 | AT22: =AS22 -> 0.059566477 | AU22: =AT22 -> 0.059566477 | ... BP22: =BO22 -> 0.059566477 | BQ22: 3 | BT22: 1.5
C23: =D10 -> AGRKER | E23: =IFERROR(E10/SUM(E$5:E$13),0) -> 9.311673e-05 | F23: =IFERROR(F10/SUM(F$5:F$13),0) -> 0.0010558498 | G23: =IFERROR(G10/SUM(G$5:G$13),0) -> 0 | H23: =IFERROR(H10/SUM(H$5:H$13),0) -> 0.0002641645 | I23: =IFERROR(I10/SUM(I$5:I$13),0) -> 0.082179993 | J23: =IFERROR(J10/SUM(J$5:J$13),0) -> 0.00018142001 | K23: =IFERROR(K10/SUM(K$5:K$13),0) -> 0 | L23: =IFERROR(L10/SUM(L$5:L$13),0) -> 0 | ... AH23: =IFERROR(AH10/SUM(AH$5:AH$13),0) -> 0 | AL23: =C23 -> AGRKER | AM23: =E23*$BT23 -> 9.311673e-05 | AN23: =F23*$BT23 -> 0.0010558498 | AO23: =G23*$BT23 -> 0 | AP23: =H23*$BT23 -> 0.0002641645 | AQ23: =I23*$BT23 -> 0.082179993 | AR23: =J23*$BT23 -> 0.00018142001 | AS23: =K23*$BT23 -> 0 | AT23: =L23*$BT23 -> 0 | ... BP23: =AH23*$BT23 -> 0 | BQ23: 3 | BT23: 1
C24: =D11 -> AGRLPG | E24: =IFERROR(E11/SUM(E$5:E$13),0) -> 0.03961188 | F24: =IFERROR(F11/SUM(F$5:F$13),0) -> 0.0016980705 | G24: =IFERROR(G11/SUM(G$5:G$13),0) -> 0.039480904 | H24: =IFERROR(H11/SUM(H$5:H$13),0) -> 0.0049839153 | I24: =IFERROR(I11/SUM(I$5:I$13),0) -> 0.0011151053 | J24: =IFERROR(J11/SUM(J$5:J$13),0) -> 0.00015115664 | K24: =IFERROR(K11/SUM(K$5:K$13),0) -> 0.017581321 | L24: =IFERROR(L11/SUM(L$5:L$13),0) -> 0.0016223631 | ... AH24: =IFERROR(AH11/SUM(AH$5:AH$13),0) -> 0 | AL24: =C24 -> AGRLPG | AM24: =E24*$BT24 -> 0.03961188 | AN24: =F24*$BT24 -> 0.0016980705 | AO24: =G24*$BT24 -> 0.039480904 | AP24: =H24*$BT24 -> 0.0049839153 | AQ24: =I24*$BT24 -> 0.0011151053 | AR24: =J24*$BT24 -> 0.00015115664 | AS24: =K24*$BT24 -> 0.017581321 | AT24: =L24*$BT24 -> 0.0016223631 | ... BP24: =AH24*$BT24 -> 0 | BQ24: 3 | BT24: 1
C25: =D12 -> AGRNGA | E25: =IFERROR(E12/SUM(E$5:E$13),0) -> 0.017622727 | F25: =IFERROR(F12/SUM(F$5:F$13),0) -> 0 | G25: =IFERROR(G12/SUM(G$5:G$13),0) -> 0.0060336181 | H25: =IFERROR(H12/SUM(H$5:H$13),0) -> 0.067669035 | I25: =IFERROR(I12/SUM(I$5:I$13),0) -> 0.00092583068 | J25: =IFERROR(J12/SUM(J$5:J$13),0) -> 0.0020245436 | K25: =IFERROR(K12/SUM(K$5:K$13),0) -> 0.020051999 | L25: =IFERROR(L12/SUM(L$5:L$13),0) -> 0 | ... AH25: =IFERROR(AH12/SUM(AH$5:AH$13),0) -> 0 | AL25: =C25 -> AGRNGA | AM25: =MAX(E25:Z25) -> 0.47850216 | AN25: =AM25 -> 0.47850216 | AO25: =AN25 -> 0.47850216 | AP25: =AO25 -> 0.47850216 | AQ25: =AP25 -> 0.47850216 | AR25: =AQ25 -> 0.47850216 | AS25: =AR25 -> 0.47850216 | AT25: =AS25 -> 0.47850216 | AU25: =AT25 -> 0.47850216 | ... BP25: =BO25 -> 0.47850216 | BQ25: 3
C26: =D13 -> AGROIL | E26: =IFERROR(E13/SUM(E$5:E$13),0) -> 0.58654331 | F26: =IFERROR(F13/SUM(F$5:F$13),0) -> 0.35748553 | G26: =IFERROR(G13/SUM(G$5:G$13),0) -> 0.88555091 | H26: =IFERROR(H13/SUM(H$5:H$13),0) -> 0.24373444 | I26: =IFERROR(I13/SUM(I$5:I$13),0) -> 0.66675762 | J26: =IFERROR(J13/SUM(J$5:J$13),0) -> 0.77650841 | K26: =IFERROR(K13/SUM(K$5:K$13),0) -> 0.80098502 | L26: =IFERROR(L13/SUM(L$5:L$13),0) -> 0.48440653 | ... AH26: =IFERROR(AH13/SUM(AH$5:AH$13),0) -> 0 | AL26: =C26 -> AGROIL | AM26: =E26*$BT26 -> 0.58654331 | AN26: =F26*$BT26 -> 0.35748553 | AO26: =G26*$BT26 -> 0.88555091 | AP26: =H26*$BT26 -> 0.24373444 | AQ26: =I26*$BT26 -> 0.66675762 | AR26: =J26*$BT26 -> 0.77650841 | AS26: =K26*$BT26 -> 0.80098502 | AT26: =L26*$BT26 -> 0.48440653 | ... BP26: =AH26*$BT26 -> 0 | BQ26: 3 | BT26: 1
B27: Demand | D27: AGR | E27: =SUM(E5:E13) -> 146.48919 | F27: =SUM(F5:F13) -> 140.82893 | G27: =SUM(G5:G13) -> 175.79428 | H27: =SUM(H5:H13) -> 143.87917 | I27: =SUM(I5:I13) -> 303.88793 | J27: =SUM(J5:J13) -> 574.96379 | K27: =SUM(K5:K13) -> 121.01276 | L27: =SUM(L5:L13) -> 531.02651 | ... AH27: =SUM(AH5:AH13) -> 0 | AI27: 1 | AL27: =AL20 -> AGRELC | AM27: =E20 -> 0.35612896 | AN27: =F20 -> 0.075232309 | AO27: =G20 -> 0.06723991 | AP27: =H20 -> 0.59466712 | AQ27: =I20 -> 0.24125655 | AR27: =J20 -> 0.17716886 | AS27: =K20 -> 0.14039074 | AT27: =L20 -> 0.21112932 | ... BP27: =AH20 -> 0 | BR27: LO
AM29: =SUM(AM18:AM26) -> 1.8854007 | AN29: =SUM(AN18:AN26) -> 2.1161405 | AO29: =SUM(AO18:AO26) -> 2.1841842 | AP29: =SUM(AP18:AP26) -> 1.5227946 | AQ29: =SUM(AQ18:AQ26) -> 2.0147952 | AR29: =SUM(AR18:AR26) -> 2.0435952 | AS29: =SUM(AS18:AS26) -> 2.0900529 | AT29: =SUM(AT18:AT26) -> 1.9810732 | ... BP29: =SUM(BP18:BP26) -> 1.2591524
C30: ~FI_Process
C31: Region | D31: Sets | E31: TechName | F31: TechDesc | G31: Tact | H31: Tcap | I31: Tslvl | J31: PrimaryCG | K31: Vintage
D32: DMD | E32: =A18 -> AGR000 | G32: PJ | H32: PJ-a

Sheet COM balance
A1: 0.041868 | B1: ktoe to PJ
B4: Sector | C4: Sub-Sector | D4: sectfuel | E4: Africa_north | F4: Africa_other | G4: Arg-Chi | H4: Asia_central | I4: Asia_east | J4: Asia_other | K4: Australia_NZ | L4: Brazil | M4: Canada | N4: China | O4: EU_north | P4: EU_northeast | Q4: EU_northwest | R4: EU_south | S4: EU_southeast | T4: EU_southwest | U4: Europe_other | V4: France | W4: Germany | X4: India | Y4: LatAm_other | Z4: Mexico | AA4: MidEast_other | AB4: Nor-Ice | AC4: Russia | AD4: SaudiArabia | AE4: SouthAfrica | AF4: UK | AG4: USA | AH4: \I: | AI4: ='RES balance'!AI4 -> WORLD
B5: COM | C5: COM | D5: COMBIO | E5: 28.176662 | F5: 321.20957 | G5: 6.9543083 | H5: 1.1963404 | I5: 100.12366 | J5: 68.929792 | K5: 0.15499952 | L5: 6.9024045 | N5: 0.1000394 | O5: 9.2209623 | P5: 19.299678 | Q5: 10.070929 | R5: 3.4630656 | S5: 10.852047 | T5: 6.4082407 | U5: 22.028107 | V5: 17.29472 | W5: 65.546669 | X5: 109.744 | Y5: 25.112368 | AA5: 10.996697 | AB5: 1.9782421 | AC5: 47.97979 | AF5: 9.209997 | AG5: 87.447745 | AI5: =SUM(E5:AH5) -> 990.40103 | AJ5: 1 | AM5: Natural Gas | AN5: COMNGA
B6: COM | C6: COM | D6: COMCOA | F6: 0.12073475 | H6: 32.991858 | I6: 5.1861473 | J6: 17.741511 | K6: 1.3771976 | N6: 512.81628 | O6: 0.10440204 | P6: 28.420714 | Q6: 0.14732512 | S6: 0.23981572 | U6: 146.05078 | V6: 1.4600209 | W6: 0.076991065 | X6: 201.2905 | Y6: 0.0004103064 | AB6: 0.003935592 | AC6: 30.837603 | AE6: 53.154231 | AF6: 0.65709733 | AG6: 15.822403 | AI6: =SUM(E6:AH6) -> 1048.5 | AM6: Distallate | AN6: COMOIL
B7: COM | C7: COM | D7: COMELC | E7: 191.40926 | F7: 117.99994 | G7: 156.29172 | H7: 97.654401 | I7: 1728.6862 | J7: 1166.1091 | K7: 290.91896 | L7: 507.75191 | M7: 544.8456 | N7: 1754.3689 | O7: 199.17714 | P7: 337.61117 | Q7: 263.45368 | R7: 397.40658 | S7: 128.06664 | T7: 327.85102 | U7: 490.53559 | V7: 491.79267 | W7: 467.9064 | X7: 409.17417 | Y7: 321.67636 | Z7: 103.3794 | AA7: 557.58492 | AB7: 99.201775 | AC7: 550.32804 | AD7: 440.62039 | AE7: 133.58737 | AF7: 324.43428 | AG7: 4910.4737 | AI7: =SUM(E7:AH7) -> 17510.297 | AM7: Heavy
B8: COM | C8: COM | D8: COMGEO | H8: 0.37200137 | I8: 8.5803107 | K8: 2.37778 | N8: 149.18138 | P8: 0.7664691 | R8: 3.616068 | S8: 4.0195666 | T8: 0.07619976 | U8: 0.12929257 | V8: 0.70015019 | W8: 2.3300003 | Y8: 0.10240075 | AB8: 0.25699834 | AF8: 0.016998408 | AI8: =SUM(E8:AH8) -> 172.52561 | AM8: Kerosene | AN8: COMKER
B9: COM | C9: COM | D9: COMHET | H9: 144.25463 | I9: 34.903045 | J9: 15.688861 | M9: 0.29199999 | N9: 138.4732 | O9: 128.08354 | P9: 112.67439 | Q9: 15.421098 | R9: 12.413473 | S9: 22.328477 | T9: 0.99962362 | U9: 122.94035 | V9: 33.50902 | W9: 58.194 | AB9: 27.786134 | AC9: 791.3496 | AF9: 12.561652 | AG9: 53.01224 | AI9: =SUM(E9:AH9) -> 1724.8853 | AM9: Coal | AN9: COMCOA
B10: COM | C10: COM | D10: COMKER | F10: 1.1534843 | G10: 0.04499554 | H10: 0.043668324 | I10: 151.63328 | J10: 9.8498782 | K10: 0.0006866352 | M10: 15.417598 | N10: 127.41378 | O10: 0.034143354 | P10: 0.0014193252 | Q10: 3.559542 | R10: 0.10083908 | S10: 0.0127823 | T10: 8.79228e-05 | X10: 3.7886981 | Y10: 0.3047488 | AA10: 3.0312223 | AB10: 0.0006866352 | AE10: 3.0335543 | AF10: 34.142002 | AG10: 0.87599998 | AI10: =SUM(E10:AH10) -> 354.4431 | AM10: LPG (called propane in nrc) | AN10: COMLPG
B11: COM | C11: COM | D11: COMLPG | E11: 6.3671389 | F11: 15.51134 | G11: 17.510839 | H11: 1.8470947 | I11: 93.531065 | J11: 138.05175 | K11: 2.2714772 | L11: 27.314365 | M11: 35.995301 | N11: 85.012459 | O11: 0.90449952 | P11: 4.6151808 | Q11: 8.4816194 | R11: 22.324214 | S11: 2.7636146 | T11: 11.45354 | U11: 29.125956 | V11: 13.773643 | W11: 8.3260003 | X11: 123.66112 | Y11: 27.114081 | Z11: 60.515526 | AA11: 11.134816 | AB11: 1.2325227 | AC11: 0.98532151 | AE11: 1.5067875 | AF11: 16.31804 | AG11: 69.2945 | AI11: =SUM(E11:AH11) -> 836.94381 | AM11: Bioliquid
B12: COM | C12: COM | D12: COMNGA | E12: 21.332822 | F12: 0.06708091 | G12: 57.223508 | H12: 393.38425 | I12: 552.5331 | J12: 60.44489 | K12: 61.790528 | L12: 6.1559735 | M12: 592.5977 | N12: 532.5603 | O12: 14.674072 | P12: 152.51479 | Q12: 220.56283 | R12: 304.83331 | S12: 92.445457 | T12: 94.010713 | U12: 234.71469 | V12: 255.70848 | W12: 413.25846 | X12: 97.295651 | Y12: 36.30134 | Z12: 9.8658006 | AA12: 540.80095 | AB12: 2.9001419 | AC12: 236.07469 | AE12: 1.1105989 | AF12: 267.0443 | AG12: 3465.7148 | AI12: =SUM(E12:AH12) -> 8717.9212 | AM12: Biomass solid | AN12: COMBIO
B13: COM | C13: COM | D13: COMOIL | E13: 4.6778614 | F13: 41.495149 | G13: 24.803884 | H13: 25.955179 | I13: 262.69809 | J13: 149.84712 | K13: 31.706904 | L13: 2.1747579 | M13: 8.2331998 | N13: 436.50623 | O13: 20.653262 | P13: 23.343072 | Q13: 44.417313 | R13: 7.4745014 | S13: 8.5805326 | T13: 47.118599 | U13: 52.493177 | V13: 85.606788 | W13: 131.4542 | Y13: 29.805611 | Z13: 1.3349989 | AA13: 41.823184 | AB13: 11.885392 | AC13: 60.84599 | AE13: 2.4958687 | AF13: 38.689139 | AG13: 390.01343 | AI13: =SUM(E13:AH13) -> 1986.1334 | AM13: Biogas
B14: COM | C14: COM | D14: COMSTH | E14: 0.11069899 | H14: 0.30489115 | I14: 1.6861709 | J14: 0.53710782 | K14: 0.47100663 | N14: 97.632002 | O14: 0.091649052 | P14: 3.0579089 | Q14: 0.30587086 | R14: 2.802556 | S14: 0.84109463 | T14: 3.6913969 | U14: 0.63914433 | V14: 0.56816969 | W14: 1.2639991 | X14: 4.1642583 | Y14: 0.5919884 | Z14: 5.175002 | AA14: 2.9220473 | AF14: 0.71899916 | AG14: 75.532556 | AI14: =SUM(E14:AH14) -> 203.10852 | AM14: Biomass waste
AM15: Electricity | AN15: COMELC
AM16: Heat | AN16: COMHET
AM17: Geothermal | AN17: COMGEO
B18: elec | C18: 3527 | D18: =C18*$A$1 -> 147.66844 | AM18: Solar | AN18: COMSTH
B19: gas | C19: 4390 | D19: =C19*$A$1 -> 183.80052
B20: oil | C20: =5913+74 -> 5987 | D20: =C20*$A$1 -> 250.66372
B21: kerosene | C21: 3 | D21: =C21*$A$1 -> 0.125604
E27: =SUM(E5:E25) -> 252.07445 | F27: =SUM(F5:F25) -> 497.5573 | G27: =SUM(G5:G25) -> 262.82925 | H27: =SUM(H5:H25) -> 698.00431 | I27: =SUM(I5:I25) -> 2939.561 | J27: =SUM(J5:J25) -> 1627.2 | K27: =SUM(K5:K25) -> 391.06954 | L27: =SUM(L5:L25) -> 550.29941 | ... AI27: =SUM(AI5:AI25) -> 33545.159
E28: =SUM('COM Assumptions'!AK3:AK61) -> 252.07445 | F28: =SUM('COM Assumptions'!AL3:AL61) -> 497.5573 | G28: =SUM('COM Assumptions'!AM3:AM61) -> 262.82925 | H28: =SUM('COM Assumptions'!AN3:AN61) -> 698.00431 | I28: =SUM('COM Assumptions'!AO3:AO61) -> 2939.561 | J28: =SUM('COM Assumptions'!AP3:AP61) -> 1627.2 | K28: =SUM('COM Assumptions'!AQ3:AQ61) -> 391.06954 | L28: =SUM('COM Assumptions'!AR3:AR61) -> 550.29941 | ... AH28: =SUM('COM Assumptions'!BN3:BN61) -> 0 | AI28: =SUM(E28:AH28) -> 33545.159
E29: =SUM('COM Assumptions'!E81:E127) -> 252.07445 | F29: =SUM('COM Assumptions'!F81:F127) -> 497.5573 | G29: =SUM('COM Assumptions'!G81:G127) -> 262.82925 | H29: =SUM('COM Assumptions'!H81:H127) -> 698.00431 | I29: =SUM('COM Assumptions'!I81:I127) -> 2939.561 | J29: =SUM('COM Assumptions'!J81:J127) -> 1627.2 | K29: =SUM('COM Assumptions'!K81:K127) -> 391.06954 | L29: =SUM('COM Assumptions'!L81:L127) -> 550.29941 | ... AH29: =SUM('COM Assumptions'!AH81:AH127) -> 0 | AI29: =SUM(E29:AH29) -> 33545.159

Sheet RES balance
A1: 0.041868 | B1: ktoe to PJ
B4: Sector | C4: Sub-Sector | D4: sectfuel | E4: Africa_north | F4: Africa_other | G4: Arg-Chi | H4: Asia_central | I4: Asia_east | J4: Asia_other | K4: Australia_NZ | L4: Brazil | M4: Canada | N4: China | O4: EU_north | P4: EU_northeast | Q4: EU_northwest | R4: EU_south | S4: EU_southeast | T4: EU_southwest | U4: Europe_other | V4: France | W4: Germany | X4: India | Y4: LatAm_other | Z4: Mexico | AA4: MidEast_other | AB4: Nor-Ice | AC4: Russia | AD4: SaudiArabia | AE4: SouthAfrica | AF4: UK | AG4: USA | AH4: \I: | AI4: WORLD
B5: RES | C5: RES | D5: RESBIO | E5: 133.12266 | F5: 11247.992 | G5: 88.826048 | H5: 15.907001 | I5: 5.8054546 | J5: 4005.889 | K5: 56.444926 | L5: 313.3952 | M5: 113.333 | N5: 3073.0708 | O5: 119.53685 | P5: 455.47956 | Q5: 41.798043 | R5: 290.91939 | S5: 269.33057 | T5: 108.76853 | U5: 320.34311 | V5: 269.83339 | W5: 257.0741 | X5: 4116.891 | Y5: 793.14386 | Z5: 247.758 | AA5: 18.147505 | AB5: 19.519247 | AC5: 43.713575 | AD5: 0.3253018 | AE5: 127.968 | AF5: 27.723001 | AG5: 545.53772 | AI5: =SUM(E5:AH5) -> 27127.596 | AL5: Biogas
B6: RES | C6: RES | D6: RESCOA | F6: 0.15049871 | H6: 199.76687 | I6: 12.476517 | J6: 87.196189 | K6: 0.27486342 | N6: 1378.6823 | O6: 0.15659888 | P6: 239.71549 | Q6: 16.416166 | R6: 0.1426987 | S6: 9.0604738 | T6: 2.7185018 | U6: 85.054222 | V6: 1.0237521 | W6: 14.460713 | X6: 122.92897 | Y6: 2.7625009 | AA6: 0.36119942 | AC6: 71.524553 | AE6: 107.34506 | AF6: 19.105089 | AI6: =SUM(E6:AH6) -> 2371.3232 | AL6: Bioliquid
B7: RES | C7: RES | D7: RESELC | E7: 411.00377 | F7: 276.40706 | G7: 204.36419 | H7: 205.82424 | I7: 1150.1278 | J7: 1652.9514 | K7: 256.9853 | L7: 513.25843 | M7: 625.0608 | N7: 3872.335 | O7: 275.92796 | P7: 270.25826 | Q7: 182.92272 | R7: 308.14358 | S7: 162.25537 | T7: 310.33569 | U7: 529.60729 | V7: 574.99948 | W7: 455.5404 | X7: 1138.887 | Y7: 410.03142 | Z7: 232.1496 | AA7: 963.53739 | AB7: 147.39991 | AC7: 579.16008 | AD7: 462.6144 | AE7: 175.19082 | AF7: 373.76952 | AG7: 5171.5757 | AI7: =SUM(E7:AH7) -> 21892.625 | AL7: Biomass solid | AM7: RESBIO
B8: RES | C8: RES | D8: RESGEO | H8: 0.26520029 | I8: 3.980889 | K8: 0.20900087 | N8: 569.20048 | P8: 0.78779666 | R8: 0.039875083 | S8: 0.149138 | T8: 0.0038686032 | U8: 55.558836 | W8: 1.0600015 | AB8: 0.49400053 | AF8: 0.016998408 | AG8: 14.09639 | AI8: =SUM(E8:AH8) -> 645.86248 | AL8: Biomass waste
B9: RES | C9: RES | D9: RESHET | H9: 111.42624 | I9: 84.562001 | J9: 17.053674 | N9: 1288.3205 | O9: 242.76058 | P9: 289.38814 | Q9: 12.609838 | R9: 39.376758 | S9: 69.09605 | T9: 0.035998106 | U9: 210.11656 | V9: 53.93069 | W9: 166.098 | AB9: 21.214365 | AC9: 1996.1618 | AF9: 11.283233 | AI9: =SUM(E9:AH9) -> 4613.4344 | AL9: Coal | AM9: RESCOA
B10: RES | C10: RES | D10: RESKER | E10: 4.5989988 | F10: 50.777975 | G10: 4.4558061 | H10: 6.474254 | I10: 349.05486 | J10: 33.561364 | L10: 0.07859461 | M10: 2.2775983 | N10: 19.041629 | O10: 0.15570291 | Q10: 34.77487 | R10: 0.75231353 | T10: 0.0042579756 | U10: 0.38699848 | V10: 7.3498604 | W10: 0.25799899 | X10: 95.208058 | Y10: 10.683529 | AA10: 158.92378 | AB10: 0.024208078 | AD10: 22.531729 | AE10: 11.256203 | AF10: 77.137268 | AG10: 11.503982 | AI10: =SUM(E10:AH10) -> 901.27185 | AL10: Distallate | AM10: RESOIL
B11: RES | C11: RES | D11: RESLPG | E11: 392.73293 | F11: 122.09616 | G11: 91.404405 | H11: 65.073486 | I11: 225.69207 | J11: 708.88631 | K11: 19.011028 | L11: 272.089 | M11: 15.277901 | N11: 1434.2433 | O11: 1.1998196 | P11: 30.43024 | Q11: 7.9087354 | R11: 52.358693 | S11: 19.054131 | T11: 51.706712 | U11: 21.353442 | V11: 34.128227 | W11: 35.19 | X11: 1091.4948 | Y11: 226.86219 | Z11: 225.92755 | AA11: 298.75247 | AB11: 0.24126854 | AC11: 506.4048 | AD11: 51.336817 | AE11: 10.084088 | AF11: 9.8021403 | AG11: 195.9166 | AI11: =SUM(E11:AH11) -> 6216.6593 | AL11: Electricity | AM11: RESELC
B12: RES | C12: RES | D12: RESNGA | E12: 498.22063 | F12: 0.0003935592 | G12: 375.78845 | H12: 616.54371 | I12: 750.03062 | J12: 505.28145 | K12: 158.05196 | L12: 17.080436 | M12: 621.027 | N12: 2121.0207 | O12: 28.807792 | P12: 347.91757 | Q12: 447.08086 | R12: 691.28343 | S12: 248.75203 | T12: 156.64187 | U12: 913.59523 | V12: 475.74438 | W12: 949.15182 | X12: 102.46138 | Y12: 82.029674 | Z12: 26.946002 | AA12: 1725.1566 | AB12: 0.064807477 | AC12: 2721.2565 | AE12: 0.2087371 | AF12: 955.4022 | AG12: 4943.7516 | AI12: =SUM(E12:AH12) -> 20479.298 | AL12: Geothermal | AM12: RESGEO
B13: RES | C13: RES | D13: RESOIL | E13: 0.35929862 | F13: 15.205197 | H13: 105.42471 | I13: 31.246206 | J13: 3.126091 | K13: 0.12168934 | M13: 49.245598 | N13: 127.42958 | O13: 27.560532 | P13: 42.735103 | Q13: 107.30435 | R13: 83.220425 | S13: 7.5016905 | T13: 64.096337 | U13: 67.069944 | V13: 140.84033 | W13: 460.3904 | Y13: 1.1786428 | AA13: 24.850349 | AB13: 0.38599784 | AC13: 101.47185 | AE13: 0.25919223 | AF13: 6.9484845 | AG13: 414.4128 | AI13: =SUM(E13:AH13) -> 1882.3848 | AL13: Heat | AM13: RESHET
B14: RES | C14: RES | D14: RESSTH | E14: 2.4618384 | H14: 0.18249424 | I14: 7.8229437 | J14: 3.6995067 | K14: 17.385871 | N14: 878.688 | O14: 1.056338 | P14: 8.3708032 | Q14: 2.6307088 | R14: 21.328476 | S14: 1.9036793 | T14: 13.060773 | U14: 24.963531 | V14: 7.1510125 | W14: 29.210998 | X14: 37.015637 | Y14: 1.2074522 | Z14: 7.8850004 | AA14: 23.267132 | AF14: 1.5130007 | AG14: 37.389912 | AI14: =SUM(E14:AH14) -> 1128.1951 | AL14: Heavy
AL15: Kerosene | AM15: RESKER
R16: =R7*'RES Assumptions T15'!S45 -> 6.1628716 | W16: =W7*'RES Assumptions T15'!J45 -> 6.833106 | AL16: LPG (called propane in nrc) | AM16: RESLPG
R17: =R16/SUM(R5:R14) -> 0.0041429242 | W17: =W16/SUM(W5:W14) -> 0.0028850729 | AL17: Natural Gas | AM17: RESNGA
AL18: Solar | AM18: RESSTH
E27: =SUM(E5:E25) -> 1442.5001 | F27: =SUM(F5:F25) -> 11712.629 | G27: =SUM(G5:G25) -> 764.8389 | H27: =SUM(H5:H25) -> 1326.8882 | I27: =SUM(I5:I25) -> 2620.7994 | J27: =SUM(J5:J25) -> 7017.6449 | K27: =SUM(K5:K25) -> 508.48465 | L27: =SUM(L5:L25) -> 1115.9017 | ... AH27: =SUM(AH5:AH25) -> 0
E28: =SUM('RES Assumptions'!AK3:AK64) -> 1442.5001 | F28: =SUM('RES Assumptions'!AL3:AL64) -> 11712.629 | G28: =SUM('RES Assumptions'!AM3:AM64) -> 764.8389 | H28: =SUM('RES Assumptions'!AN3:AN64) -> 1325.4394 | I28: =SUM('RES Assumptions'!AO3:AO64) -> 2620.7994 | J28: =SUM('RES Assumptions'!AP3:AP64) -> 7000.5913 | K28: =SUM('RES Assumptions'!AQ3:AQ64) -> 508.48465 | L28: =SUM('RES Assumptions'!AR3:AR64) -> 1115.9017 | ... AH28: =SUM('RES Assumptions'!BN3:BN64) -> 0
E29: =SUM('RES Assumptions'!E87:E144) -> 1442.5001 | F29: =SUM('RES Assumptions'!F87:F144) -> 11712.629 | G29: =SUM('RES Assumptions'!G87:G144) -> 764.8389 | H29: =SUM('RES Assumptions'!H87:H144) -> 1325.4394 | I29: =SUM('RES Assumptions'!I87:I144) -> 2620.7994 | J29: =SUM('RES Assumptions'!J87:J144) -> 7000.5913 | K29: =SUM('RES Assumptions'!K87:K144) -> 508.48465 | L29: =SUM('RES Assumptions'!L87:L144) -> 1115.9017 | ... AH29: =SUM('RES Assumptions'!AH87:AH144) -> 0
C34: Year | D34: Drvr | E34: Africa_north | F34: Africa_other | G34: Arg-Chi | H34: Asia_central | I34: Asia_east | J34: Asia_other | K34: Australia_NZ | L34: Brazil | M34: Canada | N34: China | O34: EU_north | P34: EU_northeast | Q34: EU_northwest | R34: EU_south | S34: EU_southeast | T34: EU_southwest | U34: Europe_other | V34: France | W34: Germany | X34: India | Y34: LatAm_other | Z34: Mexico | AA34: MidEast_other | AB34: Nor-Ice | AC34: Russia | AD34: SaudiArabia | AE34: SouthAfrica | AF34: UK | AG34: USA
C35: 2019 | D35: GDP | E35: 2018.274 | F35: 2783.9392 | G35: 1015.21 | H35: 1001.7532 | I35: 6334.56 | J35: 10498.518 | K35: 1111.535 | L35: 2724.93 | M35: 1586.46 | N35: 21698.553 | O35: 819.16 | P35: 1871.7913 | Q35: 1517.9469 | R35: 2016.789 | S35: 805.758 | T35: 1655.67 | U35: 2703.2985 | V35: 2313.4717 | W35: 3218.77 | X35: 8348.05 | Y35: 2670.5199 | Z35: 1782.59 | AA35: 3897.7243 | AB35: 281.3089 | AC35: 2310.67 | AD35: 1712.87 | AE35: 625.812 | AF35: 2365.1179 | AG35: 16690.1
C36: 2019 | D36: POP | E36: 198.38505 | F36: 1039.4856 | G36: 63.8907 | H36: 90.5156 | I36: 177.9741 | J36: 1196.6778 | K36: 30.345 | L36: 211.05 | M36: 37.5934 | N36: 1405.2274 | O36: 21.61493 | P36: 69.00633 | Q36: 34.388241 | R36: 72.185138 | S36: 42.27214 | T36: 57.4198 | U36: 164.81755 | V36: 68.440616 | W36: 83.093 | X36: 1366.42 | Y36: 245.14509 | Z36: 127.576 | AA36: 222.57825 | AB36: 5.708463 | AC36: 144.406 | AD36: 34.2685 | AE36: 58.5583 | AF36: 66.878303 | AG36: 328.33

Sheet RES Assumptions
A2: Fuel | B2: Sector | C2: Fuel | D2: Service | E2: ='RES balance'!E4 -> Africa_north | F2: ='RES balance'!F4 -> Africa_other | G2: ='RES balance'!G4 -> Arg-Chi | H2: ='RES balance'!H4 -> Asia_central | I2: ='RES balance'!I4 -> Asia_east | J2: ='RES balance'!J4 -> Asia_other | K2: ='RES balance'!K4 -> Australia_NZ | L2: ='RES balance'!L4 -> Brazil | ... AH2: ='RES balance'!AH4 -> \I: | AK2: =E2 -> Africa_north | AL2: =F2 -> Africa_other | AM2: =G2 -> Arg-Chi | AN2: =H2 -> Asia_central | AO2: =I2 -> Asia_east | AP2: =J2 -> Asia_other | AQ2: =K2 -> Australia_NZ | AR2: =L2 -> Brazil | ... BN2: =AH2 -> \I:
A3: =VLOOKUP(C3,'RES balance'!$AL$5:$AM$25,2,FALSE) -> RESNGA | C3: Natural Gas | D3: RH | E3: =OFFSET('RES Assumptions T15'!$D3,0,MATCH(VLOOKUP('RES Assumptions'!E$2,'RES Assumptions T15'!$V$3:$W$35,2,FALSE),'RES Assumptions T15'!$E$2:$S$2,0)) -> 0.0014979621 | F3: =OFFSET('RES Assumptions T15'!$D3,0,MATCH(VLOOKUP('RES Assumptions'!F$2,'RES Assumptions T15'!$V$3:$W$35,2,FALSE),'RES Assumptions T15'!$E$2:$S$2,0)) -> 0.0014979621 | G3: =OFFSET('RES Assumptions T15'!$D3,0,MATCH(VLOOKUP('RES Assumptions'!G$2,'RES Assumptions T15'!$V$3:$W$35,2,FALSE),'RES Assumptions T15'!$E$2:$S$2,0)) -> 0.0014979621 | H3: =OFFSET('RES Assumptions T15'!$D3,0,MATCH(VLOOKUP('RES Assumptions'!H$2,'RES Assumptions T15'!$V$3:$W$35,2,FALSE),'RES Assumptions T15'!$E$2:$S$2,0)) -> 0.66084849 | I3: =OFFSET('RES Assumptions T15'!$D3,0,MATCH(VLOOKUP('RES Assumptions'!I$2,'RES Assumptions T15'!$V$3:$W$35,2,FALSE),'RES Assumptions T15'!$E$2:$S$2,0)) -> 0.18331596 | J3: =OFFSET('RES Assumptions T15'!$D3,0,MATCH(VLOOKUP('RES Assumptions'!J$2,'RES Assumptions T15'!$V$3:$W$35,2,FALSE),'RES Assumptions T15'!$E$2:$S$2,0)) -> 0 | K3: =OFFSET('RES Assumptions T15'!$D3,0,MATCH(VLOOKUP('RES Assumptions'!K$2,'RES Assumptions T15'!$V$3:$W$35,2,FALSE),'RES Assumptions T15'!$E$2:$S$2,0)) -> 0.61715911 | L3: =OFFSET('RES Assumptions T15'!$D3,0,MATCH(VLOOKUP('RES Assumptions'!L$2,'RES Assumptions T15'!$V$3:$W$35,2,FALSE),'RES Assumptions T15'!$E$2:$S$2,0)) -> 0.0014979621 | ... AH3: =OFFSET('RES Assumptions T15'!$D3,0,MATCH(VLOOKUP('RES Assumptions'!AH$2,'RES Assumptions T15'!$V$3:$W$35,2,FALSE),'RES Assumptions T15'!$E$2:$S$2,0)) -> 0.6855783 | AK3: =IFERROR(SUMIFS('RES balance'!E$5:E$25,'RES balance'!$D$5:$D$25,'RES Assumptions'!$A3)*E3,"") -> 0.74631562 | AL3: =IFERROR(SUMIFS('RES balance'!F$5:F$25,'RES balance'!$D$5:$D$25,'RES Assumptions'!$A3)*F3,"") -> 5.8953677e-07 | AM3: =IFERROR(SUMIFS('RES balance'!G$5:G$25,'RES balance'!$D$5:$D$25,'RES Assumptions'!$A3)*G3,"") -> 0.56291686 | AN3: =IFERROR(SUMIFS('RES balance'!H$5:H$25,'RES balance'!$D$5:$D$25,'RES Assumptions'!$A3)*H3,"") -> 407.44198 | AO3: =IFERROR(SUMIFS('RES balance'!I$5:I$25,'RES balance'!$D$5:$D$25,'RES Assumptions'!$A3)*I3,"") -> 137.49259 | AP3: =IFERROR(SUMIFS('RES balance'!J$5:J$25,'RES balance'!$D$5:$D$25,'RES Assumptions'!$A3)*J3,"") -> 0 | AQ3: =IFERROR(SUMIFS('RES balance'!K$5:K$25,'RES balance'!$D$5:$D$25,'RES Assumptions'!$A3)*K3,"") -> 97.543209 | AR3: =IFERROR(SUMIFS('RES balance'!L$5:L$25,'RES balance'!$D$5:$D$25,'RES Assumptions'!$A3)*L3,"") -> 0.025585846 | ... BN3: =IFERROR(SUMIFS('RES balance'!AH$5:AH$25,'RES balance'!$D$5:$D$25,'RES Assumptions'!$A3)*AH3,"") -> 0
A4: =VLOOKUP(C4,'RES balance'!$AL$5:$AM$25,2,FALSE) -> RESNGA | C4: Natural Gas | D4: RC | E4: =OFFSET('RES Assumptions T15'!$D4,0,MATCH(VLOOKUP('RES Assumptions'!E$2,'RES Assumptions T15'!$V$3:$W$35,2,FALSE),'RES Assumptions T15'!$E$2:$S$2,0)) -> 0 | F4: =OFFSET('RES Assumptions T15'!$D4,0,MATCH(VLOOKUP('RES Assumptions'!F$2,'RES Assumptions T15'!$V$3:$W$35,2,FALSE),'RES Assumptions T15'!$E$2:$S$2,0)) -> 0 | G4: =OFFSET('RES Assumptions T15'!$D4,0,MATCH(VLOOKUP('RES Assumptions'!G$2,'RES Assumptions T15'!$V$3:$W$35,2,FALSE),'RES Assumptions T15'!$E$2:$S$2,0)) -> 0 | H4: =OFFSET('RES Assumptions T15'!$D4,0,MATCH(VLOOKUP('RES Assumptions'!H$2,'RES Assumptions T15'!$V$3:$W$35,2,FALSE),'RES Assumptions T15'!$E$2:$S$2,0)) -> 0 | I4: =OFFSET('RES Assumptions T15'!$D4,0,MATCH(VLOOKUP('RES Assumptions'!I$2,'RES Assumptions T15'!$V$3:$W$35,2,FALSE),'RES Assumptions T15'!$E$2:$S$2,0)) -> 0 | J4: =OFFSET('RES Assumptions T15'!$D4,0,MATCH(VLOOKUP('RES Assumptions'!J$2,'RES Assumptions T15'!$V$3:$W$35,2,FALSE),'RES Assumptions T15'!$E$2:$S$2,0)) -> 0 | K4: =OFFSET('RES Assumptions T15'!$D4,0,MATCH(VLOOKUP('RES Assumptions'!K$2,'RES Assumptions T15'!$V$3:$W$35,2,FALSE),'RES Assumptions T15'!$E$2:$S$2,0)) -> 0 | L4: =OFFSET('RES Assumptions T15'!$D4,0,MATCH(VLOOKUP('RES Assumptions'!L$2,'RES Assumptions T15'!$V$3:$W$35,2,FALSE),'RES Assumptions T15'!$E$2:$S$2,0)) -> 0 | ... AH4: =OFFSET('RES Assumptions T15'!$D4,0,MATCH(VLOOKUP('RES Assumptions'!AH$2,'RES Assumptions T15'!$V$3:$W$35,2,FALSE),'RES Assumptions T15'!$E$2:$S$2,0)) -> 0 | AK4: =IFERROR(SUMIFS('RES balance'!E$5:E$25,'RES balance'!$D$5:$D$25,'RES Assumptions'!$A4)*E4,"") -> 0 | AL4: =IFERROR(SUMIFS('RES balance'!F$5:F$25,'RES balance'!$D$5:$D$25,'RES Assumptions'!$A4)*F4,"") -> 0 | AM4: =IFERROR(SUMIFS('RES balance'!G$5:G$25,'RES balance'!$D$5:$D$25,'RES Assumptions'!$A4)*G4,"") -> 0 | AN4: =IFERROR(SUMIFS('RES balance'!H$5:H$25,'RES balance'!$D$5:$D$25,'RES Assumptions'!$A4)*H4,"") -> 0 | AO4: =IFERROR(SUMIFS('RES balance'!I$5:I$25,'RES balance'!$D$5:$D$25,'RES Assumptions'!$A4)*I4,"") -> 0 | AP4: =IFERROR(SUMIFS('RES balance'!J$5:J$25,'RES balance'!$D$5:$D$25,'RES Assumptions'!$A4)*J4,"") -> 0 | AQ4: =IFERROR(SUMIFS('RES balance'!K$5:K$25,'RES balance'!$D$5:$D$25,'RES Assumptions'!$A4)*K4,"") -> 0 | AR4: =IFERROR(SUMIFS('RES balance'!L$5:L$25,'RES balance'!$D$5:$D$25,'RES Assumptions'!$A4)*L4,"") -> 0 | ... BN4: =IFERROR(SUMIFS('RES balance'!AH$5:AH$25,'RES balance'!$D$5:$D$25,'RES Assumptions'!$A4)*AH4,"") -> 0
A5: =VLOOKUP(C5,'RES balance'!$AL$5:$AM$25,2,FALSE) -> RESNGA | C5: Natural Gas | D5: RHW | E5: =OFFSET('RES Assumptions T15'!$D5,0,MATCH(VLOOKUP('RES Assumptions'!E$2,'RES Assumptions T15'!$V$3:$W$35,2,FALSE),'RES Assumptions T15'!$E$2:$S$2,0)) -> 0.65441803 | F5: =OFFSET('RES Assumptions T15'!$D5,0,MATCH(VLOOKUP('RES Assumptions'!F$2,'RES Assumptions T15'!$V$3:$W$35,2,FALSE),'RES Assumptions T15'!$E$2:$S$2,0)) -> 0.65441803 | G5: =OFFSET('RES Assumptions T15'!$D5,0,MATCH(VLOOKUP('RES Assumptions'!G$2,'RES Assumptions T15'!$V$3:$W$35,2,FALSE),'RES Assumptions T15'!$E$2:$S$2,0)) -> 0.65441803 | H5: =OFFSET('RES Assumptions T15'!$D5,0,MATCH(VLOOKUP('RES Assumptions'!H$2,'RES Assumptions T15'!$V$3:$W$35,2,FALSE),'RES Assumptions T15'!$E$2:$S$2,0)) -> 0.19505887 | I5: =OFFSET('RES Assumptions T15'!$D5,0,MATCH(VLOOKUP('RES Assumptions'!I$2,'RES Assumptions T15'!$V$3:$W$35,2,FALSE),'RES Assumptions T15'!$E$2:$S$2,0)) -> 0.65308992 | J5: =OFFSET('RES Assumptions T15'!$D5,0,MATCH(VLOOKUP('RES Assumptions'!J$2,'RES Assumptions T15'!$V$3:$W$35,2,FALSE),'RES Assumptions T15'!$E$2:$S$2,0)) -> 0 | K5: =OFFSET('RES Assumptions T15'!$D5,0,MATCH(VLOOKUP('RES Assumptions'!K$2,'RES Assumptions T15'!$V$3:$W$35,2,FALSE),'RES Assumptions T15'!$E$2:$S$2,0)) -> 0.33386001 | L5: =OFFSET('RES Assumptions T15'!$D5,0,MATCH(VLOOKUP('RES Assumptions'!L$2,'RES Assumptions T15'!$V$3:$W$35,2,FALSE),'RES Assumptions T15'!$E$2:$S$2,0)) -> 0.65441803 | ... AH5: =OFFSET('RES Assumptions T15'!$D5,0,MATCH(VLOOKUP('RES Assumptions'!AH$2,'RES Assumptions T15'!$V$3:$W$35,2,FALSE),'RES Assumptions T15'!$E$2:$S$2,0)) -> 0.27180533 | AK5: =IFERROR(SUMIFS('RES balance'!E$5:E$25,'RES balance'!$D$5:$D$25,'RES Assumptions'!$A5)*E5,"") -> 326.04456 | AL5: =IFERROR(SUMIFS('RES balance'!F$5:F$25,'RES balance'!$D$5:$D$25,'RES Assumptions'!$A5)*F5,"") -> 0.00025755224 | AM5: =IFERROR(SUMIFS('RES balance'!G$5:G$25,'RES balance'!$D$5:$D$25,'RES Assumptions'!$A5)*G5,"") -> 245.92274 | AN5: =IFERROR(SUMIFS('RES balance'!H$5:H$25,'RES balance'!$D$5:$D$25,'RES Assumptions'!$A5)*H5,"") -> 120.26232 | AO5: =IFERROR(SUMIFS('RES balance'!I$5:I$25,'RES balance'!$D$5:$D$25,'RES Assumptions'!$A5)*I5,"") -> 489.83744 | AP5: =IFERROR(SUMIFS('RES balance'!J$5:J$25,'RES balance'!$D$5:$D$25,'RES Assumptions'!$A5)*J5,"") -> 0 | AQ5: =IFERROR(SUMIFS('RES balance'!K$5:K$25,'RES balance'!$D$5:$D$25,'RES Assumptions'!$A5)*K5,"") -> 52.76723 | AR5: =IFERROR(SUMIFS('RES balance'!L$5:L$25,'RES balance'!$D$5:$D$25,'RES Assumptions'!$A5)*L5,"") -> 11.177745 | ... BN5: =IFERROR(SUMIFS('RES balance'!AH$5:AH$25,'RES balance'!$D$5:$D$25,'RES Assumptions'!$A5)*AH5,"") -> 0
A6: =VLOOKUP(C6,'RES balance'!$AL$5:$AM$25,2,FALSE) -> RESNGA | C6: Natural Gas | D6: RCD | E6: =OFFSET('RES Assumptions T15'!$D6,0,MATCH(VLOOKUP('RES Assumptions'!E$2,'RES Assumptions T15'!$V$3:$W$35,2,FALSE),'RES Assumptions T15'!$E$2:$S$2,0)) -> 0 | F6: =OFFSET('RES Assumptions T15'!$D6,0,MATCH(VLOOKUP('RES Assumptions'!F$2,'RES Assumptions T15'!$V$3:$W$35,2,FALSE),'RES Assumptions T15'!$E$2:$S$2,0)) -> 0 | G6: =OFFSET('RES Assumptions T15'!$D6,0,MATCH(VLOOKUP('RES Assumptions'!G$2,'RES Assumptions T15'!$V$3:$W$35,2,FALSE),'RES Assumptions T15'!$E$2:$S$2,0)) -> 0 | H6: =OFFSET('RES Assumptions T15'!$D6,0,MATCH(VLOOKUP('RES Assumptions'!H$2,'RES Assumptions T15'!$V$3:$W$35,2,FALSE),'RES Assumptions T15'!$E$2:$S$2,0)) -> 0 | I6: =OFFSET('RES Assumptions T15'!$D6,0,MATCH(VLOOKUP('RES Assumptions'!I$2,'RES Assumptions T15'!$V$3:$W$35,2,FALSE),'RES Assumptions T15'!$E$2:$S$2,0)) -> 0 | J6: =OFFSET('RES Assumptions T15'!$D6,0,MATCH(VLOOKUP('RES Assumptions'!J$2,'RES Assumptions T15'!$V$3:$W$35,2,FALSE),'RES Assumptions T15'!$E$2:$S$2,0)) -> 0 | K6: =OFFSET('RES Assumptions T15'!$D6,0,MATCH(VLOOKUP('RES Assumptions'!K$2,'RES Assumptions T15'!$V$3:$W$35,2,FALSE),'RES Assumptions T15'!$E$2:$S$2,0)) -> 0 | L6: =OFFSET('RES Assumptions T15'!$D6,0,MATCH(VLOOKUP('RES Assumptions'!L$2,'RES Assumptions T15'!$V$3:$W$35,2,FALSE),'RES Assumptions T15'!$E$2:$S$2,0)) -> 0 | ... AH6: =OFFSET('RES Assumptions T15'!$D6,0,MATCH(VLOOKUP('RES Assumptions'!AH$2,'RES Assumptions T15'!$V$3:$W$35,2,FALSE),'RES Assumptions T15'!$E$2:$S$2,0)) -> 0 | AK6: =IFERROR(SUMIFS('RES balance'!E$5:E$25,'RES balance'!$D$5:$D$25,'RES Assumptions'!$A6)*E6,"") -> 0 | AL6: =IFERROR(SUMIFS('RES balance'!F$5:F$25,'RES balance'!$D$5:$D$25,'RES Assumptions'!$A6)*F6,"") -> 0 | AM6: =IFERROR(SUMIFS('RES balance'!G$5:G$25,'RES balance'!$D$5:$D$25,'RES Assumptions'!$A6)*G6,"") -> 0 | AN6: =IFERROR(SUMIFS('RES balance'!H$5:H$25,'RES balance'!$D$5:$D$25,'RES Assumptions'!$A6)*H6,"") -> 0 | AO6: =IFERROR(SUMIFS('RES balance'!I$5:I$25,'RES balance'!$D$5:$D$25,'RES Assumptions'!$A6)*I6,"") -> 0 | AP6: =IFERROR(SUMIFS('RES balance'!J$5:J$25,'RES balance'!$D$5:$D$25,'RES Assumptions'!$A6)*J6,"") -> 0 | AQ6: =IFERROR(SUMIFS('RES balance'!K$5:K$25,'RES balance'!$D$5:$D$25,'RES Assumptions'!$A6)*K6,"") -> 0 | AR6: =IFERROR(SUMIFS('RES balance'!L$5:L$25,'RES balance'!$D$5:$D$25,'RES Assumptions'!$A6)*L6,"") -> 0 | ... BN6: =IFERROR(SUMIFS('RES balance'!AH$5:AH$25,'RES balance'!$D$5:$D$25,'RES Assumptions'!$A6)*AH6,"") -> 0
A7: =VLOOKUP(C7,'RES balance'!$AL$5:$AM$25,2,FALSE) -> RESNGA | C7: Natural Gas | D7: RK | E7: =OFFSET('RES Assumptions T15'!$D7,0,MATCH(VLOOKUP('RES Assumptions'!E$2,'RES Assumptions T15'!$V$3:$W$35,2,FALSE),'RES Assumptions T15'!$E$2:$S$2,0)) -> 0.34408401 | F7: =OFFSET('RES Assumptions T15'!$D7,0,MATCH(VLOOKUP('RES Assumptions'!F$2,'RES Assumptions T15'!$V$3:$W$35,2,FALSE),'RES Assumptions T15'!$E$2:$S$2,0)) -> 0.34408401 | G7: =OFFSET('RES Assumptions T15'!$D7,0,MATCH(VLOOKUP('RES Assumptions'!G$2,'RES Assumptions T15'!$V$3:$W$35,2,FALSE),'RES Assumptions T15'!$E$2:$S$2,0)) -> 0.34408401 | H7: =OFFSET('RES Assumptions T15'!$D7,0,MATCH(VLOOKUP('RES Assumptions'!H$2,'RES Assumptions T15'!$V$3:$W$35,2,FALSE),'RES Assumptions T15'!$E$2:$S$2,0)) -> 0.12025082 | I7: =OFFSET('RES Assumptions T15'!$D7,0,MATCH(VLOOKUP('RES Assumptions'!I$2,'RES Assumptions T15'!$V$3:$W$35,2,FALSE),'RES Assumptions T15'!$E$2:$S$2,0)) -> 0.16359411 | J7: =OFFSET('RES Assumptions T15'!$D7,0,MATCH(VLOOKUP('RES Assumptions'!J$2,'RES Assumptions T15'!$V$3:$W$35,2,FALSE),'RES Assumptions T15'!$E$2:$S$2,0)) -> 1 | K7: =OFFSET('RES Assumptions T15'!$D7,0,MATCH(VLOOKUP('RES Assumptions'!K$2,'RES Assumptions T15'!$V$3:$W$35,2,FALSE),'RES Assumptions T15'!$E$2:$S$2,0)) -> 0.048980882 | L7: =OFFSET('RES Assumptions T15'!$D7,0,MATCH(VLOOKUP('RES Assumptions'!L$2,'RES Assumptions T15'!$V$3:$W$35,2,FALSE),'RES Assumptions T15'!$E$2:$S$2,0)) -> 0.34408401 | ... AH7: =OFFSET('RES Assumptions T15'!$D7,0,MATCH(VLOOKUP('RES Assumptions'!AH$2,'RES Assumptions T15'!$V$3:$W$35,2,FALSE),'RES Assumptions T15'!$E$2:$S$2,0)) -> 0.042616361 | AK7: =IFERROR(SUMIFS('RES balance'!E$5:E$25,'RES balance'!$D$5:$D$25,'RES Assumptions'!$A7)*E7,"") -> 171.42975 | AL7: =IFERROR(SUMIFS('RES balance'!F$5:F$25,'RES balance'!$D$5:$D$25,'RES Assumptions'!$A7)*F7,"") -> 0.00013541743 | AM7: =IFERROR(SUMIFS('RES balance'!G$5:G$25,'RES balance'!$D$5:$D$25,'RES Assumptions'!$A7)*G7,"") -> 129.30279 | AN7: =IFERROR(SUMIFS('RES balance'!H$5:H$25,'RES balance'!$D$5:$D$25,'RES Assumptions'!$A7)*H7,"") -> 74.139885 | AO7: =IFERROR(SUMIFS('RES balance'!I$5:I$25,'RES balance'!$D$5:$D$25,'RES Assumptions'!$A7)*I7,"") -> 122.7006 | AP7: =IFERROR(SUMIFS('RES balance'!J$5:J$25,'RES balance'!$D$5:$D$25,'RES Assumptions'!$A7)*J7,"") -> 505.28145 | AQ7: =IFERROR(SUMIFS('RES balance'!K$5:K$25,'RES balance'!$D$5:$D$25,'RES Assumptions'!$A7)*K7,"") -> 7.7415245 | AR7: =IFERROR(SUMIFS('RES balance'!L$5:L$25,'RES balance'!$D$5:$D$25,'RES Assumptions'!$A7)*L7,"") -> 5.8771048 | ... BN7: =IFERROR(SUMIFS('RES balance'!AH$5:AH$25,'RES balance'!$D$5:$D$25,'RES Assumptions'!$A7)*AH7,"") -> 0
A8: =VLOOKUP(C8,'RES balance'!$AL$5:$AM$25,2,FALSE) -> RESNGA | C8: Natural Gas | D8: ROT | E8: =OFFSET('RES Assumptions T15'!$D8,0,MATCH(VLOOKUP('RES Assumptions'!E$2,'RES Assumptions T15'!$V$3:$W$35,2,FALSE),'RES Assumptions T15'!$E$2:$S$2,0)) -> 0 | F8: =OFFSET('RES Assumptions T15'!$D8,0,MATCH(VLOOKUP('RES Assumptions'!F$2,'RES Assumptions T15'!$V$3:$W$35,2,FALSE),'RES Assumptions T15'!$E$2:$S$2,0)) -> 0 | G8: =OFFSET('RES Assumptions T15'!$D8,0,MATCH(VLOOKUP('RES Assumptions'!G$2,'RES Assumptions T15'!$V$3:$W$35,2,FALSE),'RES Assumptions T15'!$E$2:$S$2,0)) -> 0 | H8: =OFFSET('RES Assumptions T15'!$D8,0,MATCH(VLOOKUP('RES Assumptions'!H$2,'RES Assumptions T15'!$V$3:$W$35,2,FALSE),'RES Assumptions T15'!$E$2:$S$2,0)) -> 0.023841827 | I8: =OFFSET('RES Assumptions T15'!$D8,0,MATCH(VLOOKUP('RES Assumptions'!I$2,'RES Assumptions T15'!$V$3:$W$35,2,FALSE),'RES Assumptions T15'!$E$2:$S$2,0)) -> 0 | J8: =OFFSET('RES Assumptions T15'!$D8,0,MATCH(VLOOKUP('RES Assumptions'!J$2,'RES Assumptions T15'!$V$3:$W$35,2,FALSE),'RES Assumptions T15'!$E$2:$S$2,0)) -> 0 | K8: =OFFSET('RES Assumptions T15'!$D8,0,MATCH(VLOOKUP('RES Assumptions'!K$2,'RES Assumptions T15'!$V$3:$W$35,2,FALSE),'RES Assumptions T15'!$E$2:$S$2,0)) -> 0 | L8: =OFFSET('RES Assumptions T15'!$D8,0,MATCH(VLOOKUP('RES Assumptions'!L$2,'RES Assumptions T15'!$V$3:$W$35,2,FALSE),'RES Assumptions T15'!$E$2:$S$2,0)) -> 0 | ... AH8: =OFFSET('RES Assumptions T15'!$D8,0,MATCH(VLOOKUP('RES Assumptions'!AH$2,'RES Assumptions T15'!$V$3:$W$35,2,FALSE),'RES Assumptions T15'!$E$2:$S$2,0)) -> 0 | AK8: =IFERROR(SUMIFS('RES balance'!E$5:E$25,'RES balance'!$D$5:$D$25,'RES Assumptions'!$A8)*E8,"") -> 0 | AL8: =IFERROR(SUMIFS('RES balance'!F$5:F$25,'RES balance'!$D$5:$D$25,'RES Assumptions'!$A8)*F8,"") -> 0 | AM8: =IFERROR(SUMIFS('RES balance'!G$5:G$25,'RES balance'!$D$5:$D$25,'RES Assumptions'!$A8)*G8,"") -> 0 | AN8: =IFERROR(SUMIFS('RES balance'!H$5:H$25,'RES balance'!$D$5:$D$25,'RES Assumptions'!$A8)*H8,"") -> 14.699528 | AO8: =IFERROR(SUMIFS('RES balance'!I$5:I$25,'RES balance'!$D$5:$D$25,'RES Assumptions'!$A8)*I8,"") -> 0 | AP8: =IFERROR(SUMIFS('RES balance'!J$5:J$25,'RES balance'!$D$5:$D$25,'RES Assumptions'!$A8)*J8,"") -> 0 | AQ8: =IFERROR(SUMIFS('RES balance'!K$5:K$25,'RES balance'!$D$5:$D$25,'RES Assumptions'!$A8)*K8,"") -> 0 | AR8: =IFERROR(SUMIFS('RES balance'!L$5:L$25,'RES balance'!$D$5:$D$25,'RES Assumptions'!$A8)*L8,"") -> 0 | ... BN8: =IFERROR(SUMIFS('RES balance'!AH$5:AH$25,'RES balance'!$D$5:$D$25,'RES Assumptions'!$A8)*AH8,"") -> 0
A9: =VLOOKUP(C9,'RES balance'!$AL$5:$AM$25,2,FALSE) -> RESOIL | C9: Distallate | D9: RH | E9: =OFFSET('RES Assumptions T15'!$D9,0,MATCH(VLOOKUP('RES Assumptions'!E$2,'RES Assumptions T15'!$V$3:$W$35,2,FALSE),'RES Assumptions T15'!$E$2:$S$2,0)) -> 0.011199497 | F9: =OFFSET('RES Assumptions T15'!$D9,0,MATCH(VLOOKUP('RES Assumptions'!F$2,'RES Assumptions T15'!$V$3:$W$35,2,FALSE),'RES Assumptions T15'!$E$2:$S$2,0)) -> 0.011199497 | G9: =OFFSET('RES Assumptions T15'!$D9,0,MATCH(VLOOKUP('RES Assumptions'!G$2,'RES Assumptions T15'!$V$3:$W$35,2,FALSE),'RES Assumptions T15'!$E$2:$S$2,0)) -> 0.028907423 | H9: =OFFSET('RES Assumptions T15'!$D9,0,MATCH(VLOOKUP('RES Assumptions'!H$2,'RES Assumptions T15'!$V$3:$W$35,2,FALSE),'RES Assumptions T15'!$E$2:$S$2,0)) -> 0.74195819 | I9: =OFFSET('RES Assumptions T15'!$D9,0,MATCH(VLOOKUP('RES Assumptions'!I$2,'RES Assumptions T15'!$V$3:$W$35,2,FALSE),'RES Assumptions T15'!$E$2:$S$2,0)) -> 0.54377694 | J9: =OFFSET('RES Assumptions T15'!$D9,0,MATCH(VLOOKUP('RES Assumptions'!J$2,'RES Assumptions T15'!$V$3:$W$35,2,FALSE),'RES Assumptions T15'!$E$2:$S$2,0)) -> 0 | K9: =OFFSET('RES Assumptions T15'!$D9,0,MATCH(VLOOKUP('RES Assumptions'!K$2,'RES Assumptions T15'!$V$3:$W$35,2,FALSE),'RES Assumptions T15'!$E$2:$S$2,0)) -> 0.28924651 | L9: =OFFSET('RES Assumptions T15'!$D9,0,MATCH(VLOOKUP('RES Assumptions'!L$2,'RES Assumptions T15'!$V$3:$W$35,2,FALSE),'RES Assumptions T15'!$E$2:$S$2,0)) -> 0.028907423 | ... AH9: =OFFSET('RES Assumptions T15'!$D9,0,MATCH(VLOOKUP('RES Assumptions'!AH$2,'RES Assumptions T15'!$V$3:$W$35,2,FALSE),'RES Assumptions T15'!$E$2:$S$2,0)) -> 0.83153081 | AK9: =IFERROR(SUMIFS('RES balance'!E$5:E$25,'RES balance'!$D$5:$D$25,'RES Assumptions'!$A9)*E9,"") -> 0.0040239636 | AL9: =IFERROR(SUMIFS('RES balance'!F$5:F$25,'RES balance'!$D$5:$D$25,'RES Assumptions'!$A9)*F9,"") -> 0.17029056 | AM9: =IFERROR(SUMIFS('RES balance'!G$5:G$25,'RES balance'!$D$5:$D$25,'RES Assumptions'!$A9)*G9,"") -> 0 | AN9: =IFERROR(SUMIFS('RES balance'!H$5:H$25,'RES balance'!$D$5:$D$25,'RES Assumptions'!$A9)*H9,"") -> 78.220729 | AO9: =IFERROR(SUMIFS('RES balance'!I$5:I$25,'RES balance'!$D$5:$D$25,'RES Assumptions'!$A9)*I9,"") -> 16.990966 | AP9: =IFERROR(SUMIFS('RES balance'!J$5:J$25,'RES balance'!$D$5:$D$25,'RES Assumptions'!$A9)*J9,"") -> 0 | AQ9: =IFERROR(SUMIFS('RES balance'!K$5:K$25,'RES balance'!$D$5:$D$25,'RES Assumptions'!$A9)*K9,"") -> 0.035198217 | AR9: =IFERROR(SUMIFS('RES balance'!L$5:L$25,'RES balance'!$D$5:$D$25,'RES Assumptions'!$A9)*L9,"") -> 0 | ... BN9: =IFERROR(SUMIFS('RES balance'!AH$5:AH$25,'RES balance'!$D$5:$D$25,'RES Assumptions'!$A9)*AH9,"") -> 0
A10: =VLOOKUP(C10,'RES balance'!$AL$5:$AM$25,2,FALSE) -> RESOIL | C10: Distallate | D10: RHW | E10: =OFFSET('RES Assumptions T15'!$D10,0,MATCH(VLOOKUP('RES Assumptions'!E$2,'RES Assumptions T15'!$V$3:$W$35,2,FALSE),'RES Assumptions T15'!$E$2:$S$2,0)) -> 0.1109556 | F10: =OFFSET('RES Assumptions T15'!$D10,0,MATCH(VLOOKUP('RES Assumptions'!F$2,'RES Assumptions T15'!$V$3:$W$35,2,FALSE),'RES Assumptions T15'!$E$2:$S$2,0)) -> 0.1109556 | G10: =OFFSET('RES Assumptions T15'!$D10,0,MATCH(VLOOKUP('RES Assumptions'!G$2,'RES Assumptions T15'!$V$3:$W$35,2,FALSE),'RES Assumptions T15'!$E$2:$S$2,0)) -> 0.14250342 | H10: =OFFSET('RES Assumptions T15'!$D10,0,MATCH(VLOOKUP('RES Assumptions'!H$2,'RES Assumptions T15'!$V$3:$W$35,2,FALSE),'RES Assumptions T15'!$E$2:$S$2,0)) -> 0.096822342 | I10: =OFFSET('RES Assumptions T15'!$D10,0,MATCH(VLOOKUP('RES Assumptions'!I$2,'RES Assumptions T15'!$V$3:$W$35,2,FALSE),'RES Assumptions T15'!$E$2:$S$2,0)) -> 0.34868853 | J10: =OFFSET('RES Assumptions T15'!$D10,0,MATCH(VLOOKUP('RES Assumptions'!J$2,'RES Assumptions T15'!$V$3:$W$35,2,FALSE),'RES Assumptions T15'!$E$2:$S$2,0)) -> 0.098003347 | K10: =OFFSET('RES Assumptions T15'!$D10,0,MATCH(VLOOKUP('RES Assumptions'!K$2,'RES Assumptions T15'!$V$3:$W$35,2,FALSE),'RES Assumptions T15'!$E$2:$S$2,0)) -> 0.46648194 | L10: =OFFSET('RES Assumptions T15'!$D10,0,MATCH(VLOOKUP('RES Assumptions'!L$2,'RES Assumptions T15'!$V$3:$W$35,2,FALSE),'RES Assumptions T15'!$E$2:$S$2,0)) -> 0.14250342 | ... AH10: =OFFSET('RES Assumptions T15'!$D10,0,MATCH(VLOOKUP('RES Assumptions'!AH$2,'RES Assumptions T15'!$V$3:$W$35,2,FALSE),'RES Assumptions T15'!$E$2:$S$2,0)) -> 0.14541311 | AK10: =IFERROR(SUMIFS('RES balance'!E$5:E$25,'RES balance'!$D$5:$D$25,'RES Assumptions'!$A10)*E10,"") -> 0.039866193 | AL10: =IFERROR(SUMIFS('RES balance'!F$5:F$25,'RES balance'!$D$5:$D$25,'RES Assumptions'!$A10)*F10,"") -> 1.6871018 | AM10: =IFERROR(SUMIFS('RES balance'!G$5:G$25,'RES balance'!$D$5:$D$25,'RES Assumptions'!$A10)*G10,"") -> 0 | AN10: =IFERROR(SUMIFS('RES balance'!H$5:H$25,'RES balance'!$D$5:$D$25,'RES Assumptions'!$A10)*H10,"") -> 10.207468 | AO10: =IFERROR(SUMIFS('RES balance'!I$5:I$25,'RES balance'!$D$5:$D$25,'RES Assumptions'!$A10)*I10,"") -> 10.895194 | AP10: =IFERROR(SUMIFS('RES balance'!J$5:J$25,'RES balance'!$D$5:$D$25,'RES Assumptions'!$A10)*J10,"") -> 0.30636738 | AQ10: =IFERROR(SUMIFS('RES balance'!K$5:K$25,'RES balance'!$D$5:$D$25,'RES Assumptions'!$A10)*K10,"") -> 0.05676588 | AR10: =IFERROR(SUMIFS('RES balance'!L$5:L$25,'RES balance'!$D$5:$D$25,'RES Assumptions'!$A10)*L10,"") -> 0 | ... BN10: =IFERROR(SUMIFS('RES balance'!AH$5:AH$25,'RES balance'!$D$5:$D$25,'RES Assumptions'!$A10)*AH10,"") -> 0
A11: =VLOOKUP(C11,'RES balance'!$AL$5:$AM$25,2,FALSE) -> RESOIL | C11: Distallate | D11: RK | E11: =OFFSET('RES Assumptions T15'!$D11,0,MATCH(VLOOKUP('RES Assumptions'!E$2,'RES Assumptions T15'!$V$3:$W$35,2,FALSE),'RES Assumptions T15'!$E$2:$S$2,0)) -> 0.85970763 | F11: =OFFSET('RES Assumptions T15'!$D11,0,MATCH(VLOOKUP('RES Assumptions'!F$2,'RES Assumptions T15'!$V$3:$W$35,2,FALSE),'RES Assumptions T15'!$E$2:$S$2,0)) -> 0.85970763 | G11: =OFFSET('RES Assumptions T15'!$D11,0,MATCH(VLOOKUP('RES Assumptions'!G$2,'RES Assumptions T15'!$V$3:$W$35,2,FALSE),'RES Assumptions T15'!$E$2:$S$2,0)) -> 0.70693721 | H11: =OFFSET('RES Assumptions T15'!$D11,0,MATCH(VLOOKUP('RES Assumptions'!H$2,'RES Assumptions T15'!$V$3:$W$35,2,FALSE),'RES Assumptions T15'!$E$2:$S$2,0)) -> 0.15909809 | I11: =OFFSET('RES Assumptions T15'!$D11,0,MATCH(VLOOKUP('RES Assumptions'!I$2,'RES Assumptions T15'!$V$3:$W$35,2,FALSE),'RES Assumptions T15'!$E$2:$S$2,0)) -> 0.10753452 | J11: =OFFSET('RES Assumptions T15'!$D11,0,MATCH(VLOOKUP('RES Assumptions'!J$2,'RES Assumptions T15'!$V$3:$W$35,2,FALSE),'RES Assumptions T15'!$E$2:$S$2,0)) -> 0.89583576 | K11: =OFFSET('RES Assumptions T15'!$D11,0,MATCH(VLOOKUP('RES Assumptions'!K$2,'RES Assumptions T15'!$V$3:$W$35,2,FALSE),'RES Assumptions T15'!$E$2:$S$2,0)) -> 0.24427155 | L11: =OFFSET('RES Assumptions T15'!$D11,0,MATCH(VLOOKUP('RES Assumptions'!L$2,'RES Assumptions T15'!$V$3:$W$35,2,FALSE),'RES Assumptions T15'!$E$2:$S$2,0)) -> 0.70693721 | ... AH11: =OFFSET('RES Assumptions T15'!$D11,0,MATCH(VLOOKUP('RES Assumptions'!AH$2,'RES Assumptions T15'!$V$3:$W$35,2,FALSE),'RES Assumptions T15'!$E$2:$S$2,0)) -> 0.023056072 | AK11: =IFERROR(SUMIFS('RES balance'!E$5:E$25,'RES balance'!$D$5:$D$25,'RES Assumptions'!$A11)*E11,"") -> 0.30889176 | AL11: =IFERROR(SUMIFS('RES balance'!F$5:F$25,'RES balance'!$D$5:$D$25,'RES Assumptions'!$A11)*F11,"") -> 13.072024 | AM11: =IFERROR(SUMIFS('RES balance'!G$5:G$25,'RES balance'!$D$5:$D$25,'RES Assumptions'!$A11)*G11,"") -> 0 | AN11: =IFERROR(SUMIFS('RES balance'!H$5:H$25,'RES balance'!$D$5:$D$25,'RES Assumptions'!$A11)*H11,"") -> 16.772871 | AO11: =IFERROR(SUMIFS('RES balance'!I$5:I$25,'RES balance'!$D$5:$D$25,'RES Assumptions'!$A11)*I11,"") -> 3.3600459 | AP11: =IFERROR(SUMIFS('RES balance'!J$5:J$25,'RES balance'!$D$5:$D$25,'RES Assumptions'!$A11)*J11,"") -> 2.8004641 | AQ11: =IFERROR(SUMIFS('RES balance'!K$5:K$25,'RES balance'!$D$5:$D$25,'RES Assumptions'!$A11)*K11,"") -> 0.029725245 | AR11: =IFERROR(SUMIFS('RES balance'!L$5:L$25,'RES balance'!$D$5:$D$25,'RES Assumptions'!$A11)*L11,"") -> 0 | ... BN11: =IFERROR(SUMIFS('RES balance'!AH$5:AH$25,'RES balance'!$D$5:$D$25,'RES Assumptions'!$A11)*AH11,"") -> 0
A12: =VLOOKUP(C12,'RES balance'!$AL$5:$AM$25,2,FALSE) -> RESOIL | C12: Distallate | D12: ROT | E12: =OFFSET('RES Assumptions T15'!$D12,0,MATCH(VLOOKUP('RES Assumptions'!E$2,'RES Assumptions T15'!$V$3:$W$35,2,FALSE),'RES Assumptions T15'!$E$2:$S$2,0)) -> 0.018137279 | F12: =OFFSET('RES Assumptions T15'!$D12,0,MATCH(VLOOKUP('RES Assumptions'!F$2,'RES Assumptions T15'!$V$3:$W$35,2,FALSE),'RES Assumptions T15'!$E$2:$S$2,0)) -> 0.018137279 | G12: =OFFSET('RES Assumptions T15'!$D12,0,MATCH(VLOOKUP('RES Assumptions'!G$2,'RES Assumptions T15'!$V$3:$W$35,2,FALSE),'RES Assumptions T15'!$E$2:$S$2,0)) -> 0.12165195 | H12: =OFFSET('RES Assumptions T15'!$D12,0,MATCH(VLOOKUP('RES Assumptions'!H$2,'RES Assumptions T15'!$V$3:$W$35,2,FALSE),'RES Assumptions T15'!$E$2:$S$2,0)) -> 0.0021213736 | I12: =OFFSET('RES Assumptions T15'!$D12,0,MATCH(VLOOKUP('RES Assumptions'!I$2,'RES Assumptions T15'!$V$3:$W$35,2,FALSE),'RES Assumptions T15'!$E$2:$S$2,0)) -> 0 | J12: =OFFSET('RES Assumptions T15'!$D12,0,MATCH(VLOOKUP('RES Assumptions'!J$2,'RES Assumptions T15'!$V$3:$W$35,2,FALSE),'RES Assumptions T15'!$E$2:$S$2,0)) -> 0.0061608878 | K12: =OFFSET('RES Assumptions T15'!$D12,0,MATCH(VLOOKUP('RES Assumptions'!K$2,'RES Assumptions T15'!$V$3:$W$35,2,FALSE),'RES Assumptions T15'!$E$2:$S$2,0)) -> 0 | L12: =OFFSET('RES Assumptions T15'!$D12,0,MATCH(VLOOKUP('RES Assumptions'!L$2,'RES Assumptions T15'!$V$3:$W$35,2,FALSE),'RES Assumptions T15'!$E$2:$S$2,0)) -> 0.12165195 | ... AH12: =OFFSET('RES Assumptions T15'!$D12,0,MATCH(VLOOKUP('RES Assumptions'!AH$2,'RES Assumptions T15'!$V$3:$W$35,2,FALSE),'RES Assumptions T15'!$E$2:$S$2,0)) -> 0 | AK12: =IFERROR(SUMIFS('RES balance'!E$5:E$25,'RES balance'!$D$5:$D$25,'RES Assumptions'!$A12)*E12,"") -> 0.0065166991 | AL12: =IFERROR(SUMIFS('RES balance'!F$5:F$25,'RES balance'!$D$5:$D$25,'RES Assumptions'!$A12)*F12,"") -> 0.2757809 | AM12: =IFERROR(SUMIFS('RES balance'!G$5:G$25,'RES balance'!$D$5:$D$25,'RES Assumptions'!$A12)*G12,"") -> 0 | AN12: =IFERROR(SUMIFS('RES balance'!H$5:H$25,'RES balance'!$D$5:$D$25,'RES Assumptions'!$A12)*H12,"") -> 0.2236452 | AO12: =IFERROR(SUMIFS('RES balance'!I$5:I$25,'RES balance'!$D$5:$D$25,'RES Assumptions'!$A12)*I12,"") -> 0 | AP12: =IFERROR(SUMIFS('RES balance'!J$5:J$25,'RES balance'!$D$5:$D$25,'RES Assumptions'!$A12)*J12,"") -> 0.019259496 | AQ12: =IFERROR(SUMIFS('RES balance'!K$5:K$25,'RES balance'!$D$5:$D$25,'RES Assumptions'!$A12)*K12,"") -> 0 | AR12: =IFERROR(SUMIFS('RES balance'!L$5:L$25,'RES balance'!$D$5:$D$25,'RES Assumptions'!$A12)*L12,"") -> 0 | ... BN12: =IFERROR(SUMIFS('RES balance'!AH$5:AH$25,'RES balance'!$D$5:$D$25,'RES Assumptions'!$A12)*AH12,"") -> 0
A13: =VLOOKUP(C13,'RES balance'!$AL$5:$AM$25,2,FALSE) -> 0 | C13: Heavy | D13: RH | E13: =OFFSET('RES Assumptions T15'!$D13,0,MATCH(VLOOKUP('RES Assumptions'!E$2,'RES Assumptions T15'!$V$3:$W$35,2,FALSE),'RES Assumptions T15'!$E$2:$S$2,0)) -> 1 | F13: =OFFSET('RES Assumptions T15'!$D13,0,MATCH(VLOOKUP('RES Assumptions'!F$2,'RES Assumptions T15'!$V$3:$W$35,2,FALSE),'RES Assumptions T15'!$E$2:$S$2,0)) -> 1 | G13: =OFFSET('RES Assumptions T15'!$D13,0,MATCH(VLOOKUP('RES Assumptions'!G$2,'RES Assumptions T15'!$V$3:$W$35,2,FALSE),'RES Assumptions T15'!$E$2:$S$2,0)) -> 1 | H13: =OFFSET('RES Assumptions T15'!$D13,0,MATCH(VLOOKUP('RES Assumptions'!H$2,'RES Assumptions T15'!$V$3:$W$35,2,FALSE),'RES Assumptions T15'!$E$2:$S$2,0)) -> 0.9 | I13: =OFFSET('RES Assumptions T15'!$D13,0,MATCH(VLOOKUP('RES Assumptions'!I$2,'RES Assumptions T15'!$V$3:$W$35,2,FALSE),'RES Assumptions T15'!$E$2:$S$2,0)) -> 1 | J13: =OFFSET('RES Assumptions T15'!$D13,0,MATCH(VLOOKUP('RES Assumptions'!J$2,'RES Assumptions T15'!$V$3:$W$35,2,FALSE),'RES Assumptions T15'!$E$2:$S$2,0)) -> 1 | K13: =OFFSET('RES Assumptions T15'!$D13,0,MATCH(VLOOKUP('RES Assumptions'!K$2,'RES Assumptions T15'!$V$3:$W$35,2,FALSE),'RES Assumptions T15'!$E$2:$S$2,0)) -> 1 | L13: =OFFSET('RES Assumptions T15'!$D13,0,MATCH(VLOOKUP('RES Assumptions'!L$2,'RES Assumptions T15'!$V$3:$W$35,2,FALSE),'RES Assumptions T15'!$E$2:$S$2,0)) -> 1 | ... AH13: =OFFSET('RES Assumptions T15'!$D13,0,MATCH(VLOOKUP('RES Assumptions'!AH$2,'RES Assumptions T15'!$V$3:$W$35,2,FALSE),'RES Assumptions T15'!$E$2:$S$2,0)) -> 1 | AK13: =IFERROR(SUMIFS('RES balance'!E$5:E$25,'RES balance'!$D$5:$D$25,'RES Assumptions'!$A13)*E13,"") -> 0 | AL13: =IFERROR(SUMIFS('RES balance'!F$5:F$25,'RES balance'!$D$5:$D$25,'RES Assumptions'!$A13)*F13,"") -> 0 | AM13: =IFERROR(SUMIFS('RES balance'!G$5:G$25,'RES balance'!$D$5:$D$25,'RES Assumptions'!$A13)*G13,"") -> 0 | AN13: =IFERROR(SUMIFS('RES balance'!H$5:H$25,'RES balance'!$D$5:$D$25,'RES Assumptions'!$A13)*H13,"") -> 0 | AO13: =IFERROR(SUMIFS('RES balance'!I$5:I$25,'RES balance'!$D$5:$D$25,'RES Assumptions'!$A13)*I13,"") -> 0 | AP13: =IFERROR(SUMIFS('RES balance'!J$5:J$25,'RES balance'!$D$5:$D$25,'RES Assumptions'!$A13)*J13,"") -> 0 | AQ13: =IFERROR(SUMIFS('RES balance'!K$5:K$25,'RES balance'!$D$5:$D$25,'RES Assumptions'!$A13)*K13,"") -> 0 | AR13: =IFERROR(SUMIFS('RES balance'!L$5:L$25,'RES balance'!$D$5:$D$25,'RES Assumptions'!$A13)*L13,"") -> 0 | ... BN13: =IFERROR(SUMIFS('RES balance'!AH$5:AH$25,'RES balance'!$D$5:$D$25,'RES Assumptions'!$A13)*AH13,"") -> 0
