Workbook

Sheet veda - techs
B2: ~FI_T | J2: ~FI_Process
B3: techname | C3: comm-in | D3: comm-out | E3: LIFE | F3: ILED | G3: AFC~ACT | H3: AFC~NRG | J3: region | K3: sets | L3: techname | M3: tact | N3: tcap | O3: tslvl | P3: techdesc
B4: =L4 -> en_gas_ccgt | C4: ELCNGA | D4: ELC | E4: =unified_reference_costs!J2 -> 30 | F4: =unified_reference_costs!K2 -> 3 | J4: {=IFERROR(_xlfn.TEXTJOIN(",",TRUE,_xlfn.UNIQUE(_xlfn._xlws.FILTER(unified_reference_costs!B:B,(unified_reference_costs!A:A=L4)*(unified_reference_costs!D:D="efficiency")))),"")} -> ieapg_european_union,ieapg_united_states,ieapg_japan,ieapg_russia,ieapg_china,ieapg_india,ieapg_middle_east,ieapg_africa,ieapg_brazil | K4: ELE | L4: =unified_reference_costs!J41 -> en_gas_ccgt | M4: PJ | N4: GW | O4: daynite | P4: =unified_reference_costs!M2 -> Natural gas 2-on-1 combined cycle (F-Frame). IEA GEC: CCGT; ATB: CCAvgCF
B5: =L5 -> en_gas_turbine | C5: ELCNGA | D5: ELC | E5: =unified_reference_costs!J3 -> 30 | F5: =unified_reference_costs!K3 -> 2 | J5: {=IFERROR(_xlfn.TEXTJOIN(",",TRUE,_xlfn.UNIQUE(_xlfn._xlws.FILTER(unified_reference_costs!B:B,(unified_reference_costs!A:A=L5)*(unified_reference_costs!D:D="efficiency")))),"")} -> ieapg_european_union,ieapg_united_states,ieapg_japan,ieapg_russia,ieapg_china,ieapg_india,ieapg_middle_east,ieapg_africa,ieapg_brazil | K5: ELE | L5: =unified_reference_costs!J42 -> en_gas_turbine | M5: PJ | N5: GW | O5: daynite | P5: =unified_reference_costs!M3 -> Natural gas open-cycle combustion turbine (F-Frame, peaking). IEA GEC: Gas turbine; ATB: CTAvgCF
B6: =L6 -> en_gas_chp | C6: ELCNGA | D6: ELC,HET | E6: =unified_reference_costs!J4 -> 25 | F6: =unified_reference_costs!K4 -> 3 | J6: {=IFERROR(_xlfn.TEXTJOIN(",",TRUE,_xlfn.UNIQUE(_xlfn._xlws.FILTER(unified_reference_costs!B:B,(unified_reference_costs!A:A=L6)*(unified_reference_costs!D:D="efficiency")))),"")} -> ieapg_european_union,ieapg_united_states,ieapg_japan,ieapg_russia,ieapg_china,ieapg_india,ieapg_middle_east,ieapg_africa,ieapg_brazil | K6: CHP | L6: =unified_reference_costs!J43 -> en_gas_chp | M6: PJ | N6: GW | O6: daynite | P6: =unified_reference_costs!M4 -> Natural gas CCGT combined heat and power. IEA GEC: CCGT-CHP. Produces electricity + useful heat (LHV basis)
B7: =L7 -> \I: | E7: =unified_reference_costs!J5 -> 20 | F7: =unified_reference_costs!K5 -> 2 | J7: {=IFERROR(_xlfn.TEXTJOIN(",",TRUE,_xlfn.UNIQUE(_xlfn._xlws.FILTER(unified_reference_costs!B:B,(unified_reference_costs!A:A=L7)*(unified_reference_costs!D:D="efficiency")))),"")} | K7: ELE | L7: =unified_reference_costs!J44 -> \I: | M7: PJ | N7: GW | O7: daynite | P7: =unified_reference_costs!M5 -> Natural gas fuel cell. IEA GEC: Fuel cell
B8: =L8 -> en_gas_ccs | C8: ELCNGA | D8: ELC,CO2Captured_elc | E8: =unified_reference_costs!J6 -> 30 | F8: =unified_reference_costs!K6 -> 4 | J8: {=IFERROR(_xlfn.TEXTJOIN(",",TRUE,_xlfn.UNIQUE(_xlfn._xlws.FILTER(unified_reference_costs!B:B,(unified_reference_costs!A:A=L8)*(unified_reference_costs!D:D="efficiency")))),"")} -> ieapg_european_union,ieapg_united_states,ieapg_japan,ieapg_russia,ieapg_china,ieapg_india,ieapg_middle_east,ieapg_africa | K8: ELE | L8: =unified_reference_costs!J45 -> en_gas_ccs | M8: PJ | N8: GW | O8: daynite | P8: =unified_reference_costs!M6 -> Natural gas CCGT with 95% post-combustion CCS. IEA GEC: CCGT+CCS; ATB: CCCCSAvgCF
B9: =L9 -> en_coal_subcritical | C9: ELCCOA | D9: ELC | E9: =unified_reference_costs!J7 -> 40 | F9: =unified_reference_costs!K7 -> 4 | J9: {=IFERROR(_xlfn.TEXTJOIN(",",TRUE,_xlfn.UNIQUE(_xlfn._xlws.FILTER(unified_reference_costs!B:B,(unified_reference_costs!A:A=L9)*(unified_reference_costs!D:D="efficiency")))),"")} -> ieapg_european_union,ieapg_united_states,ieapg_japan,ieapg_russia,ieapg_china,ieapg_india,ieapg_middle_east,ieapg_africa,ieapg_brazil | K9: ELE | L9: =unified_reference_costs!J46 -> en_coal_subcritical | M9: PJ | N9: GW | O9: season | P9: =unified_reference_costs!M7 -> Coal subcritical steam cycle. IEA GEC: Subcritical
B10: =L10 -> en_coal_supercritical | C10: ELCCOA | D10: ELC | E10: =unified_reference_costs!J8 -> 40 | F10: =unified_reference_costs!K8 -> 4 | J10: {=IFERROR(_xlfn.TEXTJOIN(",",TRUE,_xlfn.UNIQUE(_xlfn._xlws.FILTER(unified_reference_costs!B:B,(unified_reference_costs!A:A=L10)*(unified_reference_costs!D:D="efficiency")))),"")} -> ieapg_european_union,ieapg_united_states,ieapg_japan,ieapg_russia,ieapg_china,ieapg_india,ieapg_middle_east,ieapg_africa,ieapg_brazil | K10: ELE | L10: =unified_reference_costs!J47 -> en_coal_supercritical | M10: PJ | N10: GW | O10: season | P10: =unified_reference_costs!M8 -> Coal supercritical steam cycle. IEA GEC: Supercritical; ATB: newAvgCF
B11: =L11 -> en_coal_ultrasupercritical | C11: ELCCOA | D11: ELC | E11: =unified_reference_costs!J9 -> 40 | F11: =unified_reference_costs!K9 -> 4 | J11: {=IFERROR(_xlfn.TEXTJOIN(",",TRUE,_xlfn.UNIQUE(_xlfn._xlws.FILTER(unified_reference_costs!B:B,(unified_reference_costs!A:A=L11)*(unified_reference_costs!D:D="efficiency")))),"")} -> ieapg_european_union,ieapg_united_states,ieapg_japan,ieapg_russia,ieapg_china,ieapg_india,ieapg_middle_east,ieapg_africa,ieapg_brazil | K11: ELE | L11: =unified_reference_costs!J48 -> en_coal_ultrasupercritical | M11: PJ | N11: GW | O11: season | P11: =unified_reference_costs!M9 -> Coal ultra-supercritical steam cycle. IEA GEC: Ultra-supercritical
B12: =L12 -> en_coal_igcc | C12: ELCCOA | D12: ELC | E12: =unified_reference_costs!J10 -> 40 | F12: =unified_reference_costs!K10 -> 4 | J12: {=IFERROR(_xlfn.TEXTJOIN(",",TRUE,_xlfn.UNIQUE(_xlfn._xlws.FILTER(unified_reference_costs!B:B,(unified_reference_costs!A:A=L12)*(unified_reference_costs!D:D="efficiency")))),"")} -> ieapg_european_union,ieapg_united_states,ieapg_japan,ieapg_russia,ieapg_china,ieapg_india,ieapg_middle_east,ieapg_africa,ieapg_brazil | K12: ELE | L12: =unified_reference_costs!J49 -> en_coal_igcc | M12: PJ | N12: GW | O12: season | P12: =unified_reference_costs!M10 -> Coal integrated gasification combined cycle. IEA GEC: IGCC; ATB: IGCCAvgCF
B13: =L13 -> en_coal_ccs | C13: ELCCOA | D13: ELC,CO2Captured_elc | E13: =unified_reference_costs!J11 -> 40 | F13: =unified_reference_costs!K11 -> 5 | J13: {=IFERROR(_xlfn.TEXTJOIN(",",TRUE,_xlfn.UNIQUE(_xlfn._xlws.FILTER(unified_reference_costs!B:B,(unified_reference_costs!A:A=L13)*(unified_reference_costs!D:D="efficiency")))),"")} -> ieapg_european_union,ieapg_united_states,ieapg_japan,ieapg_russia,ieapg_china,ieapg_india,ieapg_africa | K13: ELE | L13: =unified_reference_costs!J50 -> en_coal_ccs | M13: PJ | N13: GW | O13: season | P13: =unified_reference_costs!M11 -> Coal post-combustion with 95% CCS. IEA GEC: Coal+CCS; ATB: CCS95AvgCF
B14: =L14 -> \I: | E14: =unified_reference_costs!J12 -> 40 | F14: =unified_reference_costs!K12 -> 5 | J14: {=IFERROR(_xlfn.TEXTJOIN(",",TRUE,_xlfn.UNIQUE(_xlfn._xlws.FILTER(unified_reference_costs!B:B,(unified_reference_costs!A:A=L14)*(unified_reference_costs!D:D="efficiency")))),"")} | K14: ELE | L14: =unified_reference_costs!J51 -> \I: | M14: PJ | N14: GW | O14: daynite | P14: =unified_reference_costs!M12 -> Coal oxyfuel combustion with CCS. IEA GEC: Oxyfuel+CCS
B15: =L15 -> en_coal_igcc_ccs | C15: ELCCOA | D15: ELC,CO2Captured_elc | E15: =unified_reference_costs!J13 -> 40 | F15: =unified_reference_costs!K13 -> 5 | J15: {=IFERROR(_xlfn.TEXTJOIN(",",TRUE,_xlfn.UNIQUE(_xlfn._xlws.FILTER(unified_reference_costs!B:B,(unified_reference_costs!A:A=L15)*(unified_reference_costs!D:D="efficiency")))),"")} -> ieapg_european_union,ieapg_united_states,ieapg_japan,ieapg_russia,ieapg_china,ieapg_india,ieapg_africa | K15: ELE | L15: =unified_reference_costs!J52 -> en_coal_igcc_ccs | M15: PJ | N15: GW | O15: season | P15: =unified_reference_costs!M13 -> Coal IGCC with CCS. IEA GEC: IGCC+CCS
B16: =L16 -> en_nuclear | C16: ELCNUC | D16: ELC | E16: =unified_reference_costs!J14 -> 60 | F16: =unified_reference_costs!K14 -> 7 | J16: {=IFERROR(_xlfn.TEXTJOIN(",",TRUE,_xlfn.UNIQUE(_xlfn._xlws.FILTER(unified_reference_costs!B:B,(unified_reference_costs!A:A=L16)*(unified_reference_costs!D:D="efficiency")))),"")} | K16: ELE | L16: =unified_reference_costs!J53 -> en_nuclear | M16: PJ | N16: GW | O16: season | P16: =unified_reference_costs!M14 -> Nuclear large reactor (Gen III/III+). IEA GEC: Nuclear; ATB: Nuclear - Large. Life 60yr, constr 7yr
B17: =L17 -> en_nuclear_smr | C17: ELCNUC | D17: ELC | E17: =unified_reference_costs!J15 -> 40 | F17: =unified_reference_costs!K15 -> 3 | J17: {=IFERROR(_xlfn.TEXTJOIN(",",TRUE,_xlfn.UNIQUE(_xlfn._xlws.FILTER(unified_reference_costs!B:B,(unified_reference_costs!A:A=L17)*(unified_reference_costs!D:D="efficiency")))),"")} | K17: ELE | L17: =unified_reference_costs!J54 -> en_nuclear_smr | M17: PJ | N17: GW | O17: daynite | P17: =unified_reference_costs!M15 -> Nuclear small modular reactor. ATB: Nuclear - Small. Regional costs scaled from IEA large nuclear ratios. Life 40yr, constr 3yr
B18: =L18 -> \I: | E18: =unified_reference_costs!J16 -> 30 | F18: =unified_reference_costs!K16 -> 1.5 | J18: {=IFERROR(_xlfn.TEXTJOIN(",",TRUE,_xlfn.UNIQUE(_xlfn._xlws.FILTER(unified_reference_costs!B:B,(unified_reference_costs!A:A=L18)*(unified_reference_costs!D:D="efficiency")))),"")} | K18: ELE | L18: =unified_reference_costs!J55 -> \I: | M18: PJ | N18: GW | O18: daynite | P18: =unified_reference_costs!M16 -> Solar PV utility-scale. IEA GEC: Solar PV large-scale; ATB: UtilityPV Class5
B19: =L19 -> \I: | E19: =unified_reference_costs!J17 -> 30 | F19: =unified_reference_costs!K17 -> 3 | J19: {=IFERROR(_xlfn.TEXTJOIN(",",TRUE,_xlfn.UNIQUE(_xlfn._xlws.FILTER(unified_reference_costs!B:B,(unified_reference_costs!A:A=L19)*(unified_reference_costs!D:D="efficiency")))),"")} | K19: ELE | L19: =unified_reference_costs!J56 -> \I: | M19: PJ | N19: GW | O19: daynite | P19: =unified_reference_costs!M17 -> Concentrated solar power with thermal storage. IEA GEC: CSP; ATB: CSP Class2
B20: =L20 -> \I: | E20: =unified_reference_costs!J18 -> 30 | F20: =unified_reference_costs!K18 -> 1.5 | J20: {=IFERROR(_xlfn.TEXTJOIN(",",TRUE,_xlfn.UNIQUE(_xlfn._xlws.FILTER(unified_reference_costs!B:B,(unified_reference_costs!A:A=L20)*(unified_reference_costs!D:D="efficiency")))),"")} | K20: ELE | L20: =unified_reference_costs!J57 -> \I: | M20: PJ | N20: GW | O20: daynite | P20: =unified_reference_costs!M18 -> Wind onshore. IEA GEC: Wind onshore; ATB: LandbasedWind Class4
B21: =L21 -> \I: | E21: =unified_reference_costs!J19 -> 30 | F21: =unified_reference_costs!K19 -> 3 | J21: {=IFERROR(_xlfn.TEXTJOIN(",",TRUE,_xlfn.UNIQUE(_xlfn._xlws.FILTER(unified_reference_costs!B:B,(unified_reference_costs!A:A=L21)*(unified_reference_costs!D:D="efficiency")))),"")} | K21: ELE | L21: =unified_reference_costs!J58 -> \I: | M21: PJ | N21: GW | O21: daynite | P21: =unified_reference_costs!M19 -> Wind offshore (bottom-fixed/floating). IEA GEC: Wind offshore; ATB: OffShoreWind Class3
B22: =L22 -> \I: | E22: =unified_reference_costs!J20 -> 100 | F22: =unified_reference_costs!K20 -> 4 | J22: {=IFERROR(_xlfn.TEXTJOIN(",",TRUE,_xlfn.UNIQUE(_xlfn._xlws.FILTER(unified_reference_costs!B:B,(unified_reference_costs!A:A=L22)*(unified_reference_costs!D:D="efficiency")))),"")} | K22: ELE | L22: =unified_reference_costs!J59 -> \I: | M22: PJ | N22: GW | O22: daynite | P22: =unified_reference_costs!M20 -> Hydropower large-scale. IEA GEC: Hydropower large; ATB: NPD4
B23: =L23 -> \I: | E23: =unified_reference_costs!J21 -> 60 | F23: =unified_reference_costs!K21 -> 4 | J23: {=IFERROR(_xlfn.TEXTJOIN(",",TRUE,_xlfn.UNIQUE(_xlfn._xlws.FILTER(unified_reference_costs!B:B,(unified_reference_costs!A:A=L23)*(unified_reference_costs!D:D="efficiency")))),"")} | K23: ELE | L23: =unified_reference_costs!J60 -> \I: | M23: PJ | N23: GW | O23: daynite | P23: =unified_reference_costs!M21 -> Hydropower small-scale. IEA GEC: Hydropower small
B24: =L24 -> en_biomass | C24: ELCBIO | D24: ELC | E24: =unified_reference_costs!J22 -> 45 | F24: =unified_reference_costs!K22 -> 3 | J24: {=IFERROR(_xlfn.TEXTJOIN(",",TRUE,_xlfn.UNIQUE(_xlfn._xlws.FILTER(unified_reference_costs!B:B,(unified_reference_costs!A:A=L24)*(unified_reference_costs!D:D="efficiency")))),"")} -> ieapg_european_union,ieapg_united_states,ieapg_japan,ieapg_russia,ieapg_china,ieapg_india,ieapg_middle_east,ieapg_africa,ieapg_brazil | K24: ELE | L24: =unified_reference_costs!J61 -> en_biomass | M24: PJ | N24: GW | O24: daynite | P24: =unified_reference_costs!M22 -> Biomass dedicated large-scale. IEA GEC: Bioenergy large-scale; ATB: Biopower Dedicated
B25: =L25 -> \I: | E25: =unified_reference_costs!J23 -> 40 | F25: =unified_reference_costs!K23 -> 2 | J25: {=IFERROR(_xlfn.TEXTJOIN(",",TRUE,_xlfn.UNIQUE(_xlfn._xlws.FILTER(unified_reference_costs!B:B,(unified_reference_costs!A:A=L25)*(unified_reference_costs!D:D="efficiency")))),"")} | K25: ELE | L25: =unified_reference_costs!J62 -> \I: | M25: PJ | N25: GW | O25: daynite | P25: =unified_reference_costs!M23 -> Biomass cofiring â€” incremental investment for blending in existing coal plants. IEA GEC: Bioenergy cofiring
B26: =L26 -> en_biomass_chp | C26: ELCBIO | D26: ELC,HET | E26: =unified_reference_costs!J24 -> 25 | F26: =unified_reference_costs!K24 -> 2 | J26: {=IFERROR(_xlfn.TEXTJOIN(",",TRUE,_xlfn.UNIQUE(_xlfn._xlws.FILTER(unified_reference_costs!B:B,(unified_reference_costs!A:A=L26)*(unified_reference_costs!D:D="efficiency")))),"")} -> ieapg_european_union,ieapg_united_states,ieapg_japan,ieapg_russia,ieapg_china,ieapg_india,ieapg_middle_east,ieapg_africa,ieapg_brazil | K26: CHP | L26: =unified_reference_costs!J63 -> en_biomass_chp | M26: PJ | N26: GW | O26: daynite | P26: =unified_reference_costs!M24 -> Biomass medium-scale combined heat and power. IEA GEC: Bioenergy medium-scale CHP
B27: =L27 -> en_biomass_ccs | C27: ELCBIO | D27: ELC,CO2Captured_elc | E27: =unified_reference_costs!J25 -> 30 | F27: =unified_reference_costs!K25 -> 3 | J27: {=IFERROR(_xlfn.TEXTJOIN(",",TRUE,_xlfn.UNIQUE(_xlfn._xlws.FILTER(unified_reference_costs!B:B,(unified_reference_costs!A:A=L27)*(unified_reference_costs!D:D="efficiency")))),"")} -> ieapg_european_union,ieapg_united_states,ieapg_japan,ieapg_russia,ieapg_china,ieapg_india,ieapg_middle_east,ieapg_africa,ieapg_brazil | K27: ELE | L27: =unified_reference_costs!J64 -> en_biomass_ccs | M27: PJ | N27: GW | O27: season | P27: =unified_reference_costs!M25 -> Biomass with carbon capture and storage (BECCS). IEA GEC: Bioenergy+CCUS
B28: =L28 -> \I: | E28: =unified_reference_costs!J26 -> 30 | F28: =unified_reference_costs!K26 -> 4 | J28: {=IFERROR(_xlfn.TEXTJOIN(",",TRUE,_xlfn.UNIQUE(_xlfn._xlws.FILTER(unified_reference_costs!B:B,(unified_reference_costs!A:A=L28)*(unified_reference_costs!D:D="efficiency")))),"")} | K28: ELE | L28: =unified_reference_costs!J65 -> \I: | M28: PJ | N28: GW | O28: daynite | P28: =unified_reference_costs!M26 -> Geothermal hydrothermal flash. IEA GEC: Geothermal; ATB: HydroFlash
B29: =L29 -> en_battery_4h | D29: ELC | E29: =unified_reference_costs!J27 -> 20 | F29: =unified_reference_costs!K27 -> 1 | G29: =4/24 -> 0.16666667 | H29: 1 | J29: {=IFERROR(_xlfn.TEXTJOIN(",",TRUE,_xlfn.UNIQUE(_xlfn._xlws.FILTER(unified_reference_costs!B:B,(unified_reference_costs!A:A=L29)*(unified_reference_costs!D:D="efficiency")))),"")} | K29: STG | L29: =unified_reference_costs!J66 -> en_battery_4h | M29: PJ | N29: GW | O29: daynite | P29: =unified_reference_costs!M27 -> Utility-scale Li-ion battery, 4-hour duration. ATB only (no IEA GEC). Uniform cost across regions
B30: =L30 -> en_battery_8h | D30: ELC | E30: =unified_reference_costs!J28 -> 20 | F30: =unified_reference_costs!K28 -> 1 | G30: =8/24 -> 0.33333333 | H30: 1 | J30: {=IFERROR(_xlfn.TEXTJOIN(",",TRUE,_xlfn.UNIQUE(_xlfn._xlws.FILTER(unified_reference_costs!B:B,(unified_reference_costs!A:A=L30)*(unified_reference_costs!D:D="efficiency")))),"")} | K30: STG | L30: =unified_reference_costs!J67 -> en_battery_8h | M30: PJ | N30: GW | O30: daynite | P30: =unified_reference_costs!M28 -> Utility-scale Li-ion battery, 8-hour duration. ATB only (no IEA GEC). Uniform cost across regions

Sheet veda - data
B2: ~FI_T: USD22 | Q2: Sum of value | R2: Column Labels
B3: process | C3: attribute | D3: year | E3: ieapg_africa | F3: ieapg_brazil | G3: ieapg_china | H3: ieapg_india | I3: ieapg_japan | J3: ieapg_russia | K3: ieapg_european_union | L3: ieapg_united_states | M3: ieapg_middle_east | Q3: Row Labels | R3: ieapg_africa | S3: ieapg_brazil | T3: ieapg_china | U3: ieapg_india | V3: ieapg_japan | W3: ieapg_russia | X3: ieapg_european_union | Y3: ieapg_united_states | Z3: ieapg_middle_east
C4: =IFERROR(VLOOKUP(Q4,unified_reference_costs!$I$31:$J$41,2,FALSE),"*") -> * | D4: =IF(ISNUMBER(Q4),Q4,D3) -> 2022 | Q4: 2022
B5: =IFERROR(VLOOKUP(Q5,unified_reference_costs!$I$41:$J$69,2,FALSE),B4) -> en_gas_ccgt | C5: =IFERROR(VLOOKUP(Q5,unified_reference_costs!$I$31:$J$40,2,FALSE),"*") -> * | D5: =IF(ISNUMBER(Q5),Q5,D4) -> 2022 | Q5: en_gas_ccgt
B6: =IFERROR(VLOOKUP(Q6,unified_reference_costs!$I$41:$J$69,2,FALSE),B5) -> en_gas_ccgt | C6: =IFERROR(VLOOKUP(Q6,unified_reference_costs!$I$31:$J$40,2,FALSE),"*") -> invcost | D6: =IF(ISNUMBER(Q6),Q6,D5) -> 2022 | E6: =IF(R6="","",R6) -> 700 | F6: =IF(S6="","",S6) -> 700 | G6: =IF(T6="","",T6) -> 560 | H6: =IF(U6="","",U6) -> 700 | I6: =IF(V6="","",V6) -> 1100 | J6: =IF(W6="","",W6) -> 800 | K6: =IF(X6="","",X6) -> 1000 | L6: =IF(Y6="","",Y6) -> 1000 | M6: =IF(Z6="","",Z6) -> 800 | Q6: capex_mid | R6: 700 | S6: 700 | T6: 560 | U6: 700 | V6: 1100 | W6: 800 | X6: 1000 | Y6: 1000 | Z6: 800
B7: =IFERROR(VLOOKUP(Q7,unified_reference_costs!$I$41:$J$69,2,FALSE),B6) -> en_gas_ccgt | C7: =IFERROR(VLOOKUP(Q7,unified_reference_costs!$I$31:$J$40,2,FALSE),"*") -> efficiency | D7: =IF(ISNUMBER(Q7),Q7,D6) -> 2022 | E7: =IF(R7="","",R7) -> 0.58 | F7: =IF(S7="","",S7) -> 0.58 | G7: =IF(T7="","",T7) -> 0.57 | H7: =IF(U7="","",U7) -> 0.56 | I7: =IF(V7="","",V7) -> 0.59 | J7: =IF(W7="","",W7) -> 0.57 | K7: =IF(X7="","",X7) -> 0.59 | L7: =IF(Y7="","",Y7) -> 0.59 | M7: =IF(Z7="","",Z7) -> 0.57 | Q7: efficiency | R7: 0.58 | S7: 0.58 | T7: 0.57 | U7: 0.56 | V7: 0.59 | W7: 0.57 | X7: 0.59 | Y7: 0.59 | Z7: 0.57
B8: =IFERROR(VLOOKUP(Q8,unified_reference_costs!$I$41:$J$69,2,FALSE),B7) -> en_gas_ccgt | C8: =IFERROR(VLOOKUP(Q8,unified_reference_costs!$I$31:$J$40,2,FALSE),"*") -> fixom | D8: =IF(ISNUMBER(Q8),Q8,D7) -> 2022 | E8: =IF(R8="","",R8) -> 25 | F8: =IF(S8="","",S8) -> 25 | G8: =IF(T8="","",T8) -> 20 | H8: =IF(U8="","",U8) -> 25 | I8: =IF(V8="","",V8) -> 30 | J8: =IF(W8="","",W8) -> 30 | K8: =IF(X8="","",X8) -> 25 | L8: =IF(Y8="","",Y8) -> 25 | M8: =IF(Z8="","",Z8) -> 30 | Q8: fixed_om | R8: 25 | S8: 25 | T8: 20 | U8: 25 | V8: 30 | W8: 30 | X8: 25 | Y8: 25 | Z8: 30
B9: =IFERROR(VLOOKUP(Q9,unified_reference_costs!$I$41:$J$69,2,FALSE),B8) -> en_gas_ccgt | C9: =IFERROR(VLOOKUP(Q9,unified_reference_costs!$I$31:$J$40,2,FALSE),"*") -> varom | D9: =IF(ISNUMBER(Q9),Q9,D8) -> 2022 | E9: =IF(R9="","",R9) -> 0.603 | F9: =IF(S9="","",S9) -> 0.603 | G9: =IF(T9="","",T9) -> 0.603 | H9: =IF(U9="","",U9) -> 0.603 | I9: =IF(V9="","",V9) -> 0.603 | J9: =IF(W9="","",W9) -> 0.603 | K9: =IF(X9="","",X9) -> 0.603 | L9: =IF(Y9="","",Y9) -> 0.603 | M9: =IF(Z9="","",Z9) -> 0.603 | Q9: variable_om | R9: 0.603 | S9: 0.603 | T9: 0.603 | U9: 0.603 | V9: 0.603 | W9: 0.603 | X9: 0.603 | Y9: 0.603 | Z9: 0.603
B10: =IFERROR(VLOOKUP(Q10,unified_reference_costs!$I$41:$J$69,2,FALSE),B9) -> en_gas_turbine | C10: =IFERROR(VLOOKUP(Q10,unified_reference_costs!$I$31:$J$40,2,FALSE),"*") -> * | D10: =IF(ISNUMBER(Q10),Q10,D9) -> 2022 | E10: =IF(R10="","",R10) | F10: =IF(S10="","",S10) | G10: =IF(T10="","",T10) | H10: =IF(U10="","",U10) | I10: =IF(V10="","",V10) | J10: =IF(W10="","",W10) | K10: =IF(X10="","",X10) | L10: =IF(Y10="","",Y10) | M10: =IF(Z10="","",Z10) | Q10: en_gas_turbine
B11: =IFERROR(VLOOKUP(Q11,unified_reference_costs!$I$41:$J$69,2,FALSE),B10) -> en_gas_turbine | C11: =IFERROR(VLOOKUP(Q11,unified_reference_costs!$I$31:$J$40,2,FALSE),"*") -> invcost | D11: =IF(ISNUMBER(Q11),Q11,D10) -> 2022 | E11: =IF(R11="","",R11) -> 400 | F11: =IF(S11="","",S11) -> 400 | G11: =IF(T11="","",T11) -> 350 | H11: =IF(U11="","",U11) -> 400 | I11: =IF(V11="","",V11) -> 500 | J11: =IF(W11="","",W11) -> 450 | K11: =IF(X11="","",X11) -> 500 | L11: =IF(Y11="","",Y11) -> 500 | M11: =IF(Z11="","",Z11) -> 450 | Q11: capex_mid | R11: 400 | S11: 400 | T11: 350 | U11: 400 | V11: 500 | W11: 450 | X11: 500 | Y11: 500 | Z11: 450
B12: =IFERROR(VLOOKUP(Q12,unified_reference_costs!$I$41:$J$69,2,FALSE),B11) -> en_gas_turbine | C12: =IFERROR(VLOOKUP(Q12,unified_reference_costs!$I$31:$J$40,2,FALSE),"*") -> efficiency | D12: =IF(ISNUMBER(Q12),Q12,D11) -> 2022 | E12: =IF(R12="","",R12) -> 0.38 | F12: =IF(S12="","",S12) -> 0.38 | G12: =IF(T12="","",T12) -> 0.38 | H12: =IF(U12="","",U12) -> 0.38 | I12: =IF(V12="","",V12) -> 0.4 | J12: =IF(W12="","",W12) -> 0.38 | K12: =IF(X12="","",X12) -> 0.4 | L12: =IF(Y12="","",Y12) -> 0.4 | M12: =IF(Z12="","",Z12) -> 0.38 | Q12: efficiency | R12: 0.38 | S12: 0.38 | T12: 0.38 | U12: 0.38 | V12: 0.4 | W12: 0.38 | X12: 0.4 | Y12: 0.4 | Z12: 0.38
B13: =IFERROR(VLOOKUP(Q13,unified_reference_costs!$I$41:$J$69,2,FALSE),B12) -> en_gas_turbine | C13: =IFERROR(VLOOKUP(Q13,unified_reference_costs!$I$31:$J$40,2,FALSE),"*") -> fixom | D13: =IF(ISNUMBER(Q13),Q13,D12) -> 2022 | E13: =IF(R13="","",R13) -> 20 | F13: =IF(S13="","",S13) -> 20 | G13: =IF(T13="","",T13) -> 20 | H13: =IF(U13="","",U13) -> 20 | I13: =IF(V13="","",V13) -> 20 | J13: =IF(W13="","",W13) -> 25 | K13: =IF(X13="","",X13) -> 20 | L13: =IF(Y13="","",Y13) -> 20 | M13: =IF(Z13="","",Z13) -> 25 | Q13: fixed_om | R13: 20 | S13: 20 | T13: 20 | U13: 20 | V13: 20 | W13: 25 | X13: 20 | Y13: 20 | Z13: 25
B14: =IFERROR(VLOOKUP(Q14,unified_reference_costs!$I$41:$J$69,2,FALSE),B13) -> en_gas_turbine | C14: =IFERROR(VLOOKUP(Q14,unified_reference_costs!$I$31:$J$40,2,FALSE),"*") -> varom | D14: =IF(ISNUMBER(Q14),Q14,D13) -> 2022 | E14: =IF(R14="","",R14) -> 1.928 | F14: =IF(S14="","",S14) -> 1.928 | G14: =IF(T14="","",T14) -> 1.928 | H14: =IF(U14="","",U14) -> 1.928 | I14: =IF(V14="","",V14) -> 1.928 | J14: =IF(W14="","",W14) -> 1.928 | K14: =IF(X14="","",X14) -> 1.928 | L14: =IF(Y14="","",Y14) -> 1.928 | M14: =IF(Z14="","",Z14) -> 1.928 | Q14: variable_om | R14: 1.928 | S14: 1.928 | T14: 1.928 | U14: 1.928 | V14: 1.928 | W14: 1.928 | X14: 1.928 | Y14: 1.928 | Z14: 1.928
B15: =IFERROR(VLOOKUP(Q15,unified_reference_costs!$I$41:$J$69,2,FALSE),B14) -> en_gas_chp | C15: =IFERROR(VLOOKUP(Q15,unified_reference_costs!$I$31:$J$40,2,FALSE),"*") -> * | D15: =IF(ISNUMBER(Q15),Q15,D14) -> 2022 | E15: =IF(R15="","",R15) | F15: =IF(S15="","",S15) | G15: =IF(T15="","",T15) | H15: =IF(U15="","",U15) | I15: =IF(V15="","",V15) | J15: =IF(W15="","",W15) | K15: =IF(X15="","",X15) | L15: =IF(Y15="","",Y15) | M15: =IF(Z15="","",Z15) | Q15: en_gas_chp
B16: =IFERROR(VLOOKUP(Q16,unified_reference_costs!$I$41:$J$69,2,FALSE),B15) -> en_gas_chp | C16: =IFERROR(VLOOKUP(Q16,unified_reference_costs!$I$31:$J$40,2,FALSE),"*") -> invcost | D16: =IF(ISNUMBER(Q16),Q16,D15) -> 2022 | E16: =IF(R16="","",R16) -> 920 | F16: =IF(S16="","",S16) -> 920 | G16: =IF(T16="","",T16) -> 720 | H16: =IF(U16="","",U16) -> 920 | I16: =IF(V16="","",V16) -> 1440 | J16: =IF(W16="","",W16) -> 1040 | K16: =IF(X16="","",X16) -> 1300 | L16: =IF(Y16="","",Y16) -> 1300 | M16: =IF(Z16="","",Z16) -> 1040 | Q16: capex_mid | R16: 920 | S16: 920 | T16: 720 | U16: 920 | V16: 1440 | W16: 1040 | X16: 1300 | Y16: 1300 | Z16: 1040
B17: =IFERROR(VLOOKUP(Q17,unified_reference_costs!$I$41:$J$69,2,FALSE),B16) -> en_gas_chp | C17: =IFERROR(VLOOKUP(Q17,unified_reference_costs!$I$31:$J$40,2,FALSE),"*") -> efficiency | D17: =IF(ISNUMBER(Q17),Q17,D16) -> 2022 | E17: =IF(R17="","",R17) -> 0.527 | F17: =IF(S17="","",S17) -> 0.527 | G17: =IF(T17="","",T17) -> 0.52 | H17: =IF(U17="","",U17) -> 0.514 | I17: =IF(V17="","",V17) -> 0.533 | J17: =IF(W17="","",W17) -> 0.52 | K17: =IF(X17="","",X17) -> 0.533 | L17: =IF(Y17="","",Y17) -> 0.533 | M17: =IF(Z17="","",Z17) -> 0.52 | Q17: efficiency | R17: 0.527 | S17: 0.527 | T17: 0.52 | U17: 0.514 | V17: 0.533 | W17: 0.52 | X17: 0.533 | Y17: 0.533 | Z17: 0.52
B18: =IFERROR(VLOOKUP(Q18,unified_reference_costs!$I$41:$J$69,2,FALSE),B17) -> en_gas_chp | C18: =IFERROR(VLOOKUP(Q18,unified_reference_costs!$I$31:$J$40,2,FALSE),"*") -> fixom | D18: =IF(ISNUMBER(Q18),Q18,D17) -> 2022 | E18: =IF(R18="","",R18) -> 35 | F18: =IF(S18="","",S18) -> 35 | G18: =IF(T18="","",T18) -> 30 | H18: =IF(U18="","",U18) -> 35 | I18: =IF(V18="","",V18) -> 45 | J18: =IF(W18="","",W18) -> 40 | K18: =IF(X18="","",X18) -> 40 | L18: =IF(Y18="","",Y18) -> 40 | M18: =IF(Z18="","",Z18) -> 40 | Q18: fixed_om | R18: 35 | S18: 35 | T18: 30 | U18: 35 | V18: 45 | W18: 40 | X18: 40 | Y18: 40 | Z18: 40
B19: =IFERROR(VLOOKUP(Q19,unified_reference_costs!$I$41:$J$69,2,FALSE),B18) -> en_gas_chp | C19: =IFERROR(VLOOKUP(Q19,unified_reference_costs!$I$31:$J$40,2,FALSE),"*") -> varom | D19: =IF(ISNUMBER(Q19),Q19,D18) -> 2022 | E19: =IF(R19="","",R19) -> 0.694 | F19: =IF(S19="","",S19) -> 0.694 | G19: =IF(T19="","",T19) -> 0.694 | H19: =IF(U19="","",U19) -> 0.694 | I19: =IF(V19="","",V19) -> 0.694 | J19: =IF(W19="","",W19) -> 0.694 | K19: =IF(X19="","",X19) -> 0.694 | L19: =IF(Y19="","",Y19) -> 0.694 | M19: =IF(Z19="","",Z19) -> 0.694 | Q19: variable_om | R19: 0.694 | S19: 0.694 | T19: 0.694 | U19: 0.694 | V19: 0.694 | W19: 0.694 | X19: 0.694 | Y19: 0.694 | Z19: 0.694
B20: =IFERROR(VLOOKUP(Q20,unified_reference_costs!$I$41:$J$69,2,FALSE),B19) -> \I: | C20: =IFERROR(VLOOKUP(Q20,unified_reference_costs!$I$31:$J$40,2,FALSE),"*") -> * | D20: =IF(ISNUMBER(Q20),Q20,D19) -> 2022 | E20: =IF(R20="","",R20) | F20: =IF(S20="","",S20) | G20: =IF(T20="","",T20) | H20: =IF(U20="","",U20) | I20: =IF(V20="","",V20) | J20: =IF(W20="","",W20) | K20: =IF(X20="","",X20) | L20: =IF(Y20="","",Y20) | M20: =IF(Z20="","",Z20) | Q20: en_gas_fuelcell
B21: =IFERROR(VLOOKUP(Q21,unified_reference_costs!$I$41:$J$69,2,FALSE),B20) -> \I: | C21: =IFERROR(VLOOKUP(Q21,unified_reference_costs!$I$31:$J$40,2,FALSE),"*") -> invcost | D21: =IF(ISNUMBER(Q21),Q21,D20) -> 2022 | E21: =IF(R21="","",R21) -> 5000 | F21: =IF(S21="","",S21) -> 5000 | G21: =IF(T21="","",T21) -> 5000 | H21: =IF(U21="","",U21) -> 5000 | I21: =IF(V21="","",V21) -> 5000 | J21: =IF(W21="","",W21) -> 5000 | K21: =IF(X21="","",X21) -> 5000 | L21: =IF(Y21="","",Y21) -> 5000 | M21: =IF(Z21="","",Z21) -> 5000 | Q21: capex_mid | R21: 5000 | S21: 5000 | T21: 5000 | U21: 5000 | V21: 5000 | W21: 5000 | X21: 5000 | Y21: 5000 | Z21: 5000
B22: =IFERROR(VLOOKUP(Q22,unified_reference_costs!$I$41:$J$69,2,FALSE),B21) -> \I: | C22: =IFERROR(VLOOKUP(Q22,unified_reference_costs!$I$31:$J$40,2,FALSE),"*") -> efficiency | D22: =IF(ISNUMBER(Q22),Q22,D21) -> 2022 | E22: =IF(R22="","",R22) -> 0.46 | F22: =IF(S22="","",S22) -> 0.46 | G22: =IF(T22="","",T22) -> 0.46 | H22: =IF(U22="","",U22) -> 0.46 | I22: =IF(V22="","",V22) -> 0.46 | J22: =IF(W22="","",W22) -> 0.46 | K22: =IF(X22="","",X22) -> 0.46 | L22: =IF(Y22="","",Y22) -> 0.46 | M22: =IF(Z22="","",Z22) -> 0.46 | Q22: efficiency | R22: 0.46 | S22: 0.46 | T22: 0.46 | U22: 0.46 | V22: 0.46 | W22: 0.46 | X22: 0.46 | Y22: 0.46 | Z22: 0.46
B23: =IFERROR(VLOOKUP(Q23,unified_reference_costs!$I$41:$J$69,2,FALSE),B22) -> \I: | C23: =IFERROR(VLOOKUP(Q23,unified_reference_costs!$I$31:$J$40,2,FALSE),"*") -> fixom | D23: =IF(ISNUMBER(Q23),Q23,D22) -> 2022 | E23: =IF(R23="","",R23) -> 150 | F23: =IF(S23="","",S23) -> 150 | G23: =IF(T23="","",T23) -> 150 | H23: =IF(U23="","",U23) -> 150 | I23: =IF(V23="","",V23) -> 100 | J23: =IF(W23="","",W23) -> 150 | K23: =IF(X23="","",X23) -> 100 | L23: =IF(Y23="","",Y23) -> 100 | M23: =IF(Z23="","",Z23) -> 150 | Q23: fixed_om | R23: 150 | S23: 150 | T23: 150 | U23: 150 | V23: 100 | W23: 150 | X23: 100 | Y23: 100 | Z23: 150
B24: =IFERROR(VLOOKUP(Q24,unified_reference_costs!$I$41:$J$69,2,FALSE),B23) -> \I: | C24: =IFERROR(VLOOKUP(Q24,unified_reference_costs!$I$31:$J$40,2,FALSE),"*") -> varom | D24: =IF(ISNUMBER(Q24),Q24,D23) -> 2022 | E24: =IF(R24="","",R24) -> 0.833 | F24: =IF(S24="","",S24) -> 0.833 | G24: =IF(T24="","",T24) -> 0.833 | H24: =IF(U24="","",U24) -> 0.833 | I24: =IF(V24="","",V24) -> 0.833 | J24: =IF(W24="","",W24) -> 0.833 | K24: =IF(X24="","",X24) -> 0.833 | L24: =IF(Y24="","",Y24) -> 0.833 | M24: =IF(Z24="","",Z24) -> 0.833 | Q24: variable_om | R24: 0.833 | S24: 0.833 | T24: 0.833 | U24: 0.833 | V24: 0.833 | W24: 0.833 | X24: 0.833 | Y24: 0.833 | Z24: 0.833
B25: =IFERROR(VLOOKUP(Q25,unified_reference_costs!$I$41:$J$69,2,FALSE),B24) -> en_coal_subcritical | C25: =IFERROR(VLOOKUP(Q25,unified_reference_costs!$I$31:$J$40,2,FALSE),"*") -> * | D25: =IF(ISNUMBER(Q25),Q25,D24) -> 2022 | E25: =IF(R25="","",R25) | F25: =IF(S25="","",S25) | G25: =IF(T25="","",T25) | H25: =IF(U25="","",U25) | I25: =IF(V25="","",V25) | J25: =IF(W25="","",W25) | K25: =IF(X25="","",X25) | L25: =IF(Y25="","",Y25) | M25: =IF(Z25="","",Z25) | Q25: en_coal_subcritical
B26: =IFERROR(VLOOKUP(Q26,unified_reference_costs!$I$41:$J$69,2,FALSE),B25) -> en_coal_subcritical | C26: =IFERROR(VLOOKUP(Q26,unified_reference_costs!$I$31:$J$40,2,FALSE),"*") -> invcost | D26: =IF(ISNUMBER(Q26),Q26,D25) -> 2022 | E26: =IF(R26="","",R26) -> 1300 | F26: =IF(S26="","",S26) -> 1300 | G26: =IF(T26="","",T26) -> 600 | H26: =IF(U26="","",U26) -> 1000 | I26: =IF(V26="","",V26) -> 2100 | J26: =IF(W26="","",W26) -> 1700 | K26: =IF(X26="","",X26) -> 1700 | L26: =IF(Y26="","",Y26) -> 1800 | M26: =IF(Z26="","",Z26) -> 1300 | Q26: capex_mid | R26: 1300 | S26: 1300 | T26: 600 | U26: 1000 | V26: 2100 | W26: 1700 | X26: 1700 | Y26: 1800 | Z26: 1300
B27: =IFERROR(VLOOKUP(Q27,unified_reference_costs!$I$41:$J$69,2,FALSE),B26) -> en_coal_subcritical | C27: =IFERROR(VLOOKUP(Q27,unified_reference_costs!$I$31:$J$40,2,FALSE),"*") -> efficiency | D27: =IF(ISNUMBER(Q27),Q27,D26) -> 2022 | E27: =IF(R27="","",R27) -> 0.35 | F27: =IF(S27="","",S27) -> 0.39 | G27: =IF(T27="","",T27) -> 0.37 | H27: =IF(U27="","",U27) -> 0.36 | I27: =IF(V27="","",V27) -> 0.39 | J27: =IF(W27="","",W27) -> 0.39 | K27: =IF(X27="","",X27) -> 0.39 | L27: =IF(Y27="","",Y27) -> 0.39 | M27: =IF(Z27="","",Z27) -> 0.37 | Q27: efficiency | R27: 0.35 | S27: 0.39 | T27: 0.37 | U27: 0.36 | V27: 0.39 | W27: 0.39 | X27: 0.39 | Y27: 0.39 | Z27: 0.37
B28: =IFERROR(VLOOKUP(Q28,unified_reference_costs!$I$41:$J$69,2,FALSE),B27) -> en_coal_subcritical | C28: =IFERROR(VLOOKUP(Q28,unified_reference_costs!$I$31:$J$40,2,FALSE),"*") -> fixom | D28: =IF(ISNUMBER(Q28),Q28,D27) -> 2022 | E28: =IF(R28="","",R28) -> 45 | F28: =IF(S28="","",S28) -> 45 | G28: =IF(T28="","",T28) -> 20 | H28: =IF(U28="","",U28) -> 35 | I28: =IF(V28="","",V28) -> 55 | J28: =IF(W28="","",W28) -> 50 | K28: =IF(X28="","",X28) -> 45 | L28: =IF(Y28="","",Y28) -> 45 | M28: =IF(Z28="","",Z28) -> 45 | Q28: fixed_om | R28: 45 | S28: 45 | T28: 20 | U28: 35 | V28: 55 | W28: 50 | X28: 45 | Y28: 45 | Z28: 45
B29: =IFERROR(VLOOKUP(Q29,unified_reference_costs!$I$41:$J$69,2,FALSE),B28) -> en_coal_subcritical | C29: =IFERROR(VLOOKUP(Q29,unified_reference_costs!$I$31:$J$40,2,FALSE),"*") -> varom | D29: =IF(ISNUMBER(Q29),Q29,D28) -> 2022 | E29: =IF(R29="","",R29) -> 2.361 | F29: =IF(S29="","",S29) -> 2.361 | G29: =IF(T29="","",T29) -> 2.361 | H29: =IF(U29="","",U29) -> 2.361 | I29: =IF(V29="","",V29) -> 2.361 | J29: =IF(W29="","",W29) -> 2.361 | K29: =IF(X29="","",X29) -> 2.361 | L29: =IF(Y29="","",Y29) -> 2.361 | M29: =IF(Z29="","",Z29) -> 2.361 | Q29: variable_om | R29: 2.361 | S29: 2.361 | T29: 2.361 | U29: 2.361 | V29: 2.361 | W29: 2.361 | X29: 2.361 | Y29: 2.361 | Z29: 2.361
B30: =IFERROR(VLOOKUP(Q30,unified_reference_costs!$I$41:$J$69,2,FALSE),B29) -> en_coal_supercritical | C30: =IFERROR(VLOOKUP(Q30,unified_reference_costs!$I$31:$J$40,2,FALSE),"*") -> * | D30: =IF(ISNUMBER(Q30),Q30,D29) -> 2022 | E30: =IF(R30="","",R30) | F30: =IF(S30="","",S30) | G30: =IF(T30="","",T30) | H30: =IF(U30="","",U30) | I30: =IF(V30="","",V30) | J30: =IF(W30="","",W30) | K30: =IF(X30="","",X30) | L30: =IF(Y30="","",Y30) | M30: =IF(Z30="","",Z30) | Q30: en_coal_supercritical
B31: =IFERROR(VLOOKUP(Q31,unified_reference_costs!$I$41:$J$69,2,FALSE),B30) -> en_coal_supercritical | C31: =IFERROR(VLOOKUP(Q31,unified_reference_costs!$I$31:$J$40,2,FALSE),"*") -> invcost | D31: =IF(ISNUMBER(Q31),Q31,D30) -> 2022 | E31: =IF(R31="","",R31) -> 1600 | F31: =IF(S31="","",S31) -> 1600 | G31: =IF(T31="","",T31) -> 700 | H31: =IF(U31="","",U31) -> 1200 | I31: =IF(V31="","",V31) -> 2400 | J31: =IF(W31="","",W31) -> 2000 | K31: =IF(X31="","",X31) -> 2000 | L31: =IF(Y31="","",Y31) -> 2100 | M31: =IF(Z31="","",Z31) -> 1600 | Q31: capex_mid | R31: 1600 | S31: 1600 | T31: 700 | U31: 1200 | V31: 2400 | W31: 2000 | X31: 2000 | Y31: 2100 | Z31: 1600
B32: =IFERROR(VLOOKUP(Q32,unified_reference_costs!$I$41:$J$69,2,FALSE),B31) -> en_coal_supercritical | C32: =IFERROR(VLOOKUP(Q32,unified_reference_costs!$I$31:$J$40,2,FALSE),"*") -> efficiency | D32: =IF(ISNUMBER(Q32),Q32,D31) -> 2022 | E32: =IF(R32="","",R32) -> 0.39 | F32: =IF(S32="","",S32) -> 0.43 | G32: =IF(T32="","",T32) -> 0.41 | H32: =IF(U32="","",U32) -> 0.4 | I32: =IF(V32="","",V32) -> 0.43 | J32: =IF(W32="","",W32) -> 0.43 | K32: =IF(X32="","",X32) -> 0.43 | L32: =IF(Y32="","",Y32) -> 0.43 | M32: =IF(Z32="","",Z32) -> 0.41 | Q32: efficiency | R32: 0.39 | S32: 0.43 | T32: 0.41 | U32: 0.4 | V32: 0.43 | W32: 0.43 | X32: 0.43 | Y32: 0.43 | Z32: 0.41
B33: =IFERROR(VLOOKUP(Q33,unified_reference_costs!$I$41:$J$69,2,FALSE),B32) -> en_coal_supercritical | C33: =IFERROR(VLOOKUP(Q33,unified_reference_costs!$I$31:$J$40,2,FALSE),"*") -> fixom | D33: =IF(ISNUMBER(Q33),Q33,D32) -> 2022 | E33: =IF(R33="","",R33) -> 55 | F33: =IF(S33="","",S33) -> 65 | G33: =IF(T33="","",T33) -> 30 | H33: =IF(U33="","",U33) -> 50 | I33: =IF(V33="","",V33) -> 70 | J33: =IF(W33="","",W33) -> 70 | K33: =IF(X33="","",X33) -> 60 | L33: =IF(Y33="","",Y33) -> 65 | M33: =IF(Z33="","",Z33) -> 65 | Q33: fixed_om | R33: 55 | S33: 65 | T33: 30 | U33: 50 | V33: 70 | W33: 70 | X33: 60 | Y33: 65 | Z33: 65
B34: =IFERROR(VLOOKUP(Q34,unified_reference_costs!$I$41:$J$69,2,FALSE),B33) -> en_coal_supercritical | C34: =IFERROR(VLOOKUP(Q34,unified_reference_costs!$I$31:$J$40,2,FALSE),"*") -> varom | D34: =IF(ISNUMBER(Q34),Q34,D33) -> 2022 | E34: =IF(R34="","",R34) -> 2.583 | F34: =IF(S34="","",S34) -> 2.583 | G34: =IF(T34="","",T34) -> 2.583 | H34: =IF(U34="","",U34) -> 2.583 | I34: =IF(V34="","",V34) -> 2.583 | J34: =IF(W34="","",W34) -> 2.583 | K34: =IF(X34="","",X34) -> 2.583 | L34: =IF(Y34="","",Y34) -> 2.583 | M34: =IF(Z34="","",Z34) -> 2.583 | Q34: variable_om | R34: 2.583 | S34: 2.583 | T34: 2.583 | U34: 2.583 | V34: 2.583 | W34: 2.583 | X34: 2.583 | Y34: 2.583 | Z34: 2.583
B35: =IFERROR(VLOOKUP(Q35,unified_reference_costs!$I$41:$J$69,2,FALSE),B34) -> en_coal_ultrasupercritical | C35: =IFERROR(VLOOKUP(Q35,unified_reference_costs!$I$31:$J$40,2,FALSE),"*") -> * | D35: =IF(ISNUMBER(Q35),Q35,D34) -> 2022 | E35: =IF(R35="","",R35) | F35: =IF(S35="","",S35) | G35: =IF(T35="","",T35) | H35: =IF(U35="","",U35) | I35: =IF(V35="","",V35) | J35: =IF(W35="","",W35) | K35: =IF(X35="","",X35) | L35: =IF(Y35="","",Y35) | M35: =IF(Z35="","",Z35) | Q35: en_coal_ultrasupercritical
B36: =IFERROR(VLOOKUP(Q36,unified_reference_costs!$I$41:$J$69,2,FALSE),B35) -> en_coal_ultrasupercritical | C36: =IFERROR(VLOOKUP(Q36,unified_reference_costs!$I$31:$J$40,2,FALSE),"*") -> invcost | D36: =IF(ISNUMBER(Q36),Q36,D35) -> 2022 | E36: =IF(R36="","",R36) -> 1900 | F36: =IF(S36="","",S36) -> 1800 | G36: =IF(T36="","",T36) -> 800 | H36: =IF(U36="","",U36) -> 1400 | I36: =IF(V36="","",V36) -> 2600 | J36: =IF(W36="","",W36) -> 2200 | K36: =IF(X36="","",X36) -> 2200 | L36: =IF(Y36="","",Y36) -> 2300 | M36: =IF(Z36="","",Z36) -> 1600 | Q36: capex_mid | R36: 1900 | S36: 1800 | T36: 800 | U36: 1400 | V36: 2600 | W36: 2200 | X36: 2200 | Y36: 2300 | Z36: 1600
B37: =IFERROR(VLOOKUP(Q37,unified_reference_costs!$I$41:$J$69,2,FALSE),B36) -> en_coal_ultrasupercritical | C37: =IFERROR(VLOOKUP(Q37,unified_reference_costs!$I$31:$J$40,2,FALSE),"*") -> efficiency | D37: =IF(ISNUMBER(Q37),Q37,D36) -> 2022 | E37: =IF(R37="","",R37) -> 0.42 | F37: =IF(S37="","",S37) -> 0.45 | G37: =IF(T37="","",T37) -> 0.44 | H37: =IF(U37="","",U37) -> 0.4 | I37: =IF(V37="","",V37) -> 0.45 | J37: =IF(W37="","",W37) -> 0.45 | K37: =IF(X37="","",X37) -> 0.45 | L37: =IF(Y37="","",Y37) -> 0.45 | M37: =IF(Z37="","",Z37) -> 0.43 | Q37: efficiency | R37: 0.42 | S37: 0.45 | T37: 0.44 | U37: 0.4 | V37: 0.45 | W37: 0.45 | X37: 0.45 | Y37: 0.45 | Z37: 0.43
B38: =IFERROR(VLOOKUP(Q38,unified_reference_costs!$I$41:$J$69,2,FALSE),B37) -> en_coal_ultrasupercritical | C38: =IFERROR(VLOOKUP(Q38,unified_reference_costs!$I$31:$J$40,2,FALSE),"*") -> fixom | D38: =IF(ISNUMBER(Q38),Q38,D37) -> 2022 | E38: =IF(R38="","",R38) -> 70 | F38: =IF(S38="","",S38) -> 70 | G38: =IF(T38="","",T38) -> 30 | H38: =IF(U38="","",U38) -> 55 | I38: =IF(V38="","",V38) -> 80 | J38: =IF(W38="","",W38) -> 65 | K38: =IF(X38="","",X38) -> 65 | L38: =IF(Y38="","",Y38) -> 70 | M38: =IF(Z38="","",Z38) -> 65 | Q38: fixed_om | R38: 70 | S38: 70 | T38: 30 | U38: 55 | V38: 80 | W38: 65 | X38: 65 | Y38: 70 | Z38: 65
B39: =IFERROR(VLOOKUP(Q39,unified_reference_costs!$I$41:$J$69,2,FALSE),B38) -> en_coal_ultrasupercritical | C39: =IFERROR(VLOOKUP(Q39,unified_reference_costs!$I$31:$J$40,2,FALSE),"*") -> varom | D39: =IF(ISNUMBER(Q39),Q39,D38) -> 2022 | E39: =IF(R39="","",R39) -> 2.639 | F39: =IF(S39="","",S39) -> 2.639 | G39: =IF(T39="","",T39) -> 2.639 | H39: =IF(U39="","",U39) -> 2.639 | I39: =IF(V39="","",V39) -> 2.639 | J39: =IF(W39="","",W39) -> 2.639 | K39: =IF(X39="","",X39) -> 2.639 | L39: =IF(Y39="","",Y39) -> 2.639 | M39: =IF(Z39="","",Z39) -> 2.639 | Q39: variable_om | R39: 2.639 | S39: 2.639 | T39: 2.639 | U39: 2.639 | V39: 2.639 | W39: 2.639 | X39: 2.639 | Y39: 2.639 | Z39: 2.639
B40: =IFERROR(VLOOKUP(Q40,unified_reference_costs!$I$41:$J$69,2,FALSE),B39) -> en_coal_igcc | C40: =IFERROR(VLOOKUP(Q40,unified_reference_costs!$I$31:$J$40,2,FALSE),"*") -> * | D40: =IF(ISNUMBER(Q40),Q40,D39) -> 2022 | E40: =IF(R40="","",R40) | F40: =IF(S40="","",S40) | G40: =IF(T40="","",T40) | H40: =IF(U40="","",U40) | I40: =IF(V40="","",V40) | J40: =IF(W40="","",W40) | K40: =IF(X40="","",X40) | L40: =IF(Y40="","",Y40) | M40: =IF(Z40="","",Z40) | Q40: en_coal_igcc
B41: =IFERROR(VLOOKUP(Q41,unified_reference_costs!$I$41:$J$69,2,FALSE),B40) -> en_coal_igcc | C41: =IFERROR(VLOOKUP(Q41,unified_reference_costs!$I$31:$J$40,2,FALSE),"*") -> invcost | D41: =IF(ISNUMBER(Q41),Q41,D40) -> 2022 | E41: =IF(R41="","",R41) -> 2200 | F41: =IF(S41="","",S41) -> 2000 | G41: =IF(T41="","",T41) -> 1100 | H41: =IF(U41="","",U41) -> 1600 | I41: =IF(V41="","",V41) -> 2900 | J41: =IF(W41="","",W41) -> 2500 | K41: =IF(X41="","",X41) -> 2500 | L41: =IF(Y41="","",Y41) -> 2600 | M41: =IF(Z41="","",Z41) -> 2000 | Q41: capex_mid | R41: 2200 | S41: 2000 | T41: 1100 | U41: 1600 | V41: 2900 | W41: 2500 | X41: 2500 | Y41: 2600 | Z41: 2000
...

Sheet ELC_CO2 Transport and Storage
D2: ~FI_T | I2: ~FI_Process
B3: TechName | C3: Comm-IN | D3: Comm-OUT | E3: VAROM | F3: EFF | G3: ACT_CUM | I3: Sets | J3: TechName | K3: TechDesc | L3: Tslvl | M3: Tact | N3: Tcap | O3: PrimaryCG | P3: Vintage
B4: =J4 -> Sto-CO2_CB1 | C4: CO2ForStorage | E4: 0.001 | I4: PRE | J4: Sto-CO2_CB1 | K4: Enhanced Coalbed Meth recov <1000 m | M4: kt | N4: kt-Yr
B5: =J5 -> Sto-CO2_CB2 | C5: CO2ForStorage | E5: 0.001 | J5: Sto-CO2_CB2 | K5: Enhanced Coalbed Meth recov >1000 m | M5: kt | N5: kt-Yr
B6: =J6 -> Sto-CO2_DGF | C6: CO2ForStorage | E6: 0.001 | J6: Sto-CO2_DGF | K6: Depleted gas fields (offshore) | M6: kt | N6: kt-Yr
B7: =J7 -> Sto-CO2_DGO | C7: CO2ForStorage | E7: 0.001 | J7: Sto-CO2_DGO | K7: Depleted gas fields (onshore) | M7: kt | N7: kt-Yr
B8: =J8 -> Sto-CO2_DOF | C8: CO2ForStorage | E8: 0.001 | J8: Sto-CO2_DOF | K8: Depleted oil fields (offshore) | M8: kt | N8: kt-Yr
B9: =J9 -> Sto-CO2_DOO | C9: CO2ForStorage | E9: 0.001 | J9: Sto-CO2_DOO | K9: Depleted oil fields (onshore) | M9: kt | N9: kt-Yr
B10: =J10 -> Sto-CO2_DSA | C10: CO2ForStorage | E10: 0.001 | J10: Sto-CO2_DSA | K10: Deep saline aquifers (onshore) | M10: kt | N10: kt-Yr
B11: =J11 -> Sto-CO2_DSO | C11: CO2ForStorage | E11: 0.001 | J11: Sto-CO2_DSO | K11: Deep saline aquifers (offshore) | M11: kt | N11: kt-Yr
B12: =J12 -> Sto-CO2_EOF | C12: CO2ForStorage | E12: 0.001 | J12: Sto-CO2_EOF | K12: Enhanced Oil Recovery (offshore) | M12: kt | N12: kt-Yr
B13: =J13 -> Sto-CO2_EOR | C13: CO2ForStorage | E13: 0.001 | J13: Sto-CO2_EOR | K13: Enhanced Oil Recovery (onshore) | M13: kt | N13: kt-Yr
B14: * | I14: *
B15: =J15 -> Pipeline-CO2 | C15: CO2Captured | D15: =C7 -> CO2ForStorage | E15: 0.01 | F15: 1 | I15: PRE | J15: Pipeline-CO2 | K15: CO2 pipeline | M15: kt | N15: kt-Yr

Sheet pivot
A3: Sum of value | B3: Column Labels
A4: Row Labels | B4: ieapg_africa | C4: ieapg_brazil | D4: ieapg_china | E4: ieapg_india | F4: ieapg_japan | G4: ieapg_russia | H4: ieapg_european_union | I4: ieapg_united_states | J4: ieapg_middle_east
A5: 2022
A6: en_gas_ccgt
A7: capex_mid | B7: 700 | C7: 700 | D7: 560 | E7: 700 | F7: 1100 | G7: 800 | H7: 1000 | I7: 1000 | J7: 800
A8: efficiency | B8: 0.58 | C8: 0.58 | D8: 0.57 | E8: 0.56 | F8: 0.59 | G8: 0.57 | H8: 0.59 | I8: 0.59 | J8: 0.57
A9: fixed_om | B9: 25 | C9: 25 | D9: 20 | E9: 25 | F9: 30 | G9: 30 | H9: 25 | I9: 25 | J9: 30
A10: variable_om | B10: 0.603 | C10: 0.603 | D10: 0.603 | E10: 0.603 | F10: 0.603 | G10: 0.603 | H10: 0.603 | I10: 0.603 | J10: 0.603
A11: en_gas_turbine
A12: capex_mid | B12: 400 | C12: 400 | D12: 350 | E12: 400 | F12: 500 | G12: 450 | H12: 500 | I12: 500 | J12: 450
A13: efficiency | B13: 0.38 | C13: 0.38 | D13: 0.38 | E13: 0.38 | F13: 0.4 | G13: 0.38 | H13: 0.4 | I13: 0.4 | J13: 0.38
A14: fixed_om | B14: 20 | C14: 20 | D14: 20 | E14: 20 | F14: 20 | G14: 25 | H14: 20 | I14: 20 | J14: 25
A15: variable_om | B15: 1.928 | C15: 1.928 | D15: 1.928 | E15: 1.928 | F15: 1.928 | G15: 1.928 | H15: 1.928 | I15: 1.928 | J15: 1.928
A16: en_gas_chp
A17: capex_mid | B17: 920 | C17: 920 | D17: 720 | E17: 920 | F17: 1440 | G17: 1040 | H17: 1300 | I17: 1300 | J17: 1040
A18: efficiency | B18: 0.527 | C18: 0.527 | D18: 0.52 | E18: 0.514 | F18: 0.533 | G18: 0.52 | H18: 0.533 | I18: 0.533 | J18: 0.52
A19: fixed_om | B19: 35 | C19: 35 | D19: 30 | E19: 35 | F19: 45 | G19: 40 | H19: 40 | I19: 40 | J19: 40
A20: variable_om | B20: 0.694 | C20: 0.694 | D20: 0.694 | E20: 0.694 | F20: 0.694 | G20: 0.694 | H20: 0.694 | I20: 0.694 | J20: 0.694
A21: en_gas_fuelcell
A22: capex_mid | B22: 5000 | C22: 5000 | D22: 5000 | E22: 5000 | F22: 5000 | G22: 5000 | H22: 5000 | I22: 5000 | J22: 5000
A23: efficiency | B23: 0.46 | C23: 0.46 | D23: 0.46 | E23: 0.46 | F23: 0.46 | G23: 0.46 | H23: 0.46 | I23: 0.46 | J23: 0.46
A24: fixed_om | B24: 150 | C24: 150 | D24: 150 | E24: 150 | F24: 100 | G24: 150 | H24: 100 | I24: 100 | J24: 150
A25: variable_om | B25: 0.833 | C25: 0.833 | D25: 0.833 | E25: 0.833 | F25: 0.833 | G25: 0.833 | H25: 0.833 | I25: 0.833 | J25: 0.833
A26: en_coal_subcritical
A27: capex_mid | B27: 1300 | C27: 1300 | D27: 600 | E27: 1000 | F27: 2100 | G27: 1700 | H27: 1700 | I27: 1800 | J27: 1300
A28: efficiency | B28: 0.35 | C28: 0.39 | D28: 0.37 | E28: 0.36 | F28: 0.39 | G28: 0.39 | H28: 0.39 | I28: 0.39 | J28: 0.37
A29: fixed_om | B29: 45 | C29: 45 | D29: 20 | E29: 35 | F29: 55 | G29: 50 | H29: 45 | I29: 45 | J29: 45
A30: variable_om | B30: 2.361 | C30: 2.361 | D30: 2.361 | E30: 2.361 | F30: 2.361 | G30: 2.361 | H30: 2.361 | I30: 2.361 | J30: 2.361
A31: en_coal_supercritical
A32: capex_mid | B32: 1600 | C32: 1600 | D32: 700 | E32: 1200 | F32: 2400 | G32: 2000 | H32: 2000 | I32: 2100 | J32: 1600
A33: efficiency | B33: 0.39 | C33: 0.43 | D33: 0.41 | E33: 0.4 | F33: 0.43 | G33: 0.43 | H33: 0.43 | I33: 0.43 | J33: 0.41
A34: fixed_om | B34: 55 | C34: 65 | D34: 30 | E34: 50 | F34: 70 | G34: 70 | H34: 60 | I34: 65 | J34: 65
A35: variable_om | B35: 2.583 | C35: 2.583 | D35: 2.583 | E35: 2.583 | F35: 2.583 | G35: 2.583 | H35: 2.583 | I35: 2.583 | J35: 2.583
A36: en_coal_ultrasupercritical
A37: capex_mid | B37: 1900 | C37: 1800 | D37: 800 | E37: 1400 | F37: 2600 | G37: 2200 | H37: 2200 | I37: 2300 | J37: 1600
A38: efficiency | B38: 0.42 | C38: 0.45 | D38: 0.44 | E38: 0.4 | F38: 0.45 | G38: 0.45 | H38: 0.45 | I38: 0.45 | J38: 0.43
A39: fixed_om | B39: 70 | C39: 70 | D39: 30 | E39: 55 | F39: 80 | G39: 65 | H39: 65 | I39: 70 | J39: 65
A40: variable_om | B40: 2.639 | C40: 2.639 | D40: 2.639 | E40: 2.639 | F40: 2.639 | G40: 2.639 | H40: 2.639 | I40: 2.639 | J40: 2.639
A41: en_coal_igcc
A42: capex_mid | B42: 2200 | C42: 2000 | D42: 1100 | E42: 1600 | F42: 2900 | G42: 2500 | H42: 2500 | I42: 2600 | J42: 2000
...

Sheet unified_reference_costs
A1: variable | B1: region | C1: year | D1: parameter | E1: value | F1: unit | I1: technology | J1: lifetime_yr | K1: construction_yr | M1: description | O1: Distinct Regions (en_coal_ccs + efficiency)
A2: en_gas_ccgt | B2: ieapg_european_union | C2: 2022 | D2: capex_mid | E2: 1000 | F2: USD2022/kW | I2: en_gas_ccgt | J2: 30 | K2: 3 | M2: Natural gas 2-on-1 combined cycle (F-Frame). IEA GEC: CCGT; ATB: CCAvgCF | O2: {=_xlfn.UNIQUE(_xlfn._xlws.FILTER(B:B,(A:A="en_coal_ccs")*(D:D="efficiency")))} -> ieapg_european_union
A3: en_gas_ccgt | B3: ieapg_european_union | C3: 2022 | D3: capex_hi | E3: 1000 | F3: USD2022/kW | I3: en_gas_turbine | J3: 30 | K3: 2 | M3: Natural gas open-cycle combustion turbine (F-Frame, peaking). IEA GEC: Gas turbine; ATB: CTAvgCF | O3: ieapg_united_states
A4: en_gas_ccgt | B4: ieapg_european_union | C4: 2022 | D4: capex_lo | E4: 1000 | F4: USD2022/kW | I4: en_gas_chp | J4: 25 | K4: 3 | M4: Natural gas CCGT combined heat and power. IEA GEC: CCGT-CHP. Produces electricity + useful heat (LHV basis) | O4: ieapg_japan
A5: en_gas_ccgt | B5: ieapg_european_union | C5: 2022 | D5: fixed_om | E5: 25 | F5: USD2022/kW-yr | I5: en_gas_fuelcell | J5: 20 | K5: 2 | M5: Natural gas fuel cell. IEA GEC: Fuel cell | O5: ieapg_russia
A6: en_gas_ccgt | B6: ieapg_european_union | C6: 2022 | D6: efficiency | E6: 0.59 | F6: fraction_LHV | I6: en_gas_ccs | J6: 30 | K6: 4 | M6: Natural gas CCGT with 95% post-combustion CCS. IEA GEC: CCGT+CCS; ATB: CCCCSAvgCF | O6: ieapg_china
A7: en_gas_ccgt | B7: ieapg_european_union | C7: 2022 | D7: variable_om | E7: 0.603 | F7: USD2022/GJ | I7: en_coal_subcritical | J7: 40 | K7: 4 | M7: Coal subcritical steam cycle. IEA GEC: Subcritical | O7: ieapg_india
A8: en_gas_ccgt | B8: ieapg_european_union | C8: 2030 | D8: capex_mid | E8: 1000 | F8: USD2022/kW | I8: en_coal_supercritical | J8: 40 | K8: 4 | M8: Coal supercritical steam cycle. IEA GEC: Supercritical; ATB: newAvgCF | O8: ieapg_africa
A9: en_gas_ccgt | B9: ieapg_european_union | C9: 2030 | D9: capex_hi | E9: 1015.8 | F9: USD2022/kW | I9: en_coal_ultrasupercritical | J9: 40 | K9: 4 | M9: Coal ultra-supercritical steam cycle. IEA GEC: Ultra-supercritical
A10: en_gas_ccgt | B10: ieapg_european_union | C10: 2030 | D10: capex_lo | E10: 984.2 | F10: USD2022/kW | I10: en_coal_igcc | J10: 40 | K10: 4 | M10: Coal integrated gasification combined cycle. IEA GEC: IGCC; ATB: IGCCAvgCF
A11: en_gas_ccgt | B11: ieapg_european_union | C11: 2030 | D11: fixed_om | E11: 25 | F11: USD2022/kW-yr | I11: en_coal_ccs | J11: 40 | K11: 5 | M11: Coal post-combustion with 95% CCS. IEA GEC: Coal+CCS; ATB: CCS95AvgCF
A12: en_gas_ccgt | B12: ieapg_european_union | C12: 2030 | D12: efficiency | E12: 0.6 | F12: fraction_LHV | I12: en_coal_oxyfuel_ccs | J12: 40 | K12: 5 | M12: Coal oxyfuel combustion with CCS. IEA GEC: Oxyfuel+CCS
A13: en_gas_ccgt | B13: ieapg_european_union | C13: 2030 | D13: variable_om | E13: 0.567 | F13: USD2022/GJ | I13: en_coal_igcc_ccs | J13: 40 | K13: 5 | M13: Coal IGCC with CCS. IEA GEC: IGCC+CCS
A14: en_gas_ccgt | B14: ieapg_european_union | C14: 2050 | D14: capex_mid | E14: 1000 | F14: USD2022/kW | I14: en_nuclear | J14: 60 | K14: 7 | M14: Nuclear large reactor (Gen III/III+). IEA GEC: Nuclear; ATB: Nuclear - Large. Life 60yr, constr 7yr
A15: en_gas_ccgt | B15: ieapg_european_union | C15: 2050 | D15: capex_hi | E15: 1041.9 | F15: USD2022/kW | I15: en_nuclear_smr | J15: 40 | K15: 3 | M15: Nuclear small modular reactor. ATB: Nuclear - Small. Regional costs scaled from IEA large nuclear ratios. Life 40yr, constr 3yr
A16: en_gas_ccgt | B16: ieapg_european_union | C16: 2050 | D16: capex_lo | E16: 958.2 | F16: USD2022/kW | I16: en_solar_pv | J16: 30 | K16: 1.5 | M16: Solar PV utility-scale. IEA GEC: Solar PV large-scale; ATB: UtilityPV Class5
A17: en_gas_ccgt | B17: ieapg_european_union | C17: 2050 | D17: fixed_om | E17: 25 | F17: USD2022/kW-yr | I17: en_solar_csp | J17: 30 | K17: 3 | M17: Concentrated solar power with thermal storage. IEA GEC: CSP; ATB: CSP Class2
A18: en_gas_ccgt | B18: ieapg_european_union | C18: 2050 | D18: efficiency | E18: 0.61 | F18: fraction_LHV | I18: en_wind_onshore | J18: 30 | K18: 1.5 | M18: Wind onshore. IEA GEC: Wind onshore; ATB: LandbasedWind Class4
A19: en_gas_ccgt | B19: ieapg_european_union | C19: 2050 | D19: variable_om | E19: 0.497 | F19: USD2022/GJ | I19: en_wind_offshore | J19: 30 | K19: 3 | M19: Wind offshore (bottom-fixed/floating). IEA GEC: Wind offshore; ATB: OffShoreWind Class3
A20: en_gas_ccgt | B20: ieapg_united_states | C20: 2022 | D20: capex_mid | E20: 1000 | F20: USD2022/kW | I20: en_hydro_large | J20: 100 | K20: 4 | M20: Hydropower large-scale. IEA GEC: Hydropower large; ATB: NPD4
... A28: en_gas_ccgt | B28: ieapg_united_states | C28: 2030 | D28: capex_lo | E28: 984.2 | F28: USD2022/kW | I28: en_battery_8h | J28: 20 | K28: 1 | M28: Utility-scale Li-ion battery, 8-hour duration. ATB only (no IEA GEC). Uniform cost across regions
A29: en_gas_ccgt | B29: ieapg_united_states | C29: 2030 | D29: fixed_om | E29: 25 | F29: USD2022/kW-yr
A30: en_gas_ccgt | B30: ieapg_united_states | C30: 2030 | D30: efficiency | E30: 0.6 | F30: fraction_LHV
A31: en_gas_ccgt | B31: ieapg_united_states | C31: 2030 | D31: variable_om | E31: 0.567 | F31: USD2022/GJ | I31: capex_mid | J31: invcost
A32: en_gas_ccgt | B32: ieapg_united_states | C32: 2050 | D32: capex_mid | E32: 1000 | F32: USD2022/kW | I32: capex_hi | J32: invcost
A33: en_gas_ccgt | B33: ieapg_united_states | C33: 2050 | D33: capex_hi | E33: 1041.9 | F33: USD2022/kW | I33: capex_lo | J33: invcost
A34: en_gas_ccgt | B34: ieapg_united_states | C34: 2050 | D34: capex_lo | E34: 958.2 | F34: USD2022/kW | I34: fixed_om | J34: fixom
A35: en_gas_ccgt | B35: ieapg_united_states | C35: 2050 | D35: fixed_om | E35: 25 | F35: USD2022/kW-yr | I35: variable_om | J35: varom
A36: en_gas_ccgt | B36: ieapg_united_states | C36: 2050 | D36: efficiency | E36: 0.61 | F36: fraction_LHV | I36: efficiency | J36: =I36 -> efficiency
A37: en_gas_ccgt | B37: ieapg_united_states | C37: 2050 | D37: variable_om | E37: 0.497 | F37: USD2022/GJ | I37: capacity_factor | J37: *cf
A38: en_gas_ccgt | B38: ieapg_japan | C38: 2022 | D38: capex_mid | E38: 1100 | F38: USD2022/kW | I38: roundtrip_efficiency | J38: stg_eff
A39: en_gas_ccgt | B39: ieapg_japan | C39: 2022 | D39: capex_hi | E39: 1100 | F39: USD2022/kW
A40: en_gas_ccgt | B40: ieapg_japan | C40: 2022 | D40: capex_lo | E40: 1100 | F40: USD2022/kW
A41: en_gas_ccgt | B41: ieapg_japan | C41: 2022 | D41: fixed_om | E41: 30 | F41: USD2022/kW-yr | I41: en_gas_ccgt | J41: =I41 -> en_gas_ccgt
A42: en_gas_ccgt | B42: ieapg_japan | C42: 2022 | D42: efficiency | E42: 0.59 | F42: fraction_LHV | I42: en_gas_turbine | J42: =I42 -> en_gas_turbine
A43: en_gas_ccgt | B43: ieapg_japan | C43: 2022 | D43: variable_om | E43: 0.603 | F43: USD2022/GJ | I43: en_gas_chp | J43: =I43 -> en_gas_chp
A44: en_gas_ccgt | B44: ieapg_japan | C44: 2030 | D44: capex_mid | E44: 1100 | F44: USD2022/kW | I44: en_gas_fuelcell | J44: \I:
A45: en_gas_ccgt | B45: ieapg_japan | C45: 2030 | D45: capex_hi | E45: 1117.4 | F45: USD2022/kW | I45: en_gas_ccs | J45: =I45 -> en_gas_ccs
A46: en_gas_ccgt | B46: ieapg_japan | C46: 2030 | D46: capex_lo | E46: 1082.6 | F46: USD2022/kW | I46: en_coal_subcritical | J46: =I46 -> en_coal_subcritical
A47: en_gas_ccgt | B47: ieapg_japan | C47: 2030 | D47: fixed_om | E47: 30 | F47: USD2022/kW-yr | I47: en_coal_supercritical | J47: =I47 -> en_coal_supercritical
...
