Workbook
Name Cars_12: '[1]TechRep-Doc'!#REF!
Name Cars_12: '[1]TechRep-Doc'!#REF!
Name ddddd: [2]AGR_Fuels!$A$2
Name DISCRATE: '[1]TechRep-Doc'!#REF!
Name DISCRATE: '[1]TechRep-Doc'!#REF!
Name FID_1: [3]AGR_Fuels!$A$2
Name GROWTH: '[1]TechRep-Doc'!#REF!
Name GROWTH: '[1]TechRep-Doc'!#REF!
Name GROWTH_TID: '[1]TechRep-Doc'!#REF!
Name GROWTH_TID: '[1]TechRep-Doc'!#REF!
Name INVCOST: '[1]TechRep-Doc'!#REF!
Name INVCOST: '[1]TechRep-Doc'!#REF!
Name LIFE: '[1]TechRep-Doc'!#REF!
Name LIFE: '[1]TechRep-Doc'!#REF!
Name NAs_CCAR: '[1]TechRep-Doc'!#REF!
Name NAs_CCAR: '[1]TechRep-Doc'!#REF!
Name SETS: '[1]TechRep-Doc'!#REF!
Name SETS: '[1]TechRep-Doc'!#REF!
Name TRTGAB005: '[1]TechRep-Doc'!#REF!
Name TRTGAB005: '[1]TechRep-Doc'!#REF!
Name TRTGAC005: '[1]TechRep-Doc'!#REF!
Name TRTGAC005: '[1]TechRep-Doc'!#REF!
Name Trucks_15: '[1]TechRep-Doc'!#REF!
Name Trucks_15: '[1]TechRep-Doc'!#REF!
Name TSUB_COST: '[1]TechRep-Doc'!#REF!
Name TSUB_COST: '[1]TechRep-Doc'!#REF!
Name x: [1]AGR_Fuels!$A$2

Sheet bldg_other (old)
F2: ~FI_T | AN2: Cost Factors, as Percent of U.S.
A3: Sets | B3: TechName | C3: TechDesc | D3: \I:Source | E3: Comm-IN | F3: YEAR | G3: *CAPUNIT | H3: *START | I3: LIFE | J3: INVCOST | K3: FIXOM | L3: VAROM | M3: Share~FX | N3: EFF | O3: DELIV(ENT) | P3: MO(ENC) | Q3: CF(Z)(Y) | R3: ENV_CAP | S3: ENV_INV | T3: DISCRATE | U3: BOUND(BD)~UP | V3: BOUND(BD)~LO | W3: IBOND(BD)~UP | X3: IBOND(BD)~LO | Y3: BOUND(BD)o~UP~2000 | Z3: BOUND(BD)o~LO | AA3: BOUND(BD)o~UP~2005 | AB3: BOUND(BD)o~UP~2010 | AC3: BOUND(BD)o~UP~2020 | AD3: BOUND(BD)o~UP~2030 | AE3: BOUND(BD)o~UP~2040 | AF3: BOUND(BD)o~UP~2050 | AG3: BOUND(BD)o~UP~2060 | AH3: BOUND(BD)o~UP~2070 | AI3: BOUND(BD)o~UP~2080 | AJ3: BOUND(BD)o~UP~2090 | AK3: BOUND(BD)o~UP~2100 | AT3: South America | AW3: Europe | AZ3: Europe | BC3: Soviet Union | BL3: Developing Asia | CA3: New Zealand
A4: Cooking
B5: RCKNGA005 | C5: RES.COOK.R1: .05.NGA. | D5: Refs A, F | E5: RESNGA | F5: =H5 -> 2006 | G5: 1 | H5: 2006 | I5: 17 | J5: 183.97194 | K5: 4.5992985 | N5: 0.5 | AN5: 0.95 | AO5: 0.85 | AP5: 0.75 | AQ5: 0.75 | AR5: 0.7075 | AS5: 0.48 | AT5: 0.875 | AU5: 0.7075 | AV5: 0.48 | AW5: 1.1 | AX5: 0.9 | AY5: 0.8 | AZ5: 0.875 | BA5: 0.7075 | BB5: 0.48 | BC5: 0.875 | BD5: 0.7075 | BE5: 0.48 | BF5: 0.875 | BG5: 0.7075 | BH5: 0.48 | BI5: 0.875 | BJ5: 0.7075 | BK5: 0.48 | BL5: 0.875 | BM5: 0.7075 | BN5: 0.48 | BO5: 0.875 | BP5: 0.7075 | BQ5: 0.48 | BR5: 1.1 | BS5: 0.9 | BT5: 0.8 | BU5: 0.875 | BV5: 0.7075 | BW5: 0.48 | BX5: 0.875 | BY5: 0.7075 | BZ5: 0.48 | CA5: 0.95 | CB5: 0.85 | CC5: 0.75
B6: RCKKER005 | C6: RES.COOK.R1: .05.KER. | D6: Refs A, K | E6: RESKER | F6: =H6 -> 2006 | G6: 1 | H6: 2006 | I6: 17 | J6: 148.89815 | K6: 3.7224538 | N6: 0.5 | AN6: 0.95 | AO6: 0.85 | AP6: 0.75 | AQ6: 0.75 | AR6: 0.7075 | AS6: 0.48 | AT6: 0.875 | AU6: 0.7075 | AV6: 0.48 | AW6: 1.1 | AX6: 0.9 | AY6: 0.8 | AZ6: 0.875 | BA6: 0.7075 | BB6: 0.48 | BC6: 0.875 | BD6: 0.7075 | BE6: 0.48 | BF6: 0.875 | BG6: 0.7075 | BH6: 0.48 | BI6: 0.875 | BJ6: 0.7075 | BK6: 0.48 | BL6: 0.875 | BM6: 0.7075 | BN6: 0.48 | BO6: 0.875 | BP6: 0.7075 | BQ6: 0.48 | BR6: 1.1 | BS6: 0.9 | BT6: 0.8 | BU6: 0.875 | BV6: 0.7075 | BW6: 0.48 | BX6: 0.875 | BY6: 0.7075 | BZ6: 0.48 | CA6: 0.95 | CB6: 0.85 | CC6: 0.75
B7: RCKDST005 | C7: RES.COOK.R1: .05.DST. | D7: RCKKER | E7: RESOIL | F7: =H7 -> 2006 | G7: 1 | H7: 2006 | I7: 17 | J7: 148.89815 | K7: 3.7224538 | N7: 0.5 | AN7: 0.95 | AO7: 0.85 | AP7: 0.75 | AQ7: 0.75 | AR7: 0.7075 | AS7: 0.48 | AT7: 0.875 | AU7: 0.7075 | AV7: 0.48 | AW7: 1.1 | AX7: 0.9 | AY7: 0.8 | AZ7: 0.875 | BA7: 0.7075 | BB7: 0.48 | BC7: 0.875 | BD7: 0.7075 | BE7: 0.48 | BF7: 0.875 | BG7: 0.7075 | BH7: 0.48 | BI7: 0.875 | BJ7: 0.7075 | BK7: 0.48 | BL7: 0.875 | BM7: 0.7075 | BN7: 0.48 | BO7: 0.875 | BP7: 0.7075 | BQ7: 0.48 | BR7: 1.1 | BS7: 0.9 | BT7: 0.8 | BU7: 0.875 | BV7: 0.7075 | BW7: 0.48 | BX7: 0.875 | BY7: 0.7075 | BZ7: 0.48 | CA7: 0.95 | CB7: 0.85 | CC7: 0.75
B8: RCKCOA005 | C8: RES.COOK.R1: .05.COA. | D8: Refs A | E8: RESCOA | F8: =H8 -> 2006 | G8: 1 | H8: 2006 | I8: 17 | J8: 66.176957 | K8: 9.9265436 | N8: 0.3 | AN8: 0.95 | AO8: 0.85 | AP8: 0.75 | AQ8: 0.75 | AR8: 0.7075 | AS8: 0.48 | AT8: 0.875 | AU8: 0.7075 | AV8: 0.48 | AW8: 1.1 | AX8: 0.9 | AY8: 0.8 | AZ8: 0.875 | BA8: 0.7075 | BB8: 0.48 | BC8: 0.875 | BD8: 0.7075 | BE8: 0.48 | BF8: 0.875 | BG8: 0.7075 | BH8: 0.48 | BI8: 0.875 | BJ8: 0.7075 | BK8: 0.48 | BL8: 0.875 | BM8: 0.7075 | BN8: 0.48 | BO8: 0.875 | BP8: 0.7075 | BQ8: 0.48 | BR8: 1.1 | BS8: 0.9 | BT8: 0.8 | BU8: 0.875 | BV8: 0.7075 | BW8: 0.48 | BX8: 0.875 | BY8: 0.7075 | BZ8: 0.48 | CA8: 0.95 | CB8: 0.85 | CC8: 0.75
B9: RCKLPG005 | C9: RES.COOK.R1: .05.LPG. | D9: Refs A, F | E9: RESLPG | F9: =H9 -> 2006 | G9: 1 | H9: 2006 | I9: 17 | J9: 183.97194 | K9: 4.5992985 | N9: 0.5 | AN9: 0.95 | AO9: 0.85 | AP9: 0.75 | AQ9: 0.75 | AR9: 0.7075 | AS9: 0.48 | AT9: 0.875 | AU9: 0.7075 | AV9: 0.48 | AW9: 1.1 | AX9: 0.9 | AY9: 0.8 | AZ9: 0.875 | BA9: 0.7075 | BB9: 0.48 | BC9: 0.875 | BD9: 0.7075 | BE9: 0.48 | BF9: 0.875 | BG9: 0.7075 | BH9: 0.48 | BI9: 0.875 | BJ9: 0.7075 | BK9: 0.48 | BL9: 0.875 | BM9: 0.7075 | BN9: 0.48 | BO9: 0.875 | BP9: 0.7075 | BQ9: 0.48 | BR9: 1.1 | BS9: 0.9 | BT9: 0.8 | BU9: 0.875 | BV9: 0.7075 | BW9: 0.48 | BX9: 0.875 | BY9: 0.7075 | BZ9: 0.48 | CA9: 0.95 | CB9: 0.85 | CC9: 0.75
B10: RCKELC005 | C10: RES.COOK.R1: .05.ELC. | D10: Refs A, F | E10: RESELC | F10: =H10 -> 2006 | G10: 1 | H10: 2006 | I10: 17 | J10: 183.97194 | K10: 4.5992985 | N10: 0.7 | AN10: 0.95 | AO10: 0.85 | AP10: 0.75 | AQ10: 0.75 | AR10: 0.7075 | AS10: 0.48 | AT10: 0.875 | AU10: 0.7075 | AV10: 0.48 | AW10: 1.1 | AX10: 0.9 | AY10: 0.8 | AZ10: 0.875 | BA10: 0.7075 | BB10: 0.48 | BC10: 0.875 | BD10: 0.7075 | BE10: 0.48 | BF10: 0.875 | BG10: 0.7075 | BH10: 0.48 | BI10: 0.875 | BJ10: 0.7075 | BK10: 0.48 | BL10: 0.875 | BM10: 0.7075 | BN10: 0.48 | BO10: 0.875 | BP10: 0.7075 | BQ10: 0.48 | BR10: 1.1 | BS10: 0.9 | BT10: 0.8 | BU10: 0.875 | BV10: 0.7075 | BW10: 0.48 | BX10: 0.875 | BY10: 0.7075 | BZ10: 0.48 | CA10: 0.95 | CB10: 0.85 | CC10: 0.75
B11: RCKBIO005 | C11: RES.COOK.R1: .05.BIO. | D11: Refs A | E11: RESBIO | F11: =H11 -> 2006 | G11: 1 | H11: 2006 | I11: 17 | J11: 66.176957 | K11: 4.9632718 | N11: 0.25 | AN11: 0.95 | AO11: 0.85 | AP11: 0.75 | AQ11: 0.75 | AR11: 0.7075 | AS11: 0.48 | AT11: 0.875 | AU11: 0.7075 | AV11: 0.48 | AW11: 1.1 | AX11: 0.9 | AY11: 0.8 | AZ11: 0.875 | BA11: 0.7075 | BB11: 0.48 | BC11: 0.875 | BD11: 0.7075 | BE11: 0.48 | BF11: 0.875 | BG11: 0.7075 | BH11: 0.48 | BI11: 0.875 | BJ11: 0.7075 | BK11: 0.48 | BL11: 0.875 | BM11: 0.7075 | BN11: 0.48 | BO11: 0.875 | BP11: 0.7075 | BQ11: 0.48 | BR11: 1.1 | BS11: 0.9 | BT11: 0.8 | BU11: 0.875 | BV11: 0.7075 | BW11: 0.48 | BX11: 0.875 | BY11: 0.7075 | BZ11: 0.48 | CA11: 0.95 | CB11: 0.85 | CC11: 0.75
B12: RCKSTH005 | C12: RES.COOK.R1: .05.STH. | D12: Refs A, J | E12: RESSTH | F12: =H12 -> 2006 | G12: 1 | H12: 2006 | I12: 17 | J12: 164.11885 | K12: 2.7353142 | N12: 0.5 | AN12: 0.95 | AO12: 0.85 | AP12: 0.75 | AQ12: 0.75 | AR12: 0.7075 | AS12: 0.48 | AT12: 0.875 | AU12: 0.7075 | AV12: 0.48 | AW12: 1.1 | AX12: 0.9 | AY12: 0.8 | AZ12: 0.875 | BA12: 0.7075 | BB12: 0.48 | BC12: 0.875 | BD12: 0.7075 | BE12: 0.48 | BF12: 0.875 | BG12: 0.7075 | BH12: 0.48 | BI12: 0.875 | BJ12: 0.7075 | BK12: 0.48 | BL12: 0.875 | BM12: 0.7075 | BN12: 0.48 | BO12: 0.875 | BP12: 0.7075 | BQ12: 0.48 | BR12: 1.1 | BS12: 0.9 | BT12: 0.8 | BU12: 0.875 | BV12: 0.7075 | BW12: 0.48 | BX12: 0.875 | BY12: 0.7075 | BZ12: 0.48 | CA12: 0.95 | CB12: 0.85 | CC12: 0.75
A14: FROM UWE REMME - Nov.2007
F15: ~FI_T | AN15: Cost Factors, as Percent of U.S.
A16: Sets | B16: TechName | C16: TechDesc | D16: \I:Source | E16: Comm-IN | F16: YEAR | G16: *CAPUNIT | H16: *START | I16: LIFE | J16: INVCOST | K16: FIXOM | L16: VAROM | M16: Share~FX | N16: EFF | O16: DELIV(ENT) | P16: MO(ENC) | Q16: CF(Z)(Y) | R16: ENV_CAP | S16: ENV_INV | T16: DISCRATE | U16: BOUND(BD)~UP | V16: BOUND(BD)~LO | W16: IBOND(BD)~UP | X16: IBOND(BD)~LO | Y16: BOUND(BD)o~UP~2000 | Z16: BOUND(BD)o~LO | AA16: BOUND(BD)o~UP~2005 | AB16: BOUND(BD)o~UP~2010 | AC16: BOUND(BD)o~UP~2020 | AD16: BOUND(BD)o~UP~2030 | AE16: BOUND(BD)o~UP~2040 | AF16: BOUND(BD)o~UP~2050 | AG16: BOUND(BD)o~UP~2060 | AH16: BOUND(BD)o~UP~2070 | AI16: BOUND(BD)o~UP~2080 | AJ16: BOUND(BD)o~UP~2090 | AK16: BOUND(BD)o~UP~2100 | AT16: South America | AW16: Europe | AZ16: Europe | BC16: Soviet Union | BL16: Developing Asia | CA16: New Zealand
A17: Miscellaneous all electric equipment, REA
B18: REAELC005 | C18: RES: .05.ELC.EQUIPMENT.MISCELLANEOUS. | D18: SAIC | E18: RESELC | F18: =H18 -> 2006 | G18: 1 | H18: 2006 | I18: 10 | J18: 0.1 | K18: 1.9444444 | N18: 1 | AN18: 0.95 | AO18: 0.85 | AP18: 0.75 | AQ18: 0.75 | AR18: 0.7075 | AS18: 0.48 | AT18: 0.875 | AU18: 0.7075 | AV18: 0.48 | AW18: 1.1 | AX18: 0.9 | AY18: 0.8 | AZ18: 0.875 | BA18: 0.7075 | BB18: 0.48 | BC18: 0.875 | BD18: 0.7075 | BE18: 0.48 | BF18: 0.875 | BG18: 0.7075 | BH18: 0.48 | BI18: 0.875 | BJ18: 0.7075 | BK18: 0.48 | BL18: 0.875 | BM18: 0.7075 | BN18: 0.48 | BO18: 0.875 | BP18: 0.7075 | BQ18: 0.48 | BR18: 1.1 | BS18: 0.9 | BT18: 0.8 | BU18: 0.875 | BV18: 0.7075 | BW18: 0.48 | BX18: 0.875 | BY18: 0.7075 | BZ18: 0.48 | CA18: 0.95 | CB18: 0.85 | CC18: 0.75
F19: 2008
F20: 2018
F21: 2028
F22: 2038
F23: 2048
A24: Residential Other
B25: ROTELC005 | C25: Other Residential Electricity equipment New | D25: SAIC | E25: RESELC | F25: =H25 -> 2006 | G25: 1 | H25: 2006 | I25: 10 | J25: 0.2 | K25: 2 | N25: 1 | AN25: 0.95 | AO25: 0.85 | AP25: 0.75 | AQ25: 0.75 | AR25: 0.7075 | AS25: 0.48 | AT25: 0.875 | AU25: 0.7075 | AV25: 0.48 | AW25: 1.1 | AX25: 0.9 | AY25: 0.8 | AZ25: 0.875 | BA25: 0.7075 | BB25: 0.48 | BC25: 0.875 | BD25: 0.7075 | BE25: 0.48 | BF25: 0.875 | BG25: 0.7075 | BH25: 0.48 | BI25: 0.875 | BJ25: 0.7075 | BK25: 0.48 | BL25: 0.875 | BM25: 0.7075 | BN25: 0.48 | BO25: 0.875 | BP25: 0.7075 | BQ25: 0.48 | BR25: 1.1 | BS25: 0.9 | BT25: 0.8 | BU25: 0.875 | BV25: 0.7075 | BW25: 0.48 | BX25: 0.875 | BY25: 0.7075 | BZ25: 0.48 | CA25: 0.95 | CB25: 0.85 | CC25: 0.75
F26: 2008
F27: 2018
F28: 2028
F29: 2038
F30: 2048
B31: ROTNGA005 | C31: Other Residential Natural Gas equipment New | D31: SAIC | E31: RESNGA | F31: =H31 -> 2006 | G31: 1 | H31: 2006 | I31: 10 | J31: 0.2 | K31: 2 | N31: 1 | AN31: 0.95 | AO31: 0.85 | AP31: 0.75 | AQ31: 0.75 | AR31: 0.7075 | AS31: 0.48 | AT31: 0.875 | AU31: 0.7075 | AV31: 0.48 | AW31: 1.1 | AX31: 0.9 | AY31: 0.8 | AZ31: 0.875 | BA31: 0.7075 | BB31: 0.48 | BC31: 0.875 | BD31: 0.7075 | BE31: 0.48 | BF31: 0.875 | BG31: 0.7075 | BH31: 0.48 | BI31: 0.875 | BJ31: 0.7075 | BK31: 0.48 | BL31: 0.875 | BM31: 0.7075 | BN31: 0.48 | BO31: 0.875 | BP31: 0.7075 | BQ31: 0.48 | BR31: 1.1 | BS31: 0.9 | BT31: 0.8 | BU31: 0.875 | BV31: 0.7075 | BW31: 0.48 | BX31: 0.875 | BY31: 0.7075 | BZ31: 0.48 | CA31: 0.95 | CB31: 0.85 | CC31: 0.75
F32: 2008
F33: 2018
F34: 2028
F35: 2038
F36: 2048
A37: Commercial Elecric Office Equipment
B38: COEELC005 | C38: COM: .05.ELC.EQUIPMENT.MISCELLANEOUS. | D38: SAIC | E38: COMELC | F38: =H38 -> 2006 | G38: 1 | H38: 2006 | I38: 10 | J38: 0.4 | K38: 4.1111111 | N38: 1 | AN38: 0.95 | AO38: 0.85 | AP38: 0.75 | AQ38: 0.75 | AR38: 0.7075 | AS38: 0.48 | AT38: 0.875 | AU38: 0.7075 | AV38: 0.48 | AW38: 1.1 | AX38: 0.9 | AY38: 0.8 | AZ38: 0.875 | BA38: 0.7075 | BB38: 0.48 | BC38: 0.875 | BD38: 0.7075 | BE38: 0.48 | BF38: 0.875 | BG38: 0.7075 | BH38: 0.48 | BI38: 0.875 | BJ38: 0.7075 | BK38: 0.48 | BL38: 0.875 | BM38: 0.7075 | BN38: 0.48 | BO38: 0.875 | BP38: 0.7075 | BQ38: 0.48 | BR38: 1.1 | BS38: 0.9 | BT38: 0.8 | BU38: 0.875 | BV38: 0.7075 | BW38: 0.48 | BX38: 0.875 | BY38: 0.7075 | BZ38: 0.48 | CA38: 0.95 | CB38: 0.85 | CC38: 0.75
F39: 2008
F40: 2018
F41: 2028
F42: 2038
...

Sheet LNG terminals
D2: ~FI_T: USD20 | N2: ~FI_Process
B3: process | C3: comm-in | D3: comm-out | E3: CAP2ACT | F3: START | G3: AFA | H3: NCAP_COST | I3: NCAP_FOM | J3: NCAP_TLIFE | K3: EFF | L3: ILED | N3: Sets | O3: TechName | P3: TechDesc | Q3: Tact | R3: Tcap | S3: pcg
B4: =O4 -> LNG_New-Export | C4: GASNGA | D4: GASLNG | E4: 54 | H4: 1000 | I4: =H4*0.025 -> 25 | K4: 0.9 | L4: -2 | N4: PRE | O4: LNG_New-Export | P4: Liquefaction | Q4: PJ | R4: mtpa
B5: =O5 -> LNG_New-Import | C5: GASLNG | D5: GASNGA | E5: 54 | H5: 300 | I5: =H5*0.025 -> 7.5 | K5: 0.9755 | L5: -2 | O5: LNG_New-Import | P5: Regasification | Q5: PJ | R5: mtpa | S5: GASLNG

Sheet HPL
D3: ~FI_T: USD00 | N3: ~FI_Process
B4: process | C4: comm-in | D4: comm-out | E4: CAP2ACT | F4: VAROM | G4: FLO_DELIV | H4: AFA | I4: NCAP_COST | J4: NCAP_FOM | K4: NCAP_TLIFE | L4: EFF | N4: Sets | O4: TechName | P4: TechDesc | Q4: Tact | R4: Tcap | S4: pcg
B5: HETBIOP105 | C5: ELCBSL | D5: HET | E5: 31.536 | G5: 0.6 | H5: 0.6 | I5: 189.216 | J5: 88.3008 | K5: 60 | L5: 0.8 | N5: HPL | O5: =B5 -> HETBIOP105 | P5: ="Heat plant - "&RIGHT(C5,3) -> Heat plant - BSL | Q5: PJ | R5: GW
B6: HETCOAP105 | C6: ELCCOA | D6: HET | E6: 31.536 | G6: 0.6 | H6: 0.6 | I6: 189.216 | J6: 88.3008 | K6: 60 | L6: 0.8 | O6: =B6 -> HETCOAP105 | P6: ="Heat plant - "&RIGHT(C6,3) -> Heat plant - COA | Q6: PJ | R6: GW
B7: HETGASP105 | C7: ELCNGA | D7: HET | E7: 31.536 | G7: 0.1 | H7: 0.6 | I7: 141.912 | J7: 75.6864 | K7: 60 | L7: 0.86956522 | O7: =B7 -> HETGASP105 | P7: ="Heat plant - "&RIGHT(C7,3) -> Heat plant - NGA | Q7: PJ | R7: GW
B8: HETOILP105 | C8: ELCOIL | D8: HET | E8: 31.536 | G8: 0.3 | H8: 0.6 | I8: 157.68 | J8: 78.84 | K8: 60 | L8: 0.8 | O8: =B8 -> HETOILP105 | P8: ="Heat plant - "&RIGHT(C8,3) -> Heat plant - OIL | Q8: PJ | R8: GW
B9: \I: HETHH2P105 | C9: ELCHH2 | D9: HET | E9: =E7 -> 31.536 | G9: =G7 -> 0.1 | H9: =H7 -> 0.6 | I9: =I7 -> 141.912 | J9: =J7 -> 75.6864 | K9: =K7 -> 60 | L9: =L7 -> 0.86956522 | O9: =B9 -> \I: HETHH2P105 | P9: ="Heat plant - "&RIGHT(C9,3) -> Heat plant - HH2 | Q9: PJ | R9: GW
B10: HETHPU | C10: ELC | D10: RESHET,COMHET | E10: =E8 -> 31.536 | I10: 800 | J10: =I10/10 -> 80 | K10: 20 | L10: 2.5 | O10: =B10 -> HETHPU | P10: Utility scale heat pump - placeholder values - hoping to avoid seeing H2 going to heat | Q10: PJ | R10: GW
B11: \I: | O11: =B11 -> \I:
B12: FT_INDNUC | C12: NUC | D12: INDNUC | L12: 1 | N12: PRE | O12: =B12 -> FT_INDNUC | Q12: PJ | R12: GW
B13: \I: dummy_source | D13: NetCO2_ELC | F13: =0.1/1000 -> 0.0001 | O13: =B13 -> \I: dummy_source | P13: dummy source for commodities used in accounting | Q13: kt | R13: ktpa | S13: ENVo
B14: \I: dummy_sink | C14: NetCO2_ELC | F14: =0.1/1000 -> 0.0001 | O14: =B14 -> \I: dummy_sink | P14: dummy sink for commodities used in accounting | Q14: kt | R14: ktpa | S14: ENVi

Sheet RES
B3: ~FI_T: EFF | L3: ~FI_T: INVCOST~USD05 | S3: ~FI_T: LIFE | AA3: ~FI_Process
A4: TimeSlice | B4: process | C4: Comm-IN | D4: Comm-OUT | E4: 2010 | F4: 2011 | G4: 2015 | H4: 2020 | I4: 2030 | J4: 2040 | L4: process | M4: 2011 | N4: 2015 | O4: 2020 | P4: 2030 | Q4: 2040 | S4: process | T4: 2010 | U4: 2011 | V4: 2015 | W4: 2020 | X4: 2030 | Y4: 2040 | AA4: Sets | AB4: TechName | AC4: TechDesc | AD4: Tact | AE4: Tcap | AK4: MIN Eff | AL4: AVG
B5: RLTECFL | C5: =VLOOKUP(B5,'US9R topology'!$A$2:$C$261,3,FALSE) -> RESELC | D5: =VLOOKUP(LEFT(B5,3),$AH$5:$AI$9,2,FALSE) -> RLI | F5: 1.8709551 | G5: 1.8709551 | H5: 1.9977995 | I5: 2.0929329 | J5: 2.1880662 | L5: =$B5 -> RLTECFL | M5: 4.844454 | N5: 4.7717417 | O5: 4.5172488 | P5: 4.2991121 | Q5: 4.0809753 | S5: =$B5 -> RLTECFL | U5: 10 | AA5: =IF(LEFT(A5,3)="\I:",A5,"DMD") -> DMD | AB5: RLTECFL | AC5: RLT.ELC.EXT.CFL. | AD5: bn-lum-yr | AE5: bn-lum | AH5: RLT | AI5: RLI | AK5: =_xlfn.MINIFS($F$5:$F$80,$D$5:$D$80,AI5) -> 0.31711104 | AL5: =AVERAGEIFS($F$5:$F$79,$D$5:$D$79,AI5) -> 1.4238286
B6: RLTEHPS | C6: =VLOOKUP(B6,'US9R topology'!$A$2:$C$261,3,FALSE) -> RESELC | D6: =VLOOKUP(LEFT(B6,3),$AH$5:$AI$9,2,FALSE) -> RLI | F6: 2.9491327 | G6: 2.9491327 | H6: 2.9491327 | L6: =$B6 -> RLTEHPS | M6: 13.633548 | N6: 13.633548 | O6: 9.0890318 | S6: =$B6 -> RLTEHPS | U6: 20 | AA6: =IF(LEFT(A6,3)="\I:",A6,"DMD") -> DMD | AB6: RLTEHPS | AC6: RLT.ELC.EXT.HPS | AD6: bn-lum-yr | AE6: bn-lum | AH6: RRF | AI6: =AH6 -> RRF | AK6: =_xlfn.MINIFS($F$5:$F$80,$D$5:$D$80,AI6) -> 0.63504611 | AL6: =AVERAGEIFS($F$5:$F$79,$D$5:$D$79,AI6) -> 0.94513898
B7: RLTEINC | C7: =VLOOKUP(B7,'US9R topology'!$A$2:$C$261,3,FALSE) -> RESELC | D7: =VLOOKUP(LEFT(B7,3),$AH$5:$AI$9,2,FALSE) -> RLI | F7: 0.50737766 | G7: 0.53908877 | H7: 0.53908877 | I7: 0.57079987 | J7: 0.57079987 | L7: =$B7 -> RLTEINC | M7: 3.9809959 | N7: 4.580872 | O7: 5.3625288 | P7: 5.0989469 | Q7: 4.844454 | S7: =$B7 -> RLTEINC | U7: 2.6082192 | V7: 3.3561644 | W7: 4.1191781 | X7: 4.330137 | Y7: 4.5520548 | AA7: =IF(LEFT(A7,3)="\I:",A7,"DMD") -> DMD | AB7: RLTEINC | AC7: RLT.ELC.EXT.INC | AD7: bn-lum-yr | AE7: bn-lum | AH7: RSC | AI7: =AH7 -> RSC | AK7: =_xlfn.MINIFS($F$5:$F$80,$D$5:$D$80,AI7) -> 0.6 | AL7: =AVERAGEIFS($F$5:$F$79,$D$5:$D$79,AI7) -> 6.7808333
A8: \I: | B8: RLTELED | C8: =VLOOKUP(B8,'US9R topology'!$A$2:$C$261,3,FALSE) -> RESELC | D8: =VLOOKUP(LEFT(B8,3),$AH$5:$AI$9,2,FALSE) -> RLI | G8: 2.6954438 | H8: 3.2028215 | I8: 3.9321769 | L8: =$B8 -> RLTELED | N8: 29.993805 | O8: 10.906838 | P8: 6.0169391 | S8: =$B8 -> RLTELED | V8: 34.817808 | W8: 52.375342 | X8: 68.493151 | AA8: =IF(LEFT(A8,3)="\I:",A8,"DMD") -> \I: | AB8: RLTELED | AC8: RLT.ELC.EXT.LED | AD8: bn-lum-yr | AE8: bn-lum | AH8: RSH | AI8: =AH8 -> RSH | AK8: =_xlfn.MINIFS($F$5:$F$80,$D$5:$D$80,AI8) -> 0.78 | AL8: =AVERAGEIFS($F$5:$F$79,$D$5:$D$79,AI8) -> 1.2973077
A9: \I: | B9: RLTGCFL | C9: =VLOOKUP(B9,'US9R topology'!$A$2:$C$261,3,FALSE) -> RESELC | D9: =VLOOKUP(LEFT(B9,3),$AH$5:$AI$9,2,FALSE) -> RLI | F9: 2.0295106 | G9: 2.1880662 | H9: 2.2514884 | I9: 2.3466217 | J9: 2.4734661 | L9: =$B9 -> RLTGCFL | M9: 1.9541418 | N9: 1.8450735 | O9: 1.7996283 | P9: 1.717827 | Q9: 1.6269367 | S9: =$B9 -> RLTGCFL | U9: 13.69863 | V9: 13.69863 | W9: 14.045205 | X9: 14.763014 | Y9: 15.517808 | AA9: =IF(LEFT(A9,3)="\I:",A9,"DMD") -> \I: | AB9: RLTGCFL | AC9: RLT.ELC.GSL.CFL | AD9: bn-lum-yr | AE9: bn-lum | AH9: RWH | AI9: RHW | AK9: =_xlfn.MINIFS($F$5:$F$80,$D$5:$D$80,AI9) -> 0.53 | AL9: =AVERAGEIFS($F$5:$F$79,$D$5:$D$79,AI9) -> 0.92875
B10: RLTGICE | C10: RESELC | D10: =VLOOKUP(LEFT(B10,3),$AH$5:$AI$9,2,FALSE) -> RLI | F10: 0.44395545 | G10: 0.53908877 | L10: =$B10 -> RLTGICE | M10: 1.8632515 | N10: 1.8087173 | S10: =$B10 -> RLTGICE | T10: 1.369863 | AA10: =IF(LEFT(A10,3)="\I:",A10,"DMD") -> DMD | AB10: =S10 -> RLTGICE | AC10: RLT.ELC.GSL.INC | AD10: bn-lum-yr | AE10: bn-lum
A11: \I: | B11: RLTGLED | C11: =VLOOKUP(B11,'US9R topology'!$A$2:$C$261,3,FALSE) -> RESELC | D11: =VLOOKUP(LEFT(B11,3),$AH$5:$AI$9,2,FALSE) -> RLI | F11: 1.7123996 | G11: 2.9808438 | H11: 3.9955991 | I11: 4.1541546 | L11: =$B11 -> RLTGLED | M11: 23.631483 | N11: 13.633548 | O11: 2.7267095 | P11: 2.7267095 | S11: =$B11 -> RLTGLED | U11: 28.538356 | V11: 33.105479 | W11: 61.643836 | X11: 68.493151 | AA11: =IF(LEFT(A11,3)="\I:",A11,"DMD") -> \I: | AB11: RLTGLED | AC11: RLT.ELC.GSL.LED | AD11: bn-lum-yr | AE11: bn-lum
A12: \I: | B12: RLTLLED | C12: =VLOOKUP(B12,'US9R topology'!$A$2:$C$261,3,FALSE) -> RESELC | D12: =VLOOKUP(LEFT(B12,3),$AH$5:$AI$9,2,FALSE) -> RLI | G12: 3.678488 | H12: 4.3127101 | I12: 5.200621 | L12: =$B12 -> RLTLLED | N12: 31.284448 | O12: 20.686636 | P12: 9.4889492 | S12: =$B12 -> RLTLLED | V12: 61.643836 | W12: 67.123288 | X12: 68.493151 | AA12: =IF(LEFT(A12,3)="\I:",A12,"DMD") -> \I: | AB12: RLTLLED | AC12: RLT.ELC.LFL.LED | AD12: bn-lum-yr | AE12: bn-lum
B13: RLTLT8 | C13: =VLOOKUP(B13,'US9R topology'!$A$2:$C$261,3,FALSE) -> RESELC | D13: =VLOOKUP(LEFT(B13,3),$AH$5:$AI$9,2,FALSE) -> RLI | F13: 2.5051772 | G13: 2.5051772 | H13: 2.9174216 | I13: 2.9174216 | J13: 2.9808438 | L13: =$B13 -> RLTLT8 | M13: 0.77256771 | N13: 0.77256771 | O13: 4.8808101 | P13: 4.6444953 | Q13: 4.4172695 | S13: =$B13 -> RLTLT8 | U13: 20 | AA13: =IF(LEFT(A13,3)="\I:",A13,"DMD") -> DMD | AB13: RLTLT8 | AC13: RLT.ELC.LFL.T8 | AD13: bn-lum-yr | AE13: bn-lum
B14: RLTRCFL | C14: =VLOOKUP(B14,'US9R topology'!$A$2:$C$261,3,FALSE) -> RESELC | D14: =VLOOKUP(LEFT(B14,3),$AH$5:$AI$9,2,FALSE) -> RLI | F14: 1.4904219 | G14: 1.4904219 | H14: 1.5538441 | I14: 1.6172663 | J14: 1.7123996 | L14: =$B14 -> RLTRCFL | M14: 2.6994425 | N14: 5.3352617 | O14: 4.8353649 | P14: 4.5990501 | Q14: 4.3809133 | S14: =$B14 -> RLTRCFL | U14: 10 | AA14: =IF(LEFT(A14,3)="\I:",A14,"DMD") -> DMD | AB14: RLTRCFL | AC14: RLT.ELC.REF.CFL | AD14: bn-lum-yr | AE14: bn-lum
B15: RLTRHAL | C15: =VLOOKUP(B15,'US9R topology'!$A$2:$C$261,3,FALSE) -> RESELC | D15: =VLOOKUP(LEFT(B15,3),$AH$5:$AI$9,2,FALSE) -> RLI | F15: 0.41224435 | G15: 0.41224435 | H15: 0.44395545 | I15: 0.47566656 | J15: 0.50737766 | L15: =$B15 -> RLTRHAL | M15: 4.3809133 | N15: 3.8083043 | O15: 5.0625907 | P15: 4.8171869 | Q15: 4.580872 | S15: =$B15 -> RLTRHAL | U15: 1.9178082 | V15: 1.9178082 | W15: 2.1068493 | X15: 2.2150685 | Y15: 2.3273973 | AA15: =IF(LEFT(A15,3)="\I:",A15,"DMD") -> DMD | AB15: RLTRHAL | AC15: RLT.ELC.REF.HAL | AD15: bn-lum-yr | AE15: bn-lum
B16: RLTRINC | C16: =VLOOKUP(B16,'US9R topology'!$A$2:$C$261,3,FALSE) -> RESELC | D16: =VLOOKUP(LEFT(B16,3),$AH$5:$AI$9,2,FALSE) -> RLI | F16: 0.31711104 | G16: 0.31711104 | H16: 0.31711104 | I16: 0.31711104 | J16: 0.31711104 | L16: =$B16 -> RLTRINC | M16: 1.8178064 | N16: 1.2451974 | O16: 2.9902915 | P16: 2.844867 | Q16: 2.6994425 | S16: =$B16 -> RLTRINC | U16: 2.739726 | V16: 2.739726 | W16: 2.809589 | X16: 2.9520548 | Y16: 3.1041096 | AA16: =IF(LEFT(A16,3)="\I:",A16,"DMD") -> DMD | AB16: RLTRINC | AC16: RLT.ELC.REF.INC. | AD16: bn-lum-yr | AE16: bn-lum
B17: RLTRLED | C17: =VLOOKUP(B17,'US9R topology'!$A$2:$C$261,3,FALSE) -> RESELC | D17: =VLOOKUP(LEFT(B17,3),$AH$5:$AI$9,2,FALSE) -> RLI | G17: 2.2197773 | H17: 2.7905771 | I17: 3.7101991 | L17: =$B17 -> RLTRLED | N17: 27.267095 | O17: 9.0890318 | P17: 4.4536256 | S17: =$B17 -> RLTRLED | V17: 20 | AA17: =IF(LEFT(A17,3)="\I:",A17,"DMD") -> DMD | AB17: RLTRLED | AC17: RLT.ELC.REF.LED | AD17: bn-lum-yr | AE17: bn-lum
B18: RRFBFV1 | C18: =VLOOKUP(B18,'US9R topology'!$A$2:$C$261,3,FALSE) -> RESELC | D18: =VLOOKUP(LEFT(B18,3),$AH$5:$AI$9,2,FALSE) -> RRF | F18: 0.73363775 | G18: 0.91634981 | L18: =$B18 -> RRFBFV1 | M18: 843.22 | N18: 886.24143 | S18: =$B18 -> RRFBFV1 | T18: 15 | AA18: =IF(LEFT(A18,3)="\I:",A18,"DMD") -> DMD | AB18: RRFBFV1 | AC18: RRF.ELC.BF.V1 | AD18: PJ | AE18: PJ/a
B19: RRFBFV2 | C19: =VLOOKUP(B19,'US9R topology'!$A$2:$C$261,3,FALSE) -> RESELC | D19: =VLOOKUP(LEFT(B19,3),$AH$5:$AI$9,2,FALSE) -> RRF | F19: 0.91634981 | G19: 1.0478261 | L19: =$B19 -> RRFBFV2 | M19: 903.45 | N19: 903.45 | S19: =$B19 -> RRFBFV2 | T19: 15 | AA19: =IF(LEFT(A19,3)="\I:",A19,"DMD") -> DMD | AB19: RRFBFV2 | AC19: RRF.ELC.BF.V2 | AD19: PJ | AE19: PJ/a
B20: RRFSFV1 | C20: =VLOOKUP(B20,'US9R topology'!$A$2:$C$261,3,FALSE) -> RESELC | D20: =VLOOKUP(LEFT(B20,3),$AH$5:$AI$9,2,FALSE) -> RRF | F20: 0.63504611 | G20: 0.76265823 | L20: =$B20 -> RRFSFV1 | M20: 1015.3057 | N20: 1049.7229 | S20: =$B20 -> RRFSFV1 | T20: 15 | AA20: =IF(LEFT(A20,3)="\I:",A20,"DMD") -> DMD | AB20: RRFSFV1 | AC20: RRF.ELC.SF.V1 | AD20: PJ | AE20: PJ/a
B21: RRFSFV2 | C21: =VLOOKUP(B21,'US9R topology'!$A$2:$C$261,3,FALSE) -> RESELC | D21: =VLOOKUP(LEFT(B21,3),$AH$5:$AI$9,2,FALSE) -> RRF | F21: 0.76265823 | G21: 0.90772128 | L21: =$B21 -> RRFSFV2 | M21: 1049.7229 | N21: 1230.4129 | S21: =$B21 -> RRFSFV2 | T21: 15 | AA21: =IF(LEFT(A21,3)="\I:",A21,"DMD") -> DMD | AB21: RRFSFV2 | AC21: RRF.ELC.SF.V2 | AD21: PJ | AE21: PJ/a
B22: RRFTFV1 | C22: =VLOOKUP(B22,'US9R topology'!$A$2:$C$261,3,FALSE) -> RESELC | D22: =VLOOKUP(LEFT(B22,3),$AH$5:$AI$9,2,FALSE) -> RRF | F22: 1 | G22: 1.1871921 | L22: =$B22 -> RRFTFV1 | M22: 499.04857 | N22: 593.69572 | S22: =$B22 -> RRFTFV1 | T22: 15 | AA22: =IF(LEFT(A22,3)="\I:",A22,"DMD") -> DMD | AB22: RRFTFV1 | AC22: RRF.ELC.TF.V1 | AD22: PJ | AE22: PJ/a
B23: RRFTFV2 | C23: =VLOOKUP(B23,'US9R topology'!$A$2:$C$261,3,FALSE) -> RESELC | D23: =VLOOKUP(LEFT(B23,3),$AH$5:$AI$9,2,FALSE) -> RRF | F23: 1.1871921 | G23: 1.2819149 | L23: =$B23 -> RRFTFV2 | M23: 593.69572 | N23: 731.36429 | S23: =$B23 -> RRFTFV2 | T23: 15 | AA23: =IF(LEFT(A23,3)="\I:",A23,"DMD") -> DMD | AB23: RRFTFV2 | AC23: RRF.ELC.TF.V2 | AD23: PJ | AE23: PJ/a
B24: RRFTFV3 | C24: =VLOOKUP(B24,'US9R topology'!$A$2:$C$261,3,FALSE) -> RESELC | D24: =VLOOKUP(LEFT(B24,3),$AH$5:$AI$9,2,FALSE) -> RRF | F24: 1.3810888 | G24: 1.3810888 | L24: =$B24 -> RRFTFV3 | M24: 800.19857 | N24: 800.19857 | S24: =$B24 -> RRFTFV3 | T24: 15 | AA24: =IF(LEFT(A24,3)="\I:",A24,"DMD") -> DMD | AB24: RRFTFV3 | AC24: RRF.ELC.TF.V3 | AD24: PJ | AE24: PJ/a
B25: RSCCACV1 | C25: =VLOOKUP(B25,'US9R topology'!$A$2:$C$261,3,FALSE) -> RESELC | D25: =VLOOKUP(LEFT(B25,3),$AH$5:$AI$9,2,FALSE) -> RSC | F25: 3.81 | L25: =$B25 -> RSCCACV1 | M25: 5.4306523 | S25: =$B25 -> RSCCACV1 | T25: 15 | AA25: =IF(LEFT(A25,3)="\I:",A25,"DMD") -> DMD | AB25: RSCCACV1 | AC25: RSC.ELC.CAC.V1 | AD25: PJ | AE25: PJ/a
B26: RSCCACV2 | C26: =VLOOKUP(B26,'US9R topology'!$A$2:$C$261,3,FALSE) -> RESELC | D26: =VLOOKUP(LEFT(B26,3),$AH$5:$AI$9,2,FALSE) -> RSC | F26: 3.96 | G26: 4.25 | L26: =$B26 -> RSCCACV2 | M26: 5.5599536 | N26: 5.9478573 | S26: =$B26 -> RSCCACV2 | T26: 15 | AA26: =IF(LEFT(A26,3)="\I:",A26,"DMD") -> DMD | AB26: RSCCACV2 | AC26: RSC.ELC.CAC.V2 | AD26: PJ | AE26: PJ/a
B27: RSCCACV3 | C27: =VLOOKUP(B27,'US9R topology'!$A$2:$C$261,3,FALSE) -> RESELC | D27: =VLOOKUP(LEFT(B27,3),$AH$5:$AI$9,2,FALSE) -> RSC | F27: 7.03 | L27: =$B27 -> RSCCACV3 | M27: 13.188727 | S27: =$B27 -> RSCCACV3 | T27: 15 | AA27: =IF(LEFT(A27,3)="\I:",A27,"DMD") -> DMD | AB27: RSCCACV3 | AC27: RSC.ELC.CAC.V3 | AD27: PJ | AE27: PJ/a
B28: RSCEHPV1 | C28: =VLOOKUP(B28,'US9R topology'!$A$2:$C$261,3,FALSE) -> RESELC | D28: =VLOOKUP(LEFT(B28,3),$AH$5:$AI$9,2,FALSE) -> RSC | F28: 3.81 | L28: =$B28 -> RSCEHPV1 | M28: 4.0729892 | S28: =$B28 -> RSCEHPV1 | T28: 15 | AA28: =IF(LEFT(A28,3)="\I:",A28,"DMD") -> DMD | AB28: RSCEHPV1 | AC28: RSC.ELC.HEATPUMP.V1 | AD28: PJ | AE28: PJ/a
B29: RSCEHPV2 | C29: =VLOOKUP(B29,'US9R topology'!$A$2:$C$261,3,FALSE) -> RESELC | D29: =VLOOKUP(LEFT(B29,3),$AH$5:$AI$9,2,FALSE) -> RSC | F29: 4.1 | H29: 4.25 | I29: 4.54 | J29: 4.69 | L29: =$B29 -> RSCEHPV2 | M29: 4.2669411 | O29: 4.3962424 | P29: 4.7194955 | Q29: 4.8487967 | S29: =$B29 -> RSCEHPV2 | T29: 15 | AA29: =IF(LEFT(A29,3)="\I:",A29,"DMD") -> DMD | AB29: RSCEHPV2 | AC29: RSC.ELC.HEATPUMP.V2 | AD29: PJ | AE29: PJ/a
A30: \I: | B30: RSCEHPV3 | C30: =VLOOKUP(B30,'US9R topology'!$A$2:$C$261,3,FALSE) -> RESELC | D30: =VLOOKUP(LEFT(B30,3),$AH$5:$AI$9,2,FALSE) -> RSC | F30: 6.45 | H30: 6.74 | I30: 7.03 | J30: 7.33 | L30: =$B30 -> RSCEHPV3 | M30: 5.8185561 | O30: 5.9478573 | P30: 6.1418092 | Q30: 6.335761 | S30: =$B30 -> RSCEHPV3 | T30: 15 | AA30: =IF(LEFT(A30,3)="\I:",A30,"DMD") -> \I: | AB30: RSCEHPV3 | AC30: RSC.ELC.HEATPUMP.V3 | AD30: PJ | AE30: PJ/a
A31: \I: | B31: RSCGHPV1 | C31: =VLOOKUP(B31,'US9R topology'!$A$2:$C$261,3,FALSE) -> RESELC | D31: =VLOOKUP(LEFT(B31,3),$AH$5:$AI$9,2,FALSE) -> RSC | F31: 14.2 | H31: 17.1 | I31: 21 | J31: 24 | L31: =$B31 -> RSCGHPV1 | M31: 16.162656 | O31: 22.627718 | P31: 22.627718 | Q31: 22.627718 | S31: =$B31 -> RSCGHPV1 | T31: 15 | AA31: =IF(LEFT(A31,3)="\I:",A31,"DMD") -> \I: | AB31: RSCGHPV1 | AC31: RSC.ELC.GHP.V1 | AD31: PJ | AE31: PJ/a
A32: \I: | B32: RSCGHPV2 | C32: =VLOOKUP(B32,'US9R topology'!$A$2:$C$261,3,FALSE) -> RESELC | D32: =VLOOKUP(LEFT(B32,3),$AH$5:$AI$9,2,FALSE) -> RSC | F32: 28 | H32: 36 | I32: 42 | J32: 46 | L32: =$B32 -> RSCGHPV2 | M32: 30.385793 | O32: 30.385793 | P32: 30.385793 | Q32: 30.385793 | S32: =$B32 -> RSCGHPV2 | T32: 15 | AA32: =IF(LEFT(A32,3)="\I:",A32,"DMD") -> \I: | AB32: RSCGHPV2 | AC32: RSC.ELC.GHP.V2 | AD32: PJ | AE32: PJ/a
B33: RSCNHPV1 | C33: =VLOOKUP(B33,'US9R topology'!$A$2:$C$261,3,FALSE) -> RESNGA | D33: =VLOOKUP(LEFT(B33,3),$AH$5:$AI$9,2,FALSE) -> RSC | F33: 0.6 | H33: 0.7 | L33: =$B33 -> RSCNHPV1 | M33: 16.938463 | O33: 16.938463 | S33: =$B33 -> RSCNHPV1 | T33: 15 | AA33: =IF(LEFT(A33,3)="\I:",A33,"DMD") -> DMD | AB33: RSCNHPV1 | AC33: RSC.NGA.HEATPUMP.V1 | AD33: PJ | AE33: PJ/a
B34: RSCRACV1 | C34: =VLOOKUP(B34,'US9R topology'!$A$2:$C$261,3,FALSE) -> RESELC | D34: =VLOOKUP(LEFT(B34,3),$AH$5:$AI$9,2,FALSE) -> RSC | F34: 2.87 | L34: =$B34 -> RSCRACV1 | M34: 3.5842305 | S34: =$B34 -> RSCRACV1 | T34: 10 | AA34: =IF(LEFT(A34,3)="\I:",A34,"DMD") -> DMD | AB34: RSCRACV1 | AC34: RSC.ELC.RAC.V1 | AD34: PJ | AE34: PJ/a
B35: RSCRACV2 | C35: =VLOOKUP(B35,'US9R topology'!$A$2:$C$261,3,FALSE) -> RESELC | D35: =VLOOKUP(LEFT(B35,3),$AH$5:$AI$9,2,FALSE) -> RSC | F35: 3.17 | I35: 3.19 | L35: =$B35 -> RSCRACV2 | M35: 3.7704243 | P35: 3.7704243 | S35: =$B35 -> RSCRACV2 | T35: 10 | AA35: =IF(LEFT(A35,3)="\I:",A35,"DMD") -> DMD | AB35: RSCRACV2 | AC35: RSC.ELC.RAC.V2 | AD35: PJ | AE35: PJ/a
B36: RSCRACV3 | C36: =VLOOKUP(B36,'US9R topology'!$A$2:$C$261,3,FALSE) -> RESELC | D36: =VLOOKUP(LEFT(B36,3),$AH$5:$AI$9,2,FALSE) -> RSC | F36: 3.37 | H36: 3.49 | I36: 3.78 | L36: =$B36 -> RSCRACV3 | M36: 5.2599747 | O36: 5.7254592 | P36: 6.0512983 | S36: =$B36 -> RSCRACV3 | T36: 10 | AA36: =IF(LEFT(A36,3)="\I:",A36,"DMD") -> DMD | AB36: RSCRACV3 | AC36: RSC.ELC.RAC.V3 | AD36: PJ | AE36: PJ/a
B37: RSHDFRV1 | C37: =VLOOKUP(B37,'US9R topology'!$A$2:$C$261,3,FALSE) -> RESOIL | D37: =VLOOKUP(LEFT(B37,3),$AH$5:$AI$9,2,FALSE) -> RSH | F37: 0.8 | G37: 0.83 | L37: =$B37 -> RSHDFRV1 | M37: 5.4461685 | N37: 6.1443952 | S37: =$B37 -> RSHDFRV1 | T37: 20 | AA37: =IF(LEFT(A37,3)="\I:",A37,"DMD") -> DMD | AB37: RSHDFRV1 | AC37: RSH.DSL.FURNACE.V1 | AD37: PJ | AE37: PJ/a
B38: RSHDFRV2 | C38: =VLOOKUP(B38,'US9R topology'!$A$2:$C$261,3,FALSE) -> RESOIL | D38: =VLOOKUP(LEFT(B38,3),$AH$5:$AI$9,2,FALSE) -> RSH | F38: 0.85 | L38: =$B38 -> RSHDFRV2 | M38: 7.261558 | S38: =$B38 -> RSHDFRV2 | T38: 20 | AA38: =IF(LEFT(A38,3)="\I:",A38,"DMD") -> DMD | AB38: RSHDFRV2 | AC38: RSH.DSL.FURNACE.V2 | AD38: PJ | AE38: PJ/a
B39: RSHDFRV3 | C39: =VLOOKUP(B39,'US9R topology'!$A$2:$C$261,3,FALSE) -> RESOIL | D39: =VLOOKUP(LEFT(B39,3),$AH$5:$AI$9,2,FALSE) -> RSH | F39: 0.97 | L39: =$B39 -> RSHDFRV3 | M39: 9.0769475 | S39: =$B39 -> RSHDFRV3 | T39: 20 | AA39: =IF(LEFT(A39,3)="\I:",A39,"DMD") -> DMD | AB39: RSHDFRV3 | AC39: RSH.DSL.FURNACE.V3 | AD39: PJ | AE39: PJ/a
B40: RSHDRDV1 | C40: =VLOOKUP(B40,'US9R topology'!$A$2:$C$261,3,FALSE) -> RESOIL | D40: =VLOOKUP(LEFT(B40,3),$AH$5:$AI$9,2,FALSE) -> RSH | F40: 0.8 | G40: 0.84 | H40: 0.86 | L40: =$B40 -> RSHDRDV1 | M40: 11.507811 | N40: 11.507811 | O40: 13.705932 | S40: =$B40 -> RSHDRDV1 | T40: 20 | AA40: =IF(LEFT(A40,3)="\I:",A40,"DMD") -> DMD | AB40: RSHDRDV1 | AC40: RSH.DSL.RADIANT.V1 | AD40: PJ | AE40: PJ/a
B41: RSHDRDV2 | C41: =VLOOKUP(B41,'US9R topology'!$A$2:$C$261,3,FALSE) -> RESOIL | D41: =VLOOKUP(LEFT(B41,3),$AH$5:$AI$9,2,FALSE) -> RSH | F41: 0.85 | H41: 0.86 | L41: =$B41 -> RSHDRDV2 | M41: 13.705932 | O41: 13.705932 | S41: =$B41 -> RSHDRDV2 | T41: 20 | AA41: =IF(LEFT(A41,3)="\I:",A41,"DMD") -> DMD | AB41: RSHDRDV2 | AC41: RSH.DSL.RADIANT.V2 | AD41: PJ | AE41: PJ/a
B42: RSHDRDV3 | C42: =VLOOKUP(B42,'US9R topology'!$A$2:$C$261,3,FALSE) -> RESOIL | D42: =VLOOKUP(LEFT(B42,3),$AH$5:$AI$9,2,FALSE) -> RSH | F42: 0.91 | L42: =$B42 -> RSHDRDV3 | M42: 17.391018 | S42: =$B42 -> RSHDRDV3 | T42: 20 | AA42: =IF(LEFT(A42,3)="\I:",A42,"DMD") -> DMD | AB42: RSHDRDV3 | AC42: RSH.DSL.RADIANT.V3 | AD42: PJ | AE42: PJ/a
...

Sheet COM
B3: ~FI_T:EFF | M3: ~FI_T:NCAP_COST~USD05 | U3: ~FI_T:NCAP_FOM~USD05 | AD3: ~FI_T:NCAP_TLIFE | AG3: ~FI_Process
A4: TimeSlice | B4: process | C4: Comm-IN | D4: Comm-OUT | E4: 2010 | F4: 2011 | G4: 2015 | H4: 2020 | I4: 2030 | J4: 2040 | K4: 2050 | M4: process | N4: 2011 | O4: 2015 | P4: 2020 | Q4: 2030 | R4: 2040 | S4: 2050 | U4: process | V4: 2010 | W4: 2011 | X4: 2015 | Y4: 2020 | Z4: 2030 | AA4: 2040 | AB4: 2050 | AD4: process | AE4: 2010 | AG4: Sets | AH4: TechName | AI4: TechDesc | AJ4: Tact | AK4: Tcap | AP4: MIN Eff | AQ4: AVG
B5: CCKELB | C5: =VLOOKUP(B5,'US9R topology'!$A$2:$C$261,3,FALSE) -> COMELC | D5: =VLOOKUP(LEFT(B5,3),$AM$5:$AN$10,2,FALSE) -> CCK | F5: 0.7 | M5: =$B5 -> CCKELB | N5: 4.8928632 | U5: =$B5 -> CCKELB | W5: 0.039815343 | AD5: =$B5 -> CCKELB | AE5: 10 | AG5: =IF(LEFT(A5,3)="\I:",A5,"DMD") -> DMD | AH5: CCKELB | AI5: CCK.ELC.RANGE.ST | AJ5: PJ | AK5: PJ/a | AM5: CCK | AN5: =AM5 -> CCK | AP5: =_xlfn.MINIFS($F$5:$F$154,$D$5:$D$154,AN5) -> 0.35 | AQ5: =AVERAGEIFS($F$5:$F$154,$D$5:$D$154,AN5) -> 0.58
B6: CCKELI | C6: =VLOOKUP(B6,'US9R topology'!$A$2:$C$261,3,FALSE) -> COMELC | D6: =VLOOKUP(LEFT(B6,3),$AM$5:$AN$10,2,FALSE) -> CCK | F6: 0.8 | M6: =$B6 -> CCKELI | N6: 5.7216122 | U6: =$B6 -> CCKELI | W6: 0.039815343 | AD6: =$B6 -> CCKELI | AE6: 10 | AG6: =IF(LEFT(A6,3)="\I:",A6,"DMD") -> DMD | AH6: CCKELI | AI6: CCK.ELC.INDUCTION.ST | AJ6: PJ | AK6: PJ/a | AM6: CLT | AN6: CLA | AP6: =_xlfn.MINIFS($F$5:$F$154,$D$5:$D$154,AN6) -> 0.31336913 | AQ6: =AVERAGEIFS($F$5:$F$154,$D$5:$D$154,AN6) -> 1.5836378
B7: CCKNGC | C7: =VLOOKUP(B7,'US9R topology'!$A$2:$C$261,3,FALSE) -> COMNGA | D7: =VLOOKUP(LEFT(B7,3),$AM$5:$AN$10,2,FALSE) -> CCK | F7: 0.6 | M7: =$B7 -> CCKNGC | N7: 4.782265 | U7: =$B7 -> CCKNGC | W7: 0.039815343 | AD7: =$B7 -> CCKNGC | AE7: 10 | AG7: =IF(LEFT(A7,3)="\I:",A7,"DMD") -> DMD | AH7: CCKNGC | AI7: CCK.NG.CONVECTION.ST | AJ7: PJ | AK7: PJ/a | AM7: CRF | AN7: =AM7 -> CRF | AP7: =_xlfn.MINIFS($F$5:$F$154,$D$5:$D$154,AN7) -> 0.79111065 | AQ7: =AVERAGEIFS($F$5:$F$154,$D$5:$D$154,AN7) -> 3.0354226
B8: CCKNGR | C8: =VLOOKUP(B8,'US9R topology'!$A$2:$C$261,3,FALSE) -> COMNGA | D8: =VLOOKUP(LEFT(B8,3),$AM$5:$AN$10,2,FALSE) -> CCK | F8: 0.45 | M8: =$B8 -> CCKNGR | N8: 3.5096487 | U8: =$B8 -> CCKNGR | W8: 0.039815343 | AD8: =$B8 -> CCKNGR | AE8: 10 | AG8: =IF(LEFT(A8,3)="\I:",A8,"DMD") -> DMD | AH8: CCKNGR | AI8: CCK.NG.RANGE.ST | AJ8: PJ | AK8: PJ/a | AM8: CSC | AN8: =AM8 -> CSC | AP8: =_xlfn.MINIFS($F$5:$F$154,$D$5:$D$154,AN8) -> 0.6 | AQ8: =AVERAGEIFS($F$5:$F$154,$D$5:$D$154,AN8) -> 2.7223683
B9: CLTCFL | C9: =VLOOKUP(B9,'US9R topology'!$A$2:$C$261,3,FALSE) -> COMELC | D9: =VLOOKUP(LEFT(B9,3),$AM$5:$AN$10,2,FALSE) -> CLA | F9: 1.3176947 | G9: 1.3792951 | H9: 1.4141241 | J9: 1.5624594 | M9: =$B9 -> CLTCFL | N9: 9.049926 | O9: 10.05019 | P9: 9.9901804 | R9: 9.7646332 | U9: =$B9 -> CLTCFL | W9: 0.22684272 | X9: 0.27330538 | Y9: 0.26353683 | AA9: 0.22818563 | AD9: =$B9 -> CLTCFL | AE9: 10 | AG9: =IF(LEFT(A9,3)="\I:",A9,"DMD") -> DMD | AH9: CLTCFL | AI9: CLT.ELC.CFL | AJ9: bn-lum-yr | AK9: bn-lum | AM9: CSH | AN9: =AM9 -> CSH | AP9: =_xlfn.MINIFS($F$5:$F$154,$D$5:$D$154,AN9) -> 0.77 | AQ9: =AVERAGEIFS($F$5:$F$154,$D$5:$D$154,AN9) -> 1.41176
B10: CLTHAL | C10: =VLOOKUP(B10,'US9R topology'!$A$2:$C$261,3,FALSE) -> COMELC | D10: =VLOOKUP(LEFT(B10,3),$AM$5:$AN$10,2,FALSE) -> CLA | F10: 0.51314908 | G10: 0.58392827 | H10: 0.59867319 | I10: 0.62928941 | J10: 0.66147136 | M10: =$B10 -> CLTHAL | N10: 7.8237107 | O10: 7.9978325 | P10: 7.9449406 | Q10: 7.8430518 | R10: 7.7461443 | U10: =$B10 -> CLTHAL | W10: 1.2966185 | X10: 1.0641762 | Y10: 1.0232075 | Z10: 0.94637896 | AA10: 0.8758622 | AD10: =$B10 -> CLTHAL | AE10: 10 | AG10: =IF(LEFT(A10,3)="\I:",A10,"DMD") -> DMD | AH10: CLTHAL | AI10: CLT.ELC.HAL | AJ10: bn-lum-yr | AK10: bn-lum | AM10: CWH | AN10: CHW | AP10: =_xlfn.MINIFS($F$5:$F$154,$D$5:$D$154,AN10) -> 0.77 | AQ10: =AVERAGEIFS($F$5:$F$154,$D$5:$D$154,AN10) -> 1.40695
B11: CLTHID | C11: =VLOOKUP(B11,'US9R topology'!$A$2:$C$261,3,FALSE) -> COMELC | D11: =VLOOKUP(LEFT(B11,3),$AM$5:$AN$10,2,FALSE) -> CLA | F11: 1.73963 | G11: 1.7500887 | H11: 1.7885304 | I11: 1.8681753 | J11: 1.9516546 | M11: =$B11 -> CLTHID | N11: 2.1517381 | O11: 2.0863741 | P11: 2.0564738 | Q11: 1.998875 | R11: 1.9440922 | U11: =$B11 -> CLTHID | W11: 0.16384886 | X11: 0.15864251 | Y11: 0.1527513 | Z11: 0.14168376 | AA11: 0.13150068 | AD11: =$B11 -> CLTHID | AE11: 10 | AG11: =IF(LEFT(A11,3)="\I:",A11,"DMD") -> DMD | AH11: CLTHID | AI11: CLT.ELC.HID | AJ11: bn-lum-yr | AK11: bn-lum
A12: \I: | B12: CLTHLEDHE | C12: =VLOOKUP(B12,'US9R topology'!$A$2:$C$261,3,FALSE) -> COMELC | D12: =VLOOKUP(LEFT(B12,3),$AM$5:$AN$10,2,FALSE) -> CLA | H12: 3.4253845 | I12: 4.7890964 | J12: 6.1528084 | M12: =$B12 -> CLTHLEDHE | P12: 1.5943999 | Q12: 1.061023 | R12: 0.76073196 | U12: =$B12 -> CLTHLEDHE | Y12: 0.12560902 | Z12: 0.081917073 | AA12: 0.058732878 | AD12: =$B12 -> CLTHLEDHE | AE12: 10 | AG12: =IF(LEFT(A12,3)="\I:",A12,"DMD") -> \I: | AH12: CLTHLEDHE | AI12: CLT.ELC.HAL.LED.HE | AJ12: bn-lum-yr | AK12: bn-lum
A13: \I: | B13: CLTHLEDST | C13: =VLOOKUP(B13,'US9R topology'!$A$2:$C$261,3,FALSE) -> COMELC | D13: =VLOOKUP(LEFT(B13,3),$AM$5:$AN$10,2,FALSE) -> CLA | F13: 1.7960218 | G13: 2.4578155 | H13: 3.1055106 | I13: 4.0183855 | J13: 4.9312605 | M13: =$B13 -> CLTHLEDST | N13: 5.4587238 | O13: 2.4818229 | P13: 1.5943999 | Q13: 1.061023 | R13: 0.76073196 | U13: =$B13 -> CLTHLEDST | W13: 0.95782918 | X13: 0.34216248 | Y13: 0.12560902 | Z13: 0.081917073 | AA13: 0.058732878 | AD13: =$B13 -> CLTHLEDST | AE13: 10 | AG13: =IF(LEFT(A13,3)="\I:",A13,"DMD") -> \I: | AH13: CLTHLEDST | AI13: CLT.ELC.HAL.LED.ST | AJ13: bn-lum-yr | AK13: bn-lum
B14: CLTICE | C14: COMELC | D14: =VLOOKUP(LEFT(B14,3),$AM$5:$AN$10,2,FALSE) -> CLA | F14: 0.31336913 | M14: =$B14 -> CLTICE | N14: 9.1954307 | U14: =$B14 -> CLTICE | W14: 2.1459788 | AD14: =$B14 -> CLTICE | AE14: 10 | AG14: =IF(LEFT(A14,3)="\I:",A14,"DMD") -> DMD | AH14: =AD14 -> CLTICE | AI14: CLT.ELC.INC | AJ14: bn-lum-yr | AK14: bn-lum
A15: \I: | B15: CLTLED | C15: =VLOOKUP(B15,'US9R topology'!$A$2:$C$261,3,FALSE) -> COMELC | D15: =VLOOKUP(LEFT(B15,3),$AM$5:$AN$10,2,FALSE) -> CLA | G15: 3.2625039 | H15: 5.0507781 | I15: 6.9345467 | J15: 7.2935539 | M15: =$B15 -> CLTLED | O15: 5.1603146 | P15: 3.6308044 | Q15: 2.3286895 | R15: 1.6327228 | U15: =$B15 -> CLTLED | X15: 0.32708509 | Y15: 0.15287291 | Z15: 0.095044869 | AA15: 0.066589524 | AD15: =$B15 -> CLTLED | AE15: 10 | AG15: =IF(LEFT(A15,3)="\I:",A15,"DMD") -> \I: | AH15: CLTLED | AI15: CLT.ELC.LED | AJ15: bn-lum-yr | AK15: bn-lum
B16: CLTT5 | C16: =VLOOKUP(B16,'US9R topology'!$A$2:$C$261,3,FALSE) -> COMELC | D16: =VLOOKUP(LEFT(B16,3),$AM$5:$AN$10,2,FALSE) -> CLA | F16: 2.658204 | H16: 2.6876601 | I16: 2.7418997 | J16: 2.7972338 | M16: =$B16 -> CLTT5 | N16: 1.9848587 | P16: 1.7795343 | Q16: 1.7121695 | R16: 1.6480981 | U16: =$B16 -> CLTT5 | W16: 0.066033926 | Y16: 0.061031136 | Z16: 0.057139862 | AA16: 0.053525646 | AD16: =$B16 -> CLTT5 | AE16: 10 | AG16: =IF(LEFT(A16,3)="\I:",A16,"DMD") -> DMD | AH16: CLTT5 | AI16: CLT.ELC.T5 | AJ16: bn-lum-yr | AK16: bn-lum
B17: CLTT8 | C17: =VLOOKUP(B17,'US9R topology'!$A$2:$C$261,3,FALSE) -> COMELC | D17: =VLOOKUP(LEFT(B17,3),$AM$5:$AN$10,2,FALSE) -> CLA | F17: 2.7473956 | G17: 2.6974258 | H17: 2.7876392 | I17: 2.8238947 | J17: 2.8808836 | M17: =$B17 -> CLTT8 | N17: 1.2962249 | O17: 1.2640539 | P17: 1.330764 | Q17: 1.2398677 | R17: 1.2096229 | U17: =$B17 -> CLTT8 | W17: 0.10691074 | X17: 0.099770473 | Y17: 0.10556231 | Z17: 0.09519745 | AA17: 0.088599622 | AD17: =$B17 -> CLTT8 | AE17: 10 | AG17: =IF(LEFT(A17,3)="\I:",A17,"DMD") -> DMD | AH17: CLTT8 | AI17: CLT.ELC.T8 | AJ17: bn-lum-yr | AK17: bn-lum
A18: \I: | B18: CRFBVMHE | C18: =VLOOKUP(B18,'US9R topology'!$A$2:$C$261,3,FALSE) -> COMELC | D18: =VLOOKUP(LEFT(B18,3),$AM$5:$AN$10,2,FALSE) -> CRF | G18: 7.1082791 | H18: 8.7953107 | I18: 9.061103 | J18: 10.151559 | M18: =$B18 -> CRFBVMHE | O18: 50.798554 | P18: 54.877129 | Q18: 57.447984 | R18: 62.471783 | U18: =$B18 -> CRFBVMHE | X18: 1.8266603 | Y18: 1.8266603 | Z18: 1.8266603 | AA18: 1.8266603 | AD18: =$B18 -> CRFBVMHE | AE18: 10 | AG18: =IF(LEFT(A18,3)="\I:",A18,"DMD") -> \I: | AH18: CRFBVMHE | AI18: CRF.ELC.BVM.HE | AJ18: PJ | AK18: PJ/a
A19: \I: | B19: CRFBVMST | C19: =VLOOKUP(B19,'US9R topology'!$A$2:$C$261,3,FALSE) -> COMELC | D19: =VLOOKUP(LEFT(B19,3),$AM$5:$AN$10,2,FALSE) -> CRF | F19: 6.5806893 | G19: 6.7586916 | H19: 8.7255066 | I19: 8.7953107 | J19: 9.136403 | M19: =$B19 -> CRFBVMST | N19: 46.043438 | O19: 50.295981 | P19: 54.335896 | Q19: 54.877129 | R19: 59.496936 | U19: =$B19 -> CRFBVMST | W19: 2.0876118 | X19: 1.8846495 | Y19: 1.8266603 | Z19: 1.8266603 | AA19: 1.8266603 | AD19: =$B19 -> CRFBVMST | AE19: 10 | AG19: =IF(LEFT(A19,3)="\I:",A19,"DMD") -> \I: | AH19: CRFBVMST | AI19: CRF.ELC.BVM.ST | AJ19: PJ | AK19: PJ/a
A20: \I: | B20: CRFCENHE | C20: =VLOOKUP(B20,'US9R topology'!$A$2:$C$261,3,FALSE) -> COMELC | D20: =VLOOKUP(LEFT(B20,3),$AM$5:$AN$10,2,FALSE) -> CRF | G20: 3.8520842 | H20: 3.9052806 | I20: 4.9471442 | J20: 5.2075202 | M20: =$B20 -> CRFCENHE | O20: 61.211847 | P20: 62.266159 | Q20: 60.949554 | R20: 62.266159 | U20: =$B20 -> CRFCENHE | X20: 4.834409 | Y20: 4.834409 | Z20: 4.834409 | AA20: 4.834409 | AD20: =$B20 -> CRFCENHE | AE20: 10 | AG20: =IF(LEFT(A20,3)="\I:",A20,"DMD") -> \I: | AH20: CRFCENHE | AI20: CRF.ELC.CEN.HE | AJ20: PJ | AK20: PJ/a
B21: CRFCENST | C21: =VLOOKUP(B21,'US9R topology'!$A$2:$C$261,3,FALSE) -> COMELC | D21: =VLOOKUP(LEFT(B21,3),$AM$5:$AN$10,2,FALSE) -> CRF | F21: 3.3523436 | G21: 3.6010013 | H21: 3.8386851 | I21: 4.3227841 | J21: 4.9471442 | M21: =$B21 -> CRFCENST | N21: 55.600847 | O21: 57.812332 | P21: 59.951815 | Q21: 60.450685 | R21: 60.949554 | U21: =$B21 -> CRFCENST | W21: 4.834409 | X21: 4.834409 | Y21: 4.834409 | Z21: 4.834409 | AA21: 4.834409 | AD21: =$B21 -> CRFCENST | AE21: 10 | AG21: =IF(LEFT(A21,3)="\I:",A21,"DMD") -> DMD | AH21: CRFCENST | AI21: CRF.ELC.CEN.ST | AJ21: PJ | AK21: PJ/a
B22: CRFICMHE | C22: =VLOOKUP(B22,'US9R topology'!$A$2:$C$261,3,FALSE) -> COMELC | D22: =VLOOKUP(LEFT(B22,3),$AM$5:$AN$10,2,FALSE) -> CRF | G22: 0.83738366 | H22: 0.86855823 | I22: 0.95442706 | J22: 1.0046601 | M22: =$B22 -> CRFICMHE | O22: 124.07064 | P22: 125.68683 | Q22: 142.26434 | R22: 142.26434 | U22: =$B22 -> CRFICMHE | X22: 38.142108 | Y22: 38.142108 | Z22: 38.142108 | AA22: 38.142108 | AD22: =$B22 -> CRFICMHE | AE22: 8 | AG22: =IF(LEFT(A22,3)="\I:",A22,"DMD") -> DMD | AH22: CRFICMHE | AI22: CRF.ELC.ICM.HE | AJ22: PJ | AK22: PJ/a
B23: CRFICMST | C23: =VLOOKUP(B23,'US9R topology'!$A$2:$C$261,3,FALSE) -> COMELC | D23: =VLOOKUP(LEFT(B23,3),$AM$5:$AN$10,2,FALSE) -> CRF | F23: 0.79111065 | G23: 0.8186119 | H23: 0.86855823 | I23: 0.94796367 | J23: 0.99785649 | M23: =$B23 -> CRFICMST | N23: 112.71778 | O23: 119.08354 | P23: 124.07064 | Q23: 125.68683 | R23: 142.26434 | U23: =$B23 -> CRFICMST | W23: 38.142108 | X23: 38.142108 | Y23: 38.142108 | Z23: 38.142108 | AA23: 38.142108 | AD23: =$B23 -> CRFICMST | AE23: 8 | AG23: =IF(LEFT(A23,3)="\I:",A23,"DMD") -> DMD | AH23: CRFICMST | AI23: CRF.ELC.ICM.ST | AJ23: PJ | AK23: PJ/a
B24: CRFRIFHE | C24: =VLOOKUP(B24,'US9R topology'!$A$2:$C$261,3,FALSE) -> COMELC | D24: =VLOOKUP(LEFT(B24,3),$AM$5:$AN$10,2,FALSE) -> CRF | G24: 2.4427667 | H24: 2.5235193 | I24: 2.8039104 | J24: 3.1068259 | M24: =$B24 -> CRFRIFHE | O24: 84.540383 | P24: 88.778886 | Q24: 92.928249 | R24: 97.61084 | U24: =$B24 -> CRFRIFHE | X24: 3.7791577 | Y24: 3.7791577 | Z24: 3.7791577 | AA24: 3.7791577 | AD24: =$B24 -> CRFRIFHE | AE24: 10 | AG24: =IF(LEFT(A24,3)="\I:",A24,"DMD") -> DMD | AH24: CRFRIFHE | AI24: CRF.ELC.RIF.HE | AJ24: PJ | AK24: PJ/a
A25: \I: | B25: CRFRIFST | C25: =VLOOKUP(B25,'US9R topology'!$A$2:$C$261,3,FALSE) -> COMELC | D25: =VLOOKUP(LEFT(B25,3),$AM$5:$AN$10,2,FALSE) -> CRF | F25: 1.8505808 | G25: 1.993119 | H25: 2.5028347 | I25: 2.5235193 | J25: 2.9514846 | M25: =$B25 -> CRFRIFST | N25: 78.286608 | O25: 81.345847 | P25: 88.904162 | Q25: 85.459073 | R25: 93.537284 | U25: =$B25 -> CRFRIFST | W25: 3.7791577 | X25: 3.7791577 | Y25: 3.7791577 | Z25: 3.7791577 | AA25: 3.7791577 | AD25: =$B25 -> CRFRIFST | AE25: 10 | AG25: =IF(LEFT(A25,3)="\I:",A25,"DMD") -> \I: | AH25: CRFRIFST | AI25: CRF.ELC.RIF.ST | AJ25: PJ | AK25: PJ/a
A26: \I: | B26: CRFRIRHE | C26: =VLOOKUP(B26,'US9R topology'!$A$2:$C$261,3,FALSE) -> COMELC | D26: =VLOOKUP(LEFT(B26,3),$AM$5:$AN$10,2,FALSE) -> CRF | G26: 5.3955437 | H26: 5.6131297 | I26: 6.5397416 | J26: 6.7320869 | M26: =$B26 -> CRFRIRHE | O26: 120.20334 | P26: 119.58028 | Q26: 117.50588 | R26: 118.27835 | U26: =$B26 -> CRFRIRHE | X26: 5.7254421 | Y26: 5.7254421 | Z26: 5.7254421 | AA26: 5.7254421 | AD26: =$B26 -> CRFRIRHE | AE26: 10 | AG26: =IF(LEFT(A26,3)="\I:",A26,"DMD") -> \I: | AH26: CRFRIRHE | AI26: CRF.ELC.RIR.HE | AJ26: PJ | AK26: PJ/a
B27: CRFRIRST | C27: =VLOOKUP(B27,'US9R topology'!$A$2:$C$261,3,FALSE) -> COMELC | D27: =VLOOKUP(LEFT(B27,3),$AM$5:$AN$10,2,FALSE) -> CRF | F27: 3.2131059 | G27: 3.6985086 | H27: 5.1927264 | I27: 5.9701859 | J27: 6.1562925 | M27: =$B27 -> CRFRIRST | N27: 106.89096 | O27: 112.75864 | P27: 117.89855 | Q27: 126.16566 | R27: 128.22873 | U27: =$B27 -> CRFRIRST | W27: 5.7254421 | X27: 5.7254421 | Y27: 5.7254421 | Z27: 5.7254421 | AA27: 5.7254421 | AD27: =$B27 -> CRFRIRST | AE27: 10 | AG27: =IF(LEFT(A27,3)="\I:",A27,"DMD") -> DMD | AH27: CRFRIRST | AI27: CRF.ELC.RIR.ST | AJ27: PJ | AK27: PJ/a
B28: CRFRVMHE | C28: =VLOOKUP(B28,'US9R topology'!$A$2:$C$261,3,FALSE) -> COMELC | D28: =VLOOKUP(LEFT(B28,3),$AM$5:$AN$10,2,FALSE) -> CRF | G28: 3.0901786 | H28: 3.5969663 | I28: 3.7082127 | J28: 3.7838905 | M28: =$B28 -> CRFRVMHE | O28: 169.62917 | P28: 192.75508 | Q28: 198.54467 | R28: 202.48317 | U28: =$B28 -> CRFRVMHE | X28: 12.518943 | Y28: 12.518943 | Z28: 12.518943 | AA28: 12.518943 | AD28: =$B28 -> CRFRVMHE | AE28: 13.5 | AG28: =IF(LEFT(A28,3)="\I:",A28,"DMD") -> DMD | AH28: CRFRVMHE | AI28: CRF.ELC.RVM.HE | AJ28: PJ | AK28: PJ/a
B29: CRFRVMST | C29: =VLOOKUP(B29,'US9R topology'!$A$2:$C$261,3,FALSE) -> COMELC | D29: =VLOOKUP(LEFT(B29,3),$AM$5:$AN$10,2,FALSE) -> CRF | F29: 2.8482183 | G29: 2.8482183 | H29: 3.417118 | I29: 3.5228021 | J29: 3.594696 | M29: =$B29 -> CRFRVMST | N29: 166.24428 | O29: 166.24428 | P29: 183.39525 | Q29: 188.89536 | R29: 192.63693 | U29: =$B29 -> CRFRVMST | W29: 13.520458 | X29: 13.520458 | Y29: 12.518943 | Z29: 12.518943 | AA29: 12.518943 | AD29: =$B29 -> CRFRVMST | AE29: 13.5 | AG29: =IF(LEFT(A29,3)="\I:",A29,"DMD") -> DMD | AH29: CRFRVMST | AI29: CRF.ELC.RVM.ST | AJ29: PJ | AK29: PJ/a
B30: CRFWIFHE | C30: =VLOOKUP(B30,'US9R topology'!$A$2:$C$261,3,FALSE) -> COMELC | D30: =VLOOKUP(LEFT(B30,3),$AM$5:$AN$10,2,FALSE) -> CRF | G30: 2.7194607 | H30: 4.2680425 | I30: 4.4926763 | J30: 4.7291329 | M30: =$B30 -> CRFWIFHE | O30: 98.789293 | P30: 104.52025 | Q30: 104.52025 | R30: 104.52025 | U30: =$B30 -> CRFWIFHE | X30: 3.0370862 | Y30: 3.0370862 | Z30: 3.0370862 | AA30: 3.0370862 | AD30: =$B30 -> CRFWIFHE | AE30: 10 | AG30: =IF(LEFT(A30,3)="\I:",A30,"DMD") -> DMD | AH30: CRFWIFHE | AI30: CRF.ELC.WIF.HE | AJ30: PJ | AK30: PJ/a
B31: CRFWIFST | C31: =VLOOKUP(B31,'US9R topology'!$A$2:$C$261,3,FALSE) -> COMELC | D31: =VLOOKUP(LEFT(B31,3),$AM$5:$AN$10,2,FALSE) -> CRF | F31: 2.4833964 | G31: 2.4833964 | H31: 4.2302722 | I31: 4.4529181 | J31: 4.6872822 | M31: =$B31 -> CRFWIFST | N31: 98.603625 | O31: 98.603625 | P31: 101.82187 | Q31: 101.82187 | R31: 101.82187 | U31: =$B31 -> CRFWIFST | W31: 3.0370862 | X31: 3.0370862 | Y31: 3.0370862 | Z31: 3.0370862 | AA31: 3.0370862 | AD31: =$B31 -> CRFWIFST | AE31: 10 | AG31: =IF(LEFT(A31,3)="\I:",A31,"DMD") -> DMD | AH31: CRFWIFST | AI31: CRF.ELC.WIF.ST | AJ31: PJ | AK31: PJ/a
A32: \I: | B32: CRFWIRHE | C32: =VLOOKUP(B32,'US9R topology'!$A$2:$C$261,3,FALSE) -> COMELC | D32: =VLOOKUP(LEFT(B32,3),$AM$5:$AN$10,2,FALSE) -> CRF | G32: 3.5217487 | H32: 6.1240261 | I32: 6.4463432 | J32: 6.7856245 | M32: =$B32 -> CRFWIRHE | O32: 64.843019 | P32: 66.829727 | Q32: 66.829727 | R32: 66.829727 | U32: =$B32 -> CRFWIRHE | X32: 1.7758362 | Y32: 1.7758362 | Z32: 1.7758362 | AA32: 1.7758362 | AD32: =$B32 -> CRFWIRHE | AE32: 10 | AG32: =IF(LEFT(A32,3)="\I:",A32,"DMD") -> \I: | AH32: CRFWIRHE | AI32: CRF.ELC.WIR.HE | AJ32: PJ | AK32: PJ/a
B33: CRFWIRST | C33: =VLOOKUP(B33,'US9R topology'!$A$2:$C$261,3,FALSE) -> COMELC | D33: =VLOOKUP(LEFT(B33,3),$AM$5:$AN$10,2,FALSE) -> CRF | F33: 3.1639356 | G33: 3.1639356 | H33: 6.0633063 | I33: 6.3824276 | J33: 6.7183449 | M33: =$B33 -> CRFWIRST | N33: 64.735341 | O33: 64.734456 | P33: 66.391855 | Q33: 66.391855 | R33: 66.391855 | U33: =$B33 -> CRFWIRST | W33: 1.7159227 | X33: 1.7758362 | Y33: 1.7758362 | Z33: 1.7758362 | AA33: 1.7758362 | AD33: =$B33 -> CRFWIRST | AE33: 10 | AG33: =IF(LEFT(A33,3)="\I:",A33,"DMD") -> DMD | AH33: CRFWIRST | AI33: CRF.ELC.WIR.ST | AJ33: PJ | AK33: PJ/a
B34: CSCAHPHE | C34: =VLOOKUP(B34,'US9R topology'!$A$2:$C$261,3,FALSE) -> COMELC | D34: =VLOOKUP(LEFT(B34,3),$AM$5:$AN$10,2,FALSE) -> CSC | G34: 3.5169988 | H34: 3.7221571 | M34: =$B34 -> CSCAHPHE | O34: 9.9201516 | P34: 9.2984535 | U34: =$B34 -> CSCAHPHE | X34: 0.14060057 | Y34: 0.13319406 | AD34: =$B34 -> CSCAHPHE | AE34: 15 | AG34: =IF(LEFT(A34,3)="\I:",A34,"DMD") -> DMD | AH34: CSCAHPHE | AI34: CSC.ELC.AHP.HE | AJ34: PJ | AK34: PJ/a
B35: CSCAHPMD | C35: =VLOOKUP(B35,'US9R topology'!$A$2:$C$261,3,FALSE) -> COMELC | D35: =VLOOKUP(LEFT(B35,3),$AM$5:$AN$10,2,FALSE) -> CSC | G35: 3.34 | M35: =$B35 -> CSCAHPMD | O35: 8.0715144 | U35: =$B35 -> CSCAHPMD | X35: 0.14060057 | AD35: =$B35 -> CSCAHPMD | AE35: 15 | AG35: =IF(LEFT(A35,3)="\I:",A35,"DMD") -> DMD | AH35: CSCAHPMD | AI35: CSC.ELC.AHP.MD | AJ35: PJ | AK35: PJ/a
B36: CSCAHPST | C36: =VLOOKUP(B36,'US9R topology'!$A$2:$C$261,3,FALSE) -> COMELC | D36: =VLOOKUP(LEFT(B36,3),$AM$5:$AN$10,2,FALSE) -> CSC | F36: 2.989449 | G36: 3.2239156 | H36: 3.3411489 | M36: =$B36 -> CSCAHPST | N36: 7.8632173 | O36: 7.8632173 | P36: 7.2628461 | U36: =$B36 -> CSCAHPST | W36: 0.14060057 | X36: 0.14060057 | Y36: 0.13319406 | AD36: =$B36 -> CSCAHPST | AE36: 15 | AG36: =IF(LEFT(A36,3)="\I:",A36,"DMD") -> DMD | AH36: CSCAHPST | AI36: CSC.ELC.AHP.ST | AJ36: PJ | AK36: PJ/a
B37: CSCCACHE | C37: =VLOOKUP(B37,'US9R topology'!$A$2:$C$261,3,FALSE) -> COMELC | D37: =VLOOKUP(LEFT(B37,3),$AM$5:$AN$10,2,FALSE) -> CSC | G37: 7.0339977 | M37: =$B37 -> CSCCACHE | O37: 14.320429 | U37: =$B37 -> CSCCACHE | X37: 0.18876929 | AD37: =$B37 -> CSCCACHE | AE37: 18 | AG37: =IF(LEFT(A37,3)="\I:",A37,"DMD") -> DMD | AH37: CSCCACHE | AI37: CSC.ELC.CAC.HE | AJ37: PJ | AK37: PJ/a
B38: CSCCACMD | C38: =VLOOKUP(B38,'US9R topology'!$A$2:$C$261,3,FALSE) -> COMELC | D38: =VLOOKUP(LEFT(B38,3),$AM$5:$AN$10,2,FALSE) -> CSC | G38: 4.3962485 | M38: =$B38 -> CSCCACMD | O38: 9.8941145 | U38: =$B38 -> CSCCACMD | X38: 0.18876929 | AD38: =$B38 -> CSCCACMD | AE38: 18 | AG38: =IF(LEFT(A38,3)="\I:",A38,"DMD") -> DMD | AH38: CSCCACMD | AI38: CSC.ELC.CAC.MD | AJ38: PJ | AK38: PJ/a
B39: CSCCACST | C39: =VLOOKUP(B39,'US9R topology'!$A$2:$C$261,3,FALSE) -> COMELC | D39: =VLOOKUP(LEFT(B39,3),$AM$5:$AN$10,2,FALSE) -> CSC | F39: 3.6635404 | G39: 3.9566237 | I39: 4.1031653 | M39: =$B39 -> CSCCACST | N39: 8.722443 | O39: 8.8526287 | Q39: 6.0314293 | U39: =$B39 -> CSCCACST | W39: 0.18876929 | X39: 0.18876929 | Z39: 0.19099526 | AD39: =$B39 -> CSCCACST | AE39: 18 | AG39: =IF(LEFT(A39,3)="\I:",A39,"DMD") -> DMD | AH39: CSCCACST | AI39: CSC.ELC.CAC.ST | AJ39: PJ | AK39: PJ/a
A40: \I: | B40: CSCCCCHE | C40: =VLOOKUP(B40,'US9R topology'!$A$2:$C$261,3,FALSE) -> COMELC | D40: =VLOOKUP(LEFT(B40,3),$AM$5:$AN$10,2,FALSE) -> CSC | G40: 11.723329 | H40: 12.127582 | I40: 13.025922 | J40: 14.067995 | K40: 14.654162 | M40: =$B40 -> CSCCCCHE | O40: 4.9796037 | P40: 4.9796037 | Q40: 4.9796037 | R40: 4.9796037 | S40: 4.9796037 | U40: =$B40 -> CSCCCCHE | X40: 0.23433429 | Y40: 0.23433429 | Z40: 0.23433429 | AA40: 0.23433429 | AB40: 0.23433429 | AD40: =$B40 -> CSCCCCHE | AE40: 25 | AG40: =IF(LEFT(A40,3)="\I:",A40,"DMD") -> \I: | AH40: =AD40 -> CSCCCCHE | AI40: CSC.ELC.CCC.HE | AJ40: PJ | AK40: PJ/a
A41: \I: | B41: CSCCCCST | C41: =VLOOKUP(B41,'US9R topology'!$A$2:$C$261,3,FALSE) -> COMELC | D41: =VLOOKUP(LEFT(B41,3),$AM$5:$AN$10,2,FALSE) -> CSC | F41: 5.7769363 | G41: 9.5054022 | H41: 9.7694412 | I41: 10.048568 | J41: 10.344114 | K41: 10.657572 | M41: =$B41 -> CSCCCCST | N41: 3.1244572 | O41: 3.8079322 | P41: 3.8079322 | Q41: 3.8079322 | R41: 3.8079322 | S41: 3.8079322 | U41: =$B41 -> CSCCCCST | W41: 0.23433429 | X41: 0.23433429 | Y41: 0.23433429 | Z41: 0.23433429 | AA41: 0.23433429 | AB41: 0.23433429 | AD41: =$B41 -> CSCCCCST | AE41: 25 | AG41: =IF(LEFT(A41,3)="\I:",A41,"DMD") -> \I: | AH41: =AD41 -> CSCCCCST | AI41: CSC.ELC.CCC.ST | AJ41: PJ | AK41: PJ/a
B42: CSCCRCHE | C42: =VLOOKUP(B42,'US9R topology'!$A$2:$C$261,3,FALSE) -> COMELC | D42: =VLOOKUP(LEFT(B42,3),$AM$5:$AN$10,2,FALSE) -> CSC | G42: 4.4518973 | H42: 4.4518973 | M42: =$B42 -> CSCCRCHE | O42: 7.5182251 | P42: 7.5182251 | U42: =$B42 -> CSCCRCHE | X42: 0.27339 | Y42: 0.27339 | AD42: =$B42 -> CSCCRCHE | AE42: 20 | AG42: =IF(LEFT(A42,3)="\I:",A42,"DMD") -> DMD | AH42: =AD42 -> CSCCRCHE | AI42: CSC.ELC.CRC.HE | AJ42: PJ | AK42: PJ/a
...

Sheet US9R topology
A1: process | B1: commodity | C1: TIAM | E1: select process
A2: CCKELB | B2: COMELC | C2: =VLOOKUP(B2,$O$2:$P$14,2,FALSE) -> COMELC | E2: ,case | O2: COMDSL | P2: COMOIL
A3: CCKELBR | B3: COMELC | C3: =VLOOKUP(B3,$O$2:$P$14,2,FALSE) -> COMELC | F3: when not substring(commodity,1,3) in ('RES','COM') then sector || commodity | O3: COMELC | P3: =O3 -> COMELC
A4: CCKELI | B4: COMELC | C4: =VLOOKUP(B4,$O$2:$P$14,2,FALSE) -> COMELC | F4: else commodity | O4: COMLPG | P4: =O4 -> COMLPG
A5: CCKELIR | B5: COMELC | C5: =VLOOKUP(B5,$O$2:$P$14,2,FALSE) -> COMELC | E5: end as "commodity" | O5: COMNGA | P5: =O5 -> COMNGA
A6: CCKNGC | B6: COMNGA | C6: =VLOOKUP(B6,$O$2:$P$14,2,FALSE) -> COMNGA | E6: from topology | O6: COMRFL | P6: COMHFO
A7: CCKNGCR | B7: COMNGA | C7: =VLOOKUP(B7,$O$2:$P$14,2,FALSE) -> COMNGA | E7: where (process like 'C%' or process like 'R%') | O7: COMSOL | P7: =O7 -> COMSOL
A8: CCKNGR | B8: COMNGA | C8: =VLOOKUP(B8,$O$2:$P$14,2,FALSE) -> COMNGA | F8: and in_out='IN' and region='R1' and scenario='BASE' | O8: RESBIO | P8: =O8 -> RESBIO
A9: CCKNGRR | B9: COMNGA | C9: =VLOOKUP(B9,$O$2:$P$14,2,FALSE) -> COMNGA | O9: RESDSL | P9: RESOIL
A10: CLTCFL | B10: COMELC | C10: =VLOOKUP(B10,$O$2:$P$14,2,FALSE) -> COMELC | O10: RESELC | P10: =O10 -> RESELC
A11: CLTCFLR | B11: COMELC | C11: =VLOOKUP(B11,$O$2:$P$14,2,FALSE) -> COMELC | O11: RESKER | P11: =O11 -> RESKER
A12: CLTHAL | B12: COMELC | C12: =VLOOKUP(B12,$O$2:$P$14,2,FALSE) -> COMELC | O12: RESLPG | P12: =O12 -> RESLPG
A13: CLTHALR | B13: COMELC | C13: =VLOOKUP(B13,$O$2:$P$14,2,FALSE) -> COMELC | O13: RESNGA | P13: =O13 -> RESNGA
A14: CLTHID | B14: COMELC | C14: =VLOOKUP(B14,$O$2:$P$14,2,FALSE) -> COMELC | O14: RESSOL | P14: =O14 -> RESSOL
A15: CLTHIDR | B15: COMELC | C15: =VLOOKUP(B15,$O$2:$P$14,2,FALSE) -> COMELC
A16: CLTHLEDHE | B16: COMELC | C16: =VLOOKUP(B16,$O$2:$P$14,2,FALSE) -> COMELC
A17: CLTHLEDST | B17: COMELC | C17: =VLOOKUP(B17,$O$2:$P$14,2,FALSE) -> COMELC
A18: CLTINC | B18: COMELC | C18: =VLOOKUP(B18,$O$2:$P$14,2,FALSE) -> COMELC
A19: CLTINCR | B19: COMELC | C19: =VLOOKUP(B19,$O$2:$P$14,2,FALSE) -> COMELC
A20: CLTLED | B20: COMELC | C20: =VLOOKUP(B20,$O$2:$P$14,2,FALSE) -> COMELC
A21: CLTLEDR | B21: COMELC | C21: =VLOOKUP(B21,$O$2:$P$14,2,FALSE) -> COMELC
A22: CLTT5 | B22: COMELC | C22: =VLOOKUP(B22,$O$2:$P$14,2,FALSE) -> COMELC
A23: CLTT5R | B23: COMELC | C23: =VLOOKUP(B23,$O$2:$P$14,2,FALSE) -> COMELC
A24: CLTT8 | B24: COMELC | C24: =VLOOKUP(B24,$O$2:$P$14,2,FALSE) -> COMELC
A25: CLTT8R | B25: COMELC | C25: =VLOOKUP(B25,$O$2:$P$14,2,FALSE) -> COMELC
A26: CMDSLBS | B26: COMDSL | C26: =VLOOKUP(B26,$O$2:$P$14,2,FALSE) -> COMOIL
... A261: RWHSWHV1 | B261: RESSOL | C261: =VLOOKUP(B261,$O$2:$P$14,2,FALSE) -> RESSOL
