Workbook
Name FID_1: [1]AGR_Fuels!$A$2

Sheet data
D6: ~FI_T: USD15~UP | L6: ~FI_Process
B7: TechName | C7: Comm-IN | D7: Comm-OUT | E7: CEFF | F7: FLO_COST | G7: EFF | H7: INVCOST | I7: LIFE | J7: NCAP_BND~0 | L7: Sets | M7: TechName | N7: TechDesc | O7: Tact | P7: Tcap | Q7: Tslvl | R7: PrimaryCG | S7: Vintage
B8: =M8 -> Simple_bioref | D8: BIODST | E8: 0.38 | H8: =30*17/20 -> 25.5 | I8: 25 | J8: 2 | L8: PRE | M8: Simple_bioref | N8: place holder bio refinery | O8: PJ | P8: PJ-A
D9: BIOGSL | E9: 0.32 | M9: refineryinput | N9: place holder to balance REFFEED | O9: PJ | P9: PJ-A
C10: BIOBSL | M10: ethanesupply | N10: place holder for ethane production | O10: PJ | P10: PJ-A
B11: =M9 -> refineryinput | C11: OILCRD | D11: OILFEE,OILNCR,OILNSP | F11: 2 | G11: 1 | M11: IND_CCS | N11: Generic Industrial CCS (controlled via UC_IND CCS) | O11: kt | P11: ktpa
B12: =M10 -> ethanesupply | C12: OILNGL | D12: GASETH | F12: 1 | G12: 1
B13: =M11 -> IND_CCS | D13: CO2Captured_ind | H13: 1.25 | I13: 20
J18: 1.25 | K18: =PMT(0.07,20,J18) -> -0.11799116

Sheet RHG data
K1: ~FI_T: USD18 | W1: ~FI_Process
E2: TechName | F2: con_eff | G2: year | H2: INVCOST | I2: FIXOM | J2: VAROM | K2: Comm-IN | L2: Comm-IN-A | M2: Comm-OUT | N2: Comm-OUT-A | O2: EFF | P2: INPUT | Q2: OUTPUT | R2: ENV_ACT | S2: CAP2ACT | T2: LIFE | U2: START | W2: Sets | X2: Techname | Y2: TechDesc | Z2: Tact | AA2: Tcap
A3: biomass - > sng | B3: energy in/energy out | C3: biomass blend - solids | E3: =VLOOKUP(A3,$A$31:$B$39,2,FALSE) -> Brf_sng | F3: =conversion_efficiency!N5 -> 1.515 | H3: =IF($A3<>$A2,VLOOKUP($A3,conversion_capital_cost!$A$2:$M$35,13,FALSE),"") -> 2372 | I3: =IF($A3<>$A2,VLOOKUP($A3,conversion_fixed_om!$A$2:$M$35,13,FALSE),"") -> 119 | J3: =IF($A3<>$A2,VLOOKUP($A3,conversion_variable_om!$A$2:$M$35,13,FALSE),"") -> 0 | K3: =VLOOKUP(C3,$A$42:$B$50,2,FALSE) -> BIOBSL | M3: BIOSNG | O3: =1/F3 -> 0.66006601 | S3: =IF($E3=$E2,"",31.536) -> 31.536 | T3: =IF($E3=$E2,"",25) -> 25 | U3: 2030 | W3: PRE | X3: =IF($E3=$E2,"\I:",E3) -> Brf_sng | Y3: =A3 -> biomass - > sng | Z3: PJ | AA3: GW
A4: biomass - > sng | C4: electricity | E4: =VLOOKUP(A4,$A$31:$B$39,2,FALSE) -> Brf_sng | F4: =conversion_efficiency!N6 -> 0.021 | H4: =IF($A4<>$A3,VLOOKUP($A4,conversion_capital_cost!$A$2:$M$35,13,FALSE),"") | I4: =IF($A4<>$A3,VLOOKUP($A4,conversion_fixed_om!$A$2:$M$35,13,FALSE),"") | J4: =IF($A4<>$A3,VLOOKUP($A4,conversion_variable_om!$A$2:$M$35,13,FALSE),"") | L4: =VLOOKUP(C4,$A$42:$B$50,2,FALSE) -> SUPELC | P4: =F4 -> 0.021 | S4: =IF($E4=$E3,"",31.536) | T4: =IF($E4=$E3,"",25) | X4: =IF($E4=$E3,"\I:",E4) -> \I: | Y4: =A4 -> biomass - > sng | Z4: PJ | AA4: GW
A5: biomass -> sng w/ccu | B5: energy in/energy out | C5: biomass blend - solids | E5: =VLOOKUP(A5,$A$31:$B$39,2,FALSE) -> Brf_sng_ccs | F5: =conversion_efficiency!N7 -> 1.55 | H5: =IF($A5<>$A4,VLOOKUP($A5,conversion_capital_cost!$A$2:$M$35,13,FALSE),"") -> 2472 | I5: =IF($A5<>$A4,VLOOKUP($A5,conversion_fixed_om!$A$2:$M$35,13,FALSE),"") -> 146 | J5: =IF($A5<>$A4,VLOOKUP($A5,conversion_variable_om!$A$2:$M$35,13,FALSE),"") -> 0 | K5: =VLOOKUP(C5,$A$42:$B$50,2,FALSE) -> BIOBSL | M5: BIOSNG | O5: =1/F5 -> 0.64516129 | S5: =IF($E5=$E4,"",31.536) -> 31.536 | T5: =IF($E5=$E4,"",25) -> 25 | U5: 2035 | X5: =IF($E5=$E4,"\I:",E5) -> Brf_sng_ccs | Y5: =A5 -> biomass -> sng w/ccu | Z5: PJ | AA5: GW
A6: biomass -> sng w/ccu | C6: electricity | E6: =VLOOKUP(A6,$A$31:$B$39,2,FALSE) -> Brf_sng_ccs | F6: =conversion_efficiency!N8 -> 0.021 | H6: =IF($A6<>$A5,VLOOKUP($A6,conversion_capital_cost!$A$2:$M$35,13,FALSE),"") | I6: =IF($A6<>$A5,VLOOKUP($A6,conversion_fixed_om!$A$2:$M$35,13,FALSE),"") | J6: =IF($A6<>$A5,VLOOKUP($A6,conversion_variable_om!$A$2:$M$35,13,FALSE),"") | L6: =VLOOKUP(C6,$A$42:$B$50,2,FALSE) -> SUPELC | P6: =F6 -> 0.021 | S6: =IF($E6=$E5,"",31.536) | T6: =IF($E6=$E5,"",25) | X6: =IF($E6=$E5,"\I:",E6) -> \I: | Y6: =A6 -> biomass -> sng w/ccu | Z6: PJ | AA6: GW
A7: biomass -> sng w/ccu | B7: kilogram/gigajoule | C7: co2 utilization blend | E7: =VLOOKUP(A7,$A$31:$B$39,2,FALSE) -> Brf_sng_ccs | F7: =conversion_efficiency!N9 -> -46.064 | H7: =IF($A7<>$A6,VLOOKUP($A7,conversion_capital_cost!$A$2:$M$35,13,FALSE),"") | I7: =IF($A7<>$A6,VLOOKUP($A7,conversion_fixed_om!$A$2:$M$35,13,FALSE),"") | J7: =IF($A7<>$A6,VLOOKUP($A7,conversion_variable_om!$A$2:$M$35,13,FALSE),"") | M7: CO2Captured_ccu | R7: =ABS(F7) -> 46.064 | S7: =IF($E7=$E6,"",31.536) | T7: =IF($E7=$E6,"",25) | X7: =IF($E7=$E6,"\I:",E7) -> \I: | Y7: =A7 -> biomass -> sng w/ccu | Z7: PJ | AA7: GW
A8: biomass ft -> diesel | B8: energy in/energy out | C8: biomass blend - solids | E8: =VLOOKUP(A8,$A$31:$B$39,2,FALSE) -> Brf_FT_dsl | F8: =conversion_efficiency!N10 -> 2.15 | H8: =IF($A8<>$A7,VLOOKUP($A8,conversion_capital_cost!$A$2:$M$35,13,FALSE),"") -> 5365 | I8: =IF($A8<>$A7,VLOOKUP($A8,conversion_fixed_om!$A$2:$M$35,13,FALSE),"") -> 0 | J8: =IF($A8<>$A7,VLOOKUP($A8,conversion_variable_om!$A$2:$M$35,13,FALSE),"") -> 7.9 | K8: =VLOOKUP(C8,$A$42:$B$50,2,FALSE) -> BIOBSL | M8: BIODST,BIOJTK | O8: =1/F8 -> 0.46511628 | S8: =IF($E8=$E7,"",31.536) -> 31.536 | T8: =IF($E8=$E7,"",25) -> 25 | U8: 2030 | X8: =IF($E8=$E7,"\I:",E8) -> Brf_FT_dsl | Y8: =A8 -> biomass ft -> diesel | Z8: PJ | AA8: GW
A9: biomass ft -> diesel | C9: electricity | E9: =VLOOKUP(A9,$A$31:$B$39,2,FALSE) -> Brf_FT_dsl | F9: =conversion_efficiency!N11 -> 0.052 | H9: =IF($A9<>$A8,VLOOKUP($A9,conversion_capital_cost!$A$2:$M$35,13,FALSE),"") | I9: =IF($A9<>$A8,VLOOKUP($A9,conversion_fixed_om!$A$2:$M$35,13,FALSE),"") | J9: =IF($A9<>$A8,VLOOKUP($A9,conversion_variable_om!$A$2:$M$35,13,FALSE),"") | L9: =VLOOKUP(C9,$A$42:$B$50,2,FALSE) -> SUPELC | P9: =F9 -> 0.052 | S9: =IF($E9=$E8,"",31.536) | T9: =IF($E9=$E8,"",25) | X9: =IF($E9=$E8,"\I:",E9) -> \I: | Y9: =A9 -> biomass ft -> diesel | Z9: PJ | AA9: GW
A10: biomass ft -> diesel | C10: pipeline gas blend | E10: =VLOOKUP(A10,$A$31:$B$39,2,FALSE) -> Brf_FT_dsl | F10: =conversion_efficiency!N12 -> -0.097 | H10: =IF($A10<>$A9,VLOOKUP($A10,conversion_capital_cost!$A$2:$M$35,13,FALSE),"") | I10: =IF($A10<>$A9,VLOOKUP($A10,conversion_fixed_om!$A$2:$M$35,13,FALSE),"") | J10: =IF($A10<>$A9,VLOOKUP($A10,conversion_variable_om!$A$2:$M$35,13,FALSE),"") | N10: =VLOOKUP(C10,$A$42:$B$50,2,FALSE) -> BIOSNG | Q10: =ABS(F10) -> 0.097 | S10: =IF($E10=$E9,"",31.536) | T10: =IF($E10=$E9,"",25) | X10: =IF($E10=$E9,"\I:",E10) -> \I: | Y10: =A10 -> biomass ft -> diesel | Z10: PJ | AA10: GW
A11: biomass ft -> diesel | C11: steam blend | E11: =VLOOKUP(A11,$A$31:$B$39,2,FALSE) -> Brf_FT_dsl | F11: =conversion_efficiency!N13 -> -0.33 | H11: =IF($A11<>$A10,VLOOKUP($A11,conversion_capital_cost!$A$2:$M$35,13,FALSE),"") | I11: =IF($A11<>$A10,VLOOKUP($A11,conversion_fixed_om!$A$2:$M$35,13,FALSE),"") | J11: =IF($A11<>$A10,VLOOKUP($A11,conversion_variable_om!$A$2:$M$35,13,FALSE),"") | N11: =VLOOKUP(C11,$A$42:$B$50,2,FALSE) -> HET | Q11: =ABS(F11) -> 0.33 | S11: =IF($E11=$E10,"",31.536) | T11: =IF($E11=$E10,"",25) | X11: =IF($E11=$E10,"\I:",E11) -> \I: | Y11: =A11 -> biomass ft -> diesel | Z11: PJ | AA11: GW
A12: biomass ft -> diesel w/ccu | B12: energy in/energy out | C12: biomass blend - solids | E12: =VLOOKUP(A12,$A$31:$B$39,2,FALSE) -> Brf_FT_dsl_ccs | F12: =conversion_efficiency!N14 -> 2.15 | H12: =IF($A12<>$A11,VLOOKUP($A12,conversion_capital_cost!$A$2:$M$35,13,FALSE),"") -> 5451 | I12: =IF($A12<>$A11,VLOOKUP($A12,conversion_fixed_om!$A$2:$M$35,13,FALSE),"") -> 0 | J12: =IF($A12<>$A11,VLOOKUP($A12,conversion_variable_om!$A$2:$M$35,13,FALSE),"") -> 8.1 | K12: =VLOOKUP(C12,$A$42:$B$50,2,FALSE) -> BIOBSL | M12: BIODST,BIOJTK | O12: =1/F12 -> 0.46511628 | S12: =IF($E12=$E11,"",31.536) -> 31.536 | T12: =IF($E12=$E11,"",25) -> 25 | U12: 2035 | X12: =IF($E12=$E11,"\I:",E12) -> Brf_FT_dsl_ccs | Y12: =A12 -> biomass ft -> diesel w/ccu | Z12: PJ | AA12: GW
A13: biomass ft -> diesel w/ccu | C13: electricity | E13: =VLOOKUP(A13,$A$31:$B$39,2,FALSE) -> Brf_FT_dsl_ccs | F13: =conversion_efficiency!N15 -> 0.114 | H13: =IF($A13<>$A12,VLOOKUP($A13,conversion_capital_cost!$A$2:$M$35,13,FALSE),"") | I13: =IF($A13<>$A12,VLOOKUP($A13,conversion_fixed_om!$A$2:$M$35,13,FALSE),"") | J13: =IF($A13<>$A12,VLOOKUP($A13,conversion_variable_om!$A$2:$M$35,13,FALSE),"") | L13: =VLOOKUP(C13,$A$42:$B$50,2,FALSE) -> SUPELC | P13: =F13 -> 0.114 | S13: =IF($E13=$E12,"",31.536) | T13: =IF($E13=$E12,"",25) | X13: =IF($E13=$E12,"\I:",E13) -> \I: | Y13: =A13 -> biomass ft -> diesel w/ccu | Z13: PJ | AA13: GW
A14: biomass ft -> diesel w/ccu | C14: pipeline gas blend | E14: =VLOOKUP(A14,$A$31:$B$39,2,FALSE) -> Brf_FT_dsl_ccs | F14: =conversion_efficiency!N16 -> -0.097 | H14: =IF($A14<>$A13,VLOOKUP($A14,conversion_capital_cost!$A$2:$M$35,13,FALSE),"") | I14: =IF($A14<>$A13,VLOOKUP($A14,conversion_fixed_om!$A$2:$M$35,13,FALSE),"") | J14: =IF($A14<>$A13,VLOOKUP($A14,conversion_variable_om!$A$2:$M$35,13,FALSE),"") | N14: =VLOOKUP(C14,$A$42:$B$50,2,FALSE) -> BIOSNG | Q14: =ABS(F14) -> 0.097 | S14: =IF($E14=$E13,"",31.536) | T14: =IF($E14=$E13,"",25) | X14: =IF($E14=$E13,"\I:",E14) -> \I: | Y14: =A14 -> biomass ft -> diesel w/ccu | Z14: PJ | AA14: GW
A15: biomass ft -> diesel w/ccu | C15: steam blend | E15: =VLOOKUP(A15,$A$31:$B$39,2,FALSE) -> Brf_FT_dsl_ccs | F15: =conversion_efficiency!N17 -> -0.33 | H15: =IF($A15<>$A14,VLOOKUP($A15,conversion_capital_cost!$A$2:$M$35,13,FALSE),"") | I15: =IF($A15<>$A14,VLOOKUP($A15,conversion_fixed_om!$A$2:$M$35,13,FALSE),"") | J15: =IF($A15<>$A14,VLOOKUP($A15,conversion_variable_om!$A$2:$M$35,13,FALSE),"") | N15: =VLOOKUP(C15,$A$42:$B$50,2,FALSE) -> HET | Q15: =ABS(F15) -> 0.33 | S15: =IF($E15=$E14,"",31.536) | T15: =IF($E15=$E14,"",25) | X15: =IF($E15=$E14,"\I:",E15) -> \I: | Y15: =A15 -> biomass ft -> diesel w/ccu | Z15: PJ | AA15: GW
A16: biomass ft -> diesel w/ccu | B16: kilogram/gigajoule | C16: co2 utilization blend | E16: =VLOOKUP(A16,$A$31:$B$39,2,FALSE) -> Brf_FT_dsl_ccs | F16: =conversion_efficiency!N18 -> -81.512 | H16: =IF($A16<>$A15,VLOOKUP($A16,conversion_capital_cost!$A$2:$M$35,13,FALSE),"") | I16: =IF($A16<>$A15,VLOOKUP($A16,conversion_fixed_om!$A$2:$M$35,13,FALSE),"") | J16: =IF($A16<>$A15,VLOOKUP($A16,conversion_variable_om!$A$2:$M$35,13,FALSE),"") | M16: CO2Captured_ccu | R16: =ABS(F16) -> 81.512 | S16: =IF($E16=$E15,"",31.536) | T16: =IF($E16=$E15,"",25) | X16: =IF($E16=$E15,"\I:",E16) -> \I: | Y16: =A16 -> biomass ft -> diesel w/ccu | Z16: PJ | AA16: GW
A17: corn ethanol plant | B17: energy in/energy out | C17: biomass blend - corn | E17: =VLOOKUP(A17,$A$31:$B$39,2,FALSE) -> Brf_corn_eth | F17: =conversion_efficiency!N25 -> 2 | H17: =IF($A17<>$A16,VLOOKUP($A17,conversion_capital_cost!$A$2:$M$35,13,FALSE),"") -> 877 | I17: =IF($A17<>$A16,VLOOKUP($A17,conversion_fixed_om!$A$2:$M$35,13,FALSE),"") -> 32 | J17: =IF($A17<>$A16,VLOOKUP($A17,conversion_variable_om!$A$2:$M$35,13,FALSE),"") -> 1.8 | K17: =VLOOKUP(C17,$A$42:$B$50,2,FALSE) -> BIOBSL | M17: BIOGSL | O17: =1/F17 -> 0.5 | S17: =IF($E17=$E16,"",31.536) -> 31.536 | T17: =IF($E17=$E16,"",25) -> 25 | X17: =IF($E17=$E16,"\I:",E17) -> Brf_corn_eth | Y17: =A17 -> corn ethanol plant | Z17: PJ | AA17: GW
A18: corn ethanol plant | C18: coal blend | E18: =VLOOKUP(A18,$A$31:$B$39,2,FALSE) -> Brf_corn_eth | F18: =conversion_efficiency!N26 -> 0.025 | H18: =IF($A18<>$A17,VLOOKUP($A18,conversion_capital_cost!$A$2:$M$35,13,FALSE),"") | I18: =IF($A18<>$A17,VLOOKUP($A18,conversion_fixed_om!$A$2:$M$35,13,FALSE),"") | J18: =IF($A18<>$A17,VLOOKUP($A18,conversion_variable_om!$A$2:$M$35,13,FALSE),"") | L18: SUPCOA | P18: =F18 -> 0.025 | S18: =IF($E18=$E17,"",31.536) | T18: =IF($E18=$E17,"",25) | X18: =IF($E18=$E17,"\I:",E18) -> \I: | Y18: =A18 -> corn ethanol plant | Z18: PJ | AA18: GW
A19: corn ethanol plant | C19: diesel blend | E19: =VLOOKUP(A19,$A$31:$B$39,2,FALSE) -> Brf_corn_eth | F19: =conversion_efficiency!N27 -> 0 | H19: =IF($A19<>$A18,VLOOKUP($A19,conversion_capital_cost!$A$2:$M$35,13,FALSE),"") | I19: =IF($A19<>$A18,VLOOKUP($A19,conversion_fixed_om!$A$2:$M$35,13,FALSE),"") | J19: =IF($A19<>$A18,VLOOKUP($A19,conversion_variable_om!$A$2:$M$35,13,FALSE),"") | L19: \I: | S19: =IF($E19=$E18,"",31.536) | T19: =IF($E19=$E18,"",25) | X19: =IF($E19=$E18,"\I:",E19) -> \I: | Y19: =A19 -> corn ethanol plant | Z19: PJ | AA19: GW
A20: corn ethanol plant | C20: electricity | E20: =VLOOKUP(A20,$A$31:$B$39,2,FALSE) -> Brf_corn_eth | F20: =conversion_efficiency!N28 -> 0.034 | H20: =IF($A20<>$A19,VLOOKUP($A20,conversion_capital_cost!$A$2:$M$35,13,FALSE),"") | I20: =IF($A20<>$A19,VLOOKUP($A20,conversion_fixed_om!$A$2:$M$35,13,FALSE),"") | J20: =IF($A20<>$A19,VLOOKUP($A20,conversion_variable_om!$A$2:$M$35,13,FALSE),"") | L20: =VLOOKUP(C20,$A$42:$B$50,2,FALSE) -> SUPELC | P20: =F20 -> 0.034 | S20: =IF($E20=$E19,"",31.536) | T20: =IF($E20=$E19,"",25) | X20: =IF($E20=$E19,"\I:",E20) -> \I: | Y20: =A20 -> corn ethanol plant | Z20: PJ | AA20: GW
A21: corn ethanol plant | C21: pipeline gas blend | E21: =VLOOKUP(A21,$A$31:$B$39,2,FALSE) -> Brf_corn_eth | F21: =conversion_efficiency!N29 -> 0.298 | H21: =IF($A21<>$A20,VLOOKUP($A21,conversion_capital_cost!$A$2:$M$35,13,FALSE),"") | I21: =IF($A21<>$A20,VLOOKUP($A21,conversion_fixed_om!$A$2:$M$35,13,FALSE),"") | J21: =IF($A21<>$A20,VLOOKUP($A21,conversion_variable_om!$A$2:$M$35,13,FALSE),"") | L21: SUPNGA | P21: =F21 -> 0.298 | S21: =IF($E21=$E20,"",31.536) | T21: =IF($E21=$E20,"",25) | X21: =IF($E21=$E20,"\I:",E21) -> \I: | Y21: =A21 -> corn ethanol plant | Z21: PJ | AA21: GW
A22: direct air capture plant for power to fuels | B22: gigajoule/kilogram | C22: electricity | E22: =VLOOKUP(A22,$A$31:$B$39,2,FALSE) -> CCUS_DAC | F22: 0.018 | G22: 2020 | H22: 4.2828094 | I22: 0.055868815 | J22: 0.011259134 | K22: =VLOOKUP(C22,$A$42:$B$50,2,FALSE) -> SUPELC | M22: CO2Captured_ccu | P22: =F22 -> 0.018 | S22: 1 | T22: 25 | U22: 2030 | X22: =IF($E22=$E21,"\I:",E22) -> CCUS_DAC | Y22: =A22 -> direct air capture plant for power to fuels | Z22: kt | AA22: ktpa
F23: 0.011 | G23: 2030 | H23: 2.3841766 | I23: 0.052143463 | J23: 0.010500721 | K23: =K22 -> SUPELC | P23: =F23 -> 0.011 | X23: =IF($E25=$E24,"\I:",E25) -> CCUS_pow-to-liq | Y23: power - to - liquids | Z23: PJ | AA23: GW
F24: 0.00518 | G24: 2050 | H24: 1.0326654 | I24: 0.04469276 | J24: 0.0084004996 | K24: =K23 -> SUPELC | P24: =F24 -> 0.00518
A25: power - to - liquids | E25: =VLOOKUP(A25,$A$31:$B$42,2,FALSE) -> CCUS_pow-to-liq | G25: 2020 | H25: 1476 | I25: 57 | K25: HH2 | M25: OILDSTs,OILGSLs,OILJTKs,OILLPGs,OILHFOs | P25: 1.47 | S25: 31.536 | T25: 25 | U25: 2025
G26: 2025 | H26: 1390 | I26: 54 | L26: CO2Captured_ccu | P26: 67.2
G27: 2030 | H27: 1246 | I27: 48
G28: 2035 | H28: 1116 | I28: 43
G29: 2040 | H29: 994 | I29: 39
G30: 2045 | H30: 871 | I30: 34
A31: biomass - > sng | B31: Brf_sng | G31: 2050 | H31: 749 | I31: 29
A32: biomass -> sng w/ccu | B32: Brf_sng_ccs
A33: biomass ft -> diesel | B33: Brf_FT_dsl
A34: biomass ft -> diesel w/ccu | B34: Brf_FT_dsl_ccs
A35: biomass pyrolysis | B35: \I:
A36: biomass pyrolysis w/ccu | B36: \I:
A37: central-station hydrogen electrolysis | B37: \I:
A38: corn ethanol plant | B38: Brf_corn_eth
A39: direct air capture plant for power to fuels | B39: CCUS_DAC
A40: power - to - liquids | B40: CCUS_pow-to-liq
...

Sheet Sector fuels
B1: ~FI_T: USD18 | F1: ~FI_Process | M1: ~FI_Comm
A2: TechName | B2: Comm-IN | C2: Comm-OUT | D2: EFF | F2: Sets | G2: Techname | H2: TechDesc | I2: Tact | J2: Tcap | M2: CSet | N2: CommName | O2: CommDesc | P2: Unit | Q2: LimType | R2: CTSLvl | S2: PeakTS | T2: Ctype
A3: ="FT_"&B3 -> FT_BIOSNG | B3: =N3 -> BIOSNG | C3: INDSNG,COMSNG,RESSNG | D3: 1 | F3: PRE | G3: =A3 -> FT_BIOSNG | I3: PJ | J3: PJ-a | M3: NRG | N3: BIOSNG | O3: Nat gas from biomass | P3: PJ
A4: ="FT_"&B4 -> FT_BIOJTK | B4: BIOJTK | C4: TRABJT | D4: 1 | G4: =A4 -> FT_BIOJTK | I4: PJ | J4: PJ-a | N4: BIOJTK | O4: Biojet | P4: PJ
N5: TRABJT | O5: Transport biojet | P5: PJ
N6: INDSNG | O6: Industry sng | P6: PJ
N7: COMSNG | O7: Commercial sng | P7: PJ
N8: RESSNG | O8: Residential sng | P8: PJ
N9: OILDSTs | O9: Diesel - CCUS | P9: PJ
N10: OILGSLs | O10: Gasoline - CCUS | P10: PJ
N11: OILJTKs | O11: Jetkero - CCUS | P11: PJ
N12: OILLPGs | O12: LPG - CCUS | P12: PJ
N13: OILHFOs | O13: HFO - CCUS | P13: PJ

Sheet conversion_blend_outputs
A1: blend | B1: tech | C1: maximum blend share | E1: Notes:
A2: co2 utilization blend | B2: direct air capture plant for power to fuels | C2: 1 | E2: The conversion tech in column B can produce each of the blend fuels in column A with a maximum share given in column C.
A3: coal blend | B3: biomass pyrolysis | C3: 1 | O3: hydrogen blend | P3: HH2
A4: coal blend | B4: biomass pyrolysis w/ccu | C4: 1 | O4: pipeline gas blend | P4: BIOSNG
A5: coke blend | B5: biomass pyrolysis | C5: 1 | F5: autothermal reforming hydrogen production w/ccu -> hydrogen blend | G5: hydrogen blend | H5: =IF(F5=F4,H4&","&N5,N5) -> HH2 | N5: =VLOOKUP(G5,$O$3:$P$16,2,FALSE) -> HH2 | O5: diesel blend | P5: BIODST
A6: coke blend | B6: biomass pyrolysis w/ccu | C6: 1 | F6: BECCS hydrogen production -> hydrogen blend | G6: hydrogen blend | H6: =IF(F6=F5,H5&","&N6,N6) -> HH2 | N6: =VLOOKUP(G6,$O$3:$P$16,2,FALSE) -> HH2 | O6: jet fuel blend | P6: BIOJTK
A7: diesel blend | B7: biomass ft -> diesel | C7: 1 | F7: biomass - > sng | G7: pipeline gas blend | H7: =IF(F7=F6,H6&","&N7,N7) -> BIOSNG | N7: =VLOOKUP(G7,$O$3:$P$16,2,FALSE) -> BIOSNG | O7: lpg blend | P7: BIOLPG
A8: diesel blend | B8: biomass ft -> diesel w/ccu | C8: 1 | F8: biomass -> sng w/ccu | G8: pipeline gas blend | H8: =IF(F8=F7,H7&","&N8,N8) -> BIOSNG | N8: =VLOOKUP(G8,$O$3:$P$16,2,FALSE) -> BIOSNG | O8: residual fossil fuel oil blend | P8: BIORFO
A9: diesel blend | B9: power - to - liquids | C9: 1 | F9: biomass ft -> diesel | G9: diesel blend | H9: =IF(F9=F8,H8&","&N9,N9) -> BIODST | N9: =VLOOKUP(G9,$O$3:$P$16,2,FALSE) -> BIODST | O9: coal blend | P9: BIOCHR
A10: gasoline blend | B10: cellulosic ethanol plant | C10: 1 | F10: biomass ft -> diesel | G10: jet fuel blend | H10: =IF(F10=F9,H9&","&N10,N10) -> BIODST,BIOJTK | N10: =VLOOKUP(G10,$O$3:$P$16,2,FALSE) -> BIOJTK | O10: coke blend | P10: BIOCOK
A11: gasoline blend | B11: corn ethanol plant | C11: 1 | F11: biomass ft -> diesel | G11: lpg blend | H11: =IF(F11=F10,H10&","&N11,N11) -> BIODST,BIOJTK,BIOLPG | N11: =VLOOKUP(G11,$O$3:$P$16,2,FALSE) -> BIOLPG | O11: oil blend | P11: BIOOIL
A12: gasoline blend | B12: power - to - liquids | C12: 1 | F12: biomass ft -> diesel | G12: residual fossil fuel oil blend | H12: =IF(F12=F11,H11&","&N12,N12) -> BIODST,BIOJTK,BIOLPG,BIORFO | N12: =VLOOKUP(G12,$O$3:$P$16,2,FALSE) -> BIORFO | O12: petroleum coke blend | P12: BIOPCK
A13: hydrogen blend | B13: autothermal reforming hydrogen production w/ccu -> hydrogen blend | C13: 1 | F13: biomass ft -> diesel w/ccu | G13: diesel blend | H13: =IF(F13=F12,H12&","&N13,N13) -> BIODST | N13: =VLOOKUP(G13,$O$3:$P$16,2,FALSE) -> BIODST | O13: still gas blend | P13: BIOSNG
A14: hydrogen blend | B14: BECCS hydrogen production -> hydrogen blend | C14: 1 | F14: biomass ft -> diesel w/ccu | G14: jet fuel blend | H14: =IF(F14=F13,H13&","&N14,N14) -> BIODST,BIOJTK | N14: =VLOOKUP(G14,$O$3:$P$16,2,FALSE) -> BIOJTK | O14: gasoline blend | P14: BIOGSL
A15: hydrogen blend | B15: central-station hydrogen electrolysis | C15: 1 | F15: biomass ft -> diesel w/ccu | G15: lpg blend | H15: =IF(F15=F14,H14&","&N15,N15) -> BIODST,BIOJTK,BIOLPG | N15: =VLOOKUP(G15,$O$3:$P$16,2,FALSE) -> BIOLPG | O15: co2 utilization blend | P15: SUPCO2Nb
A16: hydrogen blend | B16: h2 natural gas reformation | C16: 1 | F16: biomass ft -> diesel w/ccu | G16: residual fossil fuel oil blend | H16: =IF(F16=F15,H15&","&N16,N16) -> BIODST,BIOJTK,BIOLPG,BIORFO | N16: =VLOOKUP(G16,$O$3:$P$16,2,FALSE) -> BIORFO | O16: steam blend | P16: HET
A17: jet fuel blend | B17: biomass ft -> diesel | C17: 1 | F17: biomass pyrolysis | G17: coal blend | H17: =IF(F17=F16,H16&","&N17,N17) -> BIOCHR | N17: =VLOOKUP(G17,$O$3:$P$16,2,FALSE) -> BIOCHR
A18: jet fuel blend | B18: biomass ft -> diesel w/ccu | C18: 1 | F18: biomass pyrolysis | G18: coke blend | H18: =IF(F18=F17,H17&","&N18,N18) -> BIOCHR,BIOCOK | N18: =VLOOKUP(G18,$O$3:$P$16,2,FALSE) -> BIOCOK
A19: jet fuel blend | B19: power - to - liquids | C19: 1 | F19: biomass pyrolysis | G19: oil blend | H19: =IF(F19=F18,H18&","&N19,N19) -> BIOCHR,BIOCOK,BIOOIL | N19: =VLOOKUP(G19,$O$3:$P$16,2,FALSE) -> BIOOIL
A20: lpg blend | B20: biomass ft -> diesel | C20: 1 | F20: biomass pyrolysis | G20: petroleum coke blend | H20: =IF(F20=F19,H19&","&N20,N20) -> BIOCHR,BIOCOK,BIOOIL,BIOPCK | N20: =VLOOKUP(G20,$O$3:$P$16,2,FALSE) -> BIOPCK
A21: lpg blend | B21: biomass ft -> diesel w/ccu | C21: 1 | F21: biomass pyrolysis | G21: still gas blend | H21: =IF(F21=F20,H20&","&N21,N21) -> BIOCHR,BIOCOK,BIOOIL,BIOPCK,BIOSNG | N21: =VLOOKUP(G21,$O$3:$P$16,2,FALSE) -> BIOSNG
A22: lpg blend | B22: power - to - liquids | C22: 1 | F22: biomass pyrolysis w/ccu | G22: coal blend | H22: =IF(F22=F21,H21&","&N22,N22) -> BIOCHR | N22: =VLOOKUP(G22,$O$3:$P$16,2,FALSE) -> BIOCHR
A23: oil blend | B23: biomass pyrolysis | C23: 1 | F23: biomass pyrolysis w/ccu | G23: coke blend | H23: =IF(F23=F22,H22&","&N23,N23) -> BIOCHR,BIOCOK | N23: =VLOOKUP(G23,$O$3:$P$16,2,FALSE) -> BIOCOK
A24: oil blend | B24: biomass pyrolysis w/ccu | C24: 1 | F24: biomass pyrolysis w/ccu | G24: oil blend | H24: =IF(F24=F23,H23&","&N24,N24) -> BIOCHR,BIOCOK,BIOOIL | N24: =VLOOKUP(G24,$O$3:$P$16,2,FALSE) -> BIOOIL
A25: petroleum coke blend | B25: biomass pyrolysis | C25: 1 | F25: biomass pyrolysis w/ccu | G25: petroleum coke blend | H25: =IF(F25=F24,H24&","&N25,N25) -> BIOCHR,BIOCOK,BIOOIL,BIOPCK | N25: =VLOOKUP(G25,$O$3:$P$16,2,FALSE) -> BIOPCK
A26: petroleum coke blend | B26: biomass pyrolysis w/ccu | C26: 1 | F26: biomass pyrolysis w/ccu | G26: still gas blend | H26: =IF(F26=F25,H25&","&N26,N26) -> BIOCHR,BIOCOK,BIOOIL,BIOPCK,BIOSNG | N26: =VLOOKUP(G26,$O$3:$P$16,2,FALSE) -> BIOSNG
A27: pipeline gas blend | B27: biomass - > sng | C27: 1 | F27: cellulosic ethanol plant | G27: gasoline blend | H27: =IF(F27=F26,H26&","&N27,N27) -> BIOGSL | N27: =VLOOKUP(G27,$O$3:$P$16,2,FALSE) -> BIOGSL
A28: pipeline gas blend | B28: biomass -> sng w/ccu | C28: 1 | F28: central-station hydrogen electrolysis | G28: hydrogen blend | H28: =IF(F28=F27,H27&","&N28,N28) -> HH2 | N28: =VLOOKUP(G28,$O$3:$P$16,2,FALSE) -> HH2
... A41: steam blend | B41: industrial pipeline gas boiler | C41: 1 | F41: industrial residual fuel oil oil boiler | G41: steam blend | H41: =IF(F41=F40,H40&","&N41,N41) -> HET | N41: =VLOOKUP(G41,$O$3:$P$16,2,FALSE) -> HET
A42: steam blend | B42: industrial residual fuel oil oil boiler | C42: 1 | F42: power - to - liquids | G42: diesel blend | H42: =IF(F42=F41,H41&","&N42,N42) -> OILDSTs | N42: OILDSTs
A43: still gas blend | B43: biomass pyrolysis | C43: 1 | F43: power - to - liquids | G43: gasoline blend | H43: =IF(F43=F42,H42&","&N43,N43) -> OILDSTs,OILGSLs | N43: OILGSLs
A44: still gas blend | B44: biomass pyrolysis w/ccu | C44: 1 | F44: power - to - liquids | G44: jet fuel blend | H44: =IF(F44=F43,H43&","&N44,N44) -> OILDSTs,OILGSLs,OILJTKs | N44: OILJTKs
F45: power - to - liquids | G45: lpg blend | H45: =IF(F45=F44,H44&","&N45,N45) -> OILDSTs,OILGSLs,OILJTKs,OILLPGs | N45: OILLPGs
F46: power - to - liquids | G46: residual fossil fuel oil blend | H46: =IF(F46=F45,H45&","&N46,N46) -> OILDSTs,OILGSLs,OILJTKs,OILLPGs,OILHFOs | N46: OILHFOs
F47: power-to-gas methanation | G47: pipeline gas blend | H47: =IF(F47=F46,H46&","&N47,N47) -> BIOSNG | N47: =VLOOKUP(G47,$O$3:$P$16,2,FALSE) -> BIOSNG

Sheet conversion_capital_cost
A1: tech | B1: zone | C1: vintage | D1: unit | E1: 100% RE | F1: central | G1: central low RE cost | H1: central low fuel price | I1: delayed electrification | J1: low demand | K1: low land | L1: net negative | M1: reference | N1: reference low RE cost | O1: reference low fuel price | R1: Notes
A2: BECCS hydrogen production -> hydrogen blend | B2: all | C2: all | D2: 2018 usd/kilowatt | E2: 2704 | F2: 2704 | G2: 2704 | H2: 2704 | I2: 2704 | J2: 2704 | K2: 2704 | L2: 2704 | M2: 2704 | N2: 2704 | O2: 2704 | R2: Costs are in dollars per unit of produced energy or carbon
A3: biomass - > sng | B3: all | C3: all | D3: 2018 usd/kilowatt | E3: 2372 | F3: 2372 | G3: 2372 | H3: 2372 | I3: 2372 | J3: 2372 | K3: 2372 | L3: 2372 | M3: 2372 | N3: 2372 | O3: 2372 | R3: techs can produce blend fuels as outlined on the conversion_blend_outputs tab
A4: biomass -> sng w/ccu | B4: all | C4: all | D4: 2018 usd/kilowatt | E4: 2472 | F4: 2472 | G4: 2472 | H4: 2472 | I4: 2472 | J4: 2472 | K4: 2472 | L4: 2472 | M4: 2472 | N4: 2472 | O4: 2472
A5: biomass ft -> diesel | B5: all | C5: all | D5: 2018 usd/kilowatt | E5: 5365 | F5: 5365 | G5: 5365 | H5: 5365 | I5: 5365 | J5: 5365 | K5: 5365 | L5: 5365 | M5: 5365 | N5: 5365 | O5: 5365 | R5: BECCS hydrogen production -> hydrogen blend
A6: biomass ft -> diesel w/ccu | B6: all | C6: all | D6: 2018 usd/kilowatt | E6: 5451 | F6: 5451 | G6: 5451 | H6: 5451 | I6: 5451 | J6: 5451 | K6: 5451 | L6: 5451 | M6: 5451 | N6: 5451 | O6: 5451 | R6: biomass - > sng
A7: biomass pyrolysis | B7: all | C7: all | D7: 2018 usd/kilowatt | E7: 2592 | F7: 2592 | G7: 2592 | H7: 2592 | I7: 2592 | J7: 2592 | K7: 2592 | L7: 2592 | M7: 2592 | N7: 2592 | O7: 2592 | R7: biomass -> sng w/ccu
A8: biomass pyrolysis w/ccu | B8: all | C8: all | D8: 2018 usd/kilowatt | E8: 4154 | F8: 4154 | G8: 4154 | H8: 4154 | I8: 4154 | J8: 4154 | K8: 4154 | L8: 4154 | M8: 4154 | N8: 4154 | O8: 4154 | R8: biomass ft -> diesel
A9: central-station hydrogen electrolysis | B9: all | C9: 2020 | D9: 2018 usd/kilowatt | E9: 1024 | F9: 1024 | G9: 1024 | H9: 1024 | I9: 1024 | J9: 1024 | K9: 1024 | L9: 1024 | M9: 1024 | N9: 1024 | O9: 1024 | R9: biomass ft -> diesel w/ccu
C10: 2025 | D10: 2018 usd/kilowatt | E10: 827 | F10: 827 | G10: 827 | H10: 827 | I10: 827 | J10: 827 | K10: 827 | L10: 827 | M10: 827 | N10: 827 | O10: 827 | R10: biomass pyrolysis
C11: 2030 | D11: 2018 usd/kilowatt | E11: 500 | F11: 500 | G11: 500 | H11: 500 | I11: 500 | J11: 500 | K11: 500 | L11: 500 | M11: 500 | N11: 500 | O11: 500 | R11: biomass pyrolysis w/ccu
C12: 2035 | D12: 2018 usd/kilowatt | E12: 347 | F12: 347 | G12: 347 | H12: 347 | I12: 347 | J12: 347 | K12: 347 | L12: 347 | M12: 347 | N12: 347 | O12: 347 | R12: central-station hydrogen electrolysis
C13: 2040 | D13: 2018 usd/kilowatt | E13: 310 | F13: 310 | G13: 310 | H13: 310 | I13: 310 | J13: 310 | K13: 310 | L13: 310 | M13: 310 | N13: 310 | O13: 310 | R13: corn ethanol plant
C14: 2045 | D14: 2018 usd/kilowatt | E14: 273 | F14: 273 | G14: 273 | H14: 273 | I14: 273 | J14: 273 | K14: 273 | L14: 273 | M14: 273 | N14: 273 | O14: 273 | R14: direct air capture plant for power to fuels
C15: 2050 | D15: 2018 usd/kilowatt | E15: 236 | F15: 236 | G15: 236 | H15: 236 | I15: 236 | J15: 236 | K15: 236 | L15: 236 | M15: 236 | N15: 236 | O15: 236 | R15: electric boiler
A16: corn ethanol plant | B16: all | C16: all | D16: 2018 usd/kilowatt | E16: 877 | F16: 877 | G16: 877 | H16: 877 | I16: 877 | J16: 877 | K16: 877 | L16: 877 | M16: 877 | N16: 877 | O16: 877 | R16: h2 natural gas reformation
A17: direct air capture plant for power to fuels | B17: all | C17: all | D17: 2018 usd/tonne | E17: 5554045 | F17: 5554045 | G17: 5554045 | H17: 5554045 | I17: 5554045 | J17: 5554045 | K17: 5554045 | L17: 5554045 | M17: 5554045 | N17: 5554045 | O17: 5554045 | R17: h2 natural gas reformation w/ccu
A18: electric boiler | B18: all | C18: all | D18: 2018 usd/kilowatt | E18: 383 | F18: 383 | G18: 383 | H18: 383 | I18: 383 | J18: 383 | K18: 383 | L18: 383 | M18: 383 | N18: 383 | O18: 383 | R18: industrial coal boiler
A19: h2 natural gas reformation | B19: all | C19: all | D19: 2018 usd/kilowatt | E19: 913 | F19: 913 | G19: 913 | H19: 913 | I19: 913 | J19: 913 | K19: 913 | L19: 913 | M19: 913 | N19: 913 | O19: 913 | R19: industrial distillate fuel oil boiler
A20: h2 natural gas reformation w/ccu | B20: all | C20: all | D20: 2018 usd/kilowatt | E20: 1632 | F20: 1632 | G20: 1632 | H20: 1632 | I20: 1632 | J20: 1632 | K20: 1632 | L20: 1632 | M20: 1632 | N20: 1632 | O20: 1632 | R20: industrial hydrogen boiler
A21: industrial coal boiler | B21: all | C21: all | D21: 2018 usd/kilowatt | E21: 466 | F21: 466 | G21: 466 | H21: 466 | I21: 466 | J21: 466 | K21: 466 | L21: 466 | M21: 466 | N21: 466 | O21: 466 | R21: industrial lpg boiler
A22: industrial distillate fuel oil boiler | B22: all | C22: all | D22: 2018 usd/kilowatt | E22: 304 | F22: 304 | G22: 304 | H22: 304 | I22: 304 | J22: 304 | K22: 304 | L22: 304 | M22: 304 | N22: 304 | O22: 304 | R22: industrial other petroleum boiler
A23: industrial hydrogen boiler | B23: all | C23: all | D23: 2018 usd/kilowatt | E23: 236 | F23: 236 | G23: 236 | H23: 236 | I23: 236 | J23: 236 | K23: 236 | L23: 236 | M23: 236 | N23: 236 | O23: 236 | R23: industrial petroleum coke boiler
A24: industrial lpg boiler | B24: all | C24: all | D24: 2018 usd/kilowatt | E24: 304 | F24: 304 | G24: 304 | H24: 304 | I24: 304 | J24: 304 | K24: 304 | L24: 304 | M24: 304 | N24: 304 | O24: 304 | R24: industrial pipeline gas boiler
A25: industrial other petroleum boiler | B25: all | C25: all | D25: 2018 usd/kilowatt | E25: 304 | F25: 304 | G25: 304 | H25: 304 | I25: 304 | J25: 304 | K25: 304 | L25: 304 | M25: 304 | N25: 304 | O25: 304 | R25: industrial residual fuel oil oil boiler
A26: industrial petroleum coke boiler | B26: all | C26: all | D26: 2018 usd/kilowatt | E26: 466 | F26: 466 | G26: 466 | H26: 466 | I26: 466 | J26: 466 | K26: 466 | L26: 466 | M26: 466 | N26: 466 | O26: 466 | R26: power - to - liquids
A27: industrial pipeline gas boiler | B27: all | C27: all | D27: 2018 usd/kilowatt | E27: 182 | F27: 182 | G27: 182 | H27: 182 | I27: 182 | J27: 182 | K27: 182 | L27: 182 | M27: 182 | N27: 182 | O27: 182 | R27: power-to-gas methanation
A28: industrial residual fuel oil oil boiler | B28: all | C28: all | D28: 2018 usd/kilowatt | E28: 304 | F28: 304 | G28: 304 | H28: 304 | I28: 304 | J28: 304 | K28: 304 | L28: 304 | M28: 304 | N28: 304 | O28: 304 | R28: power-to-lpg
A29: power - to - liquids | B29: all | C29: 2020 | D29: 2018 usd/kilowatt | E29: 1476 | F29: 1476 | G29: 1476 | H29: 1476 | I29: 1476 | J29: 1476 | K29: 1476 | L29: 1476 | M29: 1476 | N29: 1476 | O29: 1476
C30: 2025 | D30: 2018 usd/kilowatt | E30: 1390 | F30: 1390 | G30: 1390 | H30: 1390 | I30: 1390 | J30: 1390 | K30: 1390 | L30: 1390 | M30: 1390 | N30: 1390 | O30: 1390
C31: 2030 | D31: 2018 usd/kilowatt | E31: 1246 | F31: 1246 | G31: 1246 | H31: 1246 | I31: 1246 | J31: 1246 | K31: 1246 | L31: 1246 | M31: 1246 | N31: 1246 | O31: 1246
C32: 2035 | D32: 2018 usd/kilowatt | E32: 1116 | F32: 1116 | G32: 1116 | H32: 1116 | I32: 1116 | J32: 1116 | K32: 1116 | L32: 1116 | M32: 1116 | N32: 1116 | O32: 1116
C33: 2040 | D33: 2018 usd/kilowatt | E33: 994 | F33: 994 | G33: 994 | H33: 994 | I33: 994 | J33: 994 | K33: 994 | L33: 994 | M33: 994 | N33: 994 | O33: 994
C34: 2045 | D34: 2018 usd/kilowatt | E34: 871 | F34: 871 | G34: 871 | H34: 871 | I34: 871 | J34: 871 | K34: 871 | L34: 871 | M34: 871 | N34: 871 | O34: 871
C35: 2050 | D35: 2018 usd/kilowatt | E35: 749 | F35: 749 | G35: 749 | H35: 749 | I35: 749 | J35: 749 | K35: 749 | L35: 749 | M35: 749 | N35: 749 | O35: 749
A36: power-to-gas methanation | B36: all | C36: 2020 | D36: 2018 usd/kilowatt | E36: 1106 | F36: 1106 | G36: 1106 | H36: 1106 | I36: 1106 | J36: 1106 | K36: 1106 | L36: 1106 | M36: 1106 | N36: 1106 | O36: 1106
C37: 2025 | D37: 2018 usd/kilowatt | E37: 982 | F37: 982 | G37: 982 | H37: 982 | I37: 982 | J37: 982 | K37: 982 | L37: 982 | M37: 982 | N37: 982 | O37: 982
C38: 2030 | D38: 2018 usd/kilowatt | E38: 775 | F38: 775 | G38: 775 | H38: 775 | I38: 775 | J38: 775 | K38: 775 | L38: 775 | M38: 775 | N38: 775 | O38: 775
C39: 2035 | D39: 2018 usd/kilowatt | E39: 632 | F39: 632 | G39: 632 | H39: 632 | I39: 632 | J39: 632 | K39: 632 | L39: 632 | M39: 632 | N39: 632 | O39: 632
C40: 2040 | D40: 2018 usd/kilowatt | E40: 531 | F40: 531 | G40: 531 | H40: 531 | I40: 531 | J40: 531 | K40: 531 | L40: 531 | M40: 531 | N40: 531 | O40: 531
...

Sheet conversion_fixed_om
A1: tech | B1: zone | C1: vintage | D1: unit | E1: 100% RE | F1: central | G1: central low RE cost | H1: central low fuel price | I1: delayed electrification | J1: low demand | K1: low land | L1: net negative | M1: reference | N1: reference low RE cost | O1: reference low fuel price | R1: Notes:
A2: BECCS hydrogen production -> hydrogen blend | B2: all | C2: all | D2: 2018 usd/kilowatt | E2: 19 | F2: 19 | G2: 19 | H2: 19 | I2: 19 | J2: 19 | K2: 19 | L2: 19 | M2: 19 | N2: 19 | O2: 19 | R2: Costs are in dollars per unit capacity of produced energy or carbon
A3: biomass - > sng | B3: all | C3: all | D3: 2018 usd/kilowatt | E3: 119 | F3: 119 | G3: 119 | H3: 119 | I3: 119 | J3: 119 | K3: 119 | L3: 119 | M3: 119 | N3: 119 | O3: 119 | R3: techs can produce blend fuels as outlined on the conversion_blend_outputs tab
A4: biomass -> sng w/ccu | B4: all | C4: all | D4: 2018 usd/kilowatt | E4: 146 | F4: 146 | G4: 146 | H4: 146 | I4: 146 | J4: 146 | K4: 146 | L4: 146 | M4: 146 | N4: 146 | O4: 146
A5: biomass ft -> diesel | B5: all | C5: all | D5: 2018 usd/kilowatt | E5: 0 | F5: 0 | G5: 0 | H5: 0 | I5: 0 | J5: 0 | K5: 0 | L5: 0 | M5: 0 | N5: 0 | O5: 0
A6: biomass ft -> diesel w/ccu | B6: all | C6: all | D6: 2018 usd/kilowatt | E6: 0 | F6: 0 | G6: 0 | H6: 0 | I6: 0 | J6: 0 | K6: 0 | L6: 0 | M6: 0 | N6: 0 | O6: 0 | R6: 100% RE
A7: biomass pyrolysis | B7: all | C7: all | D7: 2018 usd/kilowatt | E7: 101 | F7: 101 | G7: 101 | H7: 101 | I7: 101 | J7: 101 | K7: 101 | L7: 101 | M7: 101 | N7: 101 | O7: 101 | R7: central
A8: biomass pyrolysis w/ccu | B8: all | C8: all | D8: 2018 usd/kilowatt | E8: 163 | F8: 163 | G8: 163 | H8: 163 | I8: 163 | J8: 163 | K8: 163 | L8: 163 | M8: 163 | N8: 163 | O8: 163 | R8: central low RE cost
A9: central-station hydrogen electrolysis | B9: all | C9: 2020.0 | D9: 2018 usd/kilowatt | E9: 30 | F9: 30 | G9: 30 | H9: 30 | I9: 30 | J9: 30 | K9: 30 | L9: 30 | M9: 30 | N9: 30 | O9: 30 | R9: central low fuel price
C10: 2025.0 | D10: 2018 usd/kilowatt | E10: 26 | F10: 26 | G10: 26 | H10: 26 | I10: 26 | J10: 26 | K10: 26 | L10: 26 | M10: 26 | N10: 26 | O10: 26 | R10: delayed electrification
C11: 2030.0 | D11: 2018 usd/kilowatt | E11: 19 | F11: 19 | G11: 19 | H11: 19 | I11: 19 | J11: 19 | K11: 19 | L11: 19 | M11: 19 | N11: 19 | O11: 19 | R11: low demand
C12: 2035.0 | D12: 2018 usd/kilowatt | E12: 15 | F12: 15 | G12: 15 | H12: 15 | I12: 15 | J12: 15 | K12: 15 | L12: 15 | M12: 15 | N12: 15 | O12: 15 | R12: low land
C13: 2040.0 | D13: 2018 usd/kilowatt | E13: 14 | F13: 14 | G13: 14 | H13: 14 | I13: 14 | J13: 14 | K13: 14 | L13: 14 | M13: 14 | N13: 14 | O13: 14 | R13: net negative
C14: 2045.0 | D14: 2018 usd/kilowatt | E14: 12 | F14: 12 | G14: 12 | H14: 12 | I14: 12 | J14: 12 | K14: 12 | L14: 12 | M14: 12 | N14: 12 | O14: 12 | R14: reference
C15: 2050.0 | D15: 2018 usd/kilowatt | E15: 11 | F15: 11 | G15: 11 | H15: 11 | I15: 11 | J15: 11 | K15: 11 | L15: 11 | M15: 11 | N15: 11 | O15: 11 | R15: reference low RE cost
A16: corn ethanol plant | B16: all | C16: all | D16: 2018 usd/kilowatt | E16: 32 | F16: 32 | G16: 32 | H16: 32 | I16: 32 | J16: 32 | K16: 32 | L16: 32 | M16: 32 | N16: 32 | O16: 32 | R16: reference low fuel price
A17: direct air capture plant for power to fuels | B17: all | C17: all | D17: 2018 usd/tonne | E17: 223810 | F17: 223810 | G17: 223810 | H17: 223810 | I17: 223810 | J17: 223810 | K17: 223810 | L17: 223810 | M17: 223810 | N17: 223810 | O17: 223810
A18: h2 natural gas reformation | B18: all | C18: all | D18: 2018 usd/kilowatt | E18: 36 | F18: 36 | G18: 36 | H18: 36 | I18: 36 | J18: 36 | K18: 36 | L18: 36 | M18: 36 | N18: 36 | O18: 36
A19: h2 natural gas reformation w/ccu | B19: all | C19: all | D19: 2018 usd/kilowatt | E19: 47 | F19: 47 | G19: 47 | H19: 47 | I19: 47 | J19: 47 | K19: 47 | L19: 47 | M19: 47 | N19: 47 | O19: 47
A20: power - to - liquids | B20: all | C20: 2020.0 | D20: 2018 usd/kilowatt | E20: 57 | F20: 57 | G20: 57 | H20: 57 | I20: 57 | J20: 57 | K20: 57 | L20: 57 | M20: 57 | N20: 57 | O20: 57
C21: 2025.0 | D21: 2018 usd/kilowatt | E21: 54 | F21: 54 | G21: 54 | H21: 54 | I21: 54 | J21: 54 | K21: 54 | L21: 54 | M21: 54 | N21: 54 | O21: 54
C22: 2030.0 | D22: 2018 usd/kilowatt | E22: 48 | F22: 48 | G22: 48 | H22: 48 | I22: 48 | J22: 48 | K22: 48 | L22: 48 | M22: 48 | N22: 48 | O22: 48
C23: 2035.0 | D23: 2018 usd/kilowatt | E23: 43 | F23: 43 | G23: 43 | H23: 43 | I23: 43 | J23: 43 | K23: 43 | L23: 43 | M23: 43 | N23: 43 | O23: 43
C24: 2040.0 | D24: 2018 usd/kilowatt | E24: 39 | F24: 39 | G24: 39 | H24: 39 | I24: 39 | J24: 39 | K24: 39 | L24: 39 | M24: 39 | N24: 39 | O24: 39
C25: 2045.0 | D25: 2018 usd/kilowatt | E25: 34 | F25: 34 | G25: 34 | H25: 34 | I25: 34 | J25: 34 | K25: 34 | L25: 34 | M25: 34 | N25: 34 | O25: 34
C26: 2050.0 | D26: 2018 usd/kilowatt | E26: 29 | F26: 29 | G26: 29 | H26: 29 | I26: 29 | J26: 29 | K26: 29 | L26: 29 | M26: 29 | N26: 29 | O26: 29
A27: power-to-gas methanation | B27: all | C27: 2020.0 | D27: 2018 usd/kilowatt | E27: 74 | F27: 74 | G27: 74 | H27: 74 | I27: 74 | J27: 74 | K27: 74 | L27: 74 | M27: 74 | N27: 74 | O27: 74
C28: 2025.0 | D28: 2018 usd/kilowatt | E28: 64 | F28: 64 | G28: 64 | H28: 64 | I28: 64 | J28: 64 | K28: 64 | L28: 64 | M28: 64 | N28: 64 | O28: 64
C29: 2030.0 | D29: 2018 usd/kilowatt | E29: 48 | F29: 48 | G29: 48 | H29: 48 | I29: 48 | J29: 48 | K29: 48 | L29: 48 | M29: 48 | N29: 48 | O29: 48
C30: 2035.0 | D30: 2018 usd/kilowatt | E30: 38 | F30: 38 | G30: 38 | H30: 38 | I30: 38 | J30: 38 | K30: 38 | L30: 38 | M30: 38 | N30: 38 | O30: 38
C31: 2040.0 | D31: 2018 usd/kilowatt | E31: 33 | F31: 33 | G31: 33 | H31: 33 | I31: 33 | J31: 33 | K31: 33 | L31: 33 | M31: 33 | N31: 33 | O31: 33
C32: 2045.0 | D32: 2018 usd/kilowatt | E32: 28 | F32: 28 | G32: 28 | H32: 28 | I32: 28 | J32: 28 | K32: 28 | L32: 28 | M32: 28 | N32: 28 | O32: 28
C33: 2050.0 | D33: 2018 usd/kilowatt | E33: 23 | F33: 23 | G33: 23 | H33: 23 | I33: 23 | J33: 23 | K33: 23 | L33: 23 | M33: 23 | N33: 23 | O33: 23
A34: power-to-lpg | B34: all | C34: 2020.0 | D34: 2018 usd/kilowatt | E34: 57 | F34: 57 | G34: 57 | H34: 57 | I34: 57 | J34: 57 | K34: 57 | L34: 57 | M34: 57 | N34: 57 | O34: 57
C35: 2025.0 | D35: 2018 usd/kilowatt | E35: 54 | F35: 54 | G35: 54 | H35: 54 | I35: 54 | J35: 54 | K35: 54 | L35: 54 | M35: 54 | N35: 54 | O35: 54
C36: 2030.0 | D36: 2018 usd/kilowatt | E36: 48 | F36: 48 | G36: 48 | H36: 48 | I36: 48 | J36: 48 | K36: 48 | L36: 48 | M36: 48 | N36: 48 | O36: 48
C37: 2035.0 | D37: 2018 usd/kilowatt | E37: 43 | F37: 43 | G37: 43 | H37: 43 | I37: 43 | J37: 43 | K37: 43 | L37: 43 | M37: 43 | N37: 43 | O37: 43
C38: 2040.0 | D38: 2018 usd/kilowatt | E38: 39 | F38: 39 | G38: 39 | H38: 39 | I38: 39 | J38: 39 | K38: 39 | L38: 39 | M38: 39 | N38: 39 | O38: 39
C39: 2045.0 | D39: 2018 usd/kilowatt | E39: 34 | F39: 34 | G39: 34 | H39: 34 | I39: 34 | J39: 34 | K39: 34 | L39: 34 | M39: 34 | N39: 34 | O39: 34
C40: 2050.0 | D40: 2018 usd/kilowatt | E40: 29 | F40: 29 | G40: 29 | H40: 29 | I40: 29 | J40: 29 | K40: 29 | L40: 29 | M40: 29 | N40: 29 | O40: 29

Sheet conversion_variable_om
A1: tech | B1: zone | C1: vintage | D1: unit | E1: 100% RE | F1: central | G1: central low RE cost | H1: central low fuel price | I1: delayed electrification | J1: low demand | K1: low land | L1: net negative | M1: reference | N1: reference low RE cost | O1: reference low fuel price | R1: Notes:
A2: BECCS hydrogen production -> hydrogen blend | B2: all | C2: all | D2: 2018 usd/gigajoule | E2: 3.3 | F2: 3.3 | G2: 3.3 | H2: 3.3 | I2: 3.3 | J2: 3.3 | K2: 3.3 | L2: 3.3 | M2: 3.3 | N2: 3.3 | O2: 3.3 | R2: Costs are in dollars per unit of energy or carbon output
A3: biomass - > sng | B3: all | C3: all | D3: 2018 usd/gigajoule | E3: 0 | F3: 0 | G3: 0 | H3: 0 | I3: 0 | J3: 0 | K3: 0 | L3: 0 | M3: 0 | N3: 0 | O3: 0 | R3: Some sources embed variable O&M with fixed O&M assuming a certain annual utilization
A4: biomass -> sng w/ccu | B4: all | C4: all | D4: 2018 usd/gigajoule | E4: 0 | F4: 0 | G4: 0 | H4: 0 | I4: 0 | J4: 0 | K4: 0 | L4: 0 | M4: 0 | N4: 0 | O4: 0
A5: biomass ft -> diesel | B5: all | C5: all | D5: 2018 usd/gigajoule | E5: 7.9 | F5: 7.9 | G5: 7.9 | H5: 7.9 | I5: 7.9 | J5: 7.9 | K5: 7.9 | L5: 7.9 | M5: 7.9 | N5: 7.9 | O5: 7.9
A6: biomass ft -> diesel w/ccu | B6: all | C6: all | D6: 2018 usd/gigajoule | E6: 8.1 | F6: 8.1 | G6: 8.1 | H6: 8.1 | I6: 8.1 | J6: 8.1 | K6: 8.1 | L6: 8.1 | M6: 8.1 | N6: 8.1 | O6: 8.1
A7: biomass pyrolysis | B7: all | C7: all | D7: 2018 usd/gigajoule | E7: 5.1 | F7: 5.1 | G7: 5.1 | H7: 5.1 | I7: 5.1 | J7: 5.1 | K7: 5.1 | L7: 5.1 | M7: 5.1 | N7: 5.1 | O7: 5.1
A8: biomass pyrolysis w/ccu | B8: all | C8: all | D8: 2018 usd/gigajoule | E8: 5.1 | F8: 5.1 | G8: 5.1 | H8: 5.1 | I8: 5.1 | J8: 5.1 | K8: 5.1 | L8: 5.1 | M8: 5.1 | N8: 5.1 | O8: 5.1
A9: central-station hydrogen electrolysis | B9: all | C9: all | D9: 2018 usd/gigajoule | E9: 0.3 | F9: 0.3 | G9: 0.3 | H9: 0.3 | I9: 0.3 | J9: 0.3 | K9: 0.3 | L9: 0.3 | M9: 0.3 | N9: 0.3 | O9: 0.3
A10: corn ethanol plant | B10: all | C10: all | D10: 2018 usd/gigajoule | E10: 1.8 | F10: 1.8 | G10: 1.8 | H10: 1.8 | I10: 1.8 | J10: 1.8 | K10: 1.8 | L10: 1.8 | M10: 1.8 | N10: 1.8 | O10: 1.8
A11: direct air capture plant for power to fuels | B11: all | C11: all | D11: 2018 usd/tonne | E11: 4.4 | F11: 4.4 | G11: 4.4 | H11: 4.4 | I11: 4.4 | J11: 4.4 | K11: 4.4 | L11: 4.4 | M11: 4.4 | N11: 4.4 | O11: 4.4
A12: electric boiler | B12: all | C12: all | D12: 2018 usd/gigajoule | E12: 0 | F12: 0 | G12: 0 | H12: 0 | I12: 0 | J12: 0 | K12: 0 | L12: 0 | M12: 0 | N12: 0 | O12: 0
A13: h2 natural gas reformation | B13: all | C13: all | D13: 2018 usd/gigajoule | E13: 0.3 | F13: 0.3 | G13: 0.3 | H13: 0.3 | I13: 0.3 | J13: 0.3 | K13: 0.3 | L13: 0.3 | M13: 0.3 | N13: 0.3 | O13: 0.3
A14: h2 natural gas reformation w/ccu | B14: all | C14: all | D14: 2018 usd/gigajoule | E14: 0.5 | F14: 0.5 | G14: 0.5 | H14: 0.5 | I14: 0.5 | J14: 0.5 | K14: 0.5 | L14: 0.5 | M14: 0.5 | N14: 0.5 | O14: 0.5
A15: industrial coal boiler | B15: all | C15: all | D15: 2018 usd/gigajoule | E15: 0 | F15: 0 | G15: 0 | H15: 0 | I15: 0 | J15: 0 | K15: 0 | L15: 0 | M15: 0 | N15: 0 | O15: 0
... A25: power-to-lpg | B25: all | C25: all | D25: 2018 usd/gigajoule | E25: 0 | F25: 0 | G25: 0 | H25: 0 | I25: 0 | J25: 0 | K25: 0 | L25: 0 | M25: 0 | N25: 0 | O25: 0

Sheet conversion_efficiency
A1: tech | B1: zone | C1: vintage | D1: unit | E1: blend_in | F1: 100% RE | G1: central | H1: central low RE cost | I1: central low fuel price | J1: delayed electrification | K1: low demand | L1: low land | M1: net negative | N1: reference | O1: reference low RE cost | P1: reference low fuel price | S1: Notes:
A2: BECCS hydrogen production -> hydrogen blend | B2: all | C2: all | D2: energy in/energy out | E2: biomass blend - solids | F2: 1.775 | G2: 1.775 | H2: 1.775 | I2: 1.775 | J2: 1.775 | K2: 1.775 | L2: 1.775 | M2: 1.775 | N2: 1.775 | O2: 1.775 | P2: 1.775 | S2: blend_out is mapped on the sheet conversion_blend_outputs with the ratio between output blends solved for by the model
E3: electricity | F3: -0.027 | G3: -0.027 | H3: -0.027 | I3: -0.027 | J3: -0.027 | K3: -0.027 | L3: -0.027 | M3: -0.027 | N3: -0.027 | O3: -0.027 | P3: -0.027 | S3: all units are per unit of blend_out
D4: kilogram/gigajoule | E4: co2 utilization blend | F4: -134.79 | G4: -134.79 | H4: -134.79 | I4: -134.79 | J4: -134.79 | K4: -134.79 | L4: -134.79 | M4: -134.79 | N4: -134.79 | O4: -134.79 | P4: -134.79 | S4: conversion efficiencies are given based on HHV
A5: biomass - > sng | B5: all | C5: all | D5: energy in/energy out | E5: biomass blend - solids | F5: 1.515 | G5: 1.515 | H5: 1.515 | I5: 1.515 | J5: 1.515 | K5: 1.515 | L5: 1.515 | M5: 1.515 | N5: 1.515 | O5: 1.515 | P5: 1.515 | S5: negative numbers represent co-products that are produced alongside the output blend
E6: electricity | F6: 0.021 | G6: 0.021 | H6: 0.021 | I6: 0.021 | J6: 0.021 | K6: 0.021 | L6: 0.021 | M6: 0.021 | N6: 0.021 | O6: 0.021 | P6: 0.021 | S6: postive numbers represent inputs that are required to produce the output blend
A7: biomass -> sng w/ccu | B7: all | C7: all | D7: energy in/energy out | E7: biomass blend - solids | F7: 1.55 | G7: 1.55 | H7: 1.55 | I7: 1.55 | J7: 1.55 | K7: 1.55 | L7: 1.55 | M7: 1.55 | N7: 1.55 | O7: 1.55 | P7: 1.55
E8: electricity | F8: 0.021 | G8: 0.021 | H8: 0.021 | I8: 0.021 | J8: 0.021 | K8: 0.021 | L8: 0.021 | M8: 0.021 | N8: 0.021 | O8: 0.021 | P8: 0.021
D9: kilogram/gigajoule | E9: co2 utilization blend | F9: -46.064 | G9: -46.064 | H9: -46.064 | I9: -46.064 | J9: -46.064 | K9: -46.064 | L9: -46.064 | M9: -46.064 | N9: -46.064 | O9: -46.064 | P9: -46.064
A10: biomass ft -> diesel | B10: all | C10: all | D10: energy in/energy out | E10: biomass blend - solids | F10: 2.15 | G10: 2.15 | H10: 2.15 | I10: 2.15 | J10: 2.15 | K10: 2.15 | L10: 2.15 | M10: 2.15 | N10: 2.15 | O10: 2.15 | P10: 2.15
E11: electricity | F11: 0.052 | G11: 0.052 | H11: 0.052 | I11: 0.052 | J11: 0.052 | K11: 0.052 | L11: 0.052 | M11: 0.052 | N11: 0.052 | O11: 0.052 | P11: 0.052
E12: pipeline gas blend | F12: -0.097 | G12: -0.097 | H12: -0.097 | I12: -0.097 | J12: -0.097 | K12: -0.097 | L12: -0.097 | M12: -0.097 | N12: -0.097 | O12: -0.097 | P12: -0.097
E13: steam blend | F13: -0.33 | G13: -0.33 | H13: -0.33 | I13: -0.33 | J13: -0.33 | K13: -0.33 | L13: -0.33 | M13: -0.33 | N13: -0.33 | O13: -0.33 | P13: -0.33
A14: biomass ft -> diesel w/ccu | B14: all | C14: all | D14: energy in/energy out | E14: biomass blend - solids | F14: 2.15 | G14: 2.15 | H14: 2.15 | I14: 2.15 | J14: 2.15 | K14: 2.15 | L14: 2.15 | M14: 2.15 | N14: 2.15 | O14: 2.15 | P14: 2.15
E15: electricity | F15: 0.114 | G15: 0.114 | H15: 0.114 | I15: 0.114 | J15: 0.114 | K15: 0.114 | L15: 0.114 | M15: 0.114 | N15: 0.114 | O15: 0.114 | P15: 0.114
E16: pipeline gas blend | F16: -0.097 | G16: -0.097 | H16: -0.097 | I16: -0.097 | J16: -0.097 | K16: -0.097 | L16: -0.097 | M16: -0.097 | N16: -0.097 | O16: -0.097 | P16: -0.097
E17: steam blend | F17: -0.33 | G17: -0.33 | H17: -0.33 | I17: -0.33 | J17: -0.33 | K17: -0.33 | L17: -0.33 | M17: -0.33 | N17: -0.33 | O17: -0.33 | P17: -0.33
D18: kilogram/gigajoule | E18: co2 utilization blend | F18: -81.512 | G18: -81.512 | H18: -81.512 | I18: -81.512 | J18: -81.512 | K18: -81.512 | L18: -81.512 | M18: -81.512 | N18: -81.512 | O18: -81.512 | P18: -81.512
A19: biomass pyrolysis | B19: all | C19: all | D19: energy in/energy out | E19: biomass blend - solids | F19: 1.541 | G19: 1.541 | H19: 1.541 | I19: 1.541 | J19: 1.541 | K19: 1.541 | L19: 1.541 | M19: 1.541 | N19: 1.541 | O19: 1.541 | P19: 1.541
E20: electricity | F20: -0.117 | G20: -0.117 | H20: -0.117 | I20: -0.117 | J20: -0.117 | K20: -0.117 | L20: -0.117 | M20: -0.117 | N20: -0.117 | O20: -0.117 | P20: -0.117
A21: biomass pyrolysis w/ccu | B21: all | C21: all | D21: energy in/energy out | E21: biomass blend - solids | F21: 1.541 | G21: 1.541 | H21: 1.541 | I21: 1.541 | J21: 1.541 | K21: 1.541 | L21: 1.541 | M21: 1.541 | N21: 1.541 | O21: 1.541 | P21: 1.541
E22: electricity | F22: -0.028 | G22: -0.028 | H22: -0.028 | I22: -0.028 | J22: -0.028 | K22: -0.028 | L22: -0.028 | M22: -0.028 | N22: -0.028 | O22: -0.028 | P22: -0.028
D23: kilogram/gigajoule | E23: co2 utilization blend | F23: -73.9 | G23: -73.9 | H23: -73.9 | I23: -73.9 | J23: -73.9 | K23: -73.9 | L23: -73.9 | M23: -73.9 | N23: -73.9 | O23: -73.9 | P23: -73.9
A24: central-station hydrogen electrolysis | B24: all | C24: all | D24: energy in/energy out | E24: electricity | F24: 1.377 | G24: 1.377 | H24: 1.377 | I24: 1.377 | J24: 1.377 | K24: 1.377 | L24: 1.377 | M24: 1.377 | N24: 1.377 | O24: 1.377 | P24: 1.377
A25: corn ethanol plant | B25: all | C25: all | D25: energy in/energy out | E25: biomass blend - corn | F25: 2 | G25: 2 | H25: 2 | I25: 2 | J25: 2 | K25: 2 | L25: 2 | M25: 2 | N25: 2 | O25: 2 | P25: 2
E26: coal blend | F26: 0.025 | G26: 0.025 | H26: 0.025 | I26: 0.025 | J26: 0.025 | K26: 0.025 | L26: 0.025 | M26: 0.025 | N26: 0.025 | O26: 0.025 | P26: 0.025
E27: diesel blend | F27: 0 | G27: 0 | H27: 0 | I27: 0 | J27: 0 | K27: 0 | L27: 0 | M27: 0 | N27: 0 | O27: 0 | P27: 0
E28: electricity | F28: 0.034 | G28: 0.034 | H28: 0.034 | I28: 0.034 | J28: 0.034 | K28: 0.034 | L28: 0.034 | M28: 0.034 | N28: 0.034 | O28: 0.034 | P28: 0.034
E29: pipeline gas blend | F29: 0.298 | G29: 0.298 | H29: 0.298 | I29: 0.298 | J29: 0.298 | K29: 0.298 | L29: 0.298 | M29: 0.298 | N29: 0.298 | O29: 0.298 | P29: 0.298
A30: direct air capture plant for power to fuels | B30: all | C30: all | D30: gigajoule/kilogram | E30: electricity | F30: 0.006 | G30: 0.006 | H30: 0.006 | I30: 0.006 | J30: 0.006 | K30: 0.006 | L30: 0.006 | M30: 0.006 | N30: 0.006 | O30: 0.006 | P30: 0.006
A31: electric boiler | B31: all | C31: all | D31: energy in/energy out | E31: electricity | F31: 1.035 | G31: 1.035 | H31: 1.035 | I31: 1.035 | J31: 1.035 | K31: 1.035 | L31: 1.035 | M31: 1.035 | N31: 1.035 | O31: 1.035 | P31: 1.035
A32: h2 natural gas reformation | B32: all | C32: all | D32: energy in/energy out | E32: electricity | F32: 0 | G32: 0 | H32: 0 | I32: 0 | J32: 0 | K32: 0 | L32: 0 | M32: 0 | N32: 0 | O32: 0 | P32: 0
E33: pipeline gas blend | F33: 1.313 | G33: 1.313 | H33: 1.313 | I33: 1.313 | J33: 1.313 | K33: 1.313 | L33: 1.313 | M33: 1.313 | N33: 1.313 | O33: 1.313 | P33: 1.313
A34: h2 natural gas reformation w/ccu | B34: all | C34: all | D34: energy in/energy out | E34: electricity | F34: 0.024 | G34: 0.024 | H34: 0.024 | I34: 0.024 | J34: 0.024 | K34: 0.024 | L34: 0.024 | M34: 0.024 | N34: 0.024 | O34: 0.024 | P34: 0.024
E35: pipeline gas blend | F35: 1.446 | G35: 1.446 | H35: 1.446 | I35: 1.446 | J35: 1.446 | K35: 1.446 | L35: 1.446 | M35: 1.446 | N35: 1.446 | O35: 1.446 | P35: 1.446
D36: kilogram/gigajoule | E36: co2 utilization blend | F36: -65.428 | G36: -65.428 | H36: -65.428 | I36: -65.428 | J36: -65.428 | K36: -65.428 | L36: -65.428 | M36: -65.428 | N36: -65.428 | O36: -65.428 | P36: -65.428
A37: industrial coal boiler | B37: all | C37: all | D37: energy in/energy out | E37: coal blend | F37: 1.4 | G37: 1.4 | H37: 1.4 | I37: 1.4 | J37: 1.4 | K37: 1.4 | L37: 1.4 | M37: 1.4 | N37: 1.4 | O37: 1.4 | P37: 1.4
A38: industrial distillate fuel oil boiler | B38: all | C38: all | D38: energy in/energy out | E38: diesel blend | F38: 1.053 | G38: 1.053 | H38: 1.053 | I38: 1.053 | J38: 1.053 | K38: 1.053 | L38: 1.053 | M38: 1.053 | N38: 1.053 | O38: 1.053 | P38: 1.053
A39: industrial hydrogen boiler | B39: all | C39: all | D39: energy in/energy out | E39: electricity | F39: 0.001 | G39: 0.001 | H39: 0.001 | I39: 0.001 | J39: 0.001 | K39: 0.001 | L39: 0.001 | M39: 0.001 | N39: 0.001 | O39: 0.001 | P39: 0.001
E40: hydrogen blend | F40: 1.077 | G40: 1.077 | H40: 1.077 | I40: 1.077 | J40: 1.077 | K40: 1.077 | L40: 1.077 | M40: 1.077 | N40: 1.077 | O40: 1.077 | P40: 1.077
...
