Workbook

Sheet ELC_GridExt
A1: NatGrExt | G1: 1 | N1: =G1+1 -> 2 | U1: =N1+1 -> 3 | AB1: =U1+1 -> 4 | AI1: =AB1+1 -> 5 | AP1: =AI1+1 -> 6 | AW1: =AP1+1 -> 7 | BD1: =AW1+1 -> 8 | BK1: =BD1+1 -> 9 | BR1: =BK1+1 -> 10
A3: Countries in NREL data | E3: ~FI_Process | L3: ~FI_Process | S3: ~FI_Process | Z3: ~FI_Process | AG3: ~FI_Process | AN3: ~FI_Process | AU3: ~FI_Process | BB3: ~FI_Process | BI3: ~FI_Process | BP3: ~FI_Process
A4: RegionCode | B4: RegionName | E4: Sets | F4: TechName | G4: TechDesc | H4: TACT | I4: TCAP | J4: PrimaryCG | L4: Sets | M4: TechName | N4: TechDesc | O4: TACT | P4: TCAP | Q4: PrimaryCG | S4: Sets | T4: TechName | U4: TechDesc | V4: TACT | W4: TCAP | X4: PrimaryCG | Z4: Sets | AA4: TechName | AB4: TechDesc | AC4: TACT | AD4: TCAP | AE4: PrimaryCG | AG4: Sets | AH4: TechName | AI4: TechDesc | AJ4: TACT | AK4: TCAP | AL4: PrimaryCG | AN4: Sets | AO4: TechName | AP4: TechDesc | AQ4: TACT | AR4: TCAP | AS4: PrimaryCG | AU4: Sets | AV4: TechName | AW4: TechDesc | AX4: TACT | AY4: TCAP | AZ4: PrimaryCG | BB4: Sets | BC4: TechName | BD4: TechDesc | BE4: TACT | BF4: TCAP | BG4: PrimaryCG | BI4: Sets | BJ4: TechName | BK4: TechDesc | BL4: TACT | BM4: TCAP | BN4: PrimaryCG | BP4: Sets | BQ4: TechName | BR4: TechDesc | BS4: TACT | BT4: TCAP | BU4: PrimaryCG
A5: AFG | B5: Afghanistan | E5: PRE | F5: ="NatGrdExt_"&$A5&"_"&G$1 -> NatGrdExt_AFG_1 | G5: ="Grid Extension -"&$B5&"- Step "&G$1 -> Grid Extension -Afghanistan- Step 1 | H5: PJ | I5: GW | J5: DumGrid | L5: PRE | M5: ="NatGrdExt_"&$A5&"_"&N$1 -> NatGrdExt_AFG_2 | N5: ="Grid Extension -"&$B5&"- Step "&N$1 -> Grid Extension -Afghanistan- Step 2 | O5: PJ | P5: GW | Q5: DumGrid | S5: PRE | T5: ="NatGrdExt_"&$A5&"_"&U$1 -> NatGrdExt_AFG_3 | U5: ="Grid Extension -"&$B5&"- Step "&U$1 -> Grid Extension -Afghanistan- Step 3 | V5: PJ | W5: GW | X5: DumGrid | Z5: PRE | AA5: ="NatGrdExt_"&$A5&"_"&AB$1 -> NatGrdExt_AFG_4 | AB5: ="Grid Extension -"&$B5&"- Step "&AB$1 -> Grid Extension -Afghanistan- Step 4 | AC5: PJ | AD5: GW | AE5: DumGrid | AG5: PRE | AH5: ="NatGrdExt_"&$A5&"_"&AI$1 -> NatGrdExt_AFG_5 | AI5: ="Grid Extension -"&$B5&"- Step "&AI$1 -> Grid Extension -Afghanistan- Step 5 | AJ5: PJ | AK5: GW | AL5: DumGrid | AN5: PRE | AO5: ="NatGrdExt_"&$A5&"_"&AP$1 -> NatGrdExt_AFG_6 | AP5: ="Grid Extension -"&$B5&"- Step "&AP$1 -> Grid Extension -Afghanistan- Step 6 | AQ5: PJ | AR5: GW | AS5: DumGrid | AU5: PRE | AV5: ="NatGrdExt_"&$A5&"_"&AW$1 -> NatGrdExt_AFG_7 | AW5: ="Grid Extension -"&$B5&"- Step "&AW$1 -> Grid Extension -Afghanistan- Step 7 | AX5: PJ | AY5: GW | AZ5: DumGrid | BB5: PRE | BC5: ="NatGrdExt_"&$A5&"_"&BD$1 -> NatGrdExt_AFG_8 | BD5: ="Grid Extension -"&$B5&"- Step "&BD$1 -> Grid Extension -Afghanistan- Step 8 | BE5: PJ | BF5: GW | BG5: DumGrid | BI5: PRE | BJ5: ="NatGrdExt_"&$A5&"_"&BK$1 -> NatGrdExt_AFG_9 | BK5: ="Grid Extension -"&$B5&"- Step "&BK$1 -> Grid Extension -Afghanistan- Step 9 | BL5: PJ | BM5: GW | BN5: DumGrid | BP5: PRE | BQ5: ="NatGrdExt_"&$A5&"_"&BR$1 -> NatGrdExt_AFG_10 | BR5: ="Grid Extension -"&$B5&"- Step "&BR$1 -> Grid Extension -Afghanistan- Step 10 | BS5: PJ | BT5: GW | BU5: DumGrid
A6: AGO | B6: Angola | E6: PRE | F6: ="NatGrdExt_"&$A6&"_"&G$1 -> NatGrdExt_AGO_1 | G6: ="Grid Extension -"&$B6&"- Step "&G$1 -> Grid Extension -Angola- Step 1 | H6: PJ | I6: GW | J6: DumGrid | L6: PRE | M6: ="NatGrdExt_"&$A6&"_"&N$1 -> NatGrdExt_AGO_2 | N6: ="Grid Extension -"&$B6&"- Step "&N$1 -> Grid Extension -Angola- Step 2 | O6: PJ | P6: GW | Q6: DumGrid | S6: PRE | T6: ="NatGrdExt_"&$A6&"_"&U$1 -> NatGrdExt_AGO_3 | U6: ="Grid Extension -"&$B6&"- Step "&U$1 -> Grid Extension -Angola- Step 3 | V6: PJ | W6: GW | X6: DumGrid | Z6: PRE | AA6: ="NatGrdExt_"&$A6&"_"&AB$1 -> NatGrdExt_AGO_4 | AB6: ="Grid Extension -"&$B6&"- Step "&AB$1 -> Grid Extension -Angola- Step 4 | AC6: PJ | AD6: GW | AE6: DumGrid | AG6: PRE | AH6: ="NatGrdExt_"&$A6&"_"&AI$1 -> NatGrdExt_AGO_5 | AI6: ="Grid Extension -"&$B6&"- Step "&AI$1 -> Grid Extension -Angola- Step 5 | AJ6: PJ | AK6: GW | AL6: DumGrid | AN6: PRE | AO6: ="NatGrdExt_"&$A6&"_"&AP$1 -> NatGrdExt_AGO_6 | AP6: ="Grid Extension -"&$B6&"- Step "&AP$1 -> Grid Extension -Angola- Step 6 | AQ6: PJ | AR6: GW | AS6: DumGrid | AU6: PRE | AV6: ="NatGrdExt_"&$A6&"_"&AW$1 -> NatGrdExt_AGO_7 | AW6: ="Grid Extension -"&$B6&"- Step "&AW$1 -> Grid Extension -Angola- Step 7 | AX6: PJ | AY6: GW | AZ6: DumGrid | BB6: PRE | BC6: ="NatGrdExt_"&$A6&"_"&BD$1 -> NatGrdExt_AGO_8 | BD6: ="Grid Extension -"&$B6&"- Step "&BD$1 -> Grid Extension -Angola- Step 8 | BE6: PJ | BF6: GW | BG6: DumGrid | BI6: PRE | BJ6: ="NatGrdExt_"&$A6&"_"&BK$1 -> NatGrdExt_AGO_9 | BK6: ="Grid Extension -"&$B6&"- Step "&BK$1 -> Grid Extension -Angola- Step 9 | BL6: PJ | BM6: GW | BN6: DumGrid | BP6: PRE | BQ6: ="NatGrdExt_"&$A6&"_"&BR$1 -> NatGrdExt_AGO_10 | BR6: ="Grid Extension -"&$B6&"- Step "&BR$1 -> Grid Extension -Angola- Step 10 | BS6: PJ | BT6: GW | BU6: DumGrid
A7: ALB | B7: Albania | E7: PRE | F7: ="NatGrdExt_"&$A7&"_"&G$1 -> NatGrdExt_ALB_1 | G7: ="Grid Extension -"&$B7&"- Step "&G$1 -> Grid Extension -Albania- Step 1 | H7: PJ | I7: GW | J7: DumGrid | L7: PRE | M7: ="NatGrdExt_"&$A7&"_"&N$1 -> NatGrdExt_ALB_2 | N7: ="Grid Extension -"&$B7&"- Step "&N$1 -> Grid Extension -Albania- Step 2 | O7: PJ | P7: GW | Q7: DumGrid | S7: PRE | T7: ="NatGrdExt_"&$A7&"_"&U$1 -> NatGrdExt_ALB_3 | U7: ="Grid Extension -"&$B7&"- Step "&U$1 -> Grid Extension -Albania- Step 3 | V7: PJ | W7: GW | X7: DumGrid | Z7: PRE | AA7: ="NatGrdExt_"&$A7&"_"&AB$1 -> NatGrdExt_ALB_4 | AB7: ="Grid Extension -"&$B7&"- Step "&AB$1 -> Grid Extension -Albania- Step 4 | AC7: PJ | AD7: GW | AE7: DumGrid | AG7: PRE | AH7: ="NatGrdExt_"&$A7&"_"&AI$1 -> NatGrdExt_ALB_5 | AI7: ="Grid Extension -"&$B7&"- Step "&AI$1 -> Grid Extension -Albania- Step 5 | AJ7: PJ | AK7: GW | AL7: DumGrid | AN7: PRE | AO7: ="NatGrdExt_"&$A7&"_"&AP$1 -> NatGrdExt_ALB_6 | AP7: ="Grid Extension -"&$B7&"- Step "&AP$1 -> Grid Extension -Albania- Step 6 | AQ7: PJ | AR7: GW | AS7: DumGrid | AU7: PRE | AV7: ="NatGrdExt_"&$A7&"_"&AW$1 -> NatGrdExt_ALB_7 | AW7: ="Grid Extension -"&$B7&"- Step "&AW$1 -> Grid Extension -Albania- Step 7 | AX7: PJ | AY7: GW | AZ7: DumGrid | BB7: PRE | BC7: ="NatGrdExt_"&$A7&"_"&BD$1 -> NatGrdExt_ALB_8 | BD7: ="Grid Extension -"&$B7&"- Step "&BD$1 -> Grid Extension -Albania- Step 8 | BE7: PJ | BF7: GW | BG7: DumGrid | BI7: PRE | BJ7: ="NatGrdExt_"&$A7&"_"&BK$1 -> NatGrdExt_ALB_9 | BK7: ="Grid Extension -"&$B7&"- Step "&BK$1 -> Grid Extension -Albania- Step 9 | BL7: PJ | BM7: GW | BN7: DumGrid | BP7: PRE | BQ7: ="NatGrdExt_"&$A7&"_"&BR$1 -> NatGrdExt_ALB_10 | BR7: ="Grid Extension -"&$B7&"- Step "&BR$1 -> Grid Extension -Albania- Step 10 | BS7: PJ | BT7: GW | BU7: DumGrid
A8: ARE | B8: United Arab Emirates | E8: PRE | F8: ="NatGrdExt_"&$A8&"_"&G$1 -> NatGrdExt_ARE_1 | G8: ="Grid Extension -"&$B8&"- Step "&G$1 -> Grid Extension -United Arab Emirates- Step 1 | H8: PJ | I8: GW | J8: DumGrid | L8: PRE | M8: ="NatGrdExt_"&$A8&"_"&N$1 -> NatGrdExt_ARE_2 | N8: ="Grid Extension -"&$B8&"- Step "&N$1 -> Grid Extension -United Arab Emirates- Step 2 | O8: PJ | P8: GW | Q8: DumGrid | S8: PRE | T8: ="NatGrdExt_"&$A8&"_"&U$1 -> NatGrdExt_ARE_3 | U8: ="Grid Extension -"&$B8&"- Step "&U$1 -> Grid Extension -United Arab Emirates- Step 3 | V8: PJ | W8: GW | X8: DumGrid | Z8: PRE | AA8: ="NatGrdExt_"&$A8&"_"&AB$1 -> NatGrdExt_ARE_4 | AB8: ="Grid Extension -"&$B8&"- Step "&AB$1 -> Grid Extension -United Arab Emirates- Step 4 | AC8: PJ | AD8: GW | AE8: DumGrid | AG8: PRE | AH8: ="NatGrdExt_"&$A8&"_"&AI$1 -> NatGrdExt_ARE_5 | AI8: ="Grid Extension -"&$B8&"- Step "&AI$1 -> Grid Extension -United Arab Emirates- Step 5 | AJ8: PJ | AK8: GW | AL8: DumGrid | AN8: PRE | AO8: ="NatGrdExt_"&$A8&"_"&AP$1 -> NatGrdExt_ARE_6 | AP8: ="Grid Extension -"&$B8&"- Step "&AP$1 -> Grid Extension -United Arab Emirates- Step 6 | AQ8: PJ | AR8: GW | AS8: DumGrid | AU8: PRE | AV8: ="NatGrdExt_"&$A8&"_"&AW$1 -> NatGrdExt_ARE_7 | AW8: ="Grid Extension -"&$B8&"- Step "&AW$1 -> Grid Extension -United Arab Emirates- Step 7 | AX8: PJ | AY8: GW | AZ8: DumGrid | BB8: PRE | BC8: ="NatGrdExt_"&$A8&"_"&BD$1 -> NatGrdExt_ARE_8 | BD8: ="Grid Extension -"&$B8&"- Step "&BD$1 -> Grid Extension -United Arab Emirates- Step 8 | BE8: PJ | BF8: GW | BG8: DumGrid | BI8: PRE | BJ8: ="NatGrdExt_"&$A8&"_"&BK$1 -> NatGrdExt_ARE_9 | BK8: ="Grid Extension -"&$B8&"- Step "&BK$1 -> Grid Extension -United Arab Emirates- Step 9 | BL8: PJ | BM8: GW | BN8: DumGrid | BP8: PRE | BQ8: ="NatGrdExt_"&$A8&"_"&BR$1 -> NatGrdExt_ARE_10 | BR8: ="Grid Extension -"&$B8&"- Step "&BR$1 -> Grid Extension -United Arab Emirates- Step 10 | BS8: PJ | BT8: GW | BU8: DumGrid
A9: ARG | B9: Argentina | E9: PRE | F9: ="NatGrdExt_"&$A9&"_"&G$1 -> NatGrdExt_ARG_1 | G9: ="Grid Extension -"&$B9&"- Step "&G$1 -> Grid Extension -Argentina- Step 1 | H9: PJ | I9: GW | J9: DumGrid | L9: PRE | M9: ="NatGrdExt_"&$A9&"_"&N$1 -> NatGrdExt_ARG_2 | N9: ="Grid Extension -"&$B9&"- Step "&N$1 -> Grid Extension -Argentina- Step 2 | O9: PJ | P9: GW | Q9: DumGrid | S9: PRE | T9: ="NatGrdExt_"&$A9&"_"&U$1 -> NatGrdExt_ARG_3 | U9: ="Grid Extension -"&$B9&"- Step "&U$1 -> Grid Extension -Argentina- Step 3 | V9: PJ | W9: GW | X9: DumGrid | Z9: PRE | AA9: ="NatGrdExt_"&$A9&"_"&AB$1 -> NatGrdExt_ARG_4 | AB9: ="Grid Extension -"&$B9&"- Step "&AB$1 -> Grid Extension -Argentina- Step 4 | AC9: PJ | AD9: GW | AE9: DumGrid | AG9: PRE | AH9: ="NatGrdExt_"&$A9&"_"&AI$1 -> NatGrdExt_ARG_5 | AI9: ="Grid Extension -"&$B9&"- Step "&AI$1 -> Grid Extension -Argentina- Step 5 | AJ9: PJ | AK9: GW | AL9: DumGrid | AN9: PRE | AO9: ="NatGrdExt_"&$A9&"_"&AP$1 -> NatGrdExt_ARG_6 | AP9: ="Grid Extension -"&$B9&"- Step "&AP$1 -> Grid Extension -Argentina- Step 6 | AQ9: PJ | AR9: GW | AS9: DumGrid | AU9: PRE | AV9: ="NatGrdExt_"&$A9&"_"&AW$1 -> NatGrdExt_ARG_7 | AW9: ="Grid Extension -"&$B9&"- Step "&AW$1 -> Grid Extension -Argentina- Step 7 | AX9: PJ | AY9: GW | AZ9: DumGrid | BB9: PRE | BC9: ="NatGrdExt_"&$A9&"_"&BD$1 -> NatGrdExt_ARG_8 | BD9: ="Grid Extension -"&$B9&"- Step "&BD$1 -> Grid Extension -Argentina- Step 8 | BE9: PJ | BF9: GW | BG9: DumGrid | BI9: PRE | BJ9: ="NatGrdExt_"&$A9&"_"&BK$1 -> NatGrdExt_ARG_9 | BK9: ="Grid Extension -"&$B9&"- Step "&BK$1 -> Grid Extension -Argentina- Step 9 | BL9: PJ | BM9: GW | BN9: DumGrid | BP9: PRE | BQ9: ="NatGrdExt_"&$A9&"_"&BR$1 -> NatGrdExt_ARG_10 | BR9: ="Grid Extension -"&$B9&"- Step "&BR$1 -> Grid Extension -Argentina- Step 10 | BS9: PJ | BT9: GW | BU9: DumGrid
A10: ARM | B10: Armenia | E10: PRE | F10: ="NatGrdExt_"&$A10&"_"&G$1 -> NatGrdExt_ARM_1 | G10: ="Grid Extension -"&$B10&"- Step "&G$1 -> Grid Extension -Armenia- Step 1 | H10: PJ | I10: GW | J10: DumGrid | L10: PRE | M10: ="NatGrdExt_"&$A10&"_"&N$1 -> NatGrdExt_ARM_2 | N10: ="Grid Extension -"&$B10&"- Step "&N$1 -> Grid Extension -Armenia- Step 2 | O10: PJ | P10: GW | Q10: DumGrid | S10: PRE | T10: ="NatGrdExt_"&$A10&"_"&U$1 -> NatGrdExt_ARM_3 | U10: ="Grid Extension -"&$B10&"- Step "&U$1 -> Grid Extension -Armenia- Step 3 | V10: PJ | W10: GW | X10: DumGrid | Z10: PRE | AA10: ="NatGrdExt_"&$A10&"_"&AB$1 -> NatGrdExt_ARM_4 | AB10: ="Grid Extension -"&$B10&"- Step "&AB$1 -> Grid Extension -Armenia- Step 4 | AC10: PJ | AD10: GW | AE10: DumGrid | AG10: PRE | AH10: ="NatGrdExt_"&$A10&"_"&AI$1 -> NatGrdExt_ARM_5 | AI10: ="Grid Extension -"&$B10&"- Step "&AI$1 -> Grid Extension -Armenia- Step 5 | AJ10: PJ | AK10: GW | AL10: DumGrid | AN10: PRE | AO10: ="NatGrdExt_"&$A10&"_"&AP$1 -> NatGrdExt_ARM_6 | AP10: ="Grid Extension -"&$B10&"- Step "&AP$1 -> Grid Extension -Armenia- Step 6 | AQ10: PJ | AR10: GW | AS10: DumGrid | AU10: PRE | AV10: ="NatGrdExt_"&$A10&"_"&AW$1 -> NatGrdExt_ARM_7 | AW10: ="Grid Extension -"&$B10&"- Step "&AW$1 -> Grid Extension -Armenia- Step 7 | AX10: PJ | AY10: GW | AZ10: DumGrid | BB10: PRE | BC10: ="NatGrdExt_"&$A10&"_"&BD$1 -> NatGrdExt_ARM_8 | BD10: ="Grid Extension -"&$B10&"- Step "&BD$1 -> Grid Extension -Armenia- Step 8 | BE10: PJ | BF10: GW | BG10: DumGrid | BI10: PRE | BJ10: ="NatGrdExt_"&$A10&"_"&BK$1 -> NatGrdExt_ARM_9 | BK10: ="Grid Extension -"&$B10&"- Step "&BK$1 -> Grid Extension -Armenia- Step 9 | BL10: PJ | BM10: GW | BN10: DumGrid | BP10: PRE | BQ10: ="NatGrdExt_"&$A10&"_"&BR$1 -> NatGrdExt_ARM_10 | BR10: ="Grid Extension -"&$B10&"- Step "&BR$1 -> Grid Extension -Armenia- Step 10 | BS10: PJ | BT10: GW | BU10: DumGrid
A11: ATG | B11: Antigua and Barbuda | E11: PRE | F11: ="NatGrdExt_"&$A11&"_"&G$1 -> NatGrdExt_ATG_1 | G11: ="Grid Extension -"&$B11&"- Step "&G$1 -> Grid Extension -Antigua and Barbuda- Step 1 | H11: PJ | I11: GW | J11: DumGrid | L11: PRE | M11: ="NatGrdExt_"&$A11&"_"&N$1 -> NatGrdExt_ATG_2 | N11: ="Grid Extension -"&$B11&"- Step "&N$1 -> Grid Extension -Antigua and Barbuda- Step 2 | O11: PJ | P11: GW | Q11: DumGrid | S11: PRE | T11: ="NatGrdExt_"&$A11&"_"&U$1 -> NatGrdExt_ATG_3 | U11: ="Grid Extension -"&$B11&"- Step "&U$1 -> Grid Extension -Antigua and Barbuda- Step 3 | V11: PJ | W11: GW | X11: DumGrid | Z11: PRE | AA11: ="NatGrdExt_"&$A11&"_"&AB$1 -> NatGrdExt_ATG_4 | AB11: ="Grid Extension -"&$B11&"- Step "&AB$1 -> Grid Extension -Antigua and Barbuda- Step 4 | AC11: PJ | AD11: GW | AE11: DumGrid | AG11: PRE | AH11: ="NatGrdExt_"&$A11&"_"&AI$1 -> NatGrdExt_ATG_5 | AI11: ="Grid Extension -"&$B11&"- Step "&AI$1 -> Grid Extension -Antigua and Barbuda- Step 5 | AJ11: PJ | AK11: GW | AL11: DumGrid | AN11: PRE | AO11: ="NatGrdExt_"&$A11&"_"&AP$1 -> NatGrdExt_ATG_6 | AP11: ="Grid Extension -"&$B11&"- Step "&AP$1 -> Grid Extension -Antigua and Barbuda- Step 6 | AQ11: PJ | AR11: GW | AS11: DumGrid | AU11: PRE | AV11: ="NatGrdExt_"&$A11&"_"&AW$1 -> NatGrdExt_ATG_7 | AW11: ="Grid Extension -"&$B11&"- Step "&AW$1 -> Grid Extension -Antigua and Barbuda- Step 7 | AX11: PJ | AY11: GW | AZ11: DumGrid | BB11: PRE | BC11: ="NatGrdExt_"&$A11&"_"&BD$1 -> NatGrdExt_ATG_8 | BD11: ="Grid Extension -"&$B11&"- Step "&BD$1 -> Grid Extension -Antigua and Barbuda- Step 8 | BE11: PJ | BF11: GW | BG11: DumGrid | BI11: PRE | BJ11: ="NatGrdExt_"&$A11&"_"&BK$1 -> NatGrdExt_ATG_9 | BK11: ="Grid Extension -"&$B11&"- Step "&BK$1 -> Grid Extension -Antigua and Barbuda- Step 9 | BL11: PJ | BM11: GW | BN11: DumGrid | BP11: PRE | BQ11: ="NatGrdExt_"&$A11&"_"&BR$1 -> NatGrdExt_ATG_10 | BR11: ="Grid Extension -"&$B11&"- Step "&BR$1 -> Grid Extension -Antigua and Barbuda- Step 10 | BS11: PJ | BT11: GW | BU11: DumGrid
A12: AUS | B12: Australia | E12: PRE | F12: ="NatGrdExt_"&$A12&"_"&G$1 -> NatGrdExt_AUS_1 | G12: ="Grid Extension -"&$B12&"- Step "&G$1 -> Grid Extension -Australia- Step 1 | H12: PJ | I12: GW | J12: DumGrid | L12: PRE | M12: ="NatGrdExt_"&$A12&"_"&N$1 -> NatGrdExt_AUS_2 | N12: ="Grid Extension -"&$B12&"- Step "&N$1 -> Grid Extension -Australia- Step 2 | O12: PJ | P12: GW | Q12: DumGrid | S12: PRE | T12: ="NatGrdExt_"&$A12&"_"&U$1 -> NatGrdExt_AUS_3 | U12: ="Grid Extension -"&$B12&"- Step "&U$1 -> Grid Extension -Australia- Step 3 | V12: PJ | W12: GW | X12: DumGrid | Z12: PRE | AA12: ="NatGrdExt_"&$A12&"_"&AB$1 -> NatGrdExt_AUS_4 | AB12: ="Grid Extension -"&$B12&"- Step "&AB$1 -> Grid Extension -Australia- Step 4 | AC12: PJ | AD12: GW | AE12: DumGrid | AG12: PRE | AH12: ="NatGrdExt_"&$A12&"_"&AI$1 -> NatGrdExt_AUS_5 | AI12: ="Grid Extension -"&$B12&"- Step "&AI$1 -> Grid Extension -Australia- Step 5 | AJ12: PJ | AK12: GW | AL12: DumGrid | AN12: PRE | AO12: ="NatGrdExt_"&$A12&"_"&AP$1 -> NatGrdExt_AUS_6 | AP12: ="Grid Extension -"&$B12&"- Step "&AP$1 -> Grid Extension -Australia- Step 6 | AQ12: PJ | AR12: GW | AS12: DumGrid | AU12: PRE | AV12: ="NatGrdExt_"&$A12&"_"&AW$1 -> NatGrdExt_AUS_7 | AW12: ="Grid Extension -"&$B12&"- Step "&AW$1 -> Grid Extension -Australia- Step 7 | AX12: PJ | AY12: GW | AZ12: DumGrid | BB12: PRE | BC12: ="NatGrdExt_"&$A12&"_"&BD$1 -> NatGrdExt_AUS_8 | BD12: ="Grid Extension -"&$B12&"- Step "&BD$1 -> Grid Extension -Australia- Step 8 | BE12: PJ | BF12: GW | BG12: DumGrid | BI12: PRE | BJ12: ="NatGrdExt_"&$A12&"_"&BK$1 -> NatGrdExt_AUS_9 | BK12: ="Grid Extension -"&$B12&"- Step "&BK$1 -> Grid Extension -Australia- Step 9 | BL12: PJ | BM12: GW | BN12: DumGrid | BP12: PRE | BQ12: ="NatGrdExt_"&$A12&"_"&BR$1 -> NatGrdExt_AUS_10 | BR12: ="Grid Extension -"&$B12&"- Step "&BR$1 -> Grid Extension -Australia- Step 10 | BS12: PJ | BT12: GW | BU12: DumGrid
A13: AUT | B13: Austria | E13: PRE | F13: ="NatGrdExt_"&$A13&"_"&G$1 -> NatGrdExt_AUT_1 | G13: ="Grid Extension -"&$B13&"- Step "&G$1 -> Grid Extension -Austria- Step 1 | H13: PJ | I13: GW | J13: DumGrid | L13: PRE | M13: ="NatGrdExt_"&$A13&"_"&N$1 -> NatGrdExt_AUT_2 | N13: ="Grid Extension -"&$B13&"- Step "&N$1 -> Grid Extension -Austria- Step 2 | O13: PJ | P13: GW | Q13: DumGrid | S13: PRE | T13: ="NatGrdExt_"&$A13&"_"&U$1 -> NatGrdExt_AUT_3 | U13: ="Grid Extension -"&$B13&"- Step "&U$1 -> Grid Extension -Austria- Step 3 | V13: PJ | W13: GW | X13: DumGrid | Z13: PRE | AA13: ="NatGrdExt_"&$A13&"_"&AB$1 -> NatGrdExt_AUT_4 | AB13: ="Grid Extension -"&$B13&"- Step "&AB$1 -> Grid Extension -Austria- Step 4 | AC13: PJ | AD13: GW | AE13: DumGrid | AG13: PRE | AH13: ="NatGrdExt_"&$A13&"_"&AI$1 -> NatGrdExt_AUT_5 | AI13: ="Grid Extension -"&$B13&"- Step "&AI$1 -> Grid Extension -Austria- Step 5 | AJ13: PJ | AK13: GW | AL13: DumGrid | AN13: PRE | AO13: ="NatGrdExt_"&$A13&"_"&AP$1 -> NatGrdExt_AUT_6 | AP13: ="Grid Extension -"&$B13&"- Step "&AP$1 -> Grid Extension -Austria- Step 6 | AQ13: PJ | AR13: GW | AS13: DumGrid | AU13: PRE | AV13: ="NatGrdExt_"&$A13&"_"&AW$1 -> NatGrdExt_AUT_7 | AW13: ="Grid Extension -"&$B13&"- Step "&AW$1 -> Grid Extension -Austria- Step 7 | AX13: PJ | AY13: GW | AZ13: DumGrid | BB13: PRE | BC13: ="NatGrdExt_"&$A13&"_"&BD$1 -> NatGrdExt_AUT_8 | BD13: ="Grid Extension -"&$B13&"- Step "&BD$1 -> Grid Extension -Austria- Step 8 | BE13: PJ | BF13: GW | BG13: DumGrid | BI13: PRE | BJ13: ="NatGrdExt_"&$A13&"_"&BK$1 -> NatGrdExt_AUT_9 | BK13: ="Grid Extension -"&$B13&"- Step "&BK$1 -> Grid Extension -Austria- Step 9 | BL13: PJ | BM13: GW | BN13: DumGrid | BP13: PRE | BQ13: ="NatGrdExt_"&$A13&"_"&BR$1 -> NatGrdExt_AUT_10 | BR13: ="Grid Extension -"&$B13&"- Step "&BR$1 -> Grid Extension -Austria- Step 10 | BS13: PJ | BT13: GW | BU13: DumGrid
A14: AZE | B14: Azerbaijan | E14: PRE | F14: ="NatGrdExt_"&$A14&"_"&G$1 -> NatGrdExt_AZE_1 | G14: ="Grid Extension -"&$B14&"- Step "&G$1 -> Grid Extension -Azerbaijan- Step 1 | H14: PJ | I14: GW | J14: DumGrid | L14: PRE | M14: ="NatGrdExt_"&$A14&"_"&N$1 -> NatGrdExt_AZE_2 | N14: ="Grid Extension -"&$B14&"- Step "&N$1 -> Grid Extension -Azerbaijan- Step 2 | O14: PJ | P14: GW | Q14: DumGrid | S14: PRE | T14: ="NatGrdExt_"&$A14&"_"&U$1 -> NatGrdExt_AZE_3 | U14: ="Grid Extension -"&$B14&"- Step "&U$1 -> Grid Extension -Azerbaijan- Step 3 | V14: PJ | W14: GW | X14: DumGrid | Z14: PRE | AA14: ="NatGrdExt_"&$A14&"_"&AB$1 -> NatGrdExt_AZE_4 | AB14: ="Grid Extension -"&$B14&"- Step "&AB$1 -> Grid Extension -Azerbaijan- Step 4 | AC14: PJ | AD14: GW | AE14: DumGrid | AG14: PRE | AH14: ="NatGrdExt_"&$A14&"_"&AI$1 -> NatGrdExt_AZE_5 | AI14: ="Grid Extension -"&$B14&"- Step "&AI$1 -> Grid Extension -Azerbaijan- Step 5 | AJ14: PJ | AK14: GW | AL14: DumGrid | AN14: PRE | AO14: ="NatGrdExt_"&$A14&"_"&AP$1 -> NatGrdExt_AZE_6 | AP14: ="Grid Extension -"&$B14&"- Step "&AP$1 -> Grid Extension -Azerbaijan- Step 6 | AQ14: PJ | AR14: GW | AS14: DumGrid | AU14: PRE | AV14: ="NatGrdExt_"&$A14&"_"&AW$1 -> NatGrdExt_AZE_7 | AW14: ="Grid Extension -"&$B14&"- Step "&AW$1 -> Grid Extension -Azerbaijan- Step 7 | AX14: PJ | AY14: GW | AZ14: DumGrid | BB14: PRE | BC14: ="NatGrdExt_"&$A14&"_"&BD$1 -> NatGrdExt_AZE_8 | BD14: ="Grid Extension -"&$B14&"- Step "&BD$1 -> Grid Extension -Azerbaijan- Step 8 | BE14: PJ | BF14: GW | BG14: DumGrid | BI14: PRE | BJ14: ="NatGrdExt_"&$A14&"_"&BK$1 -> NatGrdExt_AZE_9 | BK14: ="Grid Extension -"&$B14&"- Step "&BK$1 -> Grid Extension -Azerbaijan- Step 9 | BL14: PJ | BM14: GW | BN14: DumGrid | BP14: PRE | BQ14: ="NatGrdExt_"&$A14&"_"&BR$1 -> NatGrdExt_AZE_10 | BR14: ="Grid Extension -"&$B14&"- Step "&BR$1 -> Grid Extension -Azerbaijan- Step 10 | BS14: PJ | BT14: GW | BU14: DumGrid
A15: BDI | B15: Burundi | E15: PRE | F15: ="NatGrdExt_"&$A15&"_"&G$1 -> NatGrdExt_BDI_1 | G15: ="Grid Extension -"&$B15&"- Step "&G$1 -> Grid Extension -Burundi- Step 1 | H15: PJ | I15: GW | J15: DumGrid | L15: PRE | M15: ="NatGrdExt_"&$A15&"_"&N$1 -> NatGrdExt_BDI_2 | N15: ="Grid Extension -"&$B15&"- Step "&N$1 -> Grid Extension -Burundi- Step 2 | O15: PJ | P15: GW | Q15: DumGrid | S15: PRE | T15: ="NatGrdExt_"&$A15&"_"&U$1 -> NatGrdExt_BDI_3 | U15: ="Grid Extension -"&$B15&"- Step "&U$1 -> Grid Extension -Burundi- Step 3 | V15: PJ | W15: GW | X15: DumGrid | Z15: PRE | AA15: ="NatGrdExt_"&$A15&"_"&AB$1 -> NatGrdExt_BDI_4 | AB15: ="Grid Extension -"&$B15&"- Step "&AB$1 -> Grid Extension -Burundi- Step 4 | AC15: PJ | AD15: GW | AE15: DumGrid | AG15: PRE | AH15: ="NatGrdExt_"&$A15&"_"&AI$1 -> NatGrdExt_BDI_5 | AI15: ="Grid Extension -"&$B15&"- Step "&AI$1 -> Grid Extension -Burundi- Step 5 | AJ15: PJ | AK15: GW | AL15: DumGrid | AN15: PRE | AO15: ="NatGrdExt_"&$A15&"_"&AP$1 -> NatGrdExt_BDI_6 | AP15: ="Grid Extension -"&$B15&"- Step "&AP$1 -> Grid Extension -Burundi- Step 6 | AQ15: PJ | AR15: GW | AS15: DumGrid | AU15: PRE | AV15: ="NatGrdExt_"&$A15&"_"&AW$1 -> NatGrdExt_BDI_7 | AW15: ="Grid Extension -"&$B15&"- Step "&AW$1 -> Grid Extension -Burundi- Step 7 | AX15: PJ | AY15: GW | AZ15: DumGrid | BB15: PRE | BC15: ="NatGrdExt_"&$A15&"_"&BD$1 -> NatGrdExt_BDI_8 | BD15: ="Grid Extension -"&$B15&"- Step "&BD$1 -> Grid Extension -Burundi- Step 8 | BE15: PJ | BF15: GW | BG15: DumGrid | BI15: PRE | BJ15: ="NatGrdExt_"&$A15&"_"&BK$1 -> NatGrdExt_BDI_9 | BK15: ="Grid Extension -"&$B15&"- Step "&BK$1 -> Grid Extension -Burundi- Step 9 | BL15: PJ | BM15: GW | BN15: DumGrid | BP15: PRE | BQ15: ="NatGrdExt_"&$A15&"_"&BR$1 -> NatGrdExt_BDI_10 | BR15: ="Grid Extension -"&$B15&"- Step "&BR$1 -> Grid Extension -Burundi- Step 10 | BS15: PJ | BT15: GW | BU15: DumGrid
A16: BEL | B16: Belgium | E16: PRE | F16: ="NatGrdExt_"&$A16&"_"&G$1 -> NatGrdExt_BEL_1 | G16: ="Grid Extension -"&$B16&"- Step "&G$1 -> Grid Extension -Belgium- Step 1 | H16: PJ | I16: GW | J16: DumGrid | L16: PRE | M16: ="NatGrdExt_"&$A16&"_"&N$1 -> NatGrdExt_BEL_2 | N16: ="Grid Extension -"&$B16&"- Step "&N$1 -> Grid Extension -Belgium- Step 2 | O16: PJ | P16: GW | Q16: DumGrid | S16: PRE | T16: ="NatGrdExt_"&$A16&"_"&U$1 -> NatGrdExt_BEL_3 | U16: ="Grid Extension -"&$B16&"- Step "&U$1 -> Grid Extension -Belgium- Step 3 | V16: PJ | W16: GW | X16: DumGrid | Z16: PRE | AA16: ="NatGrdExt_"&$A16&"_"&AB$1 -> NatGrdExt_BEL_4 | AB16: ="Grid Extension -"&$B16&"- Step "&AB$1 -> Grid Extension -Belgium- Step 4 | AC16: PJ | AD16: GW | AE16: DumGrid | AG16: PRE | AH16: ="NatGrdExt_"&$A16&"_"&AI$1 -> NatGrdExt_BEL_5 | AI16: ="Grid Extension -"&$B16&"- Step "&AI$1 -> Grid Extension -Belgium- Step 5 | AJ16: PJ | AK16: GW | AL16: DumGrid | AN16: PRE | AO16: ="NatGrdExt_"&$A16&"_"&AP$1 -> NatGrdExt_BEL_6 | AP16: ="Grid Extension -"&$B16&"- Step "&AP$1 -> Grid Extension -Belgium- Step 6 | AQ16: PJ | AR16: GW | AS16: DumGrid | AU16: PRE | AV16: ="NatGrdExt_"&$A16&"_"&AW$1 -> NatGrdExt_BEL_7 | AW16: ="Grid Extension -"&$B16&"- Step "&AW$1 -> Grid Extension -Belgium- Step 7 | AX16: PJ | AY16: GW | AZ16: DumGrid | BB16: PRE | BC16: ="NatGrdExt_"&$A16&"_"&BD$1 -> NatGrdExt_BEL_8 | BD16: ="Grid Extension -"&$B16&"- Step "&BD$1 -> Grid Extension -Belgium- Step 8 | BE16: PJ | BF16: GW | BG16: DumGrid | BI16: PRE | BJ16: ="NatGrdExt_"&$A16&"_"&BK$1 -> NatGrdExt_BEL_9 | BK16: ="Grid Extension -"&$B16&"- Step "&BK$1 -> Grid Extension -Belgium- Step 9 | BL16: PJ | BM16: GW | BN16: DumGrid | BP16: PRE | BQ16: ="NatGrdExt_"&$A16&"_"&BR$1 -> NatGrdExt_BEL_10 | BR16: ="Grid Extension -"&$B16&"- Step "&BR$1 -> Grid Extension -Belgium- Step 10 | BS16: PJ | BT16: GW | BU16: DumGrid
... A172: ZWE | B172: Zimbabwe | E172: PRE | F172: ="NatGrdExt_"&$A172&"_"&G$1 -> NatGrdExt_ZWE_1 | G172: ="Grid Extension -"&$B172&"- Step "&G$1 -> Grid Extension -Zimbabwe- Step 1 | H172: PJ | I172: GW | J172: DumGrid | L172: PRE | M172: ="NatGrdExt_"&$A172&"_"&N$1 -> NatGrdExt_ZWE_2 | N172: ="Grid Extension -"&$B172&"- Step "&N$1 -> Grid Extension -Zimbabwe- Step 2 | O172: PJ | P172: GW | Q172: DumGrid | S172: PRE | T172: ="NatGrdExt_"&$A172&"_"&U$1 -> NatGrdExt_ZWE_3 | U172: ="Grid Extension -"&$B172&"- Step "&U$1 -> Grid Extension -Zimbabwe- Step 3 | V172: PJ | W172: GW | X172: DumGrid | Z172: PRE | AA172: ="NatGrdExt_"&$A172&"_"&AB$1 -> NatGrdExt_ZWE_4 | AB172: ="Grid Extension -"&$B172&"- Step "&AB$1 -> Grid Extension -Zimbabwe- Step 4 | AC172: PJ | AD172: GW | AE172: DumGrid | AG172: PRE | AH172: ="NatGrdExt_"&$A172&"_"&AI$1 -> NatGrdExt_ZWE_5 | AI172: ="Grid Extension -"&$B172&"- Step "&AI$1 -> Grid Extension -Zimbabwe- Step 5 | AJ172: PJ | AK172: GW | AL172: DumGrid | AN172: PRE | AO172: ="NatGrdExt_"&$A172&"_"&AP$1 -> NatGrdExt_ZWE_6 | AP172: ="Grid Extension -"&$B172&"- Step "&AP$1 -> Grid Extension -Zimbabwe- Step 6 | AQ172: PJ | AR172: GW | AS172: DumGrid | AU172: PRE | AV172: ="NatGrdExt_"&$A172&"_"&AW$1 -> NatGrdExt_ZWE_7 | AW172: ="Grid Extension -"&$B172&"- Step "&AW$1 -> Grid Extension -Zimbabwe- Step 7 | AX172: PJ | AY172: GW | AZ172: DumGrid | BB172: PRE | BC172: ="NatGrdExt_"&$A172&"_"&BD$1 -> NatGrdExt_ZWE_8 | BD172: ="Grid Extension -"&$B172&"- Step "&BD$1 -> Grid Extension -Zimbabwe- Step 8 | BE172: PJ | BF172: GW | BG172: DumGrid | BI172: PRE | BJ172: ="NatGrdExt_"&$A172&"_"&BK$1 -> NatGrdExt_ZWE_9 | BK172: ="Grid Extension -"&$B172&"- Step "&BK$1 -> Grid Extension -Zimbabwe- Step 9 | BL172: PJ | BM172: GW | BN172: DumGrid | BP172: PRE | BQ172: ="NatGrdExt_"&$A172&"_"&BR$1 -> NatGrdExt_ZWE_10 | BR172: ="Grid Extension -"&$B172&"- Step "&BR$1 -> Grid Extension -Zimbabwe- Step 10 | BS172: PJ | BT172: GW | BU172: DumGrid

Sheet Hydro Methodology
A1: HYDROPOWER SUPPLY CURVES FOR TIMES MODELING
A3: DATA SOURCES
A4: Primary - Gross Potential | B4: Hoes et al. (2017) PLOS ONE - DOI: 10.1371/journal.pone.0171844
A5: Economic Ratios | B5: Gernaat et al. (2017) Nature Energy - DOI: 10.1038/s41560-017-0006-y
A6: Capital Costs | B6: AR6 Scenario Database - Regional median costs for hydro (2020 USD/kW)
A7: Current Capacity | B7: IHA World Hydropower Outlook 2024, IRENA Statistics
A9: METHODOLOGY
A10: Gross Potential | B10: From Hoes et al. 11.8 million site assessment using 7.5 arcsec DEM
A11: Economic Potential | B11: ~18% of gross (Gernaat ratio for sites <$0.50/kWh)
A12: GW Conversion | B12: Assumes 4000 full load hours (46% capacity factor)
A13: Additional_Low | B13: Economic potential minus current installed capacity
A14: Additional_High | B14: 25% of gross potential minus current installed capacity
A16: COST METHODOLOGY (AR6-BASED)
A17: Base Cost Source | B17: AR6 scenario database median capital costs by R10 region
A18: T1 (Best Sites) | B18: 25%/20% of potential | 0.90x base cost | Best available sites
A19: T2 (Good Sites) | B19: 40%/35% of potential | 1.00x base cost | Median cost sites
A20: T3 (Average Sites) | B20: 25%/30% of potential | 1.15x base cost | Above-average cost
A21: T4 (Marginal Sites) | B21: 10%/15% of potential | 1.35x base cost | Highest cost sites
A23: AR6 REGIONAL BASE COSTS (2020 USD/kW)
A24: AFR (Africa) | B24: $2,689/kW
A25: CSA (Latin America) | B25: $3,074/kW
A26: CPA (China+) | B26: $2,273/kW
A27: SAS (India+) | B27: $2,585/kW
A28: PAS (Rest of Asia) | B28: $2,864/kW
A29: FSU (Former Soviet Union) | B29: $2,860/kW
A30: MEA (Middle East) | B30: $2,790/kW
A31: EUR (Europe) | B31: $2,752/kW
A32: NAM (North America) | B32: $2,852/kW
A33: PAO (Pacific OECD) | B33: $2,808/kW
A35: INCREMENTAL COST INTERPRETATION
A36: T1 Cost = 0 | B36: First tranche baseline; absolute cost embedded in base technology
A37: T2-T4 Costs | B37: ADDITIONAL cost above T1 to access that tranche of potential
A38: TIMES Usage | B38: Model as stepped supply curve using NCAP_BND(UP) for each tranche
A40: TECHNOLOGY NAMING
A41: Convention | B41: EN_Hydro_<ISO3>_<Tranche>
A42: Example | B42: EN_Hydro_BRA_T1, EN_Hydro_BRA_T2, EN_Hydro_BRA_T3, EN_Hydro_BRA_T4
A44: NOTES
A45: Excludes | B45: Pumped storage hydro (PSH) - separate technology
A46: Constraints | B46: Environmental/social factors may further limit development
A47: Climate | B47: Potential may shift with changing precipitation patterns
...

Sheet Hydro
B3: ~fi_t | H3: ~fi_process
B4: process | C4: comm-in | D4: comm-out | E4: cap_bnd | F4: invcost~USD21_alt | H4: set | I4: process | J4: description | K4: capacity_unit | L4: activity_unit | M4: timeslicelevel | N4: vintage
B5: =SupplyCurves_High!A2 -> EN_Hydro_BRA_T1 | C5: ELCHYD | D5: ELC | E5: =SupplyCurves_High!F2 -> 13.2 | F5: =SupplyCurves_High!H2 -> 0 | H5: ELE | I5: =B5 -> EN_Hydro_BRA_T1 | J5: =SupplyCurves_High!C2&" -- "&SupplyCurves_High!E2&" -- "&SupplyCurves_High!K2 -> Brazil -- T1 -- $0.04-0.06/kWh | K5: GW | L5: PJ | M5: daynite | N5: no
B6: =SupplyCurves_High!A3 -> EN_Hydro_BRA_T2 | C6: ELCHYD | D6: ELC | E6: =SupplyCurves_High!F3 -> 23.1 | F6: =SupplyCurves_High!H3 -> 307 | H6: ELE | I6: =B6 -> EN_Hydro_BRA_T2 | J6: =SupplyCurves_High!C3&" -- "&SupplyCurves_High!E3&" -- "&SupplyCurves_High!K3 -> Brazil -- T2 -- $0.06-0.08/kWh | K6: GW | L6: PJ | M6: daynite | N6: no
B7: =SupplyCurves_High!A4 -> EN_Hydro_BRA_T3 | C7: ELCHYD | D7: ELC | E7: =SupplyCurves_High!F4 -> 19.8 | F7: =SupplyCurves_High!H4 -> 768 | H7: ELE | I7: =B7 -> EN_Hydro_BRA_T3 | J7: =SupplyCurves_High!C4&" -- "&SupplyCurves_High!E4&" -- "&SupplyCurves_High!K4 -> Brazil -- T3 -- $0.08-0.10/kWh | K7: GW | L7: PJ | M7: daynite | N7: no
B8: =SupplyCurves_High!A5 -> EN_Hydro_BRA_T4 | C8: ELCHYD | D8: ELC | E8: =SupplyCurves_High!F5 -> 9.9 | F8: =SupplyCurves_High!H5 -> 1383 | H8: ELE | I8: =B8 -> EN_Hydro_BRA_T4 | J8: =SupplyCurves_High!C5&" -- "&SupplyCurves_High!E5&" -- "&SupplyCurves_High!K5 -> Brazil -- T4 -- $0.10-0.14/kWh | K8: GW | L8: PJ | M8: daynite | N8: no
B9: =SupplyCurves_High!A6 -> EN_Hydro_RUS_T1 | C9: ELCHYD | D9: ELC | E9: =SupplyCurves_High!F6 -> 17.1 | F9: =SupplyCurves_High!H6 -> 0 | H9: ELE | I9: =B9 -> EN_Hydro_RUS_T1 | J9: =SupplyCurves_High!C6&" -- "&SupplyCurves_High!E6&" -- "&SupplyCurves_High!K6 -> Russia -- T1 -- $0.04-0.06/kWh | K9: GW | L9: PJ | M9: daynite | N9: no
B10: =SupplyCurves_High!A7 -> EN_Hydro_RUS_T2 | C10: ELCHYD | D10: ELC | E10: =SupplyCurves_High!F7 -> 29.925 | F10: =SupplyCurves_High!H7 -> 286 | H10: ELE | I10: =B10 -> EN_Hydro_RUS_T2 | J10: =SupplyCurves_High!C7&" -- "&SupplyCurves_High!E7&" -- "&SupplyCurves_High!K7 -> Russia -- T2 -- $0.06-0.08/kWh | K10: GW | L10: PJ | M10: daynite | N10: no
B11: =SupplyCurves_High!A8 -> EN_Hydro_RUS_T3 | C11: ELCHYD | D11: ELC | E11: =SupplyCurves_High!F8 -> 25.65 | F11: =SupplyCurves_High!H8 -> 715 | H11: ELE | I11: =B11 -> EN_Hydro_RUS_T3 | J11: =SupplyCurves_High!C8&" -- "&SupplyCurves_High!E8&" -- "&SupplyCurves_High!K8 -> Russia -- T3 -- $0.08-0.10/kWh | K11: GW | L11: PJ | M11: daynite | N11: no
B12: =SupplyCurves_High!A9 -> EN_Hydro_RUS_T4 | C12: ELCHYD | D12: ELC | E12: =SupplyCurves_High!F9 -> 12.825 | F12: =SupplyCurves_High!H9 -> 1287 | H12: ELE | I12: =B12 -> EN_Hydro_RUS_T4 | J12: =SupplyCurves_High!C9&" -- "&SupplyCurves_High!E9&" -- "&SupplyCurves_High!K9 -> Russia -- T4 -- $0.10-0.14/kWh | K12: GW | L12: PJ | M12: daynite | N12: no
B13: =SupplyCurves_High!A10 -> EN_Hydro_CAN_T1 | C13: ELCHYD | D13: ELC | E13: =SupplyCurves_High!F10 -> 6.1 | F13: =SupplyCurves_High!H10 -> 0 | H13: ELE | I13: =B13 -> EN_Hydro_CAN_T1 | J13: =SupplyCurves_High!C10&" -- "&SupplyCurves_High!E10&" -- "&SupplyCurves_High!K10 -> Canada -- T1 -- $0.04-0.06/kWh | K13: GW | L13: PJ | M13: daynite | N13: no
B14: =SupplyCurves_High!A11 -> EN_Hydro_CAN_T2 | C14: ELCHYD | D14: ELC | E14: =SupplyCurves_High!F11 -> 10.675 | F14: =SupplyCurves_High!H11 -> 285 | H14: ELE | I14: =B14 -> EN_Hydro_CAN_T2 | J14: =SupplyCurves_High!C11&" -- "&SupplyCurves_High!E11&" -- "&SupplyCurves_High!K11 -> Canada -- T2 -- $0.06-0.08/kWh | K14: GW | L14: PJ | M14: daynite | N14: no
B15: =SupplyCurves_High!A12 -> EN_Hydro_CAN_T3 | C15: ELCHYD | D15: ELC | E15: =SupplyCurves_High!F12 -> 9.15 | F15: =SupplyCurves_High!H12 -> 713 | H15: ELE | I15: =B15 -> EN_Hydro_CAN_T3 | J15: =SupplyCurves_High!C12&" -- "&SupplyCurves_High!E12&" -- "&SupplyCurves_High!K12 -> Canada -- T3 -- $0.08-0.10/kWh | K15: GW | L15: PJ | M15: daynite | N15: no
B16: =SupplyCurves_High!A13 -> EN_Hydro_CAN_T4 | C16: ELCHYD | D16: ELC | E16: =SupplyCurves_High!F13 -> 4.575 | F16: =SupplyCurves_High!H13 -> 1284 | H16: ELE | I16: =B16 -> EN_Hydro_CAN_T4 | J16: =SupplyCurves_High!C13&" -- "&SupplyCurves_High!E13&" -- "&SupplyCurves_High!K13 -> Canada -- T4 -- $0.10-0.14/kWh | K16: GW | L16: PJ | M16: daynite | N16: no
... B208: =SupplyCurves_High!A205 -> EN_Hydro_MLI_T4 | C208: ELCHYD | D208: ELC | E208: =SupplyCurves_High!F205 -> 0.09 | F208: =SupplyCurves_High!H205 -> 1210 | H208: ELE | I208: =B208 -> EN_Hydro_MLI_T4 | J208: =SupplyCurves_High!C205&" -- "&SupplyCurves_High!E205&" -- "&SupplyCurves_High!K205 -> Mali -- T4 -- $0.10-0.14/kWh | K208: GW | L208: PJ | M208: daynite | N208: no

Sheet SupplyCurves_Low
A1: TechName | B1: ISO3 | C1: Country | D1: Region | E1: Tranche | F1: Potential_GW | G1: Potential_MW | H1: INVCOST_Incremental_USD_kW | I1: INVCOST_Absolute_USD_kW | J1: AR6_Base_Cost_USD_kW | K1: LCOE_Range
A2: EN_Hydro_BRA_T1 | B2: BRA | C2: Brazil | D2: CSA | E2: T1 | F2: 4.25 | G2: 4250 | H2: 0 | I2: 2767 | J2: 3074 | K2: $0.04-0.06/kWh
A3: EN_Hydro_BRA_T2 | B3: BRA | C3: Brazil | D3: CSA | E3: T2 | F3: 6.8 | G3: 6800 | H3: 307 | I3: 3074 | J3: 3074 | K3: $0.06-0.08/kWh
A4: EN_Hydro_BRA_T3 | B4: BRA | C4: Brazil | D4: CSA | E4: T3 | F4: 4.25 | G4: 4250 | H4: 768 | I4: 3535 | J4: 3074 | K4: $0.08-0.10/kWh
A5: EN_Hydro_BRA_T4 | B5: BRA | C5: Brazil | D5: CSA | E5: T4 | F5: 1.7 | G5: 1700 | H5: 1383 | I5: 4150 | J5: 3074 | K5: $0.10-0.14/kWh
A6: EN_Hydro_RUS_T1 | B6: RUS | C6: Russia | D6: FSU | E6: T1 | F6: 11.75 | G6: 11750 | H6: 0 | I6: 2574 | J6: 2860 | K6: $0.04-0.06/kWh
A7: EN_Hydro_RUS_T2 | B7: RUS | C7: Russia | D7: FSU | E7: T2 | F7: 18.8 | G7: 18800 | H7: 286 | I7: 2860 | J7: 2860 | K7: $0.06-0.08/kWh
A8: EN_Hydro_RUS_T3 | B8: RUS | C8: Russia | D8: FSU | E8: T3 | F8: 11.75 | G8: 11750 | H8: 715 | I8: 3289 | J8: 2860 | K8: $0.08-0.10/kWh
A9: EN_Hydro_RUS_T4 | B9: RUS | C9: Russia | D9: FSU | E9: T4 | F9: 4.7 | G9: 4700 | H9: 1287 | I9: 3861 | J9: 2860 | K9: $0.10-0.14/kWh
A10: EN_Hydro_IND_T1 | B10: IND | C10: India | D10: SAS | E10: T1 | F10: 0.5 | G10: 500 | H10: 0 | I10: 2327 | J10: 2585 | K10: $0.04-0.06/kWh
A11: EN_Hydro_IND_T2 | B11: IND | C11: India | D11: SAS | E11: T2 | F11: 0.8 | G11: 800 | H11: 259 | I11: 2585 | J11: 2585 | K11: $0.06-0.08/kWh
A12: EN_Hydro_IND_T3 | B12: IND | C12: India | D12: SAS | E12: T3 | F12: 0.5 | G12: 500 | H12: 646 | I12: 2973 | J12: 2585 | K12: $0.08-0.10/kWh
A13: EN_Hydro_IND_T4 | B13: IND | C13: India | D13: SAS | E13: T4 | F13: 0.2 | G13: 200 | H13: 1163 | I13: 3490 | J13: 2585 | K13: $0.10-0.14/kWh
... A205: EN_Hydro_BLR_T4 | B205: BLR | C205: Belarus | D205: FSU | E205: T4 | F205: 0.01 | G205: 10 | H205: 1287 | I205: 3861 | J205: 2860 | K205: $0.10-0.14/kWh

Sheet SupplyCurves_High
A1: TechName | B1: ISO3 | C1: Country | D1: Region | E1: Tranche | F1: Potential_GW | G1: Potential_MW | H1: INVCOST_Incremental_USD_kW | I1: INVCOST_Absolute_USD_kW | J1: AR6_Base_Cost_USD_kW | K1: LCOE_Range
A2: EN_Hydro_BRA_T1 | B2: BRA | C2: Brazil | D2: CSA | E2: T1 | F2: 13.2 | G2: 13200 | H2: 0 | I2: 2767 | J2: 3074 | K2: $0.04-0.06/kWh
A3: EN_Hydro_BRA_T2 | B3: BRA | C3: Brazil | D3: CSA | E3: T2 | F3: 23.1 | G3: 23100 | H3: 307 | I3: 3074 | J3: 3074 | K3: $0.06-0.08/kWh
A4: EN_Hydro_BRA_T3 | B4: BRA | C4: Brazil | D4: CSA | E4: T3 | F4: 19.8 | G4: 19800 | H4: 768 | I4: 3535 | J4: 3074 | K4: $0.08-0.10/kWh
A5: EN_Hydro_BRA_T4 | B5: BRA | C5: Brazil | D5: CSA | E5: T4 | F5: 9.9 | G5: 9900 | H5: 1383 | I5: 4150 | J5: 3074 | K5: $0.10-0.14/kWh
A6: EN_Hydro_RUS_T1 | B6: RUS | C6: Russia | D6: FSU | E6: T1 | F6: 17.1 | G6: 17100 | H6: 0 | I6: 2574 | J6: 2860 | K6: $0.04-0.06/kWh
A7: EN_Hydro_RUS_T2 | B7: RUS | C7: Russia | D7: FSU | E7: T2 | F7: 29.925 | G7: 29925 | H7: 286 | I7: 2860 | J7: 2860 | K7: $0.06-0.08/kWh
A8: EN_Hydro_RUS_T3 | B8: RUS | C8: Russia | D8: FSU | E8: T3 | F8: 25.65 | G8: 25650 | H8: 715 | I8: 3289 | J8: 2860 | K8: $0.08-0.10/kWh
A9: EN_Hydro_RUS_T4 | B9: RUS | C9: Russia | D9: FSU | E9: T4 | F9: 12.825 | G9: 12825 | H9: 1287 | I9: 3861 | J9: 2860 | K9: $0.10-0.14/kWh
A10: EN_Hydro_CAN_T1 | B10: CAN | C10: Canada | D10: NAM | E10: T1 | F10: 6.1 | G10: 6100 | H10: 0 | I10: 2567 | J10: 2852 | K10: $0.04-0.06/kWh
A11: EN_Hydro_CAN_T2 | B11: CAN | C11: Canada | D11: NAM | E11: T2 | F11: 10.675 | G11: 10675 | H11: 285 | I11: 2852 | J11: 2852 | K11: $0.06-0.08/kWh
A12: EN_Hydro_CAN_T3 | B12: CAN | C12: Canada | D12: NAM | E12: T3 | F12: 9.15 | G12: 9150 | H12: 713 | I12: 3280 | J12: 2852 | K12: $0.08-0.10/kWh
A13: EN_Hydro_CAN_T4 | B13: CAN | C13: Canada | D13: NAM | E13: T4 | F13: 4.575 | G13: 4575 | H13: 1284 | I13: 3851 | J13: 2852 | K13: $0.10-0.14/kWh
... A245: EN_Hydro_JOR_T4 | B245: JOR | C245: Jordan | D245: MEA | E245: T4 | F245: 0.015 | G245: 15 | H245: 1256 | I245: 3767 | J245: 2790 | K245: $0.10-0.14/kWh

Sheet spv
A1: ~fi_process | I1: ~fi_t | P1: ~fi_process | X1: ~fi_t
A2: set | B2: process | C2: description | D2: capacity_unit | E2: activity_unit | F2: timeslicelevel | G2: vintage | I2: process | J2: comm-out | K2: cap_bnd | L2: af~fx | M2: avg_grid_dist_km | N2: invcost~USD21_alt | P2: set | Q2: process | R2: description | S2: capacity_unit | T2: activity_unit | U2: timeslicelevel | V2: vintage | X2: process | Y2: comm-out | Z2: EFF
A3: ele | B3: en_spv_AFG_001 | C3: solar resource in Kunduz region (near Kunduz) -- Afghanistan | D3: GW | E3: PJ | F3: annual | G3: no | I3: en_spv_AFG_001 | J3: elc_spv_AFG_001 | K3: 40.431224 | L3: 0.2420941 | M3: 65.286859 | N3: 71.815545 | P3: ele | Q3: elcagg_spv_AFG | R3: solar aggregator to grid -- Afghanistan | S3: GW | T3: PJ | U3: daynite | V3: no | X3: elcagg_spv_AFG | Y3: ELC | Z3: 1
A4: ele | B4: en_spv_AFG_002 | C4: solar resource in Faryab region (near Aqchah) -- Afghanistan | D4: GW | E4: PJ | F4: annual | G4: no | I4: en_spv_AFG_002 | J4: elc_spv_AFG_002 | K4: 35.885729 | L4: 0.24322688 | M4: 131.68484 | N4: 144.85332 | P4: ele | Q4: elcagg_spv_AGO | R4: solar aggregator to grid -- Angola | S4: GW | T4: PJ | U4: daynite | V4: no | X4: elcagg_spv_AGO | Y4: ELC | Z4: 1
A5: ele | B5: en_spv_AFG_003 | C5: solar resource in Herat region (near Herat) -- Afghanistan | D5: GW | E5: PJ | F5: annual | G5: no | I5: en_spv_AFG_003 | J5: elc_spv_AFG_003 | K5: 1.7986177 | L5: 0.28136729 | M5: 196.78469 | N5: 216.46316 | P5: ele | Q5: elcagg_spv_ALB | R5: solar aggregator to grid -- Albania | S5: GW | T5: PJ | U5: daynite | V5: no | X5: elcagg_spv_ALB | Y5: ELC | Z5: 1
A6: ele | B6: en_spv_AFG_004 | C6: solar resource in Herat region (near Herat) -- Afghanistan | D6: GW | E6: PJ | F6: annual | G6: no | I6: en_spv_AFG_004 | J6: elc_spv_AFG_004 | K6: 26.77047 | L6: 0.25611273 | M6: 133.8085 | N6: 147.18935 | P6: ele | Q6: elcagg_spv_ARE | R6: solar aggregator to grid -- United Arab Emirates | S6: GW | T6: PJ | U6: daynite | V6: no | X6: elcagg_spv_ARE | Y6: ELC | Z6: 1
A7: ele | B7: en_spv_AFG_005 | C7: solar resource in Zabul region (near Kandahar) -- Afghanistan | D7: GW | E7: PJ | F7: annual | G7: no | I7: en_spv_AFG_005 | J7: elc_spv_AFG_005 | K7: 38.021338 | L7: 0.28060802 | M7: 176.44963 | N7: 194.09459 | P7: ele | Q7: elcagg_spv_ARG | R7: solar aggregator to grid -- Argentina | S7: GW | T7: PJ | U7: daynite | V7: no | X7: elcagg_spv_ARG | Y7: ELC | Z7: 1
A8: ele | B8: en_spv_AFG_006 | C8: solar resource in Paktika region (near Kabul) -- Afghanistan | D8: GW | E8: PJ | F8: annual | G8: no | I8: en_spv_AFG_006 | J8: elc_spv_AFG_006 | K8: 17.571408 | L8: 0.26265162 | M8: 164.63721 | N8: 181.10093 | P8: ele | Q8: elcagg_spv_ARM | R8: solar aggregator to grid -- Armenia | S8: GW | T8: PJ | U8: daynite | V8: no | X8: elcagg_spv_ARM | Y8: ELC | Z8: 1
A9: ele | B9: en_spv_AFG_007 | C9: solar resource in Federally Administered Tribal Areas region (near Jalalabad) -- Afghanistan | D9: GW | E9: PJ | F9: annual | G9: no | I9: en_spv_AFG_007 | J9: elc_spv_AFG_007 | K9: 0.64743546 | L9: 0.23145075 | M9: 104.7746 | N9: 115.25206 | P9: ele | Q9: elcagg_spv_AUS | R9: solar aggregator to grid -- Australia | S9: GW | T9: PJ | U9: daynite | V9: no | X9: elcagg_spv_AUS | Y9: ELC | Z9: 1
A10: ele | B10: en_spv_AFG_008 | C10: solar resource in Kandahar region (near Kandahar) -- Afghanistan | D10: GW | E10: PJ | F10: annual | G10: no | I10: en_spv_AFG_008 | J10: elc_spv_AFG_008 | K10: 94.710937 | L10: 0.27584857 | M10: 116.94373 | N10: 128.6381 | P10: ele | Q10: elcagg_spv_AUT | R10: solar aggregator to grid -- Austria | S10: GW | T10: PJ | U10: daynite | V10: no | X10: elcagg_spv_AUT | Y10: ELC | Z10: 1
A11: ele | B11: en_spv_AFG_009 | C11: solar resource in Nimruz region (near Farah) -- Afghanistan | D11: GW | E11: PJ | F11: annual | G11: no | I11: en_spv_AFG_009 | J11: elc_spv_AFG_009 | K11: 105.32836 | L11: 0.27260796 | M11: 156.77396 | N11: 172.45136 | P11: ele | Q11: elcagg_spv_AZE | R11: solar aggregator to grid -- Azerbaijan | S11: GW | T11: PJ | U11: daynite | V11: no | X11: elcagg_spv_AZE | Y11: ELC | Z11: 1
A12: ele | B12: en_spv_AGO_001 | C12: solar resource in Huila region (near Chibia) -- Angola | D12: GW | E12: PJ | F12: annual | G12: no | I12: en_spv_AGO_001 | J12: elc_spv_AGO_001 | K12: 178.27301 | L12: 0.25693566 | M12: 141.17778 | N12: 155.29556 | P12: ele | Q12: elcagg_spv_BDI | R12: solar aggregator to grid -- Burundi | S12: GW | T12: PJ | U12: daynite | V12: no | X12: elcagg_spv_BDI | Y12: ELC | Z12: 1
A13: ele | B13: en_spv_AGO_002 | C13: solar resource in Huila region (near Caluquembe) -- Angola | D13: GW | E13: PJ | F13: annual | G13: no | I13: en_spv_AGO_002 | J13: elc_spv_AGO_002 | K13: 129.2579 | L13: 0.23693534 | M13: 56.364731 | N13: 62.001205 | P13: ele | Q13: elcagg_spv_BEL | R13: solar aggregator to grid -- Belgium | S13: GW | T13: PJ | U13: daynite | V13: no | X13: elcagg_spv_BEL | Y13: ELC | Z13: 1
A14: ele | B14: en_spv_AGO_003 | C14: solar resource in Bie region (near Menongue) -- Angola | D14: GW | E14: PJ | F14: annual | G14: no | I14: en_spv_AGO_003 | J14: elc_spv_AGO_003 | K14: 270.2204 | L14: 0.2343414 | M14: 107.54023 | N14: 118.29425 | P14: ele | Q14: elcagg_spv_BEN | R14: solar aggregator to grid -- Benin | S14: GW | T14: PJ | U14: daynite | V14: no | X14: elcagg_spv_BEN | Y14: ELC | Z14: 1
... A158: ele | B158: en_spv_CAF_003 | C158: solar resource in Kemo Prefecture region (near Bangui) -- Central African Republic | D158: GW | E158: PJ | F158: annual | G158: no | I158: en_spv_CAF_003 | J158: elc_spv_CAF_003 | K158: 9.345 | L158: 0.22229156 | M158: 139.97298 | N158: 153.97028 | P158: ele | Q158: elcagg_spv_ZWE | R158: solar aggregator to grid -- Zimbabwe | S158: GW | T158: PJ | U158: daynite | V158: no | X158: elcagg_spv_ZWE | Y158: ELC | Z158: 1
A159: ele | B159: en_spv_CAF_004 | C159: solar resource in Mbomou Prefecture region (near Bambari) -- Central African Republic | D159: GW | E159: PJ | F159: annual | G159: no | I159: en_spv_CAF_004 | J159: elc_spv_CAF_004 | K159: 0.567 | L159: 0.22474668 | M159: 487.62406 | N159: 536.38647
A160: ele | B160: en_spv_CAF_005 | C160: solar resource in Ouaka Prefecture region (near Bambari) -- Central African Republic | D160: GW | E160: PJ | F160: annual | G160: no | I160: en_spv_CAF_005 | J160: elc_spv_CAF_005 | K160: 2.73975 | L160: 0.22062042 | M160: 99.243514 | N160: 109.16787
A161: ele | B161: en_spv_CAF_006 | C161: solar resource in Mbomou Prefecture region (near Bambari) -- Central African Republic | D161: GW | E161: PJ | F161: annual | G161: no | I161: en_spv_CAF_006 | J161: elc_spv_CAF_006 | K161: 1.51425 | L161: 0.21550422 | M161: 277.76288 | N161: 305.53917
A162: ele | B162: en_spv_CAF_007 | C162: solar resource in Bamingui-Bangoran Prefecture region (near Bambari) -- Central African Republic | D162: GW | E162: PJ | F162: annual | G162: no | I162: en_spv_CAF_007 | J162: elc_spv_CAF_007 | K162: 14.973436 | L162: 0.22648812 | M162: 229.42981 | N162: 252.3728
A163: ele | B163: en_spv_CAF_008 | C163: solar resource in Haute-Kotto Prefecture region (near Bambari) -- Central African Republic | D163: GW | E163: PJ | F163: annual | G163: no | I163: en_spv_CAF_008 | J163: elc_spv_CAF_008 | K163: 4.93125 | L163: 0.22854032 | M163: 242.39136 | N163: 266.6305
A164: ele | B164: en_spv_CAF_009 | C164: solar resource in Vakaga Prefecture region (near Bambari) -- Central African Republic | D164: GW | E164: PJ | F164: annual | G164: no | I164: en_spv_CAF_009 | J164: elc_spv_CAF_009 | K164: 62.368585 | L164: 0.24123339 | M164: 507.64265 | N164: 558.40691
A165: ele | B165: en_spv_CAN_001 | C165: solar resource in Quebec region (near Chicoutimi) -- Canada | D165: GW | E165: PJ | F165: annual | G165: no | I165: en_spv_CAN_001 | J165: elc_spv_CAN_001 | K165: 4.4125756 | L165: 0.15786736 | M165: 1026.0001 | N165: 1128.6001
A166: ele | B166: en_spv_CAN_002 | C166: solar resource in Newfoundland and Labrador region (near Chicoutimi) -- Canada | D166: GW | E166: PJ | F166: annual | G166: no | I166: en_spv_CAN_002 | J166: elc_spv_CAN_002 | K166: 6.0556602 | L166: 0.16593495 | M166: 962.52833 | N166: 1058.7812
A167: ele | B167: en_spv_CAN_003 | C167: solar resource in Quebec region (near Chicoutimi) -- Canada | D167: GW | E167: PJ | F167: annual | G167: no | I167: en_spv_CAN_003 | J167: elc_spv_CAN_003 | K167: 12.610943 | L167: 0.14784542 | M167: 1160.1315 | N167: 1276.1447
A168: ele | B168: en_spv_CAN_004 | C168: solar resource in Quebec region (near Chicoutimi) -- Canada | D168: GW | E168: PJ | F168: annual | G168: no | I168: en_spv_CAN_004 | J168: elc_spv_CAN_004 | K168: 34.111945 | L168: 0.14901524 | M168: 1187.6084 | N168: 1306.3692
A169: ele | B169: en_spv_CAN_005 | C169: solar resource in Quebec region (near Chicoutimi) -- Canada | D169: GW | E169: PJ | F169: annual | G169: no | I169: en_spv_CAN_005 | J169: elc_spv_CAN_005 | K169: 7.669362 | L169: 0.16293257 | M169: 661.03284 | N169: 727.13612
A170: ele | B170: en_spv_CAN_006 | C170: solar resource in Quebec region (near Chicoutimi) -- Canada | D170: GW | E170: PJ | F170: annual | G170: no | I170: en_spv_CAN_006 | J170: elc_spv_CAN_006 | K170: 4.3261816 | L170: 0.1594932 | M170: 826.49503 | N170: 909.14453
... A1165: ele | B1165: en_spv_ZWE_007 | C1165: solar resource in Matabeleland North region (near Nkayi) -- Zimbabwe | D1165: GW | E1165: PJ | F1165: annual | G1165: no | I1165: en_spv_ZWE_007 | J1165: elc_spv_ZWE_007 | K1165: 34.679411 | L1165: 0.23584639 | M1165: 195.1168 | N1165: 214.62848

Sheet won
A1: ~fi_process | I1: ~fi_t | P1: ~fi_process | X1: ~fi_t
A2: set | B2: process | C2: description | D2: capacity_unit | E2: activity_unit | F2: timeslicelevel | G2: vintage | I2: process | J2: comm-out | K2: cap_bnd | L2: af~fx | M2: avg_grid_dist_km | N2: invcost~USD21_alt | P2: set | Q2: process | R2: description | S2: capacity_unit | T2: activity_unit | U2: timeslicelevel | V2: vintage | X2: process | Y2: comm-out | Z2: EFF
A3: ele | B3: en_won_AFG_001 | C3: wind onshore resource in Zabul region (near Kandahar) -- Afghanistan | D3: GW | E3: PJ | F3: annual | G3: no | I3: en_won_AFG_001 | J3: elc_won_AFG_001 | K3: 24.496099 | L3: 0.13070245 | M3: 231.3259 | N3: 254.4585 | P3: ele | Q3: elcagg_won_AFG | R3: wind onshore aggregator to grid -- Afghanistan | S3: GW | T3: PJ | U3: daynite | V3: no | X3: elcagg_won_AFG | Y3: ELC | Z3: 1
A4: ele | B4: en_won_AFG_002 | C4: wind onshore resource in Kandahar region (near Kandahar) -- Afghanistan | D4: GW | E4: PJ | F4: annual | G4: no | I4: en_won_AFG_002 | J4: elc_won_AFG_002 | K4: 3.7606504 | L4: 0.13775826 | M4: 194.23722 | N4: 213.66095 | P4: ele | Q4: elcagg_won_AGO | R4: wind onshore aggregator to grid -- Angola | S4: GW | T4: PJ | U4: daynite | V4: no | X4: elcagg_won_AGO | Y4: ELC | Z4: 1
A5: ele | B5: en_won_AFG_003 | C5: wind onshore resource in Helmand region (near Lashkar Gah) -- Afghanistan | D5: GW | E5: PJ | F5: annual | G5: no | I5: en_won_AFG_003 | J5: elc_won_AFG_003 | K5: 13.423823 | L5: 0.16474966 | M5: 88.765689 | N5: 97.642258 | P5: ele | Q5: elcagg_won_ALB | R5: wind onshore aggregator to grid -- Albania | S5: GW | T5: PJ | U5: daynite | V5: no | X5: elcagg_won_ALB | Y5: ELC | Z5: 1
A6: ele | B6: en_won_AFG_004 | C6: wind onshore resource in Helmand region (near Lashkar Gah) -- Afghanistan | D6: GW | E6: PJ | F6: annual | G6: no | I6: en_won_AFG_004 | J6: elc_won_AFG_004 | K6: 46.608186 | L6: 0.24005215 | M6: 165.20126 | N6: 181.72139 | P6: ele | Q6: elcagg_won_ARE | R6: wind onshore aggregator to grid -- United Arab Emirates | S6: GW | T6: PJ | U6: daynite | V6: no | X6: elcagg_won_ARE | Y6: ELC | Z6: 1
A7: ele | B7: en_won_AFG_005 | C7: wind onshore resource in Jowzjan region (near Aqchah) -- Afghanistan | D7: GW | E7: PJ | F7: annual | G7: no | I7: en_won_AFG_005 | J7: elc_won_AFG_005 | K7: 28.981008 | L7: 0.22133395 | M7: 81.118172 | N7: 89.229989 | P7: ele | Q7: elcagg_won_ARG | R7: wind onshore aggregator to grid -- Argentina | S7: GW | T7: PJ | U7: daynite | V7: no | X7: elcagg_won_ARG | Y7: ELC | Z7: 1
A8: ele | B8: en_won_AFG_006 | C8: wind onshore resource in Mary region (near Herat) -- Afghanistan | D8: GW | E8: PJ | F8: annual | G8: no | I8: en_won_AFG_006 | J8: elc_won_AFG_006 | K8: 16.157303 | L8: 0.23220235 | M8: 149.23421 | N8: 164.15763 | P8: ele | Q8: elcagg_won_ARM | R8: wind onshore aggregator to grid -- Armenia | S8: GW | T8: PJ | U8: daynite | V8: no | X8: elcagg_won_ARM | Y8: ELC | Z8: 1
A9: ele | B9: en_won_AFG_007 | C9: wind onshore resource in Farah region (near Farah) -- Afghanistan | D9: GW | E9: PJ | F9: annual | G9: no | I9: en_won_AFG_007 | J9: elc_won_AFG_007 | K9: 95.103968 | L9: 0.41045596 | M9: 139.26386 | N9: 153.19025 | P9: ele | Q9: elcagg_won_AUS | R9: wind onshore aggregator to grid -- Australia | S9: GW | T9: PJ | U9: daynite | V9: no | X9: elcagg_won_AUS | Y9: ELC | Z9: 1
A10: ele | B10: en_won_AGO_001 | C10: wind onshore resource in Namibe region (near Mocamedes) -- Angola | D10: GW | E10: PJ | F10: annual | G10: no | I10: en_won_AGO_001 | J10: elc_won_AGO_001 | K10: 9.583413 | L10: 0.13564405 | M10: 152.09142 | N10: 167.30056 | P10: ele | Q10: elcagg_won_AUT | R10: wind onshore aggregator to grid -- Austria | S10: GW | T10: PJ | U10: daynite | V10: no | X10: elcagg_won_AUT | Y10: ELC | Z10: 1
A11: ele | B11: en_won_AGO_002 | C11: wind onshore resource in Cunene region (near Chibia) -- Angola | D11: GW | E11: PJ | F11: annual | G11: no | I11: en_won_AGO_002 | J11: elc_won_AGO_002 | K11: 12.296203 | L11: 0.11058825 | M11: 141.22545 | N11: 155.348 | P11: ele | Q11: elcagg_won_AZE | R11: wind onshore aggregator to grid -- Azerbaijan | S11: GW | T11: PJ | U11: daynite | V11: no | X11: elcagg_won_AZE | Y11: ELC | Z11: 1
A12: ele | B12: en_won_AGO_003 | C12: wind onshore resource in Namibe region (near Mocamedes) -- Angola | D12: GW | E12: PJ | F12: annual | G12: no | I12: en_won_AGO_003 | J12: elc_won_AGO_003 | K12: 14.378232 | L12: 0.095540921 | M12: 112.25181 | N12: 123.47699 | P12: ele | Q12: elcagg_won_BDI | R12: wind onshore aggregator to grid -- Burundi | S12: GW | T12: PJ | U12: daynite | V12: no | X12: elcagg_won_BDI | Y12: ELC | Z12: 1
A13: ele | B13: en_won_AGO_004 | C13: wind onshore resource in Moxico region (near Luena) -- Angola | D13: GW | E13: PJ | F13: annual | G13: no | I13: en_won_AGO_004 | J13: elc_won_AGO_004 | K13: 64.119048 | L13: 0.12978707 | M13: 222.30006 | N13: 244.53007 | P13: ele | Q13: elcagg_won_BEL | R13: wind onshore aggregator to grid -- Belgium | S13: GW | T13: PJ | U13: daynite | V13: no | X13: elcagg_won_BEL | Y13: ELC | Z13: 1
A14: ele | B14: en_won_AGO_005 | C14: wind onshore resource in Lunda Sul region (near Saurimo) -- Angola | D14: GW | E14: PJ | F14: annual | G14: no | I14: en_won_AGO_005 | J14: elc_won_AGO_005 | K14: 30.446662 | L14: 0.10794076 | M14: 120.90553 | N14: 132.99608 | P14: ele | Q14: elcagg_won_BEN | R14: wind onshore aggregator to grid -- Benin | S14: GW | T14: PJ | U14: daynite | V14: no | X14: elcagg_won_BEN | Y14: ELC | Z14: 1
... A160: ele | B160: en_won_CHE_002 | C160: wind onshore resource in Doubs region (near La Chaux-de-Fonds) -- Switzerland | D160: GW | E160: PJ | F160: annual | G160: no | I160: en_won_CHE_002 | J160: elc_won_CHE_002 | K160: 21.123225 | L160: 0.13529727 | M160: 30.808992 | N160: 33.889892 | P160: ele | Q160: elcagg_won_ZWE | R160: wind onshore aggregator to grid -- Zimbabwe | S160: GW | T160: PJ | U160: daynite | V160: no | X160: elcagg_won_ZWE | Y160: ELC | Z160: 1
A161: ele | B161: en_won_CHL_001 | C161: wind onshore resource in Magellan and the Chilean Antarctic region (near Punta Arenas) -- Chile | D161: GW | E161: PJ | F161: annual | G161: no | I161: en_won_CHL_001 | J161: elc_won_CHL_001 | K161: 63.9705 | L161: 0.53774316 | M161: 225.64873 | N161: 248.21361
A162: ele | B162: en_won_CHL_002 | C162: wind onshore resource in Santa Cruz region (near Puerto Montt) -- Chile | D162: GW | E162: PJ | F162: annual | G162: no | I162: en_won_CHL_002 | J162: elc_won_CHL_002 | K162: 40.263913 | L162: 0.32909616 | M162: 494.67651 | N162: 544.14416
A163: ele | B163: en_won_CHL_003 | C163: wind onshore resource in Aysen region (near Punta Arenas) -- Chile | D163: GW | E163: PJ | F163: annual | G163: no | I163: en_won_CHL_003 | J163: elc_won_CHL_003 | K163: 36.531479 | L163: 0.14522367 | M163: 549.58944 | N163: 604.54839
A164: ele | B164: en_won_CHL_004 | C164: wind onshore resource in Antofagasta region (near Calama) -- Chile | D164: GW | E164: PJ | F164: annual | G164: no | I164: en_won_CHL_004 | J164: elc_won_CHL_004 | K164: 12.161712 | L164: 0.10664807 | M164: 107.11078 | N164: 117.82186
A165: ele | B165: en_won_CHL_005 | C165: wind onshore resource in Nuble region (near Chillan) -- Chile | D165: GW | E165: PJ | F165: annual | G165: no | I165: en_won_CHL_005 | J165: elc_won_CHL_005 | K165: 3.8393926 | L165: 0.21136759 | M165: 46.348854 | N165: 50.983739
A166: ele | B166: en_won_CHL_006 | C166: wind onshore resource in near Ovalle -- Chile | D166: GW | E166: PJ | F166: annual | G166: no | I166: en_won_CHL_006 | J166: elc_won_CHL_006 | K166: 2.8700817 | L166: 0.33831634 | M166: 93.825604 | N166: 103.20816
A167: ele | B167: en_won_CHL_007 | C167: wind onshore resource in Araucania region (near Temuco) -- Chile | D167: GW | E167: PJ | F167: annual | G167: no | I167: en_won_CHL_007 | J167: elc_won_CHL_007 | K167: 11.200297 | L167: 0.14573084 | M167: 138.82178 | N167: 152.70396
A168: ele | B168: en_won_CHL_008 | C168: wind onshore resource in Los Lagos region (near Puerto Montt) -- Chile | D168: GW | E168: PJ | F168: annual | G168: no | I168: en_won_CHL_008 | J168: elc_won_CHL_008 | K168: 1.3004661 | L168: 0.29979741 | M168: 115.44258 | N168: 126.98684
A169: ele | B169: en_won_CHN_001 | C169: wind onshore resource in Xinjiang region (near Urumqi) -- China | D169: GW | E169: PJ | F169: annual | G169: no | I169: en_won_CHN_001 | J169: elc_won_CHN_001 | K169: 213.73047 | L169: 0.16710028 | M169: 984.10383 | N169: 1082.5142
A170: ele | B170: en_won_CHN_002 | C170: wind onshore resource in Xinjiang region (near Urumqi) -- China | D170: GW | E170: PJ | F170: annual | G170: no | I170: en_won_CHN_002 | J170: elc_won_CHN_002 | K170: 410.33682 | L170: 0.20688406 | M170: 530.25577 | N170: 583.28135
A171: ele | B171: en_won_CHN_003 | C171: wind onshore resource in Inner Mongolia region (near Yinchuan) -- China | D171: GW | E171: PJ | F171: annual | G171: no | I171: en_won_CHN_003 | J171: elc_won_CHN_003 | K171: 772.42159 | L171: 0.30835457 | M171: 392.2656 | N171: 431.49216
A172: ele | B172: en_won_CHN_004 | C172: wind onshore resource in Xinjiang region (near Urumqi) -- China | D172: GW | E172: PJ | F172: annual | G172: no | I172: en_won_CHN_004 | J172: elc_won_CHN_004 | K172: 257.85108 | L172: 0.17209788 | M172: 355.28858 | N172: 390.81743
... A1000: ele | B1000: en_won_ZWE_007 | C1000: wind onshore resource in Matabeleland North region (near Nkayi) -- Zimbabwe | D1000: GW | E1000: PJ | F1000: annual | G1000: no | I1000: en_won_ZWE_007 | J1000: elc_won_ZWE_007 | K1000: 4.3432731 | L1000: 0.15598014 | M1000: 326.78321 | N1000: 359.46153

Sheet wof
A1: ~fi_process | I1: ~fi_t | P1: ~fi_process | X1: ~fi_t
A2: set | B2: process | C2: description | D2: capacity_unit | E2: activity_unit | F2: timeslicelevel | G2: vintage | I2: process | J2: comm-out | K2: cap_bnd | L2: af~fx | M2: avg_grid_dist_km | N2: invcost~USD21_alt | P2: set | Q2: process | R2: description | S2: capacity_unit | T2: activity_unit | U2: timeslicelevel | V2: vintage | X2: process | Y2: comm-out | Z2: EFF
A3: ele | B3: en_wof_AGO_001 | C3: wind offshore resource in near Mocamedes -- Angola | D3: GW | E3: PJ | F3: annual | G3: no | I3: en_wof_AGO_001 | J3: elc_wof_AGO_001 | K3: 1.089 | L3: 0.28634051 | M3: 114.61115 | N3: 126.07226 | P3: ele | Q3: elcagg_wof_AGO | R3: wind offshore aggregator to grid -- Angola | S3: GW | T3: PJ | U3: daynite | V3: no | X3: elcagg_wof_AGO | Y3: ELC | Z3: 1
A4: ele | B4: en_wof_AGO_002 | C4: wind offshore resource in near Mocamedes -- Angola | D4: GW | E4: PJ | F4: annual | G4: no | I4: en_wof_AGO_002 | J4: elc_wof_AGO_002 | K4: 12.99075 | L4: 0.48262051 | M4: 206.4746 | N4: 227.12206 | P4: ele | Q4: elcagg_wof_ALB | R4: wind offshore aggregator to grid -- Albania | S4: GW | T4: PJ | U4: daynite | V4: no | X4: elcagg_wof_ALB | Y4: ELC | Z4: 1
A5: ele | B5: en_wof_ALB_001 | C5: wind offshore resource in near Vlore -- Albania | D5: GW | E5: PJ | F5: annual | G5: no | I5: en_wof_ALB_001 | J5: elc_wof_ALB_001 | K5: 9.15 | L5: 0.31121524 | M5: 55.018787 | N5: 60.520666 | P5: ele | Q5: elcagg_wof_ARE | R5: wind offshore aggregator to grid -- United Arab Emirates | S5: GW | T5: PJ | U5: daynite | V5: no | X5: elcagg_wof_ARE | Y5: ELC | Z5: 1
A6: ele | B6: en_wof_ALB_002 | C6: wind offshore resource in near Durres -- Albania | D6: GW | E6: PJ | F6: annual | G6: no | I6: en_wof_ALB_002 | J6: elc_wof_ALB_002 | K6: 15.11325 | L6: 0.27978349 | M6: 66.968846 | N6: 73.665731 | P6: ele | Q6: elcagg_wof_ARG | R6: wind offshore aggregator to grid -- Argentina | S6: GW | T6: PJ | U6: daynite | V6: no | X6: elcagg_wof_ARG | Y6: ELC | Z6: 1
A7: ele | B7: en_wof_ARE_001 | C7: wind offshore resource in near Abu Dhabi -- United Arab Emirates | D7: GW | E7: PJ | F7: annual | G7: no | I7: en_wof_ARE_001 | J7: elc_wof_ARE_001 | K7: 0 | L7: 0.24914216 | M7: 0 | N7: 0 | P7: ele | Q7: elcagg_wof_AUS | R7: wind offshore aggregator to grid -- Australia | S7: GW | T7: PJ | U7: daynite | V7: no | X7: elcagg_wof_AUS | Y7: ELC | Z7: 1
A8: ele | B8: en_wof_ARE_002 | C8: wind offshore resource in near Abu Dhabi -- United Arab Emirates | D8: GW | E8: PJ | F8: annual | G8: no | I8: en_wof_ARE_002 | J8: elc_wof_ARE_002 | K8: 0 | L8: 0.22329599 | M8: 0 | N8: 0 | P8: ele | Q8: elcagg_wof_AZE | R8: wind offshore aggregator to grid -- Azerbaijan | S8: GW | T8: PJ | U8: daynite | V8: no | X8: elcagg_wof_AZE | Y8: ELC | Z8: 1
A9: ele | B9: en_wof_ARG_001 | C9: wind offshore resource in near Rio Gallegos -- Argentina | D9: GW | E9: PJ | F9: annual | G9: no | I9: en_wof_ARG_001 | J9: elc_wof_ARG_001 | K9: 258.81525 | L9: 0.62034035 | M9: 323.52705 | N9: 355.87976 | P9: ele | Q9: elcagg_wof_BEN | R9: wind offshore aggregator to grid -- Benin | S9: GW | T9: PJ | U9: daynite | V9: no | X9: elcagg_wof_BEN | Y9: ELC | Z9: 1
A10: ele | B10: en_wof_ARG_002 | C10: wind offshore resource in near Rio Grande -- Argentina | D10: GW | E10: PJ | F10: annual | G10: no | I10: en_wof_ARG_002 | J10: elc_wof_ARG_002 | K10: 168.75 | L10: 0.74371122 | M10: 592.2415 | N10: 651.46565 | P10: ele | Q10: elcagg_wof_BGD | R10: wind offshore aggregator to grid -- Bangladesh | S10: GW | T10: PJ | U10: daynite | V10: no | X10: elcagg_wof_BGD | Y10: ELC | Z10: 1
