Workbook

Sheet drate
F2: ~TFM_INS-TS | N2: ~TFM_INS-TS
B3: ActiveReg | C3: Status | D3: ElastClass | F3: region | G3: attribute | H3: pset_set | I3: pset_co | J3: pset_pn | K3: 2020 | L3: 2050 | N3: region | O3: attribute | P3: pset_set | Q3: pset_co | R3: pset_pn | S3: 2020 | T3: 2050
A4: 1 | B4: Africa_other | C4: Eme | D4: =C4 -> Eme | F4: =B4 -> Africa_other | G4: NCAP_DRATE | H4: DMD | I4: C?? | J4: -CSHIN* | K4: =L4+0.1 -> 0.3 | L4: 0.2 | N4: =F4 -> Africa_other | O4: NCAP_DRATE | P4: DMD | Q4: R?? | R4: -RSHIN* | S4: =T4+0.1 -> 0.4 | T4: =L4+0.1 -> 0.3
A5: =A4+1 -> 2 | B5: India | C5: Eme | D5: =C5 -> Eme | F5: =B5 -> India | G5: NCAP_DRATE | H5: DMD | I5: C?? | J5: -CSHIN* | K5: =L5+0.1 -> 0.3 | L5: =L4 -> 0.2 | N5: =F5 -> India | O5: NCAP_DRATE | P5: DMD | Q5: R?? | R5: -RSHIN* | S5: =T5+0.1 -> 0.4 | T5: =L5+0.1 -> 0.3
A6: =A5+1 -> 3 | B6: Asia_other | C6: Eme | D6: =C6 -> Eme | F6: =B6 -> Asia_other | G6: NCAP_DRATE | H6: DMD | I6: C?? | J6: -CSHIN* | K6: =L6+0.1 -> 0.3 | L6: =L5 -> 0.2 | N6: =F6 -> Asia_other | O6: NCAP_DRATE | P6: DMD | Q6: R?? | R6: -RSHIN* | S6: =T6+0.1 -> 0.4 | T6: =L6+0.1 -> 0.3
A7: =A6+1 -> 4 | B7: Asia_central | C7: Eme | D7: =C7 -> Eme | F7: =B7 -> Asia_central | G7: NCAP_DRATE | H7: DMD | I7: C?? | J7: -CSHIN* | K7: =L7+0.1 -> 0.3 | L7: =L6 -> 0.2 | N7: =F7 -> Asia_central | O7: NCAP_DRATE | P7: DMD | Q7: R?? | R7: -RSHIN* | S7: =T7+0.1 -> 0.4 | T7: =L7+0.1 -> 0.3
A8: =A7+1 -> 5 | B8: LatAm_other | C8: Eme | D8: =C8 -> Eme | F8: =B8 -> LatAm_other | G8: NCAP_DRATE | H8: DMD | I8: C?? | J8: -CSHIN* | K8: =L8+0.1 -> 0.3 | L8: =L7 -> 0.2 | N8: =F8 -> LatAm_other | O8: NCAP_DRATE | P8: DMD | Q8: R?? | R8: -RSHIN* | S8: =T8+0.1 -> 0.4 | T8: =L8+0.1 -> 0.3
A9: =A8+1 -> 6 | B9: Brazil | C9: Eme | D9: =C9 -> Eme | F9: =B9 -> Brazil | G9: NCAP_DRATE | H9: DMD | I9: C?? | J9: -CSHIN* | K9: =L9+0.1 -> 0.3 | L9: =L8 -> 0.2 | N9: =F9 -> Brazil | O9: NCAP_DRATE | P9: DMD | Q9: R?? | R9: -RSHIN* | S9: =T9+0.1 -> 0.4 | T9: =L9+0.1 -> 0.3
A10: =A9+1 -> 7 | B10: Africa_north | C10: Eme | D10: =C10 -> Eme | F10: =B10 -> Africa_north | G10: NCAP_DRATE | H10: DMD | I10: C?? | J10: -CSHIN* | K10: =L10+0.1 -> 0.3 | L10: =L9 -> 0.2 | N10: =F10 -> Africa_north | O10: NCAP_DRATE | P10: DMD | Q10: R?? | R10: -RSHIN* | S10: =T10+0.1 -> 0.4 | T10: =L10+0.1 -> 0.3
A11: =A10+1 -> 8 | B11: SouthAfrica | C11: Eme | D11: Eme | F11: =B11 -> SouthAfrica | G11: NCAP_DRATE | H11: DMD | I11: C?? | J11: -CSHIN* | K11: =L11+0.1 -> 0.3 | L11: =L10 -> 0.2 | N11: =F11 -> SouthAfrica | O11: NCAP_DRATE | P11: DMD | Q11: R?? | R11: -RSHIN* | S11: =T11+0.1 -> 0.4 | T11: =L11+0.1 -> 0.3
A12: =A11+1 -> 9 | B12: MidEast_other | C12: Eme | D12: =C12 -> Eme | F12: =B12 -> MidEast_other | G12: NCAP_DRATE | H12: DMD | I12: C?? | J12: -CSHIN* | K12: =L12+0.1 -> 0.3 | L12: =L11 -> 0.2 | N12: =F12 -> MidEast_other | O12: NCAP_DRATE | P12: DMD | Q12: R?? | R12: -RSHIN* | S12: =T12+0.1 -> 0.4 | T12: =L12+0.1 -> 0.3
A13: =A12+1 -> 10 | B13: Mexico | C13: Eme | D13: =C13 -> Eme | F13: =B13 -> Mexico | G13: NCAP_DRATE | H13: DMD | I13: C?? | J13: -CSHIN* | K13: =L13+0.1 -> 0.3 | L13: =L12 -> 0.2 | N13: =F13 -> Mexico | O13: NCAP_DRATE | P13: DMD | Q13: R?? | R13: -RSHIN* | S13: =T13+0.1 -> 0.4 | T13: =L13+0.1 -> 0.3
A14: =A13+1 -> 11 | B14: Europe_other | C14: Dev | D14: =C14 -> Dev | F14: =B14 -> Europe_other | G14: NCAP_DRATE | H14: DMD | I14: C?? | J14: -CSHIN* | K14: =L14+0.1 -> 0.2 | L14: =L13-0.1 -> 0.1 | N14: =F14 -> Europe_other | O14: NCAP_DRATE | P14: DMD | Q14: R?? | R14: -RSHIN* | S14: =T14+0.1 -> 0.3 | T14: =L14+0.1 -> 0.2
A15: =A14+1 -> 12 | B15: Arg-Chi | C15: Dev | D15: =C15 -> Dev | F15: =B15 -> Arg-Chi | G15: NCAP_DRATE | H15: DMD | I15: C?? | J15: -CSHIN* | K15: =L15+0.1 -> 0.2 | L15: =L14 -> 0.1 | N15: =F15 -> Arg-Chi | O15: NCAP_DRATE | P15: DMD | Q15: R?? | R15: -RSHIN* | S15: =T15+0.1 -> 0.3 | T15: =L15+0.1 -> 0.2
A16: =A15+1 -> 13 | B16: Russia | C16: Dev | D16: =C16 -> Dev | F16: =B16 -> Russia | G16: NCAP_DRATE | H16: DMD | I16: C?? | J16: -CSHIN* | K16: =L16+0.1 -> 0.2 | L16: =L15 -> 0.1 | N16: =F16 -> Russia | O16: NCAP_DRATE | P16: DMD | Q16: R?? | R16: -RSHIN* | S16: =T16+0.1 -> 0.3 | T16: =L16+0.1 -> 0.2
A17: =A16+1 -> 14 | B17: EU_southeast | C17: Dev | D17: =C17 -> Dev | F17: =B17 -> EU_southeast | G17: NCAP_DRATE | H17: DMD | I17: C?? | J17: -CSHIN* | K17: =L17+0.1 -> 0.2 | L17: =L16 -> 0.1 | N17: =F17 -> EU_southeast | O17: NCAP_DRATE | P17: DMD | Q17: R?? | R17: -RSHIN* | S17: =T17+0.1 -> 0.3 | T17: =L17+0.1 -> 0.2
A18: =A17+1 -> 15 | B18: EU_southwest | C18: Dev | D18: =C18 -> Dev | F18: =B18 -> EU_southwest | G18: NCAP_DRATE | H18: DMD | I18: C?? | J18: -CSHIN* | K18: =L18+0.1 -> 0.2 | L18: =L17 -> 0.1 | N18: =F18 -> EU_southwest | O18: NCAP_DRATE | P18: DMD | Q18: R?? | R18: -RSHIN* | S18: =T18+0.1 -> 0.3 | T18: =L18+0.1 -> 0.2
A19: =A18+1 -> 16 | B19: China | C19: Dev | D19: Chi | F19: =B19 -> China | G19: NCAP_DRATE | H19: DMD | I19: C?? | J19: -CSHIN* | K19: =L19+0.1 -> 0.2 | L19: =L18 -> 0.1 | N19: =F19 -> China | O19: NCAP_DRATE | P19: DMD | Q19: R?? | R19: -RSHIN* | S19: =T19+0.1 -> 0.3 | T19: =L19+0.1 -> 0.2
A20: =A19+1 -> 17 | B20: EU_south | C20: Dev | D20: =C20 -> Dev | F20: =B20 -> EU_south | G20: NCAP_DRATE | H20: DMD | I20: C?? | J20: -CSHIN* | K20: =L20+0.1 -> 0.2 | L20: =L19 -> 0.1 | N20: =F20 -> EU_south | O20: NCAP_DRATE | P20: DMD | Q20: R?? | R20: -RSHIN* | S20: =T20+0.1 -> 0.3 | T20: =L20+0.1 -> 0.2
A21: =A20+1 -> 18 | B21: EU_northeast | C21: Dev | D21: =C21 -> Dev | F21: =B21 -> EU_northeast | G21: NCAP_DRATE | H21: DMD | I21: C?? | J21: -CSHIN* | K21: =L21+0.1 -> 0.2 | L21: =L20 -> 0.1 | N21: =F21 -> EU_northeast | O21: NCAP_DRATE | P21: DMD | Q21: R?? | R21: -RSHIN* | S21: =T21+0.1 -> 0.3 | T21: =L21+0.1 -> 0.2
A22: =A21+1 -> 19 | B22: France | C22: Dev | D22: =C22 -> Dev | F22: =B22 -> France | G22: NCAP_DRATE | H22: DMD | I22: C?? | J22: -CSHIN* | K22: =L22+0.1 -> 0.2 | L22: =L21 -> 0.1 | N22: =F22 -> France | O22: NCAP_DRATE | P22: DMD | Q22: R?? | R22: -RSHIN* | S22: =T22+0.1 -> 0.3 | T22: =L22+0.1 -> 0.2
A23: =A22+1 -> 20 | B23: UK | C23: Dev | D23: =C23 -> Dev | F23: =B23 -> UK | G23: NCAP_DRATE | H23: DMD | I23: C?? | J23: -CSHIN* | K23: =L23+0.1 -> 0.2 | L23: =L22 -> 0.1 | N23: =F23 -> UK | O23: NCAP_DRATE | P23: DMD | Q23: R?? | R23: -RSHIN* | S23: =T23+0.1 -> 0.3 | T23: =L23+0.1 -> 0.2
A24: =A23+1 -> 21 | B24: Australia_NZ | C24: Dev | D24: =C24 -> Dev | F24: =B24 -> Australia_NZ | G24: NCAP_DRATE | H24: DMD | I24: C?? | J24: -CSHIN* | K24: =L24+0.1 -> 0.2 | L24: =L23 -> 0.1 | N24: =F24 -> Australia_NZ | O24: NCAP_DRATE | P24: DMD | Q24: R?? | R24: -RSHIN* | S24: =T24+0.1 -> 0.3 | T24: =L24+0.1 -> 0.2
A25: =A24+1 -> 22 | B25: SaudiArabia | C25: Dev | D25: =C25 -> Dev | F25: =B25 -> SaudiArabia | G25: NCAP_DRATE | H25: DMD | I25: C?? | J25: -CSHIN* | K25: =L25+0.1 -> 0.2 | L25: =L24 -> 0.1 | N25: =F25 -> SaudiArabia | O25: NCAP_DRATE | P25: DMD | Q25: R?? | R25: -RSHIN* | S25: =T25+0.1 -> 0.3 | T25: =L25+0.1 -> 0.2
A26: =A25+1 -> 23 | B26: EU_north | C26: Dev | D26: =C26 -> Dev | F26: =B26 -> EU_north | G26: NCAP_DRATE | H26: DMD | I26: C?? | J26: -CSHIN* | K26: =L26+0.1 -> 0.2 | L26: =L25 -> 0.1 | N26: =F26 -> EU_north | O26: NCAP_DRATE | P26: DMD | Q26: R?? | R26: -RSHIN* | S26: =T26+0.1 -> 0.3 | T26: =L26+0.1 -> 0.2
A27: =A26+1 -> 24 | B27: Germany | C27: Dev | D27: =C27 -> Dev | F27: =B27 -> Germany | G27: NCAP_DRATE | H27: DMD | I27: C?? | J27: -CSHIN* | K27: =L27+0.1 -> 0.2 | L27: =L26 -> 0.1 | N27: =F27 -> Germany | O27: NCAP_DRATE | P27: DMD | Q27: R?? | R27: -RSHIN* | S27: =T27+0.1 -> 0.3 | T27: =L27+0.1 -> 0.2
A28: =A27+1 -> 25 | B28: Canada | C28: Dev | D28: =C28 -> Dev | F28: =B28 -> Canada | G28: NCAP_DRATE | H28: DMD | I28: C?? | J28: -CSHIN* | K28: =L28+0.1 -> 0.2 | L28: =L27 -> 0.1 | N28: =F28 -> Canada | O28: NCAP_DRATE | P28: DMD | Q28: R?? | R28: -RSHIN* | S28: =T28+0.1 -> 0.3 | T28: =L28+0.1 -> 0.2
A29: =A28+1 -> 26 | B29: Asia_east | C29: Dev | D29: =C29 -> Dev | F29: =B29 -> Asia_east | G29: NCAP_DRATE | H29: DMD | I29: C?? | J29: -CSHIN* | K29: =L29+0.1 -> 0.2 | L29: =L28 -> 0.1 | N29: =F29 -> Asia_east | O29: NCAP_DRATE | P29: DMD | Q29: R?? | R29: -RSHIN* | S29: =T29+0.1 -> 0.3 | T29: =L29+0.1 -> 0.2
A30: =A29+1 -> 27 | B30: EU_northwest | C30: Dev | D30: =C30 -> Dev | F30: =B30 -> EU_northwest | G30: NCAP_DRATE | H30: DMD | I30: C?? | J30: -CSHIN* | K30: =L30+0.1 -> 0.2 | L30: =L29 -> 0.1 | N30: =F30 -> EU_northwest | O30: NCAP_DRATE | P30: DMD | Q30: R?? | R30: -RSHIN* | S30: =T30+0.1 -> 0.3 | T30: =L30+0.1 -> 0.2
A31: =A30+1 -> 28 | B31: Nor-Ice | C31: Dev | D31: =C31 -> Dev | F31: =B31 -> Nor-Ice | G31: NCAP_DRATE | H31: DMD | I31: C?? | J31: -CSHIN* | K31: =L31+0.1 -> 0.2 | L31: =L30 -> 0.1 | N31: =F31 -> Nor-Ice | O31: NCAP_DRATE | P31: DMD | Q31: R?? | R31: -RSHIN* | S31: =T31+0.1 -> 0.3 | T31: =L31+0.1 -> 0.2
A32: =A31+1 -> 29 | B32: USA | C32: Dev | D32: =C32 -> Dev | F32: =B32 -> USA | G32: NCAP_DRATE | H32: DMD | I32: C?? | J32: -CSHIN* | K32: =L32+0.1 -> 0.2 | L32: =L31 -> 0.1 | N32: =F32 -> USA | O32: NCAP_DRATE | P32: DMD | Q32: R?? | R32: -RSHIN* | S32: =T32+0.1 -> 0.3 | T32: =L32+0.1 -> 0.2

Sheet BY_RESCOM
A1: scenario | B1: attribute | C1: process | D1: commodity | E1: lim_type | F1: time_slice | G1: year | H1: commodity_group | I1: currency | J1: stage | K1: sow | L1: Africa_north | M1: Africa_other | N1: Arg-Chi | O1: Asia_central | P1: Asia_east | Q1: Asia_other | R1: Australia_NZ | S1: Brazil | T1: Canada | U1: China | V1: EU_north | W1: EU_northeast | X1: EU_northwest | Y1: EU_south | Z1: EU_southeast | AA1: EU_southwest | AB1: Europe_other | AC1: France | AD1: Germany | AE1: India | AF1: LatAm_other | AG1: Mexico | AH1: MidEast_other | AI1: Nor-Ice | AJ1: Russia | AK1: SaudiArabia | AL1: SouthAfrica | AM1: UK | AN1: USA | AO1: year2 | AX1: Dem | AY1: Fuel
A2: BASE | B2: Stock | C2: CCKBIO000 | D2: - | E2: - | F2: - | G2: 2019 | H2: - | I2: - | J2: - | K2: - | L2: 3.3811994 | M2: 38.545149 | N2: 0.73020237 | O2: 0 | P2: 0 | Q2: 5.1697344 | R2: 0 | S2: 0.72475248 | T2: 0 | U2: 0.0052520685 | V2: 0.27662887 | W2: 0 | X2: 0.30212786 | Y2: 0.10389197 | Z2: 0 | AA2: 0.19224722 | AB2: 0 | AC2: 0.51884161 | AD2: 1.9664001 | AE2: 11.52312 | AF2: 2.6367986 | AG2: 0 | AH2: 0 | AI2: 0.059347262 | AJ2: 0 | AK2: 0 | AL2: 0 | AM2: 0.27629991 | AN2: 0 | AO2: - | AX2: =LEFT(C2,3) -> CCK | AY2: =IF(LEFT(MID(C2,4,3),1)="E","ELC",IF(LEFT(MID(C2,4,3),1)="N","NGA",MID(C2,4,3))) -> BIO
A3: BASE | B3: Stock | C3: CCKCOA000 | D3: - | E3: - | F3: - | G3: 2019 | H3: - | I3: - | J3: - | K3: - | L3: 0 | M3: 0.010866128 | N3: 0 | O3: 0 | P3: 0.2147065 | Q3: 1.596736 | R3: 0 | S3: 0 | T3: 0 | U3: 27.692079 | V3: 0 | W3: 0 | X3: 0 | Y3: 0 | Z3: 0 | AA3: 0 | AB3: 0 | AC3: 0 | AD3: 0 | AE3: 18.116145 | AF3: 0 | AG3: 0 | AH3: 0 | AI3: 0 | AJ3: 0 | AK3: 0 | AL3: 4.7838808 | AM3: 0 | AN3: 0 | AO3: - | AX3: =LEFT(C3,3) -> CCK | AY3: =IF(LEFT(MID(C3,4,3),1)="E","ELC",IF(LEFT(MID(C3,4,3),1)="N","NGA",MID(C3,4,3))) -> COA
A4: BASE | B4: Stock | C4: CCKDST000 | D4: - | E4: - | F4: - | G4: 2019 | H4: - | I4: - | J4: - | K4: - | L4: 0 | M4: 0 | N4: 6.2009711 | O4: 0 | P4: 0 | Q4: 22.477068 | R4: 0 | S4: 0.54368947 | T4: 0 | U4: 109.12656 | V4: 0 | W4: 0 | X4: 0 | Y4: 0 | Z4: 0 | AA4: 0 | AB4: 15.747953 | AC4: 0 | AD4: 0 | AE4: 0 | AF4: 7.4514029 | AG4: 0.40049966 | AH4: 12.546955 | AI4: 0 | AJ4: 0 | AK4: 0 | AL4: 0 | AM4: 0 | AN4: 0 | AO4: - | AX4: =LEFT(C4,3) -> CCK | AY4: =IF(LEFT(MID(C4,4,3),1)="E","ELC",IF(LEFT(MID(C4,4,3),1)="N","NGA",MID(C4,4,3))) -> DST
A5: BASE | B5: Stock | C5: CCKELC000 | D5: - | E5: - | F5: - | G5: 2019 | H5: - | I5: - | J5: - | K5: - | L5: 6.6993242 | M5: 4.129998 | N5: 2.188084 | O5: 2.0507424 | P5: 0 | Q5: 8.1627637 | R5: 10.182163 | S5: 7.1085267 | T5: 15.255677 | U5: 61.402911 | V5: 5.57696 | W5: 7.0898345 | X5: 7.3767031 | Y5: 11.127384 | Z5: 2.6893995 | AA5: 9.1798287 | AB5: 10.301247 | AC5: 13.770195 | AD5: 13.101379 | AE5: 8.5926575 | AF5: 4.5034691 | AG5: 1.4473116 | AH5: 11.709283 | AI5: 2.7776497 | AJ5: 11.556889 | AK5: 9.2530281 | AL5: 4.6755581 | AM5: 9.0841599 | AN5: 35.452379 | AO5: - | AX5: =LEFT(C5,3) -> CCK | AY5: =IF(LEFT(MID(C5,4,3),1)="E","ELC",IF(LEFT(MID(C5,4,3),1)="N","NGA",MID(C5,4,3))) -> ELC
A6: BASE | B6: Stock | C6: CCKKER000 | D6: - | E6: - | F6: - | G6: 2019 | H6: - | I6: - | J6: - | K6: - | L6: 0 | M6: 0.028837108 | N6: 0.0011248885 | O6: 0.010917081 | P6: 0 | Q6: 2.4624696 | R6: 0.00030898584 | S6: 0 | T6: 6.5524791 | U6: 12.741378 | V6: 0.0085358385 | W6: 0.0003548313 | X6: 0.8898855 | Y6: 0.025209769 | Z6: 0.0031955751 | AA6: 2.19807e-05 | AB6: 0 | AC6: 0 | AD6: 0 | AE6: 0 | AF6: 0.00761872 | AG6: 0 | AH6: 0.15156111 | AI6: 0.0001716588 | AJ6: 0 | AK6: 0 | AL6: 0.075838858 | AM6: 8.5355004 | AN6: 0 | AO6: - | AX6: =LEFT(C6,3) -> CCK | AY6: =IF(LEFT(MID(C6,4,3),1)="E","ELC",IF(LEFT(MID(C6,4,3),1)="N","NGA",MID(C6,4,3))) -> KER
A7: BASE | B7: Stock | C7: CCKLPG000 | D7: - | E7: - | F7: - | G7: 2019 | H7: - | I7: - | J7: - | K7: - | L7: 3.1517338 | M7: 7.6781135 | N7: 8.6678652 | O7: 0.073074942 | P7: 0 | Q7: 53.149924 | R7: 0.49972498 | S7: 13.520611 | T7: 13.858191 | U7: 23.378426 | V7: 0.24873737 | W7: 0.18258623 | X7: 2.3324453 | Y7: 6.139159 | Z7: 0.10933439 | AA7: 3.1497235 | AB7: 13.616384 | AC7: 3.7877517 | AD7: 2.2896501 | AE7: 61.212254 | AF7: 13.42147 | AG7: 29.955185 | AH7: 5.2055263 | AI7: 0.33894375 | AJ7: 0.038981386 | AK7: 0 | AL7: 0.74585979 | AM7: 4.4874611 | AN7: 2.7414358 | AO7: - | AX7: =LEFT(C7,3) -> CCK | AY7: =IF(LEFT(MID(C7,4,3),1)="E","ELC",IF(LEFT(MID(C7,4,3),1)="N","NGA",MID(C7,4,3))) -> LPG
A8: BASE | B8: Stock | C8: CCKNGA000 | D8: - | E8: - | F8: - | G8: 2019 | H8: - | I8: - | J8: - | K8: - | L8: 8.2131365 | M8: 0.02582615 | N8: 22.03105 | O8: 41.108654 | P8: 130.67408 | Q8: 16.622345 | R8: 3.398479 | S8: 2.3700498 | T8: 32.592874 | U8: 161.09949 | V8: 1.614148 | W8: 15.937795 | X8: 24.261911 | Y8: 33.531664 | Z8: 9.6605502 | AA8: 10.341178 | AB8: 101.98353 | AC8: 28.127932 | AD8: 45.458431 | AE8: 37.458826 | AF8: 13.976016 | AG8: 3.7983332 | AH8: 234.97801 | AI8: 0.31901561 | AJ8: 24.669805 | AK8: 0 | AL8: 0.42758059 | AM8: 29.374873 | AN8: 190.61431 | AO8: - | AX8: =LEFT(C8,3) -> CCK | AY8: =IF(LEFT(MID(C8,4,3),1)="E","ELC",IF(LEFT(MID(C8,4,3),1)="N","NGA",MID(C8,4,3))) -> NGA
A9: BASE | B9: Stock | C9: CCKSTH000 | D9: - | E9: - | F9: - | G9: 2019 | H9: - | I9: - | J9: - | K9: - | L9: 0 | M9: 0 | N9: 0 | O9: 0 | P9: 0 | Q9: 0 | R9: 0 | S9: 0 | T9: 0 | U9: 0 | V9: 0 | W9: 0 | X9: 0 | Y9: 0 | Z9: 0 | AA9: 0 | AB9: 0 | AC9: 0 | AD9: 0 | AE9: 0.20821291 | AF9: 0 | AG9: 0 | AH9: 0 | AI9: 0 | AJ9: 0 | AK9: 0 | AL9: 0 | AM9: 0 | AN9: 0 | AO9: - | AX9: =LEFT(C9,3) -> CCK | AY9: =IF(LEFT(MID(C9,4,3),1)="E","ELC",IF(LEFT(MID(C9,4,3),1)="N","NGA",MID(C9,4,3))) -> STH
A10: BASE | B10: Stock | C10: CHWBIO000 | D10: - | E10: - | F10: - | G10: 2019 | H10: - | I10: - | J10: - | K10: - | L10: 14.088331 | M10: 160.60479 | N10: 3.4771541 | O10: 0 | P10: 0 | Q10: 51.697344 | R10: 0.058124821 | S10: 3.4512023 | T10: 0 | U10: 0.087534474 | V10: 0 | W10: 0 | X10: 0 | Y10: 0 | Z10: 0 | AA10: 0 | AB10: 0 | AC10: 0 | AD10: 0 | AE10: 54.872 | AF10: 12.556184 | AG10: 0 | AH10: 0 | AI10: 0 | AJ10: 0 | AK10: 0 | AL10: 0 | AM10: 0 | AN10: 0 | AO10: - | AX10: =LEFT(C10,3) -> CHW | AY10: =IF(LEFT(MID(C10,4,3),1)="E","ELC",IF(LEFT(MID(C10,4,3),1)="N","NGA",MID(C10,4,3))) -> BIO
A11: BASE | B11: Stock | C11: CHWCOA000 | D11: - | E11: - | F11: - | G11: 2019 | H11: - | I11: - | J11: - | K11: - | L11: 0 | M11: 0.38635121 | N11: 0 | O11: 0 | P11: 20.578632 | Q11: 34.0637 | R11: 2.7120199 | S11: 0 | T11: 0 | U11: 984.60726 | V11: 0 | W11: 0 | X11: 0 | Y11: 0 | Z11: 0 | AA11: 0 | AB11: 0 | AC11: 0 | AD11: 0 | AE11: 386.47775 | AF11: 0 | AG11: 0 | AH11: 0 | AI11: 0 | AJ11: 0 | AK11: 0 | AL11: 170.09354 | AM11: 0 | AN11: 0 | AO11: - | AX11: =LEFT(C11,3) -> CHW | AY11: =IF(LEFT(MID(C11,4,3),1)="E","ELC",IF(LEFT(MID(C11,4,3),1)="N","NGA",MID(C11,4,3))) -> COA
A12: BASE | B12: Stock | C12: CHWDST000 | D12: - | E12: - | F12: - | G12: 2019 | H12: - | I12: - | J12: - | K12: - | L12: 21.284269 | M12: 188.80293 | N12: 64.490099 | O12: 42.177166 | P12: 631.78891 | Q12: 487.00314 | R12: 31.706904 | S12: 5.6543705 | T12: 8.2331998 | U12: 993.05168 | V12: 39.602631 | W12: 37.932492 | X12: 85.170198 | Y12: 14.332357 | Z12: 13.943365 | AA12: 90.349913 | AB12: 102.3617 | AC12: 164.15102 | AD12: 252.06343 | AE12: 0 | AF12: 77.49459 | AG12: 2.6032478 | AH12: 81.55521 | AI12: 22.790238 | AJ12: 98.874733 | AK12: 0 | AL12: 11.356203 | AM12: 74.186423 | AN12: 269.83253 | AO12: - | AX12: =LEFT(C12,3) -> CHW | AY12: =IF(LEFT(MID(C12,4,3),1)="E","ELC",IF(LEFT(MID(C12,4,3),1)="N","NGA",MID(C12,4,3))) -> DST
A13: BASE | B13: Stock | C13: CHWELC000 | D13: - | E13: - | F13: - | G13: 2019 | H13: - | I13: - | J13: - | K13: - | L13: 87.091215 | M13: 53.689974 | N13: 28.445092 | O13: 88.865505 | P13: 0 | Q13: 636.69557 | R13: 203.64327 | S13: 92.410847 | T13: 114.41758 | U13: 319.29514 | V13: 108.75072 | W13: 307.22616 | X13: 143.84571 | Y13: 216.98399 | Z13: 116.54064 | AA13: 179.00666 | AB13: 223.19369 | AC13: 268.5188 | AD13: 255.4769 | AE13: 37.234849 | AF13: 58.545098 | AG13: 47.037626 | AH13: 253.70114 | AI13: 54.164169 | AJ13: 500.79852 | AK13: 200.48228 | AL13: 60.782255 | AM13: 177.14112 | AN13: 844.56441 | AO13: - | AX13: =LEFT(C13,3) -> CHW | AY13: =IF(LEFT(MID(C13,4,3),1)="E","ELC",IF(LEFT(MID(C13,4,3),1)="N","NGA",MID(C13,4,3))) -> ELC
... A72: BASE | B72: Stock | C72: RSHNHP000 | D72: - | E72: - | F72: - | G72: 2019 | H72: - | I72: - | J72: - | K72: - | L72: 0.007 | M72: 0 | N72: 0.001 | O72: 4.074 | P72: 68.746 | Q72: 0 | R72: 0.836 | S72: 0 | T72: 159.515 | U72: 0 | V72: 2.237 | W72: 2.299 | X72: 34.712 | Y72: 53.672 | Z72: 1.644 | AA72: 12.162 | AB72: 5.915 | AC72: 36.937 | AD72: 73.693 | AE72: 0 | AF72: 0 | AG72: 0.001 | AH72: 11.17 | AI72: 0.005 | AJ72: 17.983 | AK72: 0 | AL72: 0 | AM72: 74.178 | AN72: 6.135 | AO72: - | AX72: =LEFT(C72,3) -> RSH | AY72: =IF(LEFT(MID(C72,4,3),1)="E","ELC",IF(LEFT(MID(C72,4,3),1)="N","NGA",MID(C72,4,3))) -> NGA
AX73: =LEFT(C73,3) | AY73: =IF(LEFT(MID(C73,4,3),1)="E","ELC",IF(LEFT(MID(C73,4,3),1)="N","NGA",MID(C73,4,3)))
AX74: =LEFT(C74,3) | AY74: =IF(LEFT(MID(C74,4,3),1)="E","ELC",IF(LEFT(MID(C74,4,3),1)="N","NGA",MID(C74,4,3)))
AX75: =LEFT(C75,3) | AY75: =IF(LEFT(MID(C75,4,3),1)="E","ELC",IF(LEFT(MID(C75,4,3),1)="N","NGA",MID(C75,4,3)))
AX76: =LEFT(C76,3) | AY76: =IF(LEFT(MID(C76,4,3),1)="E","ELC",IF(LEFT(MID(C76,4,3),1)="N","NGA",MID(C76,4,3)))
AX77: =LEFT(C77,3) | AY77: =IF(LEFT(MID(C77,4,3),1)="E","ELC",IF(LEFT(MID(C77,4,3),1)="N","NGA",MID(C77,4,3)))
AX78: =LEFT(C78,3) | AY78: =IF(LEFT(MID(C78,4,3),1)="E","ELC",IF(LEFT(MID(C78,4,3),1)="N","NGA",MID(C78,4,3)))
AX79: =LEFT(C79,3) | AY79: =IF(LEFT(MID(C79,4,3),1)="E","ELC",IF(LEFT(MID(C79,4,3),1)="N","NGA",MID(C79,4,3)))
AX80: =LEFT(C80,3) | AY80: =IF(LEFT(MID(C80,4,3),1)="E","ELC",IF(LEFT(MID(C80,4,3),1)="N","NGA",MID(C80,4,3)))
AX81: =LEFT(C81,3) | AY81: =IF(LEFT(MID(C81,4,3),1)="E","ELC",IF(LEFT(MID(C81,4,3),1)="N","NGA",MID(C81,4,3)))
AX82: =LEFT(C82,3) | AY82: =IF(LEFT(MID(C82,4,3),1)="E","ELC",IF(LEFT(MID(C82,4,3),1)="N","NGA",MID(C82,4,3)))
AX83: =LEFT(C83,3) | AY83: =IF(LEFT(MID(C83,4,3),1)="E","ELC",IF(LEFT(MID(C83,4,3),1)="N","NGA",MID(C83,4,3)))
AX84: =LEFT(C84,3) | AY84: =IF(LEFT(MID(C84,4,3),1)="E","ELC",IF(LEFT(MID(C84,4,3),1)="N","NGA",MID(C84,4,3)))
... AX100: =LEFT(C100,3) | AY100: =IF(LEFT(MID(C100,4,3),1)="E","ELC",IF(LEFT(MID(C100,4,3),1)="N","NGA",MID(C100,4,3)))

Sheet RESCOM
B2: Demand | C2: Fuel | D2: =IF(BY_RESCOM!L$1="","*"&COLUMN(),BY_RESCOM!L$1) -> Africa_north | E2: =IF(BY_RESCOM!M$1="","*"&COLUMN(),BY_RESCOM!M$1) -> Africa_other | F2: =IF(BY_RESCOM!N$1="","*"&COLUMN(),BY_RESCOM!N$1) -> Arg-Chi | G2: =IF(BY_RESCOM!O$1="","*"&COLUMN(),BY_RESCOM!O$1) -> Asia_central | H2: =IF(BY_RESCOM!P$1="","*"&COLUMN(),BY_RESCOM!P$1) -> Asia_east | I2: =IF(BY_RESCOM!Q$1="","*"&COLUMN(),BY_RESCOM!Q$1) -> Asia_other | J2: =IF(BY_RESCOM!R$1="","*"&COLUMN(),BY_RESCOM!R$1) -> Australia_NZ | K2: =IF(BY_RESCOM!S$1="","*"&COLUMN(),BY_RESCOM!S$1) -> Brazil | ... AH2: =IF(BY_RESCOM!AP$1="","*"&COLUMN(),BY_RESCOM!AP$1) -> *34 | AJ2: ~TFM_FILL-R:w=BY_RESCOM; hcol=region | AR2: =B2 -> Demand | AS2: =C2 -> Fuel | AU2: =IF(BY_RESCOM!L$1="","*"&COLUMN(),BY_RESCOM!L$1) -> Africa_north | AV2: =IF(BY_RESCOM!M$1="","*"&COLUMN(),BY_RESCOM!M$1) -> Africa_other | AW2: =IF(BY_RESCOM!N$1="","*"&COLUMN(),BY_RESCOM!N$1) -> Arg-Chi | AX2: =IF(BY_RESCOM!O$1="","*"&COLUMN(),BY_RESCOM!O$1) -> Asia_central | AY2: =IF(BY_RESCOM!P$1="","*"&COLUMN(),BY_RESCOM!P$1) -> Asia_east | AZ2: =IF(BY_RESCOM!Q$1="","*"&COLUMN(),BY_RESCOM!Q$1) -> Asia_other | BA2: =IF(BY_RESCOM!R$1="","*"&COLUMN(),BY_RESCOM!R$1) -> Australia_NZ | BB2: =IF(BY_RESCOM!S$1="","*"&COLUMN(),BY_RESCOM!S$1) -> Brazil | ... BX2: =IF(BY_RESCOM!AO$1="","*"&COLUMN(),BY_RESCOM!AO$1) -> year2
B3: RCK | C3: BIO | D3: =IFERROR(SUMIFS(BY_RESCOM!L$2:L$100,BY_RESCOM!$AX$2:$AX$100,RESCOM!$B3,BY_RESCOM!$AY$2:$AY$100,RESCOM!$C3)/SUMIFS(BY_RESCOM!L$2:L$100,BY_RESCOM!$AX$2:$AX$100,RESCOM!$B3),"") -> 0.074811391 | E3: =IFERROR(SUMIFS(BY_RESCOM!M$2:M$100,BY_RESCOM!$AX$2:$AX$100,RESCOM!$B3,BY_RESCOM!$AY$2:$AY$100,RESCOM!$C3)/SUMIFS(BY_RESCOM!M$2:M$100,BY_RESCOM!$AX$2:$AX$100,RESCOM!$B3),"") -> 0.95594029 | F3: =IFERROR(SUMIFS(BY_RESCOM!N$2:N$100,BY_RESCOM!$AX$2:$AX$100,RESCOM!$B3,BY_RESCOM!$AY$2:$AY$100,RESCOM!$C3)/SUMIFS(BY_RESCOM!N$2:N$100,BY_RESCOM!$AX$2:$AX$100,RESCOM!$B3),"") -> 0.1023792 | G3: =IFERROR(SUMIFS(BY_RESCOM!O$2:O$100,BY_RESCOM!$AX$2:$AX$100,RESCOM!$B3,BY_RESCOM!$AY$2:$AY$100,RESCOM!$C3)/SUMIFS(BY_RESCOM!O$2:O$100,BY_RESCOM!$AX$2:$AX$100,RESCOM!$B3),"") -> 0.00052626543 | H3: =IFERROR(SUMIFS(BY_RESCOM!P$2:P$100,BY_RESCOM!$AX$2:$AX$100,RESCOM!$B3,BY_RESCOM!$AY$2:$AY$100,RESCOM!$C3)/SUMIFS(BY_RESCOM!P$2:P$100,BY_RESCOM!$AX$2:$AX$100,RESCOM!$B3),"") -> 0 | I3: =IFERROR(SUMIFS(BY_RESCOM!Q$2:Q$100,BY_RESCOM!$AX$2:$AX$100,RESCOM!$B3,BY_RESCOM!$AY$2:$AY$100,RESCOM!$C3)/SUMIFS(BY_RESCOM!Q$2:Q$100,BY_RESCOM!$AX$2:$AX$100,RESCOM!$B3),"") -> 0.55635932 | J3: =IFERROR(SUMIFS(BY_RESCOM!R$2:R$100,BY_RESCOM!$AX$2:$AX$100,RESCOM!$B3,BY_RESCOM!$AY$2:$AY$100,RESCOM!$C3)/SUMIFS(BY_RESCOM!R$2:R$100,BY_RESCOM!$AX$2:$AX$100,RESCOM!$B3),"") -> 0.0006940428 | K3: =IFERROR(SUMIFS(BY_RESCOM!S$2:S$100,BY_RESCOM!$AX$2:$AX$100,RESCOM!$B3,BY_RESCOM!$AY$2:$AY$100,RESCOM!$C3)/SUMIFS(BY_RESCOM!S$2:S$100,BY_RESCOM!$AX$2:$AX$100,RESCOM!$B3),"") -> 0.25654142 | ... AH3: =IFERROR(SUMIFS(BY_RESCOM!AP$2:AP$100,BY_RESCOM!$AX$2:$AX$100,RESCOM!$B3,BY_RESCOM!$AY$2:$AY$100,RESCOM!$C3)/SUMIFS(BY_RESCOM!AP$2:AP$100,BY_RESCOM!$AX$2:$AX$100,RESCOM!$B3),"") | AJ3: Scenario | AK3: Attribute | AL3: PSET_CO | AM3: AllRegions | AN3: Year | AR3: RCK | AS3: NGA | AU3: =SUMIFS(BY_RESCOM!L$2:L$100,BY_RESCOM!$AX$2:$AX$100,RESCOM!$AR3,BY_RESCOM!$AY$2:$AY$100,RESCOM!$AS3)/SUMIFS(BY_RESCOM!L$2:L$100,BY_RESCOM!$AX$2:$AX$100,RESCOM!$AR3) -> 0.30105438 | AV3: =SUMIFS(BY_RESCOM!M$2:M$100,BY_RESCOM!$AX$2:$AX$100,RESCOM!$AR3,BY_RESCOM!$AY$2:$AY$100,RESCOM!$AS3)/SUMIFS(BY_RESCOM!M$2:M$100,BY_RESCOM!$AX$2:$AX$100,RESCOM!$AR3) -> 0 | AW3: =SUMIFS(BY_RESCOM!N$2:N$100,BY_RESCOM!$AX$2:$AX$100,RESCOM!$AR3,BY_RESCOM!$AY$2:$AY$100,RESCOM!$AS3)/SUMIFS(BY_RESCOM!N$2:N$100,BY_RESCOM!$AX$2:$AX$100,RESCOM!$AR3) -> 0.54084962 | AX3: =SUMIFS(BY_RESCOM!O$2:O$100,BY_RESCOM!$AX$2:$AX$100,RESCOM!$AR3,BY_RESCOM!$AY$2:$AY$100,RESCOM!$AS3)/SUMIFS(BY_RESCOM!O$2:O$100,BY_RESCOM!$AX$2:$AX$100,RESCOM!$AR3) -> 0.5911715 | AY3: =SUMIFS(BY_RESCOM!P$2:P$100,BY_RESCOM!$AX$2:$AX$100,RESCOM!$AR3,BY_RESCOM!$AY$2:$AY$100,RESCOM!$AS3)/SUMIFS(BY_RESCOM!P$2:P$100,BY_RESCOM!$AX$2:$AX$100,RESCOM!$AR3) -> 0.45181388 | AZ3: =SUMIFS(BY_RESCOM!Q$2:Q$100,BY_RESCOM!$AX$2:$AX$100,RESCOM!$AR3,BY_RESCOM!$AY$2:$AY$100,RESCOM!$AS3)/SUMIFS(BY_RESCOM!Q$2:Q$100,BY_RESCOM!$AX$2:$AX$100,RESCOM!$AR3) -> 0.17544063 | BA3: =SUMIFS(BY_RESCOM!R$2:R$100,BY_RESCOM!$AX$2:$AX$100,RESCOM!$AR3,BY_RESCOM!$AY$2:$AY$100,RESCOM!$AS3)/SUMIFS(BY_RESCOM!R$2:R$100,BY_RESCOM!$AX$2:$AX$100,RESCOM!$AR3) -> 0.22388664 | BB3: =SUMIFS(BY_RESCOM!S$2:S$100,BY_RESCOM!$AX$2:$AX$100,RESCOM!$AR3,BY_RESCOM!$AY$2:$AY$100,RESCOM!$AS3)/SUMIFS(BY_RESCOM!S$2:S$100,BY_RESCOM!$AX$2:$AX$100,RESCOM!$AR3) -> 0.017461619 | ... BX3: =SUMIFS(BY_RESCOM!AO$2:AO$100,BY_RESCOM!$AX$2:$AX$100,RESCOM!$AR3,BY_RESCOM!$AY$2:$AY$100,RESCOM!$AS3)/SUMIFS(BY_RESCOM!AO$2:AO$100,BY_RESCOM!$AX$2:$AX$100,RESCOM!$AR3) -> #DIV/0!
B4: CCK | C4: BIO | D4: =IFERROR(SUMIFS(BY_RESCOM!L$2:L$100,BY_RESCOM!$AX$2:$AX$100,RESCOM!$B4,BY_RESCOM!$AY$2:$AY$100,RESCOM!$C4)/SUMIFS(BY_RESCOM!L$2:L$100,BY_RESCOM!$AX$2:$AX$100,RESCOM!$B4),"") -> 0.15766553 | E4: =IFERROR(SUMIFS(BY_RESCOM!M$2:M$100,BY_RESCOM!$AX$2:$AX$100,RESCOM!$B4,BY_RESCOM!$AY$2:$AY$100,RESCOM!$C4)/SUMIFS(BY_RESCOM!M$2:M$100,BY_RESCOM!$AX$2:$AX$100,RESCOM!$B4),"") -> 0.76449968 | F4: =IFERROR(SUMIFS(BY_RESCOM!N$2:N$100,BY_RESCOM!$AX$2:$AX$100,RESCOM!$B4,BY_RESCOM!$AY$2:$AY$100,RESCOM!$C4)/SUMIFS(BY_RESCOM!N$2:N$100,BY_RESCOM!$AX$2:$AX$100,RESCOM!$B4),"") -> 0.018337902 | G4: =IFERROR(SUMIFS(BY_RESCOM!O$2:O$100,BY_RESCOM!$AX$2:$AX$100,RESCOM!$B4,BY_RESCOM!$AY$2:$AY$100,RESCOM!$C4)/SUMIFS(BY_RESCOM!O$2:O$100,BY_RESCOM!$AX$2:$AX$100,RESCOM!$B4),"") -> 0 | H4: =IFERROR(SUMIFS(BY_RESCOM!P$2:P$100,BY_RESCOM!$AX$2:$AX$100,RESCOM!$B4,BY_RESCOM!$AY$2:$AY$100,RESCOM!$C4)/SUMIFS(BY_RESCOM!P$2:P$100,BY_RESCOM!$AX$2:$AX$100,RESCOM!$B4),"") -> 0 | I4: =IFERROR(SUMIFS(BY_RESCOM!Q$2:Q$100,BY_RESCOM!$AX$2:$AX$100,RESCOM!$B4,BY_RESCOM!$AY$2:$AY$100,RESCOM!$C4)/SUMIFS(BY_RESCOM!Q$2:Q$100,BY_RESCOM!$AX$2:$AX$100,RESCOM!$B4),"") -> 0.047151453 | J4: =IFERROR(SUMIFS(BY_RESCOM!R$2:R$100,BY_RESCOM!$AX$2:$AX$100,RESCOM!$B4,BY_RESCOM!$AY$2:$AY$100,RESCOM!$C4)/SUMIFS(BY_RESCOM!R$2:R$100,BY_RESCOM!$AX$2:$AX$100,RESCOM!$B4),"") -> 0 | K4: =IFERROR(SUMIFS(BY_RESCOM!S$2:S$100,BY_RESCOM!$AX$2:$AX$100,RESCOM!$B4,BY_RESCOM!$AY$2:$AY$100,RESCOM!$C4)/SUMIFS(BY_RESCOM!S$2:S$100,BY_RESCOM!$AX$2:$AX$100,RESCOM!$B4),"") -> 0.029864989 | ... AH4: =IFERROR(SUMIFS(BY_RESCOM!AP$2:AP$100,BY_RESCOM!$AX$2:$AX$100,RESCOM!$B4,BY_RESCOM!$AY$2:$AY$100,RESCOM!$C4)/SUMIFS(BY_RESCOM!AP$2:AP$100,BY_RESCOM!$AX$2:$AX$100,RESCOM!$B4),"") | AK4: Stock | AL4: ?CK,CLA,RLI,?SH,?HW | AM4: *1 | AN4: 2019 | AR4: CCK | AS4: NGA | AU4: =SUMIFS(BY_RESCOM!L$2:L$100,BY_RESCOM!$AX$2:$AX$100,RESCOM!$AR4,BY_RESCOM!$AY$2:$AY$100,RESCOM!$AS4)/SUMIFS(BY_RESCOM!L$2:L$100,BY_RESCOM!$AX$2:$AX$100,RESCOM!$AR4) -> 0.38297905 | AV4: =SUMIFS(BY_RESCOM!M$2:M$100,BY_RESCOM!$AX$2:$AX$100,RESCOM!$AR4,BY_RESCOM!$AY$2:$AY$100,RESCOM!$AS4)/SUMIFS(BY_RESCOM!M$2:M$100,BY_RESCOM!$AX$2:$AX$100,RESCOM!$AR4) -> 0.00051223265 | AW4: =SUMIFS(BY_RESCOM!N$2:N$100,BY_RESCOM!$AX$2:$AX$100,RESCOM!$AR4,BY_RESCOM!$AY$2:$AY$100,RESCOM!$AS4)/SUMIFS(BY_RESCOM!N$2:N$100,BY_RESCOM!$AX$2:$AX$100,RESCOM!$AR4) -> 0.55327571 | AX4: =SUMIFS(BY_RESCOM!O$2:O$100,BY_RESCOM!$AX$2:$AX$100,RESCOM!$AR4,BY_RESCOM!$AY$2:$AY$100,RESCOM!$AS4)/SUMIFS(BY_RESCOM!O$2:O$100,BY_RESCOM!$AX$2:$AX$100,RESCOM!$AR4) -> 0.95063443 | AY4: =SUMIFS(BY_RESCOM!P$2:P$100,BY_RESCOM!$AX$2:$AX$100,RESCOM!$AR4,BY_RESCOM!$AY$2:$AY$100,RESCOM!$AS4)/SUMIFS(BY_RESCOM!P$2:P$100,BY_RESCOM!$AX$2:$AX$100,RESCOM!$AR4) -> 0.99835963 | AZ4: =SUMIFS(BY_RESCOM!Q$2:Q$100,BY_RESCOM!$AX$2:$AX$100,RESCOM!$AR4,BY_RESCOM!$AY$2:$AY$100,RESCOM!$AS4)/SUMIFS(BY_RESCOM!Q$2:Q$100,BY_RESCOM!$AX$2:$AX$100,RESCOM!$AR4) -> 0.15160696 | BA4: =SUMIFS(BY_RESCOM!R$2:R$100,BY_RESCOM!$AX$2:$AX$100,RESCOM!$AR4,BY_RESCOM!$AY$2:$AY$100,RESCOM!$AS4)/SUMIFS(BY_RESCOM!R$2:R$100,BY_RESCOM!$AX$2:$AX$100,RESCOM!$AR4) -> 0.24135765 | BB4: =SUMIFS(BY_RESCOM!S$2:S$100,BY_RESCOM!$AX$2:$AX$100,RESCOM!$AR4,BY_RESCOM!$AY$2:$AY$100,RESCOM!$AS4)/SUMIFS(BY_RESCOM!S$2:S$100,BY_RESCOM!$AX$2:$AX$100,RESCOM!$AR4) -> 0.097663013 | ... BX4: =SUMIFS(BY_RESCOM!AO$2:AO$100,BY_RESCOM!$AX$2:$AX$100,RESCOM!$AR4,BY_RESCOM!$AY$2:$AY$100,RESCOM!$AS4)/SUMIFS(BY_RESCOM!AO$2:AO$100,BY_RESCOM!$AX$2:$AX$100,RESCOM!$AR4) -> #DIV/0!
B5: RHW | C5: BIO | D5: =IFERROR(SUMIFS(BY_RESCOM!L$2:L$100,BY_RESCOM!$AX$2:$AX$100,RESCOM!$B5,BY_RESCOM!$AY$2:$AY$100,RESCOM!$C5)/SUMIFS(BY_RESCOM!L$2:L$100,BY_RESCOM!$AX$2:$AX$100,RESCOM!$B5),"") -> 0.01531739 | E5: =IFERROR(SUMIFS(BY_RESCOM!M$2:M$100,BY_RESCOM!$AX$2:$AX$100,RESCOM!$B5,BY_RESCOM!$AY$2:$AY$100,RESCOM!$C5)/SUMIFS(BY_RESCOM!M$2:M$100,BY_RESCOM!$AX$2:$AX$100,RESCOM!$B5),"") -> 0.93349454 | F5: =IFERROR(SUMIFS(BY_RESCOM!N$2:N$100,BY_RESCOM!$AX$2:$AX$100,RESCOM!$B5,BY_RESCOM!$AY$2:$AY$100,RESCOM!$C5)/SUMIFS(BY_RESCOM!N$2:N$100,BY_RESCOM!$AX$2:$AX$100,RESCOM!$B5),"") -> 0.0069317265 | G5: =IFERROR(SUMIFS(BY_RESCOM!O$2:O$100,BY_RESCOM!$AX$2:$AX$100,RESCOM!$B5,BY_RESCOM!$AY$2:$AY$100,RESCOM!$C5)/SUMIFS(BY_RESCOM!O$2:O$100,BY_RESCOM!$AX$2:$AX$100,RESCOM!$B5),"") -> 0.00094790157 | H5: =IFERROR(SUMIFS(BY_RESCOM!P$2:P$100,BY_RESCOM!$AX$2:$AX$100,RESCOM!$B5,BY_RESCOM!$AY$2:$AY$100,RESCOM!$C5)/SUMIFS(BY_RESCOM!P$2:P$100,BY_RESCOM!$AX$2:$AX$100,RESCOM!$B5),"") -> 0 | I5: =IFERROR(SUMIFS(BY_RESCOM!Q$2:Q$100,BY_RESCOM!$AX$2:$AX$100,RESCOM!$B5,BY_RESCOM!$AY$2:$AY$100,RESCOM!$C5)/SUMIFS(BY_RESCOM!Q$2:Q$100,BY_RESCOM!$AX$2:$AX$100,RESCOM!$B5),"") -> 0 | J5: =IFERROR(SUMIFS(BY_RESCOM!R$2:R$100,BY_RESCOM!$AX$2:$AX$100,RESCOM!$B5,BY_RESCOM!$AY$2:$AY$100,RESCOM!$C5)/SUMIFS(BY_RESCOM!R$2:R$100,BY_RESCOM!$AX$2:$AX$100,RESCOM!$B5),"") -> 0.00028406047 | K5: =IFERROR(SUMIFS(BY_RESCOM!S$2:S$100,BY_RESCOM!$AX$2:$AX$100,RESCOM!$B5,BY_RESCOM!$AY$2:$AY$100,RESCOM!$C5)/SUMIFS(BY_RESCOM!S$2:S$100,BY_RESCOM!$AX$2:$AX$100,RESCOM!$B5),"") -> 0.054460589 | ... AH5: =IFERROR(SUMIFS(BY_RESCOM!AP$2:AP$100,BY_RESCOM!$AX$2:$AX$100,RESCOM!$B5,BY_RESCOM!$AY$2:$AY$100,RESCOM!$C5)/SUMIFS(BY_RESCOM!AP$2:AP$100,BY_RESCOM!$AX$2:$AX$100,RESCOM!$B5),"")
B6: RCK | C6: STH | D6: =IFERROR(SUMIFS(BY_RESCOM!L$2:L$100,BY_RESCOM!$AX$2:$AX$100,RESCOM!$B6,BY_RESCOM!$AY$2:$AY$100,RESCOM!$C6)/SUMIFS(BY_RESCOM!L$2:L$100,BY_RESCOM!$AX$2:$AX$100,RESCOM!$B6),"") -> 0 | E6: =IFERROR(SUMIFS(BY_RESCOM!M$2:M$100,BY_RESCOM!$AX$2:$AX$100,RESCOM!$B6,BY_RESCOM!$AY$2:$AY$100,RESCOM!$C6)/SUMIFS(BY_RESCOM!M$2:M$100,BY_RESCOM!$AX$2:$AX$100,RESCOM!$B6),"") -> 0 | F6: =IFERROR(SUMIFS(BY_RESCOM!N$2:N$100,BY_RESCOM!$AX$2:$AX$100,RESCOM!$B6,BY_RESCOM!$AY$2:$AY$100,RESCOM!$C6)/SUMIFS(BY_RESCOM!N$2:N$100,BY_RESCOM!$AX$2:$AX$100,RESCOM!$B6),"") -> 0 | G6: =IFERROR(SUMIFS(BY_RESCOM!O$2:O$100,BY_RESCOM!$AX$2:$AX$100,RESCOM!$B6,BY_RESCOM!$AY$2:$AY$100,RESCOM!$C6)/SUMIFS(BY_RESCOM!O$2:O$100,BY_RESCOM!$AX$2:$AX$100,RESCOM!$B6),"") -> 0 | H6: =IFERROR(SUMIFS(BY_RESCOM!P$2:P$100,BY_RESCOM!$AX$2:$AX$100,RESCOM!$B6,BY_RESCOM!$AY$2:$AY$100,RESCOM!$C6)/SUMIFS(BY_RESCOM!P$2:P$100,BY_RESCOM!$AX$2:$AX$100,RESCOM!$B6),"") -> 0 | I6: =IFERROR(SUMIFS(BY_RESCOM!Q$2:Q$100,BY_RESCOM!$AX$2:$AX$100,RESCOM!$B6,BY_RESCOM!$AY$2:$AY$100,RESCOM!$C6)/SUMIFS(BY_RESCOM!Q$2:Q$100,BY_RESCOM!$AX$2:$AX$100,RESCOM!$B6),"") -> 0 | J6: =IFERROR(SUMIFS(BY_RESCOM!R$2:R$100,BY_RESCOM!$AX$2:$AX$100,RESCOM!$B6,BY_RESCOM!$AY$2:$AY$100,RESCOM!$C6)/SUMIFS(BY_RESCOM!R$2:R$100,BY_RESCOM!$AX$2:$AX$100,RESCOM!$B6),"") -> 0 | K6: =IFERROR(SUMIFS(BY_RESCOM!S$2:S$100,BY_RESCOM!$AX$2:$AX$100,RESCOM!$B6,BY_RESCOM!$AY$2:$AY$100,RESCOM!$C6)/SUMIFS(BY_RESCOM!S$2:S$100,BY_RESCOM!$AX$2:$AX$100,RESCOM!$B6),"") -> 0 | ... AH6: =IFERROR(SUMIFS(BY_RESCOM!AP$2:AP$100,BY_RESCOM!$AX$2:$AX$100,RESCOM!$B6,BY_RESCOM!$AY$2:$AY$100,RESCOM!$C6)/SUMIFS(BY_RESCOM!AP$2:AP$100,BY_RESCOM!$AX$2:$AX$100,RESCOM!$B6),"")
B7: CCK | C7: STH | D7: =IFERROR(SUMIFS(BY_RESCOM!L$2:L$100,BY_RESCOM!$AX$2:$AX$100,RESCOM!$B7,BY_RESCOM!$AY$2:$AY$100,RESCOM!$C7)/SUMIFS(BY_RESCOM!L$2:L$100,BY_RESCOM!$AX$2:$AX$100,RESCOM!$B7),"") -> 0 | E7: =IFERROR(SUMIFS(BY_RESCOM!M$2:M$100,BY_RESCOM!$AX$2:$AX$100,RESCOM!$B7,BY_RESCOM!$AY$2:$AY$100,RESCOM!$C7)/SUMIFS(BY_RESCOM!M$2:M$100,BY_RESCOM!$AX$2:$AX$100,RESCOM!$B7),"") -> 0 | F7: =IFERROR(SUMIFS(BY_RESCOM!N$2:N$100,BY_RESCOM!$AX$2:$AX$100,RESCOM!$B7,BY_RESCOM!$AY$2:$AY$100,RESCOM!$C7)/SUMIFS(BY_RESCOM!N$2:N$100,BY_RESCOM!$AX$2:$AX$100,RESCOM!$B7),"") -> 0 | G7: =IFERROR(SUMIFS(BY_RESCOM!O$2:O$100,BY_RESCOM!$AX$2:$AX$100,RESCOM!$B7,BY_RESCOM!$AY$2:$AY$100,RESCOM!$C7)/SUMIFS(BY_RESCOM!O$2:O$100,BY_RESCOM!$AX$2:$AX$100,RESCOM!$B7),"") -> 0 | H7: =IFERROR(SUMIFS(BY_RESCOM!P$2:P$100,BY_RESCOM!$AX$2:$AX$100,RESCOM!$B7,BY_RESCOM!$AY$2:$AY$100,RESCOM!$C7)/SUMIFS(BY_RESCOM!P$2:P$100,BY_RESCOM!$AX$2:$AX$100,RESCOM!$B7),"") -> 0 | I7: =IFERROR(SUMIFS(BY_RESCOM!Q$2:Q$100,BY_RESCOM!$AX$2:$AX$100,RESCOM!$B7,BY_RESCOM!$AY$2:$AY$100,RESCOM!$C7)/SUMIFS(BY_RESCOM!Q$2:Q$100,BY_RESCOM!$AX$2:$AX$100,RESCOM!$B7),"") -> 0 | J7: =IFERROR(SUMIFS(BY_RESCOM!R$2:R$100,BY_RESCOM!$AX$2:$AX$100,RESCOM!$B7,BY_RESCOM!$AY$2:$AY$100,RESCOM!$C7)/SUMIFS(BY_RESCOM!R$2:R$100,BY_RESCOM!$AX$2:$AX$100,RESCOM!$B7),"") -> 0 | K7: =IFERROR(SUMIFS(BY_RESCOM!S$2:S$100,BY_RESCOM!$AX$2:$AX$100,RESCOM!$B7,BY_RESCOM!$AY$2:$AY$100,RESCOM!$C7)/SUMIFS(BY_RESCOM!S$2:S$100,BY_RESCOM!$AX$2:$AX$100,RESCOM!$B7),"") -> 0 | ... AH7: =IFERROR(SUMIFS(BY_RESCOM!AP$2:AP$100,BY_RESCOM!$AX$2:$AX$100,RESCOM!$B7,BY_RESCOM!$AY$2:$AY$100,RESCOM!$C7)/SUMIFS(BY_RESCOM!AP$2:AP$100,BY_RESCOM!$AX$2:$AX$100,RESCOM!$B7),"") | AJ7: ~TFM_INS-TS: limtype=UP;attrib_cond=-RESID;top_check=OUT | AQ7: ~TFM_INS: attribute=PRC_MARK
B8: RLI | C8: KER | D8: =IFERROR(SUMIFS(BY_RESCOM!L$2:L$100,BY_RESCOM!$AX$2:$AX$100,RESCOM!$B8,BY_RESCOM!$AY$2:$AY$100,RESCOM!$C8)/SUMIFS(BY_RESCOM!L$2:L$100,BY_RESCOM!$AX$2:$AX$100,RESCOM!$B8),"") -> 0.00034082459 | E8: =IFERROR(SUMIFS(BY_RESCOM!M$2:M$100,BY_RESCOM!$AX$2:$AX$100,RESCOM!$B8,BY_RESCOM!$AY$2:$AY$100,RESCOM!$C8)/SUMIFS(BY_RESCOM!M$2:M$100,BY_RESCOM!$AX$2:$AX$100,RESCOM!$B8),"") -> 0.005621582 | F8: =IFERROR(SUMIFS(BY_RESCOM!N$2:N$100,BY_RESCOM!$AX$2:$AX$100,RESCOM!$B8,BY_RESCOM!$AY$2:$AY$100,RESCOM!$C8)/SUMIFS(BY_RESCOM!N$2:N$100,BY_RESCOM!$AX$2:$AX$100,RESCOM!$B8),"") -> 0 | G8: =IFERROR(SUMIFS(BY_RESCOM!O$2:O$100,BY_RESCOM!$AX$2:$AX$100,RESCOM!$B8,BY_RESCOM!$AY$2:$AY$100,RESCOM!$C8)/SUMIFS(BY_RESCOM!O$2:O$100,BY_RESCOM!$AX$2:$AX$100,RESCOM!$B8),"") -> 0 | H8: =IFERROR(SUMIFS(BY_RESCOM!P$2:P$100,BY_RESCOM!$AX$2:$AX$100,RESCOM!$B8,BY_RESCOM!$AY$2:$AY$100,RESCOM!$C8)/SUMIFS(BY_RESCOM!P$2:P$100,BY_RESCOM!$AX$2:$AX$100,RESCOM!$B8),"") | I8: =IFERROR(SUMIFS(BY_RESCOM!Q$2:Q$100,BY_RESCOM!$AX$2:$AX$100,RESCOM!$B8,BY_RESCOM!$AY$2:$AY$100,RESCOM!$C8)/SUMIFS(BY_RESCOM!Q$2:Q$100,BY_RESCOM!$AX$2:$AX$100,RESCOM!$B8),"") -> 0.00027400788 | J8: =IFERROR(SUMIFS(BY_RESCOM!R$2:R$100,BY_RESCOM!$AX$2:$AX$100,RESCOM!$B8,BY_RESCOM!$AY$2:$AY$100,RESCOM!$C8)/SUMIFS(BY_RESCOM!R$2:R$100,BY_RESCOM!$AX$2:$AX$100,RESCOM!$B8),"") -> 0 | K8: =IFERROR(SUMIFS(BY_RESCOM!S$2:S$100,BY_RESCOM!$AX$2:$AX$100,RESCOM!$B8,BY_RESCOM!$AY$2:$AY$100,RESCOM!$C8)/SUMIFS(BY_RESCOM!S$2:S$100,BY_RESCOM!$AX$2:$AX$100,RESCOM!$B8),"") -> 0 | ... AH8: =IFERROR(SUMIFS(BY_RESCOM!AP$2:AP$100,BY_RESCOM!$AX$2:$AX$100,RESCOM!$B8,BY_RESCOM!$AY$2:$AY$100,RESCOM!$C8)/SUMIFS(BY_RESCOM!AP$2:AP$100,BY_RESCOM!$AX$2:$AX$100,RESCOM!$B8),"") | AJ8: attribute | AK8: PSET_SET | AL8: PSET_CO | AM8: CSET_CN | AN8: 2025 | AO8: 0 | AQ8: Year | AR8: PSET_CO | AS8: PSET_CI | AT8: allregions | AU8: =IF(BY_RESCOM!L$1="","*"&COLUMN(),BY_RESCOM!L$1) -> Africa_north | AV8: =IF(BY_RESCOM!M$1="","*"&COLUMN(),BY_RESCOM!M$1) -> Africa_other | AW8: =IF(BY_RESCOM!N$1="","*"&COLUMN(),BY_RESCOM!N$1) -> Arg-Chi | AX8: =IF(BY_RESCOM!O$1="","*"&COLUMN(),BY_RESCOM!O$1) -> Asia_central | AY8: =IF(BY_RESCOM!P$1="","*"&COLUMN(),BY_RESCOM!P$1) -> Asia_east | AZ8: =IF(BY_RESCOM!Q$1="","*"&COLUMN(),BY_RESCOM!Q$1) -> Asia_other | BA8: =IF(BY_RESCOM!R$1="","*"&COLUMN(),BY_RESCOM!R$1) -> Australia_NZ | BB8: =IF(BY_RESCOM!S$1="","*"&COLUMN(),BY_RESCOM!S$1) -> Brazil | ... BX8: =IF(BY_RESCOM!AO$1="","*"&COLUMN(),BY_RESCOM!AO$1) -> year2 | BY8: CSET_CN | BZ8: LimType | CA8: PSET_PN | CB8: Other_indexes
B9: CLA | C9: ICE | D9: =IFERROR(SUMIFS(BY_RESCOM!L$2:L$100,BY_RESCOM!$AX$2:$AX$100,RESCOM!$B9,BY_RESCOM!$AY$2:$AY$100,RESCOM!$C9)/SUMIFS(BY_RESCOM!L$2:L$100,BY_RESCOM!$AX$2:$AX$100,RESCOM!$B9),"") -> 0.19417476 | E9: =IFERROR(SUMIFS(BY_RESCOM!M$2:M$100,BY_RESCOM!$AX$2:$AX$100,RESCOM!$B9,BY_RESCOM!$AY$2:$AY$100,RESCOM!$C9)/SUMIFS(BY_RESCOM!M$2:M$100,BY_RESCOM!$AX$2:$AX$100,RESCOM!$B9),"") -> 0.19359294 | F9: =IFERROR(SUMIFS(BY_RESCOM!N$2:N$100,BY_RESCOM!$AX$2:$AX$100,RESCOM!$B9,BY_RESCOM!$AY$2:$AY$100,RESCOM!$C9)/SUMIFS(BY_RESCOM!N$2:N$100,BY_RESCOM!$AX$2:$AX$100,RESCOM!$B9),"") -> 0.028899558 | G9: =IFERROR(SUMIFS(BY_RESCOM!O$2:O$100,BY_RESCOM!$AX$2:$AX$100,RESCOM!$B9,BY_RESCOM!$AY$2:$AY$100,RESCOM!$C9)/SUMIFS(BY_RESCOM!O$2:O$100,BY_RESCOM!$AX$2:$AX$100,RESCOM!$B9),"") -> 0.19417195 | H9: =IFERROR(SUMIFS(BY_RESCOM!P$2:P$100,BY_RESCOM!$AX$2:$AX$100,RESCOM!$B9,BY_RESCOM!$AY$2:$AY$100,RESCOM!$C9)/SUMIFS(BY_RESCOM!P$2:P$100,BY_RESCOM!$AX$2:$AX$100,RESCOM!$B9),"") -> 0.16973751 | I9: =IFERROR(SUMIFS(BY_RESCOM!Q$2:Q$100,BY_RESCOM!$AX$2:$AX$100,RESCOM!$B9,BY_RESCOM!$AY$2:$AY$100,RESCOM!$C9)/SUMIFS(BY_RESCOM!Q$2:Q$100,BY_RESCOM!$AX$2:$AX$100,RESCOM!$B9),"") -> 0.4622743 | J9: =IFERROR(SUMIFS(BY_RESCOM!R$2:R$100,BY_RESCOM!$AX$2:$AX$100,RESCOM!$B9,BY_RESCOM!$AY$2:$AY$100,RESCOM!$C9)/SUMIFS(BY_RESCOM!R$2:R$100,BY_RESCOM!$AX$2:$AX$100,RESCOM!$B9),"") -> 0.13289037 | K9: =IFERROR(SUMIFS(BY_RESCOM!S$2:S$100,BY_RESCOM!$AX$2:$AX$100,RESCOM!$B9,BY_RESCOM!$AY$2:$AY$100,RESCOM!$C9)/SUMIFS(BY_RESCOM!S$2:S$100,BY_RESCOM!$AX$2:$AX$100,RESCOM!$B9),"") -> 0.028901734 | ... AH9: =IFERROR(SUMIFS(BY_RESCOM!AP$2:AP$100,BY_RESCOM!$AX$2:$AX$100,RESCOM!$B9,BY_RESCOM!$AY$2:$AY$100,RESCOM!$C9)/SUMIFS(BY_RESCOM!AP$2:AP$100,BY_RESCOM!$AX$2:$AX$100,RESCOM!$B9),"") | AJ9: FLO_MARK | AK9: DMD | AL9: CLA,CRF | AM9: =AL9 -> CLA,CRF | AN9: 0.25 | AO9: 5 | AQ9: 2020 | AR9: =AR3 -> RCK | AS9: ="*"&AS3 -> *NGA | AU9: =AU3 -> 0.30105438 | AV9: =AV3 -> 0 | AW9: =AW3 -> 0.54084962 | AX9: =AX3 -> 0.5911715 | AY9: =AY3 -> 0.45181388 | AZ9: =AZ3 -> 0.17544063 | BA9: =BA3 -> 0.22388664 | BB9: =BB3 -> 0.017461619 | ... BX9: =BX3 -> #DIV/0! | BY9: =AR9 -> RCK | BZ9: UP | CB9: ="Techs_"&AR9&AS3 -> Techs_RCKNGA
B10: RLI | C10: ICE | D10: =IFERROR(SUMIFS(BY_RESCOM!L$2:L$100,BY_RESCOM!$AX$2:$AX$100,RESCOM!$B10,BY_RESCOM!$AY$2:$AY$100,RESCOM!$C10)/SUMIFS(BY_RESCOM!L$2:L$100,BY_RESCOM!$AX$2:$AX$100,RESCOM!$B10),"") -> 0.50937784 | E10: =IFERROR(SUMIFS(BY_RESCOM!M$2:M$100,BY_RESCOM!$AX$2:$AX$100,RESCOM!$B10,BY_RESCOM!$AY$2:$AY$100,RESCOM!$C10)/SUMIFS(BY_RESCOM!M$2:M$100,BY_RESCOM!$AX$2:$AX$100,RESCOM!$B10),"") -> 0.5066909 | F10: =IFERROR(SUMIFS(BY_RESCOM!N$2:N$100,BY_RESCOM!$AX$2:$AX$100,RESCOM!$B10,BY_RESCOM!$AY$2:$AY$100,RESCOM!$C10)/SUMIFS(BY_RESCOM!N$2:N$100,BY_RESCOM!$AX$2:$AX$100,RESCOM!$B10),"") -> 0.48287846 | G10: =IFERROR(SUMIFS(BY_RESCOM!O$2:O$100,BY_RESCOM!$AX$2:$AX$100,RESCOM!$B10,BY_RESCOM!$AY$2:$AY$100,RESCOM!$C10)/SUMIFS(BY_RESCOM!O$2:O$100,BY_RESCOM!$AX$2:$AX$100,RESCOM!$B10),"") -> 0.43603533 | H10: =IFERROR(SUMIFS(BY_RESCOM!P$2:P$100,BY_RESCOM!$AX$2:$AX$100,RESCOM!$B10,BY_RESCOM!$AY$2:$AY$100,RESCOM!$C10)/SUMIFS(BY_RESCOM!P$2:P$100,BY_RESCOM!$AX$2:$AX$100,RESCOM!$B10),"") | I10: =IFERROR(SUMIFS(BY_RESCOM!Q$2:Q$100,BY_RESCOM!$AX$2:$AX$100,RESCOM!$B10,BY_RESCOM!$AY$2:$AY$100,RESCOM!$C10)/SUMIFS(BY_RESCOM!Q$2:Q$100,BY_RESCOM!$AX$2:$AX$100,RESCOM!$B10),"") -> 0.43592672 | J10: =IFERROR(SUMIFS(BY_RESCOM!R$2:R$100,BY_RESCOM!$AX$2:$AX$100,RESCOM!$B10,BY_RESCOM!$AY$2:$AY$100,RESCOM!$C10)/SUMIFS(BY_RESCOM!R$2:R$100,BY_RESCOM!$AX$2:$AX$100,RESCOM!$B10),"") -> 0.19762613 | K10: =IFERROR(SUMIFS(BY_RESCOM!S$2:S$100,BY_RESCOM!$AX$2:$AX$100,RESCOM!$B10,BY_RESCOM!$AY$2:$AY$100,RESCOM!$C10)/SUMIFS(BY_RESCOM!S$2:S$100,BY_RESCOM!$AX$2:$AX$100,RESCOM!$B10),"") -> 0.48288587 | ... AH10: =IFERROR(SUMIFS(BY_RESCOM!AP$2:AP$100,BY_RESCOM!$AX$2:$AX$100,RESCOM!$B10,BY_RESCOM!$AY$2:$AY$100,RESCOM!$C10)/SUMIFS(BY_RESCOM!AP$2:AP$100,BY_RESCOM!$AX$2:$AX$100,RESCOM!$B10),"") | AJ10: FLO_MARK | AK10: DMD | AL10: RLI,RRF,RSH | AM10: =AL10 -> RLI,RRF,RSH | AN10: 0.25 | AO10: 5 | AQ10: 2020 | AR10: =AR4 -> CCK | AS10: ="*"&AS4 -> *NGA | AU10: =AU4 -> 0.38297905 | AV10: =AV4 -> 0.00051223265 | AW10: =AW4 -> 0.55327571 | AX10: =AX4 -> 0.95063443 | AY10: =AY4 -> 0.99835963 | AZ10: =AZ4 -> 0.15160696 | BA10: =BA4 -> 0.24135765 | BB10: =BB4 -> 0.097663013 | ... BX10: =BX4 -> #DIV/0! | BY10: =AR10 -> CCK | BZ10: UP | CB10: ="Techs_"&AR10&AS4 -> Techs_CCKNGA
B11: RSH | C11: COA | D11: =IFERROR(SUMIFS(BY_RESCOM!L$2:L$100,BY_RESCOM!$AX$2:$AX$100,RESCOM!$B11,BY_RESCOM!$AY$2:$AY$100,RESCOM!$C11)/SUMIFS(BY_RESCOM!L$2:L$100,BY_RESCOM!$AX$2:$AX$100,RESCOM!$B11),"") -> 0 | E11: =IFERROR(SUMIFS(BY_RESCOM!M$2:M$100,BY_RESCOM!$AX$2:$AX$100,RESCOM!$B11,BY_RESCOM!$AY$2:$AY$100,RESCOM!$C11)/SUMIFS(BY_RESCOM!M$2:M$100,BY_RESCOM!$AX$2:$AX$100,RESCOM!$B11),"") -> 0.023927979 | F11: =IFERROR(SUMIFS(BY_RESCOM!N$2:N$100,BY_RESCOM!$AX$2:$AX$100,RESCOM!$B11,BY_RESCOM!$AY$2:$AY$100,RESCOM!$C11)/SUMIFS(BY_RESCOM!N$2:N$100,BY_RESCOM!$AX$2:$AX$100,RESCOM!$B11),"") -> 0 | G11: =IFERROR(SUMIFS(BY_RESCOM!O$2:O$100,BY_RESCOM!$AX$2:$AX$100,RESCOM!$B11,BY_RESCOM!$AY$2:$AY$100,RESCOM!$C11)/SUMIFS(BY_RESCOM!O$2:O$100,BY_RESCOM!$AX$2:$AX$100,RESCOM!$B11),"") -> 0.1660035 | H11: =IFERROR(SUMIFS(BY_RESCOM!P$2:P$100,BY_RESCOM!$AX$2:$AX$100,RESCOM!$B11,BY_RESCOM!$AY$2:$AY$100,RESCOM!$C11)/SUMIFS(BY_RESCOM!P$2:P$100,BY_RESCOM!$AX$2:$AX$100,RESCOM!$B11),"") -> 0.0094612305 | I11: =IFERROR(SUMIFS(BY_RESCOM!Q$2:Q$100,BY_RESCOM!$AX$2:$AX$100,RESCOM!$B11,BY_RESCOM!$AY$2:$AY$100,RESCOM!$C11)/SUMIFS(BY_RESCOM!Q$2:Q$100,BY_RESCOM!$AX$2:$AX$100,RESCOM!$B11),"") | J11: =IFERROR(SUMIFS(BY_RESCOM!R$2:R$100,BY_RESCOM!$AX$2:$AX$100,RESCOM!$B11,BY_RESCOM!$AY$2:$AY$100,RESCOM!$C11)/SUMIFS(BY_RESCOM!R$2:R$100,BY_RESCOM!$AX$2:$AX$100,RESCOM!$B11),"") -> 0.0013199337 | K11: =IFERROR(SUMIFS(BY_RESCOM!S$2:S$100,BY_RESCOM!$AX$2:$AX$100,RESCOM!$B11,BY_RESCOM!$AY$2:$AY$100,RESCOM!$C11)/SUMIFS(BY_RESCOM!S$2:S$100,BY_RESCOM!$AX$2:$AX$100,RESCOM!$B11),"") -> 0 | ... AH11: =IFERROR(SUMIFS(BY_RESCOM!AP$2:AP$100,BY_RESCOM!$AX$2:$AX$100,RESCOM!$B11,BY_RESCOM!$AY$2:$AY$100,RESCOM!$C11)/SUMIFS(BY_RESCOM!AP$2:AP$100,BY_RESCOM!$AX$2:$AX$100,RESCOM!$B11),"") | AJ11: FLO_MARK | AK11: DMD | AL11: CHW,CSH | AM11: =AL11 -> CHW,CSH | AN11: =1/3 -> 0.33333333 | AO11: 5 | AQ11: 2050 | AR11: =AR9 -> RCK | AS11: =AS9 -> *NGA | AU11: =AU9+(MAX($AU9:$BW9)-AU9)*$CD11 -> 0.45281615 | AV11: =AV9+(MAX($AU9:$BW9)-AV9)*$CD11 -> 0.27218352 | AW11: =AW9+(MAX($AU9:$BW9)-AW9)*$CD11 -> 0.59669329 | AX11: =AX9+(MAX($AU9:$BW9)-AX9)*$CD11 -> 0.62688642 | AY11: =AY9+(MAX($AU9:$BW9)-AY9)*$CD11 -> 0.54327185 | AZ11: =AZ9+(MAX($AU9:$BW9)-AZ9)*$CD11 -> 0.3774479 | BA11: =BA9+(MAX($AU9:$BW9)-BA9)*$CD11 -> 0.40651551 | BB11: =BB9+(MAX($AU9:$BW9)-BB9)*$CD11 -> 0.28266049 | ... BW11: =BW9+(MAX($AU9:$BW9)-BW9)*$CD11 -> 0.50450348 | BX11: =BX9+(MAX($AU9:$BI9)-BX9)*$CD11 -> #DIV/0! | BY11: =AR11 -> RCK | BZ11: UP | CB11: =CB9 -> Techs_RCKNGA | CD11: 0.4
B12: CSH | C12: COA | D12: =IFERROR(SUMIFS(BY_RESCOM!L$2:L$100,BY_RESCOM!$AX$2:$AX$100,RESCOM!$B12,BY_RESCOM!$AY$2:$AY$100,RESCOM!$C12)/SUMIFS(BY_RESCOM!L$2:L$100,BY_RESCOM!$AX$2:$AX$100,RESCOM!$B12),"") -> 0 | E12: =IFERROR(SUMIFS(BY_RESCOM!M$2:M$100,BY_RESCOM!$AX$2:$AX$100,RESCOM!$B12,BY_RESCOM!$AY$2:$AY$100,RESCOM!$C12)/SUMIFS(BY_RESCOM!M$2:M$100,BY_RESCOM!$AX$2:$AX$100,RESCOM!$B12),"") -> 0 | F12: =IFERROR(SUMIFS(BY_RESCOM!N$2:N$100,BY_RESCOM!$AX$2:$AX$100,RESCOM!$B12,BY_RESCOM!$AY$2:$AY$100,RESCOM!$C12)/SUMIFS(BY_RESCOM!N$2:N$100,BY_RESCOM!$AX$2:$AX$100,RESCOM!$B12),"") -> 0 | G12: =IFERROR(SUMIFS(BY_RESCOM!O$2:O$100,BY_RESCOM!$AX$2:$AX$100,RESCOM!$B12,BY_RESCOM!$AY$2:$AY$100,RESCOM!$C12)/SUMIFS(BY_RESCOM!O$2:O$100,BY_RESCOM!$AX$2:$AX$100,RESCOM!$B12),"") -> 0.053437189 | H12: =IFERROR(SUMIFS(BY_RESCOM!P$2:P$100,BY_RESCOM!$AX$2:$AX$100,RESCOM!$B12,BY_RESCOM!$AY$2:$AY$100,RESCOM!$C12)/SUMIFS(BY_RESCOM!P$2:P$100,BY_RESCOM!$AX$2:$AX$100,RESCOM!$B12),"") -> 0.00098107162 | I12: =IFERROR(SUMIFS(BY_RESCOM!Q$2:Q$100,BY_RESCOM!$AX$2:$AX$100,RESCOM!$B12,BY_RESCOM!$AY$2:$AY$100,RESCOM!$C12)/SUMIFS(BY_RESCOM!Q$2:Q$100,BY_RESCOM!$AX$2:$AX$100,RESCOM!$B12),"") -> 0.022761041 | J12: =IFERROR(SUMIFS(BY_RESCOM!R$2:R$100,BY_RESCOM!$AX$2:$AX$100,RESCOM!$B12,BY_RESCOM!$AY$2:$AY$100,RESCOM!$C12)/SUMIFS(BY_RESCOM!R$2:R$100,BY_RESCOM!$AX$2:$AX$100,RESCOM!$B12),"") -> 0.0085211715 | K12: =IFERROR(SUMIFS(BY_RESCOM!S$2:S$100,BY_RESCOM!$AX$2:$AX$100,RESCOM!$B12,BY_RESCOM!$AY$2:$AY$100,RESCOM!$C12)/SUMIFS(BY_RESCOM!S$2:S$100,BY_RESCOM!$AX$2:$AX$100,RESCOM!$B12),"") -> 0 | ... AH12: =IFERROR(SUMIFS(BY_RESCOM!AP$2:AP$100,BY_RESCOM!$AX$2:$AX$100,RESCOM!$B12,BY_RESCOM!$AY$2:$AY$100,RESCOM!$C12)/SUMIFS(BY_RESCOM!AP$2:AP$100,BY_RESCOM!$AX$2:$AX$100,RESCOM!$B12),"") | AJ12: FLO_MARK | AK12: DMD | AL12: CSC | AM12: =AL12 -> CSC | AN12: 0.2 | AO12: 5 | AQ12: 2050 | AR12: =AR10 -> CCK | AS12: =AS10 -> *NGA | AU12: =AU10+(MAX($AU10:$BW10)-AU10)*$CD12 -> 0.62913128 | AV12: =AV10+(MAX($AU10:$BW10)-AV10)*$CD12 -> 0.39965119 | AW12: =AW10+(MAX($AU10:$BW10)-AW10)*$CD12 -> 0.73130928 | AX12: =AX10+(MAX($AU10:$BW10)-AX10)*$CD12 -> 0.96972451 | AY12: =AY10+(MAX($AU10:$BW10)-AY10)*$CD12 -> 0.99835963 | AZ12: =AZ10+(MAX($AU10:$BW10)-AZ10)*$CD12 -> 0.49030803 | BA12: =BA10+(MAX($AU10:$BW10)-BA10)*$CD12 -> 0.54415844 | BB12: =BB10+(MAX($AU10:$BW10)-BB10)*$CD12 -> 0.45794166 | ... BW12: =BW10+(MAX($AU10:$BW10)-BW10)*$CD12 -> 0.8991888 | BX12: =BX10+(MAX($AU10:$BI10)-BX10)*$CD12 -> #DIV/0! | BY12: =AR12 -> CCK | BZ12: UP | CB12: =CB10 -> Techs_CCKNGA | CD12: 0.4
B13: RSH | C13: LPG | D13: =IFERROR(SUMIFS(BY_RESCOM!L$2:L$100,BY_RESCOM!$AX$2:$AX$100,RESCOM!$B13,BY_RESCOM!$AY$2:$AY$100,RESCOM!$C13)/SUMIFS(BY_RESCOM!L$2:L$100,BY_RESCOM!$AX$2:$AX$100,RESCOM!$B13),"") -> 0.83872708 | E13: =IFERROR(SUMIFS(BY_RESCOM!M$2:M$100,BY_RESCOM!$AX$2:$AX$100,RESCOM!$B13,BY_RESCOM!$AY$2:$AY$100,RESCOM!$C13)/SUMIFS(BY_RESCOM!M$2:M$100,BY_RESCOM!$AX$2:$AX$100,RESCOM!$B13),"") -> 0.62994551 | F13: =IFERROR(SUMIFS(BY_RESCOM!N$2:N$100,BY_RESCOM!$AX$2:$AX$100,RESCOM!$B13,BY_RESCOM!$AY$2:$AY$100,RESCOM!$C13)/SUMIFS(BY_RESCOM!N$2:N$100,BY_RESCOM!$AX$2:$AX$100,RESCOM!$B13),"") -> 0.097998671 | G13: =IFERROR(SUMIFS(BY_RESCOM!O$2:O$100,BY_RESCOM!$AX$2:$AX$100,RESCOM!$B13,BY_RESCOM!$AY$2:$AY$100,RESCOM!$C13)/SUMIFS(BY_RESCOM!O$2:O$100,BY_RESCOM!$AX$2:$AX$100,RESCOM!$B13),"") -> 0.058004965 | H13: =IFERROR(SUMIFS(BY_RESCOM!P$2:P$100,BY_RESCOM!$AX$2:$AX$100,RESCOM!$B13,BY_RESCOM!$AY$2:$AY$100,RESCOM!$C13)/SUMIFS(BY_RESCOM!P$2:P$100,BY_RESCOM!$AX$2:$AX$100,RESCOM!$B13),"") -> 0.14505903 | I13: =IFERROR(SUMIFS(BY_RESCOM!Q$2:Q$100,BY_RESCOM!$AX$2:$AX$100,RESCOM!$B13,BY_RESCOM!$AY$2:$AY$100,RESCOM!$C13)/SUMIFS(BY_RESCOM!Q$2:Q$100,BY_RESCOM!$AX$2:$AX$100,RESCOM!$B13),"") | J13: =IFERROR(SUMIFS(BY_RESCOM!R$2:R$100,BY_RESCOM!$AX$2:$AX$100,RESCOM!$B13,BY_RESCOM!$AY$2:$AY$100,RESCOM!$C13)/SUMIFS(BY_RESCOM!R$2:R$100,BY_RESCOM!$AX$2:$AX$100,RESCOM!$B13),"") -> 0.032783719 | K13: =IFERROR(SUMIFS(BY_RESCOM!S$2:S$100,BY_RESCOM!$AX$2:$AX$100,RESCOM!$B13,BY_RESCOM!$AY$2:$AY$100,RESCOM!$C13)/SUMIFS(BY_RESCOM!S$2:S$100,BY_RESCOM!$AX$2:$AX$100,RESCOM!$B13),"") -> 0.095903271 | ... AH13: =IFERROR(SUMIFS(BY_RESCOM!AP$2:AP$100,BY_RESCOM!$AX$2:$AX$100,RESCOM!$B13,BY_RESCOM!$AY$2:$AY$100,RESCOM!$C13)/SUMIFS(BY_RESCOM!AP$2:AP$100,BY_RESCOM!$AX$2:$AX$100,RESCOM!$B13),"") | AQ13: 2100 | AR13: =AR11 -> RCK | AS13: =AS11 -> *NGA | AU13: =AU11+(MAX($AU11:$BW11)-AU11)*$CD13 -> 0.63493027 | AV13: =AV11+(MAX($AU11:$BW11)-AV11)*$CD13 -> 0.59880375 | AW13: =AW11+(MAX($AU11:$BW11)-AW11)*$CD13 -> 0.6637057 | AX13: =AX11+(MAX($AU11:$BW11)-AX11)*$CD13 -> 0.66974433 | AY13: =AY11+(MAX($AU11:$BW11)-AY11)*$CD13 -> 0.65302141 | AZ13: =AZ11+(MAX($AU11:$BW11)-AZ11)*$CD13 -> 0.61985662 | BA13: =BA11+(MAX($AU11:$BW11)-BA11)*$CD13 -> 0.62567014 | BB13: =BB11+(MAX($AU11:$BW11)-BB11)*$CD13 -> 0.60089914 | ... BW13: =BW11+(MAX($AU11:$BW11)-BW11)*$CD13 -> 0.64526774 | BX13: =BX11+(MAX($AU11:$BI11)-BX11)*$CD13 -> #DIV/0! | BY13: =AR13 -> RCK | BZ13: UP | CB13: =CB11 -> Techs_RCKNGA | CD13: 0.8
B14: CSH | C14: LPG | D14: =IFERROR(SUMIFS(BY_RESCOM!L$2:L$100,BY_RESCOM!$AX$2:$AX$100,RESCOM!$B14,BY_RESCOM!$AY$2:$AY$100,RESCOM!$C14)/SUMIFS(BY_RESCOM!L$2:L$100,BY_RESCOM!$AX$2:$AX$100,RESCOM!$B14),"") -> 0 | E14: =IFERROR(SUMIFS(BY_RESCOM!M$2:M$100,BY_RESCOM!$AX$2:$AX$100,RESCOM!$B14,BY_RESCOM!$AY$2:$AY$100,RESCOM!$C14)/SUMIFS(BY_RESCOM!M$2:M$100,BY_RESCOM!$AX$2:$AX$100,RESCOM!$B14),"") -> 0 | F14: =IFERROR(SUMIFS(BY_RESCOM!N$2:N$100,BY_RESCOM!$AX$2:$AX$100,RESCOM!$B14,BY_RESCOM!$AY$2:$AY$100,RESCOM!$C14)/SUMIFS(BY_RESCOM!N$2:N$100,BY_RESCOM!$AX$2:$AX$100,RESCOM!$B14),"") -> 0 | G14: =IFERROR(SUMIFS(BY_RESCOM!O$2:O$100,BY_RESCOM!$AX$2:$AX$100,RESCOM!$B14,BY_RESCOM!$AY$2:$AY$100,RESCOM!$C14)/SUMIFS(BY_RESCOM!O$2:O$100,BY_RESCOM!$AX$2:$AX$100,RESCOM!$B14),"") -> 0.0021212228 | H14: =IFERROR(SUMIFS(BY_RESCOM!P$2:P$100,BY_RESCOM!$AX$2:$AX$100,RESCOM!$B14,BY_RESCOM!$AY$2:$AY$100,RESCOM!$C14)/SUMIFS(BY_RESCOM!P$2:P$100,BY_RESCOM!$AX$2:$AX$100,RESCOM!$B14),"") -> 0.070773673 | I14: =IFERROR(SUMIFS(BY_RESCOM!Q$2:Q$100,BY_RESCOM!$AX$2:$AX$100,RESCOM!$B14,BY_RESCOM!$AY$2:$AY$100,RESCOM!$C14)/SUMIFS(BY_RESCOM!Q$2:Q$100,BY_RESCOM!$AX$2:$AX$100,RESCOM!$B14),"") -> 0.088555072 | J14: =IFERROR(SUMIFS(BY_RESCOM!R$2:R$100,BY_RESCOM!$AX$2:$AX$100,RESCOM!$B14,BY_RESCOM!$AY$2:$AY$100,RESCOM!$C14)/SUMIFS(BY_RESCOM!R$2:R$100,BY_RESCOM!$AX$2:$AX$100,RESCOM!$B14),"") -> 0.0070271855 | K14: =IFERROR(SUMIFS(BY_RESCOM!S$2:S$100,BY_RESCOM!$AX$2:$AX$100,RESCOM!$B14,BY_RESCOM!$AY$2:$AY$100,RESCOM!$C14)/SUMIFS(BY_RESCOM!S$2:S$100,BY_RESCOM!$AX$2:$AX$100,RESCOM!$B14),"") -> 0 | ... AH14: =IFERROR(SUMIFS(BY_RESCOM!AP$2:AP$100,BY_RESCOM!$AX$2:$AX$100,RESCOM!$B14,BY_RESCOM!$AY$2:$AY$100,RESCOM!$C14)/SUMIFS(BY_RESCOM!AP$2:AP$100,BY_RESCOM!$AX$2:$AX$100,RESCOM!$B14),"") | AQ14: 2100 | AR14: =AR12 -> CCK | AS14: =AS12 -> *NGA | AU14: =AU12+(MAX($AU12:$BW12)-AU12)*$CD14 -> 0.92451396 | AV14: =AV12+(MAX($AU12:$BW12)-AV12)*$CD14 -> 0.87861794 | AW14: =AW12+(MAX($AU12:$BW12)-AW12)*$CD14 -> 0.94494956 | AX14: =AX12+(MAX($AU12:$BW12)-AX12)*$CD14 -> 0.9926326 | AY14: =AY12+(MAX($AU12:$BW12)-AY12)*$CD14 -> 0.99835963 | AZ14: =AZ12+(MAX($AU12:$BW12)-AZ12)*$CD14 -> 0.89674931 | BA14: =BA12+(MAX($AU12:$BW12)-BA12)*$CD14 -> 0.90751939 | BB14: =BB12+(MAX($AU12:$BW12)-BB12)*$CD14 -> 0.89027603 | ... BW14: =BW12+(MAX($AU12:$BW12)-BW12)*$CD14 -> 0.97852546 | BX14: =BX12+(MAX($AU12:$BI12)-BX12)*$CD14 -> #DIV/0! | BY14: =AR14 -> CCK | BZ14: UP | CB14: =CB12 -> Techs_CCKNGA | CD14: 0.8
B15: RSH | C15: ELC | D15: =IFERROR(SUMIFS(BY_RESCOM!L$2:L$100,BY_RESCOM!$AX$2:$AX$100,RESCOM!$B15,BY_RESCOM!$AY$2:$AY$100,RESCOM!$C15)/SUMIFS(BY_RESCOM!L$2:L$100,BY_RESCOM!$AX$2:$AX$100,RESCOM!$B15),"") -> 0 | E15: =IFERROR(SUMIFS(BY_RESCOM!M$2:M$100,BY_RESCOM!$AX$2:$AX$100,RESCOM!$B15,BY_RESCOM!$AY$2:$AY$100,RESCOM!$C15)/SUMIFS(BY_RESCOM!M$2:M$100,BY_RESCOM!$AX$2:$AX$100,RESCOM!$B15),"") -> 0 | F15: =IFERROR(SUMIFS(BY_RESCOM!N$2:N$100,BY_RESCOM!$AX$2:$AX$100,RESCOM!$B15,BY_RESCOM!$AY$2:$AY$100,RESCOM!$C15)/SUMIFS(BY_RESCOM!N$2:N$100,BY_RESCOM!$AX$2:$AX$100,RESCOM!$B15),"") -> 0.18752923 | G15: =IFERROR(SUMIFS(BY_RESCOM!O$2:O$100,BY_RESCOM!$AX$2:$AX$100,RESCOM!$B15,BY_RESCOM!$AY$2:$AY$100,RESCOM!$C15)/SUMIFS(BY_RESCOM!O$2:O$100,BY_RESCOM!$AX$2:$AX$100,RESCOM!$B15),"") -> 0.025875992 | H15: =IFERROR(SUMIFS(BY_RESCOM!P$2:P$100,BY_RESCOM!$AX$2:$AX$100,RESCOM!$B15,BY_RESCOM!$AY$2:$AY$100,RESCOM!$C15)/SUMIFS(BY_RESCOM!P$2:P$100,BY_RESCOM!$AX$2:$AX$100,RESCOM!$B15),"") -> 0.40701041 | I15: =IFERROR(SUMIFS(BY_RESCOM!Q$2:Q$100,BY_RESCOM!$AX$2:$AX$100,RESCOM!$B15,BY_RESCOM!$AY$2:$AY$100,RESCOM!$C15)/SUMIFS(BY_RESCOM!Q$2:Q$100,BY_RESCOM!$AX$2:$AX$100,RESCOM!$B15),"") | J15: =IFERROR(SUMIFS(BY_RESCOM!R$2:R$100,BY_RESCOM!$AX$2:$AX$100,RESCOM!$B15,BY_RESCOM!$AY$2:$AY$100,RESCOM!$C15)/SUMIFS(BY_RESCOM!R$2:R$100,BY_RESCOM!$AX$2:$AX$100,RESCOM!$B15),"") -> 0.22879745 | K15: =IFERROR(SUMIFS(BY_RESCOM!S$2:S$100,BY_RESCOM!$AX$2:$AX$100,RESCOM!$B15,BY_RESCOM!$AY$2:$AY$100,RESCOM!$C15)/SUMIFS(BY_RESCOM!S$2:S$100,BY_RESCOM!$AX$2:$AX$100,RESCOM!$B15),"") -> 0.15484534 | ... AH15: =IFERROR(SUMIFS(BY_RESCOM!AP$2:AP$100,BY_RESCOM!$AX$2:$AX$100,RESCOM!$B15,BY_RESCOM!$AY$2:$AY$100,RESCOM!$C15)/SUMIFS(BY_RESCOM!AP$2:AP$100,BY_RESCOM!$AX$2:$AX$100,RESCOM!$B15),"") | AQ15: 2050 | AR15: RHW | AS15: *STH | AT15: 0.2 | BY15: =AR15 -> RHW | BZ15: UP | CB15: Techs_RHWSTH
B16: CSH | C16: ELC | D16: =IFERROR(SUMIFS(BY_RESCOM!L$2:L$100,BY_RESCOM!$AX$2:$AX$100,RESCOM!$B16,BY_RESCOM!$AY$2:$AY$100,RESCOM!$C16)/SUMIFS(BY_RESCOM!L$2:L$100,BY_RESCOM!$AX$2:$AX$100,RESCOM!$B16),"") -> 0 | E16: =IFERROR(SUMIFS(BY_RESCOM!M$2:M$100,BY_RESCOM!$AX$2:$AX$100,RESCOM!$B16,BY_RESCOM!$AY$2:$AY$100,RESCOM!$C16)/SUMIFS(BY_RESCOM!M$2:M$100,BY_RESCOM!$AX$2:$AX$100,RESCOM!$B16),"") -> 0 | F16: =IFERROR(SUMIFS(BY_RESCOM!N$2:N$100,BY_RESCOM!$AX$2:$AX$100,RESCOM!$B16,BY_RESCOM!$AY$2:$AY$100,RESCOM!$C16)/SUMIFS(BY_RESCOM!N$2:N$100,BY_RESCOM!$AX$2:$AX$100,RESCOM!$B16),"") -> 0.33690946 | G16: =IFERROR(SUMIFS(BY_RESCOM!O$2:O$100,BY_RESCOM!$AX$2:$AX$100,RESCOM!$B16,BY_RESCOM!$AY$2:$AY$100,RESCOM!$C16)/SUMIFS(BY_RESCOM!O$2:O$100,BY_RESCOM!$AX$2:$AX$100,RESCOM!$B16),"") -> 0.030316233 | H16: =IFERROR(SUMIFS(BY_RESCOM!P$2:P$100,BY_RESCOM!$AX$2:$AX$100,RESCOM!$B16,BY_RESCOM!$AY$2:$AY$100,RESCOM!$C16)/SUMIFS(BY_RESCOM!P$2:P$100,BY_RESCOM!$AX$2:$AX$100,RESCOM!$B16),"") -> 0.28159907 | I16: =IFERROR(SUMIFS(BY_RESCOM!Q$2:Q$100,BY_RESCOM!$AX$2:$AX$100,RESCOM!$B16,BY_RESCOM!$AY$2:$AY$100,RESCOM!$C16)/SUMIFS(BY_RESCOM!Q$2:Q$100,BY_RESCOM!$AX$2:$AX$100,RESCOM!$B16),"") -> 0.41140863 | J16: =IFERROR(SUMIFS(BY_RESCOM!R$2:R$100,BY_RESCOM!$AX$2:$AX$100,RESCOM!$B16,BY_RESCOM!$AY$2:$AY$100,RESCOM!$C16)/SUMIFS(BY_RESCOM!R$2:R$100,BY_RESCOM!$AX$2:$AX$100,RESCOM!$B16),"") -> 0.21000124 | K16: =IFERROR(SUMIFS(BY_RESCOM!S$2:S$100,BY_RESCOM!$AX$2:$AX$100,RESCOM!$B16,BY_RESCOM!$AY$2:$AY$100,RESCOM!$C16)/SUMIFS(BY_RESCOM!S$2:S$100,BY_RESCOM!$AX$2:$AX$100,RESCOM!$B16),"") -> 0.9161158 | ... AH16: =IFERROR(SUMIFS(BY_RESCOM!AP$2:AP$100,BY_RESCOM!$AX$2:$AX$100,RESCOM!$B16,BY_RESCOM!$AY$2:$AY$100,RESCOM!$C16)/SUMIFS(BY_RESCOM!AP$2:AP$100,BY_RESCOM!$AX$2:$AX$100,RESCOM!$B16),"") | AQ16: 2050 | AR16: CHW | AS16: *STH | AT16: 0.2 | BY16: =AR16 -> CHW | BZ16: UP | CB16: Techs_CHWSTH
B17: RSH | C17: HET | D17: =IFERROR(SUMIFS(BY_RESCOM!L$2:L$100,BY_RESCOM!$AX$2:$AX$100,RESCOM!$B17,BY_RESCOM!$AY$2:$AY$100,RESCOM!$C17)/SUMIFS(BY_RESCOM!L$2:L$100,BY_RESCOM!$AX$2:$AX$100,RESCOM!$B17),"") -> 0 | E17: =IFERROR(SUMIFS(BY_RESCOM!M$2:M$100,BY_RESCOM!$AX$2:$AX$100,RESCOM!$B17,BY_RESCOM!$AY$2:$AY$100,RESCOM!$C17)/SUMIFS(BY_RESCOM!M$2:M$100,BY_RESCOM!$AX$2:$AX$100,RESCOM!$B17),"") -> 0 | F17: =IFERROR(SUMIFS(BY_RESCOM!N$2:N$100,BY_RESCOM!$AX$2:$AX$100,RESCOM!$B17,BY_RESCOM!$AY$2:$AY$100,RESCOM!$C17)/SUMIFS(BY_RESCOM!N$2:N$100,BY_RESCOM!$AX$2:$AX$100,RESCOM!$B17),"") -> 0 | G17: =IFERROR(SUMIFS(BY_RESCOM!O$2:O$100,BY_RESCOM!$AX$2:$AX$100,RESCOM!$B17,BY_RESCOM!$AY$2:$AY$100,RESCOM!$C17)/SUMIFS(BY_RESCOM!O$2:O$100,BY_RESCOM!$AX$2:$AX$100,RESCOM!$B17),"") -> 0.11881993 | H17: =IFERROR(SUMIFS(BY_RESCOM!P$2:P$100,BY_RESCOM!$AX$2:$AX$100,RESCOM!$B17,BY_RESCOM!$AY$2:$AY$100,RESCOM!$C17)/SUMIFS(BY_RESCOM!P$2:P$100,BY_RESCOM!$AX$2:$AX$100,RESCOM!$B17),"") -> 0 | I17: =IFERROR(SUMIFS(BY_RESCOM!Q$2:Q$100,BY_RESCOM!$AX$2:$AX$100,RESCOM!$B17,BY_RESCOM!$AY$2:$AY$100,RESCOM!$C17)/SUMIFS(BY_RESCOM!Q$2:Q$100,BY_RESCOM!$AX$2:$AX$100,RESCOM!$B17),"") | J17: =IFERROR(SUMIFS(BY_RESCOM!R$2:R$100,BY_RESCOM!$AX$2:$AX$100,RESCOM!$B17,BY_RESCOM!$AY$2:$AY$100,RESCOM!$C17)/SUMIFS(BY_RESCOM!R$2:R$100,BY_RESCOM!$AX$2:$AX$100,RESCOM!$B17),"") -> 0 | K17: =IFERROR(SUMIFS(BY_RESCOM!S$2:S$100,BY_RESCOM!$AX$2:$AX$100,RESCOM!$B17,BY_RESCOM!$AY$2:$AY$100,RESCOM!$C17)/SUMIFS(BY_RESCOM!S$2:S$100,BY_RESCOM!$AX$2:$AX$100,RESCOM!$B17),"") -> 0 | ... AH17: =IFERROR(SUMIFS(BY_RESCOM!AP$2:AP$100,BY_RESCOM!$AX$2:$AX$100,RESCOM!$B17,BY_RESCOM!$AY$2:$AY$100,RESCOM!$C17)/SUMIFS(BY_RESCOM!AP$2:AP$100,BY_RESCOM!$AX$2:$AX$100,RESCOM!$B17),"") | AQ17: 2020 | AR17: CSH | AT17: 0.05 | BY17: =AR17 -> CSH | BZ17: UP | CA17: C*HP*,-*000 | CB17: TechsHP
B18: CSH | C18: HET | D18: =IFERROR(SUMIFS(BY_RESCOM!L$2:L$100,BY_RESCOM!$AX$2:$AX$100,RESCOM!$B18,BY_RESCOM!$AY$2:$AY$100,RESCOM!$C18)/SUMIFS(BY_RESCOM!L$2:L$100,BY_RESCOM!$AX$2:$AX$100,RESCOM!$B18),"") -> 0 | E18: =IFERROR(SUMIFS(BY_RESCOM!M$2:M$100,BY_RESCOM!$AX$2:$AX$100,RESCOM!$B18,BY_RESCOM!$AY$2:$AY$100,RESCOM!$C18)/SUMIFS(BY_RESCOM!M$2:M$100,BY_RESCOM!$AX$2:$AX$100,RESCOM!$B18),"") -> 0 | F18: =IFERROR(SUMIFS(BY_RESCOM!N$2:N$100,BY_RESCOM!$AX$2:$AX$100,RESCOM!$B18,BY_RESCOM!$AY$2:$AY$100,RESCOM!$C18)/SUMIFS(BY_RESCOM!N$2:N$100,BY_RESCOM!$AX$2:$AX$100,RESCOM!$B18),"") -> 0 | G18: =IFERROR(SUMIFS(BY_RESCOM!O$2:O$100,BY_RESCOM!$AX$2:$AX$100,RESCOM!$B18,BY_RESCOM!$AY$2:$AY$100,RESCOM!$C18)/SUMIFS(BY_RESCOM!O$2:O$100,BY_RESCOM!$AX$2:$AX$100,RESCOM!$B18),"") -> 0.35047564 | H18: =IFERROR(SUMIFS(BY_RESCOM!P$2:P$100,BY_RESCOM!$AX$2:$AX$100,RESCOM!$B18,BY_RESCOM!$AY$2:$AY$100,RESCOM!$C18)/SUMIFS(BY_RESCOM!P$2:P$100,BY_RESCOM!$AX$2:$AX$100,RESCOM!$B18),"") -> 0.066026637 | I18: =IFERROR(SUMIFS(BY_RESCOM!Q$2:Q$100,BY_RESCOM!$AX$2:$AX$100,RESCOM!$B18,BY_RESCOM!$AY$2:$AY$100,RESCOM!$C18)/SUMIFS(BY_RESCOM!Q$2:Q$100,BY_RESCOM!$AX$2:$AX$100,RESCOM!$B18),"") -> 0.12076586 | J18: =IFERROR(SUMIFS(BY_RESCOM!R$2:R$100,BY_RESCOM!$AX$2:$AX$100,RESCOM!$B18,BY_RESCOM!$AY$2:$AY$100,RESCOM!$C18)/SUMIFS(BY_RESCOM!R$2:R$100,BY_RESCOM!$AX$2:$AX$100,RESCOM!$B18),"") -> 0 | K18: =IFERROR(SUMIFS(BY_RESCOM!S$2:S$100,BY_RESCOM!$AX$2:$AX$100,RESCOM!$B18,BY_RESCOM!$AY$2:$AY$100,RESCOM!$C18)/SUMIFS(BY_RESCOM!S$2:S$100,BY_RESCOM!$AX$2:$AX$100,RESCOM!$B18),"") -> 0 | ... AH18: =IFERROR(SUMIFS(BY_RESCOM!AP$2:AP$100,BY_RESCOM!$AX$2:$AX$100,RESCOM!$B18,BY_RESCOM!$AY$2:$AY$100,RESCOM!$C18)/SUMIFS(BY_RESCOM!AP$2:AP$100,BY_RESCOM!$AX$2:$AX$100,RESCOM!$B18),"") | AQ18: 2050 | AR18: CSH | AT18: 0.75 | BY18: =AR18 -> CSH | BZ18: UP | CA18: =CA17 -> C*HP*,-*000 | CB18: TechsHP
B19: RCK | C19: COA | D19: =IFERROR(SUMIFS(BY_RESCOM!L$2:L$100,BY_RESCOM!$AX$2:$AX$100,RESCOM!$B19,BY_RESCOM!$AY$2:$AY$100,RESCOM!$C19)/SUMIFS(BY_RESCOM!L$2:L$100,BY_RESCOM!$AX$2:$AX$100,RESCOM!$B19),"") -> 0 | E19: =IFERROR(SUMIFS(BY_RESCOM!M$2:M$100,BY_RESCOM!$AX$2:$AX$100,RESCOM!$B19,BY_RESCOM!$AY$2:$AY$100,RESCOM!$C19)/SUMIFS(BY_RESCOM!M$2:M$100,BY_RESCOM!$AX$2:$AX$100,RESCOM!$B19),"") -> 1.0623453e-06 | F19: =IFERROR(SUMIFS(BY_RESCOM!N$2:N$100,BY_RESCOM!$AX$2:$AX$100,RESCOM!$B19,BY_RESCOM!$AY$2:$AY$100,RESCOM!$C19)/SUMIFS(BY_RESCOM!N$2:N$100,BY_RESCOM!$AX$2:$AX$100,RESCOM!$B19),"") -> 0 | G19: =IFERROR(SUMIFS(BY_RESCOM!O$2:O$100,BY_RESCOM!$AX$2:$AX$100,RESCOM!$B19,BY_RESCOM!$AY$2:$AY$100,RESCOM!$C19)/SUMIFS(BY_RESCOM!O$2:O$100,BY_RESCOM!$AX$2:$AX$100,RESCOM!$B19),"") -> 0.032931458 | H19: =IFERROR(SUMIFS(BY_RESCOM!P$2:P$100,BY_RESCOM!$AX$2:$AX$100,RESCOM!$B19,BY_RESCOM!$AY$2:$AY$100,RESCOM!$C19)/SUMIFS(BY_RESCOM!P$2:P$100,BY_RESCOM!$AX$2:$AX$100,RESCOM!$B19),"") -> 0 | I19: =IFERROR(SUMIFS(BY_RESCOM!Q$2:Q$100,BY_RESCOM!$AX$2:$AX$100,RESCOM!$B19,BY_RESCOM!$AY$2:$AY$100,RESCOM!$C19)/SUMIFS(BY_RESCOM!Q$2:Q$100,BY_RESCOM!$AX$2:$AX$100,RESCOM!$B19),"") -> 0.015137805 | J19: =IFERROR(SUMIFS(BY_RESCOM!R$2:R$100,BY_RESCOM!$AX$2:$AX$100,RESCOM!$B19,BY_RESCOM!$AY$2:$AY$100,RESCOM!$C19)/SUMIFS(BY_RESCOM!R$2:R$100,BY_RESCOM!$AX$2:$AX$100,RESCOM!$B19),"") -> 0 | K19: =IFERROR(SUMIFS(BY_RESCOM!S$2:S$100,BY_RESCOM!$AX$2:$AX$100,RESCOM!$B19,BY_RESCOM!$AY$2:$AY$100,RESCOM!$C19)/SUMIFS(BY_RESCOM!S$2:S$100,BY_RESCOM!$AX$2:$AX$100,RESCOM!$B19),"") -> 0 | ... AH19: =IFERROR(SUMIFS(BY_RESCOM!AP$2:AP$100,BY_RESCOM!$AX$2:$AX$100,RESCOM!$B19,BY_RESCOM!$AY$2:$AY$100,RESCOM!$C19)/SUMIFS(BY_RESCOM!AP$2:AP$100,BY_RESCOM!$AX$2:$AX$100,RESCOM!$B19),"") | AQ19: 2020 | AR19: RSH | AT19: 0.05 | BY19: =AR19 -> RSH | BZ19: UP | CA19: R*HP*,-*000 | CB19: TechsHP_r
