Workbook

Sheet Constants
B2: ~TFM_INS-TS | Y2: ~TFM_INS
B3: TimeSlice | C3: LimType | D3: Attribute | E3: Year | F3: Other_Indexes | G3: Curr | H3: 2022 | I3: Cset_CN | Y3: TimeSlice | Z3: LimType | AA3: Attribute | AB3: Year | AC3: Other_Indexes | AD3: Curr | AE3: AllRegions
D4: COM_PKRSV | H4: 0.05 | I4: ELC | T4: varbl | U4: region | V4: year | W4: value | AA4: G_CUREX | AC4: USD20 | AD4: EUR15 | AE4: =1.10926234054354*H40 -> 1.201442
B5: ANNUAL | D5: COM_PKTS | H5: 1 | I5: ELC | T5: hmacgdpd | U5: USA | V5: 2001 | W5: 0.76282752 | AA5: G_DRATE | AD5: EUR15 | AE5: =O6 -> 0.07
D6: G_Dyear | H6: 2020 | O6: 0.07 | P6: Discount Rate | T6: hmacgdpd | U6: USA | V6: 2002 | W6: 0.77446032 | AA6: G_CUREX | AC6: USD20 | AD6: USD21_alt | AE6: =H46 -> 0.9896
D7: G_OFFTHD | H7: 1 | T7: hmacgdpd | U7: USA | V7: 2003 | W7: 0.78906536 | AA7: G_DRATE | AD7: USD21_alt | AE7: =AE5 -> 0.07
D8: =IF(F8=G8,"*","")&"G_CUREX" -> G_CUREX | F8: USD20 | G8: ="USD"&RIGHT(O9,2) -> USD83 | H8: =ROUND($P$46/P9,4) -> 2.2201 | P8: Deflator | T8: hmacgdpd | U8: USA | V8: 2004 | W8: 0.81019747 | AA8: G_CUREX | AC8: USD20 | AD8: EUR17 | AE8: =0.975997658308128*AE4 -> 1.1726046
D9: =IF(F9=G9,"*","")&"G_CUREX" -> G_CUREX | F9: USD20 | G9: ="USD"&RIGHT(O10,2) -> USD84 | H9: =ROUND($P$46/P10,4) -> 2.1427 | O9: 1983 | P9: =VLOOKUP(O9,$V$5:$W$99,2,FALSE) -> 0.48787263 | T9: hmacgdpd | U9: USA | V9: 2005 | W9: 0.83531958 | AA9: G_DRATE | AD9: EUR17 | AE9: 0.07
D10: =IF(F10=G10,"*","")&"G_CUREX" -> G_CUREX | F10: USD20 | G10: ="USD"&RIGHT(O11,2) -> USD85 | H10: =ROUND($P$46/P11,4) -> 2.077 | O10: 1984 | P10: =VLOOKUP(O10,$V$5:$W$99,2,FALSE) -> 0.50549513 | T10: hmacgdpd | U10: USA | V10: 2006 | W10: 0.86080724 | AA10: G_CUREX | AC10: USD20 | AD10: EUR18 | AE10: =0.961364728495915*AE4 -> 1.155024
D11: =IF(F11=G11,"*","")&"G_CUREX" -> G_CUREX | F11: USD20 | G11: ="USD"&RIGHT(O12,2) -> USD86 | H11: =ROUND($P$46/P12,4) -> 2.0358 | O11: 1985 | P11: =VLOOKUP(O11,$V$5:$W$99,2,FALSE) -> 0.52148581 | T11: hmacgdpd | U11: USA | V11: 2007 | W11: 0.88397014 | AA11: G_DRATE | AD11: EUR18 | AE11: 0.07
D12: =IF(F12=G12,"*","")&"G_CUREX" -> G_CUREX | F12: USD20 | G12: ="USD"&RIGHT(O13,2) -> USD87 | H12: =ROUND($P$46/P13,4) -> 1.987 | O12: 1986 | P12: =VLOOKUP(O12,$V$5:$W$99,2,FALSE) -> 0.53205073 | T12: hmacgdpd | U12: USA | V12: 2008 | W12: 0.90084481 | AA12: G_CUREX | AC12: USD20 | AD12: EUR10 | AE12: =1.06008902077151*AE4 -> 1.2736355
D13: =IF(F13=G13,"*","")&"G_CUREX" -> G_CUREX | F13: USD20 | G13: ="USD"&RIGHT(O14,2) -> USD88 | H13: =ROUND($P$46/P14,4) -> 1.9192 | O13: 1987 | P13: =VLOOKUP(O13,$V$5:$W$99,2,FALSE) -> 0.54511946 | T13: hmacgdpd | U13: USA | V13: 2009 | W13: 0.90787375 | AA13: G_DRATE | AD13: EUR10 | AE13: 0.07
D14: =IF(F14=G14,"*","")&"G_CUREX" -> G_CUREX | F14: USD20 | G14: ="USD"&RIGHT(O15,2) -> USD89 | H14: =ROUND($P$46/P15,4) -> 1.8468 | O14: 1988 | P14: =VLOOKUP(O14,$V$5:$W$99,2,FALSE) -> 0.56437135 | T14: hmacgdpd | U14: USA | V14: 2010 | W14: 0.9184792 | AA14: G_CUREX | AC14: USD20 | AD14: EUR12 | AE14: =1.0182*AE4 -> 1.2233083
D15: =IF(F15=G15,"*","")&"G_CUREX" -> G_CUREX | F15: USD20 | G15: ="USD"&RIGHT(O16,2) -> USD90 | H15: =ROUND($P$46/P16,4) -> 1.7799 | O15: 1989 | P15: =VLOOKUP(O15,$V$5:$W$99,2,FALSE) -> 0.58649743 | T15: hmacgdpd | U15: USA | V15: 2011 | W15: 0.93761897 | AA15: G_DRATE | AD15: EUR12 | AE15: 0.07
D16: =IF(F16=G16,"*","")&"G_CUREX" -> G_CUREX | F16: USD20 | G16: ="USD"&RIGHT(O17,2) -> USD91 | H16: =ROUND($P$46/P17,4) -> 1.722 | O16: 1990 | P16: =VLOOKUP(O16,$V$5:$W$99,2,FALSE) -> 0.60853273 | T16: hmacgdpd | U16: USA | V16: 2012 | W16: 0.9556666 | AA16: G_CUREX | AC16: USD20 | AD16: EUR19 | AE16: =0.9486*AE4 -> 1.1396879
D17: =IF(F17=G17,"*","")&"G_CUREX" -> G_CUREX | F17: USD20 | G17: ="USD"&RIGHT(O18,2) -> USD92 | H17: =ROUND($P$46/P18,4) -> 1.6836 | O17: 1991 | P17: =VLOOKUP(O17,$V$5:$W$99,2,FALSE) -> 0.62901258 | T17: hmacgdpd | U17: USA | V17: 2013 | W17: 0.97260576 | AA17: G_DRATE | AD17: EUR19 | AE17: 0.07
D18: =IF(F18=G18,"*","")&"G_CUREX" -> G_CUREX | F18: USD20 | G18: ="USD"&RIGHT(O19,2) -> USD93 | H18: =ROUND($P$46/P19,4) -> 1.6446 | O18: 1992 | P18: =VLOOKUP(O18,$V$5:$W$99,2,FALSE) -> 0.6433621 | T18: hmacgdpd | U18: USA | V18: 2014 | W18: 0.99051732
D19: =IF(F19=G19,"*","")&"G_CUREX" -> G_CUREX | F19: USD20 | G19: ="USD"&RIGHT(O20,2) -> USD94 | H19: =ROUND($P$46/P20,4) -> 1.6102 | O19: 1993 | P19: =VLOOKUP(O19,$V$5:$W$99,2,FALSE) -> 0.65861923 | T19: hmacgdpd | U19: USA | V19: 2015 | W19: 1
D20: =IF(F20=G20,"*","")&"G_CUREX" -> G_CUREX | F20: USD20 | G20: ="USD"&RIGHT(O21,2) -> USD95 | H20: =ROUND($P$46/P21,4) -> 1.5771 | O20: 1994 | P20: =VLOOKUP(O20,$V$5:$W$99,2,FALSE) -> 0.67265797 | T20: hmacgdpd | U20: USA | V20: 2016 | W20: 1.0104837
D21: =IF(F21=G21,"*","")&"G_CUREX" -> G_CUREX | F21: USD20 | G21: ="USD"&RIGHT(O22,2) -> USD96 | H21: =ROUND($P$46/P22,4) -> 1.5488 | O21: 1995 | P21: =VLOOKUP(O21,$V$5:$W$99,2,FALSE) -> 0.68678039 | T21: hmacgdpd | U21: USA | V21: 2017 | W21: 1.0297403
D22: =IF(F22=G22,"*","")&"G_CUREX" -> G_CUREX | F22: USD20 | G22: ="USD"&RIGHT(O23,2) -> USD97 | H22: =ROUND($P$46/P23,4) -> 1.5224 | O22: 1996 | P22: =VLOOKUP(O22,$V$5:$W$99,2,FALSE) -> 0.6993354 | T22: hmacgdpd | U22: USA | V22: 2018 | W22: 1.0543081
D23: =IF(F23=G23,"*","")&"G_CUREX" -> G_CUREX | F23: USD20 | G23: ="USD"&RIGHT(O24,2) -> USD98 | H23: =ROUND($P$46/P24,4) -> 1.5058 | O23: 1997 | P23: =VLOOKUP(O23,$V$5:$W$99,2,FALSE) -> 0.71145087 | T23: hmacgdpd | U23: USA | V23: 2019 | W23: 1.0733783
D24: =IF(F24=G24,"*","")&"G_CUREX" -> G_CUREX | F24: USD20 | G24: ="USD"&RIGHT(O25,2) -> USD99 | H24: =ROUND($P$46/P25,4) -> 1.4845 | O24: 1998 | P24: =VLOOKUP(O24,$V$5:$W$99,2,FALSE) -> 0.71929687 | T24: hmacgdpd | U24: USA | V24: 2020 | W24: 1.0831454
D25: =IF(F25=G25,"*","")&"G_CUREX" -> G_CUREX | F25: USD20 | G25: ="USD"&RIGHT(O26,2) -> USD00 | H25: =ROUND($P$46/P26,4) -> 1.4518 | O25: 1999 | P25: =VLOOKUP(O25,$V$5:$W$99,2,FALSE) -> 0.7296133 | T25: hmacgdpd | U25: USA | V25: 2021 | W25: 1.0945699
D26: =IF(F26=G26,"*","")&"G_CUREX" -> G_CUREX | F26: USD20 | G26: ="USD"&RIGHT(O27,2) -> USD01 | H26: =ROUND($P$46/P27,4) -> 1.4199 | O26: 2000 | P26: =VLOOKUP(O26,$V$5:$W$99,2,FALSE) -> 0.74607462 | T26: hmacgdpd | U26: USA | V26: 2022 | W26: 1.1073887
D27: =IF(F27=G27,"*","")&"G_CUREX" -> G_CUREX | F27: USD20 | G27: ="USD"&RIGHT(O28,2) -> USD02 | H27: =ROUND($P$46/P28,4) -> 1.3986 | O27: 2001 | P27: =VLOOKUP(O27,$V$5:$W$99,2,FALSE) -> 0.76282752 | T27: hmacgdpd | U27: USA | V27: 2023 | W27: 1.1224308
D28: =IF(F28=G28,"*","")&"G_CUREX" -> G_CUREX | F28: USD20 | G28: ="USD"&RIGHT(O29,2) -> USD03 | H28: =ROUND($P$46/P29,4) -> 1.3727 | O28: 2002 | P28: =VLOOKUP(O28,$V$5:$W$99,2,FALSE) -> 0.77446032 | T28: hmacgdpd | U28: USA | V28: 2024 | W28: 1.1412873
D29: =IF(F29=G29,"*","")&"G_CUREX" -> G_CUREX | F29: USD20 | G29: ="USD"&RIGHT(O30,2) -> USD04 | H29: =ROUND($P$46/P30,4) -> 1.3369 | O29: 2003 | P29: =VLOOKUP(O29,$V$5:$W$99,2,FALSE) -> 0.78906536 | T29: hmacgdpd | U29: USA | V29: 2025 | W29: 1.1650648
... D50: =IF(F50=G50,"*","")&"G_CUREX" -> G_CUREX | F50: USD20 | G50: ="USD"&RIGHT(O51,2) -> USD25 | H50: =ROUND($P$46/P51,4) -> 0.9297 | O50: 2024 | P50: =VLOOKUP(O50,$V$5:$W$99,2,FALSE) -> 1.1412873 | T50: hmacgdpd | U50: USA | V50: 1995 | W50: 0.68678039
D51: G_DRATE | G51: =G8 -> USD83 | H51: =$O$6 -> 0.07 | O51: 2025 | P51: =VLOOKUP(O51,$V$5:$W$99,2,FALSE) -> 1.1650648 | T51: hmacgdpd | U51: USA | V51: 1996 | W51: 0.6993354
D52: G_DRATE | G52: =G9 -> USD84 | H52: =$O$6 -> 0.07 | T52: hmacgdpd | U52: USA | V52: 1997 | W52: 0.71145087
D53: G_DRATE | G53: =G10 -> USD85 | H53: =$O$6 -> 0.07 | T53: hmacgdpd | U53: USA | V53: 1998 | W53: 0.71929687
D54: G_DRATE | G54: =G11 -> USD86 | H54: =$O$6 -> 0.07 | T54: hmacgdpd | U54: USA | V54: 1999 | W54: 0.7296133
D55: G_DRATE | G55: =G12 -> USD87 | H55: =$O$6 -> 0.07 | T55: hmacgdpd | U55: USA | V55: 2000 | W55: 0.74607462
D56: G_DRATE | G56: =G13 -> USD88 | H56: =$O$6 -> 0.07
D57: G_DRATE | G57: =G14 -> USD89 | H57: =$O$6 -> 0.07
D58: G_DRATE | G58: =G15 -> USD90 | H58: =$O$6 -> 0.07
D59: G_DRATE | G59: =G16 -> USD91 | H59: =$O$6 -> 0.07
D60: G_DRATE | G60: =G17 -> USD92 | H60: =$O$6 -> 0.07
D61: G_DRATE | G61: =G18 -> USD93 | H61: =$O$6 -> 0.07
...

Sheet nuclear
A1: Current capacities | E1: ~UC_SETS: R_E: AllRegions
A3: Region | B3: GW | G3: ~UC_T: UC_RHSRT~UP | M3: Year | N3: ActiveReg | O3: Twh | P3: GW_25pc | Q3: GW_10pc | S3: ~TFM_INS
A4: Africa_north | B4: 2.4 | E4: UC_N | F4: pset_set | G4: Region | H4: *2018 | I4: 2020 | J4: 0 | K4: UC_CAP | M4: 2050 | N4: Africa_north | O4: 1362.886 | P4: 46 | Q4: 18 | S4: attribute | T4: pset_set | U4: Region | V4: value
A5: Arg-Chi | B5: 1.798 | E5: UCE_NucLimit | F5: E_Nuclear | I5: 0 | J5: 3 | K5: 1 | M5: 2050 | N5: Africa_other | O5: 2356.745 | P5: 79 | Q5: 32 | S5: START | T5: =F5 -> E_Nuclear | V5: 2150
A6: Asia_central | B6: 0.408 | G6: =IF(A4="","\I:",A4) -> Africa_north | H6: =B4 -> 2.4 | I6: =IF(VLOOKUP(G6,$N$4:$R$32,4,FALSE)>H6,VLOOKUP(G6,$N$4:$R$32,4,FALSE),H6*2) -> 18 | M6: 2050 | N6: Arg-Chi | O6: 595.601 | P6: 20 | Q6: 8 | S6: START | T6: =T5 -> E_Nuclear | U6: =G6 -> Africa_north | V6: 2022
A7: Asia_east | B7: 63.853 | G7: =IF(A5="","\I:",A5) -> Arg-Chi | H7: =B5 -> 1.798 | I7: =IF(VLOOKUP(G7,$N$4:$R$32,4,FALSE)>H7,VLOOKUP(G7,$N$4:$R$32,4,FALSE),H7*2) -> 8 | M7: 2050 | N7: Asia_central | O7: 446.348 | P7: 15 | Q7: 6 | S7: START | T7: =T6 -> E_Nuclear | U7: =G7 -> Arg-Chi | V7: 2022
A8: Asia_other | B8: 9.042 | G8: =IF(A6="","\I:",A6) -> Asia_central | H8: =B6 -> 0.408 | I8: =IF(VLOOKUP(G8,$N$4:$R$32,4,FALSE)>H8,VLOOKUP(G8,$N$4:$R$32,4,FALSE),H8*2) -> 6 | M8: 2050 | N8: Asia_east | O8: 1787.223 | P8: 60 | Q8: 24 | S8: START | T8: =T7 -> E_Nuclear | U8: =G8 -> Asia_central | V8: 2022
A9: Brazil | B9: 2.062 | G9: =IF(A7="","\I:",A7) -> Asia_east | H9: =B7 -> 63.853 | I9: =IF(VLOOKUP(G9,$N$4:$R$32,4,FALSE)>H9,VLOOKUP(G9,$N$4:$R$32,4,FALSE),H9*2) -> 127.706 | M9: 2050 | N9: Asia_other | O9: 4026.377 | P9: 135 | Q9: 54 | S9: START | T9: =T8 -> E_Nuclear | U9: =G9 -> Asia_east | V9: 2022
A10: Canada | B10: 14.519 | G10: =IF(A8="","\I:",A8) -> Asia_other | H10: =B8 -> 9.042 | I10: =IF(VLOOKUP(G10,$N$4:$R$32,4,FALSE)>H10,VLOOKUP(G10,$N$4:$R$32,4,FALSE),H10*2) -> 54 | M10: 2050 | N10: Australia_NZ | O10: 470.212 | P10: 16 | Q10: 6 | S10: START | T10: =T9 -> E_Nuclear | U10: =G10 -> Asia_other | V10: 2022
A11: China | B11: 84.77 | G11: =IF(A9="","\I:",A9) -> Brazil | H11: =B9 -> 2.062 | I11: =IF(VLOOKUP(G11,$N$4:$R$32,4,FALSE)>H11,VLOOKUP(G11,$N$4:$R$32,4,FALSE),H11*2) -> 14 | M11: 2050 | N11: Brazil | O11: 1078.937 | P11: 36 | Q11: 14 | S11: START | T11: =T10 -> E_Nuclear | U11: =G11 -> Brazil | V11: 2022
A12: EU_north | B12: 12.906 | G12: =IF(A10="","\I:",A10) -> Canada | H12: =B10 -> 14.519 | I12: =IF(VLOOKUP(G12,$N$4:$R$32,4,FALSE)>H12,VLOOKUP(G12,$N$4:$R$32,4,FALSE),H12*2) -> 29.038 | M12: 2050 | N12: Canada | O12: 790.721 | P12: 27 | Q12: 11 | S12: START | T12: =T11 -> E_Nuclear | U12: =G12 -> Canada | V12: 2022
A13: EU_northeast | B13: 6.954 | G13: =IF(A11="","\I:",A11) -> China | H13: =B11 -> 84.77 | I13: =IF(VLOOKUP(G13,$N$4:$R$32,4,FALSE)>H13,VLOOKUP(G13,$N$4:$R$32,4,FALSE),H13*2) -> 304 | M13: 2050 | N13: China | O13: 22633.933 | P13: 760 | Q13: 304 | S13: START | T13: =T12 -> E_Nuclear | U13: =G13 -> China | V13: 2022
A14: EU_northwest | B14: 5.563 | G14: =IF(A12="","\I:",A12) -> EU_north | H14: =B12 -> 12.906 | I14: =IF(VLOOKUP(G14,$N$4:$R$32,4,FALSE)>H14,VLOOKUP(G14,$N$4:$R$32,4,FALSE),H14*2) -> 25.812 | M14: 2050 | N14: EU_north | O14: 336.336 | P14: 11 | Q14: 5 | S14: START | T14: =T13 -> E_Nuclear | U14: =G14 -> EU_north | V14: 2022
A15: EU_southeast | B15: 6.177 | G15: =IF(A13="","\I:",A13) -> EU_northeast | H15: =B13 -> 6.954 | I15: =IF(VLOOKUP(G15,$N$4:$R$32,4,FALSE)>H15,VLOOKUP(G15,$N$4:$R$32,4,FALSE),H15*2)+6 -> 19.908 | M15: 2050 | N15: EU_northeast | O15: 415.174 | P15: 14 | Q15: 6 | S15: START | T15: =T14 -> E_Nuclear | U15: =G15 -> EU_northeast | V15: 2022
A16: EU_southwest | B16: 7.398 | G16: =IF(A14="","\I:",A14) -> EU_northwest | H16: =B14 -> 5.563 | I16: =IF(VLOOKUP(G16,$N$4:$R$32,4,FALSE)>H16,VLOOKUP(G16,$N$4:$R$32,4,FALSE),H16*2)+6 -> 17.126 | M16: 2050 | N16: EU_northwest | O16: 320.559 | P16: 11 | Q16: 4 | S16: START | T16: =T15 -> E_Nuclear | U16: =G16 -> EU_northwest | V16: 2022
A17: Europe_other | B17: 24.105 | G17: =IF(A15="","\I:",A15) -> EU_southeast | H17: =B15 -> 6.177 | I17: =IF(VLOOKUP(G17,$N$4:$R$32,4,FALSE)>H17,VLOOKUP(G17,$N$4:$R$32,4,FALSE),H17*2)+6 -> 18.354 | M17: 2050 | N17: EU_south | O17: 430.946 | P17: 14 | Q17: 6 | S17: START | T17: =T16 -> E_Nuclear | U17: =G17 -> EU_southeast | V17: 2022
A18: France | B18: 65.792 | G18: =IF(A16="","\I:",A16) -> EU_southwest | H18: =B16 -> 7.398 | I18: =IF(VLOOKUP(G18,$N$4:$R$32,4,FALSE)>H18,VLOOKUP(G18,$N$4:$R$32,4,FALSE),H18*2)+6 -> 20.796 | M18: 2050 | N18: EU_southeast | O18: 157.629 | P18: 5 | Q18: 2 | S18: START | T18: =T17 -> E_Nuclear | U18: =G18 -> EU_southwest | V18: 2022
A19: Germany | B19: 4.291 | G19: =IF(A17="","\I:",A17) -> Europe_other | H19: =B17 -> 24.105 | I19: =IF(VLOOKUP(G19,$N$4:$R$32,4,FALSE)>H19,VLOOKUP(G19,$N$4:$R$32,4,FALSE),H19*2) -> 48.21 | M19: 2050 | N19: EU_southwest | O19: 348.017 | P19: 12 | Q19: 5 | S19: START | T19: =T18 -> E_Nuclear | U19: =G19 -> Europe_other | V19: 2022
A20: India | B20: 17.23 | G20: =IF(A18="","\I:",A18) -> France | H20: =B18 -> 65.792 | I20: =IF(VLOOKUP(G20,$N$4:$R$32,4,FALSE)>H20,VLOOKUP(G20,$N$4:$R$32,4,FALSE),H20*2) -> 131.584 | M20: 2050 | N20: Europe_other | O20: 988.571 | P20: 33 | Q20: 13 | S20: START | T20: =T19 -> E_Nuclear | U20: =G20 -> France | V20: 2022
A21: Mexico | B21: 1.64 | G21: =IF(A19="","\I:",A19) -> Germany | H21: =B19 -> 4.291 | I21: =IF(VLOOKUP(G21,$N$4:$R$32,4,FALSE)>H21,VLOOKUP(G21,$N$4:$R$32,4,FALSE),H21*2) -> 8 | M21: 2050 | N21: France | O21: 611.054 | P21: 21 | Q21: 8 | S21: START | T21: =T20 -> E_Nuclear | U21: =G21 -> Germany | V21: 2022
A22: MidEast_other | B22: 8.98 | G22: =IF(A20="","\I:",A20) -> India | H22: =B20 -> 17.23 | I22: =IF(VLOOKUP(G22,$N$4:$R$32,4,FALSE)>H22,VLOOKUP(G22,$N$4:$R$32,4,FALSE),H22*2) -> 98 | M22: 2050 | N22: Germany | O22: 612.165 | P22: 21 | Q22: 8 | S22: START | T22: =T21 -> E_Nuclear | U22: =G22 -> India | V22: 2022
A23: Russia | B23: 32.678 | G23: =IF(A21="","\I:",A21) -> Mexico | H23: =B21 -> 1.64 | I23: =IF(VLOOKUP(G23,$N$4:$R$32,4,FALSE)>H23,VLOOKUP(G23,$N$4:$R$32,4,FALSE),H23*2) -> 8 | M23: 2050 | N23: India | O23: 7308.052 | P23: 245 | Q23: 98 | S23: START | T23: =T22 -> E_Nuclear | U23: =G23 -> Mexico | V23: 2022
A24: SouthAfrica | B24: 1.94 | G24: =IF(A22="","\I:",A22) -> MidEast_other | H24: =B22 -> 8.98 | I24: =IF(VLOOKUP(G24,$N$4:$R$32,4,FALSE)>H24,VLOOKUP(G24,$N$4:$R$32,4,FALSE),H24*2) -> 23 | M24: 2050 | N24: LatAm_other | O24: 1130.997 | P24: 38 | Q24: 15 | S24: START | T24: =T23 -> E_Nuclear | U24: =G24 -> MidEast_other | V24: 2022
A25: UK | B25: 10.224 | G25: =IF(A23="","\I:",A23) -> Russia | H25: =B23 -> 32.678 | I25: =IF(VLOOKUP(G25,$N$4:$R$32,4,FALSE)>H25,VLOOKUP(G25,$N$4:$R$32,4,FALSE),H25*2) -> 65.356 | M25: 2050 | N25: Mexico | O25: 607.858 | P25: 20 | Q25: 8 | S25: START | T25: =T24 -> E_Nuclear | U25: =G25 -> Russia | V25: 2022
A26: USA | B26: 103.496 | G26: =IF(A24="","\I:",A24) -> SouthAfrica | H26: =B24 -> 1.94 | I26: =IF(VLOOKUP(G26,$N$4:$R$32,4,FALSE)>H26,VLOOKUP(G26,$N$4:$R$32,4,FALSE),H26*2)+6 -> 11 | M26: 2050 | N26: MidEast_other | O26: 1710.293 | P26: 57 | Q26: 23 | S26: START | T26: =T25 -> E_Nuclear | U26: =G26 -> SouthAfrica | V26: 2022
G27: =IF(A25="","\I:",A25) -> UK | H27: =B25 -> 10.224 | I27: =IF(VLOOKUP(G27,$N$4:$R$32,4,FALSE)>H27,VLOOKUP(G27,$N$4:$R$32,4,FALSE),H27*2) -> 20.448 | M27: 2050 | N27: Nor-Ice | O27: 198.204 | P27: 7 | Q27: 3 | S27: START | T27: =T26 -> E_Nuclear | U27: =G27 -> UK | V27: 2022
G28: =IF(A26="","\I:",A26) -> USA | H28: =B26 -> 103.496 | I28: =IF(VLOOKUP(G28,$N$4:$R$32,4,FALSE)>H28,VLOOKUP(G28,$N$4:$R$32,4,FALSE),H28*2) -> 206.992 | M28: 2050 | N28: Russia | O28: 1241.521 | P28: 42 | Q28: 17 | S28: START | T28: =T27 -> E_Nuclear | U28: =G28 -> USA | V28: 2022
G29: =IF(A27="","\I:",A27) -> \I: | H29: =B27 -> 0 | I29: =IF(VLOOKUP(G29,$N$4:$R$32,4,FALSE)>H29,VLOOKUP(G29,$N$4:$R$32,4,FALSE),H29*1.1) -> #N/A | M29: 2050 | N29: SaudiArabia | O29: 751.373 | P29: 25 | Q29: 10 | S29: START | T29: =T28 -> E_Nuclear | U29: =G29 -> \I: | V29: 2022
M30: 2050 | N30: SouthAfrica | O30: 352.644 | P30: 12 | Q30: 5
M31: 2050 | N31: UK | O31: 474.693 | P31: 16 | Q31: 6
H32: =SUM(H6:H29) -> 488.226 | I32: =SUM(I6:I28) -> 1283.33 | M32: 2050 | N32: USA | O32: 5867.595 | P32: 197 | Q32: 79

Sheet DEF topology
B3: ~TFM_TOPINS
B4: process | C4: commodity | D4: io
B5: EN_STG8hbNREL | C5: ELC4H,ELC8H,ELC | D5: IN
B6: EN_STG4hbNREL | C6: ELC4H,ELC | D6: IN
B7: elcagg[_]???[_]??? | C7: ELC4H,ELC8H | D7: OUT
B11: ~TFM_INS-AT
B12: process | C12: pset_ci | D12: START
B13: elcagg[_]???[_]??? | C13: -elc* | D13: 2100
B17: ~UC_Sets: R_E: AllRegions
H20: ~UC_T: LO
B21: UC_N | C21: PSET_SET | D21: PSET_PN | E21: Pset_CI | F21: PSET_CO | G21: Cset_CN | H21: TimeSlice | I21: UC_CAP | J21: UC_COMPRD | K21: UC_RHSRT | L21: UC_RHSRT~0 | M21: UC_Desc
B22: UCE_Min-DispatchableCAP | C22: ELE,CHP | D22: E* | E22: *,-ELCSOL,-ELCWIN,-ELC,-ELCSPV,-elc[_]???[_]* | F22: ELC | G22: ELC | I22: 1 | K22: 0 | L22: 5 | M22: Min dispatchable capacity for VRE portfolio
G23: DEF_C | J23: -1

Sheet agg cap UC
A1: spv | C1: ~UC_Sets: R_S: Allregions | K1: won | V1: wof
C3: ~UC_T: FX | G3: ~UC_T | M3: ~UC_T: FX | Q3: ~UC_T | X3: ~UC_T: FX | AB3: ~UC_T
A4: * | B4: uc_n | C4: process | D4: uc_cap | E4: uc_rhst~0 | G4: =B4 -> uc_n | H4: =C4 -> process | I4: =D4 -> uc_cap | K4: * | L4: uc_n | M4: process | N4: uc_cap | O4: uc_rhst~0 | Q4: =L4 -> uc_n | R4: =M4 -> process | S4: =N4 -> uc_cap | V4: * | W4: uc_n | X4: process | Y4: uc_cap | Z4: uc_rhst~0 | AB4: =W4 -> uc_n | AC4: =X4 -> process | AD4: =Y4 -> uc_cap
A5: AFG | B5: ="UCE_elcaggCap_"&A$1&"_"&A5 -> UCE_elcaggCap_spv_AFG | C5: ="e?_spv_"&$A5&"*" -> e?_spv_AFG* | D5: 1 | E5: 2 | G5: =B5 -> UCE_elcaggCap_spv_AFG | H5: ="elcagg_spv_"&$A5 -> elcagg_spv_AFG | I5: -1 | K5: AFG | L5: ="UCE_elcaggCap_"&K$1&"_"&K5 -> UCE_elcaggCap_won_AFG | M5: ="e?_won_"&$K5&"*" -> e?_won_AFG* | N5: 1 | O5: 2 | Q5: =L5 -> UCE_elcaggCap_won_AFG | R5: ="elcagg_won_"&$K5 -> elcagg_won_AFG | S5: -1 | V5: AGO | W5: ="UCE_elcaggCap_"&V$1&"_"&V5 -> UCE_elcaggCap_wof_AGO | X5: ="e?_wof_"&$V5&"*" -> e?_wof_AGO* | Y5: 1 | Z5: 2 | AB5: =W5 -> UCE_elcaggCap_wof_AGO | AC5: ="elcagg_wof_"&$V5 -> elcagg_wof_AGO | AD5: -1
A6: AGO | B6: ="UCE_elcaggCap_"&A$1&"_"&A6 -> UCE_elcaggCap_spv_AGO | C6: ="e?_spv_"&$A6&"*" -> e?_spv_AGO* | D6: 1 | E6: 2 | G6: =B6 -> UCE_elcaggCap_spv_AGO | H6: ="elcagg_spv_"&$A6 -> elcagg_spv_AGO | I6: -1 | K6: AGO | L6: ="UCE_elcaggCap_"&K$1&"_"&K6 -> UCE_elcaggCap_won_AGO | M6: ="e?_won_"&$K6&"*" -> e?_won_AGO* | N6: 1 | O6: 2 | Q6: =L6 -> UCE_elcaggCap_won_AGO | R6: ="elcagg_won_"&$K6 -> elcagg_won_AGO | S6: -1 | V6: ALB | W6: ="UCE_elcaggCap_"&V$1&"_"&V6 -> UCE_elcaggCap_wof_ALB | X6: ="e?_wof_"&$V6&"*" -> e?_wof_ALB* | Y6: 1 | Z6: 2 | AB6: =W6 -> UCE_elcaggCap_wof_ALB | AC6: ="elcagg_wof_"&$V6 -> elcagg_wof_ALB | AD6: -1
A7: ALB | B7: ="UCE_elcaggCap_"&A$1&"_"&A7 -> UCE_elcaggCap_spv_ALB | C7: ="e?_spv_"&$A7&"*" -> e?_spv_ALB* | D7: 1 | E7: 2 | G7: =B7 -> UCE_elcaggCap_spv_ALB | H7: ="elcagg_spv_"&$A7 -> elcagg_spv_ALB | I7: -1 | K7: ALB | L7: ="UCE_elcaggCap_"&K$1&"_"&K7 -> UCE_elcaggCap_won_ALB | M7: ="e?_won_"&$K7&"*" -> e?_won_ALB* | N7: 1 | O7: 2 | Q7: =L7 -> UCE_elcaggCap_won_ALB | R7: ="elcagg_won_"&$K7 -> elcagg_won_ALB | S7: -1 | V7: ARE | W7: ="UCE_elcaggCap_"&V$1&"_"&V7 -> UCE_elcaggCap_wof_ARE | X7: ="e?_wof_"&$V7&"*" -> e?_wof_ARE* | Y7: 1 | Z7: 2 | AB7: =W7 -> UCE_elcaggCap_wof_ARE | AC7: ="elcagg_wof_"&$V7 -> elcagg_wof_ARE | AD7: -1
A8: ARE | B8: ="UCE_elcaggCap_"&A$1&"_"&A8 -> UCE_elcaggCap_spv_ARE | C8: ="e?_spv_"&$A8&"*" -> e?_spv_ARE* | D8: 1 | E8: 2 | G8: =B8 -> UCE_elcaggCap_spv_ARE | H8: ="elcagg_spv_"&$A8 -> elcagg_spv_ARE | I8: -1 | K8: ARE | L8: ="UCE_elcaggCap_"&K$1&"_"&K8 -> UCE_elcaggCap_won_ARE | M8: ="e?_won_"&$K8&"*" -> e?_won_ARE* | N8: 1 | O8: 2 | Q8: =L8 -> UCE_elcaggCap_won_ARE | R8: ="elcagg_won_"&$K8 -> elcagg_won_ARE | S8: -1 | V8: ARG | W8: ="UCE_elcaggCap_"&V$1&"_"&V8 -> UCE_elcaggCap_wof_ARG | X8: ="e?_wof_"&$V8&"*" -> e?_wof_ARG* | Y8: 1 | Z8: 2 | AB8: =W8 -> UCE_elcaggCap_wof_ARG | AC8: ="elcagg_wof_"&$V8 -> elcagg_wof_ARG | AD8: -1
A9: ARG | B9: ="UCE_elcaggCap_"&A$1&"_"&A9 -> UCE_elcaggCap_spv_ARG | C9: ="e?_spv_"&$A9&"*" -> e?_spv_ARG* | D9: 1 | E9: 2 | G9: =B9 -> UCE_elcaggCap_spv_ARG | H9: ="elcagg_spv_"&$A9 -> elcagg_spv_ARG | I9: -1 | K9: ARG | L9: ="UCE_elcaggCap_"&K$1&"_"&K9 -> UCE_elcaggCap_won_ARG | M9: ="e?_won_"&$K9&"*" -> e?_won_ARG* | N9: 1 | O9: 2 | Q9: =L9 -> UCE_elcaggCap_won_ARG | R9: ="elcagg_won_"&$K9 -> elcagg_won_ARG | S9: -1 | V9: AUS | W9: ="UCE_elcaggCap_"&V$1&"_"&V9 -> UCE_elcaggCap_wof_AUS | X9: ="e?_wof_"&$V9&"*" -> e?_wof_AUS* | Y9: 1 | Z9: 2 | AB9: =W9 -> UCE_elcaggCap_wof_AUS | AC9: ="elcagg_wof_"&$V9 -> elcagg_wof_AUS | AD9: -1
A10: ARM | B10: ="UCE_elcaggCap_"&A$1&"_"&A10 -> UCE_elcaggCap_spv_ARM | C10: ="e?_spv_"&$A10&"*" -> e?_spv_ARM* | D10: 1 | E10: 2 | G10: =B10 -> UCE_elcaggCap_spv_ARM | H10: ="elcagg_spv_"&$A10 -> elcagg_spv_ARM | I10: -1 | K10: ARM | L10: ="UCE_elcaggCap_"&K$1&"_"&K10 -> UCE_elcaggCap_won_ARM | M10: ="e?_won_"&$K10&"*" -> e?_won_ARM* | N10: 1 | O10: 2 | Q10: =L10 -> UCE_elcaggCap_won_ARM | R10: ="elcagg_won_"&$K10 -> elcagg_won_ARM | S10: -1 | V10: AZE | W10: ="UCE_elcaggCap_"&V$1&"_"&V10 -> UCE_elcaggCap_wof_AZE | X10: ="e?_wof_"&$V10&"*" -> e?_wof_AZE* | Y10: 1 | Z10: 2 | AB10: =W10 -> UCE_elcaggCap_wof_AZE | AC10: ="elcagg_wof_"&$V10 -> elcagg_wof_AZE | AD10: -1
A11: AUS | B11: ="UCE_elcaggCap_"&A$1&"_"&A11 -> UCE_elcaggCap_spv_AUS | C11: ="e?_spv_"&$A11&"*" -> e?_spv_AUS* | D11: 1 | E11: 2 | G11: =B11 -> UCE_elcaggCap_spv_AUS | H11: ="elcagg_spv_"&$A11 -> elcagg_spv_AUS | I11: -1 | K11: AUS | L11: ="UCE_elcaggCap_"&K$1&"_"&K11 -> UCE_elcaggCap_won_AUS | M11: ="e?_won_"&$K11&"*" -> e?_won_AUS* | N11: 1 | O11: 2 | Q11: =L11 -> UCE_elcaggCap_won_AUS | R11: ="elcagg_won_"&$K11 -> elcagg_won_AUS | S11: -1 | V11: BEN | W11: ="UCE_elcaggCap_"&V$1&"_"&V11 -> UCE_elcaggCap_wof_BEN | X11: ="e?_wof_"&$V11&"*" -> e?_wof_BEN* | Y11: 1 | Z11: 2 | AB11: =W11 -> UCE_elcaggCap_wof_BEN | AC11: ="elcagg_wof_"&$V11 -> elcagg_wof_BEN | AD11: -1
A12: AUT | B12: ="UCE_elcaggCap_"&A$1&"_"&A12 -> UCE_elcaggCap_spv_AUT | C12: ="e?_spv_"&$A12&"*" -> e?_spv_AUT* | D12: 1 | E12: 2 | G12: =B12 -> UCE_elcaggCap_spv_AUT | H12: ="elcagg_spv_"&$A12 -> elcagg_spv_AUT | I12: -1 | K12: AUT | L12: ="UCE_elcaggCap_"&K$1&"_"&K12 -> UCE_elcaggCap_won_AUT | M12: ="e?_won_"&$K12&"*" -> e?_won_AUT* | N12: 1 | O12: 2 | Q12: =L12 -> UCE_elcaggCap_won_AUT | R12: ="elcagg_won_"&$K12 -> elcagg_won_AUT | S12: -1 | V12: BGD | W12: ="UCE_elcaggCap_"&V$1&"_"&V12 -> UCE_elcaggCap_wof_BGD | X12: ="e?_wof_"&$V12&"*" -> e?_wof_BGD* | Y12: 1 | Z12: 2 | AB12: =W12 -> UCE_elcaggCap_wof_BGD | AC12: ="elcagg_wof_"&$V12 -> elcagg_wof_BGD | AD12: -1
A13: AZE | B13: ="UCE_elcaggCap_"&A$1&"_"&A13 -> UCE_elcaggCap_spv_AZE | C13: ="e?_spv_"&$A13&"*" -> e?_spv_AZE* | D13: 1 | E13: 2 | G13: =B13 -> UCE_elcaggCap_spv_AZE | H13: ="elcagg_spv_"&$A13 -> elcagg_spv_AZE | I13: -1 | K13: AZE | L13: ="UCE_elcaggCap_"&K$1&"_"&K13 -> UCE_elcaggCap_won_AZE | M13: ="e?_won_"&$K13&"*" -> e?_won_AZE* | N13: 1 | O13: 2 | Q13: =L13 -> UCE_elcaggCap_won_AZE | R13: ="elcagg_won_"&$K13 -> elcagg_won_AZE | S13: -1 | V13: BGR | W13: ="UCE_elcaggCap_"&V$1&"_"&V13 -> UCE_elcaggCap_wof_BGR | X13: ="e?_wof_"&$V13&"*" -> e?_wof_BGR* | Y13: 1 | Z13: 2 | AB13: =W13 -> UCE_elcaggCap_wof_BGR | AC13: ="elcagg_wof_"&$V13 -> elcagg_wof_BGR | AD13: -1
A14: BDI | B14: ="UCE_elcaggCap_"&A$1&"_"&A14 -> UCE_elcaggCap_spv_BDI | C14: ="e?_spv_"&$A14&"*" -> e?_spv_BDI* | D14: 1 | E14: 2 | G14: =B14 -> UCE_elcaggCap_spv_BDI | H14: ="elcagg_spv_"&$A14 -> elcagg_spv_BDI | I14: -1 | K14: BDI | L14: ="UCE_elcaggCap_"&K$1&"_"&K14 -> UCE_elcaggCap_won_BDI | M14: ="e?_won_"&$K14&"*" -> e?_won_BDI* | N14: 1 | O14: 2 | Q14: =L14 -> UCE_elcaggCap_won_BDI | R14: ="elcagg_won_"&$K14 -> elcagg_won_BDI | S14: -1 | V14: BRA | W14: ="UCE_elcaggCap_"&V$1&"_"&V14 -> UCE_elcaggCap_wof_BRA | X14: ="e?_wof_"&$V14&"*" -> e?_wof_BRA* | Y14: 1 | Z14: 2 | AB14: =W14 -> UCE_elcaggCap_wof_BRA | AC14: ="elcagg_wof_"&$V14 -> elcagg_wof_BRA | AD14: -1
A15: BEL | B15: ="UCE_elcaggCap_"&A$1&"_"&A15 -> UCE_elcaggCap_spv_BEL | C15: ="e?_spv_"&$A15&"*" -> e?_spv_BEL* | D15: 1 | E15: 2 | G15: =B15 -> UCE_elcaggCap_spv_BEL | H15: ="elcagg_spv_"&$A15 -> elcagg_spv_BEL | I15: -1 | K15: BEL | L15: ="UCE_elcaggCap_"&K$1&"_"&K15 -> UCE_elcaggCap_won_BEL | M15: ="e?_won_"&$K15&"*" -> e?_won_BEL* | N15: 1 | O15: 2 | Q15: =L15 -> UCE_elcaggCap_won_BEL | R15: ="elcagg_won_"&$K15 -> elcagg_won_BEL | S15: -1 | V15: CAN | W15: ="UCE_elcaggCap_"&V$1&"_"&V15 -> UCE_elcaggCap_wof_CAN | X15: ="e?_wof_"&$V15&"*" -> e?_wof_CAN* | Y15: 1 | Z15: 2 | AB15: =W15 -> UCE_elcaggCap_wof_CAN | AC15: ="elcagg_wof_"&$V15 -> elcagg_wof_CAN | AD15: -1
A16: BEN | B16: ="UCE_elcaggCap_"&A$1&"_"&A16 -> UCE_elcaggCap_spv_BEN | C16: ="e?_spv_"&$A16&"*" -> e?_spv_BEN* | D16: 1 | E16: 2 | G16: =B16 -> UCE_elcaggCap_spv_BEN | H16: ="elcagg_spv_"&$A16 -> elcagg_spv_BEN | I16: -1 | K16: BEN | L16: ="UCE_elcaggCap_"&K$1&"_"&K16 -> UCE_elcaggCap_won_BEN | M16: ="e?_won_"&$K16&"*" -> e?_won_BEN* | N16: 1 | O16: 2 | Q16: =L16 -> UCE_elcaggCap_won_BEN | R16: ="elcagg_won_"&$K16 -> elcagg_won_BEN | S16: -1 | V16: CHL | W16: ="UCE_elcaggCap_"&V$1&"_"&V16 -> UCE_elcaggCap_wof_CHL | X16: ="e?_wof_"&$V16&"*" -> e?_wof_CHL* | Y16: 1 | Z16: 2 | AB16: =W16 -> UCE_elcaggCap_wof_CHL | AC16: ="elcagg_wof_"&$V16 -> elcagg_wof_CHL | AD16: -1
... A120: PRK | B120: ="UCE_elcaggCap_"&A$1&"_"&A120 -> UCE_elcaggCap_spv_PRK | C120: ="e?_spv_"&$A120&"*" -> e?_spv_PRK* | D120: 1 | E120: 2 | G120: =B120 -> UCE_elcaggCap_spv_PRK | H120: ="elcagg_spv_"&$A120 -> elcagg_spv_PRK | I120: -1 | K120: PRI | L120: ="UCE_elcaggCap_"&K$1&"_"&K120 -> UCE_elcaggCap_won_PRI | M120: ="e?_won_"&$K120&"*" -> e?_won_PRI* | N120: 1 | O120: 2 | Q120: =L120 -> UCE_elcaggCap_won_PRI | R120: ="elcagg_won_"&$K120 -> elcagg_won_PRI | S120: -1 | V120: ZAF | W120: ="UCE_elcaggCap_"&V$1&"_"&V120 -> UCE_elcaggCap_wof_ZAF | X120: ="e?_wof_"&$V120&"*" -> e?_wof_ZAF* | Y120: 1 | Z120: 2 | AB120: =W120 -> UCE_elcaggCap_wof_ZAF | AC120: ="elcagg_wof_"&$V120 -> elcagg_wof_ZAF | AD120: -1
A121: PRT | B121: ="UCE_elcaggCap_"&A$1&"_"&A121 -> UCE_elcaggCap_spv_PRT | C121: ="e?_spv_"&$A121&"*" -> e?_spv_PRT* | D121: 1 | E121: 2 | G121: =B121 -> UCE_elcaggCap_spv_PRT | H121: ="elcagg_spv_"&$A121 -> elcagg_spv_PRT | I121: -1 | K121: PRK | L121: ="UCE_elcaggCap_"&K$1&"_"&K121 -> UCE_elcaggCap_won_PRK | M121: ="e?_won_"&$K121&"*" -> e?_won_PRK* | N121: 1 | O121: 2 | Q121: =L121 -> UCE_elcaggCap_won_PRK | R121: ="elcagg_won_"&$K121 -> elcagg_won_PRK | S121: -1
A122: PRY | B122: ="UCE_elcaggCap_"&A$1&"_"&A122 -> UCE_elcaggCap_spv_PRY | C122: ="e?_spv_"&$A122&"*" -> e?_spv_PRY* | D122: 1 | E122: 2 | G122: =B122 -> UCE_elcaggCap_spv_PRY | H122: ="elcagg_spv_"&$A122 -> elcagg_spv_PRY | I122: -1 | K122: PRT | L122: ="UCE_elcaggCap_"&K$1&"_"&K122 -> UCE_elcaggCap_won_PRT | M122: ="e?_won_"&$K122&"*" -> e?_won_PRT* | N122: 1 | O122: 2 | Q122: =L122 -> UCE_elcaggCap_won_PRT | R122: ="elcagg_won_"&$K122 -> elcagg_won_PRT | S122: -1
A123: QAT | B123: ="UCE_elcaggCap_"&A$1&"_"&A123 -> UCE_elcaggCap_spv_QAT | C123: ="e?_spv_"&$A123&"*" -> e?_spv_QAT* | D123: 1 | E123: 2 | G123: =B123 -> UCE_elcaggCap_spv_QAT | H123: ="elcagg_spv_"&$A123 -> elcagg_spv_QAT | I123: -1 | K123: PRY | L123: ="UCE_elcaggCap_"&K$1&"_"&K123 -> UCE_elcaggCap_won_PRY | M123: ="e?_won_"&$K123&"*" -> e?_won_PRY* | N123: 1 | O123: 2 | Q123: =L123 -> UCE_elcaggCap_won_PRY | R123: ="elcagg_won_"&$K123 -> elcagg_won_PRY | S123: -1
A124: ROU | B124: ="UCE_elcaggCap_"&A$1&"_"&A124 -> UCE_elcaggCap_spv_ROU | C124: ="e?_spv_"&$A124&"*" -> e?_spv_ROU* | D124: 1 | E124: 2 | G124: =B124 -> UCE_elcaggCap_spv_ROU | H124: ="elcagg_spv_"&$A124 -> elcagg_spv_ROU | I124: -1 | K124: QAT | L124: ="UCE_elcaggCap_"&K$1&"_"&K124 -> UCE_elcaggCap_won_QAT | M124: ="e?_won_"&$K124&"*" -> e?_won_QAT* | N124: 1 | O124: 2 | Q124: =L124 -> UCE_elcaggCap_won_QAT | R124: ="elcagg_won_"&$K124 -> elcagg_won_QAT | S124: -1
A125: RUS | B125: ="UCE_elcaggCap_"&A$1&"_"&A125 -> UCE_elcaggCap_spv_RUS | C125: ="e?_spv_"&$A125&"*" -> e?_spv_RUS* | D125: 1 | E125: 2 | G125: =B125 -> UCE_elcaggCap_spv_RUS | H125: ="elcagg_spv_"&$A125 -> elcagg_spv_RUS | I125: -1 | K125: ROU | L125: ="UCE_elcaggCap_"&K$1&"_"&K125 -> UCE_elcaggCap_won_ROU | M125: ="e?_won_"&$K125&"*" -> e?_won_ROU* | N125: 1 | O125: 2 | Q125: =L125 -> UCE_elcaggCap_won_ROU | R125: ="elcagg_won_"&$K125 -> elcagg_won_ROU | S125: -1
A126: RWA | B126: ="UCE_elcaggCap_"&A$1&"_"&A126 -> UCE_elcaggCap_spv_RWA | C126: ="e?_spv_"&$A126&"*" -> e?_spv_RWA* | D126: 1 | E126: 2 | G126: =B126 -> UCE_elcaggCap_spv_RWA | H126: ="elcagg_spv_"&$A126 -> elcagg_spv_RWA | I126: -1 | K126: RUS | L126: ="UCE_elcaggCap_"&K$1&"_"&K126 -> UCE_elcaggCap_won_RUS | M126: ="e?_won_"&$K126&"*" -> e?_won_RUS* | N126: 1 | O126: 2 | Q126: =L126 -> UCE_elcaggCap_won_RUS | R126: ="elcagg_won_"&$K126 -> elcagg_won_RUS | S126: -1
A127: SAU | B127: ="UCE_elcaggCap_"&A$1&"_"&A127 -> UCE_elcaggCap_spv_SAU | C127: ="e?_spv_"&$A127&"*" -> e?_spv_SAU* | D127: 1 | E127: 2 | G127: =B127 -> UCE_elcaggCap_spv_SAU | H127: ="elcagg_spv_"&$A127 -> elcagg_spv_SAU | I127: -1 | K127: RWA | L127: ="UCE_elcaggCap_"&K$1&"_"&K127 -> UCE_elcaggCap_won_RWA | M127: ="e?_won_"&$K127&"*" -> e?_won_RWA* | N127: 1 | O127: 2 | Q127: =L127 -> UCE_elcaggCap_won_RWA | R127: ="elcagg_won_"&$K127 -> elcagg_won_RWA | S127: -1
A128: SDN | B128: ="UCE_elcaggCap_"&A$1&"_"&A128 -> UCE_elcaggCap_spv_SDN | C128: ="e?_spv_"&$A128&"*" -> e?_spv_SDN* | D128: 1 | E128: 2 | G128: =B128 -> UCE_elcaggCap_spv_SDN | H128: ="elcagg_spv_"&$A128 -> elcagg_spv_SDN | I128: -1 | K128: SAU | L128: ="UCE_elcaggCap_"&K$1&"_"&K128 -> UCE_elcaggCap_won_SAU | M128: ="e?_won_"&$K128&"*" -> e?_won_SAU* | N128: 1 | O128: 2 | Q128: =L128 -> UCE_elcaggCap_won_SAU | R128: ="elcagg_won_"&$K128 -> elcagg_won_SAU | S128: -1
A129: SEN | B129: ="UCE_elcaggCap_"&A$1&"_"&A129 -> UCE_elcaggCap_spv_SEN | C129: ="e?_spv_"&$A129&"*" -> e?_spv_SEN* | D129: 1 | E129: 2 | G129: =B129 -> UCE_elcaggCap_spv_SEN | H129: ="elcagg_spv_"&$A129 -> elcagg_spv_SEN | I129: -1 | K129: SDN | L129: ="UCE_elcaggCap_"&K$1&"_"&K129 -> UCE_elcaggCap_won_SDN | M129: ="e?_won_"&$K129&"*" -> e?_won_SDN* | N129: 1 | O129: 2 | Q129: =L129 -> UCE_elcaggCap_won_SDN | R129: ="elcagg_won_"&$K129 -> elcagg_won_SDN | S129: -1
A130: SGP | B130: ="UCE_elcaggCap_"&A$1&"_"&A130 -> UCE_elcaggCap_spv_SGP | C130: ="e?_spv_"&$A130&"*" -> e?_spv_SGP* | D130: 1 | E130: 2 | G130: =B130 -> UCE_elcaggCap_spv_SGP | H130: ="elcagg_spv_"&$A130 -> elcagg_spv_SGP | I130: -1 | K130: SEN | L130: ="UCE_elcaggCap_"&K$1&"_"&K130 -> UCE_elcaggCap_won_SEN | M130: ="e?_won_"&$K130&"*" -> e?_won_SEN* | N130: 1 | O130: 2 | Q130: =L130 -> UCE_elcaggCap_won_SEN | R130: ="elcagg_won_"&$K130 -> elcagg_won_SEN | S130: -1
A131: SLE | B131: ="UCE_elcaggCap_"&A$1&"_"&A131 -> UCE_elcaggCap_spv_SLE | C131: ="e?_spv_"&$A131&"*" -> e?_spv_SLE* | D131: 1 | E131: 2 | G131: =B131 -> UCE_elcaggCap_spv_SLE | H131: ="elcagg_spv_"&$A131 -> elcagg_spv_SLE | I131: -1 | K131: SGP | L131: ="UCE_elcaggCap_"&K$1&"_"&K131 -> UCE_elcaggCap_won_SGP | M131: ="e?_won_"&$K131&"*" -> e?_won_SGP* | N131: 1 | O131: 2 | Q131: =L131 -> UCE_elcaggCap_won_SGP | R131: ="elcagg_won_"&$K131 -> elcagg_won_SGP | S131: -1
A132: SLV | B132: ="UCE_elcaggCap_"&A$1&"_"&A132 -> UCE_elcaggCap_spv_SLV | C132: ="e?_spv_"&$A132&"*" -> e?_spv_SLV* | D132: 1 | E132: 2 | G132: =B132 -> UCE_elcaggCap_spv_SLV | H132: ="elcagg_spv_"&$A132 -> elcagg_spv_SLV | I132: -1 | K132: SLE | L132: ="UCE_elcaggCap_"&K$1&"_"&K132 -> UCE_elcaggCap_won_SLE | M132: ="e?_won_"&$K132&"*" -> e?_won_SLE* | N132: 1 | O132: 2 | Q132: =L132 -> UCE_elcaggCap_won_SLE | R132: ="elcagg_won_"&$K132 -> elcagg_won_SLE | S132: -1
... A160: ZWE | B160: ="UCE_elcaggCap_"&A$1&"_"&A160 -> UCE_elcaggCap_spv_ZWE | C160: ="e?_spv_"&$A160&"*" -> e?_spv_ZWE* | D160: 1 | E160: 2 | G160: =B160 -> UCE_elcaggCap_spv_ZWE | H160: ="elcagg_spv_"&$A160 -> elcagg_spv_ZWE | I160: -1 | K160: ZAF | L160: ="UCE_elcaggCap_"&K$1&"_"&K160 -> UCE_elcaggCap_won_ZAF | M160: ="e?_won_"&$K160&"*" -> e?_won_ZAF* | N160: 1 | O160: 2 | Q160: =L160 -> UCE_elcaggCap_won_ZAF | R160: ="elcagg_won_"&$K160 -> elcagg_won_ZAF | S160: -1
K161: ZMB | L161: ="UCE_elcaggCap_"&K$1&"_"&K161 -> UCE_elcaggCap_won_ZMB | M161: ="e?_won_"&$K161&"*" -> e?_won_ZMB* | N161: 1 | O161: 2 | Q161: =L161 -> UCE_elcaggCap_won_ZMB | R161: ="elcagg_won_"&$K161 -> elcagg_won_ZMB | S161: -1
K162: ZWE | L162: ="UCE_elcaggCap_"&K$1&"_"&K162 -> UCE_elcaggCap_won_ZWE | M162: ="e?_won_"&$K162&"*" -> e?_won_ZWE* | N162: 1 | O162: 2 | Q162: =L162 -> UCE_elcaggCap_won_ZWE | R162: ="elcagg_won_"&$K162 -> elcagg_won_ZWE | S162: -1

Sheet Grid ext UCs
D1: ~UC_SETS: R_S: AllRegions
D3: ~UC_T: UC_RHST~UP | K3: ~UC_T
B4: UC_N | C4: PSET_CI | D4: PSET_PN | E4: UC_ACT | F4: UC_RHST~0 | G4: 2030 | J4: UC_N | K4: PSET_PN | L4: UC_ACT | M4: UC_Desc
B5: ="UC_CountryLev_RE_Steps-"&'Grid ext bounds'!A5 -> UC_CountryLev_RE_Steps-AFG | C5: ELCSPV,ELCWIN | D5: ="*"&'Grid ext bounds'!A5&"*,-*BySt*" -> *AFG*,-*BySt* | E5: 1 | F5: 0 | G5: 0 | J5: =B5 -> UC_CountryLev_RE_Steps-AFG | K5: =LEFT('Grid ext bounds'!E5,14)&"*" -> NatGrdExt_AFG_* | L5: -1 | M5: ="Grid expansion penalties for solar/wind generation - "&'Grid ext bounds'!B5 -> Grid expansion penalties for solar/wind generation - Afghanistan
B6: ="UC_CountryLev_RE_Steps-"&'Grid ext bounds'!A6 -> UC_CountryLev_RE_Steps-AGO | C6: ELCSPV,ELCWIN | D6: ="*"&'Grid ext bounds'!A6&"*,-*BySt*" -> *AGO*,-*BySt* | E6: 1 | F6: 3 | G6: 0 | J6: =B6 -> UC_CountryLev_RE_Steps-AGO | K6: =LEFT('Grid ext bounds'!E6,14)&"*" -> NatGrdExt_AGO_* | L6: -1 | M6: ="Grid expansion penalties for solar/wind generation - "&'Grid ext bounds'!B6 -> Grid expansion penalties for solar/wind generation - Angola
B7: ="UC_CountryLev_RE_Steps-"&'Grid ext bounds'!A7 -> UC_CountryLev_RE_Steps-ALB | C7: ELCSPV,ELCWIN | D7: ="*"&'Grid ext bounds'!A7&"*,-*BySt*" -> *ALB*,-*BySt* | E7: 1 | F7: 3 | G7: 0 | J7: =B7 -> UC_CountryLev_RE_Steps-ALB | K7: =LEFT('Grid ext bounds'!E7,14)&"*" -> NatGrdExt_ALB_* | L7: -1 | M7: ="Grid expansion penalties for solar/wind generation - "&'Grid ext bounds'!B7 -> Grid expansion penalties for solar/wind generation - Albania
B8: ="UC_CountryLev_RE_Steps-"&'Grid ext bounds'!A8 -> UC_CountryLev_RE_Steps-ARE | C8: ELCSPV,ELCWIN | D8: ="*"&'Grid ext bounds'!A8&"*,-*BySt*" -> *ARE*,-*BySt* | E8: 1 | F8: 3 | G8: 0 | J8: =B8 -> UC_CountryLev_RE_Steps-ARE | K8: =LEFT('Grid ext bounds'!E8,14)&"*" -> NatGrdExt_ARE_* | L8: -1 | M8: ="Grid expansion penalties for solar/wind generation - "&'Grid ext bounds'!B8 -> Grid expansion penalties for solar/wind generation - United Arab Emirates
B9: ="UC_CountryLev_RE_Steps-"&'Grid ext bounds'!A9 -> UC_CountryLev_RE_Steps-ARG | C9: ELCSPV,ELCWIN | D9: ="*"&'Grid ext bounds'!A9&"*,-*BySt*" -> *ARG*,-*BySt* | E9: 1 | F9: 3 | G9: 0 | J9: =B9 -> UC_CountryLev_RE_Steps-ARG | K9: =LEFT('Grid ext bounds'!E9,14)&"*" -> NatGrdExt_ARG_* | L9: -1 | M9: ="Grid expansion penalties for solar/wind generation - "&'Grid ext bounds'!B9 -> Grid expansion penalties for solar/wind generation - Argentina
B10: ="UC_CountryLev_RE_Steps-"&'Grid ext bounds'!A10 -> UC_CountryLev_RE_Steps-ARM | C10: ELCSPV,ELCWIN | D10: ="*"&'Grid ext bounds'!A10&"*,-*BySt*" -> *ARM*,-*BySt* | E10: 1 | F10: 3 | G10: 0 | J10: =B10 -> UC_CountryLev_RE_Steps-ARM | K10: =LEFT('Grid ext bounds'!E10,14)&"*" -> NatGrdExt_ARM_* | L10: -1 | M10: ="Grid expansion penalties for solar/wind generation - "&'Grid ext bounds'!B10 -> Grid expansion penalties for solar/wind generation - Armenia
B11: ="UC_CountryLev_RE_Steps-"&'Grid ext bounds'!A11 -> UC_CountryLev_RE_Steps-ATG | C11: ELCSPV,ELCWIN | D11: ="*"&'Grid ext bounds'!A11&"*,-*BySt*" -> *ATG*,-*BySt* | E11: 1 | F11: 3 | G11: 0 | J11: =B11 -> UC_CountryLev_RE_Steps-ATG | K11: =LEFT('Grid ext bounds'!E11,14)&"*" -> NatGrdExt_ATG_* | L11: -1 | M11: ="Grid expansion penalties for solar/wind generation - "&'Grid ext bounds'!B11 -> Grid expansion penalties for solar/wind generation - Antigua and Barbuda
B12: ="UC_CountryLev_RE_Steps-"&'Grid ext bounds'!A12 -> UC_CountryLev_RE_Steps-AUS | C12: ELCSPV,ELCWIN | D12: ="*"&'Grid ext bounds'!A12&"*,-*BySt*" -> *AUS*,-*BySt* | E12: 1 | F12: 3 | G12: 0 | J12: =B12 -> UC_CountryLev_RE_Steps-AUS | K12: =LEFT('Grid ext bounds'!E12,14)&"*" -> NatGrdExt_AUS_* | L12: -1 | M12: ="Grid expansion penalties for solar/wind generation - "&'Grid ext bounds'!B12 -> Grid expansion penalties for solar/wind generation - Australia
B13: ="UC_CountryLev_RE_Steps-"&'Grid ext bounds'!A13 -> UC_CountryLev_RE_Steps-AUT | C13: ELCSPV,ELCWIN | D13: ="*"&'Grid ext bounds'!A13&"*,-*BySt*" -> *AUT*,-*BySt* | E13: 1 | F13: 3 | G13: 0 | J13: =B13 -> UC_CountryLev_RE_Steps-AUT | K13: =LEFT('Grid ext bounds'!E13,14)&"*" -> NatGrdExt_AUT_* | L13: -1 | M13: ="Grid expansion penalties for solar/wind generation - "&'Grid ext bounds'!B13 -> Grid expansion penalties for solar/wind generation - Austria
B14: ="UC_CountryLev_RE_Steps-"&'Grid ext bounds'!A14 -> UC_CountryLev_RE_Steps-AZE | C14: ELCSPV,ELCWIN | D14: ="*"&'Grid ext bounds'!A14&"*,-*BySt*" -> *AZE*,-*BySt* | E14: 1 | F14: 3 | G14: 0 | J14: =B14 -> UC_CountryLev_RE_Steps-AZE | K14: =LEFT('Grid ext bounds'!E14,14)&"*" -> NatGrdExt_AZE_* | L14: -1 | M14: ="Grid expansion penalties for solar/wind generation - "&'Grid ext bounds'!B14 -> Grid expansion penalties for solar/wind generation - Azerbaijan
B15: ="UC_CountryLev_RE_Steps-"&'Grid ext bounds'!A15 -> UC_CountryLev_RE_Steps-BDI | C15: ELCSPV,ELCWIN | D15: ="*"&'Grid ext bounds'!A15&"*,-*BySt*" -> *BDI*,-*BySt* | E15: 1 | F15: 3 | G15: 0 | J15: =B15 -> UC_CountryLev_RE_Steps-BDI | K15: =LEFT('Grid ext bounds'!E15,14)&"*" -> NatGrdExt_BDI_* | L15: -1 | M15: ="Grid expansion penalties for solar/wind generation - "&'Grid ext bounds'!B15 -> Grid expansion penalties for solar/wind generation - Burundi
B16: ="UC_CountryLev_RE_Steps-"&'Grid ext bounds'!A16 -> UC_CountryLev_RE_Steps-BEL | C16: ELCSPV,ELCWIN | D16: ="*"&'Grid ext bounds'!A16&"*,-*BySt*" -> *BEL*,-*BySt* | E16: 1 | F16: 3 | G16: 0 | J16: =B16 -> UC_CountryLev_RE_Steps-BEL | K16: =LEFT('Grid ext bounds'!E16,14)&"*" -> NatGrdExt_BEL_* | L16: -1 | M16: ="Grid expansion penalties for solar/wind generation - "&'Grid ext bounds'!B16 -> Grid expansion penalties for solar/wind generation - Belgium
... B172: ="UC_CountryLev_RE_Steps-"&'Grid ext bounds'!A172 -> UC_CountryLev_RE_Steps-ZWE | C172: ELCSPV,ELCWIN | D172: ="*"&'Grid ext bounds'!A172&"*,-*BySt*" -> *ZWE*,-*BySt* | E172: 1 | F172: 3 | G172: 0 | J172: =B172 -> UC_CountryLev_RE_Steps-ZWE | K172: =LEFT('Grid ext bounds'!E172,14)&"*" -> NatGrdExt_ZWE_* | L172: -1 | M172: ="Grid expansion penalties for solar/wind generation - "&'Grid ext bounds'!B172 -> Grid expansion penalties for solar/wind generation - Zimbabwe

Sheet Grid ext bounds
Z1: =SUM(Z5:Z14) -> 4.6
A3: Countries in REZoning data | E3: ~TFM_DINS-TS: attribute=CAP_BND; limtype=UP | Q3: SSP3
A4: RegionCode | B4: RegionName | E4: process | F4: 2025 | G4: 2030 | H4: 2040 | I4: 2050 | J4: 2060 | K4: 2070 | L4: 2080 | M4: 2090 | N4: 2095 | O4: 0 | R4: ISO | S4: Year | T4: SSP1 | U4: SSP2 | V4: SSP3 | Y4: step | Z4: share
A5: AFG | B5: Afghanistan | C5: 1 | E5: ="NatGrdExt_"&A5&"_"&C5 -> NatGrdExt_AFG_1 | F5: =SUMIFS($Q$5:$Q$19999,$R$5:$R$19999,RIGHT($A5,3),$S$5:$S$19999,F$4)*VLOOKUP($C5,$Y$5:$Z$15,2,FALSE)/8.76+SUMIF($Y$5:$Y$15,$C5,$AA$5:$AA$15) -> 2.9283105 | G5: =MAX(F5,SUMIFS($Q$5:$Q$19999,$R$5:$R$19999,RIGHT($A5,3),$S$5:$S$19999,G$4)*VLOOKUP($C5,$Y$5:$Z$15,2,FALSE)/8.76)+SUMIF($Y$5:$Y$15,$C5,$AA$5:$AA$15) -> 3.9722603 | H5: =MAX(G5,SUMIFS($Q$5:$Q$19999,$R$5:$R$19999,RIGHT($A5,3),$S$5:$S$19999,H$4)*VLOOKUP($C5,$Y$5:$Z$15,2,FALSE)/8.76)+SUMIF($Y$5:$Y$15,$C5,$AA$5:$AA$15) -> 7.1941781 | I5: =MAX(H5,SUMIFS($Q$5:$Q$19999,$R$5:$R$19999,RIGHT($A5,3),$S$5:$S$19999,I$4)*VLOOKUP($C5,$Y$5:$Z$15,2,FALSE)/8.76)+SUMIF($Y$5:$Y$15,$C5,$AA$5:$AA$15) -> 12.199087 | J5: =MAX(I5,SUMIFS($Q$5:$Q$19999,$R$5:$R$19999,RIGHT($A5,3),$S$5:$S$19999,J$4)*VLOOKUP($C5,$Y$5:$Z$15,2,FALSE)/8.76)+SUMIF($Y$5:$Y$15,$C5,$AA$5:$AA$15) -> 19.423973 | K5: =MAX(J5,SUMIFS($Q$5:$Q$19999,$R$5:$R$19999,RIGHT($A5,3),$S$5:$S$19999,K$4)*VLOOKUP($C5,$Y$5:$Z$15,2,FALSE)/8.76)+SUMIF($Y$5:$Y$15,$C5,$AA$5:$AA$15) -> 28.764269 | L5: =MAX(K5,SUMIFS($Q$5:$Q$19999,$R$5:$R$19999,RIGHT($A5,3),$S$5:$S$19999,L$4)*VLOOKUP($C5,$Y$5:$Z$15,2,FALSE)/8.76)+SUMIF($Y$5:$Y$15,$C5,$AA$5:$AA$15) -> 39.810959 | M5: =MAX(L5,SUMIFS($Q$5:$Q$19999,$R$5:$R$19999,RIGHT($A5,3),$S$5:$S$19999,M$4)*VLOOKUP($C5,$Y$5:$Z$15,2,FALSE)/8.76)+SUMIF($Y$5:$Y$15,$C5,$AA$5:$AA$15) -> 51.89258 | N5: =MAX(M5,SUMIFS($Q$5:$Q$19999,$R$5:$R$19999,RIGHT($A5,3),$S$5:$S$19999,N$4)*VLOOKUP($C5,$Y$5:$Z$15,2,FALSE)/8.76)+SUMIF($Y$5:$Y$15,$C5,$AA$5:$AA$15) -> 57.976941 | O5: 3 | Q5: =OFFSET(S5,0,MATCH($Q$3,$T$4:$V$4,0)) -> 0.601 | R5: ABW | S5: 2020 | T5: 0.601 | U5: 0.601 | V5: 0.601 | Y5: 1 | Z5: 1
A6: AGO | B6: Angola | C6: 1 | E6: ="NatGrdExt_"&A6&"_"&C6 -> NatGrdExt_AGO_1 | F6: =SUMIFS($Q$5:$Q$19999,$R$5:$R$19999,RIGHT($A6,3),$S$5:$S$19999,F$4)*VLOOKUP($C6,$Y$5:$Z$15,2,FALSE)/8.76+SUMIF($Y$5:$Y$15,$C6,$AA$5:$AA$15) -> 3.0006849 | G6: =MAX(F6,SUMIFS($Q$5:$Q$19999,$R$5:$R$19999,RIGHT($A6,3),$S$5:$S$19999,G$4)*VLOOKUP($C6,$Y$5:$Z$15,2,FALSE)/8.76)+SUMIF($Y$5:$Y$15,$C6,$AA$5:$AA$15) -> 5.1116438 | H6: =MAX(G6,SUMIFS($Q$5:$Q$19999,$R$5:$R$19999,RIGHT($A6,3),$S$5:$S$19999,H$4)*VLOOKUP($C6,$Y$5:$Z$15,2,FALSE)/8.76)+SUMIF($Y$5:$Y$15,$C6,$AA$5:$AA$15) -> 13.744064 | I6: =MAX(H6,SUMIFS($Q$5:$Q$19999,$R$5:$R$19999,RIGHT($A6,3),$S$5:$S$19999,I$4)*VLOOKUP($C6,$Y$5:$Z$15,2,FALSE)/8.76)+SUMIF($Y$5:$Y$15,$C6,$AA$5:$AA$15) -> 32.526598 | J6: =MAX(I6,SUMIFS($Q$5:$Q$19999,$R$5:$R$19999,RIGHT($A6,3),$S$5:$S$19999,J$4)*VLOOKUP($C6,$Y$5:$Z$15,2,FALSE)/8.76)+SUMIF($Y$5:$Y$15,$C6,$AA$5:$AA$15) -> 64.817922 | K6: =MAX(J6,SUMIFS($Q$5:$Q$19999,$R$5:$R$19999,RIGHT($A6,3),$S$5:$S$19999,K$4)*VLOOKUP($C6,$Y$5:$Z$15,2,FALSE)/8.76)+SUMIF($Y$5:$Y$15,$C6,$AA$5:$AA$15) -> 105.90251 | L6: =MAX(K6,SUMIFS($Q$5:$Q$19999,$R$5:$R$19999,RIGHT($A6,3),$S$5:$S$19999,L$4)*VLOOKUP($C6,$Y$5:$Z$15,2,FALSE)/8.76)+SUMIF($Y$5:$Y$15,$C6,$AA$5:$AA$15) -> 144.54224 | M6: =MAX(L6,SUMIFS($Q$5:$Q$19999,$R$5:$R$19999,RIGHT($A6,3),$S$5:$S$19999,M$4)*VLOOKUP($C6,$Y$5:$Z$15,2,FALSE)/8.76)+SUMIF($Y$5:$Y$15,$C6,$AA$5:$AA$15) -> 173.59018 | N6: =MAX(M6,SUMIFS($Q$5:$Q$19999,$R$5:$R$19999,RIGHT($A6,3),$S$5:$S$19999,N$4)*VLOOKUP($C6,$Y$5:$Z$15,2,FALSE)/8.76)+SUMIF($Y$5:$Y$15,$C6,$AA$5:$AA$15) -> 184.25457 | O6: 3 | Q6: =OFFSET(S6,0,MATCH($Q$3,$T$4:$V$4,0)) -> 0.605 | R6: ABW | S6: 2021 | T6: 0.605 | U6: 0.605 | V6: 0.605 | Y6: 2 | Z6: 0.2
A7: ALB | B7: Albania | C7: 1 | E7: ="NatGrdExt_"&A7&"_"&C7 -> NatGrdExt_ALB_1 | F7: =SUMIFS($Q$5:$Q$19999,$R$5:$R$19999,RIGHT($A7,3),$S$5:$S$19999,F$4)*VLOOKUP($C7,$Y$5:$Z$15,2,FALSE)/8.76+SUMIF($Y$5:$Y$15,$C7,$AA$5:$AA$15) -> 1.1940639 | G7: =MAX(F7,SUMIFS($Q$5:$Q$19999,$R$5:$R$19999,RIGHT($A7,3),$S$5:$S$19999,G$4)*VLOOKUP($C7,$Y$5:$Z$15,2,FALSE)/8.76)+SUMIF($Y$5:$Y$15,$C7,$AA$5:$AA$15) -> 1.4478311 | H7: =MAX(G7,SUMIFS($Q$5:$Q$19999,$R$5:$R$19999,RIGHT($A7,3),$S$5:$S$19999,H$4)*VLOOKUP($C7,$Y$5:$Z$15,2,FALSE)/8.76)+SUMIF($Y$5:$Y$15,$C7,$AA$5:$AA$15) -> 1.996347 | I7: =MAX(H7,SUMIFS($Q$5:$Q$19999,$R$5:$R$19999,RIGHT($A7,3),$S$5:$S$19999,I$4)*VLOOKUP($C7,$Y$5:$Z$15,2,FALSE)/8.76)+SUMIF($Y$5:$Y$15,$C7,$AA$5:$AA$15) -> 2.5638128 | J7: =MAX(I7,SUMIFS($Q$5:$Q$19999,$R$5:$R$19999,RIGHT($A7,3),$S$5:$S$19999,J$4)*VLOOKUP($C7,$Y$5:$Z$15,2,FALSE)/8.76)+SUMIF($Y$5:$Y$15,$C7,$AA$5:$AA$15) -> 3.1106164 | K7: =MAX(J7,SUMIFS($Q$5:$Q$19999,$R$5:$R$19999,RIGHT($A7,3),$S$5:$S$19999,K$4)*VLOOKUP($C7,$Y$5:$Z$15,2,FALSE)/8.76)+SUMIF($Y$5:$Y$15,$C7,$AA$5:$AA$15) -> 3.54121 | L7: =MAX(K7,SUMIFS($Q$5:$Q$19999,$R$5:$R$19999,RIGHT($A7,3),$S$5:$S$19999,L$4)*VLOOKUP($C7,$Y$5:$Z$15,2,FALSE)/8.76)+SUMIF($Y$5:$Y$15,$C7,$AA$5:$AA$15) -> 3.8636986 | M7: =MAX(L7,SUMIFS($Q$5:$Q$19999,$R$5:$R$19999,RIGHT($A7,3),$S$5:$S$19999,M$4)*VLOOKUP($C7,$Y$5:$Z$15,2,FALSE)/8.76)+SUMIF($Y$5:$Y$15,$C7,$AA$5:$AA$15) -> 4.0891553 | N7: =MAX(M7,SUMIFS($Q$5:$Q$19999,$R$5:$R$19999,RIGHT($A7,3),$S$5:$S$19999,N$4)*VLOOKUP($C7,$Y$5:$Z$15,2,FALSE)/8.76)+SUMIF($Y$5:$Y$15,$C7,$AA$5:$AA$15) -> 4.1818493 | O7: 3 | Q7: =OFFSET(S7,0,MATCH($Q$3,$T$4:$V$4,0)) -> 0.612 | R7: ABW | S7: 2022 | T7: 0.612 | U7: 0.612 | V7: 0.612 | Y7: 3 | Z7: =Z6+0.05 -> 0.25
A8: ARE | B8: United Arab Emirates | C8: 1 | E8: ="NatGrdExt_"&A8&"_"&C8 -> NatGrdExt_ARE_1 | F8: =SUMIFS($Q$5:$Q$19999,$R$5:$R$19999,RIGHT($A8,3),$S$5:$S$19999,F$4)*VLOOKUP($C8,$Y$5:$Z$15,2,FALSE)/8.76+SUMIF($Y$5:$Y$15,$C8,$AA$5:$AA$15) -> 12.909132 | G8: =MAX(F8,SUMIFS($Q$5:$Q$19999,$R$5:$R$19999,RIGHT($A8,3),$S$5:$S$19999,G$4)*VLOOKUP($C8,$Y$5:$Z$15,2,FALSE)/8.76)+SUMIF($Y$5:$Y$15,$C8,$AA$5:$AA$15) -> 12.909132 | H8: =MAX(G8,SUMIFS($Q$5:$Q$19999,$R$5:$R$19999,RIGHT($A8,3),$S$5:$S$19999,H$4)*VLOOKUP($C8,$Y$5:$Z$15,2,FALSE)/8.76)+SUMIF($Y$5:$Y$15,$C8,$AA$5:$AA$15) -> 13.58516 | I8: =MAX(H8,SUMIFS($Q$5:$Q$19999,$R$5:$R$19999,RIGHT($A8,3),$S$5:$S$19999,I$4)*VLOOKUP($C8,$Y$5:$Z$15,2,FALSE)/8.76)+SUMIF($Y$5:$Y$15,$C8,$AA$5:$AA$15) -> 13.58516 | J8: =MAX(I8,SUMIFS($Q$5:$Q$19999,$R$5:$R$19999,RIGHT($A8,3),$S$5:$S$19999,J$4)*VLOOKUP($C8,$Y$5:$Z$15,2,FALSE)/8.76)+SUMIF($Y$5:$Y$15,$C8,$AA$5:$AA$15) -> 13.58516 | K8: =MAX(J8,SUMIFS($Q$5:$Q$19999,$R$5:$R$19999,RIGHT($A8,3),$S$5:$S$19999,K$4)*VLOOKUP($C8,$Y$5:$Z$15,2,FALSE)/8.76)+SUMIF($Y$5:$Y$15,$C8,$AA$5:$AA$15) -> 13.58516 | L8: =MAX(K8,SUMIFS($Q$5:$Q$19999,$R$5:$R$19999,RIGHT($A8,3),$S$5:$S$19999,L$4)*VLOOKUP($C8,$Y$5:$Z$15,2,FALSE)/8.76)+SUMIF($Y$5:$Y$15,$C8,$AA$5:$AA$15) -> 13.58516 | M8: =MAX(L8,SUMIFS($Q$5:$Q$19999,$R$5:$R$19999,RIGHT($A8,3),$S$5:$S$19999,M$4)*VLOOKUP($C8,$Y$5:$Z$15,2,FALSE)/8.76)+SUMIF($Y$5:$Y$15,$C8,$AA$5:$AA$15) -> 13.58516 | N8: =MAX(M8,SUMIFS($Q$5:$Q$19999,$R$5:$R$19999,RIGHT($A8,3),$S$5:$S$19999,N$4)*VLOOKUP($C8,$Y$5:$Z$15,2,FALSE)/8.76)+SUMIF($Y$5:$Y$15,$C8,$AA$5:$AA$15) -> 13.58516 | O8: 3 | Q8: =OFFSET(S8,0,MATCH($Q$3,$T$4:$V$4,0)) -> 0.614 | R8: ABW | S8: 2023 | T8: 0.614 | U8: 0.614 | V8: 0.614 | Y8: 4 | Z8: =Z7+0.05 -> 0.3
A9: ARG | B9: Argentina | C9: 1 | E9: ="NatGrdExt_"&A9&"_"&C9 -> NatGrdExt_ARG_1 | F9: =SUMIFS($Q$5:$Q$19999,$R$5:$R$19999,RIGHT($A9,3),$S$5:$S$19999,F$4)*VLOOKUP($C9,$Y$5:$Z$15,2,FALSE)/8.76+SUMIF($Y$5:$Y$15,$C9,$AA$5:$AA$15) -> 22.9379 | G9: =MAX(F9,SUMIFS($Q$5:$Q$19999,$R$5:$R$19999,RIGHT($A9,3),$S$5:$S$19999,G$4)*VLOOKUP($C9,$Y$5:$Z$15,2,FALSE)/8.76)+SUMIF($Y$5:$Y$15,$C9,$AA$5:$AA$15) -> 27.317009 | H9: =MAX(G9,SUMIFS($Q$5:$Q$19999,$R$5:$R$19999,RIGHT($A9,3),$S$5:$S$19999,H$4)*VLOOKUP($C9,$Y$5:$Z$15,2,FALSE)/8.76)+SUMIF($Y$5:$Y$15,$C9,$AA$5:$AA$15) -> 37.755594 | I9: =MAX(H9,SUMIFS($Q$5:$Q$19999,$R$5:$R$19999,RIGHT($A9,3),$S$5:$S$19999,I$4)*VLOOKUP($C9,$Y$5:$Z$15,2,FALSE)/8.76)+SUMIF($Y$5:$Y$15,$C9,$AA$5:$AA$15) -> 50.038242 | J9: =MAX(I9,SUMIFS($Q$5:$Q$19999,$R$5:$R$19999,RIGHT($A9,3),$S$5:$S$19999,J$4)*VLOOKUP($C9,$Y$5:$Z$15,2,FALSE)/8.76)+SUMIF($Y$5:$Y$15,$C9,$AA$5:$AA$15) -> 63.593607 | K9: =MAX(J9,SUMIFS($Q$5:$Q$19999,$R$5:$R$19999,RIGHT($A9,3),$S$5:$S$19999,K$4)*VLOOKUP($C9,$Y$5:$Z$15,2,FALSE)/8.76)+SUMIF($Y$5:$Y$15,$C9,$AA$5:$AA$15) -> 77.480137 | L9: =MAX(K9,SUMIFS($Q$5:$Q$19999,$R$5:$R$19999,RIGHT($A9,3),$S$5:$S$19999,L$4)*VLOOKUP($C9,$Y$5:$Z$15,2,FALSE)/8.76)+SUMIF($Y$5:$Y$15,$C9,$AA$5:$AA$15) -> 90.97226 | M9: =MAX(L9,SUMIFS($Q$5:$Q$19999,$R$5:$R$19999,RIGHT($A9,3),$S$5:$S$19999,M$4)*VLOOKUP($C9,$Y$5:$Z$15,2,FALSE)/8.76)+SUMIF($Y$5:$Y$15,$C9,$AA$5:$AA$15) -> 103.80251 | N9: =MAX(M9,SUMIFS($Q$5:$Q$19999,$R$5:$R$19999,RIGHT($A9,3),$S$5:$S$19999,N$4)*VLOOKUP($C9,$Y$5:$Z$15,2,FALSE)/8.76)+SUMIF($Y$5:$Y$15,$C9,$AA$5:$AA$15) -> 109.91975 | O9: 3 | Q9: =OFFSET(S9,0,MATCH($Q$3,$T$4:$V$4,0)) -> 0.616 | R9: ABW | S9: 2024 | T9: 0.616 | U9: 0.616 | V9: 0.616 | Y9: 5 | Z9: =Z8+0.05 -> 0.35 | AA9: 0.5
A10: ARM | B10: Armenia | C10: 1 | E10: ="NatGrdExt_"&A10&"_"&C10 -> NatGrdExt_ARM_1 | F10: =SUMIFS($Q$5:$Q$19999,$R$5:$R$19999,RIGHT($A10,3),$S$5:$S$19999,F$4)*VLOOKUP($C10,$Y$5:$Z$15,2,FALSE)/8.76+SUMIF($Y$5:$Y$15,$C10,$AA$5:$AA$15) -> 0.72614155 | G10: =MAX(F10,SUMIFS($Q$5:$Q$19999,$R$5:$R$19999,RIGHT($A10,3),$S$5:$S$19999,G$4)*VLOOKUP($C10,$Y$5:$Z$15,2,FALSE)/8.76)+SUMIF($Y$5:$Y$15,$C10,$AA$5:$AA$15) -> 0.77089041 | H10: =MAX(G10,SUMIFS($Q$5:$Q$19999,$R$5:$R$19999,RIGHT($A10,3),$S$5:$S$19999,H$4)*VLOOKUP($C10,$Y$5:$Z$15,2,FALSE)/8.76)+SUMIF($Y$5:$Y$15,$C10,$AA$5:$AA$15) -> 0.85399543 | I10: =MAX(H10,SUMIFS($Q$5:$Q$19999,$R$5:$R$19999,RIGHT($A10,3),$S$5:$S$19999,I$4)*VLOOKUP($C10,$Y$5:$Z$15,2,FALSE)/8.76)+SUMIF($Y$5:$Y$15,$C10,$AA$5:$AA$15) -> 0.93321918 | J10: =MAX(I10,SUMIFS($Q$5:$Q$19999,$R$5:$R$19999,RIGHT($A10,3),$S$5:$S$19999,J$4)*VLOOKUP($C10,$Y$5:$Z$15,2,FALSE)/8.76)+SUMIF($Y$5:$Y$15,$C10,$AA$5:$AA$15) -> 0.99977169 | K10: =MAX(J10,SUMIFS($Q$5:$Q$19999,$R$5:$R$19999,RIGHT($A10,3),$S$5:$S$19999,K$4)*VLOOKUP($C10,$Y$5:$Z$15,2,FALSE)/8.76)+SUMIF($Y$5:$Y$15,$C10,$AA$5:$AA$15) -> 1.0522831 | L10: =MAX(K10,SUMIFS($Q$5:$Q$19999,$R$5:$R$19999,RIGHT($A10,3),$S$5:$S$19999,L$4)*VLOOKUP($C10,$Y$5:$Z$15,2,FALSE)/8.76)+SUMIF($Y$5:$Y$15,$C10,$AA$5:$AA$15) -> 1.1049087 | M10: =MAX(L10,SUMIFS($Q$5:$Q$19999,$R$5:$R$19999,RIGHT($A10,3),$S$5:$S$19999,M$4)*VLOOKUP($C10,$Y$5:$Z$15,2,FALSE)/8.76)+SUMIF($Y$5:$Y$15,$C10,$AA$5:$AA$15) -> 1.1570776 | N10: =MAX(M10,SUMIFS($Q$5:$Q$19999,$R$5:$R$19999,RIGHT($A10,3),$S$5:$S$19999,N$4)*VLOOKUP($C10,$Y$5:$Z$15,2,FALSE)/8.76)+SUMIF($Y$5:$Y$15,$C10,$AA$5:$AA$15) -> 1.183105 | O10: 3 | Q10: =OFFSET(S10,0,MATCH($Q$3,$T$4:$V$4,0)) -> 0.623 | R10: ABW | S10: 2025 | T10: 0.623 | U10: 0.623 | V10: 0.623 | Y10: 6 | Z10: =Z9+0.05 -> 0.4
A11: ATG | B11: Antigua and Barbuda | C11: 1 | E11: ="NatGrdExt_"&A11&"_"&C11 -> NatGrdExt_ATG_1 | F11: =SUMIFS($Q$5:$Q$19999,$R$5:$R$19999,RIGHT($A11,3),$S$5:$S$19999,F$4)*VLOOKUP($C11,$Y$5:$Z$15,2,FALSE)/8.76+SUMIF($Y$5:$Y$15,$C11,$AA$5:$AA$15) -> 0.064840183 | G11: =MAX(F11,SUMIFS($Q$5:$Q$19999,$R$5:$R$19999,RIGHT($A11,3),$S$5:$S$19999,G$4)*VLOOKUP($C11,$Y$5:$Z$15,2,FALSE)/8.76)+SUMIF($Y$5:$Y$15,$C11,$AA$5:$AA$15) -> 0.069063927 | H11: =MAX(G11,SUMIFS($Q$5:$Q$19999,$R$5:$R$19999,RIGHT($A11,3),$S$5:$S$19999,H$4)*VLOOKUP($C11,$Y$5:$Z$15,2,FALSE)/8.76)+SUMIF($Y$5:$Y$15,$C11,$AA$5:$AA$15) -> 0.075913242 | I11: =MAX(H11,SUMIFS($Q$5:$Q$19999,$R$5:$R$19999,RIGHT($A11,3),$S$5:$S$19999,I$4)*VLOOKUP($C11,$Y$5:$Z$15,2,FALSE)/8.76)+SUMIF($Y$5:$Y$15,$C11,$AA$5:$AA$15) -> 0.080479452 | J11: =MAX(I11,SUMIFS($Q$5:$Q$19999,$R$5:$R$19999,RIGHT($A11,3),$S$5:$S$19999,J$4)*VLOOKUP($C11,$Y$5:$Z$15,2,FALSE)/8.76)+SUMIF($Y$5:$Y$15,$C11,$AA$5:$AA$15) -> 0.084246575 | K11: =MAX(J11,SUMIFS($Q$5:$Q$19999,$R$5:$R$19999,RIGHT($A11,3),$S$5:$S$19999,K$4)*VLOOKUP($C11,$Y$5:$Z$15,2,FALSE)/8.76)+SUMIF($Y$5:$Y$15,$C11,$AA$5:$AA$15) -> 0.088926941 | L11: =MAX(K11,SUMIFS($Q$5:$Q$19999,$R$5:$R$19999,RIGHT($A11,3),$S$5:$S$19999,L$4)*VLOOKUP($C11,$Y$5:$Z$15,2,FALSE)/8.76)+SUMIF($Y$5:$Y$15,$C11,$AA$5:$AA$15) -> 0.093378995 | M11: =MAX(L11,SUMIFS($Q$5:$Q$19999,$R$5:$R$19999,RIGHT($A11,3),$S$5:$S$19999,M$4)*VLOOKUP($C11,$Y$5:$Z$15,2,FALSE)/8.76)+SUMIF($Y$5:$Y$15,$C11,$AA$5:$AA$15) -> 0.097945205 | N11: =MAX(M11,SUMIFS($Q$5:$Q$19999,$R$5:$R$19999,RIGHT($A11,3),$S$5:$S$19999,N$4)*VLOOKUP($C11,$Y$5:$Z$15,2,FALSE)/8.76)+SUMIF($Y$5:$Y$15,$C11,$AA$5:$AA$15) -> 0.10011416 | O11: 3 | Q11: =OFFSET(S11,0,MATCH($Q$3,$T$4:$V$4,0)) -> 0.625 | R11: ABW | S11: 2026 | T11: 0.625 | U11: 0.625 | V11: 0.625 | Y11: 7 | Z11: =Z10+0.05 -> 0.45
A12: AUS | B12: Australia | C12: 1 | E12: ="NatGrdExt_"&A12&"_"&C12 -> NatGrdExt_AUS_1 | F12: =SUMIFS($Q$5:$Q$19999,$R$5:$R$19999,RIGHT($A12,3),$S$5:$S$19999,F$4)*VLOOKUP($C12,$Y$5:$Z$15,2,FALSE)/8.76+SUMIF($Y$5:$Y$15,$C12,$AA$5:$AA$15) -> 34.055822 | G12: =MAX(F12,SUMIFS($Q$5:$Q$19999,$R$5:$R$19999,RIGHT($A12,3),$S$5:$S$19999,G$4)*VLOOKUP($C12,$Y$5:$Z$15,2,FALSE)/8.76)+SUMIF($Y$5:$Y$15,$C12,$AA$5:$AA$15) -> 35.323402 | H12: =MAX(G12,SUMIFS($Q$5:$Q$19999,$R$5:$R$19999,RIGHT($A12,3),$S$5:$S$19999,H$4)*VLOOKUP($C12,$Y$5:$Z$15,2,FALSE)/8.76)+SUMIF($Y$5:$Y$15,$C12,$AA$5:$AA$15) -> 36.988242 | I12: =MAX(H12,SUMIFS($Q$5:$Q$19999,$R$5:$R$19999,RIGHT($A12,3),$S$5:$S$19999,I$4)*VLOOKUP($C12,$Y$5:$Z$15,2,FALSE)/8.76)+SUMIF($Y$5:$Y$15,$C12,$AA$5:$AA$15) -> 38.242922 | J12: =MAX(I12,SUMIFS($Q$5:$Q$19999,$R$5:$R$19999,RIGHT($A12,3),$S$5:$S$19999,J$4)*VLOOKUP($C12,$Y$5:$Z$15,2,FALSE)/8.76)+SUMIF($Y$5:$Y$15,$C12,$AA$5:$AA$15) -> 39.485502 | K12: =MAX(J12,SUMIFS($Q$5:$Q$19999,$R$5:$R$19999,RIGHT($A12,3),$S$5:$S$19999,K$4)*VLOOKUP($C12,$Y$5:$Z$15,2,FALSE)/8.76)+SUMIF($Y$5:$Y$15,$C12,$AA$5:$AA$15) -> 40.63984 | L12: =MAX(K12,SUMIFS($Q$5:$Q$19999,$R$5:$R$19999,RIGHT($A12,3),$S$5:$S$19999,L$4)*VLOOKUP($C12,$Y$5:$Z$15,2,FALSE)/8.76)+SUMIF($Y$5:$Y$15,$C12,$AA$5:$AA$15) -> 41.723973 | M12: =MAX(L12,SUMIFS($Q$5:$Q$19999,$R$5:$R$19999,RIGHT($A12,3),$S$5:$S$19999,M$4)*VLOOKUP($C12,$Y$5:$Z$15,2,FALSE)/8.76)+SUMIF($Y$5:$Y$15,$C12,$AA$5:$AA$15) -> 43.141895 | N12: =MAX(M12,SUMIFS($Q$5:$Q$19999,$R$5:$R$19999,RIGHT($A12,3),$S$5:$S$19999,N$4)*VLOOKUP($C12,$Y$5:$Z$15,2,FALSE)/8.76)+SUMIF($Y$5:$Y$15,$C12,$AA$5:$AA$15) -> 44.045776 | O12: 3 | Q12: =OFFSET(S12,0,MATCH($Q$3,$T$4:$V$4,0)) -> 0.627 | R12: ABW | S12: 2027 | T12: 0.627 | U12: 0.627 | V12: 0.627 | Y12: 8 | Z12: =Z11+0.05 -> 0.5
A13: AUT | B13: Austria | C13: 1 | E13: ="NatGrdExt_"&A13&"_"&C13 -> NatGrdExt_AUT_1 | F13: =SUMIFS($Q$5:$Q$19999,$R$5:$R$19999,RIGHT($A13,3),$S$5:$S$19999,F$4)*VLOOKUP($C13,$Y$5:$Z$15,2,FALSE)/8.76+SUMIF($Y$5:$Y$15,$C13,$AA$5:$AA$15) -> 9.581621 | G13: =MAX(F13,SUMIFS($Q$5:$Q$19999,$R$5:$R$19999,RIGHT($A13,3),$S$5:$S$19999,G$4)*VLOOKUP($C13,$Y$5:$Z$15,2,FALSE)/8.76)+SUMIF($Y$5:$Y$15,$C13,$AA$5:$AA$15) -> 9.8005708 | H13: =MAX(G13,SUMIFS($Q$5:$Q$19999,$R$5:$R$19999,RIGHT($A13,3),$S$5:$S$19999,H$4)*VLOOKUP($C13,$Y$5:$Z$15,2,FALSE)/8.76)+SUMIF($Y$5:$Y$15,$C13,$AA$5:$AA$15) -> 9.9436073 | I13: =MAX(H13,SUMIFS($Q$5:$Q$19999,$R$5:$R$19999,RIGHT($A13,3),$S$5:$S$19999,I$4)*VLOOKUP($C13,$Y$5:$Z$15,2,FALSE)/8.76)+SUMIF($Y$5:$Y$15,$C13,$AA$5:$AA$15) -> 9.9436073 | J13: =MAX(I13,SUMIFS($Q$5:$Q$19999,$R$5:$R$19999,RIGHT($A13,3),$S$5:$S$19999,J$4)*VLOOKUP($C13,$Y$5:$Z$15,2,FALSE)/8.76)+SUMIF($Y$5:$Y$15,$C13,$AA$5:$AA$15) -> 9.9436073 | K13: =MAX(J13,SUMIFS($Q$5:$Q$19999,$R$5:$R$19999,RIGHT($A13,3),$S$5:$S$19999,K$4)*VLOOKUP($C13,$Y$5:$Z$15,2,FALSE)/8.76)+SUMIF($Y$5:$Y$15,$C13,$AA$5:$AA$15) -> 9.9436073 | L13: =MAX(K13,SUMIFS($Q$5:$Q$19999,$R$5:$R$19999,RIGHT($A13,3),$S$5:$S$19999,L$4)*VLOOKUP($C13,$Y$5:$Z$15,2,FALSE)/8.76)+SUMIF($Y$5:$Y$15,$C13,$AA$5:$AA$15) -> 9.9436073 | M13: =MAX(L13,SUMIFS($Q$5:$Q$19999,$R$5:$R$19999,RIGHT($A13,3),$S$5:$S$19999,M$4)*VLOOKUP($C13,$Y$5:$Z$15,2,FALSE)/8.76)+SUMIF($Y$5:$Y$15,$C13,$AA$5:$AA$15) -> 9.9436073 | N13: =MAX(M13,SUMIFS($Q$5:$Q$19999,$R$5:$R$19999,RIGHT($A13,3),$S$5:$S$19999,N$4)*VLOOKUP($C13,$Y$5:$Z$15,2,FALSE)/8.76)+SUMIF($Y$5:$Y$15,$C13,$AA$5:$AA$15) -> 9.9436073 | O13: 3 | Q13: =OFFSET(S13,0,MATCH($Q$3,$T$4:$V$4,0)) -> 0.63 | R13: ABW | S13: 2028 | T13: 0.63 | U13: 0.63 | V13: 0.63 | Y13: 9 | Z13: =Z12+0.05 -> 0.55
A14: AZE | B14: Azerbaijan | C14: 1 | E14: ="NatGrdExt_"&A14&"_"&C14 -> NatGrdExt_AZE_1 | F14: =SUMIFS($Q$5:$Q$19999,$R$5:$R$19999,RIGHT($A14,3),$S$5:$S$19999,F$4)*VLOOKUP($C14,$Y$5:$Z$15,2,FALSE)/8.76+SUMIF($Y$5:$Y$15,$C14,$AA$5:$AA$15) -> 2.5538813 | G14: =MAX(F14,SUMIFS($Q$5:$Q$19999,$R$5:$R$19999,RIGHT($A14,3),$S$5:$S$19999,G$4)*VLOOKUP($C14,$Y$5:$Z$15,2,FALSE)/8.76)+SUMIF($Y$5:$Y$15,$C14,$AA$5:$AA$15) -> 2.7541096 | H14: =MAX(G14,SUMIFS($Q$5:$Q$19999,$R$5:$R$19999,RIGHT($A14,3),$S$5:$S$19999,H$4)*VLOOKUP($C14,$Y$5:$Z$15,2,FALSE)/8.76)+SUMIF($Y$5:$Y$15,$C14,$AA$5:$AA$15) -> 3.1275114 | I14: =MAX(H14,SUMIFS($Q$5:$Q$19999,$R$5:$R$19999,RIGHT($A14,3),$S$5:$S$19999,I$4)*VLOOKUP($C14,$Y$5:$Z$15,2,FALSE)/8.76)+SUMIF($Y$5:$Y$15,$C14,$AA$5:$AA$15) -> 3.4307078 | J14: =MAX(I14,SUMIFS($Q$5:$Q$19999,$R$5:$R$19999,RIGHT($A14,3),$S$5:$S$19999,J$4)*VLOOKUP($C14,$Y$5:$Z$15,2,FALSE)/8.76)+SUMIF($Y$5:$Y$15,$C14,$AA$5:$AA$15) -> 3.6590183 | K14: =MAX(J14,SUMIFS($Q$5:$Q$19999,$R$5:$R$19999,RIGHT($A14,3),$S$5:$S$19999,K$4)*VLOOKUP($C14,$Y$5:$Z$15,2,FALSE)/8.76)+SUMIF($Y$5:$Y$15,$C14,$AA$5:$AA$15) -> 3.8409817 | L14: =MAX(K14,SUMIFS($Q$5:$Q$19999,$R$5:$R$19999,RIGHT($A14,3),$S$5:$S$19999,L$4)*VLOOKUP($C14,$Y$5:$Z$15,2,FALSE)/8.76)+SUMIF($Y$5:$Y$15,$C14,$AA$5:$AA$15) -> 3.9971461 | M14: =MAX(L14,SUMIFS($Q$5:$Q$19999,$R$5:$R$19999,RIGHT($A14,3),$S$5:$S$19999,M$4)*VLOOKUP($C14,$Y$5:$Z$15,2,FALSE)/8.76)+SUMIF($Y$5:$Y$15,$C14,$AA$5:$AA$15) -> 4.1609589 | N14: =MAX(M14,SUMIFS($Q$5:$Q$19999,$R$5:$R$19999,RIGHT($A14,3),$S$5:$S$19999,N$4)*VLOOKUP($C14,$Y$5:$Z$15,2,FALSE)/8.76)+SUMIF($Y$5:$Y$15,$C14,$AA$5:$AA$15) -> 4.2445205 | O14: 3 | Q14: =OFFSET(S14,0,MATCH($Q$3,$T$4:$V$4,0)) -> 0.632 | R14: ABW | S14: 2029 | T14: 0.632 | U14: 0.632 | V14: 0.632 | Y14: 10 | Z14: =Z13+0.05 -> 0.6
A15: BDI | B15: Burundi | C15: 1 | E15: ="NatGrdExt_"&A15&"_"&C15 -> NatGrdExt_BDI_1 | F15: =SUMIFS($Q$5:$Q$19999,$R$5:$R$19999,RIGHT($A15,3),$S$5:$S$19999,F$4)*VLOOKUP($C15,$Y$5:$Z$15,2,FALSE)/8.76+SUMIF($Y$5:$Y$15,$C15,$AA$5:$AA$15) -> 0.2466895 | G15: =MAX(F15,SUMIFS($Q$5:$Q$19999,$R$5:$R$19999,RIGHT($A15,3),$S$5:$S$19999,G$4)*VLOOKUP($C15,$Y$5:$Z$15,2,FALSE)/8.76)+SUMIF($Y$5:$Y$15,$C15,$AA$5:$AA$15) -> 0.34143836 | H15: =MAX(G15,SUMIFS($Q$5:$Q$19999,$R$5:$R$19999,RIGHT($A15,3),$S$5:$S$19999,H$4)*VLOOKUP($C15,$Y$5:$Z$15,2,FALSE)/8.76)+SUMIF($Y$5:$Y$15,$C15,$AA$5:$AA$15) -> 0.62009132 | I15: =MAX(H15,SUMIFS($Q$5:$Q$19999,$R$5:$R$19999,RIGHT($A15,3),$S$5:$S$19999,I$4)*VLOOKUP($C15,$Y$5:$Z$15,2,FALSE)/8.76)+SUMIF($Y$5:$Y$15,$C15,$AA$5:$AA$15) -> 1.0727169 | J15: =MAX(I15,SUMIFS($Q$5:$Q$19999,$R$5:$R$19999,RIGHT($A15,3),$S$5:$S$19999,J$4)*VLOOKUP($C15,$Y$5:$Z$15,2,FALSE)/8.76)+SUMIF($Y$5:$Y$15,$C15,$AA$5:$AA$15) -> 1.7557078 | K15: =MAX(J15,SUMIFS($Q$5:$Q$19999,$R$5:$R$19999,RIGHT($A15,3),$S$5:$S$19999,K$4)*VLOOKUP($C15,$Y$5:$Z$15,2,FALSE)/8.76)+SUMIF($Y$5:$Y$15,$C15,$AA$5:$AA$15) -> 2.7143836 | L15: =MAX(K15,SUMIFS($Q$5:$Q$19999,$R$5:$R$19999,RIGHT($A15,3),$S$5:$S$19999,L$4)*VLOOKUP($C15,$Y$5:$Z$15,2,FALSE)/8.76)+SUMIF($Y$5:$Y$15,$C15,$AA$5:$AA$15) -> 3.9609589 | M15: =MAX(L15,SUMIFS($Q$5:$Q$19999,$R$5:$R$19999,RIGHT($A15,3),$S$5:$S$19999,M$4)*VLOOKUP($C15,$Y$5:$Z$15,2,FALSE)/8.76)+SUMIF($Y$5:$Y$15,$C15,$AA$5:$AA$15) -> 5.4251142 | N15: =MAX(M15,SUMIFS($Q$5:$Q$19999,$R$5:$R$19999,RIGHT($A15,3),$S$5:$S$19999,N$4)*VLOOKUP($C15,$Y$5:$Z$15,2,FALSE)/8.76)+SUMIF($Y$5:$Y$15,$C15,$AA$5:$AA$15) -> 6.1993151 | O15: 3 | Q15: =OFFSET(S15,0,MATCH($Q$3,$T$4:$V$4,0)) -> 0.634 | R15: ABW | S15: 2030 | T15: 0.634 | U15: 0.635 | V15: 0.634
