Workbook
Name IQ_CH: 110000
Name IQ_CQ: 5000
Name IQ_CY: 10000
Name IQ_DAILY: 500000
Name IQ_FH: 100000
Name IQ_FQ: 500
Name IQ_FY: 1000
Name IQ_LTM: 2000
Name IQ_MONTH: 15000
Name IQ_NTM: 6000
Name IQ_WEEK: 50000
Name IQ_YTD: 3000

Sheet RE costs
C3: ~TFM_INS: curr=USD22 | R3: ~TFM_MIG: attribute=NCAP_COST
C4: pset_ci | D4: pset_co | E4: attribute | F4: year | G4: ieapg_africa | H4: ieapg_brazil | I4: ieapg_china | J4: ieapg_india | K4: ieapg_japan | L4: ieapg_russia | M4: ieapg_european_union | N4: ieapg_united_states | O4: ieapg_middle_east | R4: currency | S4: year2 | T4: pset_ci | U4: value
C5: elcspv | E5: invcost | F5: 2022 | G5: 1420 | H5: 750 | I5: 720 | J5: 640 | K5: 1910 | L5: 1710 | M5: 990 | N5: 1120 | O5: 620 | R5: USD21_alt | S5: 2022,2030,2050 | T5: elcspv,elcwin,elchyd | U5: *1
C6: elcspv | E6: fixom | F6: 2022 | G6: 22 | H6: 12 | I6: 12 | J6: 10 | K6: 28 | L6: 26 | M6: 14 | N6: 16 | O6: 10
D7: elc_won_* | E7: invcost | F7: 2022 | G7: 1950 | H7: 1050 | I7: 1100 | J7: 1120 | K7: 3520 | L7: 1640 | M7: 1750 | N7: 1220 | O7: 1950
D8: elc_won_* | E8: fixom | F8: 2022 | G8: 48 | H8: 26 | I8: 28 | J8: 28 | K8: 88 | L8: 40 | M8: 46 | N8: 30 | O8: 48
D9: elc_wof_* | E9: invcost | F9: 2022 | G9: 4260 | H9: 4440 | I9: 2820 | J9: 3060 | K9: 6640 | L9: 4600 | M9: 3420 | N9: 4060 | O9: 4400
D10: elc_wof_* | E10: fixom | F10: 2022 | G10: 105 | H10: 110 | I10: 70 | J10: 75 | K10: 165 | L10: 115 | M10: 70 | N10: 120 | O10: 110
C11: elchyd | E11: invcost | F11: 2022 | G11: 3300 | H11: 3350 | I11: 2000 | J11: 3050 | K11: 3550 | L11: 3500 | M11: 3900 | N11: 4050 | O11: 3400
C12: elchyd | E12: fixom | F12: 2022 | G12: 65 | H12: 65 | I12: 40 | J12: 60 | K12: 70 | L12: 70 | M12: 80 | N12: 80 | O12: 70
C13: elcspv | E13: invcost | F13: 2030 | G13: 850 | H13: 460 | I13: 430 | J13: 390 | K13: 1250 | L13: 1090 | M13: 620 | N13: 690 | O13: 360
C14: elcspv | E14: fixom | F14: 2030 | G14: 20 | H14: 10 | I14: 10 | J14: 8 | K14: 26 | L14: 24 | M14: 14 | N14: 16 | O14: 8
D15: elc_won_* | E15: invcost | F15: 2030 | G15: 1830 | H15: 1000 | I15: 1040 | J15: 1060 | K15: 3320 | L15: 1550 | M15: 1670 | N15: 1160 | O15: 1830
D16: elc_won_* | E16: fixom | F16: 2030 | G16: 46 | H16: 26 | I16: 26 | J16: 26 | K16: 84 | L16: 40 | M16: 42 | N16: 30 | O16: 46
D17: elc_wof_* | E17: invcost | F17: 2030 | G17: 2880 | H17: 3000 | I17: 1880 | J17: 2060 | K17: 4180 | L17: 3120 | M17: 2280 | N17: 2520 | O17: 3000
D18: elc_wof_* | E18: fixom | F18: 2030 | G18: 80 | H18: 80 | I18: 50 | J18: 55 | K18: 115 | L18: 85 | M18: 50 | N18: 90 | O18: 80
C19: elchyd | E19: invcost | F19: 2030 | G19: 3300 | H19: 3350 | I19: 2000 | J19: 3050 | K19: 3550 | L19: 3500 | M19: 3900 | N19: 4050 | O19: 3400
C20: elchyd | E20: fixom | F20: 2030 | G20: 65 | H20: 65 | I20: 40 | J20: 60 | K20: 70 | L20: 70 | M20: 80 | N20: 80 | O20: 70
C21: elcspv | E21: invcost | F21: 2050 | G21: 580 | H21: 330 | I21: 300 | J21: 270 | K21: 940 | L21: 770 | M21: 450 | N21: 480 | O21: 250
C22: elcspv | E22: fixom | F22: 2050 | G22: 18 | H22: 10 | I22: 10 | J22: 8 | K22: 24 | L22: 22 | M22: 12 | N22: 16 | O22: 8
D23: elc_won_* | E23: invcost | F23: 2050 | G23: 1740 | H23: 950 | I23: 1000 | J23: 1010 | K23: 3170 | L23: 1470 | M23: 1610 | N23: 1110 | O23: 1710
D24: elc_won_* | E24: fixom | F24: 2050 | G24: 44 | H24: 24 | I24: 26 | J24: 26 | K24: 82 | L24: 38 | M24: 42 | N24: 30 | O24: 44
D25: elc_wof_* | E25: invcost | F25: 2050 | G25: 2080 | H25: 2160 | I25: 1420 | J25: 1500 | K25: 3160 | L25: 2280 | M25: 1740 | N25: 1900 | O25: 2180
D26: elc_wof_* | E26: fixom | F26: 2050 | G26: 65 | H26: 65 | I26: 45 | J26: 45 | K26: 95 | L26: 70 | M26: 45 | N26: 70 | O26: 65
C27: elchyd | E27: invcost | F27: 2050 | G27: 3250 | H27: 3350 | I27: 2000 | J27: 3050 | K27: 3550 | L27: 3500 | M27: 3900 | N27: 4050 | O27: 3400
C28: elchyd | E28: fixom | F28: 2050 | G28: 65 | H28: 65 | I28: 40 | J28: 60 | K28: 70 | L28: 70 | M28: 80 | N28: 80 | O28: 70

Sheet Elec_materials
A1: Technology_Agg | B1: Technology | C1: Material | D1: Unit | E1: 1990 | F1: 2010 | G1: 2012 | H1: 2021
A2: Grid | B2: grid - high voltage lines (above ground) | C2: aluminium | D2: kt/000km | H2: 26.6667 | J2: 1 | K2: aluminium
A3: Grid | B3: grid - high voltage lines (above ground) | C3: asphalt | D3: kt/000km | G3: 37.85 | J3: 2 | K3: cement
A4: Grid | B4: grid - high voltage lines (above ground) | C4: concrete | D4: kt/000km | H4: 135.333 | J4: 3 | K4: concrete
A5: Grid | B5: grid - high voltage lines (above ground) | C5: copper | D5: kt/000km | G5: 11.65 | H5: 8e-05 | J5: 4 | K5: copper
A6: Grid | B6: grid - high voltage lines (above ground) | C6: lead | D6: kt/000km | G6: 14.05 | J6: 5 | K6: fiberglass
A7: Grid | B7: grid - high voltage lines (above ground) | C7: plastics | D7: kt/000km | G7: 2.3 | J7: 6 | K7: glass
A8: Grid | B8: grid - high voltage lines (above ground) | C8: steel | D8: kt/000km | H8: 30.75 | J8: 7 | K8: manganese
A9: Grid | B9: grid - high voltage lines (below ground) | C9: aluminium | D9: kt/000km | G9: 12.883 | H9: 8.63333 | J9: 8 | K9: nickel
A10: Grid | B10: grid - high voltage lines (below ground) | C10: concrete | D10: kt/000km | G10: 209.137 | J10: 9 | K10: silicon
A11: Grid | B11: grid - high voltage lines (below ground) | C11: copper | D11: kt/000km | H11: 18.4667 | J11: 10 | K11: silver
A12: Grid | B12: grid - high voltage lines (below ground) | C12: glass | D12: kt/000km | G12: 1.0965 | J12: 11 | K12: steel
A13: Grid | B13: grid - high voltage lines (below ground) | C13: steel | D13: kt/000km | G13: 52.266
A14: Grid | B14: grid - high voltage lines (below ground) | C14: zinc | D14: kt/000km | G14: 0.9
A15: Grid | B15: grid - low voltage lines (above ground) | C15: copper | D15: kt/000km | H15: 4
A16: Grid | B16: grid - medium voltage lines (above ground) | C16: aluminium | D16: kt/000km | H16: 3 | K16: bioenergy
A17: Grid | B17: grid - medium voltage lines (above ground) | C17: concrete | D17: kt/000km | H17: 26 | K17: biomass + CCS | L17: E_Bio-S
A18: Grid | B18: grid - medium voltage lines (above ground) | C18: copper | D18: kt/000km | F18: 1.48767 | H18: 8e-05 | K18: biomass | L18: E_Bio
A19: Grid | B19: grid - medium voltage lines (above ground) | C19: plastics | D19: kt/000km | F19: 0.01933 | K19: coal + CCS | L19: E_Coal-S
A20: Grid | B20: grid - medium voltage lines (above ground) | C20: steel | D20: kt/000km | F20: 0.80233 | H20: 11.025 | K20: coal | L20: E_Coal
A21: Grid | B21: grid - medium voltage lines (above ground) | C21: wood | D21: kt/000km | F21: 4.111 | K21: CSP | L21: E_CSP
A22: Grid | B22: grid - medium voltage lines (below ground) | C22: aluminium | D22: kt/000km | F22: 1.0845 | H22: 3.15 | K22: gas + CCS | L22: E_Gas-S
A23: Grid | B23: grid - medium voltage lines (below ground) | C23: copper | D23: kt/000km | F23: 0.9615 | H23: 5.95 | K23: gas | L23: E_Gas
A24: Grid | B24: grid - medium voltage lines (below ground) | C24: plastics | D24: kt/000km | F24: 1.4915 | K24: geothermal | L24: E_Geothermal
A25: Other | B25: bioenergy | C25: aluminium | D25: kt/GW | E25: 2.3 | K25: hydro (run-of-river)
A26: Other | B26: bioenergy | C26: concrete | D26: kt/GW | E26: 540 | K26: hydro | L26: E_Hydro
A27: Other | B27: bioenergy | C27: copper | D27: kt/GW | E27: 2.5 | K27: nuclear | L27: E_Nuclear
A28: Other | B28: bioenergy | C28: steel | D28: kt/GW | E28: 198 | K28: oil | L28: E_Oil
A29: Other | B29: biomass + CCS | C29: aluminium | D29: kt/GW | E29: 1.3 | K29: solar PV (rooftop)
A30: Other | B30: biomass + CCS | C30: cement | D30: kt/GW | E30: 32.005 | K30: solar PV (ground-mounted) | L30: E_SPV
A31: Other | B31: biomass + CCS | C31: copper | D31: kt/GW | E31: 0.596667 | K31: solar PV
A32: Other | B32: biomass + CCS | C32: steel | D32: kt/GW | E32: 79.56 | K32: storage - pumped hydro storage
A33: Other | B33: biomass | C33: aluminium | D33: kt/GW | E33: 1.3 | K33: wind offshore | L33: E_WOF
A34: Other | B34: biomass | C34: cement | D34: kt/GW | E34: 20.9185 | K34: wind onshore | L34: E_WON
A35: Other | B35: biomass | C35: copper | D35: kt/GW | E35: 0.49075 | P35: ~TFM_INS-AT
A36: Other | B36: biomass | C36: steel | D36: kt/GW | E36: 52 | P36: pset_set | Q36: commodity | R36: NCAP_ICOM
A37: Other | B37: coal + CCS | C37: aluminium | D37: kt/GW | E37: 0.39475 | J37: 1 | K37: E_Bio | M37: 1 | N37: =J37 -> 1 | P37: =VLOOKUP(N37,$J$37:$K$50,2,FALSE) -> E_Bio | Q37: ="m_"&VLOOKUP(M37,$J$2:$K$12,2,FALSE) -> m_aluminium | R37: =IF(SUMIFS($E$25:$E$114,$C$25:$C$114,MID(Q37,3,100),$B$25:$B$114,_xlfn.XLOOKUP(P37,$L$17:$L$34,$K$17:$K$34,,0)) = 0,"",SUMIFS($E$25:$E$114,$C$25:$C$114,MID(Q37,3,100),$B$25:$B$114,_xlfn.XLOOKUP(P37,$L$17:$L$34,$K$17:$K$34,,0))) -> 1.3
A38: Other | B38: coal + CCS | C38: cement | D38: kt/GW | E38: 20.6965 | J38: 2 | K38: E_Bio-S | M38: 1 | N38: =J38 -> 2 | P38: =VLOOKUP(N38,$J$37:$K$50,2,FALSE) -> E_Bio-S | Q38: ="m_"&VLOOKUP(M38,$J$2:$K$12,2,FALSE) -> m_aluminium | R38: =IF(SUMIFS($E$25:$E$114,$C$25:$C$114,MID(Q38,3,100),$B$25:$B$114,_xlfn.XLOOKUP(P38,$L$17:$L$34,$K$17:$K$34,,0)) = 0,"",SUMIFS($E$25:$E$114,$C$25:$C$114,MID(Q38,3,100),$B$25:$B$114,_xlfn.XLOOKUP(P38,$L$17:$L$34,$K$17:$K$34,,0))) -> 1.3
A39: Other | B39: coal + CCS | C39: copper | D39: kt/GW | E39: 0.58875 | J39: 3 | K39: E_Coal | M39: 1 | N39: =J39 -> 3 | P39: =VLOOKUP(N39,$J$37:$K$50,2,FALSE) -> E_Coal | Q39: ="m_"&VLOOKUP(M39,$J$2:$K$12,2,FALSE) -> m_aluminium | R39: =IF(SUMIFS($E$25:$E$114,$C$25:$C$114,MID(Q39,3,100),$B$25:$B$114,_xlfn.XLOOKUP(P39,$L$17:$L$34,$K$17:$K$34,,0)) = 0,"",SUMIFS($E$25:$E$114,$C$25:$C$114,MID(Q39,3,100),$B$25:$B$114,_xlfn.XLOOKUP(P39,$L$17:$L$34,$K$17:$K$34,,0))) -> 1.99475
A40: Other | B40: coal + CCS | C40: steel | D40: kt/GW | E40: 75.7648 | J40: 4 | K40: E_Coal-S | M40: 1 | N40: =J40 -> 4 | P40: =VLOOKUP(N40,$J$37:$K$50,2,FALSE) -> E_Coal-S | Q40: ="m_"&VLOOKUP(M40,$J$2:$K$12,2,FALSE) -> m_aluminium | R40: =IF(SUMIFS($E$25:$E$114,$C$25:$C$114,MID(Q40,3,100),$B$25:$B$114,_xlfn.XLOOKUP(P40,$L$17:$L$34,$K$17:$K$34,,0)) = 0,"",SUMIFS($E$25:$E$114,$C$25:$C$114,MID(Q40,3,100),$B$25:$B$114,_xlfn.XLOOKUP(P40,$L$17:$L$34,$K$17:$K$34,,0))) -> 0.39475
...

Sheet INS
A1: Trans - Insert
B2: ~TFM_INS
B3: TimeSlice | C3: LimType | D3: Attribute | E3: Year | F3: Curr | G3: Val_Cond | H3: AllRegions | I3: Pset_Set | J3: Pset_PN | K3: Pset_PD | L3: Pset_CI | M3: Pset_CO | N3: Cset_Set | O3: Cset_CN | P3: Cset_CD | U3: ~TFM_INS
D4: FLO_COST | F4: USD15 | H4: 2.7 | J4: *REFINE* | O4: OILDST | U4: attribute | V4: process | W4: value | X4: pset_ci | Y4: pset_co
D5: FLO_COST | F5: USD15 | H5: 1.83 | J5: *REFINE* | O5: OILGSL | U5: END | V5: EN_GeoThermal* | W5: 2025
D6: FLO_COST | F6: USD15 | H6: -2.35 | J6: *REFINE* | O6: OILHFO | U6: START | W6: 2150 | X6: *NGA | Y6: CSC,RSC
D7: FLO_COST | F7: USD15 | H7: 2.66 | J7: *REFINE* | O7: OILJTK
D8: FLO_COST | F8: USD15 | H8: -1.35 | J8: *REFINE* | O8: OILKER
D9: FLO_COST | F9: USD15 | H9: =H6 -> -2.35 | J9: *REFINE* | O9: OILLPG | U9: ~TFM_INS-TS
D10: START | H10: 2150 | J10: Trd*GH2_10 | U10: Curr | V10: Attribute | W10: 2020 | X10: 2040 | Y10: Pset_CI | Z10: Pset_CO | AA10: Pset_PN | AB10: Cset_Set | AC10: Cset_CN | AD10: PSET_SET | AE10: Top_Check | AI10: ~TFM_INS
D11: START | H11: 2150 | J11: Trd_Hdt_gsl_01 | U11: USD15 | V11: DELIV | W11: 19.44 | Y11: ELC | Z11: ___ELC | AC11: =Y11 -> ELC | AE11: IN | AI11: attribute | AJ11: pset_pn | AK11: allregions | AL11: year
U12: USD15 | V12: DELIV | W12: 15.28 | Y12: ELC | Z12: COMELC | AC12: =Y12 -> ELC | AE12: IN | AI12: NCAP_CPX | AJ12: Trd[_]* | AK12: 15
B13: ~TFM_INS | U13: USD15 | V13: DELIV | W13: 6.94 | Y13: ELC | Z13: INDELC | AC13: =Y13 -> ELC | AE13: IN | AI13: NCAP_CPX | AJ13: Trd[_]* | AK13: 2 | AL13: 0
B14: TimeSlice | C14: LimType | D14: Attribute | E14: Year | F14: Curr | G14: Val_Cond | H14: AllRegions | I14: Pset_Set | J14: Pset_PN | K14: Pset_PD | L14: Pset_CI | M14: Pset_CO | N14: Cset_Set | O14: Cset_CN | U14: USD15 | V14: DELIV | W14: 3.5 | Y14: GASNGA | Z14: ___NGA,-ELCNGA | AC14: GASNGA | AD14: PRE | AE14: IN | AI14: ELIFE | AJ14: Trd[_]* | AK14: 7
D15: START | H15: 2120 | J15: I*GEO* | U15: USD15 | V15: DELIV | W15: 0.8 | Y15: GASNGA | Z15: INDNGA,*methane | AC15: GASNGA | AD15: PRE | AE15: IN
D16: INVCOST | H16: 25 | J16: SUP_TREFINER | U16: USD15 | V16: DELIV | W16: 3.6 | Y16: GASNGA | Z16: RESNGA,COMNGA | AC16: GASNGA | AE16: IN
D17: LIFE | H17: 60 | J17: SUP_TREFINER | U17: USD15 | V17: DELIV | W17: 4.7 | Y17: GASNGA | Z17: TRANGA | AC17: GASNGA | AE17: IN
D18: DELIV | H18: 10 | I18: DMD | M18: TAD,TAI | O18: TRAELC | U18: USD15 | V18: DELIV | W18: 4 | Y18: GASNGA | Z18: GASLNG | AC18: GASNGA | AD18: PRE | AE18: IN
U19: USD15 | V19: DELIV | W19: 3.5 | Z19: ___NGAHH2,-ELCNGAHH2 | AC19: GASNGA | AE19: IN
B20: ~TFM_MIG | U20: USD15 | V20: DELIV | W20: 0.8 | Z20: INDNGAHH2 | AC20: GASNGA | AE20: IN
B21: LimType | C21: LimType2 | D21: Attribute | E21: Year2 | F21: attribute2 | G21: Val_Cond | H21: AllRegions | I21: Pset_PN | J21: CSET_SET | K21: CSET_CN | L21: top_check | U21: USD15 | V21: DELIV | W21: 3.6 | Z21: RESNGAHH2,COMNGAHH2 | AC21: GASNGA | AE21: IN
C22: UP | D22: ACT_BND | E22: 2020 | H22: *1 | I22: SUP_TRANSFER,SUP_TCOALLIQ,SUP_TGTL,SUP_TNONSPEC,SUP_TBLENDGAS | U22: USD15 | V22: DELIV | W22: 4.7 | Z22: TRANGAHH2 | AC22: GASNGA | AE22: IN
C23: UP | D23: ACT_BND | E23: 2030 | H23: 0 | I23: SUP_TCOALLIQ,SUP_TGTL,SUP_TNONSPEC,SUP_TBLENDGAS | U23: USD15 | V23: DELIV | W23: 3.04 | Y23: *LPG | Z23: RESLPG,COMLPG | AC23: *LPG | AE23: IN
C24: UP | D24: ACT_BND | E24: 2020 | H24: *1 | I24: SUP_TGASWKS | U24: USD15 | V24: DELIV | W24: 1.52 | Y24: *HFO,*KER,*DST | Z24: COMHFO,COMDST,COMKER,RESHFO,RESDST,RESKER | AC24: *HFO,*KER,*DST | AE24: IN
C25: UP | D25: ACT_BND | E25: 2050 | H25: *2 | I25: SUP_TGASWKS | U25: USD15 | V25: DELIV | W25: 23.328 | Y25: HH2 | Z25: *H2 | AC25: HH2 | AD25: -IRE,-STG | AE25: IN
D26: FLO_SHAR | E26: 2020 | H26: +.25 | I26: *REFINE* | J26: NRG | L26: OUT | U26: USD15 | V26: DELIV | W26: 45.84 | Y26: HH2 | Z26: COM* | AC26: HH2 | AE26: IN
D27: FLO_SHAR | E27: 2050 | H27: +.5 | I27: *REFINE* | J27: NRG | L27: OUT | U27: USD15 | V27: DELIV | W27: 1 | Y27: HH2 | Z27: IND* | AC27: HH2 | AE27: IN | AH27: 8.328
D28: FLO_SHAR | E28: 2020 | H28: 1 | I28: *REFINE* | J28: NRG | K28: OILCRD | U28: USD15 | V28: DELIV | W28: 1 | Y28: HH2 | Z28: ELC* | AC28: HH2 | AE28: IN | AH28: 8.328
C29: LO | D29: ACT_BND | E29: 2020 | H29: *1 | I29: SUP_TREFINER | U29: USD15 | V29: DELIV | W29: 5 | Y29: OIL*, BIO* | Z29: TRA* | AC29: OIL*, BIO* | AD29: -IRE | AE29: IN
C30: LO | D30: ACT_BND | E30: 2040 | H30: 0 | I30: =I29 -> SUP_TREFINER | U30: USD15 | V30: DELIV | W30: 45.84 | Y30: HH2 | Z30: TRA* | AC30: HH2 | AE30: IN
C31: LO | D31: ACT_BND | E31: 0 | H31: 1 | I31: =I30 -> SUP_TREFINER
B32: FX | D32: ACT_BND | E32: 2000 | F32: PASTI | H32: *.5 | I32: =I31 -> SUP_TREFINER
B33: FX | D33: ACT_BND | E33: 2010 | F33: PASTI | H33: *.5 | I33: =I32 -> SUP_TREFINER
C34: FX | D34: FLO_SHAR | H34: *1 | I34: =I33 -> SUP_TREFINER | K34: GASRFG
C35: FX | D35: FLO_SHAR | E35: 0 | H35: 3 | I35: =I34 -> SUP_TREFINER | K35: GASRFG
D36: FLO_SHAR | E36: 2020 | H36: +.25 | I36: *REFINE* | J36: NRG | K36: OILNGL | W36: ~TFM_INS: limtype=FX; PSET_SET=CHP
W37: attribute | X37: Africa_north | Y37: Africa_other | Z37: Arg-Chi | AA37: Asia_central | AB37: Asia_east | AC37: Asia_other | AD37: Australia_NZ | AE37: Brazil | AF37: Canada | AG37: China | AH37: EU_north | AI37: EU_northeast | AJ37: EU_northwest | AK37: EU_south | AL37: EU_southeast | AM37: EU_southwest | AN37: Europe_other | AO37: France | AP37: Germany | AQ37: India | AR37: LatAm_other | AS37: Mexico | AT37: MidEast_other | AU37: Nor-Ice | AV37: Russia | AW37: SaudiArabia | AX37: SouthAfrica | AY37: UK | AZ37: USA | BA37: \I: | BB37: *WORLD | BC37: year | BD37: allregions
W38: CHPR | X38: 0.5 | Y38: 0.5 | Z38: 0.5 | AA38: 0.7853622 | AB38: 0.88598513 | AC38: 0.93816871 | AD38: 0.01773276 | AE38: 0.5 | AF38: 0.51784156 | AG38: 0.68859434 | AH38: 1.9069225 | AI38: 0.60710833 | AJ38: 0.50471052 | AK38: 0.52497815 | AL38: 1.1058538 | AM38: 0.14198837 | AN38: 1.6943788 | AO38: 1.2633356 | AP38: 0.81146351 | AQ38: 0.5 | AR38: 0.5 | AS38: 0.5 | AT38: 0.5 | AU38: 0.78320258 | AV38: 1.1637896 | AW38: 0.5 | AX38: 0.5 | AY38: 0.5 | AZ38: 0.41864325 | BA38: 0.5 | BB38: 0.7497967
B39: ~TFM_TOPINS | J39: ~TFM_UPD: sourcescen=BASE | W39: CHPR | BC39: 0 | BD39: 3
B40: pset_set | C40: PSET_CO | D40: value | E40: cset_cn | F40: pset_pn | J40: attribute | K40: process | L40: commodity | M40: value
...

Sheet misc
B2: ~TFM_UPD: attribute=NCAP_COST
B3: process | C3: AllRegions
B4: RSHEHP* | C4: *3
B5: CSHAHP* | C5: *2
B8: ~TFM_INS-AT
B9: process | C9: START | D9: Share | E9: commodity | F9: region | G9: LimType
B10: H2prd_Gas_ATR_CCS | C10: 2022 | H10: late start
B11: HETHPU | C11: 2030 | H11: late start
B14: ~TFM_INS-TS: limtype=UP
B15: attribute | C15: pset_ci | D15: process | E15: Region | F15: 2024 | G15: 0
B16: ACT_BND | C16: ELCNUC | E16: Germany | F16: 0 | G16: 5 | I16: phase-out of NUC in Germany

Sheet Bldgs AFA
A1: year | B1: attribute | C1: Africa_north | D1: Africa_other | E1: Arg-Chi | F1: Asia_central | G1: Asia_east | H1: Asia_other | I1: Australia_NZ | J1: Brazil | K1: Canada | L1: China | M1: EU_north | N1: EU_northeast | O1: EU_northwest | P1: EU_south | Q1: EU_southeast | R1: EU_southwest | S1: Europe_other | T1: France | U1: Germany | V1: India | W1: LatAm_other | X1: Mexico | Y1: MidEast_other | Z1: Nor-Ice | AA1: Russia | AB1: SaudiArabia | AC1: SouthAfrica | AD1: UK | AE1: USA
A2: 2019 | B2: CDD | C2: 5999 | D2: 13019 | E2: 3440 | F2: 2020 | G2: 5384 | H2: 18766 | I2: 3695 | J2: 13340 | K2: 1255 | L2: 6485 | M2: 493 | N2: 1331 | O2: 629 | P2: 2966 | Q2: 2283 | R2: 2440 | S2: 2330 | T2: 1359 | U2: 999 | V2: 15706 | W2: 12457 | X2: 7004 | Y2: 7012 | Z2: 42 | AA2: 1627 | AB2: 9806 | AC2: 3595 | AD2: 248 | AE2: 5351
A3: 2019 | B3: HDD | C3: 6664 | D3: 1062 | E3: 13152 | F3: 22269 | G3: 12550 | H3: 1829 | I3: 6394 | J3: 819 | K3: 26043 | L3: 14399 | M3: 22121 | N3: 21518 | O3: 15787 | P3: 13725 | Q3: 17815 | R3: 12326 | S3: 17939 | T3: 15798 | U3: 20080 | V3: 2485 | W3: 2139 | X3: 3360 | Y3: 9457 | Z3: 29653 | AA3: 27031 | AB3: 4111 | AC3: 7792 | AD3: 15962 | AE3: 14715
A4: 2019 | B4: GDP | C4: 2018 | D4: 2784 | E4: 1015 | F4: 1002 | G4: 6335 | H4: 10499 | I4: 1112 | J4: 2725 | K4: 1586 | L4: 21699 | M4: 819 | N4: 1872 | O4: 1518 | P4: 2017 | Q4: 806 | R4: 1656 | S4: 2703 | T4: 2313 | U4: 3219 | V4: 8348 | W4: 2671 | X4: 1783 | Y4: 3898 | Z4: 281 | AA4: 2311 | AB4: 1713 | AC4: 626 | AD4: 2365 | AE4: 16690
A5: 2019 | B5: GDPPCAP | C5: 10174 | D5: 2678 | E5: 15890 | F5: 11067 | G5: 35593 | H5: 8773 | I5: 36630 | J5: 12911 | K5: 42200 | L5: 15441 | M5: 37898 | N5: 27125 | O5: 44141 | P5: 27939 | Q5: 19061 | R5: 28834 | S5: 16402 | T5: 33803 | U5: 38737 | V5: 6109 | W5: 10894 | X5: 13973 | Y5: 17512 | Z5: 49279 | AA5: 16001 | AB5: 49984 | AC5: 10687 | AD5: 35365 | AE5: 50833
A6: 2019 | B6: POP | C6: 198.385 | D6: 1039.486 | E6: 63.891 | F6: 90.516 | G6: 177.974 | H6: 1196.678 | I6: 30.345 | J6: 211.05 | K6: 37.593 | L6: 1405.227 | M6: 21.615 | N6: 69.006 | O6: 34.388 | P6: 72.185 | Q6: 42.272 | R6: 57.42 | S6: 164.818 | T6: 68.441 | U6: 83.093 | V6: 1366.42 | W6: 245.145 | X6: 127.576 | Y6: 222.578 | Z6: 5.708 | AA6: 144.406 | AB6: 34.269 | AC6: 58.558 | AD6: 66.878 | AE6: 328.33
A7: 2050 | B7: GDP | C7: 6067 | D7: 13490 | E7: 2490 | F7: 2356 | G7: 8794 | H7: 26893 | I7: 2116 | J7: 5225 | K7: 2531 | L7: 53306 | M7: 1323 | N7: 3082 | O7: 2380 | P7: 2797 | Q7: 1246 | R7: 2208 | S7: 5589 | T7: 3774 | U7: 4523 | V7: 27800 | W7: 6626 | X7: 4169 | Y7: 8543 | Z7: 439 | AA7: 4902 | AB7: 2584 | AC7: 1699 | AD7: 3867 | AE7: 26241
A8: 2050 | B8: GDPPCAP | C8: 23111 | D8: 7094 | E8: 33402 | F8: 21913 | G8: 56834 | H8: 17918 | I8: 54003 | J8: 22860 | K8: 55970 | L8: 41279 | M8: 55063 | N8: 48761 | O8: 63540 | P8: 41362 | Q8: 36629 | R8: 38866 | S8: 33214 | T8: 49439 | U8: 55730 | V8: 16949 | W8: 22416 | X8: 26995 | Y8: 26110 | Z8: 64101 | AA8: 36220 | AB8: 54793 | AC8: 23407 | AD8: 51926 | AE8: 67715
A9: 2050 | B9: POP | C9: 262.498 | D9: 1901.494 | E9: 74.558 | F9: 107.525 | G9: 154.724 | H9: 1500.905 | I9: 39.187 | J9: 228.559 | K9: 45.217 | L9: 1291.362 | M9: 24.02 | N9: 63.215 | O9: 37.455 | P9: 67.628 | Q9: 34.004 | R9: 56.819 | S9: 168.271 | T9: 76.329 | U9: 81.159 | V9: 1640.26 | W9: 295.594 | X9: 154.439 | Y9: 327.186 | Z9: 6.855 | AA9: 135.353 | AB9: 47.151 | AC9: 72.602 | AD9: 74.474 | AE9: 387.522
A10: 2100 | B10: GDP | C10: 17071 | D10: 110456 | E10: 6000 | F10: 4540 | G10: 11577 | H10: 73692 | I10: 5157 | J10: 9825 | K10: 5534 | L10: 62666 | M10: 2984 | N10: 5216 | O10: 4574 | P10: 5624 | Q10: 1825 | R10: 4594 | S10: 11573 | T10: 8119 | U10: 8985 | V10: 74723 | W10: 17750 | X10: 10405 | Y10: 21491 | Z10: 963 | AA10: 10246 | AB10: 3767 | AC10: 4360 | AD10: 8575 | AE10: 43396
A11: 2100 | B11: GDPPCAP | C11: 66074 | D11: 43563 | E11: 83323 | F11: 48747 | G11: 105223 | H11: 51750 | I11: 100098 | J11: 54732 | K11: 96208 | L11: 77591 | M11: 102746 | N11: 97894 | O11: 110192 | P11: 89438 | Q11: 78818 | R11: 80876 | S11: 77216 | T11: 90702 | U11: 105612 | V11: 51149 | W11: 67772 | X11: 78473 | Y11: 59071 | Z11: 113298 | AA11: 75972 | AB11: 72232 | AC11: 63460 | AD11: 100335 | AE11: 90160
A12: 2100 | B12: POP | C12: 258.364 | D12: 2535.526 | E12: 72.009 | F12: 93.143 | G12: 110.023 | H12: 1423.986 | I12: 51.518 | J12: 179.517 | K12: 57.524 | L12: 807.647 | M12: 29.04 | N12: 53.279 | O12: 41.511 | P12: 62.88 | Q12: 23.157 | R12: 56.799 | S12: 149.875 | T12: 89.518 | U12: 85.077 | V12: 1460.88 | W12: 261.912 | X12: 132.598 | Y12: 363.809 | Z12: 8.499 | AA12: 134.865 | AB12: 52.155 | AC12: 68.711 | AD12: 85.465 | AE12: 481.327
B14: MIN | C14: AVG | D14: MAX
A15: =B2 -> CDD | B15: =MIN($C2:$AC2) -> 42 | C15: =AVERAGE($C2:$AC2) -> 5388.2222 | D15: =MAX($C2:$AC2) -> 18766
A16: =B3 -> HDD | B16: =MIN($C3:$AC3) -> 819 | C16: =AVERAGE($C3:$AC3) -> 12900.667 | D16: =MAX($C3:$AC3) -> 29653
A18: RSH | B18: =1/12 -> 0.083333333 | C18: =3/12 -> 0.25 | D18: =5/12 -> 0.41666667 | E18: AFA
A19: RSC | B19: =1/12/2 -> 0.041666667 | C19: =4/12/2 -> 0.16666667 | D19: =8/12/2 -> 0.33333333
A20: RHW | B20: =2/12 -> 0.16666667 | C20: =4/12 -> 0.33333333 | D20: =D18 -> 0.41666667
A21: RLI | B21: =4/12/2 -> 0.16666667 | C21: =AVERAGE(B21,D21) -> 0.20833333 | D21: =6/12/2 -> 0.25
A22: CSH | B22: =B18-0.05 -> 0.033333333 | C22: =C18-0.05 -> 0.2 | D22: =D18-0.05 -> 0.36666667
A23: CSC | B23: =B19+0.2 -> 0.24166667 | C23: =C19+0.2 -> 0.36666667 | D23: =D19+0.2 -> 0.53333333
A24: CHW | B24: =B20+0.05 -> 0.21666667 | C24: =C20+0.05 -> 0.38333333 | D24: =D20+0.05 -> 0.46666667
A25: CLA | B25: =B21+0.3 -> 0.46666667 | C25: =C21+0.3 -> 0.50833333 | D25: =D21+0.3 -> 0.55
A26: RSH | B26: 0 | C26: 0.1 | D26: 0.2 | E26: HP share
B29: ~TFM_INS: attribute=AFA;PSET_SET=DMD,PRE; attrib_cond=-RESID
B30: pset_co | C30: pset_pn | D30: =IF(C$1="","\:"&COLUMN(),C$1) -> Africa_north | E30: =IF(D$1="","\:"&COLUMN(),D$1) -> Africa_other | F30: =IF(E$1="","\:"&COLUMN(),E$1) -> Arg-Chi | G30: =IF(F$1="","\:"&COLUMN(),F$1) -> Asia_central | H30: =IF(G$1="","\:"&COLUMN(),G$1) -> Asia_east | I30: =IF(H$1="","\:"&COLUMN(),H$1) -> Asia_other | J30: =IF(I$1="","\:"&COLUMN(),I$1) -> Australia_NZ | K30: =IF(J$1="","\:"&COLUMN(),J$1) -> Brazil | ... AK30: =IF(AJ$1="","\:"&COLUMN(),AJ$1) -> \:37
B31: =A18 -> RSH | D31: {=IFERROR(TREND($B18:$D18,$B$16:$D$16,C$3),"")} -> 0.16068436 | E31: {=IFERROR(TREND($B18:$D18,$B$16:$D$16,D$3),"")} -> 0.096484368 | F31: {=IFERROR(TREND($B18:$D18,$B$16:$D$16,E$3),"")} -> 0.23503808 | G31: {=IFERROR(TREND($B18:$D18,$B$16:$D$16,F$3),"")} -> 0.33952065 | H31: {=IFERROR(TREND($B18:$D18,$B$16:$D$16,G$3),"")} -> 0.22813905 | I31: {=IFERROR(TREND($B18:$D18,$B$16:$D$16,H$3),"")} -> 0.10527433 | J31: {=IFERROR(TREND($B18:$D18,$B$16:$D$16,I$3),"")} -> 0.15759011 | K31: {=IFERROR(TREND($B18:$D18,$B$16:$D$16,J$3),"")} -> 0.093699541 | ... AK31: {=IFERROR(TREND($B18:$D18,$B$16:$D$16,AJ$3),"")}
B32: =A19 -> RSC | D32: {=IFERROR(TREND($B19:$D19,$B$15:$D$15,C$2),"")} -> 0.1496074 | E32: {=IFERROR(TREND($B19:$D19,$B$15:$D$15,D$2),"")} -> 0.25474447 | F32: {=IFERROR(TREND($B19:$D19,$B$15:$D$15,E$2),"")} -> 0.1112818 | G32: {=IFERROR(TREND($B19:$D19,$B$15:$D$15,F$2),"")} -> 0.090014755 | H32: {=IFERROR(TREND($B19:$D19,$B$15:$D$15,G$2),"")} -> 0.14039668 | I32: {=IFERROR(TREND($B19:$D19,$B$15:$D$15,H$2),"")} -> 0.34081609 | J32: {=IFERROR(TREND($B19:$D19,$B$15:$D$15,I$2),"")} -> 0.11510088 | K32: {=IFERROR(TREND($B19:$D19,$B$15:$D$15,J$2),"")} -> 0.25955202 | ... AK32: {=IFERROR(TREND($B19:$D19,$B$15:$D$15,AJ$2),"")}
B33: =A20 -> RHW | D33: {=IFERROR(TREND($B20:$D20,$B$16:$D$16,C$3),"")} -> 0.23977447 | E33: {=IFERROR(TREND($B20:$D20,$B$16:$D$16,D$3),"")} -> 0.1924911 | F33: {=IFERROR(TREND($B20:$D20,$B$16:$D$16,E$3),"")} -> 0.29453608 | G33: {=IFERROR(TREND($B20:$D20,$B$16:$D$16,F$3),"")} -> 0.37148763 | H33: {=IFERROR(TREND($B20:$D20,$B$16:$D$16,G$3),"")} -> 0.28945494 | I33: {=IFERROR(TREND($B20:$D20,$B$16:$D$16,H$3),"")} -> 0.19896492 | J33: {=IFERROR(TREND($B20:$D20,$B$16:$D$16,I$3),"")} -> 0.23749555 | K33: {=IFERROR(TREND($B20:$D20,$B$16:$D$16,J$3),"")} -> 0.19044007 | ... AK33: {=IFERROR(TREND($B20:$D20,$B$16:$D$16,AJ$3),"")}
B34: =A21 -> RLI | D34: {=IFERROR(TREND($B21:$D21,$B$16:$D$16,C$3),"")} -> 0.18600442 | E34: {=IFERROR(TREND($B21:$D21,$B$16:$D$16,D$3),"")} -> 0.16995443 | F34: {=IFERROR(TREND($B21:$D21,$B$16:$D$16,E$3),"")} -> 0.20459285 | G34: {=IFERROR(TREND($B21:$D21,$B$16:$D$16,F$3),"")} -> 0.2307135 | H34: {=IFERROR(TREND($B21:$D21,$B$16:$D$16,G$3),"")} -> 0.2028681 | I34: {=IFERROR(TREND($B21:$D21,$B$16:$D$16,H$3),"")} -> 0.17215192 | J34: {=IFERROR(TREND($B21:$D21,$B$16:$D$16,I$3),"")} -> 0.18523086 | K34: {=IFERROR(TREND($B21:$D21,$B$16:$D$16,J$3),"")} -> 0.16925822 | ... AK34: {=IFERROR(TREND($B21:$D21,$B$16:$D$16,AJ$3),"")}
B35: =A22 -> CSH | D35: {=IFERROR(TREND($B22:$D22,$B$16:$D$16,C$3),"")} -> 0.11068436 | E35: {=IFERROR(TREND($B22:$D22,$B$16:$D$16,D$3),"")} -> 0.046484368 | F35: {=IFERROR(TREND($B22:$D22,$B$16:$D$16,E$3),"")} -> 0.18503808 | G35: {=IFERROR(TREND($B22:$D22,$B$16:$D$16,F$3),"")} -> 0.28952065 | H35: {=IFERROR(TREND($B22:$D22,$B$16:$D$16,G$3),"")} -> 0.17813905 | I35: {=IFERROR(TREND($B22:$D22,$B$16:$D$16,H$3),"")} -> 0.055274335 | J35: {=IFERROR(TREND($B22:$D22,$B$16:$D$16,I$3),"")} -> 0.10759011 | K35: {=IFERROR(TREND($B22:$D22,$B$16:$D$16,J$3),"")} -> 0.043699541 | ... AK35: {=IFERROR(TREND($B22:$D22,$B$16:$D$16,AJ$3),"")}
B36: =A23 -> CSC | D36: {=IFERROR(TREND($B23:$D23,$B$15:$D$15,C$2),"")} -> 0.3496074 | E36: {=IFERROR(TREND($B23:$D23,$B$15:$D$15,D$2),"")} -> 0.45474447 | F36: {=IFERROR(TREND($B23:$D23,$B$15:$D$15,E$2),"")} -> 0.3112818 | G36: {=IFERROR(TREND($B23:$D23,$B$15:$D$15,F$2),"")} -> 0.29001476 | H36: {=IFERROR(TREND($B23:$D23,$B$15:$D$15,G$2),"")} -> 0.34039668 | I36: {=IFERROR(TREND($B23:$D23,$B$15:$D$15,H$2),"")} -> 0.54081609 | J36: {=IFERROR(TREND($B23:$D23,$B$15:$D$15,I$2),"")} -> 0.31510088 | K36: {=IFERROR(TREND($B23:$D23,$B$15:$D$15,J$2),"")} -> 0.45955202 | ... AK36: {=IFERROR(TREND($B23:$D23,$B$15:$D$15,AJ$2),"")}
B37: =A24 -> CHW | D37: {=IFERROR(TREND($B24:$D24,$B$16:$D$16,C$3),"")} -> 0.28977447 | E37: {=IFERROR(TREND($B24:$D24,$B$16:$D$16,D$3),"")} -> 0.2424911 | F37: {=IFERROR(TREND($B24:$D24,$B$16:$D$16,E$3),"")} -> 0.34453608 | G37: {=IFERROR(TREND($B24:$D24,$B$16:$D$16,F$3),"")} -> 0.42148763 | H37: {=IFERROR(TREND($B24:$D24,$B$16:$D$16,G$3),"")} -> 0.33945494 | I37: {=IFERROR(TREND($B24:$D24,$B$16:$D$16,H$3),"")} -> 0.24896492 | J37: {=IFERROR(TREND($B24:$D24,$B$16:$D$16,I$3),"")} -> 0.28749555 | K37: {=IFERROR(TREND($B24:$D24,$B$16:$D$16,J$3),"")} -> 0.24044007 | ... AK37: {=IFERROR(TREND($B24:$D24,$B$16:$D$16,AJ$3),"")}
B38: =A25 -> CLA | D38: {=IFERROR(TREND($B25:$D25,$B$16:$D$16,C$3),"")} -> 0.48600442 | E38: {=IFERROR(TREND($B25:$D25,$B$16:$D$16,D$3),"")} -> 0.46995443 | F38: {=IFERROR(TREND($B25:$D25,$B$16:$D$16,E$3),"")} -> 0.50459285 | G38: {=IFERROR(TREND($B25:$D25,$B$16:$D$16,F$3),"")} -> 0.5307135 | H38: {=IFERROR(TREND($B25:$D25,$B$16:$D$16,G$3),"")} -> 0.5028681 | I38: {=IFERROR(TREND($B25:$D25,$B$16:$D$16,H$3),"")} -> 0.47215192 | J38: {=IFERROR(TREND($B25:$D25,$B$16:$D$16,I$3),"")} -> 0.48523086 | K38: {=IFERROR(TREND($B25:$D25,$B$16:$D$16,J$3),"")} -> 0.46925822 | ... AK38: {=IFERROR(TREND($B25:$D25,$B$16:$D$16,AJ$3),"")}
C39: FT_RESHH2_RSH | D39: =D31 -> 0.16068436 | E39: =E31 -> 0.096484368 | F39: =F31 -> 0.23503808 | G39: =G31 -> 0.33952065 | H39: =H31 -> 0.22813905 | I39: =I31 -> 0.10527433 | J39: =J31 -> 0.15759011 | K39: =K31 -> 0.093699541 | ... AF39: =AF31 -> 0.25295036
C40: FT_RESHH2_RWH | D40: =D33 -> 0.23977447 | E40: =E33 -> 0.1924911 | F40: =F33 -> 0.29453608 | G40: =G33 -> 0.37148763 | H40: =H33 -> 0.28945494 | I40: =I33 -> 0.19896492 | J40: =J33 -> 0.23749555 | K40: =K33 -> 0.19044007 | ... AF40: =AF33 -> 0.3077285
C41: FT_COMHH2_CSH | D41: =D35 -> 0.11068436 | E41: =E35 -> 0.046484368 | F41: =F35 -> 0.18503808 | G41: =G35 -> 0.28952065 | H41: =H35 -> 0.17813905 | I41: =I35 -> 0.055274335 | J41: =J35 -> 0.10759011 | K41: =K35 -> 0.043699541 | ... AF41: =AF35 -> 0.20295036
C42: FT_COMHH2_CWH | D42: =D37 -> 0.28977447 | E42: =E37 -> 0.2424911 | F42: =F37 -> 0.34453608 | G42: =G37 -> 0.42148763 | H42: =H37 -> 0.33945494 | I42: =I37 -> 0.24896492 | J42: =J37 -> 0.28749555 | K42: =K37 -> 0.24044007 | ... AF42: =AF37 -> 0.3577285
A46: DeACT TFM_INS: attribute=prc_mark;PSET_SET=DMD,PRE;limtype=UP
A47: other_indexes | B47: pset_co | C47: =IF(C$1="","\:"&COLUMN(),C$1) -> Africa_north | D47: =IF(D$1="","\:"&COLUMN(),D$1) -> Africa_other | E47: =IF(E$1="","\:"&COLUMN(),E$1) -> Arg-Chi | F47: =IF(F$1="","\:"&COLUMN(),F$1) -> Asia_central | G47: =IF(G$1="","\:"&COLUMN(),G$1) -> Asia_east | H47: =IF(H$1="","\:"&COLUMN(),H$1) -> Asia_other | I47: =IF(I$1="","\:"&COLUMN(),I$1) -> Australia_NZ | J47: =IF(J$1="","\:"&COLUMN(),J$1) -> Brazil | ... AJ47: =IF(AJ$1="","\:"&COLUMN(),AJ$1) -> \:36 | AK47: cset_cn | AL47: attrib_cond | AM47: val_cond | AN47: pset_pn | AO47: year
...

Sheet Cap decay limits
A2: ~UC_Sets: R_E: AllRegions
D4: ="~UC_T: 2022" -> ~UC_T: 2022
A5: UC_N | B5: PSET_SET | C5: PSET_CI | D5: LimType | E5: UC_CAP | F5: UC_CAP~RHS | G5: UC_RHSRT~0 | H5: UC_Desc | I5: UC_DYNBND
A6: UC_Capdecay-OIL | B6: ELE,CHP | C6: ELCOIL* | D6: LO | E6: 0.88 | F6: -0.5 | G6: 5 | H6: =RIGHT(A6,3)&" capacity annual decay limit - "&TEXT(1-E6,"0.0%") -> OIL capacity annual decay limit - 12.0% | I6: 1 | K6: =E6^30 -> 0.021601314
A7: UC_Capdecay-Coa | B7: ELE,CHP | C7: ELCCOA, ELCCOB | D7: LO | E7: 0.88 | F7: -1 | G7: 5 | H7: =RIGHT(A7,3)&" capacity annual decay limit - "&TEXT(1-E7,"0.0%") -> Coa capacity annual decay limit - 12.0% | I7: 1 | K7: =E7^30 -> 0.021601314
A8: UC_Capdecay-Gas | B8: ELE,CHP | C8: ELCNGA | D8: LO | E8: 0.9 | F8: -1 | G8: 5 | H8: =RIGHT(A8,3)&" capacity annual decay limit - "&TEXT(1-E8,"0.0%") -> Gas capacity annual decay limit - 10.0% | I8: 1 | K8: =E8^30 -> 0.042391158

Sheet Trade costs
B2: ~TFM_INS
B3: TimeSlice | C3: Attribute | D3: Curr | E3: AllRegions | F3: MidEast_Naf | G3: Pset_Set | H3: Pset_PN | I3: Pset_CI | J3: Pset_CO
C4: ACT_COST | D4: USD18 | E4: 25 | G4: IRE | H4: Glb*
C5: ACT_COST | D5: USD18 | E5: =E6*3 -> 1.5 | G5: IRE | H5: Glb* | I5: BIO*
C6: ACT_COST | D6: USD18 | E6: =(0.1+0.9)/2 -> 0.5 | G6: IRE | H6: Glb* | I6: COA* | L6: $10/t
C7: ACT_COST | D7: USD18 | E7: =3/1.1/2 -> 1.3636364 | G7: IRE | H7: Glb* | I7: GAS* | L7: $3/1000 cf
C8: ACT_COST | D8: USD18 | E8: =5/5.8/2 -> 0.43103448 | G8: IRE | H8: Glb* | I8: OIL* | L8: $5/bbl
C9: ACT_COST | D9: USD18 | E9: =E8 -> 0.43103448 | G9: IRE | H9: Glb* | I9: BIODST,BIOGSL,BIOJTK
B10: \I: | C10: ACT_COST | D10: USD18 | E10: =O11/2 -> 6.25 | G10: IRE | H10: Glb* | I10: HH2 | O10: 1 | P10: Euro/kg | Q10: ammonia shipping
C11: ACT_COST | D11: USD18 | E11: =10/(3.6)*1.11/2 -> 1.5416667 | G11: IRE | H11: Glb* | I11: NH3 | O11: =1/120*1000*1.5 -> 12.5 | P11: m$/PJ
C12: ACT_COST | D12: USD18 | E12: =E7*0.95 -> 1.2954545 | G12: IRE | H12: TU_LNG*
C13: ACT_COST | D13: USD18 | E13: =0.15/2 -> 0.075 | F13: =E13/2 -> 0.0375 | G13: IRE | H13: Glb* | I13: *CO2* | L13: CO2 shipping at $150/t
C14: ACT_COST | D14: USD18 | E14: =100/2 -> 50 | G14: IRE | H14: Glb* | I14: im[_]*
B16: ~UC_SETS: R_E: AllRegions
P17: ~TFM_INS: attribute=START
E18: DeACT UC_T: UC_RHSRT~UP | P18: process | Q18: attrib_cond | R18: value
B19: UC_N | C19: cset_set | D19: pset_pn | E19: pset_set | F19: UC_IRE-E | G19: UC_IRE-I | H19: 2020 | I19: 0 | J19: commodity | K19: top_check | L19: region | P19: TU[_]ELC[_]* | Q19: -CAP_BND | R19: 2150 | T19: disabling unbounded trade links
B20: UCS_oil prod export lim | C20: ALLOILcrd,ALLOILprd | E20: IRE | F20: 1 | H20: 0 | I20: 3 | J20: -SUP* | K20: IN
C21: ALLOILcrd | D21: SUP[_]*,WB_Sup* | G21: -1 | J21: -SUP* | K21: OUT
C22: =C20 -> ALLOILcrd,ALLOILprd | E22: =E20 -> IRE | F22: -1 | L22: GBL
B23: UCS_coal prod export lim | C23: AllCOAL,AllCoalind | E23: IRE | F23: 1 | H23: 0 | I23: 3 | J23: -SUP* | K23: IN
C24: AllCoal | D24: MIN*,-IMPNRGZ | E24: IRE | G24: -1 | J24: -SUP* | K24: OUT | R24: 2018 | S24: Décembre | T24: 0.88 | V24: =AVERAGE(T24:T35) -> 0.84833333
C25: AllCOAL,AllCoalind | E25: IRE | F25: -1 | L25: GBL | R25: 2018 | S25: Novembre | T25: 0.88
R26: 2018 | S26: Octobre | T26: 0.87
R27: 2018 | S27: Septembre | T27: 0.86
R28: 2018 | S28: Août | T28: 0.87
E29: ~UC_T: UC_RHSRT~UP | R29: 2018 | S29: Juillet | T29: 0.86
B30: UC_N | C30: pset_pn | D30: pset_co | E30: pset_set | F30: UC_FLO | G30: UC_ACT | H30: 2035 | I30: 0 | J30: commodity | K30: top_check | R30: 2018 | S30: Juin | T30: 0.86
B31: UC_BECCS only from dom bio | D31: CO2Cap* | F31: 1 | H31: 50 | I31: 5 | J31: *BSL* | K31: IN | R31: 2018 | S31: Mai | T31: 0.85
C32: MINBIO* | G32: -1 | R32: 2018 | S32: Avril | T32: 0.81
R33: 2018 | S33: Mars | T33: 0.81
R34: 2018 | S34: Février | T34: 0.81
R35: 2018 | S35: Janvier | T35: 0.82
C36: DeactUC_T: UC_RHSRT~N
B37: UC_N | C37: pset_pn | D37: uc_act | E37: 2035 | F37: 0
B38: UC_H2 export only from elec | C38: Glb*HH2 | D38: 1 | E38: 0 | F38: 5
C39: H2prd_Elc* | D39: -1

Sheet Buildrates
A2: Transport sector | G2: Road transport | H2: Year | I2: fuel | J2: Africa_north | K2: Africa_other | L2: Arg-Chi | M2: Asia_central | N2: Asia_east | O2: Asia_other | P2: Australia_NZ | Q2: Brazil | R2: Canada | S2: China | T2: EU_north | U2: EU_northeast | V2: EU_northwest | W2: EU_south | X2: EU_southeast | Y2: EU_southwest | Z2: Europe_other | AA2: France | AB2: Germany | AC2: India | AD2: LatAm_other | AE2: Mexico | AF2: MidEast_other | AG2: Nor-Ice | AH2: Russia | AI2: SaudiArabia | AJ2: SouthAfrica | AK2: UK | AL2: USA | AM2: \I:
G3: 2019 PJ | H3: 2019 | I3: OBI | Q3: 496.38605 | V3: 0.0008 | AB3: 0.0538506
A4: ~TFM_INS-TS: limtype=FX;pset_set=PRE | H4: 2019 | I4: NON | J4: 1827.6908 | K4: 2230.9798 | L4: 884.22634 | M4: 606.9714 | N4: 3732.6134 | O4: 6390.0862 | P4: 1349.7912 | Q4: 2334.1735 | R4: 2004.2857 | S4: 9984.4677 | T4: 512.62599 | U4: 1611.9483 | V4: 971.72154 | W4: 1451.8878 | X4: 699.79049 | Y4: 1345.321 | Z4: 1759.8616 | AA4: 1615.5034 | AB4: 2111.8832 | AC4: 3776.5389 | AD4: 2297.9322 | AE4: 2014.3127 | AF4: 3857.3898 | AG4: 129.42536 | AH4: 2109.5665 | AI4: 1871.1694 | AJ4: 663.70264 | AK4: 1537.3774 | AL4: 20628.797
A5: attribute | B5: pset_co | C5: pset_pn | D5: 2020 | E5: 0 | H5: 2019 | I5: BIO | K5: 1.9221429 | L5: 64.911063 | M5: 0.0096045 | N5: 44.007304 | O5: 311.06761 | P5: 5.6731723 | Q5: 390.59743 | R5: 88.233519 | S5: 123.93562 | T5: 85.160876 | U5: 89.585484 | V5: 59.366566 | W5: 62.103475 | X5: 39.855055 | Y5: 79.38233 | Z5: 23.4148 | AA5: 133.05519 | AB5: 111.51554 | AC5: 38.457755 | AD5: 62.441997 | AG5: 21.235321 | AK5: 68.90072 | AL5: 1551.2082
A6: ncap_cost | B6: TRAB??,TRA?H2 | C6: -TRAGH2*,-TRALH2* | D6: 0.01
A7: AF | B7: TRAB??,TRA?H2 | C7: -TRAGH2*,-TRALH2* | D7: 1 | E7: 3
A8: LIFE | B8: TRAB??,TRA?H2 | C8: -TRAGH2*,-TRALH2* | D8: 100
H10: ~UC_T: UC_RHSRT~N
E11: UC_N | F11: Pset_CO | G11: pset_pn | H11: UC_ATTR | I11: Year | J11: UC_NCAP | K11: =J$2 -> Africa_north | L11: =K$2 -> Africa_other | M11: =L$2 -> Arg-Chi | N11: =M$2 -> Asia_central | O11: =N$2 -> Asia_east | P11: =O$2 -> Asia_other | Q11: =P$2 -> Australia_NZ | R11: =Q$2 -> Brazil | ... AN11: =AM$2 -> \I: | AO11: 0
A12: 0.01 | E12: UC_Bld_Tra biofuels | F12: TRAB?? | G12: IMPNRGZ | H12: NCAP,BUILDUP | I12: 2019 | J12: 1 | K12: =J$4*$A12+J$5+J$3 -> 18.276908 | L12: =K$4*$A12+K$5+K$3 -> 24.231941 | M12: =L$4*$A12+L$5+L$3 -> 73.753326 | N12: =M$4*$A12+M$5+M$3 -> 6.0793185 | O12: =N$4*$A12+N$5+N$3 -> 81.333438 | P12: =O$4*$A12+O$5+O$3 -> 374.96847 | Q12: =P$4*$A12+P$5+P$3 -> 19.171085 | R12: =Q$4*$A12+Q$5+Q$3 -> 910.32521 | ... AN12: =AM$4*$A12+AM$5+AM$3 -> 0 | AO12: 3
A13: 0.03 | I13: 2030 | K13: =J$4*$A13+J$5+J$3 -> 54.830725 | L13: =K$4*$A13+K$5+K$3 -> 68.851537 | M13: =L$4*$A13+L$5+L$3 -> 91.437853 | N13: =M$4*$A13+M$5+M$3 -> 18.218746 | O13: =N$4*$A13+N$5+N$3 -> 155.98571 | P13: =O$4*$A13+O$5+O$3 -> 502.77019 | Q13: =P$4*$A13+P$5+P$3 -> 46.166909 | R13: =Q$4*$A13+Q$5+Q$3 -> 957.00868 | ... AN13: =AM$4*$A13+AM$5+AM$3 -> 0
A14: 0.06 | I14: 2050 | K14: =J$4*$A14+J$5+J$3 -> 109.66145 | L14: =K$4*$A14+K$5+K$3 -> 135.78093 | M14: =L$4*$A14+L$5+L$3 -> 117.96464 | N14: =M$4*$A14+M$5+M$3 -> 36.427888 | O14: =N$4*$A14+N$5+N$3 -> 267.96411 | P14: =O$4*$A14+O$5+O$3 -> 694.47278 | Q14: =P$4*$A14+P$5+P$3 -> 86.660647 | R14: =Q$4*$A14+Q$5+Q$3 -> 1027.0339 | ... AN14: =AM$4*$A14+AM$5+AM$3 -> 0
H16: ~UC_T: UC_RHSRT~N
E17: UC_N | F17: Pset_CO | G17: pset_pn | H17: UC_ATTR | I17: Year | J17: UC_NCAP | K17: =J$2 -> Africa_north | L17: =K$2 -> Africa_other | M17: =L$2 -> Arg-Chi | N17: =M$2 -> Asia_central | O17: =N$2 -> Asia_east | P17: =O$2 -> Asia_other | Q17: =P$2 -> Australia_NZ | R17: =Q$2 -> Brazil | ... AN17: =AM$2 -> \I: | AO17: 0
A18: 0.02 | E18: UC_Bld_Tra H2 | F18: TRA?H2 | G18: IMPNRGZ | H18: NCAP,BUILDUP | I18: 2019 | J18: 1 | K18: =J$4*$A18 -> 36.553817 | L18: =K$4*$A18 -> 44.619596 | M18: =L$4*$A18 -> 17.684527 | N18: =M$4*$A18 -> 12.139428 | O18: =N$4*$A18 -> 74.652268 | P18: =O$4*$A18 -> 127.80172 | Q18: =P$4*$A18 -> 26.995825 | R18: =Q$4*$A18 -> 46.683469 | ... AN18: =AM$4*$A18 -> 0 | AO18: 3
A19: 0.05 | I19: 2030 | K19: =J$4*$A19 -> 91.384542 | L19: =K$4*$A19 -> 111.54899 | M19: =L$4*$A19 -> 44.211317 | N19: =M$4*$A19 -> 30.34857 | O19: =N$4*$A19 -> 186.63067 | P19: =O$4*$A19 -> 319.50431 | Q19: =P$4*$A19 -> 67.489562 | R19: =Q$4*$A19 -> 116.70867 | ... AN19: =AM$4*$A19 -> 0
A20: 0.075 | I20: 2050 | K20: =J$4*$A20 -> 137.07681 | L20: =K$4*$A20 -> 167.32349 | M20: =L$4*$A20 -> 66.316975 | N20: =M$4*$A20 -> 45.522855 | O20: =N$4*$A20 -> 279.94601 | P20: =O$4*$A20 -> 479.25646 | Q20: =P$4*$A20 -> 101.23434 | R20: =Q$4*$A20 -> 175.06301 | ... AN20: =AM$4*$A20 -> 0

Sheet demelast and reporting
H1: ~UC_SETS: R_E: AllRegions
B2: ~tfm_topins | O2: ~UC_T: N
B3: process | C3: commodity | D3: value | K3: UC_N | L3: pset_set | M3: pset_pn | N3: cset_set | O3: commodity | P3: uc_flo | Q3: uc_ire-e | R3: uc_comprd | S3: uc_comnet | T3: uc_rhsrt~0 | U3: UC_ATTR
B4: agr000 | C4: repuc_unity | D4: out | K4: rep_tra_road_pass | O4: Trd_Car,Trd_2w,Trd_3w,Trd_bus | R4: 1 | T4: 2
B5: dummy_source | C5: NETCO2[_]* | D5: out | K5: rep_tra_road_frt | O5: Trd_Hdt,Trd_Lcv | R5: 1 | T5: 2
B6: dummy_sink | C6: NETCO2[_]* | D6: in | K6: rep_totco2 | O6: TOTCO2 | S6: 1 | T6: 2
K7: *
B8: ~tfm_ins-ts | K8: rep_com_cookhw | O8: CCK | R8: 1 | T8: 2
B9: attribute | C9: commodity | D9: 2020 | E9: 0 | F9: limtype | K9: rep_com_cookhw | O9: CHW | R9: 1 | T9: 2
B10: com_bndnet | C10: repuc_unity | D10: 1 | E10: 3 | F10: FX | K10: rep_com_lightappl | O10: CLA | R10: 1 | T10: 2
K11: rep_com_lightappl | O11: COE,COT,CRF | R11: 1 | T11: 2
K12: rep_com_spcool | O12: CSC | R12: 1 | T12: 2
B13: ~tfm_ins-ts: limtype=LO | K13: rep_com_spht | O13: CSH | R13: 1 | T13: 2
B14: attribute | C14: cset_set | D14: 2025 | E14: 2035 | F14: 2050 | G14: commodity | H14: c_pos_andor_forsets | K14: *
B15: COM_ELAST | C15: DEM | D15: -0.3 | G15: im_stlslabs | H15: OR | K15: rep_res_cookhw | O15: RCK | R15: 1 | T15: 2
B16: COM_VOC | C16: DEM | D16: 0 | E16: 0.3 | F16: 0.5 | G16: im_stlslabs | H16: OR | K16: rep_res_cookhw | O16: RHW | R16: 1 | T16: 2
B17: COM_STEP | C17: DEM | D17: 10 | G17: im_stlslabs | H17: OR | K17: rep_res_lightappl | O17: RCD,RCW,RDW,REA,ROT,RRF | R17: 1 | T17: 2
B18: COM_ELAST | C18: DEM | D18: -0.1 | G18: RSH,RCK,RWH,RSC,CSH,CCK,CSC,CHW | K18: rep_res_lightappl | O18: RLI | R18: 1 | T18: 2
B19: COM_VOC | C19: DEM | D19: 0 | E19: =F19/2 -> 0.025 | F19: 0.05 | K19: rep_res_spcool | O19: RSC | R19: 1 | T19: 2
K20: rep_res_spht | O20: RSH | R20: 1 | T20: 2
K21: *
K22: rep_period_length | M22: agr000 | O22: repuc_unity | P22: 1 | T22: 2 | U22: FLO,PERIOD
L26: ~UC_T: N
K27: UC_N | L27: process | M27: uc_cumact | N27: uc_dynbnd | O27: year
K28: rep_CumFlows | N28: 1
L29: mingas_rs*,minoil_rs* | M29: 1 | O29: 2019-2030
L30: mingas_rs*,minoil_rs* | M30: 1 | O30: 2019-2035
L31: mingas_rs*,minoil_rs* | M31: 1 | O31: 2019-2040
L32: mingas_rs*,minoil_rs* | M32: 1 | O32: 2019-2045

Sheet Thermal elec op costs
A1: Fixom and Varom computation for NEEDS units.sql | AC1: ~TFM_INS-TS: attribute=SHAPE
A2: Plant Type | B2: SO2 Control | C2: NOx Control | D2: Hg Control | E2: Age of Unit | F2: FOM (2019$ /kW-Yr) | G2: Age2 | H2: FOM2 | I2: SHAPE | J2: 1 | K2: 39 | L2: 40 | M2: 41 | N2: 79 | O2: 80 | P2: 81 | Q2: 119 | R2: 120 | S2: 121 | T2: 159 | U2: 160 | V2: 161 | W2: 199 | X2: 200 | AC2: other_indexes | AD2: =J2 -> 1 | AE2: =K2 -> 39 | AF2: =L2 -> 40 | AG2: =M2 -> 41 | AH2: =N2 -> 79 | AI2: =O2 -> 80 | AJ2: =P2 -> 81 | AK2: =Q2 -> 119 | ... AR2: =X2 -> 200
A3: Coal Steam | B3: Dry FGD | C3: None | D3: None | E3: 0 to 40 Years | F3: 39.18 | G3: 40 to 50 Years | H3: 43.5 | I3: 81 | J3: 1 | K3: 1.11 | L3: 6.18 | M3: 1 | N3: 1.11 | O3: 6.18 | P3: 1 | Q3: 1.11 | R3: 6.18 | S3: 1 | T3: 1.11 | U3: 6.18 | V3: 1 | W3: 1.11 | X3: 6.18 | AC3: =I3 -> 81 | AD3: =J3 -> 1 | AE3: =K3 -> 1.11 | AF3: =L3 -> 6.18 | AG3: =M3 -> 1 | AH3: =N3 -> 1.11 | AI3: =O3 -> 6.18 | AJ3: =P3 -> 1 | ... AR3: =X3 -> 6.18
A4: O/G Steam | B4: None | C4: SCR | D4: None | E4: 0 to 40 Years | F4: 19.34 | G4: 40 to 50 Years | H4: 28.67 | I4: 82 | J4: 1 | K4: 1.48 | L4: 10 | M4: 1 | N4: 1.48 | O4: 10 | P4: 1 | Q4: 1.48 | R4: 10 | S4: 1 | T4: 1.48 | U4: 10 | V4: 1 | W4: 1.48 | X4: 10 | AC4: =I4 -> 82 | AD4: =J4 -> 1 | AE4: =K4 -> 1.48 | AF4: =L4 -> 10 | AG4: =M4 -> 1 | AH4: =N4 -> 1.48 | AI4: =O4 -> 10 | AJ4: =P4 -> 1 | ... AR4: =X4 -> 10
AC6: ~TFM_INS-TS: attribute=SHAPE
A7: Plant Type | B7: SO2 Control | C7: NOx Control | D7: Hg Control | E7: Age of Unit | F7: FOM (2019$ /kW-Yr) | G7: SHAPE | H7: 1 | I7: 29 | J7: 30 | K7: 31 | L7: 59 | M7: 60 | N7: 61 | O7: 89 | P7: 90 | Q7: 91 | R7: 119 | S7: 120 | T7: 121 | U7: 149 | V7: 150 | W7: 151 | X7: 179 | Y7: 180 | Z7: 181 | AA7: 200 | AC7: other_indexes | AD7: =H7 -> 1 | AE7: =I7 -> 29 | AF7: =J7 -> 30 | AG7: =K7 -> 31 | AH7: =L7 -> 59 | AI7: =M7 -> 60 | AJ7: =N7 -> 61 | AK7: =O7 -> 89 | ... AW7: =AA7 -> 200
A8: Combined Cycle | B8: None | C8: None | D8: None | E8: All Years | F8: 30.18 | G8: 83 | H8: 1 | I8: 1 | J8: 3.72 | K8: 1 | L8: 1 | M8: 3.72 | N8: 1 | O8: 1 | P8: 3.72 | Q8: 1 | R8: 1 | S8: 3.72 | T8: 1 | U8: 1 | V8: 3.72 | W8: 1 | X8: 1 | Y8: 3.72 | Z8: 1 | AA8: 3.72 | AC8: =G8 -> 83 | AD8: =H8 -> 1 | AE8: =I8 -> 1 | AF8: =J8 -> 3.72 | AG8: =K8 -> 1 | AH8: =L8 -> 1 | AI8: =M8 -> 3.72 | AJ8: =N8 -> 1 | ... AW8: =AA8 -> 3.72
A9: Combustion Turbine | B9: None | C9: None | D9: None | E9: All Years | F9: 19.73 | G9: 84 | H9: 1 | I9: 1 | J9: 13.27 | K9: 1 | L9: 1 | M9: 13.27 | N9: 1 | O9: 1 | P9: 13.27 | Q9: 1 | R9: 1 | S9: 13.27 | T9: 1 | U9: 1 | V9: 13.27 | W9: 1 | X9: 1 | Y9: 13.27 | Z9: 1 | AA9: 13.27 | AC9: =G9 -> 84 | AD9: =H9 -> 1 | AE9: =I9 -> 1 | AF9: =J9 -> 13.27 | AG9: =K9 -> 1 | AH9: =L9 -> 1 | AI9: =M9 -> 13.27 | AJ9: =N9 -> 1 | ... AW9: =AA9 -> 13.27
A12: IPM Table 4-10 Life Extension Cost Assumptions Used in v6
A13: The life extension costs were added once the unit reaches its assumed lifespan.
A14: However, if the unit reaches its lifespan before the first run year, then the life extension cost was applied when the unit reaches twice its lifespan age.
A15: The assumption implies if the unit has reached its lifespan before the first run year, it has already incurred the necessary life extension related investment costs and is considered sunk.
A17: Type, Lifespan | B17: Lifespan | C17: Life Extension Cost (2019$/kW)
A18: Biomass 40 | B18: 40 | C18: 253
A19: Coal Steam 40 | B19: 40 | C19: 203 | G19: ~TFM_INS-TS
A20: Combined Cycle 30 | B20: 30 | C20: 82 | G20: attribute | H20: PSET_SET | I20: other_indexes | J20: CSET_CN | K20: PSET_CI | L20: 2019 | M20: 0
A21: Combustion Turbine 30 | B21: 30 | C21: 242 | G21: NCAP_FOMX | H21: E_Coal,DMD_AUTOP | K21: *CO? | L21: =AC3 -> 81 | M21: 2
A22: IC Engine 30 | B22: 30 | C22: 226 | G22: NCAP_FOMX | H22: E_Gas-ST | L22: =AC4 -> 82 | M22: 2
A23: Oil/Gas Steam 40 | B23: 40 | C23: 174 | G23: NCAP_FOMX | H23: E_Gas-CC | L23: =AC8 -> 83 | M23: 2
A24: IGCC 40 | B24: 40 | C24: 258 | G24: NCAP_FOMX | H24: E_Gas-CT | L24: =AC9 -> 84 | M24: 2
A25: Landfill Gas 20 | B25: 20 | C25: 135
A30: ~TFM_INS
A31: Attribute | B31: Other_Indexes | C31: Year | D31: AllRegions
A32: SHAPE | B32: 85 | C32: 1 | D32: 1 | F32: coal var
A33: SHAPE | B33: =B32 -> 85 | C33: 100 | D33: 1.5
A34: SHAPE | B34: 86 | C34: 1 | D34: 1 | F34: gas var
A35: SHAPE | B35: =B34 -> 86 | C35: 100 | D35: 1.25

Sheet emissions
D1: fuel | E1: kg/GJ | F1: source | R1: ~TFM_DINS | X1: ~TFM_INS | AF1: ~TFM_TOPINS
A2: AGRCOA | B2: =MID(A2,4,7) -> COA | D2: BFG | E2: =N12 -> 55.99 | F2: c | G2: Carbon Dioxide Emissions Coefficients by Fuel | R2: attribute | S2: commodity | T2: other_indexes | U2: value | X2: attribute | Y2: pset_set | Z2: commodity | AA2: other_indexes | AB2: value | AF2: process | AG2: io | AH2: commodity
A3: AGRKER | B3: =MID(A3,4,7) -> KER | D3: BIO | E3: =E5 -> 98.43 | F3: b | H3: Pounds CO2 | J3: Kilograms CO2 | L3: Pounds CO2 | M3: Kilograms CO2 | N3: Kilograms CO2 | R3: VDA_EMCB | S3: =A2 -> AGRCOA | T3: =LEFT(S3,3)&"CO2N"&VLOOKUP(MID(S3,4,7),$D$2:$F$27,3,FALSE) -> AGRCO2Nc | U3: =VLOOKUP(MID(S3,4,7),$D$2:$F$27,2,FALSE) -> 98.43 | X3: COM_AGG | Z3: ???CO2??,-*b,INDCO2P | AA3: TOTCO2 | AB3: 0.001 | AF3: Pipeline-CO2 | AG3: in | AH3: CO2Captured[_]*
A4: AGRLPG | B4: =MID(A4,4,7) -> LPG | D4: BSL | E4: =E3 -> 98.43 | F4: =F3 -> b | G4: Carbon Dioxide (CO2) Factors: | H4: Per Unit of Volume or Mass | J4: Per Unit of Volume or Mass | L4: Per Million Btu | M4: Per Million Btu | N4: Per GJ | R4: VDA_EMCB | S4: =A3 -> AGRKER | T4: =LEFT(S4,3)&"CO2N"&VLOOKUP(MID(S4,4,7),$D$2:$F$27,3,FALSE) -> AGRCO2No | U4: =VLOOKUP(MID(S4,4,7),$D$2:$F$27,2,FALSE) -> 76.28 | X4: COM_AGG | Z4: CO2Captured* | AA4: TOTCO2 | AB4: -0.001
A5: AGRNGA | B5: =MID(A5,4,7) -> NGA | D5: COA | E5: =N30 -> 98.43 | F5: c | G5: For homes and businesses | R5: VDA_EMCB | S5: =A4 -> AGRLPG | T5: =LEFT(S5,3)&"CO2N"&VLOOKUP(MID(S5,4,7),$D$2:$F$27,3,FALSE) -> AGRCO2No | U5: =VLOOKUP(MID(S5,4,7),$D$2:$F$27,2,FALSE) -> 67.53
A6: AGROIL | B6: =MID(A6,4,7) -> OIL | D6: CoaG | E6: =E5 -> 98.43 | F6: c | G6: Propane | H6: 12.7 | I6: gallon | J6: 5.76 | K6: gallon | L6: 139.05 | M6: 63.07 | N6: 66.54 | R6: VDA_EMCB | S6: =A5 -> AGRNGA | T6: =LEFT(S6,3)&"CO2N"&VLOOKUP(MID(S6,4,7),$D$2:$F$27,3,FALSE) -> AGRCO2Ng | U6: =VLOOKUP(MID(S6,4,7),$D$2:$F$27,2,FALSE) -> 55.99
A7: COMCOA | B7: =MID(A7,4,7) -> COA | D7: COB | E7: =N32 -> 103.08 | F7: c | G7: Butane | H7: 14.8 | I7: gallon | J7: 6.71 | K7: gallon | L7: 143.2 | M7: 64.95 | N7: 68.53 | R7: VDA_EMCB | S7: =A6 -> AGROIL | T7: =LEFT(S7,3)&"CO2N"&VLOOKUP(MID(S7,4,7),$D$2:$F$27,3,FALSE) -> AGRCO2No | U7: =VLOOKUP(MID(S7,4,7),$D$2:$F$27,2,FALSE) -> 83.12
A8: COMHFO | B8: =MID(A8,4,7) -> HFO | D8: COG | E8: =E2 -> 55.99 | F8: c | G8: Butane/Propane Mix | H8: 13.7 | I8: gallon | J8: 6.21 | K8: gallon | L8: 141.12 | M8: 64.01 | N8: 67.53 | R8: VDA_EMCB | S8: =A7 -> COMCOA | T8: =LEFT(S8,3)&"CO2N"&VLOOKUP(MID(S8,4,7),$D$2:$F$27,3,FALSE) -> COMCO2Nc | U8: =VLOOKUP(MID(S8,4,7),$D$2:$F$27,2,FALSE) -> 98.43
A9: COMKER | B9: =MID(A9,4,7) -> KER | D9: COK | E9: =N33 -> 120.4 | F9: c | G9: Home Heating and Diesel Fuel (Distillate) | H9: 22.4 | I9: gallon | J9: 10.16 | K9: gallon | L9: 161.3 | M9: 73.16 | N9: 77.19 | R9: VDA_EMCB | S9: =A8 -> COMHFO | T9: =LEFT(S9,3)&"CO2N"&VLOOKUP(MID(S9,4,7),$D$2:$F$27,3,FALSE) -> COMCO2No | U9: =VLOOKUP(MID(S9,4,7),$D$2:$F$27,2,FALSE) -> 83.12 | X9: ~TFM_INS
A10: COMLPG | B10: =MID(A10,4,7) -> LPG | D10: DST | E10: =N9 -> 77.19 | F10: o | G10: Kerosene | H10: 21.5 | I10: gallon | J10: 9.75 | K10: gallon | L10: 159.4 | M10: 72.3 | N10: 76.28 | R10: VDA_EMCB | S10: =A9 -> COMKER | T10: =LEFT(S10,3)&"CO2N"&VLOOKUP(MID(S10,4,7),$D$2:$F$27,3,FALSE) -> COMCO2No | U10: =VLOOKUP(MID(S10,4,7),$D$2:$F$27,2,FALSE) -> 76.28 | X10: attribute | Y10: pset_co | Z10: commodity | AA10: other_indexes | AB10: value | AC10: pset_ci | AD10: pset_set | AF10: main non-energy use emissions
A11: COMNGA | B11: =MID(A11,4,7) -> NGA | D11: ETH | E11: =N6 -> 66.54 | F11: g | G11: Coal (All types) | H11: 4631.5 | I11: short ton | J11: 2100.82 | K11: short ton | L11: 210.2 | M11: 95.35 | N11: 100.59 | R11: VDA_EMCB | S11: =A10 -> COMLPG | T11: =LEFT(S11,3)&"CO2N"&VLOOKUP(MID(S11,4,7),$D$2:$F$27,3,FALSE) -> COMCO2No | U11: =VLOOKUP(MID(S11,4,7),$D$2:$F$27,2,FALSE) -> 67.53 | X11: FLO_EMIS | Y11: ICH_feedstock | Z11: ="INDCO2N"&VLOOKUP(MID(AA11,4,7),$D$2:$F$27,3,FALSE) -> INDCO2No | AA11: OILNAP | AB11: =VLOOKUP(MID(AA11,4,7),$D$2:$F$27,2,FALSE)*AF11 -> 15.362 | AC11: =AA11 -> OILNAP | AD11: -IRE | AF11: 0.2
A12: COMOIL | B12: =MID(A12,4,7) -> OIL | D12: GAS | E12: =N12 -> 55.99 | F12: g | G12: Natural Gas | H12: 117.1 | I12: thousand cubic feet | J12: 53.12 | K12: thousand cubic feet | L12: 117 | M12: 53.07 | N12: 55.99 | R12: VDA_EMCB | S12: =A11 -> COMNGA | T12: =LEFT(S12,3)&"CO2N"&VLOOKUP(MID(S12,4,7),$D$2:$F$27,3,FALSE) -> COMCO2Ng | U12: =VLOOKUP(MID(S12,4,7),$D$2:$F$27,2,FALSE) -> 55.99 | X12: FLO_EMIS | Y12: ICH_feedstock | Z12: ="INDCO2N"&VLOOKUP(MID(AA12,4,7),$D$2:$F$27,3,FALSE) -> INDCO2No | AA12: OILLPG | AB12: =VLOOKUP(MID(AA12,4,7),$D$2:$F$27,2,FALSE)*AF12 -> 13.506 | AC12: =AA12 -> OILLPG | AD12: -IRE | AF12: 0.2
A13: ELCCOA | B13: =MID(A13,4,7) -> COA | D13: GSL | E13: =N13 -> 75.22 | F13: o | G13: Gasoline | H13: 19.6 | I13: gallon | J13: 8.89 | K13: gallon | L13: 157.2 | M13: 71.3 | N13: 75.22 | R13: VDA_EMCB | S13: =A12 -> COMOIL | T13: =LEFT(S13,3)&"CO2N"&VLOOKUP(MID(S13,4,7),$D$2:$F$27,3,FALSE) -> COMCO2No | U13: =VLOOKUP(MID(S13,4,7),$D$2:$F$27,2,FALSE) -> 83.12 | X13: FLO_EMIS | Y13: ICH_feedstock | Z13: ="INDCO2N"&VLOOKUP(MID(AA13,1,3),$D$2:$F$27,3,FALSE) -> INDCO2Ng | AA13: GASNGA | AB13: =VLOOKUP(MID(AA13,4,7),$D$2:$F$27,2,FALSE)*AF13 -> 33.594 | AC13: =AA13 -> GASNGA | AD13: -IRE | AF13: 0.6
A14: ELCCoaG | B14: =MID(A14,4,7) -> CoaG | D14: NAP | E14: =N26 -> 76.81 | F14: o | G14: Residual Heating Fuel (Businesses only) | H14: 26 | I14: gallon | J14: 11.79 | K14: gallon | L14: 173.7 | M14: 78.79 | N14: 83.12 | R14: VDA_EMCB | S14: =A13 -> ELCCOA | T14: =LEFT(S14,3)&"CO2N"&VLOOKUP(MID(S14,4,7),$D$2:$F$27,3,FALSE) -> ELCCO2Nc | U14: =VLOOKUP(MID(S14,4,7),$D$2:$F$27,2,FALSE) -> 98.43 | X14: FLO_EMIS | Y14: ICH_feedstock | Z14: ="INDCO2N"&VLOOKUP(MID(AA14,1,3),$D$2:$F$27,3,FALSE) -> INDCO2Ng | AA14: GASETH | AB14: =VLOOKUP(MID(AA14,4,7),$D$2:$F$27,2,FALSE)*AF14 -> 5.3232 | AC14: =AA14 -> GASETH | AD14: -IRE | AF14: 0.08
A15: ELCCOB | B15: =MID(A15,4,7) -> COB | D15: HFO | E15: =N14 -> 83.12 | F15: o | G15: Other transportation fuels | N15: 0 | R15: VDA_EMCB | S15: =A14 -> ELCCoaG | T15: =LEFT(S15,3)&"CO2N"&VLOOKUP(MID(S15,4,7),$D$2:$F$27,3,FALSE) -> ELCCO2Nc | U15: =VLOOKUP(MID(S15,4,7),$D$2:$F$27,2,FALSE) -> 98.43
A16: ELCGAS | B16: =MID(A16,4,7) -> GAS | D16: JTK | E16: =N16 -> 74.8 | F16: o | G16: Jet Fuel | H16: 21.1 | I16: gallon | J16: 9.57 | K16: gallon | L16: 156.3 | M16: 70.9 | N16: 74.8 | R16: VDA_EMCB | S16: =A15 -> ELCCOB | T16: =LEFT(S16,3)&"CO2N"&VLOOKUP(MID(S16,4,7),$D$2:$F$27,3,FALSE) -> ELCCO2Nc | U16: =VLOOKUP(MID(S16,4,7),$D$2:$F$27,2,FALSE) -> 103.08
A17: ELCNGA | B17: =MID(A17,4,7) -> NGA | D17: KER | E17: =N10 -> 76.28 | F17: o | G17: Aviation Gas | H17: 18.4 | I17: gallon | J17: 8.35 | K17: gallon | L17: 152.6 | M17: 69.2 | N17: 73.01 | R17: VDA_EMCB | S17: =A16 -> ELCGAS | T17: =LEFT(S17,3)&"CO2N"&VLOOKUP(MID(S17,4,7),$D$2:$F$27,3,FALSE) -> ELCCO2Ng | U17: =VLOOKUP(MID(S17,4,7),$D$2:$F$27,2,FALSE) -> 55.99
A18: ELCOIL | B18: =MID(A18,4,7) -> OIL | D18: LPG | E18: =N8 -> 67.53 | F18: o | G18: Industrial fuels and others not listed above | N18: 0 | R18: VDA_EMCB | S18: =A17 -> ELCNGA | T18: =LEFT(S18,3)&"CO2N"&VLOOKUP(MID(S18,4,7),$D$2:$F$27,3,FALSE) -> ELCCO2Ng | U18: =VLOOKUP(MID(S18,4,7),$D$2:$F$27,2,FALSE) -> 55.99 | X18: ~TFM_INS
A19: ELCOIL_CRD | B19: =MID(A19,4,7) -> OIL_CRD | D19: NGA | E19: =N12 -> 55.99 | F19: g | G19: Flared natural gas | H19: 120.7 | I19: thousand cubic feet | J19: 54.75 | K19: thousand cubic feet | L19: 120.6 | M19: 54.7 | N19: 57.71 | R19: VDA_EMCB | S19: =A18 -> ELCOIL | T19: =LEFT(S19,3)&"CO2N"&VLOOKUP(MID(S19,4,7),$D$2:$F$27,3,FALSE) -> ELCCO2No | U19: =VLOOKUP(MID(S19,4,7),$D$2:$F$27,2,FALSE) -> 83.12 | X19: attribute | Y19: pset_ci | Z19: pset_pn | AA19: commodity | AB19: other_indexes | AC19: value | AD19: pset_co | AE19: pset_set
A20: ELCOIL_DST | B20: =MID(A20,4,7) -> OIL_DST | D20: OIL | E20: =N14 -> 83.12 | F20: o | G20: Petroleum coke | H20: 32.4 | I20: gallon | J20: 14.7 | K20: gallon | L20: 225.1 | M20: 102.1 | N20: 107.72 | R20: VDA_EMCB | S20: =A19 -> ELCOIL_CRD | T20: =LEFT(S20,3)&"CO2N"&VLOOKUP(MID(S20,4,7),$D$2:$F$27,3,FALSE) -> ELCCO2No | U20: =VLOOKUP(MID(S20,4,7),$D$2:$F$27,2,FALSE) -> 83.12 | X20: FLO_EMIS | Y20: BIOBSL | AA20: HH2CO2Nb | AB20: BIOBSL | AC20: =VLOOKUP(MID(AB20,1,3),$D$2:$F$27,2,FALSE) -> 98.43 | AD20: HH2 | AE20: PRE
A21: ELCWAS | B21: =MID(A21,4,7) -> WAS | D21: OIL_CRD | E21: =N14 -> 83.12 | F21: o | G21: Other petroleum & miscellaneous | H21: 22.09 | I21: gallon | J21: 10.02 | K21: gallon | L21: 160.1 | M21: 72.62 | N21: 76.61 | R21: VDA_EMCB | S21: =A20 -> ELCOIL_DST | T21: =LEFT(S21,3)&"CO2N"&VLOOKUP(MID(S21,4,7),$D$2:$F$27,3,FALSE) -> ELCCO2No | U21: =VLOOKUP(MID(S21,4,7),$D$2:$F$27,2,FALSE) -> 77.19 | X21: FLO_EMIS | Y21: COAHCO | AA21: HH2CO2Nc | AB21: COAHCO | AC21: =VLOOKUP(MID(AB21,1,3),$D$2:$F$27,2,FALSE) -> 98.43 | AD21: HH2 | AE21: PRE
A22: INDBFG | B22: =MID(A22,4,7) -> BFG | D22: OIL_DST | E22: =E10 -> 77.19 | F22: o | G22: Nonfuel uses | N22: 0 | R22: VDA_EMCB | S22: =A21 -> ELCWAS | T22: =LEFT(S22,3)&"CO2N"&VLOOKUP(MID(S22,4,7),$D$2:$F$27,3,FALSE) -> ELCCO2Nw | U22: =VLOOKUP(MID(S22,4,7),$D$2:$F$27,2,FALSE) -> 43.98 | X22: FLO_EMIS | Y22: GASNGA | AA22: HH2CO2Ng | AB22: GASNGA | AC22: =VLOOKUP(MID(AB22,1,3),$D$2:$F$27,2,FALSE) -> 55.99 | AD22: HH2 | AE22: PRE
A23: ELCBSL | B23: =MID(A23,4,7) -> BSL | D23: OVC | E23: =N33 -> 120.4 | F23: c | G23: Asphalt and Road Oil | H23: 26.34 | I23: gallon | J23: 11.95 | K23: gallon | L23: 166.7 | M23: 75.61 | N23: 79.77 | R23: VDA_EMCB | S23: =A22 -> INDBFG | T23: =LEFT(S23,3)&"CO2N"&VLOOKUP(MID(S23,4,7),$D$2:$F$27,3,FALSE) -> INDCO2Nc | U23: =VLOOKUP(MID(S23,4,7),$D$2:$F$27,2,FALSE) -> 55.99
A24: INDCOA | B24: =MID(A24,4,7) -> COA | D24: PTC | E24: =N20 -> 107.72 | F24: o | G24: Lubricants | H24: 23.62 | I24: gallon | J24: 10.72 | K24: gallon | L24: 163.6 | M24: 74.21 | N24: 78.29 | R24: VDA_EMCB | S24: =A23 -> ELCBSL | T24: =LEFT(S24,3)&"CO2N"&VLOOKUP(MID(S24,4,7),$D$2:$F$27,3,FALSE) -> ELCCO2Nb | U24: =VLOOKUP(MID(S24,4,7),$D$2:$F$27,2,FALSE) -> 98.43
A25: INDCOG | B25: =MID(A25,4,7) -> COG | D25: RFG | E25: =E2 -> 55.99 | F25: o | G25: Petrochemical Feedstocks | H25: 24.74 | I25: gallon | J25: 11.22 | K25: gallon | L25: 156.6 | M25: 71.03 | N25: 74.94 | R25: VDA_EMCB | S25: =A24 -> INDCOA | T25: =LEFT(S25,3)&"CO2N"&VLOOKUP(MID(S25,4,7),$D$2:$F$27,3,FALSE) -> INDCO2Nc | U25: =VLOOKUP(MID(S25,4,7),$D$2:$F$27,2,FALSE) -> 98.43
A26: INDCOK | B26: =MID(A26,4,7) -> COK | D26: RPP | E26: =N9 -> 77.19 | F26: o | G26: Special Naphthas (solvents) | H26: 20.05 | I26: gallon | J26: 9.1 | K26: gallon | L26: 160.5 | M26: 72.8 | N26: 76.81 | R26: VDA_EMCB | S26: =A25 -> INDCOG | T26: =LEFT(S26,3)&"CO2N"&VLOOKUP(MID(S26,4,7),$D$2:$F$27,3,FALSE) -> INDCO2Nc | U26: =VLOOKUP(MID(S26,4,7),$D$2:$F$27,2,FALSE) -> 55.99
A27: INDHFO | B27: =MID(A27,4,7) -> HFO | D27: WAS | E27: =N36 -> 43.98 | F27: w | G27: Waxes | H27: 21.11 | I27: gallon | J27: 9.57 | K27: gallon | L27: 160.1 | M27: 72.62 | N27: 76.61 | R27: VDA_EMCB | S27: =A26 -> INDCOK | T27: =LEFT(S27,3)&"CO2N"&VLOOKUP(MID(S27,4,7),$D$2:$F$27,3,FALSE) -> INDCO2Nc | U27: =VLOOKUP(MID(S27,4,7),$D$2:$F$27,2,FALSE) -> 120.4
A28: INDLPG | B28: =MID(A28,4,7) -> LPG | G28: Coals by type | R28: VDA_EMCB | S28: =A27 -> INDHFO | T28: =LEFT(S28,3)&"CO2N"&VLOOKUP(MID(S28,4,7),$D$2:$F$27,3,FALSE) -> INDCO2No | U28: =VLOOKUP(MID(S28,4,7),$D$2:$F$27,2,FALSE) -> 83.12 | X28: ~TFM_INS
A29: INDNGA | B29: =MID(A29,4,7) -> NGA | G29: Anthractie | H29: 5685 | I29: short ton | J29: 2578.68 | K29: short ton | L29: 228.6 | M29: 103.7 | N29: 109.4 | R29: VDA_EMCB | S29: =A28 -> INDLPG | T29: =LEFT(S29,3)&"CO2N"&VLOOKUP(MID(S29,4,7),$D$2:$F$27,3,FALSE) -> INDCO2No | U29: =VLOOKUP(MID(S29,4,7),$D$2:$F$27,2,FALSE) -> 67.53 | X29: attribute | Y29: commodity | Z29: other_indexes | AA29: value
A30: INDOIL | B30: =MID(A30,4,7) -> OIL | G30: Bituminous | H30: 4931.3 | I30: short ton | J30: 2236.8 | K30: short ton | L30: 205.7 | M30: 93.3 | N30: 98.43 | R30: VDA_EMCB | S30: =A29 -> INDNGA | T30: =LEFT(S30,3)&"CO2N"&VLOOKUP(MID(S30,4,7),$D$2:$F$27,3,FALSE) -> INDCO2Ng | U30: =VLOOKUP(MID(S30,4,7),$D$2:$F$27,2,FALSE) -> 55.99 | X30: COM_AGG | Y30: ELCCO2??,-*b | Z30: NetCO2_ELC | AA30: 0.001
A31: INDOVC | B31: =MID(A31,4,7) -> OVC | G31: Subbituminous | H31: 3715.9 | I31: short ton | J31: 1685.51 | K31: short ton | L31: 214.3 | M31: 97.2 | N31: 102.55 | R31: VDA_EMCB | S31: =A30 -> INDOIL | T31: =LEFT(S31,3)&"CO2N"&VLOOKUP(MID(S31,4,7),$D$2:$F$27,3,FALSE) -> INDCO2No | U31: =VLOOKUP(MID(S31,4,7),$D$2:$F$27,2,FALSE) -> 83.12 | X31: COM_AGG | Y31: CO2Captured_elc | Z31: NetCO2_ELC | AA31: -0.001
A32: INDPTC | B32: =MID(A32,4,7) -> PTC | G32: Lignite | H32: 2791.6 | I32: short ton | J32: 1266.25 | K32: short ton | L32: 215.4 | M32: 97.7 | N32: 103.08 | R32: VDA_EMCB | S32: =A31 -> INDOVC | T32: =LEFT(S32,3)&"CO2N"&VLOOKUP(MID(S32,4,7),$D$2:$F$27,3,FALSE) -> INDCO2Nc | U32: =VLOOKUP(MID(S32,4,7),$D$2:$F$27,2,FALSE) -> 120.4 | X32: *
A33: RESCOA | B33: =MID(A33,4,7) -> COA | G33: Coke | H33: 6239.68 | I33: short ton | J33: 2830.27 | K33: short ton | L33: 251.6 | M33: 114.12 | N33: 120.4 | R33: VDA_EMCB | S33: =A32 -> INDPTC | T33: =LEFT(S33,3)&"CO2N"&VLOOKUP(MID(S33,4,7),$D$2:$F$27,3,FALSE) -> INDCO2No | U33: =VLOOKUP(MID(S33,4,7),$D$2:$F$27,2,FALSE) -> 107.72 | X33: COM_AGG | Y33: INDCO2??,-*b,INDCO2P | Z33: NetCO2_IND | AA33: 0.001
A34: RESHFO | B34: =MID(A34,4,7) -> HFO | G34: Other fuels | R34: VDA_EMCB | S34: =A33 -> RESCOA | T34: =LEFT(S34,3)&"CO2N"&VLOOKUP(MID(S34,4,7),$D$2:$F$27,3,FALSE) -> RESCO2Nc | U34: =VLOOKUP(MID(S34,4,7),$D$2:$F$27,2,FALSE) -> 98.43 | X34: COM_AGG | Y34: CO2Captured_ind | Z34: NetCO2_IND | AA34: -0.001
A35: RESKER | B35: =MID(A35,4,7) -> KER | G35: Geothermal (average all generation) | H35: NA | J35: NA | L35: 16.99 | M35: 7.71 | N35: 8.13 | R35: VDA_EMCB | S35: =A34 -> RESHFO | T35: =LEFT(S35,3)&"CO2N"&VLOOKUP(MID(S35,4,7),$D$2:$F$27,3,FALSE) -> RESCO2No | U35: =VLOOKUP(MID(S35,4,7),$D$2:$F$27,2,FALSE) -> 83.12 | X35: *
