Workbook
Name IQ_CH: 110000
Name IQ_CQ: 5000
Name IQ_CY: 10000
Name IQ_DAILY: 500000
Name IQ_FH: 100000
Name IQ_FQ: 500
Name IQ_FY: 1000
Name IQ_LTM: 2000
Name IQ_MONTH: 15000
Name IQ_NTM: 6000
Name IQ_WEEK: 50000
Name IQ_YTD: 3000

Sheet reporting
E1: ~UC_Sets: R_E: AllRegions
E3: ~UC_T: UC_COMNET~repuc_unity~N
D4: uc_n | E4: region | F4: ='Selected scen drivers'!F1 -> 2019 | G4: ='Selected scen drivers'!G1 -> 2020 | H4: ='Selected scen drivers'!H1 -> 2025 | I4: ='Selected scen drivers'!I1 -> 2030 | J4: ='Selected scen drivers'!J1 -> 2035 | K4: ='Selected scen drivers'!K1 -> 2040 | L4: ='Selected scen drivers'!L1 -> 2045 | M4: ='Selected scen drivers'!M1 -> 2050 | ... W4: ='Selected scen drivers'!W1 -> 2100 | X4: uc_rhsrt~0
A5: 1 | B5: 1 | D5: =IFERROR("rep_"&VLOOKUP(B5,Classification!$N$5:$O$14,2,FALSE),"\I:") -> rep_GDP | E5: =IFERROR(VLOOKUP(A5,Classification!$A$4:$B$39,2,FALSE),"\I:") -> Africa_other | F5: =SUMIFS('Selected scen drivers'!F$2:F$271,'Selected scen drivers'!$A$2:$A$271,reporting!$A5,'Selected scen drivers'!$B$2:$B$271,reporting!$B5) -> 3397.857 | G5: =SUMIFS('Selected scen drivers'!G$2:G$271,'Selected scen drivers'!$A$2:$A$271,reporting!$A5,'Selected scen drivers'!$B$2:$B$271,reporting!$B5) -> 3468.8105 | H5: =SUMIFS('Selected scen drivers'!H$2:H$271,'Selected scen drivers'!$A$2:$A$271,reporting!$A5,'Selected scen drivers'!$B$2:$B$271,reporting!$B5) -> 4236.7911 | I5: =SUMIFS('Selected scen drivers'!I$2:I$271,'Selected scen drivers'!$A$2:$A$271,reporting!$A5,'Selected scen drivers'!$B$2:$B$271,reporting!$B5) -> 5413.3577 | J5: =SUMIFS('Selected scen drivers'!J$2:J$271,'Selected scen drivers'!$A$2:$A$271,reporting!$A5,'Selected scen drivers'!$B$2:$B$271,reporting!$B5) -> 7069.4163 | K5: =SUMIFS('Selected scen drivers'!K$2:K$271,'Selected scen drivers'!$A$2:$A$271,reporting!$A5,'Selected scen drivers'!$B$2:$B$271,reporting!$B5) -> 9098.1883 | L5: =SUMIFS('Selected scen drivers'!L$2:L$271,'Selected scen drivers'!$A$2:$A$271,reporting!$A5,'Selected scen drivers'!$B$2:$B$271,reporting!$B5) -> 11631.587 | M5: =SUMIFS('Selected scen drivers'!M$2:M$271,'Selected scen drivers'!$A$2:$A$271,reporting!$A5,'Selected scen drivers'!$B$2:$B$271,reporting!$B5) -> 14792.512 | ... W5: =SUMIFS('Selected scen drivers'!W$2:W$271,'Selected scen drivers'!$A$2:$A$271,reporting!$A5,'Selected scen drivers'!$B$2:$B$271,reporting!$B5) -> 104963.21 | X5: 2
A6: 1 | B6: 2 | D6: =IFERROR("rep_"&VLOOKUP(B6,Classification!$N$5:$O$14,2,FALSE),"\I:") -> rep_GDPAGR | E6: =IFERROR(VLOOKUP(A6,Classification!$A$4:$B$39,2,FALSE),"\I:") -> Africa_other | F6: =SUMIFS('Selected scen drivers'!F$2:F$271,'Selected scen drivers'!$A$2:$A$271,reporting!$A6,'Selected scen drivers'!$B$2:$B$271,reporting!$B6) -> 791.76348 | G6: =SUMIFS('Selected scen drivers'!G$2:G$271,'Selected scen drivers'!$A$2:$A$271,reporting!$A6,'Selected scen drivers'!$B$2:$B$271,reporting!$B6) -> 812.01851 | H6: =SUMIFS('Selected scen drivers'!H$2:H$271,'Selected scen drivers'!$A$2:$A$271,reporting!$A6,'Selected scen drivers'!$B$2:$B$271,reporting!$B6) -> 951.88078 | I6: =SUMIFS('Selected scen drivers'!I$2:I$271,'Selected scen drivers'!$A$2:$A$271,reporting!$A6,'Selected scen drivers'!$B$2:$B$271,reporting!$B6) -> 1175.539 | J6: =SUMIFS('Selected scen drivers'!J$2:J$271,'Selected scen drivers'!$A$2:$A$271,reporting!$A6,'Selected scen drivers'!$B$2:$B$271,reporting!$B6) -> 1475.4991 | K6: =SUMIFS('Selected scen drivers'!K$2:K$271,'Selected scen drivers'!$A$2:$A$271,reporting!$A6,'Selected scen drivers'!$B$2:$B$271,reporting!$B6) -> 1819.0655 | L6: =SUMIFS('Selected scen drivers'!L$2:L$271,'Selected scen drivers'!$A$2:$A$271,reporting!$A6,'Selected scen drivers'!$B$2:$B$271,reporting!$B6) -> 2219.798 | M6: =SUMIFS('Selected scen drivers'!M$2:M$271,'Selected scen drivers'!$A$2:$A$271,reporting!$A6,'Selected scen drivers'!$B$2:$B$271,reporting!$B6) -> 2683.1018 | ... W6: =SUMIFS('Selected scen drivers'!W$2:W$271,'Selected scen drivers'!$A$2:$A$271,reporting!$A6,'Selected scen drivers'!$B$2:$B$271,reporting!$B6) -> 7763.9847 | X6: 2
A7: 1 | B7: 3 | D7: =IFERROR("rep_"&VLOOKUP(B7,Classification!$N$5:$O$14,2,FALSE),"\I:") -> rep_GDPIND | E7: =IFERROR(VLOOKUP(A7,Classification!$A$4:$B$39,2,FALSE),"\I:") -> Africa_other | F7: =SUMIFS('Selected scen drivers'!F$2:F$271,'Selected scen drivers'!$A$2:$A$271,reporting!$A7,'Selected scen drivers'!$B$2:$B$271,reporting!$B7) -> 923.83924 | G7: =SUMIFS('Selected scen drivers'!G$2:G$271,'Selected scen drivers'!$A$2:$A$271,reporting!$A7,'Selected scen drivers'!$B$2:$B$271,reporting!$B7) -> 941.62527 | H7: =SUMIFS('Selected scen drivers'!H$2:H$271,'Selected scen drivers'!$A$2:$A$271,reporting!$A7,'Selected scen drivers'!$B$2:$B$271,reporting!$B7) -> 1171.0965 | I7: =SUMIFS('Selected scen drivers'!I$2:I$271,'Selected scen drivers'!$A$2:$A$271,reporting!$A7,'Selected scen drivers'!$B$2:$B$271,reporting!$B7) -> 1507.2619 | J7: =SUMIFS('Selected scen drivers'!J$2:J$271,'Selected scen drivers'!$A$2:$A$271,reporting!$A7,'Selected scen drivers'!$B$2:$B$271,reporting!$B7) -> 1985.9926 | K7: =SUMIFS('Selected scen drivers'!K$2:K$271,'Selected scen drivers'!$A$2:$A$271,reporting!$A7,'Selected scen drivers'!$B$2:$B$271,reporting!$B7) -> 2581.9862 | L7: =SUMIFS('Selected scen drivers'!L$2:L$271,'Selected scen drivers'!$A$2:$A$271,reporting!$A7,'Selected scen drivers'!$B$2:$B$271,reporting!$B7) -> 3336.6232 | M7: =SUMIFS('Selected scen drivers'!M$2:M$271,'Selected scen drivers'!$A$2:$A$271,reporting!$A7,'Selected scen drivers'!$B$2:$B$271,reporting!$B7) -> 4290.277 | ... W7: =SUMIFS('Selected scen drivers'!W$2:W$271,'Selected scen drivers'!$A$2:$A$271,reporting!$A7,'Selected scen drivers'!$B$2:$B$271,reporting!$B7) -> 33780.085 | X7: 2
A8: 1 | B8: 7 | D8: =IFERROR("rep_"&VLOOKUP(B8,Classification!$N$5:$O$14,2,FALSE),"\I:") -> rep_GDPSER | E8: =IFERROR(VLOOKUP(A8,Classification!$A$4:$B$39,2,FALSE),"\I:") -> Africa_other | F8: =SUMIFS('Selected scen drivers'!F$2:F$271,'Selected scen drivers'!$A$2:$A$271,reporting!$A8,'Selected scen drivers'!$B$2:$B$271,reporting!$B8) -> 1681.2763 | G8: =SUMIFS('Selected scen drivers'!G$2:G$271,'Selected scen drivers'!$A$2:$A$271,reporting!$A8,'Selected scen drivers'!$B$2:$B$271,reporting!$B8) -> 1713.1844 | H8: =SUMIFS('Selected scen drivers'!H$2:H$271,'Selected scen drivers'!$A$2:$A$271,reporting!$A8,'Selected scen drivers'!$B$2:$B$271,reporting!$B8) -> 2110.325 | I8: =SUMIFS('Selected scen drivers'!I$2:I$271,'Selected scen drivers'!$A$2:$A$271,reporting!$A8,'Selected scen drivers'!$B$2:$B$271,reporting!$B8) -> 2724.9262 | J8: =SUMIFS('Selected scen drivers'!J$2:J$271,'Selected scen drivers'!$A$2:$A$271,reporting!$A8,'Selected scen drivers'!$B$2:$B$271,reporting!$B8) -> 3598.6769 | K8: =SUMIFS('Selected scen drivers'!K$2:K$271,'Selected scen drivers'!$A$2:$A$271,reporting!$A8,'Selected scen drivers'!$B$2:$B$271,reporting!$B8) -> 4681.8771 | L8: =SUMIFS('Selected scen drivers'!L$2:L$271,'Selected scen drivers'!$A$2:$A$271,reporting!$A8,'Selected scen drivers'!$B$2:$B$271,reporting!$B8) -> 6050.1115 | M8: =SUMIFS('Selected scen drivers'!M$2:M$271,'Selected scen drivers'!$A$2:$A$271,reporting!$A8,'Selected scen drivers'!$B$2:$B$271,reporting!$B8) -> 7778.8484 | ... W8: =SUMIFS('Selected scen drivers'!W$2:W$271,'Selected scen drivers'!$A$2:$A$271,reporting!$A8,'Selected scen drivers'!$B$2:$B$271,reporting!$B8) -> 63396.71 | X8: 2
A9: 1 | B9: 8 | D9: =IFERROR("rep_"&VLOOKUP(B9,Classification!$N$5:$O$14,2,FALSE),"\I:") -> rep_HOU | E9: =IFERROR(VLOOKUP(A9,Classification!$A$4:$B$39,2,FALSE),"\I:") -> Africa_other | F9: =SUMIFS('Selected scen drivers'!F$2:F$271,'Selected scen drivers'!$A$2:$A$271,reporting!$A9,'Selected scen drivers'!$B$2:$B$271,reporting!$B9) -> 230.00091 | G9: =SUMIFS('Selected scen drivers'!G$2:G$271,'Selected scen drivers'!$A$2:$A$271,reporting!$A9,'Selected scen drivers'!$B$2:$B$271,reporting!$B9) -> 238.05682 | H9: =SUMIFS('Selected scen drivers'!H$2:H$271,'Selected scen drivers'!$A$2:$A$271,reporting!$A9,'Selected scen drivers'!$B$2:$B$271,reporting!$B9) -> 278.33633 | I9: =SUMIFS('Selected scen drivers'!I$2:I$271,'Selected scen drivers'!$A$2:$A$271,reporting!$A9,'Selected scen drivers'!$B$2:$B$271,reporting!$B9) -> 324.35781 | J9: =SUMIFS('Selected scen drivers'!J$2:J$271,'Selected scen drivers'!$A$2:$A$271,reporting!$A9,'Selected scen drivers'!$B$2:$B$271,reporting!$B9) -> 375.62398 | K9: =SUMIFS('Selected scen drivers'!K$2:K$271,'Selected scen drivers'!$A$2:$A$271,reporting!$A9,'Selected scen drivers'!$B$2:$B$271,reporting!$B9) -> 430.53618 | L9: =SUMIFS('Selected scen drivers'!L$2:L$271,'Selected scen drivers'!$A$2:$A$271,reporting!$A9,'Selected scen drivers'!$B$2:$B$271,reporting!$B9) -> 488.07515 | M9: =SUMIFS('Selected scen drivers'!M$2:M$271,'Selected scen drivers'!$A$2:$A$271,reporting!$A9,'Selected scen drivers'!$B$2:$B$271,reporting!$B9) -> 547.08217 | ... W9: =SUMIFS('Selected scen drivers'!W$2:W$271,'Selected scen drivers'!$A$2:$A$271,reporting!$A9,'Selected scen drivers'!$B$2:$B$271,reporting!$B9) -> 949.59983 | X9: 2
A10: 1 | B10: 9 | D10: =IFERROR("rep_"&VLOOKUP(B10,Classification!$N$5:$O$14,2,FALSE),"\I:") -> rep_POP | E10: =IFERROR(VLOOKUP(A10,Classification!$A$4:$B$39,2,FALSE),"\I:") -> Africa_other | F10: =SUMIFS('Selected scen drivers'!F$2:F$271,'Selected scen drivers'!$A$2:$A$271,reporting!$A10,'Selected scen drivers'!$B$2:$B$271,reporting!$B10) -> 1049.7463 | G10: =SUMIFS('Selected scen drivers'!G$2:G$271,'Selected scen drivers'!$A$2:$A$271,reporting!$A10,'Selected scen drivers'!$B$2:$B$271,reporting!$B10) -> 1079.5075 | H10: =SUMIFS('Selected scen drivers'!H$2:H$271,'Selected scen drivers'!$A$2:$A$271,reporting!$A10,'Selected scen drivers'!$B$2:$B$271,reporting!$B10) -> 1228.3137 | I10: =SUMIFS('Selected scen drivers'!I$2:I$271,'Selected scen drivers'!$A$2:$A$271,reporting!$A10,'Selected scen drivers'!$B$2:$B$271,reporting!$B10) -> 1387.4222 | J10: =SUMIFS('Selected scen drivers'!J$2:J$271,'Selected scen drivers'!$A$2:$A$271,reporting!$A10,'Selected scen drivers'!$B$2:$B$271,reporting!$B10) -> 1553.773 | K10: =SUMIFS('Selected scen drivers'!K$2:K$271,'Selected scen drivers'!$A$2:$A$271,reporting!$A10,'Selected scen drivers'!$B$2:$B$271,reporting!$B10) -> 1724.7482 | L10: =SUMIFS('Selected scen drivers'!L$2:L$271,'Selected scen drivers'!$A$2:$A$271,reporting!$A10,'Selected scen drivers'!$B$2:$B$271,reporting!$B10) -> 1897.4143 | M10: =SUMIFS('Selected scen drivers'!M$2:M$271,'Selected scen drivers'!$A$2:$A$271,reporting!$A10,'Selected scen drivers'!$B$2:$B$271,reporting!$B10) -> 2068.6944 | ... W10: =SUMIFS('Selected scen drivers'!W$2:W$271,'Selected scen drivers'!$A$2:$A$271,reporting!$A10,'Selected scen drivers'!$B$2:$B$271,reporting!$B10) -> 3157.8287 | X10: 2
A11: =A5+1 -> 2 | B11: =B5 -> 1 | D11: =IFERROR("rep_"&VLOOKUP(B11,Classification!$N$5:$O$14,2,FALSE),"\I:") -> rep_GDP | E11: =IFERROR(VLOOKUP(A11,Classification!$A$4:$B$39,2,FALSE),"\I:") -> India | F11: =SUMIFS('Selected scen drivers'!F$2:F$271,'Selected scen drivers'!$A$2:$A$271,reporting!$A11,'Selected scen drivers'!$B$2:$B$271,reporting!$B11) -> 8195.484 | G11: =SUMIFS('Selected scen drivers'!G$2:G$271,'Selected scen drivers'!$A$2:$A$271,reporting!$A11,'Selected scen drivers'!$B$2:$B$271,reporting!$B11) -> 8503.83 | H11: =SUMIFS('Selected scen drivers'!H$2:H$271,'Selected scen drivers'!$A$2:$A$271,reporting!$A11,'Selected scen drivers'!$B$2:$B$271,reporting!$B11) -> 11852.9 | I11: =SUMIFS('Selected scen drivers'!I$2:I$271,'Selected scen drivers'!$A$2:$A$271,reporting!$A11,'Selected scen drivers'!$B$2:$B$271,reporting!$B11) -> 15709.5 | J11: =SUMIFS('Selected scen drivers'!J$2:J$271,'Selected scen drivers'!$A$2:$A$271,reporting!$A11,'Selected scen drivers'!$B$2:$B$271,reporting!$B11) -> 19813.1 | K11: =SUMIFS('Selected scen drivers'!K$2:K$271,'Selected scen drivers'!$A$2:$A$271,reporting!$A11,'Selected scen drivers'!$B$2:$B$271,reporting!$B11) -> 24247.7 | L11: =SUMIFS('Selected scen drivers'!L$2:L$271,'Selected scen drivers'!$A$2:$A$271,reporting!$A11,'Selected scen drivers'!$B$2:$B$271,reporting!$B11) -> 29018.4 | M11: =SUMIFS('Selected scen drivers'!M$2:M$271,'Selected scen drivers'!$A$2:$A$271,reporting!$A11,'Selected scen drivers'!$B$2:$B$271,reporting!$B11) -> 34135.9 | ... W11: =SUMIFS('Selected scen drivers'!W$2:W$271,'Selected scen drivers'!$A$2:$A$271,reporting!$A11,'Selected scen drivers'!$B$2:$B$271,reporting!$B11) -> 90238.2 | X11: 2
A12: =A6+1 -> 2 | B12: =B6 -> 2 | D12: =IFERROR("rep_"&VLOOKUP(B12,Classification!$N$5:$O$14,2,FALSE),"\I:") -> rep_GDPAGR | E12: =IFERROR(VLOOKUP(A12,Classification!$A$4:$B$39,2,FALSE),"\I:") -> India | F12: =SUMIFS('Selected scen drivers'!F$2:F$271,'Selected scen drivers'!$A$2:$A$271,reporting!$A12,'Selected scen drivers'!$B$2:$B$271,reporting!$B12) -> 1281.0098 | G12: =SUMIFS('Selected scen drivers'!G$2:G$271,'Selected scen drivers'!$A$2:$A$271,reporting!$A12,'Selected scen drivers'!$B$2:$B$271,reporting!$B12) -> 1329.2063 | H12: =SUMIFS('Selected scen drivers'!H$2:H$271,'Selected scen drivers'!$A$2:$A$271,reporting!$A12,'Selected scen drivers'!$B$2:$B$271,reporting!$B12) -> 1792.4561 | I12: =SUMIFS('Selected scen drivers'!I$2:I$271,'Selected scen drivers'!$A$2:$A$271,reporting!$A12,'Selected scen drivers'!$B$2:$B$271,reporting!$B12) -> 2295.8404 | J12: =SUMIFS('Selected scen drivers'!J$2:J$271,'Selected scen drivers'!$A$2:$A$271,reporting!$A12,'Selected scen drivers'!$B$2:$B$271,reporting!$B12) -> 2794.8708 | K12: =SUMIFS('Selected scen drivers'!K$2:K$271,'Selected scen drivers'!$A$2:$A$271,reporting!$A12,'Selected scen drivers'!$B$2:$B$271,reporting!$B12) -> 3297.2044 | L12: =SUMIFS('Selected scen drivers'!L$2:L$271,'Selected scen drivers'!$A$2:$A$271,reporting!$A12,'Selected scen drivers'!$B$2:$B$271,reporting!$B12) -> 3798.4626 | M12: =SUMIFS('Selected scen drivers'!M$2:M$271,'Selected scen drivers'!$A$2:$A$271,reporting!$A12,'Selected scen drivers'!$B$2:$B$271,reporting!$B12) -> 4294.8677 | ... W12: =SUMIFS('Selected scen drivers'!W$2:W$271,'Selected scen drivers'!$A$2:$A$271,reporting!$A12,'Selected scen drivers'!$B$2:$B$271,reporting!$B12) -> 6767.865 | X12: 2
A13: =A7+1 -> 2 | B13: =B7 -> 3 | D13: =IFERROR("rep_"&VLOOKUP(B13,Classification!$N$5:$O$14,2,FALSE),"\I:") -> rep_GDPIND | E13: =IFERROR(VLOOKUP(A13,Classification!$A$4:$B$39,2,FALSE),"\I:") -> India | F13: =SUMIFS('Selected scen drivers'!F$2:F$271,'Selected scen drivers'!$A$2:$A$271,reporting!$A13,'Selected scen drivers'!$B$2:$B$271,reporting!$B13) -> 2424.8263 | G13: =SUMIFS('Selected scen drivers'!G$2:G$271,'Selected scen drivers'!$A$2:$A$271,reporting!$A13,'Selected scen drivers'!$B$2:$B$271,reporting!$B13) -> 2516.0577 | H13: =SUMIFS('Selected scen drivers'!H$2:H$271,'Selected scen drivers'!$A$2:$A$271,reporting!$A13,'Selected scen drivers'!$B$2:$B$271,reporting!$B13) -> 3510.0156 | I13: =SUMIFS('Selected scen drivers'!I$2:I$271,'Selected scen drivers'!$A$2:$A$271,reporting!$A13,'Selected scen drivers'!$B$2:$B$271,reporting!$B13) -> 4656.1275 | J13: =SUMIFS('Selected scen drivers'!J$2:J$271,'Selected scen drivers'!$A$2:$A$271,reporting!$A13,'Selected scen drivers'!$B$2:$B$271,reporting!$B13) -> 5877.5005 | K13: =SUMIFS('Selected scen drivers'!K$2:K$271,'Selected scen drivers'!$A$2:$A$271,reporting!$A13,'Selected scen drivers'!$B$2:$B$271,reporting!$B13) -> 7199.2658 | L13: =SUMIFS('Selected scen drivers'!L$2:L$271,'Selected scen drivers'!$A$2:$A$271,reporting!$A13,'Selected scen drivers'!$B$2:$B$271,reporting!$B13) -> 8623.1951 | M13: =SUMIFS('Selected scen drivers'!M$2:M$271,'Selected scen drivers'!$A$2:$A$271,reporting!$A13,'Selected scen drivers'!$B$2:$B$271,reporting!$B13) -> 10152.731 | ... W13: =SUMIFS('Selected scen drivers'!W$2:W$271,'Selected scen drivers'!$A$2:$A$271,reporting!$A13,'Selected scen drivers'!$B$2:$B$271,reporting!$B13) -> 27071.46 | X13: 2
A14: =A8+1 -> 2 | B14: =B8 -> 7 | D14: =IFERROR("rep_"&VLOOKUP(B14,Classification!$N$5:$O$14,2,FALSE),"\I:") -> rep_GDPSER | E14: =IFERROR(VLOOKUP(A14,Classification!$A$4:$B$39,2,FALSE),"\I:") -> India | F14: =SUMIFS('Selected scen drivers'!F$2:F$271,'Selected scen drivers'!$A$2:$A$271,reporting!$A14,'Selected scen drivers'!$B$2:$B$271,reporting!$B14) -> 4489.648 | G14: =SUMIFS('Selected scen drivers'!G$2:G$271,'Selected scen drivers'!$A$2:$A$271,reporting!$A14,'Selected scen drivers'!$B$2:$B$271,reporting!$B14) -> 4658.566 | H14: =SUMIFS('Selected scen drivers'!H$2:H$271,'Selected scen drivers'!$A$2:$A$271,reporting!$A14,'Selected scen drivers'!$B$2:$B$271,reporting!$B14) -> 6550.4283 | I14: =SUMIFS('Selected scen drivers'!I$2:I$271,'Selected scen drivers'!$A$2:$A$271,reporting!$A14,'Selected scen drivers'!$B$2:$B$271,reporting!$B14) -> 8757.5322 | J14: =SUMIFS('Selected scen drivers'!J$2:J$271,'Selected scen drivers'!$A$2:$A$271,reporting!$A14,'Selected scen drivers'!$B$2:$B$271,reporting!$B14) -> 11140.729 | K14: =SUMIFS('Selected scen drivers'!K$2:K$271,'Selected scen drivers'!$A$2:$A$271,reporting!$A14,'Selected scen drivers'!$B$2:$B$271,reporting!$B14) -> 13751.23 | L14: =SUMIFS('Selected scen drivers'!L$2:L$271,'Selected scen drivers'!$A$2:$A$271,reporting!$A14,'Selected scen drivers'!$B$2:$B$271,reporting!$B14) -> 16596.742 | M14: =SUMIFS('Selected scen drivers'!M$2:M$271,'Selected scen drivers'!$A$2:$A$271,reporting!$A14,'Selected scen drivers'!$B$2:$B$271,reporting!$B14) -> 19688.302 | ... W14: =SUMIFS('Selected scen drivers'!W$2:W$271,'Selected scen drivers'!$A$2:$A$271,reporting!$A14,'Selected scen drivers'!$B$2:$B$271,reporting!$B14) -> 56398.875 | X14: 2
A15: =A9+1 -> 2 | B15: =B9 -> 8 | D15: =IFERROR("rep_"&VLOOKUP(B15,Classification!$N$5:$O$14,2,FALSE),"\I:") -> rep_HOU | E15: =IFERROR(VLOOKUP(A15,Classification!$A$4:$B$39,2,FALSE),"\I:") -> India | F15: =SUMIFS('Selected scen drivers'!F$2:F$271,'Selected scen drivers'!$A$2:$A$271,reporting!$A15,'Selected scen drivers'!$B$2:$B$271,reporting!$B15) -> 400.06803 | G15: =SUMIFS('Selected scen drivers'!G$2:G$271,'Selected scen drivers'!$A$2:$A$271,reporting!$A15,'Selected scen drivers'!$B$2:$B$271,reporting!$B15) -> 405.79446 | H15: =SUMIFS('Selected scen drivers'!H$2:H$271,'Selected scen drivers'!$A$2:$A$271,reporting!$A15,'Selected scen drivers'!$B$2:$B$271,reporting!$B15) -> 434.42666 | I15: =SUMIFS('Selected scen drivers'!I$2:I$271,'Selected scen drivers'!$A$2:$A$271,reporting!$A15,'Selected scen drivers'!$B$2:$B$271,reporting!$B15) -> 461.41704 | J15: =SUMIFS('Selected scen drivers'!J$2:J$271,'Selected scen drivers'!$A$2:$A$271,reporting!$A15,'Selected scen drivers'!$B$2:$B$271,reporting!$B15) -> 482.37817 | K15: =SUMIFS('Selected scen drivers'!K$2:K$271,'Selected scen drivers'!$A$2:$A$271,reporting!$A15,'Selected scen drivers'!$B$2:$B$271,reporting!$B15) -> 496.38372 | L15: =SUMIFS('Selected scen drivers'!L$2:L$271,'Selected scen drivers'!$A$2:$A$271,reporting!$A15,'Selected scen drivers'!$B$2:$B$271,reporting!$B15) -> 504.36066 | M15: =SUMIFS('Selected scen drivers'!M$2:M$271,'Selected scen drivers'!$A$2:$A$271,reporting!$A15,'Selected scen drivers'!$B$2:$B$271,reporting!$B15) -> 504.71485 | ... W15: =SUMIFS('Selected scen drivers'!W$2:W$271,'Selected scen drivers'!$A$2:$A$271,reporting!$A15,'Selected scen drivers'!$B$2:$B$271,reporting!$B15) -> 356.18949 | X15: 2
A16: =A10+1 -> 2 | B16: =B10 -> 9 | D16: =IFERROR("rep_"&VLOOKUP(B16,Classification!$N$5:$O$14,2,FALSE),"\I:") -> rep_POP | E16: =IFERROR(VLOOKUP(A16,Classification!$A$4:$B$39,2,FALSE),"\I:") -> India | F16: =SUMIFS('Selected scen drivers'!F$2:F$271,'Selected scen drivers'!$A$2:$A$271,reporting!$A16,'Selected scen drivers'!$B$2:$B$271,reporting!$B16) -> 1378.8638 | G16: =SUMIFS('Selected scen drivers'!G$2:G$271,'Selected scen drivers'!$A$2:$A$271,reporting!$A16,'Selected scen drivers'!$B$2:$B$271,reporting!$B16) -> 1389.9664 | H16: =SUMIFS('Selected scen drivers'!H$2:H$271,'Selected scen drivers'!$A$2:$A$271,reporting!$A16,'Selected scen drivers'!$B$2:$B$271,reporting!$B16) -> 1445.4796 | I16: =SUMIFS('Selected scen drivers'!I$2:I$271,'Selected scen drivers'!$A$2:$A$271,reporting!$A16,'Selected scen drivers'!$B$2:$B$271,reporting!$B16) -> 1501.7254 | J16: =SUMIFS('Selected scen drivers'!J$2:J$271,'Selected scen drivers'!$A$2:$A$271,reporting!$A16,'Selected scen drivers'!$B$2:$B$271,reporting!$B16) -> 1548.0675 | K16: =SUMIFS('Selected scen drivers'!K$2:K$271,'Selected scen drivers'!$A$2:$A$271,reporting!$A16,'Selected scen drivers'!$B$2:$B$271,reporting!$B16) -> 1583.687 | L16: =SUMIFS('Selected scen drivers'!L$2:L$271,'Selected scen drivers'!$A$2:$A$271,reporting!$A16,'Selected scen drivers'!$B$2:$B$271,reporting!$B16) -> 1607.6946 | M16: =SUMIFS('Selected scen drivers'!M$2:M$271,'Selected scen drivers'!$A$2:$A$271,reporting!$A16,'Selected scen drivers'!$B$2:$B$271,reporting!$B16) -> 1620.3579 | ... W16: =SUMIFS('Selected scen drivers'!W$2:W$271,'Selected scen drivers'!$A$2:$A$271,reporting!$A16,'Selected scen drivers'!$B$2:$B$271,reporting!$B16) -> 1391.608 | X16: 2
A17: =A11+1 -> 3 | B17: =B11 -> 1 | D17: =IFERROR("rep_"&VLOOKUP(B17,Classification!$N$5:$O$14,2,FALSE),"\I:") -> rep_GDP | E17: =IFERROR(VLOOKUP(A17,Classification!$A$4:$B$39,2,FALSE),"\I:") -> Asia_other | F17: =SUMIFS('Selected scen drivers'!F$2:F$271,'Selected scen drivers'!$A$2:$A$271,reporting!$A17,'Selected scen drivers'!$B$2:$B$271,reporting!$B17) -> 11714.345 | G17: =SUMIFS('Selected scen drivers'!G$2:G$271,'Selected scen drivers'!$A$2:$A$271,reporting!$A17,'Selected scen drivers'!$B$2:$B$271,reporting!$B17) -> 12146.472 | H17: =SUMIFS('Selected scen drivers'!H$2:H$271,'Selected scen drivers'!$A$2:$A$271,reporting!$A17,'Selected scen drivers'!$B$2:$B$271,reporting!$B17) -> 15028.804 | I17: =SUMIFS('Selected scen drivers'!I$2:I$271,'Selected scen drivers'!$A$2:$A$271,reporting!$A17,'Selected scen drivers'!$B$2:$B$271,reporting!$B17) -> 18856.172 | J17: =SUMIFS('Selected scen drivers'!J$2:J$271,'Selected scen drivers'!$A$2:$A$271,reporting!$A17,'Selected scen drivers'!$B$2:$B$271,reporting!$B17) -> 22959.734 | K17: =SUMIFS('Selected scen drivers'!K$2:K$271,'Selected scen drivers'!$A$2:$A$271,reporting!$A17,'Selected scen drivers'!$B$2:$B$271,reporting!$B17) -> 27131.52 | L17: =SUMIFS('Selected scen drivers'!L$2:L$271,'Selected scen drivers'!$A$2:$A$271,reporting!$A17,'Selected scen drivers'!$B$2:$B$271,reporting!$B17) -> 31460.714 | M17: =SUMIFS('Selected scen drivers'!M$2:M$271,'Selected scen drivers'!$A$2:$A$271,reporting!$A17,'Selected scen drivers'!$B$2:$B$271,reporting!$B17) -> 36006.751 | ... W17: =SUMIFS('Selected scen drivers'!W$2:W$271,'Selected scen drivers'!$A$2:$A$271,reporting!$A17,'Selected scen drivers'!$B$2:$B$271,reporting!$B17) -> 98435.497 | X17: 2
A18: =A12+1 -> 3 | B18: =B12 -> 2 | D18: =IFERROR("rep_"&VLOOKUP(B18,Classification!$N$5:$O$14,2,FALSE),"\I:") -> rep_GDPAGR | E18: =IFERROR(VLOOKUP(A18,Classification!$A$4:$B$39,2,FALSE),"\I:") -> Asia_other | F18: =SUMIFS('Selected scen drivers'!F$2:F$271,'Selected scen drivers'!$A$2:$A$271,reporting!$A18,'Selected scen drivers'!$B$2:$B$271,reporting!$B18) -> 1336.8355 | G18: =SUMIFS('Selected scen drivers'!G$2:G$271,'Selected scen drivers'!$A$2:$A$271,reporting!$A18,'Selected scen drivers'!$B$2:$B$271,reporting!$B18) -> 1386.313 | H18: =SUMIFS('Selected scen drivers'!H$2:H$271,'Selected scen drivers'!$A$2:$A$271,reporting!$A18,'Selected scen drivers'!$B$2:$B$271,reporting!$B18) -> 1669.2505 | I18: =SUMIFS('Selected scen drivers'!I$2:I$271,'Selected scen drivers'!$A$2:$A$271,reporting!$A18,'Selected scen drivers'!$B$2:$B$271,reporting!$B18) -> 2078.722 | J18: =SUMIFS('Selected scen drivers'!J$2:J$271,'Selected scen drivers'!$A$2:$A$271,reporting!$A18,'Selected scen drivers'!$B$2:$B$271,reporting!$B18) -> 2514.4048 | K18: =SUMIFS('Selected scen drivers'!K$2:K$271,'Selected scen drivers'!$A$2:$A$271,reporting!$A18,'Selected scen drivers'!$B$2:$B$271,reporting!$B18) -> 2954.1833 | L18: =SUMIFS('Selected scen drivers'!L$2:L$271,'Selected scen drivers'!$A$2:$A$271,reporting!$A18,'Selected scen drivers'!$B$2:$B$271,reporting!$B18) -> 3400.4285 | M18: =SUMIFS('Selected scen drivers'!M$2:M$271,'Selected scen drivers'!$A$2:$A$271,reporting!$A18,'Selected scen drivers'!$B$2:$B$271,reporting!$B18) -> 3851.4182 | ... W18: =SUMIFS('Selected scen drivers'!W$2:W$271,'Selected scen drivers'!$A$2:$A$271,reporting!$A18,'Selected scen drivers'!$B$2:$B$271,reporting!$B18) -> 7100.6285 | X18: 2
A19: =A13+1 -> 3 | B19: =B13 -> 3 | D19: =IFERROR("rep_"&VLOOKUP(B19,Classification!$N$5:$O$14,2,FALSE),"\I:") -> rep_GDPIND | E19: =IFERROR(VLOOKUP(A19,Classification!$A$4:$B$39,2,FALSE),"\I:") -> Asia_other | F19: =SUMIFS('Selected scen drivers'!F$2:F$271,'Selected scen drivers'!$A$2:$A$271,reporting!$A19,'Selected scen drivers'!$B$2:$B$271,reporting!$B19) -> 3564.3207 | G19: =SUMIFS('Selected scen drivers'!G$2:G$271,'Selected scen drivers'!$A$2:$A$271,reporting!$A19,'Selected scen drivers'!$B$2:$B$271,reporting!$B19) -> 3688.6003 | H19: =SUMIFS('Selected scen drivers'!H$2:H$271,'Selected scen drivers'!$A$2:$A$271,reporting!$A19,'Selected scen drivers'!$B$2:$B$271,reporting!$B19) -> 4615.5331 | I19: =SUMIFS('Selected scen drivers'!I$2:I$271,'Selected scen drivers'!$A$2:$A$271,reporting!$A19,'Selected scen drivers'!$B$2:$B$271,reporting!$B19) -> 5867.0657 | J19: =SUMIFS('Selected scen drivers'!J$2:J$271,'Selected scen drivers'!$A$2:$A$271,reporting!$A19,'Selected scen drivers'!$B$2:$B$271,reporting!$B19) -> 7224.6937 | K19: =SUMIFS('Selected scen drivers'!K$2:K$271,'Selected scen drivers'!$A$2:$A$271,reporting!$A19,'Selected scen drivers'!$B$2:$B$271,reporting!$B19) -> 8622.5871 | L19: =SUMIFS('Selected scen drivers'!L$2:L$271,'Selected scen drivers'!$A$2:$A$271,reporting!$A19,'Selected scen drivers'!$B$2:$B$271,reporting!$B19) -> 10073.64 | M19: =SUMIFS('Selected scen drivers'!M$2:M$271,'Selected scen drivers'!$A$2:$A$271,reporting!$A19,'Selected scen drivers'!$B$2:$B$271,reporting!$B19) -> 11588.937 | ... W19: =SUMIFS('Selected scen drivers'!W$2:W$271,'Selected scen drivers'!$A$2:$A$271,reporting!$A19,'Selected scen drivers'!$B$2:$B$271,reporting!$B19) -> 32296.69 | X19: 2
A20: =A14+1 -> 3 | B20: =B14 -> 7 | D20: =IFERROR("rep_"&VLOOKUP(B20,Classification!$N$5:$O$14,2,FALSE),"\I:") -> rep_GDPSER | E20: =IFERROR(VLOOKUP(A20,Classification!$A$4:$B$39,2,FALSE),"\I:") -> Asia_other | F20: =SUMIFS('Selected scen drivers'!F$2:F$271,'Selected scen drivers'!$A$2:$A$271,reporting!$A20,'Selected scen drivers'!$B$2:$B$271,reporting!$B20) -> 5561.9094 | G20: =SUMIFS('Selected scen drivers'!G$2:G$271,'Selected scen drivers'!$A$2:$A$271,reporting!$A20,'Selected scen drivers'!$B$2:$B$271,reporting!$B20) -> 5734.8657 | H20: =SUMIFS('Selected scen drivers'!H$2:H$271,'Selected scen drivers'!$A$2:$A$271,reporting!$A20,'Selected scen drivers'!$B$2:$B$271,reporting!$B20) -> 7181.4398 | I20: =SUMIFS('Selected scen drivers'!I$2:I$271,'Selected scen drivers'!$A$2:$A$271,reporting!$A20,'Selected scen drivers'!$B$2:$B$271,reporting!$B20) -> 9144.3954 | J20: =SUMIFS('Selected scen drivers'!J$2:J$271,'Selected scen drivers'!$A$2:$A$271,reporting!$A20,'Selected scen drivers'!$B$2:$B$271,reporting!$B20) -> 11317.14 | K20: =SUMIFS('Selected scen drivers'!K$2:K$271,'Selected scen drivers'!$A$2:$A$271,reporting!$A20,'Selected scen drivers'!$B$2:$B$271,reporting!$B20) -> 13594.466 | L20: =SUMIFS('Selected scen drivers'!L$2:L$271,'Selected scen drivers'!$A$2:$A$271,reporting!$A20,'Selected scen drivers'!$B$2:$B$271,reporting!$B20) -> 16014.225 | M20: =SUMIFS('Selected scen drivers'!M$2:M$271,'Selected scen drivers'!$A$2:$A$271,reporting!$A20,'Selected scen drivers'!$B$2:$B$271,reporting!$B20) -> 18601.606 | ... W20: =SUMIFS('Selected scen drivers'!W$2:W$271,'Selected scen drivers'!$A$2:$A$271,reporting!$A20,'Selected scen drivers'!$B$2:$B$271,reporting!$B20) -> 56482.062 | X20: 2
A21: =A15+1 -> 3 | B21: =B15 -> 8 | D21: =IFERROR("rep_"&VLOOKUP(B21,Classification!$N$5:$O$14,2,FALSE),"\I:") -> rep_HOU | E21: =IFERROR(VLOOKUP(A21,Classification!$A$4:$B$39,2,FALSE),"\I:") -> Asia_other | F21: =SUMIFS('Selected scen drivers'!F$2:F$271,'Selected scen drivers'!$A$2:$A$271,reporting!$A21,'Selected scen drivers'!$B$2:$B$271,reporting!$B21) -> 339.98886 | G21: =SUMIFS('Selected scen drivers'!G$2:G$271,'Selected scen drivers'!$A$2:$A$271,reporting!$A21,'Selected scen drivers'!$B$2:$B$271,reporting!$B21) -> 344.92208 | H21: =SUMIFS('Selected scen drivers'!H$2:H$271,'Selected scen drivers'!$A$2:$A$271,reporting!$A21,'Selected scen drivers'!$B$2:$B$271,reporting!$B21) -> 369.58804 | I21: =SUMIFS('Selected scen drivers'!I$2:I$271,'Selected scen drivers'!$A$2:$A$271,reporting!$A21,'Selected scen drivers'!$B$2:$B$271,reporting!$B21) -> 392.53586 | J21: =SUMIFS('Selected scen drivers'!J$2:J$271,'Selected scen drivers'!$A$2:$A$271,reporting!$A21,'Selected scen drivers'!$B$2:$B$271,reporting!$B21) -> 412.89709 | K21: =SUMIFS('Selected scen drivers'!K$2:K$271,'Selected scen drivers'!$A$2:$A$271,reporting!$A21,'Selected scen drivers'!$B$2:$B$271,reporting!$B21) -> 430.87593 | L21: =SUMIFS('Selected scen drivers'!L$2:L$271,'Selected scen drivers'!$A$2:$A$271,reporting!$A21,'Selected scen drivers'!$B$2:$B$271,reporting!$B21) -> 445.77786 | M21: =SUMIFS('Selected scen drivers'!M$2:M$271,'Selected scen drivers'!$A$2:$A$271,reporting!$A21,'Selected scen drivers'!$B$2:$B$271,reporting!$B21) -> 456.34764 | ... W21: =SUMIFS('Selected scen drivers'!W$2:W$271,'Selected scen drivers'!$A$2:$A$271,reporting!$A21,'Selected scen drivers'!$B$2:$B$271,reporting!$B21) -> 418.6083 | X21: 2
A22: =A16+1 -> 3 | B22: =B16 -> 9 | D22: =IFERROR("rep_"&VLOOKUP(B22,Classification!$N$5:$O$14,2,FALSE),"\I:") -> rep_POP | E22: =IFERROR(VLOOKUP(A22,Classification!$A$4:$B$39,2,FALSE),"\I:") -> Asia_other | F22: =SUMIFS('Selected scen drivers'!F$2:F$271,'Selected scen drivers'!$A$2:$A$271,reporting!$A22,'Selected scen drivers'!$B$2:$B$271,reporting!$B22) -> 1202.7846 | G22: =SUMIFS('Selected scen drivers'!G$2:G$271,'Selected scen drivers'!$A$2:$A$271,reporting!$A22,'Selected scen drivers'!$B$2:$B$271,reporting!$B22) -> 1216.8755 | H22: =SUMIFS('Selected scen drivers'!H$2:H$271,'Selected scen drivers'!$A$2:$A$271,reporting!$A22,'Selected scen drivers'!$B$2:$B$271,reporting!$B22) -> 1287.3297 | I22: =SUMIFS('Selected scen drivers'!I$2:I$271,'Selected scen drivers'!$A$2:$A$271,reporting!$A22,'Selected scen drivers'!$B$2:$B$271,reporting!$B22) -> 1355.2111 | J22: =SUMIFS('Selected scen drivers'!J$2:J$271,'Selected scen drivers'!$A$2:$A$271,reporting!$A22,'Selected scen drivers'!$B$2:$B$271,reporting!$B22) -> 1416.3443 | K22: =SUMIFS('Selected scen drivers'!K$2:K$271,'Selected scen drivers'!$A$2:$A$271,reporting!$A22,'Selected scen drivers'!$B$2:$B$271,reporting!$B22) -> 1469.8098 | L22: =SUMIFS('Selected scen drivers'!L$2:L$271,'Selected scen drivers'!$A$2:$A$271,reporting!$A22,'Selected scen drivers'!$B$2:$B$271,reporting!$B22) -> 1515.5399 | M22: =SUMIFS('Selected scen drivers'!M$2:M$271,'Selected scen drivers'!$A$2:$A$271,reporting!$A22,'Selected scen drivers'!$B$2:$B$271,reporting!$B22) -> 1554.02 | ... W22: =SUMIFS('Selected scen drivers'!W$2:W$271,'Selected scen drivers'!$A$2:$A$271,reporting!$A22,'Selected scen drivers'!$B$2:$B$271,reporting!$B22) -> 1577.7737 | X22: 2
... A214: =A208+1 -> 35 | B214: =B208 -> 9 | D214: =IFERROR("rep_"&VLOOKUP(B214,Classification!$N$5:$O$14,2,FALSE),"\I:") -> rep_POP | E214: =IFERROR(VLOOKUP(A214,Classification!$A$4:$B$39,2,FALSE),"\I:") -> \I: | F214: =SUMIFS('Selected scen drivers'!F$2:F$271,'Selected scen drivers'!$A$2:$A$271,reporting!$A214,'Selected scen drivers'!$B$2:$B$271,reporting!$B214) -> 0 | G214: =SUMIFS('Selected scen drivers'!G$2:G$271,'Selected scen drivers'!$A$2:$A$271,reporting!$A214,'Selected scen drivers'!$B$2:$B$271,reporting!$B214) -> 0 | H214: =SUMIFS('Selected scen drivers'!H$2:H$271,'Selected scen drivers'!$A$2:$A$271,reporting!$A214,'Selected scen drivers'!$B$2:$B$271,reporting!$B214) -> 0 | I214: =SUMIFS('Selected scen drivers'!I$2:I$271,'Selected scen drivers'!$A$2:$A$271,reporting!$A214,'Selected scen drivers'!$B$2:$B$271,reporting!$B214) -> 0 | J214: =SUMIFS('Selected scen drivers'!J$2:J$271,'Selected scen drivers'!$A$2:$A$271,reporting!$A214,'Selected scen drivers'!$B$2:$B$271,reporting!$B214) -> 0 | K214: =SUMIFS('Selected scen drivers'!K$2:K$271,'Selected scen drivers'!$A$2:$A$271,reporting!$A214,'Selected scen drivers'!$B$2:$B$271,reporting!$B214) -> 0 | L214: =SUMIFS('Selected scen drivers'!L$2:L$271,'Selected scen drivers'!$A$2:$A$271,reporting!$A214,'Selected scen drivers'!$B$2:$B$271,reporting!$B214) -> 0 | M214: =SUMIFS('Selected scen drivers'!M$2:M$271,'Selected scen drivers'!$A$2:$A$271,reporting!$A214,'Selected scen drivers'!$B$2:$B$271,reporting!$B214) -> 0 | ... W214: =SUMIFS('Selected scen drivers'!W$2:W$271,'Selected scen drivers'!$A$2:$A$271,reporting!$A214,'Selected scen drivers'!$B$2:$B$271,reporting!$B214) -> 0 | X214: 2

Sheet Classification
B3: ActiveReg | C3: Status | D3: ElastClass
A4: 1 | B4: Africa_other | C4: Eme | D4: =C4 -> Eme | F4: ~TFM_FILL-R:w=BYDem
A5: =A4+1 -> 2 | B5: India | C5: Eme | D5: =C5 -> Eme | F5: Scenario | G5: Attribute | H5: CSET_Set | I5: Year | J5: AllRegions | N5: 1 | O5: GDP
A6: =A5+1 -> 3 | B6: Asia_other | C6: Eme | D6: =C6 -> Eme | F6: BASE | G6: Demand | H6: DEM | I6: 2019 | J6: *1 | N6: 2 | O6: GDPAGR
A7: =A6+1 -> 4 | B7: Asia_central | C7: Eme | D7: =C7 -> Eme | N7: 3 | O7: GDPIND
A8: =A7+1 -> 5 | B8: LatAm_other | C8: Eme | D8: =C8 -> Eme | N8: 4 | O8: GDPMFG
A9: =A8+1 -> 6 | B9: Brazil | C9: Eme | D9: =C9 -> Eme | N9: 5 | O9: GDPPCAP
A10: =A9+1 -> 7 | B10: Africa_north | C10: Eme | D10: =C10 -> Eme | N10: 6 | O10: GDPPHOU
A11: =A10+1 -> 8 | B11: SouthAfrica | C11: Eme | D11: Eme | N11: 7 | O11: GDPSER
A12: =A11+1 -> 9 | B12: MidEast_other | C12: Eme | D12: =C12 -> Eme | N12: 8 | O12: HOU
A13: =A12+1 -> 10 | B13: Mexico | C13: Eme | D13: =C13 -> Eme | N13: 9 | O13: POP
A14: =A13+1 -> 11 | B14: Europe_other | C14: Dev | D14: =C14 -> Dev
A15: =A14+1 -> 12 | B15: Arg-Chi | C15: Dev | D15: =C15 -> Dev
A16: =A15+1 -> 13 | B16: Russia | C16: Dev | D16: =C16 -> Dev
A17: =A16+1 -> 14 | B17: EU_southeast | C17: Dev | D17: =C17 -> Dev
A18: =A17+1 -> 15 | B18: EU_southwest | C18: Dev | D18: =C18 -> Dev
A19: =A18+1 -> 16 | B19: China | C19: Dev | D19: Chi
A20: =A19+1 -> 17 | B20: EU_south | C20: Dev | D20: =C20 -> Dev
A21: =A20+1 -> 18 | B21: EU_northeast | C21: Dev | D21: =C21 -> Dev
A22: =A21+1 -> 19 | B22: France | C22: Dev | D22: =C22 -> Dev
A23: =A22+1 -> 20 | B23: UK | C23: Dev | D23: =C23 -> Dev
A24: =A23+1 -> 21 | B24: Australia_NZ | C24: Dev | D24: =C24 -> Dev
A25: =A24+1 -> 22 | B25: SaudiArabia | C25: Dev | D25: =C25 -> Dev
A26: =A25+1 -> 23 | B26: EU_north | C26: Dev | D26: =C26 -> Dev
A27: =A26+1 -> 24 | B27: Germany | C27: Dev | D27: =C27 -> Dev
A28: =A27+1 -> 25 | B28: Canada | C28: Dev | D28: =C28 -> Dev
A29: =A28+1 -> 26 | B29: Asia_east | C29: Dev | D29: =C29 -> Dev
A30: =A29+1 -> 27 | B30: EU_northwest | C30: Dev | D30: =C30 -> Dev
A31: =A30+1 -> 28 | B31: Nor-Ice | C31: Dev | D31: =C31 -> Dev
A32: =A31+1 -> 29 | B32: USA | C32: Dev | D32: =C32 -> Dev

Sheet SSP drivers
A1: Model | B1: Scenario | C1: ActiveReg | D1: drvr | E1: 2015 | F1: 2019 | G1: 2020 | H1: 2025 | I1: 2030 | J1: 2035 | K1: 2040 | L1: 2045 | M1: 2050 | N1: 2055 | O1: 2060 | P1: 2065 | Q1: 2070 | R1: 2075 | S1: 2080 | T1: 2085 | U1: 2090 | V1: 2095 | W1: 2100
A2: OECD23 | B2: SSP1 | C2: Africa_north | D2: GDP | F2: 2210.4794 | G2: 2262.425 | H2: 2781.659 | I2: 3473.068 | J2: 4436.465 | K2: 5730.945 | L2: 7368.96 | M2: 9262.532 | N2: 11383.986 | O2: 13731.282 | P2: 16261.404 | Q2: 18844.799 | R2: 21467.312 | S2: 24108.468 | T2: 26758.704 | U2: 29423.216 | V2: 32089.367 | W2: 34706.937
A3: OECD23 | B3: SSP1 | C3: Africa_north | D3: GDPPCAP | F3: 10.951082 | G3: 11.045012 | H3: 12.657175 | I3: 14.908783 | J3: 18.137203 | K3: 22.480366 | L3: 27.884857 | M3: 34.054782 | N3: 40.996313 | O3: 48.820785 | P3: 57.478341 | Q3: 66.603511 | R3: 76.20171 | S3: 86.265851 | T3: 96.842016 | U3: 107.99847 | V3: 119.82143 | W3: 132.30086
A4: OECD23 | B4: SSP1 | C4: Africa_north | D4: GDPPHOU | F4: 39.501721 | G4: 39.778539 | H4: 45.2613 | I4: 52.232334 | J4: 62.043485 | K4: 75.181998 | L4: 92.383772 | M4: 113.35523 | N4: 138.00734 | O4: 165.48178 | P4: 195.35926 | Q4: 227.74622 | R4: 266.03337 | S4: 315.40895 | T4: 375.40723 | U4: 442.89494 | V4: 517.694 | W4: 602.10906
A5: OECD23 | B5: SSP1 | C5: Africa_north | D5: HOU | F5: 55.959065 | G5: 56.875518 | H5: 61.45778 | I5: 66.492683 | J5: 71.505735 | K5: 76.227624 | L5: 79.764658 | M5: 81.712435 | N5: 82.488262 | O5: 82.977605 | P5: 83.238458 | Q5: 82.744727 | R5: 80.694056 | S5: 76.435587 | T5: 71.279139 | U5: 66.43385 | V5: 61.985202 | W5: 57.642277
A6: OECD23 | B6: SSP1 | C6: Africa_north | D6: POP | F6: 201.85031 | G6: 204.83682 | H6: 219.76933 | I6: 232.95449 | J6: 244.6058 | K6: 254.93113 | L6: 264.26387 | M6: 271.98917 | N6: 277.68317 | O6: 281.25893 | P6: 282.91359 | Q6: 282.94003 | R6: 281.71693 | S6: 279.46711 | T6: 276.31296 | U6: 272.44105 | V6: 267.80992 | W6: 262.33342
A7: OECD23 | B7: SSP1 | C7: Africa_other | D7: GDP | F7: 3397.857 | G7: 3468.8105 | H7: 4236.7911 | I7: 5417.4402 | J7: 7165.7299 | K7: 9450.1902 | L7: 12439.912 | M7: 16161.965 | N7: 20685.528 | O7: 26153.297 | P7: 32676.41 | Q7: 40228.156 | R7: 48807.647 | S7: 58335.329 | T7: 68745.744 | U7: 80007.093 | V7: 92058.261 | W7: 104801.48
A8: OECD23 | B8: SSP1 | C8: Africa_other | D8: GDPPCAP | F8: 3.2289289 | G8: 3.2133267 | H8: 3.4857513 | I8: 4.0209551 | J8: 4.8570815 | K8: 5.9174144 | L8: 7.249812 | M8: 8.8415303 | N8: 10.734936 | O8: 13.005033 | P8: 15.697089 | Q8: 18.80613 | R8: 22.3601 | S8: 26.370627 | T8: 30.873742 | U8: 35.932011 | V8: 41.610009 | W8: 47.960975
A9: OECD23 | B9: SSP1 | C9: Africa_other | D9: GDPPHOU | F9: 14.780145 | G9: 14.571355 | H9: 15.192482 | I9: 16.606544 | J9: 18.886173 | K9: 21.806344 | L9: 25.570143 | M9: 30.193792 | N9: 35.776375 | O9: 42.435621 | P9: 50.494791 | Q9: 60.128703 | R9: 71.786509 | S9: 85.851326 | T9: 102.98749 | U9: 122.92662 | V9: 145.9713 | W9: 172.94845
A10: OECD23 | B10: SSP1 | C10: Africa_other | D10: HOU | F10: 229.89334 | G10: 238.05682 | H10: 278.87419 | I10: 326.22321 | J10: 379.41671 | K10: 433.36885 | L10: 486.50146 | M10: 535.27442 | N10: 578.1896 | O10: 616.30527 | P10: 647.12437 | Q10: 669.03416 | R10: 679.89999 | S10: 679.49246 | T10: 667.5155 | U10: 650.85247 | V10: 630.66002 | W10: 605.96946
A11: OECD23 | B11: SSP1 | C11: Africa_other | D11: POP | F11: 1052.3171 | G11: 1079.5075 | H11: 1215.4599 | I11: 1347.3018 | J11: 1475.316 | K11: 1597.0134 | L11: 1715.8944 | M11: 1827.9601 | N11: 1926.9354 | O11: 2011.0135 | P11: 2081.6859 | Q11: 2139.0981 | R11: 2182.8009 | S11: 2212.1328 | T11: 2226.6735 | U11: 2226.6245 | V11: 2212.4067 | W11: 2185.1408
A12: OECD23 | B12: SSP1 | C12: Arg-Chi | D12: GDP | F12: 1183.2516 | G12: 1160.954 | H12: 1351.418 | I12: 1504.165 | J12: 1688.292 | K12: 1916.964 | L12: 2189.559 | M12: 2484.397 | N12: 2790.632 | O12: 3102.68 | P12: 3422.2 | Q12: 3740.34 | R12: 4042.28 | S12: 4318.22 | T12: 4563.09 | U12: 4771.92 | V12: 4938.15 | W12: 5055.7
A13: OECD23 | B13: SSP1 | C13: Arg-Chi | D13: GDPPCAP | F13: 18.532211 | G13: 18.107332 | H13: 20.648441 | I13: 22.564267 | J13: 24.978353 | K13: 28.110596 | L13: 31.937247 | M13: 36.189008 | N13: 40.776477 | O13: 45.719215 | P13: 51.085741 | Q13: 56.793002 | R13: 62.671746 | S13: 68.632408 | T13: 74.656008 | U13: 80.742076 | V13: 86.873153 | W13: 93.005116
... A1306: OECD23 | B1306: SSP5 | C1306: USA | D1306: GDPSER | F1306: 15437.372 | G1306: 15659.411 | H1306: 17712.161 | I1306: 19366.227 | J1306: 21477.772 | K1306: 24069.211 | L1306: 26933.697 | M1306: 29801.638 | N1306: 32765.254 | O1306: 35940.159 | P1306: 39351.015 | Q1306: 42936.04 | R1306: 46659.905 | S1306: 50489.614 | T1306: 54376.057 | U1306: 58253.245 | V1306: 62024.052 | W1306: 65494.941

Sheet Selected scen drivers
C1: region | D1: driver | E1: ='SSP drivers'!E1 -> 2015 | F1: ='SSP drivers'!F1 -> 2019 | G1: ='SSP drivers'!G1 -> 2020 | H1: ='SSP drivers'!H1 -> 2025 | I1: ='SSP drivers'!I1 -> 2030 | J1: ='SSP drivers'!J1 -> 2035 | K1: ='SSP drivers'!K1 -> 2040 | L1: ='SSP drivers'!L1 -> 2045 | ... W1: ='SSP drivers'!W1 -> 2100 | AH1: =VLOOKUP($AI$10,$AJ$12:$AL$23,2,FALSE) -> OECD23 | AI1: =VLOOKUP($AI$10,$AJ$12:$AL$23,3,FALSE) -> SSP2
A2: 1 | B2: 1 | C2: =IFERROR(VLOOKUP(A2,Classification!$A$4:$B$37,2,FALSE),"") -> Africa_other | D2: =IFERROR(VLOOKUP(B2,Classification!$N$5:$O$14,2,FALSE),"") -> GDP | E2: =SUMIFS('SSP drivers'!E$2:E$7886,'SSP drivers'!$A$2:$A$7886,'Selected scen drivers'!$AH$1,'SSP drivers'!$B$2:$B$7886,'Selected scen drivers'!$AI$1,'SSP drivers'!$C$2:$C$7886,'Selected scen drivers'!$C2,'SSP drivers'!$D$2:$D$7886,'Selected scen drivers'!$D2) -> 0 | F2: =SUMIFS('SSP drivers'!F$2:F$7886,'SSP drivers'!$A$2:$A$7886,'Selected scen drivers'!$AH$1,'SSP drivers'!$B$2:$B$7886,'Selected scen drivers'!$AI$1,'SSP drivers'!$C$2:$C$7886,'Selected scen drivers'!$C2,'SSP drivers'!$D$2:$D$7886,'Selected scen drivers'!$D2) -> 3397.857 | G2: =SUMIFS('SSP drivers'!G$2:G$7886,'SSP drivers'!$A$2:$A$7886,'Selected scen drivers'!$AH$1,'SSP drivers'!$B$2:$B$7886,'Selected scen drivers'!$AI$1,'SSP drivers'!$C$2:$C$7886,'Selected scen drivers'!$C2,'SSP drivers'!$D$2:$D$7886,'Selected scen drivers'!$D2) -> 3468.8105 | H2: =SUMIFS('SSP drivers'!H$2:H$7886,'SSP drivers'!$A$2:$A$7886,'Selected scen drivers'!$AH$1,'SSP drivers'!$B$2:$B$7886,'Selected scen drivers'!$AI$1,'SSP drivers'!$C$2:$C$7886,'Selected scen drivers'!$C2,'SSP drivers'!$D$2:$D$7886,'Selected scen drivers'!$D2) -> 4236.7911 | I2: =SUMIFS('SSP drivers'!I$2:I$7886,'SSP drivers'!$A$2:$A$7886,'Selected scen drivers'!$AH$1,'SSP drivers'!$B$2:$B$7886,'Selected scen drivers'!$AI$1,'SSP drivers'!$C$2:$C$7886,'Selected scen drivers'!$C2,'SSP drivers'!$D$2:$D$7886,'Selected scen drivers'!$D2) -> 5413.3577 | J2: =SUMIFS('SSP drivers'!J$2:J$7886,'SSP drivers'!$A$2:$A$7886,'Selected scen drivers'!$AH$1,'SSP drivers'!$B$2:$B$7886,'Selected scen drivers'!$AI$1,'SSP drivers'!$C$2:$C$7886,'Selected scen drivers'!$C2,'SSP drivers'!$D$2:$D$7886,'Selected scen drivers'!$D2) -> 7069.4163 | K2: =SUMIFS('SSP drivers'!K$2:K$7886,'SSP drivers'!$A$2:$A$7886,'Selected scen drivers'!$AH$1,'SSP drivers'!$B$2:$B$7886,'Selected scen drivers'!$AI$1,'SSP drivers'!$C$2:$C$7886,'Selected scen drivers'!$C2,'SSP drivers'!$D$2:$D$7886,'Selected scen drivers'!$D2) -> 9098.1883 | L2: =SUMIFS('SSP drivers'!L$2:L$7886,'SSP drivers'!$A$2:$A$7886,'Selected scen drivers'!$AH$1,'SSP drivers'!$B$2:$B$7886,'Selected scen drivers'!$AI$1,'SSP drivers'!$C$2:$C$7886,'Selected scen drivers'!$C2,'SSP drivers'!$D$2:$D$7886,'Selected scen drivers'!$D2) -> 11631.587 | ... W2: =SUMIFS('SSP drivers'!W$2:W$7886,'SSP drivers'!$A$2:$A$7886,'Selected scen drivers'!$AH$1,'SSP drivers'!$B$2:$B$7886,'Selected scen drivers'!$AI$1,'SSP drivers'!$C$2:$C$7886,'Selected scen drivers'!$C2,'SSP drivers'!$D$2:$D$7886,'Selected scen drivers'!$D2) -> 104963.21
A3: 1 | B3: 2 | C3: =IFERROR(VLOOKUP(A3,Classification!$A$4:$B$37,2,FALSE),"") -> Africa_other | D3: =IFERROR(VLOOKUP(B3,Classification!$N$5:$O$14,2,FALSE),"") -> GDPAGR | E3: =SUMIFS('SSP drivers'!E$2:E$7886,'SSP drivers'!$A$2:$A$7886,'Selected scen drivers'!$AH$1,'SSP drivers'!$B$2:$B$7886,'Selected scen drivers'!$AI$1,'SSP drivers'!$C$2:$C$7886,'Selected scen drivers'!$C3,'SSP drivers'!$D$2:$D$7886,'Selected scen drivers'!$D3) -> 0 | F3: =SUMIFS('SSP drivers'!F$2:F$7886,'SSP drivers'!$A$2:$A$7886,'Selected scen drivers'!$AH$1,'SSP drivers'!$B$2:$B$7886,'Selected scen drivers'!$AI$1,'SSP drivers'!$C$2:$C$7886,'Selected scen drivers'!$C3,'SSP drivers'!$D$2:$D$7886,'Selected scen drivers'!$D3) -> 791.76348 | G3: =SUMIFS('SSP drivers'!G$2:G$7886,'SSP drivers'!$A$2:$A$7886,'Selected scen drivers'!$AH$1,'SSP drivers'!$B$2:$B$7886,'Selected scen drivers'!$AI$1,'SSP drivers'!$C$2:$C$7886,'Selected scen drivers'!$C3,'SSP drivers'!$D$2:$D$7886,'Selected scen drivers'!$D3) -> 812.01851 | H3: =SUMIFS('SSP drivers'!H$2:H$7886,'SSP drivers'!$A$2:$A$7886,'Selected scen drivers'!$AH$1,'SSP drivers'!$B$2:$B$7886,'Selected scen drivers'!$AI$1,'SSP drivers'!$C$2:$C$7886,'Selected scen drivers'!$C3,'SSP drivers'!$D$2:$D$7886,'Selected scen drivers'!$D3) -> 951.88078 | I3: =SUMIFS('SSP drivers'!I$2:I$7886,'SSP drivers'!$A$2:$A$7886,'Selected scen drivers'!$AH$1,'SSP drivers'!$B$2:$B$7886,'Selected scen drivers'!$AI$1,'SSP drivers'!$C$2:$C$7886,'Selected scen drivers'!$C3,'SSP drivers'!$D$2:$D$7886,'Selected scen drivers'!$D3) -> 1175.539 | J3: =SUMIFS('SSP drivers'!J$2:J$7886,'SSP drivers'!$A$2:$A$7886,'Selected scen drivers'!$AH$1,'SSP drivers'!$B$2:$B$7886,'Selected scen drivers'!$AI$1,'SSP drivers'!$C$2:$C$7886,'Selected scen drivers'!$C3,'SSP drivers'!$D$2:$D$7886,'Selected scen drivers'!$D3) -> 1475.4991 | K3: =SUMIFS('SSP drivers'!K$2:K$7886,'SSP drivers'!$A$2:$A$7886,'Selected scen drivers'!$AH$1,'SSP drivers'!$B$2:$B$7886,'Selected scen drivers'!$AI$1,'SSP drivers'!$C$2:$C$7886,'Selected scen drivers'!$C3,'SSP drivers'!$D$2:$D$7886,'Selected scen drivers'!$D3) -> 1819.0655 | L3: =SUMIFS('SSP drivers'!L$2:L$7886,'SSP drivers'!$A$2:$A$7886,'Selected scen drivers'!$AH$1,'SSP drivers'!$B$2:$B$7886,'Selected scen drivers'!$AI$1,'SSP drivers'!$C$2:$C$7886,'Selected scen drivers'!$C3,'SSP drivers'!$D$2:$D$7886,'Selected scen drivers'!$D3) -> 2219.798 | ... W3: =SUMIFS('SSP drivers'!W$2:W$7886,'SSP drivers'!$A$2:$A$7886,'Selected scen drivers'!$AH$1,'SSP drivers'!$B$2:$B$7886,'Selected scen drivers'!$AI$1,'SSP drivers'!$C$2:$C$7886,'Selected scen drivers'!$C3,'SSP drivers'!$D$2:$D$7886,'Selected scen drivers'!$D3) -> 7763.9847
A4: 1 | B4: 3 | C4: =IFERROR(VLOOKUP(A4,Classification!$A$4:$B$37,2,FALSE),"") -> Africa_other | D4: =IFERROR(VLOOKUP(B4,Classification!$N$5:$O$14,2,FALSE),"") -> GDPIND | E4: =SUMIFS('SSP drivers'!E$2:E$7886,'SSP drivers'!$A$2:$A$7886,'Selected scen drivers'!$AH$1,'SSP drivers'!$B$2:$B$7886,'Selected scen drivers'!$AI$1,'SSP drivers'!$C$2:$C$7886,'Selected scen drivers'!$C4,'SSP drivers'!$D$2:$D$7886,'Selected scen drivers'!$D4) -> 0 | F4: =SUMIFS('SSP drivers'!F$2:F$7886,'SSP drivers'!$A$2:$A$7886,'Selected scen drivers'!$AH$1,'SSP drivers'!$B$2:$B$7886,'Selected scen drivers'!$AI$1,'SSP drivers'!$C$2:$C$7886,'Selected scen drivers'!$C4,'SSP drivers'!$D$2:$D$7886,'Selected scen drivers'!$D4) -> 923.83924 | G4: =SUMIFS('SSP drivers'!G$2:G$7886,'SSP drivers'!$A$2:$A$7886,'Selected scen drivers'!$AH$1,'SSP drivers'!$B$2:$B$7886,'Selected scen drivers'!$AI$1,'SSP drivers'!$C$2:$C$7886,'Selected scen drivers'!$C4,'SSP drivers'!$D$2:$D$7886,'Selected scen drivers'!$D4) -> 941.62527 | H4: =SUMIFS('SSP drivers'!H$2:H$7886,'SSP drivers'!$A$2:$A$7886,'Selected scen drivers'!$AH$1,'SSP drivers'!$B$2:$B$7886,'Selected scen drivers'!$AI$1,'SSP drivers'!$C$2:$C$7886,'Selected scen drivers'!$C4,'SSP drivers'!$D$2:$D$7886,'Selected scen drivers'!$D4) -> 1171.0965 | I4: =SUMIFS('SSP drivers'!I$2:I$7886,'SSP drivers'!$A$2:$A$7886,'Selected scen drivers'!$AH$1,'SSP drivers'!$B$2:$B$7886,'Selected scen drivers'!$AI$1,'SSP drivers'!$C$2:$C$7886,'Selected scen drivers'!$C4,'SSP drivers'!$D$2:$D$7886,'Selected scen drivers'!$D4) -> 1507.2619 | J4: =SUMIFS('SSP drivers'!J$2:J$7886,'SSP drivers'!$A$2:$A$7886,'Selected scen drivers'!$AH$1,'SSP drivers'!$B$2:$B$7886,'Selected scen drivers'!$AI$1,'SSP drivers'!$C$2:$C$7886,'Selected scen drivers'!$C4,'SSP drivers'!$D$2:$D$7886,'Selected scen drivers'!$D4) -> 1985.9926 | K4: =SUMIFS('SSP drivers'!K$2:K$7886,'SSP drivers'!$A$2:$A$7886,'Selected scen drivers'!$AH$1,'SSP drivers'!$B$2:$B$7886,'Selected scen drivers'!$AI$1,'SSP drivers'!$C$2:$C$7886,'Selected scen drivers'!$C4,'SSP drivers'!$D$2:$D$7886,'Selected scen drivers'!$D4) -> 2581.9862 | L4: =SUMIFS('SSP drivers'!L$2:L$7886,'SSP drivers'!$A$2:$A$7886,'Selected scen drivers'!$AH$1,'SSP drivers'!$B$2:$B$7886,'Selected scen drivers'!$AI$1,'SSP drivers'!$C$2:$C$7886,'Selected scen drivers'!$C4,'SSP drivers'!$D$2:$D$7886,'Selected scen drivers'!$D4) -> 3336.6232 | ... W4: =SUMIFS('SSP drivers'!W$2:W$7886,'SSP drivers'!$A$2:$A$7886,'Selected scen drivers'!$AH$1,'SSP drivers'!$B$2:$B$7886,'Selected scen drivers'!$AI$1,'SSP drivers'!$C$2:$C$7886,'Selected scen drivers'!$C4,'SSP drivers'!$D$2:$D$7886,'Selected scen drivers'!$D4) -> 33780.085
A5: 1 | B5: 4 | C5: =IFERROR(VLOOKUP(A5,Classification!$A$4:$B$37,2,FALSE),"") -> Africa_other | D5: =IFERROR(VLOOKUP(B5,Classification!$N$5:$O$14,2,FALSE),"") -> GDPMFG | E5: =SUMIFS('SSP drivers'!E$2:E$7886,'SSP drivers'!$A$2:$A$7886,'Selected scen drivers'!$AH$1,'SSP drivers'!$B$2:$B$7886,'Selected scen drivers'!$AI$1,'SSP drivers'!$C$2:$C$7886,'Selected scen drivers'!$C5,'SSP drivers'!$D$2:$D$7886,'Selected scen drivers'!$D5) -> 0 | F5: =SUMIFS('SSP drivers'!F$2:F$7886,'SSP drivers'!$A$2:$A$7886,'Selected scen drivers'!$AH$1,'SSP drivers'!$B$2:$B$7886,'Selected scen drivers'!$AI$1,'SSP drivers'!$C$2:$C$7886,'Selected scen drivers'!$C5,'SSP drivers'!$D$2:$D$7886,'Selected scen drivers'!$D5) -> 99.687461 | G5: =SUMIFS('SSP drivers'!G$2:G$7886,'SSP drivers'!$A$2:$A$7886,'Selected scen drivers'!$AH$1,'SSP drivers'!$B$2:$B$7886,'Selected scen drivers'!$AI$1,'SSP drivers'!$C$2:$C$7886,'Selected scen drivers'!$C5,'SSP drivers'!$D$2:$D$7886,'Selected scen drivers'!$D5) -> 101.47959 | H5: =SUMIFS('SSP drivers'!H$2:H$7886,'SSP drivers'!$A$2:$A$7886,'Selected scen drivers'!$AH$1,'SSP drivers'!$B$2:$B$7886,'Selected scen drivers'!$AI$1,'SSP drivers'!$C$2:$C$7886,'Selected scen drivers'!$C5,'SSP drivers'!$D$2:$D$7886,'Selected scen drivers'!$D5) -> 136.06685 | I5: =SUMIFS('SSP drivers'!I$2:I$7886,'SSP drivers'!$A$2:$A$7886,'Selected scen drivers'!$AH$1,'SSP drivers'!$B$2:$B$7886,'Selected scen drivers'!$AI$1,'SSP drivers'!$C$2:$C$7886,'Selected scen drivers'!$C5,'SSP drivers'!$D$2:$D$7886,'Selected scen drivers'!$D5) -> 187.38865 | J5: =SUMIFS('SSP drivers'!J$2:J$7886,'SSP drivers'!$A$2:$A$7886,'Selected scen drivers'!$AH$1,'SSP drivers'!$B$2:$B$7886,'Selected scen drivers'!$AI$1,'SSP drivers'!$C$2:$C$7886,'Selected scen drivers'!$C5,'SSP drivers'!$D$2:$D$7886,'Selected scen drivers'!$D5) -> 264.00246 | K5: =SUMIFS('SSP drivers'!K$2:K$7886,'SSP drivers'!$A$2:$A$7886,'Selected scen drivers'!$AH$1,'SSP drivers'!$B$2:$B$7886,'Selected scen drivers'!$AI$1,'SSP drivers'!$C$2:$C$7886,'Selected scen drivers'!$C5,'SSP drivers'!$D$2:$D$7886,'Selected scen drivers'!$D5) -> 365.9454 | L5: =SUMIFS('SSP drivers'!L$2:L$7886,'SSP drivers'!$A$2:$A$7886,'Selected scen drivers'!$AH$1,'SSP drivers'!$B$2:$B$7886,'Selected scen drivers'!$AI$1,'SSP drivers'!$C$2:$C$7886,'Selected scen drivers'!$C5,'SSP drivers'!$D$2:$D$7886,'Selected scen drivers'!$D5) -> 502.46406 | ... W5: =SUMIFS('SSP drivers'!W$2:W$7886,'SSP drivers'!$A$2:$A$7886,'Selected scen drivers'!$AH$1,'SSP drivers'!$B$2:$B$7886,'Selected scen drivers'!$AI$1,'SSP drivers'!$C$2:$C$7886,'Selected scen drivers'!$C5,'SSP drivers'!$D$2:$D$7886,'Selected scen drivers'!$D5) -> 8440.4372
A6: 1 | B6: 5 | C6: =IFERROR(VLOOKUP(A6,Classification!$A$4:$B$37,2,FALSE),"") -> Africa_other | D6: =IFERROR(VLOOKUP(B6,Classification!$N$5:$O$14,2,FALSE),"") -> GDPPCAP | E6: =SUMIFS('SSP drivers'!E$2:E$7886,'SSP drivers'!$A$2:$A$7886,'Selected scen drivers'!$AH$1,'SSP drivers'!$B$2:$B$7886,'Selected scen drivers'!$AI$1,'SSP drivers'!$C$2:$C$7886,'Selected scen drivers'!$C6,'SSP drivers'!$D$2:$D$7886,'Selected scen drivers'!$D6) -> 0 | F6: =SUMIFS('SSP drivers'!F$2:F$7886,'SSP drivers'!$A$2:$A$7886,'Selected scen drivers'!$AH$1,'SSP drivers'!$B$2:$B$7886,'Selected scen drivers'!$AI$1,'SSP drivers'!$C$2:$C$7886,'Selected scen drivers'!$C6,'SSP drivers'!$D$2:$D$7886,'Selected scen drivers'!$D6) -> 3.2368363 | G6: =SUMIFS('SSP drivers'!G$2:G$7886,'SSP drivers'!$A$2:$A$7886,'Selected scen drivers'!$AH$1,'SSP drivers'!$B$2:$B$7886,'Selected scen drivers'!$AI$1,'SSP drivers'!$C$2:$C$7886,'Selected scen drivers'!$C6,'SSP drivers'!$D$2:$D$7886,'Selected scen drivers'!$D6) -> 3.2133267 | H6: =SUMIFS('SSP drivers'!H$2:H$7886,'SSP drivers'!$A$2:$A$7886,'Selected scen drivers'!$AH$1,'SSP drivers'!$B$2:$B$7886,'Selected scen drivers'!$AI$1,'SSP drivers'!$C$2:$C$7886,'Selected scen drivers'!$C6,'SSP drivers'!$D$2:$D$7886,'Selected scen drivers'!$D6) -> 3.4492745 | I6: =SUMIFS('SSP drivers'!I$2:I$7886,'SSP drivers'!$A$2:$A$7886,'Selected scen drivers'!$AH$1,'SSP drivers'!$B$2:$B$7886,'Selected scen drivers'!$AI$1,'SSP drivers'!$C$2:$C$7886,'Selected scen drivers'!$C6,'SSP drivers'!$D$2:$D$7886,'Selected scen drivers'!$D6) -> 3.9017378 | J6: =SUMIFS('SSP drivers'!J$2:J$7886,'SSP drivers'!$A$2:$A$7886,'Selected scen drivers'!$AH$1,'SSP drivers'!$B$2:$B$7886,'Selected scen drivers'!$AI$1,'SSP drivers'!$C$2:$C$7886,'Selected scen drivers'!$C6,'SSP drivers'!$D$2:$D$7886,'Selected scen drivers'!$D6) -> 4.5498385 | K6: =SUMIFS('SSP drivers'!K$2:K$7886,'SSP drivers'!$A$2:$A$7886,'Selected scen drivers'!$AH$1,'SSP drivers'!$B$2:$B$7886,'Selected scen drivers'!$AI$1,'SSP drivers'!$C$2:$C$7886,'Selected scen drivers'!$C6,'SSP drivers'!$D$2:$D$7886,'Selected scen drivers'!$D6) -> 5.2750821 | L6: =SUMIFS('SSP drivers'!L$2:L$7886,'SSP drivers'!$A$2:$A$7886,'Selected scen drivers'!$AH$1,'SSP drivers'!$B$2:$B$7886,'Selected scen drivers'!$AI$1,'SSP drivers'!$C$2:$C$7886,'Selected scen drivers'!$C6,'SSP drivers'!$D$2:$D$7886,'Selected scen drivers'!$D6) -> 6.1302306 | ... W6: =SUMIFS('SSP drivers'!W$2:W$7886,'SSP drivers'!$A$2:$A$7886,'Selected scen drivers'!$AH$1,'SSP drivers'!$B$2:$B$7886,'Selected scen drivers'!$AI$1,'SSP drivers'!$C$2:$C$7886,'Selected scen drivers'!$C6,'SSP drivers'!$D$2:$D$7886,'Selected scen drivers'!$D6) -> 33.239044
A7: 1 | B7: 6 | C7: =IFERROR(VLOOKUP(A7,Classification!$A$4:$B$37,2,FALSE),"") -> Africa_other | D7: =IFERROR(VLOOKUP(B7,Classification!$N$5:$O$14,2,FALSE),"") -> GDPPHOU | E7: =SUMIFS('SSP drivers'!E$2:E$7886,'SSP drivers'!$A$2:$A$7886,'Selected scen drivers'!$AH$1,'SSP drivers'!$B$2:$B$7886,'Selected scen drivers'!$AI$1,'SSP drivers'!$C$2:$C$7886,'Selected scen drivers'!$C7,'SSP drivers'!$D$2:$D$7886,'Selected scen drivers'!$D7) -> 0 | F7: =SUMIFS('SSP drivers'!F$2:F$7886,'SSP drivers'!$A$2:$A$7886,'Selected scen drivers'!$AH$1,'SSP drivers'!$B$2:$B$7886,'Selected scen drivers'!$AI$1,'SSP drivers'!$C$2:$C$7886,'Selected scen drivers'!$C7,'SSP drivers'!$D$2:$D$7886,'Selected scen drivers'!$D7) -> 14.773233 | G7: =SUMIFS('SSP drivers'!G$2:G$7886,'SSP drivers'!$A$2:$A$7886,'Selected scen drivers'!$AH$1,'SSP drivers'!$B$2:$B$7886,'Selected scen drivers'!$AI$1,'SSP drivers'!$C$2:$C$7886,'Selected scen drivers'!$C7,'SSP drivers'!$D$2:$D$7886,'Selected scen drivers'!$D7) -> 14.571355 | H7: =SUMIFS('SSP drivers'!H$2:H$7886,'SSP drivers'!$A$2:$A$7886,'Selected scen drivers'!$AH$1,'SSP drivers'!$B$2:$B$7886,'Selected scen drivers'!$AI$1,'SSP drivers'!$C$2:$C$7886,'Selected scen drivers'!$C7,'SSP drivers'!$D$2:$D$7886,'Selected scen drivers'!$D7) -> 15.22184 | I7: =SUMIFS('SSP drivers'!I$2:I$7886,'SSP drivers'!$A$2:$A$7886,'Selected scen drivers'!$AH$1,'SSP drivers'!$B$2:$B$7886,'Selected scen drivers'!$AI$1,'SSP drivers'!$C$2:$C$7886,'Selected scen drivers'!$C7,'SSP drivers'!$D$2:$D$7886,'Selected scen drivers'!$D7) -> 16.689463 | J7: =SUMIFS('SSP drivers'!J$2:J$7886,'SSP drivers'!$A$2:$A$7886,'Selected scen drivers'!$AH$1,'SSP drivers'!$B$2:$B$7886,'Selected scen drivers'!$AI$1,'SSP drivers'!$C$2:$C$7886,'Selected scen drivers'!$C7,'SSP drivers'!$D$2:$D$7886,'Selected scen drivers'!$D7) -> 18.820461 | K7: =SUMIFS('SSP drivers'!K$2:K$7886,'SSP drivers'!$A$2:$A$7886,'Selected scen drivers'!$AH$1,'SSP drivers'!$B$2:$B$7886,'Selected scen drivers'!$AI$1,'SSP drivers'!$C$2:$C$7886,'Selected scen drivers'!$C7,'SSP drivers'!$D$2:$D$7886,'Selected scen drivers'!$D7) -> 21.132227 | L7: =SUMIFS('SSP drivers'!L$2:L$7886,'SSP drivers'!$A$2:$A$7886,'Selected scen drivers'!$AH$1,'SSP drivers'!$B$2:$B$7886,'Selected scen drivers'!$AI$1,'SSP drivers'!$C$2:$C$7886,'Selected scen drivers'!$C7,'SSP drivers'!$D$2:$D$7886,'Selected scen drivers'!$D7) -> 23.831549 | ... W7: =SUMIFS('SSP drivers'!W$2:W$7886,'SSP drivers'!$A$2:$A$7886,'Selected scen drivers'!$AH$1,'SSP drivers'!$B$2:$B$7886,'Selected scen drivers'!$AI$1,'SSP drivers'!$C$2:$C$7886,'Selected scen drivers'!$C7,'SSP drivers'!$D$2:$D$7886,'Selected scen drivers'!$D7) -> 110.53415
A8: 1 | B8: 7 | C8: =IFERROR(VLOOKUP(A8,Classification!$A$4:$B$37,2,FALSE),"") -> Africa_other | D8: =IFERROR(VLOOKUP(B8,Classification!$N$5:$O$14,2,FALSE),"") -> GDPSER | E8: =SUMIFS('SSP drivers'!E$2:E$7886,'SSP drivers'!$A$2:$A$7886,'Selected scen drivers'!$AH$1,'SSP drivers'!$B$2:$B$7886,'Selected scen drivers'!$AI$1,'SSP drivers'!$C$2:$C$7886,'Selected scen drivers'!$C8,'SSP drivers'!$D$2:$D$7886,'Selected scen drivers'!$D8) -> 0 | F8: =SUMIFS('SSP drivers'!F$2:F$7886,'SSP drivers'!$A$2:$A$7886,'Selected scen drivers'!$AH$1,'SSP drivers'!$B$2:$B$7886,'Selected scen drivers'!$AI$1,'SSP drivers'!$C$2:$C$7886,'Selected scen drivers'!$C8,'SSP drivers'!$D$2:$D$7886,'Selected scen drivers'!$D8) -> 1681.2763 | G8: =SUMIFS('SSP drivers'!G$2:G$7886,'SSP drivers'!$A$2:$A$7886,'Selected scen drivers'!$AH$1,'SSP drivers'!$B$2:$B$7886,'Selected scen drivers'!$AI$1,'SSP drivers'!$C$2:$C$7886,'Selected scen drivers'!$C8,'SSP drivers'!$D$2:$D$7886,'Selected scen drivers'!$D8) -> 1713.1844 | H8: =SUMIFS('SSP drivers'!H$2:H$7886,'SSP drivers'!$A$2:$A$7886,'Selected scen drivers'!$AH$1,'SSP drivers'!$B$2:$B$7886,'Selected scen drivers'!$AI$1,'SSP drivers'!$C$2:$C$7886,'Selected scen drivers'!$C8,'SSP drivers'!$D$2:$D$7886,'Selected scen drivers'!$D8) -> 2110.325 | I8: =SUMIFS('SSP drivers'!I$2:I$7886,'SSP drivers'!$A$2:$A$7886,'Selected scen drivers'!$AH$1,'SSP drivers'!$B$2:$B$7886,'Selected scen drivers'!$AI$1,'SSP drivers'!$C$2:$C$7886,'Selected scen drivers'!$C8,'SSP drivers'!$D$2:$D$7886,'Selected scen drivers'!$D8) -> 2724.9262 | J8: =SUMIFS('SSP drivers'!J$2:J$7886,'SSP drivers'!$A$2:$A$7886,'Selected scen drivers'!$AH$1,'SSP drivers'!$B$2:$B$7886,'Selected scen drivers'!$AI$1,'SSP drivers'!$C$2:$C$7886,'Selected scen drivers'!$C8,'SSP drivers'!$D$2:$D$7886,'Selected scen drivers'!$D8) -> 3598.6769 | K8: =SUMIFS('SSP drivers'!K$2:K$7886,'SSP drivers'!$A$2:$A$7886,'Selected scen drivers'!$AH$1,'SSP drivers'!$B$2:$B$7886,'Selected scen drivers'!$AI$1,'SSP drivers'!$C$2:$C$7886,'Selected scen drivers'!$C8,'SSP drivers'!$D$2:$D$7886,'Selected scen drivers'!$D8) -> 4681.8771 | L8: =SUMIFS('SSP drivers'!L$2:L$7886,'SSP drivers'!$A$2:$A$7886,'Selected scen drivers'!$AH$1,'SSP drivers'!$B$2:$B$7886,'Selected scen drivers'!$AI$1,'SSP drivers'!$C$2:$C$7886,'Selected scen drivers'!$C8,'SSP drivers'!$D$2:$D$7886,'Selected scen drivers'!$D8) -> 6050.1115 | ... W8: =SUMIFS('SSP drivers'!W$2:W$7886,'SSP drivers'!$A$2:$A$7886,'Selected scen drivers'!$AH$1,'SSP drivers'!$B$2:$B$7886,'Selected scen drivers'!$AI$1,'SSP drivers'!$C$2:$C$7886,'Selected scen drivers'!$C8,'SSP drivers'!$D$2:$D$7886,'Selected scen drivers'!$D8) -> 63396.71
